schematic = {
	size = {x=9, y=8, z=11},
	yslice_prob = {
		{ypos=0, prob=254},
		{ypos=1, prob=254},
		{ypos=2, prob=254},
		{ypos=3, prob=254},
		{ypos=4, prob=254},
		{ypos=5, prob=254},
		{ypos=6, prob=254},
		{ypos=7, prob=254},
	},
	data = {
		{name="vlf_villages:no_paths", prob=254, param2=0},
		{name="vlf_villages:no_paths", prob=254, param2=0},
		{name="vlf_villages:no_paths", prob=254, param2=0},
		{name="vlf_villages:no_paths", prob=254, param2=0},
		{name="vlf_villages:no_paths", prob=254, param2=0},
		{name="vlf_villages:no_paths", prob=254, param2=0},
		{name="vlf_villages:no_paths", prob=254, param2=0},
		{name="vlf_villages:no_paths", prob=254, param2=0},
		{name="vlf_villages:no_paths", prob=254, param2=0},
		{name="vlf_villages:no_paths", prob=254, param2=0},
		{name="vlf_villages:no_paths", prob=254, param2=0},
		{name="vlf_villages:no_paths", prob=254, param2=0},
		{name="vlf_villages:no_paths", prob=254, param2=0},
		{name="vlf_villages:no_paths", prob=254, param2=0},
		{name="vlf_villages:no_paths", prob=254, param2=0},
		{name="vlf_villages:no_paths", prob=254, param2=0},
		{name="vlf_villages:no_paths", prob=254, param2=0},
		{name="vlf_villages:no_paths", prob=254, param2=0},
		{name="air", prob=254, param2=0},
		{name="air", prob=254, param2=0},
		{name="air", prob=254, param2=0},
		{name="air", prob=254, param2=0},
		{name="air", prob=254, param2=0},
		{name="air", prob=254, param2=0},
		{name="air", prob=254, param2=0},
		{name="air", prob=254, param2=0},
		{name="air", prob=254, param2=0},
		{name="air", prob=254, param2=0},
		{name="air", prob=254, param2=0},
		{name="air", prob=254, param2=0},
		{name="air", prob=254, param2=0},
		{name="air", prob=254, param2=0},
		{name="air", prob=254, param2=0},
		{name="air", prob=254, param2=0},
		{name="air", prob=254, param2=0},
		{name="air", prob=254, param2=0},
		{name="air", prob=254, param2=0},
		{name="air", prob=254, param2=0},
		{name="air", prob=254, param2=0},
		{name="air", prob=254, param2=0},
		{name="air", prob=254, param2=0},
		{name="air", prob=254, param2=0},
		{name="air", prob=254, param2=0},
		{name="air", prob=254, param2=0},
		{name="air", prob=254, param2=0},
		{name="air", prob=254, param2=0},
		{name="air", prob=254, param2=0},
		{name="air", prob=254, param2=0},
		{name="air", prob=254, param2=0},
		{name="air", prob=254, param2=0},
		{name="air", prob=254, param2=0},
		{name="air", prob=254, param2=0},
		{name="air", prob=254, param2=0},
		{name="air", prob=254, param2=0},
		{name="air", prob=254, param2=0},
		{name="air", prob=254, param2=0},
		{name="air", prob=254, param2=0},
		{name="air", prob=254, param2=0},
		{name="air", prob=254, param2=0},
		{name="air", prob=254, param2=0},
		{name="air", prob=254, param2=0},
		{name="air", prob=254, param2=0},
		{name="air", prob=254, param2=0},
		{name="air", prob=254, param2=0},
		{name="air", prob=254, param2=0},
		{name="air", prob=254, param2=0},
		{name="air", prob=254, param2=0},
		{name="air", prob=254, param2=0},
		{name="air", prob=254, param2=0},
		{name="air", prob=254, param2=0},
		{name="air", prob=254, param2=0},
		{name="air", prob=254, param2=0},
		{name="vlf_villages:no_paths", prob=254, param2=0},
		{name="vlf_core:cobble", prob=254, param2=0},
		{name="vlf_core:cobble", prob=254, param2=0},
		{name="vlf_core:cobble", prob=254, param2=0},
		{name="vlf_core:cobble", prob=254, param2=0},
		{name="vlf_core:cobble", prob=254, param2=0},
		{name="vlf_core:cobble", prob=254, param2=0},
		{name="vlf_core:cobble", prob=254, param2=0},
		{name="vlf_villages:no_paths", prob=254, param2=0},
		{name="vlf_villages:no_paths", prob=254, param2=0},
		{name="vlf_core:brick_block", prob=254, param2=0},
		{name="vlf_core:brick_block", prob=254, param2=0},
		{name="vlf_core:brick_block", prob=254, param2=0},
		{name="vlf_core:brick_block", prob=254, param2=0},
		{name="vlf_core:brick_block", prob=254, param2=0},
		{name="vlf_core:brick_block", prob=254, param2=0},
		{name="vlf_core:brick_block", prob=254, param2=0},
		{name="vlf_villages:no_paths", prob=254, param2=0},
		{name="air", prob=254, param2=0},
		{name="vlf_core:brick_block", prob=254, param2=0},
		{name="vlf_stairs:slab_stone", prob=254, param2=0},
		{name="vlf_stairs:slab_stone", prob=254, param2=0},
		{name="vlf_stairs:slab_stone", prob=254, param2=0},
		{name="vlf_stairs:slab_stone", prob=254, param2=0},
		{name="vlf_stairs:slab_stone", prob=254, param2=0},
		{name="vlf_core:brick_block", prob=254, param2=0},
		{name="air", prob=254, param2=0},
		{name="vlf_torches:torch_wall", prob=254, param2=2},
		{name="vlf_core:brick_block", prob=254, param2=0},
		{name="vlf_panes:bar_flat", prob=254, param2=2},
		{name="vlf_panes:bar_flat", prob=254, param2=0},
		{name="vlf_panes:bar_flat", prob=254, param2=0},
		{name="vlf_panes:bar_flat", prob=254, param2=0},
		{name="vlf_panes:bar_flat", prob=254, param2=0},
		{name="vlf_core:brick_block", prob=254, param2=0},
		{name="air", prob=254, param2=0},
		{name="air", prob=254, param2=0},
		{name="vlf_core:cobble", prob=254, param2=0},
		{name="vlf_core:cobble", prob=254, param2=0},
		{name="vlf_core:cobble", prob=254, param2=0},
		{name="vlf_core:cobble", prob=254, param2=0},
		{name="vlf_core:cobble", prob=254, param2=0},
		{name="vlf_core:cobble", prob=254, param2=0},
		{name="vlf_core:cobble", prob=254, param2=0},
		{name="air", prob=254, param2=0},
		{name="air", prob=254, param2=0},
		{name="air", prob=254, param2=0},
		{name="air", prob=254, param2=0},
		{name="air", prob=254, param2=0},
		{name="air", prob=254, param2=0},
		{name="air", prob=254, param2=0},
		{name="air", prob=254, param2=0},
		{name="air", prob=254, param2=0},
		{name="air", prob=254, param2=0},
		{name="air", prob=254, param2=0},
		{name="air", prob=254, param2=0},
		{name="air", prob=254, param2=0},
		{name="air", prob=254, param2=0},
		{name="air", prob=254, param2=0},
		{name="air", prob=254, param2=0},
		{name="air", prob=254, param2=0},
		{name="air", prob=254, param2=0},
		{name="air", prob=254, param2=0},
		{name="air", prob=254, param2=0},
		{name="air", prob=254, param2=0},
		{name="air", prob=254, param2=0},
		{name="air", prob=254, param2=0},
		{name="air", prob=254, param2=0},
		{name="air", prob=254, param2=0},
		{name="air", prob=254, param2=0},
		{name="air", prob=254, param2=0},
		{name="air", prob=254, param2=0},
		{name="vlf_villages:no_paths", prob=254, param2=0},
		{name="vlf_stairs:stair_cobble", prob=254, param2=1},
		{name="vlf_colorblocks:hardened_clay", prob=254, param2=0},
		{name="vlf_colorblocks:hardened_clay", prob=254, param2=0},
		{name="vlf_colorblocks:hardened_clay", prob=254, param2=0},
		{name="vlf_colorblocks:hardened_clay", prob=254, param2=0},
		{name="vlf_colorblocks:hardened_clay", prob=254, param2=0},
		{name="vlf_core:cobble", prob=254, param2=0},
		{name="vlf_villages:no_paths", prob=254, param2=0},
		{name="vlf_villages:no_paths", prob=254, param2=0},
		{name="air", prob=254, param2=0},
		{name="air", prob=254, param2=0},
		{name="vlf_stairs:stair_diorite_smooth", prob=254, param2=2},
		{name="vlf_stairs:stair_diorite_smooth", prob=254, param2=2},
		{name="vlf_stairs:stair_diorite_smooth", prob=254, param2=2},
		{name="vlf_chests:chest_small", prob=254, param2=2},
		{name="vlf_core:brick_block", prob=254, param2=0},
		{name="vlf_villages:no_paths", prob=254, param2=0},
		{name="air", prob=254, param2=0},
		{name="air", prob=254, param2=0},
		{name="air", prob=254, param2=0},
		{name="air", prob=254, param2=0},
		{name="air", prob=254, param2=0},
		{name="air", prob=254, param2=0},
		{name="air", prob=254, param2=0},
		{name="vlf_core:brick_block", prob=254, param2=0},
		{name="air", prob=254, param2=0},
		{name="air", prob=254, param2=0},
		{name="air", prob=254, param2=0},
		{name="air", prob=254, param2=0},
		{name="air", prob=254, param2=0},
		{name="air", prob=254, param2=0},
		{name="air", prob=254, param2=0},
		{name="air", prob=254, param2=0},
		{name="vlf_core:brick_block", prob=254, param2=0},
		{name="air", prob=254, param2=0},
		{name="air", prob=254, param2=0},
		{name="vlf_core:cobble", prob=254, param2=0},
		{name="vlf_core:cobble", prob=254, param2=0},
		{name="vlf_core:cobble", prob=254, param2=0},
		{name="vlf_core:cobble", prob=254, param2=0},
		{name="vlf_core:cobble", prob=254, param2=0},
		{name="vlf_core:cobble", prob=254, param2=0},
		{name="vlf_core:cobble", prob=254, param2=0},
		{name="air", prob=254, param2=0},
		{name="air", prob=254, param2=0},
		{name="air", prob=254, param2=0},
		{name="air", prob=254, param2=0},
		{name="air", prob=254, param2=0},
		{name="air", prob=254, param2=0},
		{name="air", prob=254, param2=0},
		{name="air", prob=254, param2=0},
		{name="air", prob=254, param2=0},
		{name="air", prob=254, param2=0},
		{name="air", prob=254, param2=0},
		{name="air", prob=254, param2=0},
		{name="air", prob=254, param2=0},
		{name="air", prob=254, param2=0},
		{name="air", prob=254, param2=0},
		{name="air", prob=254, param2=0},
		{name="air", prob=254, param2=0},
		{name="air", prob=254, param2=0},
		{name="air", prob=254, param2=0},
		{name="air", prob=254, param2=0},
		{name="air", prob=254, param2=0},
		{name="air", prob=254, param2=0},
		{name="air", prob=254, param2=0},
		{name="air", prob=254, param2=0},
		{name="air", prob=254, param2=0},
		{name="air", prob=254, param2=0},
		{name="air", prob=254, param2=0},
		{name="air", prob=254, param2=0},
		{name="vlf_villages:no_paths", prob=254, param2=0},
		{name="vlf_stairs:stair_cobble", prob=254, param2=1},
		{name="vlf_colorblocks:hardened_clay", prob=254, param2=0},
		{name="vlf_colorblocks:hardened_clay", prob=254, param2=0},
		{name="vlf_colorblocks:hardened_clay", prob=254, param2=0},
		{name="vlf_colorblocks:hardened_clay", prob=254, param2=0},
		{name="vlf_colorblocks:hardened_clay", prob=254, param2=0},
		{name="vlf_core:cobble", prob=254, param2=0},
		{name="vlf_villages:no_paths", prob=254, param2=0},
		{name="vlf_villages:no_paths", prob=254, param2=0},
		{name="vlf_villages:no_paths", prob=254, param2=0},
		{name="air", prob=254, param2=0},
		{name="air", prob=254, param2=0},
		{name="air", prob=254, param2=0},
		{name="air", prob=254, param2=0},
		{name="air", prob=254, param2=0},
		{name="vlf_core:brick_block", prob=254, param2=0},
		{name="vlf_villages:no_paths", prob=254, param2=0},
		{name="air", prob=254, param2=0},
		{name="air", prob=254, param2=0},
		{name="air", prob=254, param2=0},
		{name="air", prob=254, param2=0},
		{name="air", prob=254, param2=0},
		{name="air", prob=254, param2=0},
		{name="air", prob=254, param2=0},
		{name="vlf_stairs:slab_stone", prob=254, param2=0},
		{name="air", prob=254, param2=0},
		{name="air", prob=254, param2=0},
		{name="air", prob=254, param2=0},
		{name="air", prob=254, param2=0},
		{name="air", prob=254, param2=0},
		{name="air", prob=254, param2=0},
		{name="air", prob=254, param2=0},
		{name="air", prob=254, param2=0},
		{name="vlf_panes:bar_flat", prob=254, param2=1},
		{name="air", prob=254, param2=0},
		{name="air", prob=254, param2=0},
		{name="vlf_core:cobble", prob=254, param2=0},
		{name="vlf_core:cobble", prob=254, param2=0},
		{name="vlf_core:cobble", prob=254, param2=0},
		{name="vlf_core:cobble", prob=254, param2=0},
		{name="vlf_core:cobble", prob=254, param2=0},
		{name="vlf_core:cobble", prob=254, param2=0},
		{name="vlf_core:cobble", prob=254, param2=0},
		{name="air", prob=254, param2=0},
		{name="air", prob=254, param2=0},
		{name="air", prob=254, param2=0},
		{name="air", prob=254, param2=0},
		{name="air", prob=254, param2=0},
		{name="air", prob=254, param2=0},
		{name="air", prob=254, param2=0},
		{name="air", prob=254, param2=0},
		{name="air", prob=254, param2=0},
		{name="air", prob=254, param2=0},
		{name="air", prob=254, param2=0},
		{name="air", prob=254, param2=0},
		{name="air", prob=254, param2=0},
		{name="air", prob=254, param2=0},
		{name="air", prob=254, param2=0},
		{name="air", prob=254, param2=0},
		{name="air", prob=254, param2=0},
		{name="air", prob=254, param2=0},
		{name="air", prob=254, param2=0},
		{name="air", prob=254, param2=0},
		{name="air", prob=254, param2=0},
		{name="air", prob=254, param2=0},
		{name="air", prob=254, param2=0},
		{name="air", prob=254, param2=0},
		{name="air", prob=254, param2=0},
		{name="air", prob=254, param2=0},
		{name="air", prob=254, param2=0},
		{name="air", prob=254, param2=0},
		{name="vlf_villages:path_endpoint", prob=254, param2=0},
		{name="vlf_stairs:stair_cobble", prob=254, param2=1},
		{name="vlf_colorblocks:hardened_clay", prob=254, param2=0},
		{name="vlf_colorblocks:hardened_clay", prob=254, param2=0},
		{name="vlf_colorblocks:hardened_clay", prob=254, param2=0},
		{name="vlf_colorblocks:hardened_clay", prob=254, param2=0},
		{name="vlf_colorblocks:hardened_clay", prob=254, param2=0},
		{name="vlf_core:cobble", prob=254, param2=0},
		{name="vlf_villages:no_paths", prob=254, param2=0},
		{name="vlf_villages:no_paths", prob=254, param2=0},
		{name="vlf_villages:no_paths", prob=254, param2=0},
		{name="air", prob=254, param2=0},
		{name="air", prob=254, param2=0},
		{name="air", prob=254, param2=0},
		{name="air", prob=254, param2=0},
		{name="vlf_anvils:anvil", prob=254, param2=1},
		{name="vlf_core:brick_block", prob=254, param2=0},
		{name="vlf_villages:no_paths", prob=254, param2=0},
		{name="air", prob=254, param2=0},
		{name="air", prob=254, param2=0},
		{name="air", prob=254, param2=0},
		{name="air", prob=254, param2=0},
		{name="air", prob=254, param2=0},
		{name="air", prob=254, param2=0},
		{name="air", prob=254, param2=0},
		{name="vlf_stairs:slab_stone", prob=254, param2=0},
		{name="air", prob=254, param2=0},
		{name="air", prob=254, param2=0},
		{name="air", prob=254, param2=0},
		{name="air", prob=254, param2=0},
		{name="air", prob=254, param2=0},
		{name="air", prob=254, param2=0},
		{name="air", prob=254, param2=0},
		{name="air", prob=254, param2=0},
		{name="vlf_panes:bar_flat", prob=254, param2=3},
		{name="air", prob=254, param2=0},
		{name="air", prob=254, param2=0},
		{name="vlf_core:cobble", prob=254, param2=0},
		{name="vlf_core:cobble", prob=254, param2=0},
		{name="vlf_core:cobble", prob=254, param2=0},
		{name="vlf_core:cobble", prob=254, param2=0},
		{name="vlf_core:cobble", prob=254, param2=0},
		{name="vlf_core:cobble", prob=254, param2=0},
		{name="vlf_core:cobble", prob=254, param2=0},
		{name="air", prob=254, param2=0},
		{name="air", prob=254, param2=0},
		{name="air", prob=254, param2=0},
		{name="air", prob=254, param2=0},
		{name="air", prob=254, param2=0},
		{name="air", prob=254, param2=0},
		{name="air", prob=254, param2=0},
		{name="air", prob=254, param2=0},
		{name="air", prob=254, param2=0},
		{name="air", prob=254, param2=0},
		{name="air", prob=254, param2=0},
		{name="air", prob=254, param2=0},
		{name="air", prob=254, param2=0},
		{name="air", prob=254, param2=0},
		{name="air", prob=254, param2=0},
		{name="air", prob=254, param2=0},
		{name="air", prob=254, param2=0},
		{name="air", prob=254, param2=0},
		{name="air", prob=254, param2=0},
		{name="air", prob=254, param2=0},
		{name="air", prob=254, param2=0},
		{name="air", prob=254, param2=0},
		{name="air", prob=254, param2=0},
		{name="air", prob=254, param2=0},
		{name="air", prob=254, param2=0},
		{name="air", prob=254, param2=0},
		{name="air", prob=254, param2=0},
		{name="air", prob=254, param2=0},
		{name="vlf_villages:no_paths", prob=254, param2=0},
		{name="vlf_stairs:stair_cobble", prob=254, param2=1},
		{name="vlf_colorblocks:hardened_clay", prob=254, param2=0},
		{name="vlf_colorblocks:hardened_clay", prob=254, param2=0},
		{name="vlf_colorblocks:hardened_clay", prob=254, param2=0},
		{name="vlf_colorblocks:hardened_clay", prob=254, param2=0},
		{name="vlf_colorblocks:hardened_clay", prob=254, param2=0},
		{name="vlf_core:cobble", prob=254, param2=0},
		{name="vlf_villages:no_paths", prob=254, param2=0},
		{name="vlf_villages:no_paths", prob=254, param2=0},
		{name="vlf_villages:no_paths", prob=254, param2=0},
		{name="air", prob=254, param2=0},
		{name="air", prob=254, param2=0},
		{name="air", prob=254, param2=0},
		{name="air", prob=254, param2=0},
		{name="air", prob=254, param2=0},
		{name="vlf_core:brick_block", prob=254, param2=0},
		{name="vlf_villages:no_paths", prob=254, param2=0},
		{name="air", prob=254, param2=0},
		{name="air", prob=254, param2=0},
		{name="air", prob=254, param2=0},
		{name="air", prob=254, param2=0},
		{name="air", prob=254, param2=0},
		{name="air", prob=254, param2=0},
		{name="air", prob=254, param2=0},
		{name="vlf_stairs:slab_stone", prob=254, param2=0},
		{name="air", prob=254, param2=0},
		{name="air", prob=254, param2=0},
		{name="air", prob=254, param2=0},
		{name="air", prob=254, param2=0},
		{name="air", prob=254, param2=0},
		{name="air", prob=254, param2=0},
		{name="air", prob=254, param2=0},
		{name="air", prob=254, param2=0},
		{name="vlf_panes:bar_flat", prob=254, param2=3},
		{name="air", prob=254, param2=0},
		{name="air", prob=254, param2=0},
		{name="vlf_core:cobble", prob=254, param2=0},
		{name="vlf_core:cobble", prob=254, param2=0},
		{name="vlf_core:cobble", prob=254, param2=0},
		{name="vlf_core:cobble", prob=254, param2=0},
		{name="vlf_core:cobble", prob=254, param2=0},
		{name="vlf_core:cobble", prob=254, param2=0},
		{name="vlf_core:cobble", prob=254, param2=0},
		{name="air", prob=254, param2=0},
		{name="air", prob=254, param2=0},
		{name="air", prob=254, param2=0},
		{name="air", prob=254, param2=0},
		{name="air", prob=254, param2=0},
		{name="air", prob=254, param2=0},
		{name="air", prob=254, param2=0},
		{name="air", prob=254, param2=0},
		{name="air", prob=254, param2=0},
		{name="air", prob=254, param2=0},
		{name="air", prob=254, param2=0},
		{name="air", prob=254, param2=0},
		{name="air", prob=254, param2=0},
		{name="air", prob=254, param2=0},
		{name="air", prob=254, param2=0},
		{name="air", prob=254, param2=0},
		{name="air", prob=254, param2=0},
		{name="air", prob=254, param2=0},
		{name="air", prob=254, param2=0},
		{name="air", prob=254, param2=0},
		{name="air", prob=254, param2=0},
		{name="air", prob=254, param2=0},
		{name="air", prob=254, param2=0},
		{name="air", prob=254, param2=0},
		{name="air", prob=254, param2=0},
		{name="air", prob=254, param2=0},
		{name="air", prob=254, param2=0},
		{name="air", prob=254, param2=0},
		{name="vlf_villages:no_paths", prob=254, param2=0},
		{name="vlf_stairs:stair_cobble", prob=254, param2=1},
		{name="vlf_colorblocks:hardened_clay", prob=254, param2=0},
		{name="vlf_colorblocks:hardened_clay", prob=254, param2=0},
		{name="vlf_core:cobble", prob=254, param2=0},
		{name="vlf_core:cobble", prob=254, param2=0},
		{name="vlf_core:cobble", prob=254, param2=0},
		{name="vlf_core:cobble", prob=254, param2=0},
		{name="vlf_villages:no_paths", prob=254, param2=0},
		{name="vlf_villages:no_paths", prob=254, param2=0},
		{name="air", prob=254, param2=0},
		{name="air", prob=254, param2=0},
		{name="air", prob=254, param2=0},
		{name="vlf_stairs:slab_stone_double", prob=254, param2=0},
		{name="vlf_blast_furnace:blast_furnace", prob=254, param2=0},
		{name="vlf_stairs:slab_stone_double", prob=254, param2=0},
		{name="vlf_core:brick_block", prob=254, param2=0},
		{name="vlf_villages:no_paths", prob=254, param2=0},
		{name="air", prob=254, param2=0},
		{name="air", prob=254, param2=0},
		{name="air", prob=254, param2=0},
		{name="air", prob=254, param2=0},
		{name="vlf_stairs:slab_stone_top", prob=254, param2=0},
		{name="vlf_stairs:slab_stone_top", prob=254, param2=0},
		{name="vlf_stairs:slab_stone_top", prob=254, param2=0},
		{name="vlf_core:brick_block", prob=254, param2=0},
		{name="air", prob=254, param2=0},
		{name="air", prob=254, param2=0},
		{name="air", prob=254, param2=0},
		{name="air", prob=254, param2=0},
		{name="air", prob=254, param2=0},
		{name="vlf_panes:bar", prob=254, param2=0},
		{name="vlf_panes:bar_flat", prob=254, param2=0},
		{name="vlf_panes:bar_flat", prob=254, param2=0},
		{name="vlf_core:brick_block", prob=254, param2=0},
		{name="air", prob=254, param2=0},
		{name="air", prob=254, param2=0},
		{name="vlf_core:cobble", prob=254, param2=0},
		{name="vlf_core:cobble", prob=254, param2=0},
		{name="vlf_core:cobble", prob=254, param2=0},
		{name="vlf_core:cobble", prob=254, param2=0},
		{name="vlf_core:cobble", prob=254, param2=0},
		{name="vlf_core:cobble", prob=254, param2=0},
		{name="vlf_core:cobble", prob=254, param2=0},
		{name="air", prob=254, param2=0},
		{name="air", prob=254, param2=0},
		{name="air", prob=254, param2=0},
		{name="air", prob=254, param2=0},
		{name="air", prob=254, param2=0},
		{name="vlf_stairs:stair_cobble_outer", prob=254, param2=1},
		{name="vlf_stairs:stair_cobble", prob=254, param2=0},
		{name="vlf_stairs:stair_cobble", prob=254, param2=0},
		{name="vlf_stairs:stair_cobble_outer", prob=254, param2=0},
		{name="air", prob=254, param2=0},
		{name="air", prob=254, param2=0},
		{name="air", prob=254, param2=0},
		{name="air", prob=254, param2=0},
		{name="air", prob=254, param2=0},
		{name="air", prob=254, param2=0},
		{name="air", prob=254, param2=0},
		{name="air", prob=254, param2=0},
		{name="air", prob=254, param2=0},
		{name="air", prob=254, param2=0},
		{name="air", prob=254, param2=0},
		{name="air", prob=254, param2=0},
		{name="air", prob=254, param2=0},
		{name="air", prob=254, param2=0},
		{name="air", prob=254, param2=0},
		{name="air", prob=254, param2=0},
		{name="air", prob=254, param2=0},
		{name="air", prob=254, param2=0},
		{name="air", prob=254, param2=0},
		{name="vlf_villages:no_paths", prob=254, param2=0},
		{name="vlf_stairs:stair_cobble", prob=254, param2=1},
		{name="vlf_colorblocks:hardened_clay", prob=254, param2=0},
		{name="vlf_colorblocks:hardened_clay", prob=254, param2=0},
		{name="vlf_core:cobble", prob=254, param2=0},
		{name="vlf_core:cobble", prob=254, param2=0},
		{name="vlf_core:cobble", prob=254, param2=0},
		{name="vlf_core:cobble", prob=254, param2=0},
		{name="vlf_villages:no_paths", prob=254, param2=0},
		{name="vlf_villages:no_paths", prob=254, param2=0},
		{name="air", prob=254, param2=0},
		{name="air", prob=254, param2=0},
		{name="air", prob=254, param2=0},
		{name="vlf_stairs:slab_stone_double", prob=254, param2=0},
		{name="vlf_core:lava_source", prob=254, param2=3},
		{name="vlf_core:lava_source", prob=254, param2=3},
		{name="vlf_stairs:slab_stone_double", prob=254, param2=0},
		{name="vlf_villages:no_paths", prob=254, param2=0},
		{name="air", prob=254, param2=0},
		{name="air", prob=254, param2=0},
		{name="air", prob=254, param2=0},
		{name="air", prob=254, param2=0},
		{name="vlf_stairs:slab_stone_top", prob=254, param2=0},
		{name="air", prob=254, param2=0},
		{name="air", prob=254, param2=0},
		{name="vlf_stairs:slab_stone", prob=254, param2=0},
		{name="air", prob=254, param2=0},
		{name="air", prob=254, param2=0},
		{name="air", prob=254, param2=0},
		{name="air", prob=254, param2=0},
		{name="air", prob=254, param2=0},
		{name="vlf_panes:bar_flat", prob=254, param2=3},
		{name="air", prob=254, param2=0},
		{name="air", prob=254, param2=0},
		{name="vlf_panes:bar_flat", prob=254, param2=1},
		{name="air", prob=254, param2=0},
		{name="air", prob=254, param2=0},
		{name="vlf_core:cobble", prob=254, param2=0},
		{name="vlf_core:cobble", prob=254, param2=0},
		{name="vlf_core:cobble", prob=254, param2=0},
		{name="vlf_core:cobble", prob=254, param2=0},
		{name="air", prob=254, param2=0},
		{name="air", prob=254, param2=0},
		{name="vlf_core:cobble", prob=254, param2=0},
		{name="air", prob=254, param2=0},
		{name="air", prob=254, param2=0},
		{name="air", prob=254, param2=0},
		{name="air", prob=254, param2=0},
		{name="air", prob=254, param2=0},
		{name="vlf_stairs:stair_cobble", prob=254, param2=1},
		{name="air", prob=254, param2=0},
		{name="air", prob=254, param2=0},
		{name="vlf_stairs:stair_cobble", prob=254, param2=3},
		{name="air", prob=254, param2=0},
		{name="air", prob=254, param2=0},
		{name="air", prob=254, param2=0},
		{name="air", prob=254, param2=0},
		{name="air", prob=254, param2=0},
		{name="air", prob=254, param2=0},
		{name="vlf_stairs:slab_cobble_top", prob=254, param2=0},
		{name="vlf_stairs:slab_cobble_top", prob=254, param2=0},
		{name="air", prob=254, param2=0},
		{name="air", prob=254, param2=0},
		{name="air", prob=254, param2=0},
		{name="air", prob=254, param2=0},
		{name="air", prob=254, param2=0},
		{name="air", prob=254, param2=0},
		{name="air", prob=254, param2=0},
		{name="air", prob=254, param2=0},
		{name="air", prob=254, param2=0},
		{name="air", prob=254, param2=0},
		{name="air", prob=254, param2=0},
		{name="vlf_villages:no_paths", prob=254, param2=0},
		{name="vlf_stairs:stair_cobble", prob=254, param2=1},
		{name="vlf_colorblocks:hardened_clay", prob=254, param2=0},
		{name="vlf_colorblocks:hardened_clay", prob=254, param2=0},
		{name="vlf_core:cobble", prob=254, param2=0},
		{name="vlf_core:cobble", prob=254, param2=0},
		{name="vlf_core:cobble", prob=254, param2=0},
		{name="vlf_core:cobble", prob=254, param2=0},
		{name="vlf_villages:no_paths", prob=254, param2=0},
		{name="vlf_villages:no_paths", prob=254, param2=0},
		{name="air", prob=254, param2=0},
		{name="air", prob=254, param2=0},
		{name="air", prob=254, param2=0},
		{name="vlf_stairs:slab_stone_double", prob=254, param2=0},
		{name="vlf_core:lava_source", prob=254, param2=3},
		{name="vlf_core:lava_source", prob=254, param2=3},
		{name="vlf_stairs:slab_stone_double", prob=254, param2=0},
		{name="vlf_villages:no_paths", prob=254, param2=0},
		{name="air", prob=254, param2=0},
		{name="air", prob=254, param2=0},
		{name="air", prob=254, param2=0},
		{name="air", prob=254, param2=0},
		{name="vlf_stairs:slab_stone_top", prob=254, param2=0},
		{name="air", prob=254, param2=0},
		{name="air", prob=254, param2=0},
		{name="vlf_stairs:slab_stone", prob=254, param2=0},
		{name="air", prob=254, param2=0},
		{name="air", prob=254, param2=0},
		{name="air", prob=254, param2=0},
		{name="air", prob=254, param2=0},
		{name="air", prob=254, param2=0},
		{name="vlf_panes:bar_flat", prob=254, param2=3},
		{name="air", prob=254, param2=0},
		{name="air", prob=254, param2=0},
		{name="vlf_panes:bar_flat", prob=254, param2=3},
		{name="air", prob=254, param2=0},
		{name="air", prob=254, param2=0},
		{name="vlf_core:cobble", prob=254, param2=0},
		{name="vlf_core:cobble", prob=254, param2=0},
		{name="vlf_core:cobble", prob=254, param2=0},
		{name="vlf_core:cobble", prob=254, param2=0},
		{name="air", prob=254, param2=0},
		{name="air", prob=254, param2=0},
		{name="vlf_core:cobble", prob=254, param2=0},
		{name="air", prob=254, param2=0},
		{name="air", prob=254, param2=0},
		{name="air", prob=254, param2=0},
		{name="air", prob=254, param2=0},
		{name="air", prob=254, param2=0},
		{name="vlf_stairs:stair_cobble", prob=254, param2=1},
		{name="air", prob=254, param2=0},
		{name="air", prob=254, param2=0},
		{name="vlf_stairs:stair_cobble", prob=254, param2=3},
		{name="air", prob=254, param2=0},
		{name="air", prob=254, param2=0},
		{name="air", prob=254, param2=0},
		{name="air", prob=254, param2=0},
		{name="air", prob=254, param2=0},
		{name="air", prob=254, param2=0},
		{name="vlf_stairs:slab_cobble_top", prob=254, param2=0},
		{name="vlf_stairs:slab_cobble_top", prob=254, param2=0},
		{name="air", prob=254, param2=0},
		{name="air", prob=254, param2=0},
		{name="air", prob=254, param2=0},
		{name="air", prob=254, param2=0},
		{name="air", prob=254, param2=0},
		{name="air", prob=254, param2=0},
		{name="air", prob=254, param2=0},
		{name="air", prob=254, param2=0},
		{name="air", prob=254, param2=0},
		{name="air", prob=254, param2=0},
		{name="air", prob=254, param2=0},
		{name="vlf_villages:no_paths", prob=254, param2=0},
		{name="vlf_core:cobble", prob=254, param2=0},
		{name="vlf_stairs:stair_cobble", prob=254, param2=2},
		{name="vlf_stairs:stair_cobble", prob=254, param2=2},
		{name="vlf_core:cobble", prob=254, param2=0},
		{name="vlf_core:cobble", prob=254, param2=0},
		{name="vlf_core:cobble", prob=254, param2=0},
		{name="vlf_core:cobble", prob=254, param2=0},
		{name="vlf_villages:no_paths", prob=254, param2=0},
		{name="vlf_villages:no_paths", prob=254, param2=0},
		{name="vlf_walls:brick_6", prob=254, param2=0},
		{name="air", prob=254, param2=0},
		{name="air", prob=254, param2=0},
		{name="vlf_core:brick_block", prob=254, param2=0},
		{name="vlf_stairs:slab_stone_double", prob=254, param2=0},
		{name="vlf_stairs:slab_stone_double", prob=254, param2=0},
		{name="vlf_core:brick_block", prob=254, param2=0},
		{name="vlf_villages:no_paths", prob=254, param2=0},
		{name="air", prob=254, param2=0},
		{name="vlf_walls:brick_0", prob=254, param2=0},
		{name="air", prob=254, param2=0},
		{name="air", prob=254, param2=0},
		{name="vlf_core:brick_block", prob=254, param2=0},
		{name="vlf_stairs:slab_stone", prob=254, param2=0},
		{name="vlf_stairs:slab_stone", prob=254, param2=0},
		{name="vlf_core:brick_block", prob=254, param2=0},
		{name="air", prob=254, param2=0},
		{name="air", prob=254, param2=0},
		{name="vlf_walls:brick_0", prob=254, param2=0},
		{name="air", prob=254, param2=0},
		{name="air", prob=254, param2=0},
		{name="vlf_core:brick_block", prob=254, param2=0},
		{name="vlf_panes:bar_flat", prob=254, param2=2},
		{name="vlf_panes:bar_flat", prob=254, param2=0},
		{name="vlf_core:brick_block", prob=254, param2=0},
		{name="air", prob=254, param2=0},
		{name="air", prob=254, param2=0},
		{name="vlf_core:cobble", prob=254, param2=0},
		{name="vlf_core:cobble", prob=254, param2=0},
		{name="vlf_core:cobble", prob=254, param2=0},
		{name="vlf_core:cobble", prob=254, param2=0},
		{name="vlf_core:cobble", prob=254, param2=0},
		{name="vlf_core:cobble", prob=254, param2=0},
		{name="vlf_core:cobble", prob=254, param2=0},
		{name="air", prob=254, param2=0},
		{name="air", prob=254, param2=0},
		{name="air", prob=254, param2=0},
		{name="air", prob=254, param2=0},
		{name="air", prob=254, param2=0},
		{name="vlf_stairs:stair_cobble_outer", prob=254, param2=2},
		{name="vlf_stairs:stair_cobble", prob=254, param2=2},
		{name="vlf_stairs:stair_cobble", prob=254, param2=2},
		{name="vlf_stairs:stair_cobble_outer", prob=254, param2=3},
		{name="air", prob=254, param2=0},
		{name="air", prob=254, param2=0},
		{name="air", prob=254, param2=0},
		{name="air", prob=254, param2=0},
		{name="air", prob=254, param2=0},
		{name="air", prob=254, param2=0},
		{name="air", prob=254, param2=0},
		{name="air", prob=254, param2=0},
		{name="air", prob=254, param2=0},
		{name="air", prob=254, param2=0},
		{name="air", prob=254, param2=0},
		{name="air", prob=254, param2=0},
		{name="air", prob=254, param2=0},
		{name="air", prob=254, param2=0},
		{name="air", prob=254, param2=0},
		{name="air", prob=254, param2=0},
		{name="air", prob=254, param2=0},
		{name="air", prob=254, param2=0},
		{name="air", prob=254, param2=0},
		{name="vlf_villages:no_paths", prob=254, param2=0},
		{name="vlf_villages:no_paths", prob=254, param2=0},
		{name="vlf_villages:no_paths", prob=254, param2=0},
		{name="vlf_villages:no_paths", prob=254, param2=0},
		{name="vlf_villages:no_paths", prob=254, param2=0},
		{name="vlf_villages:no_paths", prob=254, param2=0},
		{name="vlf_villages:no_paths", prob=254, param2=0},
		{name="vlf_villages:no_paths", prob=254, param2=0},
		{name="vlf_villages:no_paths", prob=254, param2=0},
		{name="vlf_villages:no_paths", prob=254, param2=0},
		{name="vlf_villages:no_paths", prob=254, param2=0},
		{name="vlf_villages:no_paths", prob=254, param2=0},
		{name="vlf_villages:no_paths", prob=254, param2=0},
		{name="vlf_villages:no_paths", prob=254, param2=0},
		{name="vlf_villages:no_paths", prob=254, param2=0},
		{name="vlf_villages:no_paths", prob=254, param2=0},
		{name="vlf_villages:no_paths", prob=254, param2=0},
		{name="vlf_villages:no_paths", prob=254, param2=0},
		{name="air", prob=254, param2=0},
		{name="air", prob=254, param2=0},
		{name="air", prob=254, param2=0},
		{name="air", prob=254, param2=0},
		{name="air", prob=254, param2=0},
		{name="air", prob=254, param2=0},
		{name="air", prob=254, param2=0},
		{name="air", prob=254, param2=0},
		{name="air", prob=254, param2=0},
		{name="air", prob=254, param2=0},
		{name="air", prob=254, param2=0},
		{name="air", prob=254, param2=0},
		{name="air", prob=254, param2=0},
		{name="air", prob=254, param2=0},
		{name="air", prob=254, param2=0},
		{name="air", prob=254, param2=0},
		{name="air", prob=254, param2=0},
		{name="air", prob=254, param2=0},
		{name="air", prob=254, param2=0},
		{name="air", prob=254, param2=0},
		{name="air", prob=254, param2=0},
		{name="air", prob=254, param2=0},
		{name="air", prob=254, param2=0},
		{name="air", prob=254, param2=0},
		{name="air", prob=254, param2=0},
		{name="air", prob=254, param2=0},
		{name="air", prob=254, param2=0},
		{name="air", prob=254, param2=0},
		{name="air", prob=254, param2=0},
		{name="air", prob=254, param2=0},
		{name="air", prob=254, param2=0},
		{name="air", prob=254, param2=0},
		{name="air", prob=254, param2=0},
		{name="air", prob=254, param2=0},
		{name="air", prob=254, param2=0},
		{name="air", prob=254, param2=0},
		{name="air", prob=254, param2=0},
		{name="air", prob=254, param2=0},
		{name="air", prob=254, param2=0},
		{name="air", prob=254, param2=0},
		{name="air", prob=254, param2=0},
		{name="air", prob=254, param2=0},
		{name="air", prob=254, param2=0},
		{name="air", prob=254, param2=0},
		{name="air", prob=254, param2=0},
		{name="air", prob=254, param2=0},
		{name="air", prob=254, param2=0},
		{name="air", prob=254, param2=0},
		{name="air", prob=254, param2=0},
		{name="air", prob=254, param2=0},
		{name="air", prob=254, param2=0},
		{name="air", prob=254, param2=0},
		{name="air", prob=254, param2=0},
		{name="air", prob=254, param2=0},
	},
}
