schematic = {
	size = {x=8, y=9, z=14},
	yslice_prob = {
		{ypos=0, prob=254},
		{ypos=1, prob=254},
		{ypos=2, prob=254},
		{ypos=3, prob=254},
		{ypos=4, prob=254},
		{ypos=5, prob=254},
		{ypos=6, prob=254},
		{ypos=7, prob=254},
		{ypos=8, prob=254},
	},
	data = {
		{name="vlf_villages:no_paths", prob=254, param2=0},
		{name="vlf_villages:no_paths", prob=254, param2=0},
		{name="vlf_villages:no_paths", prob=254, param2=0},
		{name="vlf_villages:no_paths", prob=254, param2=0},
		{name="vlf_villages:no_paths", prob=254, param2=0},
		{name="vlf_villages:no_paths", prob=254, param2=0},
		{name="vlf_villages:no_paths", prob=254, param2=0},
		{name="vlf_villages:no_paths", prob=254, param2=0},
		{name="vlf_villages:no_paths", prob=254, param2=0},
		{name="vlf_villages:no_paths", prob=254, param2=0},
		{name="vlf_villages:no_paths", prob=254, param2=0},
		{name="vlf_villages:no_paths", prob=254, param2=0},
		{name="vlf_villages:no_paths", prob=254, param2=0},
		{name="vlf_villages:no_paths", prob=254, param2=0},
		{name="vlf_villages:no_paths", prob=254, param2=0},
		{name="vlf_villages:no_paths", prob=254, param2=0},
		{name="air", prob=254, param2=0},
		{name="air", prob=254, param2=0},
		{name="air", prob=254, param2=0},
		{name="air", prob=254, param2=0},
		{name="air", prob=254, param2=0},
		{name="air", prob=254, param2=0},
		{name="air", prob=254, param2=0},
		{name="air", prob=254, param2=0},
		{name="air", prob=254, param2=0},
		{name="air", prob=254, param2=0},
		{name="air", prob=254, param2=0},
		{name="air", prob=254, param2=0},
		{name="air", prob=254, param2=0},
		{name="air", prob=254, param2=0},
		{name="air", prob=254, param2=0},
		{name="air", prob=254, param2=0},
		{name="air", prob=254, param2=0},
		{name="air", prob=254, param2=0},
		{name="air", prob=254, param2=0},
		{name="air", prob=254, param2=0},
		{name="air", prob=254, param2=0},
		{name="air", prob=254, param2=0},
		{name="air", prob=254, param2=0},
		{name="air", prob=254, param2=0},
		{name="air", prob=254, param2=0},
		{name="air", prob=254, param2=0},
		{name="air", prob=254, param2=0},
		{name="air", prob=254, param2=0},
		{name="air", prob=254, param2=0},
		{name="air", prob=254, param2=0},
		{name="air", prob=254, param2=0},
		{name="air", prob=254, param2=0},
		{name="air", prob=254, param2=0},
		{name="air", prob=254, param2=0},
		{name="air", prob=254, param2=0},
		{name="air", prob=254, param2=0},
		{name="air", prob=254, param2=0},
		{name="air", prob=254, param2=0},
		{name="air", prob=254, param2=0},
		{name="air", prob=254, param2=0},
		{name="air", prob=254, param2=0},
		{name="air", prob=254, param2=0},
		{name="air", prob=254, param2=0},
		{name="air", prob=254, param2=0},
		{name="air", prob=254, param2=0},
		{name="air", prob=254, param2=0},
		{name="air", prob=254, param2=0},
		{name="air", prob=254, param2=0},
		{name="air", prob=254, param2=0},
		{name="air", prob=254, param2=0},
		{name="air", prob=254, param2=0},
		{name="air", prob=254, param2=0},
		{name="air", prob=254, param2=0},
		{name="air", prob=254, param2=0},
		{name="air", prob=254, param2=0},
		{name="air", prob=254, param2=0},
		{name="vlf_villages:no_paths", prob=254, param2=0},
		{name="vlf_core:cobble", prob=254, param2=0},
		{name="vlf_core:cobble", prob=254, param2=0},
		{name="vlf_core:cobble", prob=254, param2=0},
		{name="vlf_core:cobble", prob=254, param2=0},
		{name="vlf_core:cobble", prob=254, param2=0},
		{name="vlf_core:cobble", prob=254, param2=0},
		{name="vlf_villages:no_paths", prob=254, param2=0},
		{name="vlf_villages:no_paths", prob=254, param2=0},
		{name="vlf_fences:oak_fence", prob=254, param2=0},
		{name="vlf_fences:oak_fence", prob=254, param2=0},
		{name="vlf_fences:oak_fence", prob=254, param2=0},
		{name="vlf_fences:oak_fence", prob=254, param2=0},
		{name="vlf_fences:oak_fence", prob=254, param2=0},
		{name="vlf_fences:oak_fence", prob=254, param2=0},
		{name="vlf_villages:no_paths", prob=254, param2=0},
		{name="air", prob=254, param2=0},
		{name="vlf_torches:torch", prob=254, param2=1},
		{name="air", prob=254, param2=0},
		{name="air", prob=254, param2=0},
		{name="air", prob=254, param2=0},
		{name="air", prob=254, param2=0},
		{name="vlf_torches:torch", prob=254, param2=1},
		{name="air", prob=254, param2=0},
		{name="air", prob=254, param2=0},
		{name="air", prob=254, param2=0},
		{name="air", prob=254, param2=0},
		{name="air", prob=254, param2=0},
		{name="air", prob=254, param2=0},
		{name="air", prob=254, param2=0},
		{name="air", prob=254, param2=0},
		{name="air", prob=254, param2=0},
		{name="air", prob=254, param2=0},
		{name="air", prob=254, param2=0},
		{name="air", prob=254, param2=0},
		{name="air", prob=254, param2=0},
		{name="air", prob=254, param2=0},
		{name="air", prob=254, param2=0},
		{name="air", prob=254, param2=0},
		{name="air", prob=254, param2=0},
		{name="air", prob=254, param2=0},
		{name="air", prob=254, param2=0},
		{name="air", prob=254, param2=0},
		{name="air", prob=254, param2=0},
		{name="air", prob=254, param2=0},
		{name="air", prob=254, param2=0},
		{name="air", prob=254, param2=0},
		{name="air", prob=254, param2=0},
		{name="air", prob=254, param2=0},
		{name="air", prob=254, param2=0},
		{name="air", prob=254, param2=0},
		{name="air", prob=254, param2=0},
		{name="air", prob=254, param2=0},
		{name="air", prob=254, param2=0},
		{name="air", prob=254, param2=0},
		{name="air", prob=254, param2=0},
		{name="air", prob=254, param2=0},
		{name="air", prob=254, param2=0},
		{name="air", prob=254, param2=0},
		{name="air", prob=254, param2=0},
		{name="air", prob=254, param2=0},
		{name="air", prob=254, param2=0},
		{name="air", prob=254, param2=0},
		{name="air", prob=254, param2=0},
		{name="air", prob=254, param2=0},
		{name="air", prob=254, param2=0},
		{name="air", prob=254, param2=0},
		{name="air", prob=254, param2=0},
		{name="air", prob=254, param2=0},
		{name="air", prob=254, param2=0},
		{name="air", prob=254, param2=0},
		{name="air", prob=254, param2=0},
		{name="vlf_villages:no_paths", prob=254, param2=0},
		{name="vlf_core:cobble", prob=254, param2=0},
		{name="vlf_core:dirt_with_grass", prob=254, param2=0},
		{name="vlf_core:dirt_with_grass", prob=254, param2=0},
		{name="vlf_core:dirt_with_grass", prob=254, param2=0},
		{name="vlf_core:dirt_with_grass", prob=254, param2=0},
		{name="vlf_core:cobble", prob=254, param2=0},
		{name="vlf_villages:no_paths", prob=254, param2=0},
		{name="vlf_villages:no_paths", prob=254, param2=0},
		{name="vlf_fences:oak_fence", prob=254, param2=0},
		{name="air", prob=254, param2=0},
		{name="air", prob=254, param2=0},
		{name="air", prob=254, param2=0},
		{name="air", prob=254, param2=0},
		{name="vlf_fences:oak_fence", prob=254, param2=0},
		{name="vlf_villages:no_paths", prob=254, param2=0},
		{name="air", prob=254, param2=0},
		{name="air", prob=254, param2=0},
		{name="air", prob=254, param2=0},
		{name="air", prob=254, param2=0},
		{name="air", prob=254, param2=0},
		{name="air", prob=254, param2=0},
		{name="air", prob=254, param2=0},
		{name="air", prob=254, param2=0},
		{name="air", prob=254, param2=0},
		{name="air", prob=254, param2=0},
		{name="air", prob=254, param2=0},
		{name="air", prob=254, param2=0},
		{name="air", prob=254, param2=0},
		{name="air", prob=254, param2=0},
		{name="air", prob=254, param2=0},
		{name="air", prob=254, param2=0},
		{name="air", prob=254, param2=0},
		{name="air", prob=254, param2=0},
		{name="air", prob=254, param2=0},
		{name="air", prob=254, param2=0},
		{name="air", prob=254, param2=0},
		{name="air", prob=254, param2=0},
		{name="air", prob=254, param2=0},
		{name="air", prob=254, param2=0},
		{name="air", prob=254, param2=0},
		{name="air", prob=254, param2=0},
		{name="air", prob=254, param2=0},
		{name="air", prob=254, param2=0},
		{name="air", prob=254, param2=0},
		{name="air", prob=254, param2=0},
		{name="air", prob=254, param2=0},
		{name="air", prob=254, param2=0},
		{name="air", prob=254, param2=0},
		{name="air", prob=254, param2=0},
		{name="air", prob=254, param2=0},
		{name="air", prob=254, param2=0},
		{name="air", prob=254, param2=0},
		{name="air", prob=254, param2=0},
		{name="air", prob=254, param2=0},
		{name="air", prob=254, param2=0},
		{name="air", prob=254, param2=0},
		{name="air", prob=254, param2=0},
		{name="air", prob=254, param2=0},
		{name="air", prob=254, param2=0},
		{name="air", prob=254, param2=0},
		{name="air", prob=254, param2=0},
		{name="air", prob=254, param2=0},
		{name="air", prob=254, param2=0},
		{name="air", prob=254, param2=0},
		{name="air", prob=254, param2=0},
		{name="air", prob=254, param2=0},
		{name="air", prob=254, param2=0},
		{name="air", prob=254, param2=0},
		{name="air", prob=254, param2=0},
		{name="air", prob=254, param2=0},
		{name="air", prob=254, param2=0},
		{name="vlf_villages:no_paths", prob=254, param2=0},
		{name="vlf_core:cobble", prob=254, param2=0},
		{name="vlf_core:dirt_with_grass", prob=254, param2=0},
		{name="vlf_core:dirt_with_grass", prob=254, param2=0},
		{name="vlf_core:dirt_with_grass", prob=254, param2=0},
		{name="vlf_core:dirt_with_grass", prob=254, param2=0},
		{name="vlf_core:cobble", prob=254, param2=0},
		{name="vlf_villages:no_paths", prob=254, param2=0},
		{name="vlf_villages:no_paths", prob=254, param2=0},
		{name="vlf_fences:oak_fence", prob=254, param2=0},
		{name="air", prob=254, param2=0},
		{name="air", prob=254, param2=0},
		{name="air", prob=254, param2=0},
		{name="air", prob=254, param2=0},
		{name="vlf_fences:oak_fence", prob=254, param2=0},
		{name="vlf_villages:no_paths", prob=254, param2=0},
		{name="air", prob=254, param2=0},
		{name="air", prob=254, param2=0},
		{name="air", prob=254, param2=0},
		{name="air", prob=254, param2=0},
		{name="air", prob=254, param2=0},
		{name="air", prob=254, param2=0},
		{name="air", prob=254, param2=0},
		{name="air", prob=254, param2=0},
		{name="air", prob=254, param2=0},
		{name="air", prob=254, param2=0},
		{name="air", prob=254, param2=0},
		{name="air", prob=254, param2=0},
		{name="air", prob=254, param2=0},
		{name="air", prob=254, param2=0},
		{name="air", prob=254, param2=0},
		{name="air", prob=254, param2=0},
		{name="air", prob=254, param2=0},
		{name="air", prob=254, param2=0},
		{name="air", prob=254, param2=0},
		{name="air", prob=254, param2=0},
		{name="air", prob=254, param2=0},
		{name="air", prob=254, param2=0},
		{name="air", prob=254, param2=0},
		{name="air", prob=254, param2=0},
		{name="air", prob=254, param2=0},
		{name="air", prob=254, param2=0},
		{name="air", prob=254, param2=0},
		{name="air", prob=254, param2=0},
		{name="air", prob=254, param2=0},
		{name="air", prob=254, param2=0},
		{name="air", prob=254, param2=0},
		{name="air", prob=254, param2=0},
		{name="air", prob=254, param2=0},
		{name="air", prob=254, param2=0},
		{name="air", prob=254, param2=0},
		{name="air", prob=254, param2=0},
		{name="air", prob=254, param2=0},
		{name="air", prob=254, param2=0},
		{name="air", prob=254, param2=0},
		{name="air", prob=254, param2=0},
		{name="air", prob=254, param2=0},
		{name="air", prob=254, param2=0},
		{name="air", prob=254, param2=0},
		{name="air", prob=254, param2=0},
		{name="air", prob=254, param2=0},
		{name="air", prob=254, param2=0},
		{name="air", prob=254, param2=0},
		{name="air", prob=254, param2=0},
		{name="air", prob=254, param2=0},
		{name="air", prob=254, param2=0},
		{name="air", prob=254, param2=0},
		{name="air", prob=254, param2=0},
		{name="air", prob=254, param2=0},
		{name="air", prob=254, param2=0},
		{name="air", prob=254, param2=0},
		{name="air", prob=254, param2=0},
		{name="vlf_villages:no_paths", prob=254, param2=0},
		{name="vlf_core:cobble", prob=254, param2=0},
		{name="vlf_core:dirt_with_grass", prob=254, param2=0},
		{name="vlf_core:dirt_with_grass", prob=254, param2=0},
		{name="vlf_core:dirt_with_grass", prob=254, param2=0},
		{name="vlf_core:dirt_with_grass", prob=254, param2=0},
		{name="vlf_core:cobble", prob=254, param2=0},
		{name="vlf_villages:no_paths", prob=254, param2=0},
		{name="vlf_villages:no_paths", prob=254, param2=0},
		{name="vlf_fences:oak_fence", prob=254, param2=0},
		{name="air", prob=254, param2=0},
		{name="air", prob=254, param2=0},
		{name="air", prob=254, param2=0},
		{name="air", prob=254, param2=0},
		{name="vlf_fences:oak_fence", prob=254, param2=0},
		{name="vlf_villages:no_paths", prob=254, param2=0},
		{name="air", prob=254, param2=0},
		{name="air", prob=254, param2=0},
		{name="air", prob=254, param2=0},
		{name="air", prob=254, param2=0},
		{name="air", prob=254, param2=0},
		{name="air", prob=254, param2=0},
		{name="air", prob=254, param2=0},
		{name="air", prob=254, param2=0},
		{name="air", prob=254, param2=0},
		{name="air", prob=254, param2=0},
		{name="air", prob=254, param2=0},
		{name="air", prob=254, param2=0},
		{name="air", prob=254, param2=0},
		{name="air", prob=254, param2=0},
		{name="air", prob=254, param2=0},
		{name="air", prob=254, param2=0},
		{name="air", prob=254, param2=0},
		{name="air", prob=254, param2=0},
		{name="air", prob=254, param2=0},
		{name="air", prob=254, param2=0},
		{name="air", prob=254, param2=0},
		{name="air", prob=254, param2=0},
		{name="air", prob=254, param2=0},
		{name="air", prob=254, param2=0},
		{name="air", prob=254, param2=0},
		{name="air", prob=254, param2=0},
		{name="air", prob=254, param2=0},
		{name="air", prob=254, param2=0},
		{name="air", prob=254, param2=0},
		{name="air", prob=254, param2=0},
		{name="air", prob=254, param2=0},
		{name="air", prob=254, param2=0},
		{name="air", prob=254, param2=0},
		{name="air", prob=254, param2=0},
		{name="air", prob=254, param2=0},
		{name="air", prob=254, param2=0},
		{name="air", prob=254, param2=0},
		{name="air", prob=254, param2=0},
		{name="air", prob=254, param2=0},
		{name="air", prob=254, param2=0},
		{name="air", prob=254, param2=0},
		{name="air", prob=254, param2=0},
		{name="air", prob=254, param2=0},
		{name="air", prob=254, param2=0},
		{name="air", prob=254, param2=0},
		{name="air", prob=254, param2=0},
		{name="air", prob=254, param2=0},
		{name="air", prob=254, param2=0},
		{name="air", prob=254, param2=0},
		{name="air", prob=254, param2=0},
		{name="air", prob=254, param2=0},
		{name="air", prob=254, param2=0},
		{name="air", prob=254, param2=0},
		{name="air", prob=254, param2=0},
		{name="air", prob=254, param2=0},
		{name="air", prob=254, param2=0},
		{name="vlf_villages:no_paths", prob=254, param2=0},
		{name="vlf_core:cobble", prob=254, param2=0},
		{name="vlf_core:dirt_with_grass", prob=254, param2=0},
		{name="vlf_core:dirt_with_grass", prob=254, param2=0},
		{name="vlf_core:dirt_with_grass", prob=254, param2=0},
		{name="vlf_core:dirt_with_grass", prob=254, param2=0},
		{name="vlf_core:cobble", prob=254, param2=0},
		{name="vlf_villages:no_paths", prob=254, param2=0},
		{name="vlf_villages:no_paths", prob=254, param2=0},
		{name="vlf_fences:oak_fence", prob=254, param2=0},
		{name="air", prob=254, param2=0},
		{name="air", prob=254, param2=0},
		{name="air", prob=254, param2=0},
		{name="air", prob=254, param2=0},
		{name="vlf_fences:oak_fence", prob=254, param2=0},
		{name="vlf_villages:no_paths", prob=254, param2=0},
		{name="air", prob=254, param2=0},
		{name="air", prob=254, param2=0},
		{name="air", prob=254, param2=0},
		{name="air", prob=254, param2=0},
		{name="air", prob=254, param2=0},
		{name="air", prob=254, param2=0},
		{name="air", prob=254, param2=0},
		{name="air", prob=254, param2=0},
		{name="air", prob=254, param2=0},
		{name="vlf_torches:torch_wall", prob=254, param2=4},
		{name="air", prob=254, param2=0},
		{name="air", prob=254, param2=0},
		{name="air", prob=254, param2=0},
		{name="air", prob=254, param2=0},
		{name="vlf_torches:torch_wall", prob=254, param2=4},
		{name="air", prob=254, param2=0},
		{name="air", prob=254, param2=0},
		{name="air", prob=254, param2=0},
		{name="air", prob=254, param2=0},
		{name="air", prob=254, param2=0},
		{name="air", prob=254, param2=0},
		{name="air", prob=254, param2=0},
		{name="air", prob=254, param2=0},
		{name="air", prob=254, param2=0},
		{name="air", prob=254, param2=0},
		{name="air", prob=254, param2=0},
		{name="air", prob=254, param2=0},
		{name="air", prob=254, param2=0},
		{name="air", prob=254, param2=0},
		{name="air", prob=254, param2=0},
		{name="air", prob=254, param2=0},
		{name="air", prob=254, param2=0},
		{name="air", prob=254, param2=0},
		{name="air", prob=254, param2=0},
		{name="air", prob=254, param2=0},
		{name="air", prob=254, param2=0},
		{name="air", prob=254, param2=0},
		{name="air", prob=254, param2=0},
		{name="air", prob=254, param2=0},
		{name="air", prob=254, param2=0},
		{name="air", prob=254, param2=0},
		{name="air", prob=254, param2=0},
		{name="air", prob=254, param2=0},
		{name="air", prob=254, param2=0},
		{name="air", prob=254, param2=0},
		{name="air", prob=254, param2=0},
		{name="air", prob=254, param2=0},
		{name="air", prob=254, param2=0},
		{name="air", prob=254, param2=0},
		{name="air", prob=254, param2=0},
		{name="air", prob=254, param2=0},
		{name="air", prob=254, param2=0},
		{name="air", prob=254, param2=0},
		{name="air", prob=254, param2=0},
		{name="air", prob=254, param2=0},
		{name="air", prob=254, param2=0},
		{name="vlf_villages:no_paths", prob=254, param2=0},
		{name="vlf_core:cobble", prob=254, param2=0},
		{name="vlf_core:cobble", prob=254, param2=0},
		{name="vlf_core:cobble", prob=254, param2=0},
		{name="vlf_core:cobble", prob=254, param2=0},
		{name="vlf_core:cobble", prob=254, param2=0},
		{name="vlf_core:cobble", prob=254, param2=0},
		{name="vlf_villages:no_paths", prob=254, param2=0},
		{name="vlf_villages:no_paths", prob=254, param2=0},
		{name="vlf_core:cobble", prob=254, param2=0},
		{name="vlf_fences:oak_fence_gate", prob=254, param2=2},
		{name="vlf_trees:wood_oak", prob=254, param2=0},
		{name="vlf_trees:wood_oak", prob=254, param2=0},
		{name="vlf_trees:wood_oak", prob=254, param2=0},
		{name="vlf_core:cobble", prob=254, param2=0},
		{name="vlf_villages:no_paths", prob=254, param2=0},
		{name="air", prob=254, param2=0},
		{name="vlf_core:cobble", prob=254, param2=0},
		{name="air", prob=254, param2=0},
		{name="vlf_trees:wood_oak", prob=254, param2=0},
		{name="vlf_panes:pane_natural_flat", prob=254, param2=2},
		{name="vlf_panes:pane_natural_flat", prob=254, param2=0},
		{name="vlf_core:cobble", prob=254, param2=0},
		{name="air", prob=254, param2=0},
		{name="air", prob=254, param2=0},
		{name="vlf_core:cobble", prob=254, param2=0},
		{name="vlf_trees:wood_oak", prob=254, param2=0},
		{name="vlf_trees:wood_oak", prob=254, param2=0},
		{name="vlf_trees:wood_oak", prob=254, param2=0},
		{name="vlf_trees:wood_oak", prob=254, param2=0},
		{name="vlf_core:cobble", prob=254, param2=0},
		{name="air", prob=254, param2=0},
		{name="air", prob=254, param2=0},
		{name="vlf_trees:tree_oak", prob=254, param2=3},
		{name="vlf_panes:bar_flat", prob=254, param2=2},
		{name="vlf_panes:bar_flat", prob=254, param2=2},
		{name="vlf_panes:bar_flat", prob=254, param2=2},
		{name="vlf_panes:bar_flat", prob=254, param2=2},
		{name="vlf_trees:tree_oak", prob=254, param2=3},
		{name="air", prob=254, param2=0},
		{name="air", prob=254, param2=0},
		{name="vlf_stairs:stair_oak_outer", prob=254, param2=1},
		{name="vlf_stairs:stair_oak", prob=254, param2=0},
		{name="vlf_stairs:stair_oak", prob=254, param2=0},
		{name="vlf_stairs:stair_oak", prob=254, param2=0},
		{name="vlf_stairs:stair_oak", prob=254, param2=0},
		{name="vlf_stairs:stair_oak_outer", prob=254, param2=0},
		{name="air", prob=254, param2=0},
		{name="air", prob=254, param2=0},
		{name="air", prob=254, param2=0},
		{name="vlf_stairs:stair_oak", prob=254, param2=20},
		{name="vlf_stairs:stair_oak", prob=254, param2=20},
		{name="vlf_stairs:stair_oak", prob=254, param2=20},
		{name="vlf_stairs:stair_oak", prob=254, param2=20},
		{name="air", prob=254, param2=0},
		{name="air", prob=254, param2=0},
		{name="air", prob=254, param2=0},
		{name="air", prob=254, param2=0},
		{name="air", prob=254, param2=0},
		{name="air", prob=254, param2=0},
		{name="air", prob=254, param2=0},
		{name="air", prob=254, param2=0},
		{name="air", prob=254, param2=0},
		{name="air", prob=254, param2=0},
		{name="air", prob=254, param2=0},
		{name="air", prob=254, param2=0},
		{name="air", prob=254, param2=0},
		{name="air", prob=254, param2=0},
		{name="air", prob=254, param2=0},
		{name="air", prob=254, param2=0},
		{name="air", prob=254, param2=0},
		{name="air", prob=254, param2=0},
		{name="vlf_villages:no_paths", prob=254, param2=0},
		{name="vlf_core:cobble", prob=254, param2=0},
		{name="vlf_core:cobble", prob=254, param2=0},
		{name="vlf_core:cobble", prob=254, param2=0},
		{name="vlf_core:cobble", prob=254, param2=0},
		{name="vlf_core:cobble", prob=254, param2=0},
		{name="vlf_core:cobble", prob=254, param2=0},
		{name="vlf_villages:no_paths", prob=254, param2=0},
		{name="vlf_villages:no_paths", prob=254, param2=0},
		{name="vlf_trees:wood_oak", prob=254, param2=0},
		{name="air", prob=254, param2=0},
		{name="air", prob=254, param2=0},
		{name="vlf_smoker:smoker", prob=254, param2=1},
		{name="vlf_fences:oak_fence", prob=254, param2=0},
		{name="vlf_trees:wood_oak", prob=254, param2=0},
		{name="vlf_villages:no_paths", prob=254, param2=0},
		{name="air", prob=254, param2=0},
		{name="vlf_trees:wood_oak", prob=254, param2=0},
		{name="air", prob=254, param2=0},
		{name="air", prob=254, param2=0},
		{name="air", prob=254, param2=0},
		{name="mesecons_pressureplates:pressure_plate_oak_off", prob=254, param2=0},
		{name="vlf_trees:wood_oak", prob=254, param2=0},
		{name="air", prob=254, param2=0},
		{name="air", prob=254, param2=0},
		{name="vlf_trees:wood_oak", prob=254, param2=0},
		{name="air", prob=254, param2=0},
		{name="air", prob=254, param2=0},
		{name="vlf_itemframes:frame", prob=254, param2=5},
		{name="air", prob=254, param2=0},
		{name="vlf_trees:wood_oak", prob=254, param2=0},
		{name="air", prob=254, param2=0},
		{name="air", prob=254, param2=0},
		{name="vlf_panes:bar_flat", prob=254, param2=3},
		{name="vlf_stairs:slab_stone", prob=254, param2=0},
		{name="vlf_stairs:slab_stone", prob=254, param2=0},
		{name="vlf_stairs:slab_stone", prob=254, param2=0},
		{name="vlf_stairs:slab_stone", prob=254, param2=0},
		{name="vlf_panes:bar_flat", prob=254, param2=3},
		{name="air", prob=254, param2=0},
		{name="air", prob=254, param2=0},
		{name="vlf_stairs:stair_oak", prob=254, param2=1},
		{name="air", prob=254, param2=0},
		{name="air", prob=254, param2=0},
		{name="air", prob=254, param2=0},
		{name="air", prob=254, param2=0},
		{name="vlf_stairs:stair_oak", prob=254, param2=3},
		{name="air", prob=254, param2=0},
		{name="air", prob=254, param2=0},
		{name="vlf_stairs:stair_oak", prob=254, param2=23},
		{name="air", prob=254, param2=0},
		{name="vlf_itemframes:frame", prob=254, param2=2},
		{name="air", prob=254, param2=0},
		{name="air", prob=254, param2=0},
		{name="vlf_stairs:stair_oak", prob=254, param2=21},
		{name="air", prob=254, param2=0},
		{name="air", prob=254, param2=0},
		{name="air", prob=254, param2=0},
		{name="vlf_core:cobble", prob=254, param2=0},
		{name="vlf_core:cobble", prob=254, param2=0},
		{name="vlf_core:cobble", prob=254, param2=0},
		{name="vlf_core:cobble", prob=254, param2=0},
		{name="air", prob=254, param2=0},
		{name="air", prob=254, param2=0},
		{name="air", prob=254, param2=0},
		{name="air", prob=254, param2=0},
		{name="air", prob=254, param2=0},
		{name="air", prob=254, param2=0},
		{name="air", prob=254, param2=0},
		{name="air", prob=254, param2=0},
		{name="air", prob=254, param2=0},
		{name="air", prob=254, param2=0},
		{name="vlf_villages:no_paths", prob=254, param2=0},
		{name="vlf_core:cobble", prob=254, param2=0},
		{name="vlf_core:cobble", prob=254, param2=0},
		{name="vlf_core:stonebrickcarved", prob=254, param2=0},
		{name="vlf_core:cobble", prob=254, param2=0},
		{name="vlf_core:cobble", prob=254, param2=0},
		{name="vlf_core:cobble", prob=254, param2=0},
		{name="vlf_villages:no_paths", prob=254, param2=0},
		{name="vlf_villages:no_paths", prob=254, param2=0},
		{name="vlf_trees:wood_oak", prob=254, param2=0},
		{name="air", prob=254, param2=0},
		{name="air", prob=254, param2=0},
		{name="air", prob=254, param2=0},
		{name="air", prob=254, param2=0},
		{name="vlf_trees:wood_oak", prob=254, param2=0},
		{name="vlf_villages:no_paths", prob=254, param2=0},
		{name="air", prob=254, param2=0},
		{name="vlf_panes:pane_natural_flat", prob=254, param2=3},
		{name="air", prob=254, param2=0},
		{name="air", prob=254, param2=0},
		{name="air", prob=254, param2=0},
		{name="air", prob=254, param2=0},
		{name="vlf_panes:pane_natural_flat", prob=254, param2=3},
		{name="air", prob=254, param2=0},
		{name="air", prob=254, param2=0},
		{name="vlf_trees:wood_oak", prob=254, param2=0},
		{name="air", prob=254, param2=0},
		{name="air", prob=254, param2=0},
		{name="air", prob=254, param2=0},
		{name="vlf_itemframes:frame", prob=254, param2=2},
		{name="vlf_trees:wood_oak", prob=254, param2=0},
		{name="air", prob=254, param2=0},
		{name="air", prob=254, param2=0},
		{name="vlf_panes:bar_flat", prob=254, param2=3},
		{name="vlf_stairs:slab_stone", prob=254, param2=0},
		{name="vlf_stairs:slab_stone", prob=254, param2=0},
		{name="vlf_stairs:slab_stone", prob=254, param2=0},
		{name="vlf_stairs:slab_stone", prob=254, param2=0},
		{name="vlf_panes:bar_flat", prob=254, param2=3},
		{name="air", prob=254, param2=0},
		{name="air", prob=254, param2=0},
		{name="vlf_stairs:stair_oak", prob=254, param2=1},
		{name="air", prob=254, param2=0},
		{name="air", prob=254, param2=0},
		{name="air", prob=254, param2=0},
		{name="air", prob=254, param2=0},
		{name="vlf_stairs:stair_oak", prob=254, param2=3},
		{name="air", prob=254, param2=0},
		{name="air", prob=254, param2=0},
		{name="vlf_stairs:stair_oak", prob=254, param2=23},
		{name="air", prob=254, param2=0},
		{name="air", prob=254, param2=0},
		{name="air", prob=254, param2=0},
		{name="air", prob=254, param2=0},
		{name="vlf_stairs:stair_oak", prob=254, param2=21},
		{name="air", prob=254, param2=0},
		{name="air", prob=254, param2=0},
		{name="air", prob=254, param2=0},
		{name="vlf_core:cobble", prob=254, param2=0},
		{name="vlf_core:cobble", prob=254, param2=0},
		{name="vlf_core:cobble", prob=254, param2=0},
		{name="vlf_core:cobble", prob=254, param2=0},
		{name="air", prob=254, param2=0},
		{name="air", prob=254, param2=0},
		{name="air", prob=254, param2=0},
		{name="air", prob=254, param2=0},
		{name="air", prob=254, param2=0},
		{name="air", prob=254, param2=0},
		{name="air", prob=254, param2=0},
		{name="air", prob=254, param2=0},
		{name="air", prob=254, param2=0},
		{name="air", prob=254, param2=0},
		{name="vlf_villages:no_paths", prob=254, param2=0},
		{name="vlf_core:cobble", prob=254, param2=0},
		{name="vlf_core:cobble", prob=254, param2=0},
		{name="vlf_core:cobble", prob=254, param2=0},
		{name="vlf_core:cobble", prob=254, param2=0},
		{name="vlf_core:cobble", prob=254, param2=0},
		{name="vlf_core:cobble", prob=254, param2=0},
		{name="vlf_villages:no_paths", prob=254, param2=0},
		{name="vlf_villages:no_paths", prob=254, param2=0},
		{name="vlf_trees:wood_oak", prob=254, param2=0},
		{name="vlf_core:ladder", prob=254, param2=3},
		{name="air", prob=254, param2=0},
		{name="vlf_stairs:stair_oak", prob=254, param2=0},
		{name="vlf_stairs:stair_oak", prob=254, param2=0},
		{name="vlf_trees:wood_oak", prob=254, param2=0},
		{name="vlf_villages:no_paths", prob=254, param2=0},
		{name="air", prob=254, param2=0},
		{name="vlf_trees:wood_oak", prob=254, param2=0},
		{name="vlf_core:ladder", prob=254, param2=3},
		{name="air", prob=254, param2=0},
		{name="air", prob=254, param2=0},
		{name="air", prob=254, param2=0},
		{name="vlf_trees:wood_oak", prob=254, param2=0},
		{name="air", prob=254, param2=0},
		{name="air", prob=254, param2=0},
		{name="vlf_trees:wood_oak", prob=254, param2=0},
		{name="vlf_core:ladder", prob=254, param2=3},
		{name="air", prob=254, param2=0},
		{name="vlf_itemframes:frame", prob=254, param2=4},
		{name="air", prob=254, param2=0},
		{name="vlf_trees:wood_oak", prob=254, param2=0},
		{name="air", prob=254, param2=0},
		{name="air", prob=254, param2=0},
		{name="vlf_panes:bar_flat", prob=254, param2=3},
		{name="vlf_core:ladder", prob=254, param2=3},
		{name="vlf_stairs:slab_stone", prob=254, param2=0},
		{name="vlf_stairs:slab_stone", prob=254, param2=0},
		{name="vlf_stairs:slab_stone", prob=254, param2=0},
		{name="vlf_panes:bar_flat", prob=254, param2=3},
		{name="air", prob=254, param2=0},
		{name="air", prob=254, param2=0},
		{name="vlf_stairs:stair_oak", prob=254, param2=1},
		{name="vlf_core:ladder", prob=254, param2=3},
		{name="air", prob=254, param2=0},
		{name="air", prob=254, param2=0},
		{name="air", prob=254, param2=0},
		{name="vlf_stairs:stair_oak", prob=254, param2=3},
		{name="air", prob=254, param2=0},
		{name="air", prob=254, param2=0},
		{name="vlf_stairs:stair_oak", prob=254, param2=23},
		{name="air", prob=254, param2=0},
		{name="air", prob=254, param2=0},
		{name="air", prob=254, param2=0},
		{name="air", prob=254, param2=0},
		{name="vlf_stairs:stair_oak", prob=254, param2=21},
		{name="air", prob=254, param2=0},
		{name="air", prob=254, param2=0},
		{name="air", prob=254, param2=0},
		{name="vlf_core:cobble", prob=254, param2=0},
		{name="vlf_core:cobble", prob=254, param2=0},
		{name="vlf_core:cobble", prob=254, param2=0},
		{name="vlf_core:cobble", prob=254, param2=0},
		{name="air", prob=254, param2=0},
		{name="air", prob=254, param2=0},
		{name="air", prob=254, param2=0},
		{name="air", prob=254, param2=0},
		{name="air", prob=254, param2=0},
		{name="air", prob=254, param2=0},
		{name="air", prob=254, param2=0},
		{name="air", prob=254, param2=0},
		{name="air", prob=254, param2=0},
		{name="air", prob=254, param2=0},
		{name="vlf_villages:no_paths", prob=254, param2=0},
		{name="vlf_core:cobble", prob=254, param2=0},
		{name="vlf_core:cobble", prob=254, param2=0},
		{name="vlf_core:cobble", prob=254, param2=0},
		{name="vlf_core:cobble", prob=254, param2=0},
		{name="vlf_core:cobble", prob=254, param2=0},
		{name="vlf_core:cobble", prob=254, param2=0},
		{name="vlf_villages:no_paths", prob=254, param2=0},
		{name="vlf_villages:no_paths", prob=254, param2=0},
		{name="vlf_core:cobble", prob=254, param2=0},
		{name="vlf_trees:wood_oak", prob=254, param2=0},
		{name="vlf_doors:door_oak_b_1", prob=254, param2=2},
		{name="vlf_trees:wood_oak", prob=254, param2=0},
		{name="vlf_trees:wood_oak", prob=254, param2=0},
		{name="vlf_core:cobble", prob=254, param2=0},
		{name="vlf_villages:no_paths", prob=254, param2=0},
		{name="air", prob=254, param2=0},
		{name="vlf_core:cobble", prob=254, param2=0},
		{name="vlf_trees:wood_oak", prob=254, param2=0},
		{name="vlf_doors:door_oak_t_1", prob=254, param2=2},
		{name="vlf_trees:wood_oak", prob=254, param2=0},
		{name="vlf_trees:wood_oak", prob=254, param2=0},
		{name="vlf_core:cobble", prob=254, param2=0},
		{name="air", prob=254, param2=0},
		{name="air", prob=254, param2=0},
		{name="vlf_core:cobble", prob=254, param2=0},
		{name="vlf_trees:wood_oak", prob=254, param2=0},
		{name="air", prob=254, param2=0},
		{name="vlf_trees:wood_oak", prob=254, param2=0},
		{name="vlf_trees:wood_oak", prob=254, param2=0},
		{name="vlf_core:cobble", prob=254, param2=0},
		{name="air", prob=254, param2=0},
		{name="air", prob=254, param2=0},
		{name="vlf_trees:tree_oak", prob=254, param2=3},
		{name="vlf_panes:bar_flat", prob=254, param2=2},
		{name="vlf_panes:bar_flat", prob=254, param2=2},
		{name="vlf_panes:bar_flat", prob=254, param2=2},
		{name="vlf_panes:bar_flat", prob=254, param2=2},
		{name="vlf_trees:tree_oak", prob=254, param2=3},
		{name="air", prob=254, param2=0},
		{name="air", prob=254, param2=0},
		{name="vlf_stairs:stair_oak_outer", prob=254, param2=2},
		{name="vlf_stairs:stair_oak", prob=254, param2=2},
		{name="vlf_stairs:stair_oak", prob=254, param2=2},
		{name="vlf_stairs:stair_oak", prob=254, param2=2},
		{name="vlf_stairs:stair_oak", prob=254, param2=2},
		{name="vlf_stairs:stair_oak_outer", prob=254, param2=3},
		{name="air", prob=254, param2=0},
		{name="air", prob=254, param2=0},
		{name="air", prob=254, param2=0},
		{name="vlf_stairs:stair_oak", prob=254, param2=22},
		{name="vlf_stairs:stair_oak", prob=254, param2=22},
		{name="vlf_stairs:stair_oak", prob=254, param2=22},
		{name="vlf_stairs:stair_oak", prob=254, param2=22},
		{name="air", prob=254, param2=0},
		{name="air", prob=254, param2=0},
		{name="air", prob=254, param2=0},
		{name="air", prob=254, param2=0},
		{name="air", prob=254, param2=0},
		{name="air", prob=254, param2=0},
		{name="air", prob=254, param2=0},
		{name="air", prob=254, param2=0},
		{name="air", prob=254, param2=0},
		{name="air", prob=254, param2=0},
		{name="air", prob=254, param2=0},
		{name="air", prob=254, param2=0},
		{name="air", prob=254, param2=0},
		{name="air", prob=254, param2=0},
		{name="air", prob=254, param2=0},
		{name="air", prob=254, param2=0},
		{name="air", prob=254, param2=0},
		{name="air", prob=254, param2=0},
		{name="vlf_villages:no_paths", prob=254, param2=0},
		{name="vlf_stairs:stair_cobble", prob=254, param2=1},
		{name="vlf_core:cobble", prob=254, param2=0},
		{name="vlf_core:cobble", prob=254, param2=0},
		{name="vlf_core:cobble", prob=254, param2=0},
		{name="vlf_stairs:stair_cobble", prob=254, param2=3},
		{name="vlf_villages:no_paths", prob=254, param2=0},
		{name="vlf_villages:no_paths", prob=254, param2=0},
		{name="vlf_villages:no_paths", prob=254, param2=0},
		{name="air", prob=254, param2=0},
		{name="air", prob=254, param2=0},
		{name="air", prob=254, param2=0},
		{name="air", prob=254, param2=0},
		{name="air", prob=254, param2=0},
		{name="air", prob=254, param2=0},
		{name="vlf_villages:no_paths", prob=254, param2=0},
		{name="air", prob=254, param2=0},
		{name="vlf_torches:torch_wall", prob=254, param2=5},
		{name="vlf_itemframes:frame", prob=254, param2=5},
		{name="air", prob=254, param2=0},
		{name="vlf_itemframes:frame", prob=254, param2=5},
		{name="vlf_itemframes:frame", prob=254, param2=5},
		{name="vlf_torches:torch_wall", prob=254, param2=5},
		{name="air", prob=254, param2=0},
		{name="air", prob=254, param2=0},
		{name="air", prob=254, param2=0},
		{name="air", prob=254, param2=0},
		{name="vlf_doors:trapdoor_open", prob=254, param2=22},
		{name="air", prob=254, param2=0},
		{name="air", prob=254, param2=0},
		{name="air", prob=254, param2=0},
		{name="air", prob=254, param2=0},
		{name="air", prob=254, param2=0},
		{name="air", prob=254, param2=0},
		{name="air", prob=254, param2=0},
		{name="air", prob=254, param2=0},
		{name="air", prob=254, param2=0},
		{name="air", prob=254, param2=0},
		{name="air", prob=254, param2=0},
		{name="air", prob=254, param2=0},
		{name="air", prob=254, param2=0},
		{name="air", prob=254, param2=0},
		{name="air", prob=254, param2=0},
		{name="air", prob=254, param2=0},
		{name="air", prob=254, param2=0},
		{name="air", prob=254, param2=0},
		{name="air", prob=254, param2=0},
		{name="air", prob=254, param2=0},
		{name="air", prob=254, param2=0},
		{name="air", prob=254, param2=0},
		{name="air", prob=254, param2=0},
		{name="air", prob=254, param2=0},
		{name="air", prob=254, param2=0},
		{name="air", prob=254, param2=0},
		{name="air", prob=254, param2=0},
		{name="air", prob=254, param2=0},
		{name="air", prob=254, param2=0},
		{name="air", prob=254, param2=0},
		{name="air", prob=254, param2=0},
		{name="air", prob=254, param2=0},
		{name="air", prob=254, param2=0},
		{name="air", prob=254, param2=0},
		{name="air", prob=254, param2=0},
		{name="air", prob=254, param2=0},
		{name="air", prob=254, param2=0},
		{name="air", prob=254, param2=0},
		{name="air", prob=254, param2=0},
		{name="air", prob=254, param2=0},
		{name="air", prob=254, param2=0},
		{name="air", prob=254, param2=0},
		{name="air", prob=254, param2=0},
		{name="air", prob=254, param2=0},
		{name="vlf_villages:no_paths", prob=254, param2=0},
		{name="vlf_stairs:stair_cobble_outer", prob=254, param2=2},
		{name="vlf_stairs:stair_cobble", prob=254, param2=2},
		{name="vlf_stairs:stair_cobble", prob=254, param2=2},
		{name="vlf_stairs:stair_cobble", prob=254, param2=2},
		{name="vlf_stairs:stair_cobble_outer", prob=254, param2=3},
		{name="vlf_villages:no_paths", prob=254, param2=0},
		{name="vlf_villages:no_paths", prob=254, param2=0},
		{name="vlf_villages:no_paths", prob=254, param2=0},
		{name="air", prob=254, param2=0},
		{name="vlf_villages:no_paths", prob=254, param2=0},
		{name="vlf_villages:no_paths", prob=254, param2=0},
		{name="vlf_villages:no_paths", prob=254, param2=0},
		{name="air", prob=254, param2=0},
		{name="air", prob=254, param2=0},
		{name="vlf_villages:no_paths", prob=254, param2=0},
		{name="air", prob=254, param2=0},
		{name="air", prob=254, param2=0},
		{name="air", prob=254, param2=0},
		{name="air", prob=254, param2=0},
		{name="air", prob=254, param2=0},
		{name="air", prob=254, param2=0},
		{name="air", prob=254, param2=0},
		{name="air", prob=254, param2=0},
		{name="air", prob=254, param2=0},
		{name="air", prob=254, param2=0},
		{name="air", prob=254, param2=0},
		{name="air", prob=254, param2=0},
		{name="air", prob=254, param2=0},
		{name="air", prob=254, param2=0},
		{name="air", prob=254, param2=0},
		{name="air", prob=254, param2=0},
		{name="air", prob=254, param2=0},
		{name="air", prob=254, param2=0},
		{name="air", prob=254, param2=0},
		{name="air", prob=254, param2=0},
		{name="air", prob=254, param2=0},
		{name="air", prob=254, param2=0},
		{name="air", prob=254, param2=0},
		{name="air", prob=254, param2=0},
		{name="air", prob=254, param2=0},
		{name="air", prob=254, param2=0},
		{name="air", prob=254, param2=0},
		{name="air", prob=254, param2=0},
		{name="air", prob=254, param2=0},
		{name="air", prob=254, param2=0},
		{name="air", prob=254, param2=0},
		{name="air", prob=254, param2=0},
		{name="air", prob=254, param2=0},
		{name="air", prob=254, param2=0},
		{name="air", prob=254, param2=0},
		{name="air", prob=254, param2=0},
		{name="air", prob=254, param2=0},
		{name="air", prob=254, param2=0},
		{name="air", prob=254, param2=0},
		{name="air", prob=254, param2=0},
		{name="air", prob=254, param2=0},
		{name="air", prob=254, param2=0},
		{name="air", prob=254, param2=0},
		{name="air", prob=254, param2=0},
		{name="air", prob=254, param2=0},
		{name="air", prob=254, param2=0},
		{name="air", prob=254, param2=0},
		{name="air", prob=254, param2=0},
		{name="air", prob=254, param2=0},
		{name="air", prob=254, param2=0},
		{name="air", prob=254, param2=0},
		{name="air", prob=254, param2=0},
		{name="air", prob=254, param2=0},
		{name="air", prob=254, param2=0},
		{name="air", prob=254, param2=0},
		{name="air", prob=254, param2=0},
		{name="vlf_villages:no_paths", prob=254, param2=0},
		{name="vlf_villages:no_paths", prob=254, param2=0},
		{name="vlf_villages:no_paths", prob=254, param2=0},
		{name="vlf_villages:path_endpoint", prob=254, param2=0},
		{name="vlf_villages:no_paths", prob=254, param2=0},
		{name="vlf_villages:no_paths", prob=254, param2=0},
		{name="vlf_villages:no_paths", prob=254, param2=0},
		{name="vlf_villages:no_paths", prob=254, param2=0},
		{name="vlf_villages:no_paths", prob=254, param2=0},
		{name="vlf_villages:no_paths", prob=254, param2=0},
		{name="vlf_villages:no_paths", prob=254, param2=0},
		{name="vlf_villages:no_paths", prob=254, param2=0},
		{name="vlf_villages:no_paths", prob=254, param2=0},
		{name="vlf_villages:no_paths", prob=254, param2=0},
		{name="vlf_villages:no_paths", prob=254, param2=0},
		{name="vlf_villages:no_paths", prob=254, param2=0},
		{name="air", prob=254, param2=0},
		{name="air", prob=254, param2=0},
		{name="air", prob=254, param2=0},
		{name="air", prob=254, param2=0},
		{name="air", prob=254, param2=0},
		{name="air", prob=254, param2=0},
		{name="air", prob=254, param2=0},
		{name="air", prob=254, param2=0},
		{name="air", prob=254, param2=0},
		{name="air", prob=254, param2=0},
		{name="air", prob=254, param2=0},
		{name="air", prob=254, param2=0},
		{name="air", prob=254, param2=0},
		{name="air", prob=254, param2=0},
		{name="air", prob=254, param2=0},
		{name="air", prob=254, param2=0},
		{name="air", prob=254, param2=0},
		{name="air", prob=254, param2=0},
		{name="air", prob=254, param2=0},
		{name="air", prob=254, param2=0},
		{name="air", prob=254, param2=0},
		{name="air", prob=254, param2=0},
		{name="air", prob=254, param2=0},
		{name="air", prob=254, param2=0},
		{name="air", prob=254, param2=0},
		{name="air", prob=254, param2=0},
		{name="air", prob=254, param2=0},
		{name="air", prob=254, param2=0},
		{name="air", prob=254, param2=0},
		{name="air", prob=254, param2=0},
		{name="air", prob=254, param2=0},
		{name="air", prob=254, param2=0},
		{name="air", prob=254, param2=0},
		{name="air", prob=254, param2=0},
		{name="air", prob=254, param2=0},
		{name="air", prob=254, param2=0},
		{name="air", prob=254, param2=0},
		{name="air", prob=254, param2=0},
		{name="air", prob=254, param2=0},
		{name="air", prob=254, param2=0},
		{name="air", prob=254, param2=0},
		{name="air", prob=254, param2=0},
		{name="air", prob=254, param2=0},
		{name="air", prob=254, param2=0},
		{name="air", prob=254, param2=0},
		{name="air", prob=254, param2=0},
		{name="air", prob=254, param2=0},
		{name="air", prob=254, param2=0},
		{name="air", prob=254, param2=0},
		{name="air", prob=254, param2=0},
		{name="air", prob=254, param2=0},
		{name="air", prob=254, param2=0},
		{name="air", prob=254, param2=0},
		{name="air", prob=254, param2=0},
		{name="air", prob=254, param2=0},
		{name="air", prob=254, param2=0},
	},
}
