schematic = {
	size = {x=13, y=4, z=13},
	yslice_prob = {
		{ypos=0, prob=254},
		{ypos=1, prob=254},
		{ypos=2, prob=254},
		{ypos=3, prob=254},
	},
	data = {
		{name="vlf_villages:no_paths", prob=254, param2=0},
		{name="vlf_villages:no_paths", prob=254, param2=0},
		{name="vlf_villages:no_paths", prob=254, param2=0},
		{name="vlf_villages:no_paths", prob=254, param2=0},
		{name="vlf_villages:no_paths", prob=254, param2=0},
		{name="vlf_villages:no_paths", prob=254, param2=0},
		{name="vlf_villages:no_paths", prob=254, param2=0},
		{name="vlf_villages:no_paths", prob=254, param2=0},
		{name="vlf_villages:no_paths", prob=254, param2=0},
		{name="vlf_villages:no_paths", prob=254, param2=0},
		{name="vlf_villages:no_paths", prob=254, param2=0},
		{name="vlf_villages:no_paths", prob=254, param2=0},
		{name="vlf_villages:no_paths", prob=254, param2=0},
		{name="vlf_villages:no_paths", prob=254, param2=0},
		{name="vlf_villages:no_paths", prob=254, param2=0},
		{name="vlf_villages:no_paths", prob=254, param2=0},
		{name="vlf_villages:no_paths", prob=254, param2=0},
		{name="vlf_villages:no_paths", prob=254, param2=0},
		{name="vlf_villages:no_paths", prob=254, param2=0},
		{name="vlf_villages:no_paths", prob=254, param2=0},
		{name="vlf_villages:no_paths", prob=254, param2=0},
		{name="vlf_villages:no_paths", prob=254, param2=0},
		{name="vlf_villages:no_paths", prob=254, param2=0},
		{name="vlf_villages:no_paths", prob=254, param2=0},
		{name="vlf_villages:no_paths", prob=254, param2=0},
		{name="vlf_villages:no_paths", prob=254, param2=0},
		{name="air", prob=254, param2=0},
		{name="air", prob=254, param2=0},
		{name="air", prob=254, param2=0},
		{name="air", prob=254, param2=0},
		{name="air", prob=254, param2=0},
		{name="air", prob=254, param2=0},
		{name="air", prob=254, param2=0},
		{name="air", prob=254, param2=0},
		{name="air", prob=254, param2=0},
		{name="air", prob=254, param2=0},
		{name="air", prob=254, param2=0},
		{name="air", prob=254, param2=0},
		{name="air", prob=254, param2=0},
		{name="air", prob=254, param2=0},
		{name="air", prob=254, param2=0},
		{name="air", prob=254, param2=0},
		{name="air", prob=254, param2=0},
		{name="air", prob=254, param2=0},
		{name="air", prob=254, param2=0},
		{name="air", prob=254, param2=0},
		{name="air", prob=254, param2=0},
		{name="air", prob=254, param2=0},
		{name="air", prob=254, param2=0},
		{name="air", prob=254, param2=0},
		{name="air", prob=254, param2=0},
		{name="air", prob=254, param2=0},
		{name="vlf_villages:no_paths", prob=254, param2=0},
		{name="vlf_stairs:stair_oak_bark_outer", prob=254, param2=1},
		{name="vlf_stairs:stair_oak_bark", prob=254, param2=0},
		{name="vlf_stairs:stair_oak_bark", prob=254, param2=0},
		{name="vlf_stairs:stair_oak_bark", prob=254, param2=0},
		{name="vlf_stairs:stair_oak_bark", prob=254, param2=0},
		{name="vlf_stairs:stair_oak_bark", prob=254, param2=0},
		{name="vlf_stairs:stair_oak_bark", prob=254, param2=0},
		{name="vlf_stairs:stair_oak_bark", prob=254, param2=0},
		{name="vlf_stairs:stair_oak_bark", prob=254, param2=0},
		{name="vlf_stairs:stair_oak_bark", prob=254, param2=0},
		{name="vlf_stairs:stair_oak_bark_outer", prob=254, param2=0},
		{name="vlf_villages:no_paths", prob=254, param2=0},
		{name="vlf_villages:no_paths", prob=254, param2=0},
		{name="vlf_villages:no_paths", prob=254, param2=0},
		{name="vlf_villages:no_paths", prob=254, param2=0},
		{name="vlf_villages:no_paths", prob=254, param2=0},
		{name="vlf_villages:no_paths", prob=254, param2=0},
		{name="vlf_villages:no_paths", prob=254, param2=0},
		{name="vlf_villages:no_paths", prob=254, param2=0},
		{name="vlf_villages:no_paths", prob=254, param2=0},
		{name="vlf_villages:no_paths", prob=254, param2=0},
		{name="vlf_villages:no_paths", prob=254, param2=0},
		{name="vlf_villages:no_paths", prob=254, param2=0},
		{name="vlf_villages:no_paths", prob=254, param2=0},
		{name="vlf_villages:no_paths", prob=254, param2=0},
		{name="air", prob=254, param2=0},
		{name="air", prob=254, param2=0},
		{name="air", prob=254, param2=0},
		{name="air", prob=254, param2=0},
		{name="air", prob=254, param2=0},
		{name="air", prob=254, param2=0},
		{name="air", prob=254, param2=0},
		{name="air", prob=254, param2=0},
		{name="air", prob=254, param2=0},
		{name="air", prob=254, param2=0},
		{name="air", prob=254, param2=0},
		{name="air", prob=254, param2=0},
		{name="air", prob=254, param2=0},
		{name="air", prob=254, param2=0},
		{name="air", prob=254, param2=0},
		{name="air", prob=254, param2=0},
		{name="air", prob=254, param2=0},
		{name="air", prob=254, param2=0},
		{name="air", prob=254, param2=0},
		{name="air", prob=254, param2=0},
		{name="air", prob=254, param2=0},
		{name="air", prob=254, param2=0},
		{name="air", prob=254, param2=0},
		{name="air", prob=254, param2=0},
		{name="air", prob=254, param2=0},
		{name="air", prob=254, param2=0},
		{name="vlf_villages:no_paths", prob=254, param2=0},
		{name="vlf_stairs:stair_oak_bark", prob=254, param2=1},
		{name="vlf_farming:soil_wet", prob=254, param2=0},
		{name="vlf_core:dirt", prob=254, param2=0},
		{name="vlf_farming:soil_wet", prob=254, param2=0},
		{name="vlf_farming:soil_wet", prob=254, param2=0},
		{name="vlf_farming:soil_wet", prob=254, param2=0},
		{name="vlf_farming:soil_wet", prob=254, param2=0},
		{name="vlf_farming:soil_wet", prob=254, param2=0},
		{name="vlf_core:dirt", prob=254, param2=0},
		{name="vlf_core:dirt", prob=254, param2=0},
		{name="vlf_stairs:stair_oak_bark", prob=254, param2=3},
		{name="vlf_villages:no_paths", prob=254, param2=0},
		{name="vlf_villages:no_paths", prob=254, param2=0},
		{name="vlf_villages:no_paths", prob=254, param2=0},
		{name="vlf_villages:crop_grain_1", prob=254, param2=0},
		{name="air", prob=254, param2=0},
		{name="vlf_villages:crop_grain_1", prob=254, param2=0},
		{name="vlf_villages:crop_grain_1", prob=254, param2=0},
		{name="vlf_villages:crop_root_1", prob=254, param2=0},
		{name="vlf_villages:crop_grain_3", prob=254, param2=0},
		{name="vlf_villages:crop_grain_3", prob=254, param2=0},
		{name="air", prob=254, param2=0},
		{name="vlf_composters:composter", prob=254, param2=0},
		{name="vlf_villages:no_paths", prob=254, param2=0},
		{name="vlf_villages:no_paths", prob=254, param2=0},
		{name="air", prob=254, param2=0},
		{name="air", prob=254, param2=0},
		{name="air", prob=254, param2=0},
		{name="air", prob=254, param2=0},
		{name="air", prob=254, param2=0},
		{name="air", prob=254, param2=0},
		{name="air", prob=254, param2=0},
		{name="air", prob=254, param2=0},
		{name="air", prob=254, param2=0},
		{name="air", prob=254, param2=0},
		{name="air", prob=254, param2=0},
		{name="air", prob=254, param2=0},
		{name="air", prob=254, param2=0},
		{name="air", prob=254, param2=0},
		{name="air", prob=254, param2=0},
		{name="air", prob=254, param2=0},
		{name="air", prob=254, param2=0},
		{name="air", prob=254, param2=0},
		{name="air", prob=254, param2=0},
		{name="air", prob=254, param2=0},
		{name="air", prob=254, param2=0},
		{name="air", prob=254, param2=0},
		{name="air", prob=254, param2=0},
		{name="air", prob=254, param2=0},
		{name="air", prob=254, param2=0},
		{name="air", prob=254, param2=0},
		{name="vlf_villages:no_paths", prob=254, param2=0},
		{name="vlf_stairs:stair_oak_bark", prob=254, param2=1},
		{name="vlf_core:dirt", prob=254, param2=0},
		{name="vlf_farming:soil_wet", prob=254, param2=0},
		{name="vlf_core:dirt", prob=254, param2=0},
		{name="vlf_farming:soil_wet", prob=254, param2=0},
		{name="vlf_farming:soil_wet", prob=254, param2=0},
		{name="vlf_farming:soil_wet", prob=254, param2=0},
		{name="vlf_core:dirt", prob=254, param2=0},
		{name="vlf_farming:soil_wet", prob=254, param2=0},
		{name="vlf_core:dirt", prob=254, param2=0},
		{name="vlf_stairs:stair_oak_bark", prob=254, param2=3},
		{name="vlf_villages:no_paths", prob=254, param2=0},
		{name="vlf_villages:no_paths", prob=254, param2=0},
		{name="vlf_villages:no_paths", prob=254, param2=0},
		{name="air", prob=254, param2=0},
		{name="vlf_villages:crop_gourd_2", prob=254, param2=0},
		{name="air", prob=254, param2=0},
		{name="vlf_villages:crop_grain_1", prob=254, param2=0},
		{name="vlf_villages:crop_root_1", prob=254, param2=0},
		{name="vlf_villages:crop_grain_3", prob=254, param2=0},
		{name="air", prob=254, param2=0},
		{name="vlf_villages:crop_gourd_1", prob=254, param2=0},
		{name="air", prob=254, param2=0},
		{name="vlf_villages:no_paths", prob=254, param2=0},
		{name="vlf_villages:no_paths", prob=254, param2=0},
		{name="air", prob=254, param2=0},
		{name="air", prob=254, param2=0},
		{name="air", prob=254, param2=0},
		{name="air", prob=254, param2=0},
		{name="air", prob=254, param2=0},
		{name="air", prob=254, param2=0},
		{name="air", prob=254, param2=0},
		{name="air", prob=254, param2=0},
		{name="air", prob=254, param2=0},
		{name="air", prob=254, param2=0},
		{name="air", prob=254, param2=0},
		{name="air", prob=254, param2=0},
		{name="air", prob=254, param2=0},
		{name="air", prob=254, param2=0},
		{name="air", prob=254, param2=0},
		{name="air", prob=254, param2=0},
		{name="air", prob=254, param2=0},
		{name="air", prob=254, param2=0},
		{name="air", prob=254, param2=0},
		{name="air", prob=254, param2=0},
		{name="air", prob=254, param2=0},
		{name="air", prob=254, param2=0},
		{name="air", prob=254, param2=0},
		{name="air", prob=254, param2=0},
		{name="air", prob=254, param2=0},
		{name="air", prob=254, param2=0},
		{name="vlf_villages:path_endpoint", prob=254, param2=0},
		{name="vlf_stairs:stair_oak_bark", prob=254, param2=1},
		{name="vlf_farming:soil_wet", prob=254, param2=0},
		{name="vlf_core:dirt", prob=254, param2=0},
		{name="vlf_farming:soil_wet", prob=254, param2=0},
		{name="vlf_farming:soil_wet", prob=254, param2=0},
		{name="vlf_farming:soil_wet", prob=254, param2=0},
		{name="vlf_farming:soil_wet", prob=254, param2=0},
		{name="vlf_farming:soil_wet", prob=254, param2=0},
		{name="vlf_core:dirt", prob=254, param2=0},
		{name="vlf_farming:soil_wet", prob=254, param2=0},
		{name="vlf_stairs:stair_oak_bark", prob=254, param2=3},
		{name="vlf_villages:path_endpoint", prob=254, param2=0},
		{name="vlf_villages:no_paths", prob=254, param2=0},
		{name="vlf_villages:no_paths", prob=254, param2=0},
		{name="vlf_villages:crop_grain_1", prob=254, param2=0},
		{name="air", prob=254, param2=0},
		{name="vlf_villages:crop_grain_1", prob=254, param2=0},
		{name="vlf_villages:crop_grain_1", prob=254, param2=0},
		{name="vlf_villages:crop_root_1", prob=254, param2=0},
		{name="vlf_villages:crop_grain_3", prob=254, param2=0},
		{name="vlf_villages:crop_grain_3", prob=254, param2=0},
		{name="air", prob=254, param2=0},
		{name="vlf_villages:crop_grain_3", prob=254, param2=0},
		{name="vlf_villages:no_paths", prob=254, param2=0},
		{name="vlf_villages:no_paths", prob=254, param2=0},
		{name="air", prob=254, param2=0},
		{name="air", prob=254, param2=0},
		{name="air", prob=254, param2=0},
		{name="air", prob=254, param2=0},
		{name="air", prob=254, param2=0},
		{name="air", prob=254, param2=0},
		{name="air", prob=254, param2=0},
		{name="air", prob=254, param2=0},
		{name="air", prob=254, param2=0},
		{name="air", prob=254, param2=0},
		{name="air", prob=254, param2=0},
		{name="air", prob=254, param2=0},
		{name="air", prob=254, param2=0},
		{name="air", prob=254, param2=0},
		{name="air", prob=254, param2=0},
		{name="air", prob=254, param2=0},
		{name="air", prob=254, param2=0},
		{name="air", prob=254, param2=0},
		{name="air", prob=254, param2=0},
		{name="air", prob=254, param2=0},
		{name="air", prob=254, param2=0},
		{name="air", prob=254, param2=0},
		{name="air", prob=254, param2=0},
		{name="air", prob=254, param2=0},
		{name="air", prob=254, param2=0},
		{name="air", prob=254, param2=0},
		{name="vlf_villages:no_paths", prob=254, param2=0},
		{name="vlf_stairs:stair_oak_bark", prob=254, param2=1},
		{name="vlf_farming:soil_wet", prob=254, param2=0},
		{name="vlf_farming:soil_wet", prob=254, param2=0},
		{name="vlf_farming:soil_wet", prob=254, param2=0},
		{name="vlf_farming:soil_wet", prob=254, param2=0},
		{name="vlf_farming:soil_wet", prob=254, param2=0},
		{name="vlf_farming:soil_wet", prob=254, param2=0},
		{name="vlf_farming:soil_wet", prob=254, param2=0},
		{name="vlf_farming:soil_wet", prob=254, param2=0},
		{name="vlf_farming:soil_wet", prob=254, param2=0},
		{name="vlf_stairs:stair_oak_bark", prob=254, param2=3},
		{name="vlf_villages:no_paths", prob=254, param2=0},
		{name="vlf_villages:no_paths", prob=254, param2=0},
		{name="vlf_villages:no_paths", prob=254, param2=0},
		{name="vlf_villages:crop_grain_1", prob=254, param2=0},
		{name="vlf_villages:crop_grain_1", prob=254, param2=0},
		{name="vlf_villages:crop_grain_1", prob=254, param2=0},
		{name="vlf_villages:crop_grain_1", prob=254, param2=0},
		{name="vlf_villages:crop_root_1", prob=254, param2=0},
		{name="vlf_villages:crop_grain_3", prob=254, param2=0},
		{name="vlf_villages:crop_grain_3", prob=254, param2=0},
		{name="vlf_villages:crop_grain_3", prob=254, param2=0},
		{name="vlf_villages:crop_grain_3", prob=254, param2=0},
		{name="vlf_villages:no_paths", prob=254, param2=0},
		{name="vlf_villages:no_paths", prob=254, param2=0},
		{name="air", prob=254, param2=0},
		{name="air", prob=254, param2=0},
		{name="air", prob=254, param2=0},
		{name="air", prob=254, param2=0},
		{name="air", prob=254, param2=0},
		{name="air", prob=254, param2=0},
		{name="air", prob=254, param2=0},
		{name="air", prob=254, param2=0},
		{name="air", prob=254, param2=0},
		{name="air", prob=254, param2=0},
		{name="air", prob=254, param2=0},
		{name="air", prob=254, param2=0},
		{name="air", prob=254, param2=0},
		{name="air", prob=254, param2=0},
		{name="air", prob=254, param2=0},
		{name="air", prob=254, param2=0},
		{name="air", prob=254, param2=0},
		{name="air", prob=254, param2=0},
		{name="air", prob=254, param2=0},
		{name="air", prob=254, param2=0},
		{name="air", prob=254, param2=0},
		{name="air", prob=254, param2=0},
		{name="air", prob=254, param2=0},
		{name="air", prob=254, param2=0},
		{name="air", prob=254, param2=0},
		{name="air", prob=254, param2=0},
		{name="vlf_villages:no_paths", prob=254, param2=0},
		{name="vlf_stairs:stair_oak_bark", prob=254, param2=1},
		{name="vlf_farming:soil_wet", prob=254, param2=0},
		{name="vlf_farming:soil_wet", prob=254, param2=0},
		{name="vlf_farming:soil_wet", prob=254, param2=0},
		{name="vlf_farming:soil_wet", prob=254, param2=0},
		{name="vlf_core:water_source", prob=254, param2=7},
		{name="vlf_farming:soil_wet", prob=254, param2=0},
		{name="vlf_farming:soil_wet", prob=254, param2=0},
		{name="vlf_farming:soil_wet", prob=254, param2=0},
		{name="vlf_farming:soil_wet", prob=254, param2=0},
		{name="vlf_stairs:stair_oak_bark", prob=254, param2=3},
		{name="vlf_villages:no_paths", prob=254, param2=0},
		{name="vlf_villages:no_paths", prob=254, param2=0},
		{name="vlf_villages:no_paths", prob=254, param2=0},
		{name="vlf_villages:crop_root_2", prob=254, param2=0},
		{name="vlf_villages:crop_root_2", prob=254, param2=0},
		{name="vlf_villages:crop_root_2", prob=254, param2=0},
		{name="vlf_villages:crop_root_2", prob=254, param2=0},
		{name="vlf_fences:oak_fence", prob=254, param2=0},
		{name="vlf_villages:crop_root_3", prob=254, param2=0},
		{name="vlf_villages:crop_root_3", prob=254, param2=0},
		{name="vlf_villages:crop_root_3", prob=254, param2=0},
		{name="vlf_villages:crop_root_3", prob=254, param2=0},
		{name="vlf_villages:no_paths", prob=254, param2=0},
		{name="vlf_villages:no_paths", prob=254, param2=0},
		{name="air", prob=254, param2=0},
		{name="air", prob=254, param2=0},
		{name="air", prob=254, param2=0},
		{name="air", prob=254, param2=0},
		{name="air", prob=254, param2=0},
		{name="air", prob=254, param2=0},
		{name="vlf_lanterns:lantern_floor", prob=254, param2=1},
		{name="air", prob=254, param2=0},
		{name="air", prob=254, param2=0},
		{name="air", prob=254, param2=0},
		{name="air", prob=254, param2=0},
		{name="air", prob=254, param2=0},
		{name="air", prob=254, param2=0},
		{name="air", prob=254, param2=0},
		{name="air", prob=254, param2=0},
		{name="air", prob=254, param2=0},
		{name="air", prob=254, param2=0},
		{name="air", prob=254, param2=0},
		{name="air", prob=254, param2=0},
		{name="air", prob=254, param2=0},
		{name="air", prob=254, param2=0},
		{name="air", prob=254, param2=0},
		{name="air", prob=254, param2=0},
		{name="air", prob=254, param2=0},
		{name="air", prob=254, param2=0},
		{name="air", prob=254, param2=0},
		{name="vlf_villages:no_paths", prob=254, param2=0},
		{name="vlf_stairs:stair_oak_bark", prob=254, param2=1},
		{name="vlf_farming:soil_wet", prob=254, param2=0},
		{name="vlf_farming:soil_wet", prob=254, param2=0},
		{name="vlf_farming:soil_wet", prob=254, param2=0},
		{name="vlf_farming:soil_wet", prob=254, param2=0},
		{name="vlf_farming:soil_wet", prob=254, param2=0},
		{name="vlf_farming:soil_wet", prob=254, param2=0},
		{name="vlf_farming:soil_wet", prob=254, param2=0},
		{name="vlf_farming:soil_wet", prob=254, param2=0},
		{name="vlf_farming:soil_wet", prob=254, param2=0},
		{name="vlf_stairs:stair_oak_bark", prob=254, param2=3},
		{name="vlf_villages:no_paths", prob=254, param2=0},
		{name="vlf_villages:no_paths", prob=254, param2=0},
		{name="vlf_villages:no_paths", prob=254, param2=0},
		{name="vlf_villages:crop_root_2", prob=254, param2=0},
		{name="vlf_villages:crop_root_2", prob=254, param2=0},
		{name="vlf_villages:crop_root_2", prob=254, param2=0},
		{name="vlf_villages:crop_root_2", prob=254, param2=0},
		{name="vlf_villages:crop_root_3", prob=254, param2=0},
		{name="vlf_villages:crop_grain_2", prob=254, param2=0},
		{name="vlf_villages:crop_grain_2", prob=254, param2=0},
		{name="vlf_villages:crop_grain_2", prob=254, param2=0},
		{name="vlf_villages:crop_grain_2", prob=254, param2=0},
		{name="vlf_villages:no_paths", prob=254, param2=0},
		{name="vlf_villages:no_paths", prob=254, param2=0},
		{name="air", prob=254, param2=0},
		{name="air", prob=254, param2=0},
		{name="air", prob=254, param2=0},
		{name="air", prob=254, param2=0},
		{name="air", prob=254, param2=0},
		{name="air", prob=254, param2=0},
		{name="air", prob=254, param2=0},
		{name="air", prob=254, param2=0},
		{name="air", prob=254, param2=0},
		{name="air", prob=254, param2=0},
		{name="air", prob=254, param2=0},
		{name="air", prob=254, param2=0},
		{name="air", prob=254, param2=0},
		{name="air", prob=254, param2=0},
		{name="air", prob=254, param2=0},
		{name="air", prob=254, param2=0},
		{name="air", prob=254, param2=0},
		{name="air", prob=254, param2=0},
		{name="air", prob=254, param2=0},
		{name="air", prob=254, param2=0},
		{name="air", prob=254, param2=0},
		{name="air", prob=254, param2=0},
		{name="air", prob=254, param2=0},
		{name="air", prob=254, param2=0},
		{name="air", prob=254, param2=0},
		{name="air", prob=254, param2=0},
		{name="vlf_villages:path_endpoint", prob=254, param2=0},
		{name="vlf_stairs:stair_oak_bark", prob=254, param2=1},
		{name="vlf_farming:soil_wet", prob=254, param2=0},
		{name="vlf_core:dirt", prob=254, param2=0},
		{name="vlf_farming:soil_wet", prob=254, param2=0},
		{name="vlf_farming:soil_wet", prob=254, param2=0},
		{name="vlf_farming:soil_wet", prob=254, param2=0},
		{name="vlf_farming:soil_wet", prob=254, param2=0},
		{name="vlf_farming:soil_wet", prob=254, param2=0},
		{name="vlf_core:dirt", prob=254, param2=0},
		{name="vlf_farming:soil_wet", prob=254, param2=0},
		{name="vlf_stairs:stair_oak_bark", prob=254, param2=3},
		{name="vlf_villages:path_endpoint", prob=254, param2=0},
		{name="vlf_villages:no_paths", prob=254, param2=0},
		{name="vlf_villages:no_paths", prob=254, param2=0},
		{name="vlf_villages:crop_root_2", prob=254, param2=0},
		{name="air", prob=254, param2=0},
		{name="vlf_villages:crop_root_2", prob=254, param2=0},
		{name="vlf_villages:crop_root_2", prob=254, param2=0},
		{name="vlf_villages:crop_root_3", prob=254, param2=0},
		{name="vlf_villages:crop_grain_2", prob=254, param2=0},
		{name="vlf_villages:crop_grain_2", prob=254, param2=0},
		{name="air", prob=254, param2=0},
		{name="vlf_villages:crop_grain_2", prob=254, param2=0},
		{name="vlf_villages:no_paths", prob=254, param2=0},
		{name="vlf_villages:no_paths", prob=254, param2=0},
		{name="air", prob=254, param2=0},
		{name="air", prob=254, param2=0},
		{name="air", prob=254, param2=0},
		{name="air", prob=254, param2=0},
		{name="air", prob=254, param2=0},
		{name="air", prob=254, param2=0},
		{name="air", prob=254, param2=0},
		{name="air", prob=254, param2=0},
		{name="air", prob=254, param2=0},
		{name="air", prob=254, param2=0},
		{name="air", prob=254, param2=0},
		{name="air", prob=254, param2=0},
		{name="air", prob=254, param2=0},
		{name="air", prob=254, param2=0},
		{name="air", prob=254, param2=0},
		{name="air", prob=254, param2=0},
		{name="air", prob=254, param2=0},
		{name="air", prob=254, param2=0},
		{name="air", prob=254, param2=0},
		{name="air", prob=254, param2=0},
		{name="air", prob=254, param2=0},
		{name="air", prob=254, param2=0},
		{name="air", prob=254, param2=0},
		{name="air", prob=254, param2=0},
		{name="air", prob=254, param2=0},
		{name="air", prob=254, param2=0},
		{name="vlf_villages:no_paths", prob=254, param2=0},
		{name="vlf_stairs:stair_oak_bark", prob=254, param2=1},
		{name="vlf_core:dirt", prob=254, param2=0},
		{name="vlf_farming:soil_wet", prob=254, param2=0},
		{name="vlf_core:dirt", prob=254, param2=0},
		{name="vlf_farming:soil_wet", prob=254, param2=0},
		{name="vlf_farming:soil_wet", prob=254, param2=0},
		{name="vlf_farming:soil_wet", prob=254, param2=0},
		{name="vlf_core:dirt", prob=254, param2=0},
		{name="vlf_farming:soil_wet", prob=254, param2=0},
		{name="vlf_core:dirt", prob=254, param2=0},
		{name="vlf_stairs:stair_oak_bark", prob=254, param2=3},
		{name="vlf_villages:no_paths", prob=254, param2=0},
		{name="vlf_villages:no_paths", prob=254, param2=0},
		{name="vlf_villages:no_paths", prob=254, param2=0},
		{name="air", prob=254, param2=0},
		{name="vlf_villages:crop_gourd_1", prob=254, param2=0},
		{name="air", prob=254, param2=0},
		{name="vlf_villages:crop_root_1", prob=254, param2=0},
		{name="vlf_villages:crop_root_3", prob=254, param2=0},
		{name="vlf_villages:crop_grain_2", prob=254, param2=0},
		{name="air", prob=254, param2=0},
		{name="vlf_villages:crop_gourd_2", prob=254, param2=0},
		{name="air", prob=254, param2=0},
		{name="vlf_villages:no_paths", prob=254, param2=0},
		{name="vlf_villages:no_paths", prob=254, param2=0},
		{name="air", prob=254, param2=0},
		{name="air", prob=254, param2=0},
		{name="air", prob=254, param2=0},
		{name="air", prob=254, param2=0},
		{name="air", prob=254, param2=0},
		{name="air", prob=254, param2=0},
		{name="air", prob=254, param2=0},
		{name="air", prob=254, param2=0},
		{name="air", prob=254, param2=0},
		{name="air", prob=254, param2=0},
		{name="air", prob=254, param2=0},
		{name="air", prob=254, param2=0},
		{name="air", prob=254, param2=0},
		{name="air", prob=254, param2=0},
		{name="air", prob=254, param2=0},
		{name="air", prob=254, param2=0},
		{name="air", prob=254, param2=0},
		{name="air", prob=254, param2=0},
		{name="air", prob=254, param2=0},
		{name="air", prob=254, param2=0},
		{name="air", prob=254, param2=0},
		{name="air", prob=254, param2=0},
		{name="air", prob=254, param2=0},
		{name="air", prob=254, param2=0},
		{name="air", prob=254, param2=0},
		{name="air", prob=254, param2=0},
		{name="vlf_villages:no_paths", prob=254, param2=0},
		{name="vlf_stairs:stair_oak_bark", prob=254, param2=1},
		{name="vlf_farming:soil_wet", prob=254, param2=0},
		{name="vlf_core:dirt", prob=254, param2=0},
		{name="vlf_farming:soil_wet", prob=254, param2=0},
		{name="vlf_farming:soil_wet", prob=254, param2=0},
		{name="vlf_farming:soil_wet", prob=254, param2=0},
		{name="vlf_farming:soil_wet", prob=254, param2=0},
		{name="vlf_farming:soil_wet", prob=254, param2=0},
		{name="vlf_core:dirt", prob=254, param2=0},
		{name="vlf_core:dirt", prob=254, param2=0},
		{name="vlf_stairs:stair_oak_bark", prob=254, param2=3},
		{name="vlf_villages:no_paths", prob=254, param2=0},
		{name="vlf_villages:no_paths", prob=254, param2=0},
		{name="vlf_villages:no_paths", prob=254, param2=0},
		{name="vlf_villages:crop_root_1", prob=254, param2=0},
		{name="air", prob=254, param2=0},
		{name="vlf_villages:crop_root_1", prob=254, param2=0},
		{name="vlf_villages:crop_root_1", prob=254, param2=0},
		{name="vlf_villages:crop_root_3", prob=254, param2=0},
		{name="vlf_villages:crop_grain_2", prob=254, param2=0},
		{name="vlf_villages:crop_grain_2", prob=254, param2=0},
		{name="air", prob=254, param2=0},
		{name="vlf_composters:composter", prob=254, param2=0},
		{name="vlf_villages:no_paths", prob=254, param2=0},
		{name="vlf_villages:no_paths", prob=254, param2=0},
		{name="air", prob=254, param2=0},
		{name="air", prob=254, param2=0},
		{name="air", prob=254, param2=0},
		{name="air", prob=254, param2=0},
		{name="air", prob=254, param2=0},
		{name="air", prob=254, param2=0},
		{name="air", prob=254, param2=0},
		{name="air", prob=254, param2=0},
		{name="air", prob=254, param2=0},
		{name="air", prob=254, param2=0},
		{name="air", prob=254, param2=0},
		{name="air", prob=254, param2=0},
		{name="air", prob=254, param2=0},
		{name="air", prob=254, param2=0},
		{name="air", prob=254, param2=0},
		{name="air", prob=254, param2=0},
		{name="air", prob=254, param2=0},
		{name="air", prob=254, param2=0},
		{name="air", prob=254, param2=0},
		{name="air", prob=254, param2=0},
		{name="air", prob=254, param2=0},
		{name="air", prob=254, param2=0},
		{name="air", prob=254, param2=0},
		{name="air", prob=254, param2=0},
		{name="air", prob=254, param2=0},
		{name="air", prob=254, param2=0},
		{name="vlf_villages:no_paths", prob=254, param2=0},
		{name="vlf_stairs:stair_oak_bark_outer", prob=254, param2=2},
		{name="vlf_stairs:stair_oak_bark", prob=254, param2=2},
		{name="vlf_stairs:stair_oak_bark", prob=254, param2=2},
		{name="vlf_stairs:stair_oak_bark", prob=254, param2=2},
		{name="vlf_stairs:stair_oak_bark", prob=254, param2=2},
		{name="vlf_stairs:stair_oak_bark", prob=254, param2=2},
		{name="vlf_stairs:stair_oak_bark", prob=254, param2=2},
		{name="vlf_stairs:stair_oak_bark", prob=254, param2=2},
		{name="vlf_stairs:stair_oak_bark", prob=254, param2=2},
		{name="vlf_stairs:stair_oak_bark", prob=254, param2=2},
		{name="vlf_stairs:stair_oak_bark_outer", prob=254, param2=3},
		{name="vlf_villages:no_paths", prob=254, param2=0},
		{name="vlf_villages:no_paths", prob=254, param2=0},
		{name="vlf_villages:no_paths", prob=254, param2=0},
		{name="vlf_villages:no_paths", prob=254, param2=0},
		{name="vlf_villages:no_paths", prob=254, param2=0},
		{name="vlf_villages:no_paths", prob=254, param2=0},
		{name="vlf_villages:no_paths", prob=254, param2=0},
		{name="vlf_villages:no_paths", prob=254, param2=0},
		{name="vlf_villages:no_paths", prob=254, param2=0},
		{name="vlf_villages:no_paths", prob=254, param2=0},
		{name="vlf_villages:no_paths", prob=254, param2=0},
		{name="vlf_villages:no_paths", prob=254, param2=0},
		{name="vlf_villages:no_paths", prob=254, param2=0},
		{name="vlf_villages:no_paths", prob=254, param2=0},
		{name="air", prob=254, param2=0},
		{name="air", prob=254, param2=0},
		{name="air", prob=254, param2=0},
		{name="air", prob=254, param2=0},
		{name="air", prob=254, param2=0},
		{name="air", prob=254, param2=0},
		{name="air", prob=254, param2=0},
		{name="air", prob=254, param2=0},
		{name="air", prob=254, param2=0},
		{name="air", prob=254, param2=0},
		{name="air", prob=254, param2=0},
		{name="air", prob=254, param2=0},
		{name="air", prob=254, param2=0},
		{name="air", prob=254, param2=0},
		{name="air", prob=254, param2=0},
		{name="air", prob=254, param2=0},
		{name="air", prob=254, param2=0},
		{name="air", prob=254, param2=0},
		{name="air", prob=254, param2=0},
		{name="air", prob=254, param2=0},
		{name="air", prob=254, param2=0},
		{name="air", prob=254, param2=0},
		{name="air", prob=254, param2=0},
		{name="air", prob=254, param2=0},
		{name="air", prob=254, param2=0},
		{name="air", prob=254, param2=0},
		{name="vlf_villages:no_paths", prob=254, param2=0},
		{name="vlf_villages:no_paths", prob=254, param2=0},
		{name="vlf_villages:no_paths", prob=254, param2=0},
		{name="vlf_villages:no_paths", prob=254, param2=0},
		{name="vlf_villages:no_paths", prob=254, param2=0},
		{name="vlf_villages:no_paths", prob=254, param2=0},
		{name="vlf_villages:no_paths", prob=254, param2=0},
		{name="vlf_villages:no_paths", prob=254, param2=0},
		{name="vlf_villages:no_paths", prob=254, param2=0},
		{name="vlf_villages:no_paths", prob=254, param2=0},
		{name="vlf_villages:no_paths", prob=254, param2=0},
		{name="vlf_villages:no_paths", prob=254, param2=0},
		{name="vlf_villages:no_paths", prob=254, param2=0},
		{name="vlf_villages:no_paths", prob=254, param2=0},
		{name="vlf_villages:no_paths", prob=254, param2=0},
		{name="vlf_villages:no_paths", prob=254, param2=0},
		{name="vlf_villages:no_paths", prob=254, param2=0},
		{name="vlf_villages:no_paths", prob=254, param2=0},
		{name="vlf_villages:no_paths", prob=254, param2=0},
		{name="vlf_villages:no_paths", prob=254, param2=0},
		{name="vlf_villages:no_paths", prob=254, param2=0},
		{name="vlf_villages:no_paths", prob=254, param2=0},
		{name="vlf_villages:no_paths", prob=254, param2=0},
		{name="vlf_villages:no_paths", prob=254, param2=0},
		{name="vlf_villages:no_paths", prob=254, param2=0},
		{name="vlf_villages:no_paths", prob=254, param2=0},
		{name="air", prob=254, param2=0},
		{name="air", prob=254, param2=0},
		{name="air", prob=254, param2=0},
		{name="air", prob=254, param2=0},
		{name="air", prob=254, param2=0},
		{name="air", prob=254, param2=0},
		{name="air", prob=254, param2=0},
		{name="air", prob=254, param2=0},
		{name="air", prob=254, param2=0},
		{name="air", prob=254, param2=0},
		{name="air", prob=254, param2=0},
		{name="air", prob=254, param2=0},
		{name="air", prob=254, param2=0},
		{name="air", prob=254, param2=0},
		{name="air", prob=254, param2=0},
		{name="air", prob=254, param2=0},
		{name="air", prob=254, param2=0},
		{name="air", prob=254, param2=0},
		{name="air", prob=254, param2=0},
		{name="air", prob=254, param2=0},
		{name="air", prob=254, param2=0},
		{name="air", prob=254, param2=0},
		{name="air", prob=254, param2=0},
		{name="air", prob=254, param2=0},
		{name="air", prob=254, param2=0},
		{name="air", prob=254, param2=0},
	},
}
