schematic = {
	size = {x=3, y=6, z=4},
	yslice_prob = {
		{ypos=0, prob=254},
		{ypos=1, prob=254},
		{ypos=2, prob=254},
		{ypos=3, prob=254},
		{ypos=4, prob=254},
		{ypos=5, prob=254},
	},
	data = {
		{name="vlf_core:dirt", prob=254, param2=0},
		{name="vlf_core:dirt", prob=254, param2=0},
		{name="vlf_core:dirt", prob=254, param2=0},
		{name="air", prob=254, param2=0},
		{name="air", prob=254, param2=0},
		{name="air", prob=254, param2=0},
		{name="air", prob=254, param2=0},
		{name="air", prob=254, param2=0},
		{name="air", prob=254, param2=0},
		{name="air", prob=254, param2=0},
		{name="air", prob=254, param2=0},
		{name="air", prob=254, param2=0},
		{name="air", prob=254, param2=0},
		{name="air", prob=254, param2=0},
		{name="air", prob=254, param2=0},
		{name="air", prob=254, param2=0},
		{name="air", prob=254, param2=0},
		{name="air", prob=254, param2=0},
		{name="vlf_core:dirt", prob=254, param2=0},
		{name="vlf_core:dirt", prob=254, param2=0},
		{name="vlf_core:dirt", prob=254, param2=0},
		{name="air", prob=254, param2=0},
		{name="air", prob=254, param2=0},
		{name="air", prob=254, param2=0},
		{name="air", prob=254, param2=0},
		{name="air", prob=254, param2=0},
		{name="air", prob=254, param2=0},
		{name="air", prob=254, param2=0},
		{name="air", prob=254, param2=0},
		{name="air", prob=254, param2=0},
		{name="air", prob=254, param2=0},
		{name="vlf_doors:trapdoor_open", prob=254, param2=20},
		{name="air", prob=254, param2=0},
		{name="air", prob=254, param2=0},
		{name="air", prob=254, param2=0},
		{name="air", prob=254, param2=0},
		{name="vlf_core:dirt", prob=254, param2=0},
		{name="vlf_core:dirt", prob=254, param2=0},
		{name="vlf_core:dirt", prob=254, param2=0},
		{name="air", prob=254, param2=0},
		{name="vlf_fences:fence", prob=254, param2=0},
		{name="air", prob=254, param2=0},
		{name="air", prob=254, param2=0},
		{name="vlf_fences:fence", prob=254, param2=0},
		{name="air", prob=254, param2=0},
		{name="air", prob=254, param2=0},
		{name="vlf_fences:fence", prob=254, param2=0},
		{name="air", prob=254, param2=0},
		{name="vlf_doors:trapdoor_open", prob=254, param2=23},
		{name="vlf_ocean:sea_lantern", prob=254, param2=0},
		{name="vlf_doors:trapdoor_open", prob=254, param2=21},
		{name="air", prob=254, param2=0},
		{name="vlf_doors:trapdoor", prob=254, param2=1},
		{name="air", prob=254, param2=0},
		{name="vlf_core:dirt", prob=254, param2=0},
		{name="vlf_core:dirt", prob=254, param2=0},
		{name="vlf_core:dirt", prob=254, param2=0},
		{name="air", prob=254, param2=0},
		{name="air", prob=254, param2=0},
		{name="air", prob=254, param2=0},
		{name="air", prob=254, param2=0},
		{name="air", prob=254, param2=0},
		{name="air", prob=254, param2=0},
		{name="air", prob=254, param2=0},
		{name="air", prob=254, param2=0},
		{name="air", prob=254, param2=0},
		{name="air", prob=254, param2=0},
		{name="vlf_doors:trapdoor_open", prob=254, param2=22},
		{name="air", prob=254, param2=0},
		{name="air", prob=254, param2=0},
		{name="air", prob=254, param2=0},
		{name="air", prob=254, param2=0},
	},
}
