schematic = {
	size = {x=12, y=9, z=12},
	yslice_prob = {
		{ypos=0, prob=254},
		{ypos=1, prob=254},
		{ypos=2, prob=254},
		{ypos=3, prob=254},
		{ypos=4, prob=254},
		{ypos=5, prob=254},
		{ypos=6, prob=254},
		{ypos=7, prob=254},
		{ypos=8, prob=254},
	},
	data = {
		{name="vlf_core:dirt", prob=254, param2=0},
		{name="vlf_core:dirt", prob=254, param2=0},
		{name="vlf_core:dirt", prob=254, param2=0},
		{name="vlf_core:dirt", prob=254, param2=0},
		{name="vlf_core:dirt", prob=254, param2=0},
		{name="vlf_core:dirt", prob=254, param2=0},
		{name="vlf_core:dirt", prob=254, param2=0},
		{name="vlf_core:dirt", prob=254, param2=0},
		{name="vlf_core:dirt", prob=254, param2=0},
		{name="vlf_core:dirt", prob=254, param2=0},
		{name="vlf_core:dirt", prob=254, param2=0},
		{name="vlf_core:dirt", prob=254, param2=0},
		{name="air", prob=254, param2=0},
		{name="air", prob=254, param2=0},
		{name="air", prob=254, param2=0},
		{name="air", prob=254, param2=0},
		{name="air", prob=254, param2=0},
		{name="air", prob=254, param2=0},
		{name="air", prob=254, param2=0},
		{name="air", prob=254, param2=0},
		{name="air", prob=254, param2=0},
		{name="air", prob=254, param2=0},
		{name="air", prob=254, param2=0},
		{name="air", prob=254, param2=0},
		{name="air", prob=254, param2=0},
		{name="air", prob=254, param2=0},
		{name="air", prob=254, param2=0},
		{name="air", prob=254, param2=0},
		{name="air", prob=254, param2=0},
		{name="air", prob=254, param2=0},
		{name="air", prob=254, param2=0},
		{name="air", prob=254, param2=0},
		{name="air", prob=254, param2=0},
		{name="air", prob=254, param2=0},
		{name="air", prob=254, param2=0},
		{name="air", prob=254, param2=0},
		{name="air", prob=254, param2=0},
		{name="air", prob=254, param2=0},
		{name="air", prob=254, param2=0},
		{name="air", prob=254, param2=0},
		{name="air", prob=254, param2=0},
		{name="air", prob=254, param2=0},
		{name="air", prob=254, param2=0},
		{name="air", prob=254, param2=0},
		{name="air", prob=254, param2=0},
		{name="air", prob=254, param2=0},
		{name="air", prob=254, param2=0},
		{name="air", prob=254, param2=0},
		{name="air", prob=254, param2=0},
		{name="air", prob=254, param2=0},
		{name="air", prob=254, param2=0},
		{name="air", prob=254, param2=0},
		{name="air", prob=254, param2=0},
		{name="air", prob=254, param2=0},
		{name="air", prob=254, param2=0},
		{name="air", prob=254, param2=0},
		{name="air", prob=254, param2=0},
		{name="air", prob=254, param2=0},
		{name="air", prob=254, param2=0},
		{name="air", prob=254, param2=0},
		{name="air", prob=254, param2=0},
		{name="air", prob=254, param2=0},
		{name="air", prob=254, param2=0},
		{name="air", prob=254, param2=0},
		{name="air", prob=254, param2=0},
		{name="air", prob=254, param2=0},
		{name="air", prob=254, param2=0},
		{name="air", prob=254, param2=0},
		{name="air", prob=254, param2=0},
		{name="air", prob=254, param2=0},
		{name="air", prob=254, param2=0},
		{name="air", prob=254, param2=0},
		{name="air", prob=254, param2=0},
		{name="air", prob=254, param2=0},
		{name="air", prob=254, param2=0},
		{name="air", prob=254, param2=0},
		{name="air", prob=254, param2=0},
		{name="air", prob=254, param2=0},
		{name="air", prob=254, param2=0},
		{name="air", prob=254, param2=0},
		{name="air", prob=254, param2=0},
		{name="air", prob=254, param2=0},
		{name="air", prob=254, param2=0},
		{name="air", prob=254, param2=0},
		{name="air", prob=254, param2=0},
		{name="air", prob=254, param2=0},
		{name="air", prob=254, param2=0},
		{name="air", prob=254, param2=0},
		{name="air", prob=254, param2=0},
		{name="air", prob=254, param2=0},
		{name="air", prob=254, param2=0},
		{name="air", prob=254, param2=0},
		{name="air", prob=254, param2=0},
		{name="air", prob=254, param2=0},
		{name="air", prob=254, param2=0},
		{name="air", prob=254, param2=0},
		{name="air", prob=254, param2=0},
		{name="air", prob=254, param2=0},
		{name="air", prob=254, param2=0},
		{name="air", prob=254, param2=0},
		{name="air", prob=254, param2=0},
		{name="air", prob=254, param2=0},
		{name="air", prob=254, param2=0},
		{name="air", prob=254, param2=0},
		{name="air", prob=254, param2=0},
		{name="air", prob=254, param2=0},
		{name="air", prob=254, param2=0},
		{name="air", prob=254, param2=0},
		{name="vlf_core:dirt", prob=254, param2=0},
		{name="vlf_core:dirt", prob=254, param2=0},
		{name="vlf_core:dirt", prob=254, param2=0},
		{name="vlf_core:dirt", prob=254, param2=0},
		{name="vlf_core:dirt", prob=254, param2=0},
		{name="vlf_core:dirt", prob=254, param2=0},
		{name="vlf_core:dirt", prob=254, param2=0},
		{name="vlf_core:dirt", prob=254, param2=0},
		{name="vlf_core:dirt", prob=254, param2=0},
		{name="vlf_core:dirt", prob=254, param2=0},
		{name="vlf_core:dirt", prob=254, param2=0},
		{name="vlf_core:dirt", prob=254, param2=0},
		{name="air", prob=254, param2=0},
		{name="air", prob=254, param2=0},
		{name="air", prob=254, param2=0},
		{name="air", prob=254, param2=0},
		{name="air", prob=254, param2=0},
		{name="air", prob=254, param2=0},
		{name="air", prob=254, param2=0},
		{name="air", prob=254, param2=0},
		{name="vlf_core:cobble", prob=254, param2=0},
		{name="vlf_core:cobble", prob=254, param2=0},
		{name="vlf_core:cobble", prob=254, param2=0},
		{name="vlf_core:cobble", prob=254, param2=0},
		{name="air", prob=254, param2=0},
		{name="air", prob=254, param2=0},
		{name="air", prob=254, param2=0},
		{name="air", prob=254, param2=0},
		{name="air", prob=254, param2=0},
		{name="air", prob=254, param2=0},
		{name="air", prob=254, param2=0},
		{name="air", prob=254, param2=0},
		{name="vlf_core:stonebrick", prob=254, param2=0},
		{name="vlf_core:wood", prob=254, param2=0},
		{name="vlf_core:wood", prob=254, param2=0},
		{name="vlf_core:stonebrick", prob=254, param2=0},
		{name="air", prob=254, param2=0},
		{name="air", prob=254, param2=0},
		{name="air", prob=254, param2=0},
		{name="air", prob=254, param2=0},
		{name="air", prob=254, param2=0},
		{name="air", prob=254, param2=0},
		{name="air", prob=254, param2=0},
		{name="air", prob=254, param2=0},
		{name="vlf_core:stonebrick", prob=254, param2=0},
		{name="vlf_core:wood", prob=254, param2=0},
		{name="vlf_core:wood", prob=254, param2=0},
		{name="vlf_core:stonebrick", prob=254, param2=0},
		{name="air", prob=254, param2=0},
		{name="air", prob=254, param2=0},
		{name="air", prob=254, param2=0},
		{name="air", prob=254, param2=0},
		{name="air", prob=254, param2=0},
		{name="air", prob=254, param2=0},
		{name="air", prob=254, param2=0},
		{name="air", prob=254, param2=0},
		{name="vlf_core:stonebrick", prob=254, param2=0},
		{name="vlf_core:glass", prob=254, param2=0},
		{name="vlf_core:glass", prob=254, param2=0},
		{name="vlf_core:stonebrick", prob=254, param2=0},
		{name="air", prob=254, param2=0},
		{name="air", prob=254, param2=0},
		{name="air", prob=254, param2=0},
		{name="air", prob=254, param2=0},
		{name="air", prob=254, param2=0},
		{name="air", prob=254, param2=0},
		{name="air", prob=254, param2=0},
		{name="air", prob=254, param2=0},
		{name="vlf_core:stonebrick", prob=254, param2=0},
		{name="vlf_core:glass", prob=254, param2=0},
		{name="vlf_core:glass", prob=254, param2=0},
		{name="vlf_core:stonebrick", prob=254, param2=0},
		{name="air", prob=254, param2=0},
		{name="air", prob=254, param2=0},
		{name="air", prob=254, param2=0},
		{name="air", prob=254, param2=0},
		{name="air", prob=254, param2=0},
		{name="air", prob=254, param2=0},
		{name="air", prob=254, param2=0},
		{name="air", prob=254, param2=0},
		{name="vlf_core:wood", prob=254, param2=0},
		{name="vlf_core:wood", prob=254, param2=0},
		{name="vlf_core:wood", prob=254, param2=0},
		{name="vlf_core:wood", prob=254, param2=0},
		{name="air", prob=254, param2=0},
		{name="air", prob=254, param2=0},
		{name="air", prob=254, param2=0},
		{name="air", prob=254, param2=0},
		{name="air", prob=254, param2=0},
		{name="air", prob=254, param2=0},
		{name="air", prob=254, param2=0},
		{name="air", prob=254, param2=0},
		{name="air", prob=254, param2=0},
		{name="vlf_stairs:slab_wood", prob=254, param2=0},
		{name="vlf_stairs:slab_wood", prob=254, param2=0},
		{name="air", prob=254, param2=0},
		{name="air", prob=254, param2=0},
		{name="air", prob=254, param2=0},
		{name="air", prob=254, param2=0},
		{name="air", prob=254, param2=0},
		{name="air", prob=254, param2=0},
		{name="air", prob=254, param2=0},
		{name="air", prob=254, param2=0},
		{name="air", prob=254, param2=0},
		{name="air", prob=254, param2=0},
		{name="air", prob=254, param2=0},
		{name="air", prob=254, param2=0},
		{name="air", prob=254, param2=0},
		{name="vlf_core:dirt", prob=254, param2=0},
		{name="vlf_core:dirt", prob=254, param2=0},
		{name="vlf_core:dirt", prob=254, param2=0},
		{name="vlf_core:dirt", prob=254, param2=0},
		{name="vlf_core:dirt", prob=254, param2=0},
		{name="vlf_core:dirt", prob=254, param2=0},
		{name="vlf_core:dirt", prob=254, param2=0},
		{name="vlf_core:dirt", prob=254, param2=0},
		{name="vlf_core:dirt", prob=254, param2=0},
		{name="vlf_core:dirt", prob=254, param2=0},
		{name="vlf_core:dirt", prob=254, param2=0},
		{name="vlf_core:dirt", prob=254, param2=0},
		{name="air", prob=254, param2=0},
		{name="air", prob=254, param2=0},
		{name="air", prob=254, param2=0},
		{name="vlf_cauldrons:cauldron", prob=254, param2=0},
		{name="air", prob=254, param2=0},
		{name="air", prob=254, param2=0},
		{name="air", prob=254, param2=0},
		{name="air", prob=254, param2=0},
		{name="vlf_core:cobble", prob=254, param2=0},
		{name="vlf_core:stonebrick", prob=254, param2=0},
		{name="vlf_core:stonebrick", prob=254, param2=0},
		{name="vlf_core:cobble", prob=254, param2=0},
		{name="air", prob=254, param2=0},
		{name="air", prob=254, param2=0},
		{name="air", prob=254, param2=0},
		{name="air", prob=254, param2=0},
		{name="air", prob=254, param2=0},
		{name="air", prob=254, param2=0},
		{name="air", prob=254, param2=0},
		{name="air", prob=254, param2=0},
		{name="vlf_core:wood", prob=254, param2=0},
		{name="vlf_stairs:stair_wood", prob=254, param2=2},
		{name="vlf_stairs:stair_wood", prob=254, param2=2},
		{name="vlf_core:wood", prob=254, param2=0},
		{name="air", prob=254, param2=0},
		{name="air", prob=254, param2=0},
		{name="air", prob=254, param2=0},
		{name="air", prob=254, param2=0},
		{name="air", prob=254, param2=0},
		{name="air", prob=254, param2=0},
		{name="air", prob=254, param2=0},
		{name="air", prob=254, param2=0},
		{name="vlf_core:wood", prob=254, param2=0},
		{name="air", prob=254, param2=0},
		{name="air", prob=254, param2=0},
		{name="vlf_core:wood", prob=254, param2=0},
		{name="air", prob=254, param2=0},
		{name="air", prob=254, param2=0},
		{name="air", prob=254, param2=0},
		{name="air", prob=254, param2=0},
		{name="air", prob=254, param2=0},
		{name="air", prob=254, param2=0},
		{name="air", prob=254, param2=0},
		{name="air", prob=254, param2=0},
		{name="vlf_core:glass", prob=254, param2=0},
		{name="air", prob=254, param2=0},
		{name="air", prob=254, param2=0},
		{name="vlf_core:glass", prob=254, param2=0},
		{name="air", prob=254, param2=0},
		{name="air", prob=254, param2=0},
		{name="air", prob=254, param2=0},
		{name="air", prob=254, param2=0},
		{name="air", prob=254, param2=0},
		{name="air", prob=254, param2=0},
		{name="air", prob=254, param2=0},
		{name="air", prob=254, param2=0},
		{name="vlf_core:glass", prob=254, param2=0},
		{name="air", prob=254, param2=0},
		{name="air", prob=254, param2=0},
		{name="vlf_core:glass", prob=254, param2=0},
		{name="air", prob=254, param2=0},
		{name="air", prob=254, param2=0},
		{name="air", prob=254, param2=0},
		{name="air", prob=254, param2=0},
		{name="air", prob=254, param2=0},
		{name="air", prob=254, param2=0},
		{name="air", prob=254, param2=0},
		{name="air", prob=254, param2=0},
		{name="vlf_core:wood", prob=254, param2=0},
		{name="air", prob=254, param2=0},
		{name="air", prob=254, param2=0},
		{name="vlf_core:wood", prob=254, param2=0},
		{name="air", prob=254, param2=0},
		{name="air", prob=254, param2=0},
		{name="air", prob=254, param2=0},
		{name="air", prob=254, param2=0},
		{name="air", prob=254, param2=0},
		{name="air", prob=254, param2=0},
		{name="air", prob=254, param2=0},
		{name="air", prob=254, param2=0},
		{name="vlf_stairs:slab_wood", prob=254, param2=0},
		{name="vlf_core:glass", prob=254, param2=0},
		{name="vlf_core:glass", prob=254, param2=0},
		{name="vlf_stairs:slab_wood", prob=254, param2=0},
		{name="air", prob=254, param2=0},
		{name="air", prob=254, param2=0},
		{name="air", prob=254, param2=0},
		{name="air", prob=254, param2=0},
		{name="air", prob=254, param2=0},
		{name="air", prob=254, param2=0},
		{name="air", prob=254, param2=0},
		{name="air", prob=254, param2=0},
		{name="air", prob=254, param2=0},
		{name="air", prob=254, param2=0},
		{name="air", prob=254, param2=0},
		{name="air", prob=254, param2=0},
		{name="vlf_core:dirt", prob=254, param2=0},
		{name="vlf_core:dirt", prob=254, param2=0},
		{name="vlf_core:dirt", prob=254, param2=0},
		{name="vlf_core:dirt", prob=254, param2=0},
		{name="vlf_core:dirt", prob=254, param2=0},
		{name="vlf_core:dirt", prob=254, param2=0},
		{name="vlf_core:dirt", prob=254, param2=0},
		{name="vlf_core:dirt", prob=254, param2=0},
		{name="vlf_core:dirt", prob=254, param2=0},
		{name="vlf_core:dirt", prob=254, param2=0},
		{name="vlf_core:dirt", prob=254, param2=0},
		{name="vlf_core:dirt", prob=254, param2=0},
		{name="air", prob=254, param2=0},
		{name="air", prob=254, param2=0},
		{name="air", prob=254, param2=0},
		{name="air", prob=254, param2=0},
		{name="air", prob=254, param2=0},
		{name="air", prob=254, param2=0},
		{name="air", prob=254, param2=0},
		{name="air", prob=254, param2=0},
		{name="vlf_core:cobble", prob=254, param2=0},
		{name="vlf_core:stonebrick", prob=254, param2=0},
		{name="vlf_core:stonebrick", prob=254, param2=0},
		{name="vlf_core:cobble", prob=254, param2=0},
		{name="air", prob=254, param2=0},
		{name="air", prob=254, param2=0},
		{name="air", prob=254, param2=0},
		{name="air", prob=254, param2=0},
		{name="air", prob=254, param2=0},
		{name="air", prob=254, param2=0},
		{name="air", prob=254, param2=0},
		{name="air", prob=254, param2=0},
		{name="vlf_core:wood", prob=254, param2=0},
		{name="air", prob=254, param2=0},
		{name="air", prob=254, param2=0},
		{name="vlf_core:wood", prob=254, param2=0},
		{name="air", prob=254, param2=0},
		{name="air", prob=254, param2=0},
		{name="air", prob=254, param2=0},
		{name="air", prob=254, param2=0},
		{name="air", prob=254, param2=0},
		{name="air", prob=254, param2=0},
		{name="air", prob=254, param2=0},
		{name="air", prob=254, param2=0},
		{name="vlf_core:wood", prob=254, param2=0},
		{name="air", prob=254, param2=0},
		{name="air", prob=254, param2=0},
		{name="vlf_core:wood", prob=254, param2=0},
		{name="air", prob=254, param2=0},
		{name="air", prob=254, param2=0},
		{name="air", prob=254, param2=0},
		{name="air", prob=254, param2=0},
		{name="air", prob=254, param2=0},
		{name="air", prob=254, param2=0},
		{name="air", prob=254, param2=0},
		{name="air", prob=254, param2=0},
		{name="vlf_core:glass", prob=254, param2=0},
		{name="air", prob=254, param2=0},
		{name="air", prob=254, param2=0},
		{name="vlf_core:glass", prob=254, param2=0},
		{name="air", prob=254, param2=0},
		{name="air", prob=254, param2=0},
		{name="air", prob=254, param2=0},
		{name="air", prob=254, param2=0},
		{name="air", prob=254, param2=0},
		{name="air", prob=254, param2=0},
		{name="air", prob=254, param2=0},
		{name="air", prob=254, param2=0},
		{name="vlf_core:glass", prob=254, param2=0},
		{name="air", prob=254, param2=0},
		{name="air", prob=254, param2=0},
		{name="vlf_core:glass", prob=254, param2=0},
		{name="air", prob=254, param2=0},
		{name="air", prob=254, param2=0},
		{name="air", prob=254, param2=0},
		{name="air", prob=254, param2=0},
		{name="air", prob=254, param2=0},
		{name="air", prob=254, param2=0},
		{name="air", prob=254, param2=0},
		{name="air", prob=254, param2=0},
		{name="vlf_core:wood", prob=254, param2=0},
		{name="air", prob=254, param2=0},
		{name="air", prob=254, param2=0},
		{name="vlf_core:wood", prob=254, param2=0},
		{name="air", prob=254, param2=0},
		{name="air", prob=254, param2=0},
		{name="air", prob=254, param2=0},
		{name="air", prob=254, param2=0},
		{name="air", prob=254, param2=0},
		{name="air", prob=254, param2=0},
		{name="air", prob=254, param2=0},
		{name="air", prob=254, param2=0},
		{name="vlf_stairs:slab_wood", prob=254, param2=0},
		{name="vlf_core:glass", prob=254, param2=0},
		{name="vlf_core:glass", prob=254, param2=0},
		{name="vlf_stairs:slab_wood", prob=254, param2=0},
		{name="air", prob=254, param2=0},
		{name="air", prob=254, param2=0},
		{name="air", prob=254, param2=0},
		{name="air", prob=254, param2=0},
		{name="air", prob=254, param2=0},
		{name="air", prob=254, param2=0},
		{name="air", prob=254, param2=0},
		{name="air", prob=254, param2=0},
		{name="air", prob=254, param2=0},
		{name="air", prob=254, param2=0},
		{name="air", prob=254, param2=0},
		{name="air", prob=254, param2=0},
		{name="vlf_core:dirt", prob=254, param2=0},
		{name="vlf_core:dirt", prob=254, param2=0},
		{name="vlf_core:dirt", prob=254, param2=0},
		{name="vlf_core:dirt", prob=254, param2=0},
		{name="vlf_core:dirt", prob=254, param2=0},
		{name="vlf_core:dirt", prob=254, param2=0},
		{name="vlf_core:dirt", prob=254, param2=0},
		{name="vlf_core:dirt", prob=254, param2=0},
		{name="vlf_core:dirt", prob=254, param2=0},
		{name="vlf_core:dirt", prob=254, param2=0},
		{name="vlf_core:dirt", prob=254, param2=0},
		{name="vlf_core:dirt", prob=254, param2=0},
		{name="air", prob=254, param2=0},
		{name="air", prob=254, param2=0},
		{name="air", prob=254, param2=0},
		{name="air", prob=254, param2=0},
		{name="air", prob=254, param2=0},
		{name="air", prob=254, param2=0},
		{name="air", prob=254, param2=0},
		{name="air", prob=254, param2=0},
		{name="vlf_core:cobble", prob=254, param2=0},
		{name="vlf_core:stonebrick", prob=254, param2=0},
		{name="vlf_core:stonebrick", prob=254, param2=0},
		{name="vlf_core:cobble", prob=254, param2=0},
		{name="air", prob=254, param2=0},
		{name="air", prob=254, param2=0},
		{name="air", prob=254, param2=0},
		{name="air", prob=254, param2=0},
		{name="air", prob=254, param2=0},
		{name="air", prob=254, param2=0},
		{name="air", prob=254, param2=0},
		{name="air", prob=254, param2=0},
		{name="vlf_core:wood", prob=254, param2=0},
		{name="vlf_fences:fence", prob=254, param2=0},
		{name="air", prob=254, param2=0},
		{name="vlf_core:wood", prob=254, param2=0},
		{name="air", prob=254, param2=0},
		{name="air", prob=254, param2=0},
		{name="air", prob=254, param2=0},
		{name="air", prob=254, param2=0},
		{name="air", prob=254, param2=0},
		{name="air", prob=254, param2=0},
		{name="air", prob=254, param2=0},
		{name="air", prob=254, param2=0},
		{name="vlf_core:wood", prob=254, param2=0},
		{name="mesecons_pressureplates:pressure_plate_wood_off", prob=254, param2=0},
		{name="air", prob=254, param2=0},
		{name="vlf_core:wood", prob=254, param2=0},
		{name="air", prob=254, param2=0},
		{name="air", prob=254, param2=0},
		{name="air", prob=254, param2=0},
		{name="air", prob=254, param2=0},
		{name="air", prob=254, param2=0},
		{name="air", prob=254, param2=0},
		{name="air", prob=254, param2=0},
		{name="air", prob=254, param2=0},
		{name="vlf_core:glass", prob=254, param2=0},
		{name="air", prob=254, param2=0},
		{name="air", prob=254, param2=0},
		{name="vlf_core:glass", prob=254, param2=0},
		{name="air", prob=254, param2=0},
		{name="air", prob=254, param2=0},
		{name="air", prob=254, param2=0},
		{name="air", prob=254, param2=0},
		{name="air", prob=254, param2=0},
		{name="air", prob=254, param2=0},
		{name="air", prob=254, param2=0},
		{name="air", prob=254, param2=0},
		{name="vlf_core:glass", prob=254, param2=0},
		{name="vlf_torches:torch_wall", prob=254, param2=4},
		{name="vlf_torches:torch_wall", prob=254, param2=4},
		{name="vlf_core:glass", prob=254, param2=0},
		{name="air", prob=254, param2=0},
		{name="air", prob=254, param2=0},
		{name="air", prob=254, param2=0},
		{name="air", prob=254, param2=0},
		{name="air", prob=254, param2=0},
		{name="air", prob=254, param2=0},
		{name="air", prob=254, param2=0},
		{name="air", prob=254, param2=0},
		{name="vlf_core:wood", prob=254, param2=0},
		{name="air", prob=254, param2=0},
		{name="air", prob=254, param2=0},
		{name="vlf_core:wood", prob=254, param2=0},
		{name="air", prob=254, param2=0},
		{name="air", prob=254, param2=0},
		{name="air", prob=254, param2=0},
		{name="air", prob=254, param2=0},
		{name="air", prob=254, param2=0},
		{name="air", prob=254, param2=0},
		{name="air", prob=254, param2=0},
		{name="air", prob=254, param2=0},
		{name="vlf_stairs:slab_wood", prob=254, param2=0},
		{name="vlf_core:glass", prob=254, param2=0},
		{name="vlf_core:glass", prob=254, param2=0},
		{name="vlf_stairs:slab_wood", prob=254, param2=0},
		{name="air", prob=254, param2=0},
		{name="air", prob=254, param2=0},
		{name="air", prob=254, param2=0},
		{name="air", prob=254, param2=0},
		{name="air", prob=254, param2=0},
		{name="air", prob=254, param2=0},
		{name="air", prob=254, param2=0},
		{name="air", prob=254, param2=0},
		{name="air", prob=254, param2=0},
		{name="air", prob=254, param2=0},
		{name="air", prob=254, param2=0},
		{name="air", prob=254, param2=0},
		{name="vlf_core:dirt", prob=254, param2=0},
		{name="vlf_core:dirt", prob=254, param2=0},
		{name="vlf_core:dirt", prob=254, param2=0},
		{name="vlf_core:dirt", prob=254, param2=0},
		{name="vlf_core:dirt", prob=254, param2=0},
		{name="vlf_core:dirt", prob=254, param2=0},
		{name="vlf_core:dirt", prob=254, param2=0},
		{name="vlf_core:dirt", prob=254, param2=0},
		{name="vlf_core:dirt", prob=254, param2=0},
		{name="vlf_core:dirt", prob=254, param2=0},
		{name="vlf_core:dirt", prob=254, param2=0},
		{name="vlf_core:dirt", prob=254, param2=0},
		{name="air", prob=254, param2=0},
		{name="air", prob=254, param2=0},
		{name="vlf_core:cobble", prob=254, param2=0},
		{name="vlf_core:cobble", prob=254, param2=0},
		{name="vlf_core:cobble", prob=254, param2=0},
		{name="vlf_core:cobble", prob=254, param2=0},
		{name="vlf_core:cobble", prob=254, param2=0},
		{name="vlf_core:cobble", prob=254, param2=0},
		{name="vlf_core:cobble", prob=254, param2=0},
		{name="vlf_core:cobble", prob=254, param2=0},
		{name="vlf_core:stonebrick", prob=254, param2=0},
		{name="vlf_core:cobble", prob=254, param2=0},
		{name="air", prob=254, param2=0},
		{name="air", prob=254, param2=0},
		{name="vlf_core:stonebrick", prob=254, param2=0},
		{name="vlf_core:wood", prob=254, param2=0},
		{name="vlf_core:wood", prob=254, param2=0},
		{name="vlf_core:wood", prob=254, param2=0},
		{name="vlf_core:wood", prob=254, param2=0},
		{name="vlf_core:wood", prob=254, param2=0},
		{name="vlf_core:cobble", prob=254, param2=0},
		{name="vlf_core:wood", prob=254, param2=0},
		{name="vlf_doors:wooden_door_b_1", prob=254, param2=0},
		{name="vlf_core:wood", prob=254, param2=0},
		{name="air", prob=254, param2=0},
		{name="air", prob=254, param2=0},
		{name="vlf_core:stonebrick", prob=254, param2=0},
		{name="vlf_core:wood", prob=254, param2=0},
		{name="vlf_core:wood", prob=254, param2=0},
		{name="vlf_core:wood", prob=254, param2=0},
		{name="vlf_core:wood", prob=254, param2=0},
		{name="vlf_core:wood", prob=254, param2=0},
		{name="vlf_core:cobble", prob=254, param2=0},
		{name="vlf_core:wood", prob=254, param2=0},
		{name="vlf_doors:wooden_door_t_1", prob=254, param2=0},
		{name="vlf_core:wood", prob=254, param2=0},
		{name="air", prob=254, param2=0},
		{name="air", prob=254, param2=0},
		{name="vlf_core:stonebrick", prob=254, param2=0},
		{name="vlf_core:glass", prob=254, param2=0},
		{name="vlf_core:glass", prob=254, param2=0},
		{name="vlf_core:glass", prob=254, param2=0},
		{name="vlf_core:glass", prob=254, param2=0},
		{name="vlf_core:glass", prob=254, param2=0},
		{name="vlf_core:cobble", prob=254, param2=0},
		{name="vlf_core:wood", prob=254, param2=0},
		{name="vlf_core:wood", prob=254, param2=0},
		{name="vlf_core:glass", prob=254, param2=0},
		{name="air", prob=254, param2=0},
		{name="air", prob=254, param2=0},
		{name="vlf_core:stonebrick", prob=254, param2=0},
		{name="vlf_core:glass", prob=254, param2=0},
		{name="vlf_core:glass", prob=254, param2=0},
		{name="vlf_core:glass", prob=254, param2=0},
		{name="vlf_core:glass", prob=254, param2=0},
		{name="vlf_core:glass", prob=254, param2=0},
		{name="vlf_core:cobble", prob=254, param2=0},
		{name="vlf_core:wood", prob=254, param2=0},
		{name="vlf_core:wood", prob=254, param2=0},
		{name="vlf_core:glass", prob=254, param2=0},
		{name="air", prob=254, param2=0},
		{name="air", prob=254, param2=0},
		{name="vlf_core:wood", prob=254, param2=0},
		{name="vlf_core:wood", prob=254, param2=0},
		{name="vlf_core:wood", prob=254, param2=0},
		{name="vlf_core:wood", prob=254, param2=0},
		{name="vlf_core:wood", prob=254, param2=0},
		{name="vlf_core:wood", prob=254, param2=0},
		{name="vlf_core:wood", prob=254, param2=0},
		{name="vlf_core:wood", prob=254, param2=0},
		{name="vlf_core:wood", prob=254, param2=0},
		{name="vlf_core:wood", prob=254, param2=0},
		{name="air", prob=254, param2=0},
		{name="air", prob=254, param2=0},
		{name="air", prob=254, param2=0},
		{name="vlf_stairs:slab_wood", prob=254, param2=0},
		{name="vlf_stairs:slab_wood", prob=254, param2=0},
		{name="vlf_stairs:slab_wood", prob=254, param2=0},
		{name="vlf_stairs:slab_wood", prob=254, param2=0},
		{name="vlf_stairs:slab_wood", prob=254, param2=0},
		{name="vlf_stairs:slab_wood", prob=254, param2=0},
		{name="vlf_core:glass", prob=254, param2=0},
		{name="vlf_core:glass", prob=254, param2=0},
		{name="vlf_stairs:slab_wood", prob=254, param2=0},
		{name="air", prob=254, param2=0},
		{name="air", prob=254, param2=0},
		{name="air", prob=254, param2=0},
		{name="air", prob=254, param2=0},
		{name="air", prob=254, param2=0},
		{name="air", prob=254, param2=0},
		{name="air", prob=254, param2=0},
		{name="air", prob=254, param2=0},
		{name="air", prob=254, param2=0},
		{name="air", prob=254, param2=0},
		{name="air", prob=254, param2=0},
		{name="air", prob=254, param2=0},
		{name="vlf_core:dirt", prob=254, param2=0},
		{name="vlf_core:dirt", prob=254, param2=0},
		{name="vlf_core:dirt", prob=254, param2=0},
		{name="vlf_core:dirt", prob=254, param2=0},
		{name="vlf_core:dirt", prob=254, param2=0},
		{name="vlf_core:dirt", prob=254, param2=0},
		{name="vlf_core:dirt", prob=254, param2=0},
		{name="vlf_core:dirt", prob=254, param2=0},
		{name="vlf_core:dirt", prob=254, param2=0},
		{name="vlf_core:dirt", prob=254, param2=0},
		{name="vlf_core:dirt", prob=254, param2=0},
		{name="vlf_core:dirt", prob=254, param2=0},
		{name="vlf_stairs:stair_stonebrick_outer", prob=254, param2=1},
		{name="vlf_stairs:stair_stonebrick", prob=254, param2=0},
		{name="vlf_core:cobble", prob=254, param2=0},
		{name="vlf_core:stonebrick", prob=254, param2=0},
		{name="vlf_core:stonebrick", prob=254, param2=0},
		{name="vlf_core:stonebrick", prob=254, param2=0},
		{name="vlf_core:stonebrick", prob=254, param2=0},
		{name="vlf_core:stonebrick", prob=254, param2=0},
		{name="vlf_core:stonebrick", prob=254, param2=0},
		{name="vlf_core:stonebrick", prob=254, param2=0},
		{name="vlf_core:stonebrick", prob=254, param2=0},
		{name="vlf_core:cobble", prob=254, param2=0},
		{name="air", prob=254, param2=0},
		{name="air", prob=254, param2=0},
		{name="vlf_core:wood", prob=254, param2=0},
		{name="vlf_stairs:slab_wood_top", prob=254, param2=0},
		{name="vlf_books:bookshelf", prob=254, param2=0},
		{name="vlf_books:bookshelf", prob=254, param2=0},
		{name="vlf_stairs:stair_wood", prob=254, param2=2},
		{name="vlf_books:bookshelf", prob=254, param2=0},
		{name="vlf_books:bookshelf", prob=254, param2=0},
		{name="air", prob=254, param2=0},
		{name="air", prob=254, param2=0},
		{name="vlf_core:wood", prob=254, param2=0},
		{name="air", prob=254, param2=0},
		{name="air", prob=254, param2=0},
		{name="vlf_core:wood", prob=254, param2=0},
		{name="vlf_torches:torch", prob=254, param2=1},
		{name="vlf_books:bookshelf", prob=254, param2=0},
		{name="vlf_books:bookshelf", prob=254, param2=0},
		{name="air", prob=254, param2=0},
		{name="vlf_books:bookshelf", prob=254, param2=0},
		{name="vlf_books:bookshelf", prob=254, param2=0},
		{name="air", prob=254, param2=0},
		{name="air", prob=254, param2=0},
		{name="vlf_core:wood", prob=254, param2=0},
		{name="air", prob=254, param2=0},
		{name="air", prob=254, param2=0},
		{name="vlf_core:glass", prob=254, param2=0},
		{name="air", prob=254, param2=0},
		{name="air", prob=254, param2=0},
		{name="air", prob=254, param2=0},
		{name="air", prob=254, param2=0},
		{name="air", prob=254, param2=0},
		{name="air", prob=254, param2=0},
		{name="air", prob=254, param2=0},
		{name="air", prob=254, param2=0},
		{name="vlf_core:glass", prob=254, param2=0},
		{name="air", prob=254, param2=0},
		{name="air", prob=254, param2=0},
		{name="vlf_core:glass", prob=254, param2=0},
		{name="air", prob=254, param2=0},
		{name="air", prob=254, param2=0},
		{name="air", prob=254, param2=0},
		{name="air", prob=254, param2=0},
		{name="air", prob=254, param2=0},
		{name="air", prob=254, param2=0},
		{name="air", prob=254, param2=0},
		{name="air", prob=254, param2=0},
		{name="vlf_core:glass", prob=254, param2=0},
		{name="air", prob=254, param2=0},
		{name="vlf_stairs:stair_wood", prob=254, param2=23},
		{name="vlf_core:wood", prob=254, param2=0},
		{name="air", prob=254, param2=0},
		{name="air", prob=254, param2=0},
		{name="air", prob=254, param2=0},
		{name="air", prob=254, param2=0},
		{name="air", prob=254, param2=0},
		{name="air", prob=254, param2=0},
		{name="air", prob=254, param2=0},
		{name="air", prob=254, param2=0},
		{name="vlf_core:wood", prob=254, param2=0},
		{name="air", prob=254, param2=0},
		{name="air", prob=254, param2=0},
		{name="vlf_stairs:slab_wood", prob=254, param2=0},
		{name="vlf_core:glass", prob=254, param2=0},
		{name="vlf_core:glass", prob=254, param2=0},
		{name="vlf_core:glass", prob=254, param2=0},
		{name="vlf_core:glass", prob=254, param2=0},
		{name="vlf_core:glass", prob=254, param2=0},
		{name="vlf_core:glass", prob=254, param2=0},
		{name="vlf_core:glass", prob=254, param2=0},
		{name="vlf_core:glass", prob=254, param2=0},
		{name="vlf_stairs:slab_wood", prob=254, param2=0},
		{name="air", prob=254, param2=0},
		{name="air", prob=254, param2=0},
		{name="air", prob=254, param2=0},
		{name="air", prob=254, param2=0},
		{name="air", prob=254, param2=0},
		{name="air", prob=254, param2=0},
		{name="air", prob=254, param2=0},
		{name="air", prob=254, param2=0},
		{name="air", prob=254, param2=0},
		{name="air", prob=254, param2=0},
		{name="air", prob=254, param2=0},
		{name="air", prob=254, param2=0},
		{name="vlf_core:dirt", prob=254, param2=0},
		{name="vlf_core:dirt", prob=254, param2=0},
		{name="vlf_core:dirt", prob=254, param2=0},
		{name="vlf_core:dirt", prob=254, param2=0},
		{name="vlf_core:dirt", prob=254, param2=0},
		{name="vlf_core:dirt", prob=254, param2=0},
		{name="vlf_core:dirt", prob=254, param2=0},
		{name="vlf_core:dirt", prob=254, param2=0},
		{name="vlf_core:dirt", prob=254, param2=0},
		{name="vlf_core:dirt", prob=254, param2=0},
		{name="vlf_core:dirt", prob=254, param2=0},
		{name="vlf_core:dirt", prob=254, param2=0},
		{name="vlf_stairs:stair_stonebrick", prob=254, param2=1},
		{name="vlf_core:stonebrickcarved", prob=254, param2=0},
		{name="vlf_core:stonebrickcarved", prob=254, param2=0},
		{name="vlf_core:stonebrick", prob=254, param2=0},
		{name="vlf_core:stonebrick", prob=254, param2=0},
		{name="vlf_core:stonebrick", prob=254, param2=0},
		{name="vlf_core:stonebrick", prob=254, param2=0},
		{name="vlf_core:stonebrick", prob=254, param2=0},
		{name="vlf_core:stonebrick", prob=254, param2=0},
		{name="vlf_core:stonebrick", prob=254, param2=0},
		{name="vlf_core:stonebrick", prob=254, param2=0},
		{name="vlf_core:cobble", prob=254, param2=0},
		{name="air", prob=254, param2=0},
		{name="air", prob=254, param2=0},
		{name="vlf_doors:wooden_door_b_1", prob=254, param2=1},
		{name="air", prob=254, param2=0},
		{name="air", prob=254, param2=0},
		{name="air", prob=254, param2=0},
		{name="air", prob=254, param2=0},
		{name="air", prob=254, param2=0},
		{name="air", prob=254, param2=0},
		{name="air", prob=254, param2=0},
		{name="air", prob=254, param2=0},
		{name="vlf_core:wood", prob=254, param2=0},
		{name="air", prob=254, param2=0},
		{name="air", prob=254, param2=0},
		{name="vlf_doors:wooden_door_t_1", prob=254, param2=1},
		{name="air", prob=254, param2=0},
		{name="air", prob=254, param2=0},
		{name="air", prob=254, param2=0},
		{name="air", prob=254, param2=0},
		{name="air", prob=254, param2=0},
		{name="air", prob=254, param2=0},
		{name="air", prob=254, param2=0},
		{name="air", prob=254, param2=0},
		{name="vlf_core:wood", prob=254, param2=0},
		{name="air", prob=254, param2=0},
		{name="air", prob=254, param2=0},
		{name="vlf_core:glass", prob=254, param2=0},
		{name="air", prob=254, param2=0},
		{name="air", prob=254, param2=0},
		{name="air", prob=254, param2=0},
		{name="air", prob=254, param2=0},
		{name="air", prob=254, param2=0},
		{name="air", prob=254, param2=0},
		{name="air", prob=254, param2=0},
		{name="air", prob=254, param2=0},
		{name="vlf_core:glass", prob=254, param2=0},
		{name="air", prob=254, param2=0},
		{name="air", prob=254, param2=0},
		{name="vlf_core:glass", prob=254, param2=0},
		{name="air", prob=254, param2=0},
		{name="air", prob=254, param2=0},
		{name="air", prob=254, param2=0},
		{name="air", prob=254, param2=0},
		{name="air", prob=254, param2=0},
		{name="air", prob=254, param2=0},
		{name="air", prob=254, param2=0},
		{name="air", prob=254, param2=0},
		{name="vlf_core:glass", prob=254, param2=0},
		{name="air", prob=254, param2=0},
		{name="vlf_stairs:stair_wood", prob=254, param2=23},
		{name="vlf_core:wood", prob=254, param2=0},
		{name="air", prob=254, param2=0},
		{name="air", prob=254, param2=0},
		{name="air", prob=254, param2=0},
		{name="air", prob=254, param2=0},
		{name="air", prob=254, param2=0},
		{name="air", prob=254, param2=0},
		{name="air", prob=254, param2=0},
		{name="air", prob=254, param2=0},
		{name="vlf_core:wood", prob=254, param2=0},
		{name="air", prob=254, param2=0},
		{name="air", prob=254, param2=0},
		{name="vlf_stairs:slab_wood", prob=254, param2=0},
		{name="vlf_core:glass", prob=254, param2=0},
		{name="vlf_core:glass", prob=254, param2=0},
		{name="vlf_core:glass", prob=254, param2=0},
		{name="vlf_core:glass", prob=254, param2=0},
		{name="vlf_core:glass", prob=254, param2=0},
		{name="vlf_core:glass", prob=254, param2=0},
		{name="vlf_core:glass", prob=254, param2=0},
		{name="vlf_core:glass", prob=254, param2=0},
		{name="vlf_stairs:slab_wood", prob=254, param2=0},
		{name="air", prob=254, param2=0},
		{name="air", prob=254, param2=0},
		{name="air", prob=254, param2=0},
		{name="air", prob=254, param2=0},
		{name="air", prob=254, param2=0},
		{name="air", prob=254, param2=0},
		{name="air", prob=254, param2=0},
		{name="air", prob=254, param2=0},
		{name="air", prob=254, param2=0},
		{name="air", prob=254, param2=0},
		{name="air", prob=254, param2=0},
		{name="air", prob=254, param2=0},
		{name="vlf_core:dirt", prob=254, param2=0},
		{name="vlf_core:dirt", prob=254, param2=0},
		{name="vlf_core:dirt", prob=254, param2=0},
		{name="vlf_core:dirt", prob=254, param2=0},
		{name="vlf_core:dirt", prob=254, param2=0},
		{name="vlf_core:dirt", prob=254, param2=0},
		{name="vlf_core:dirt", prob=254, param2=0},
		{name="vlf_core:dirt", prob=254, param2=0},
		{name="vlf_core:dirt", prob=254, param2=0},
		{name="vlf_core:dirt", prob=254, param2=0},
		{name="vlf_core:dirt", prob=254, param2=0},
		{name="vlf_core:dirt", prob=254, param2=0},
		{name="vlf_stairs:stair_stonebrick", prob=254, param2=1},
		{name="vlf_core:stonebrickcarved", prob=254, param2=0},
		{name="vlf_core:cobble", prob=254, param2=0},
		{name="vlf_core:stonebrick", prob=254, param2=0},
		{name="vlf_core:stonebrick", prob=254, param2=0},
		{name="vlf_core:stonebrick", prob=254, param2=0},
		{name="vlf_core:stonebrick", prob=254, param2=0},
		{name="vlf_core:stonebrick", prob=254, param2=0},
		{name="vlf_core:stonebrick", prob=254, param2=0},
		{name="vlf_core:stonebrick", prob=254, param2=0},
		{name="vlf_core:stonebrick", prob=254, param2=0},
		{name="vlf_core:cobble", prob=254, param2=0},
		{name="air", prob=254, param2=0},
		{name="air", prob=254, param2=0},
		{name="vlf_core:stonebrick", prob=254, param2=0},
		{name="air", prob=254, param2=0},
		{name="air", prob=254, param2=0},
		{name="air", prob=254, param2=0},
		{name="air", prob=254, param2=0},
		{name="air", prob=254, param2=0},
		{name="air", prob=254, param2=0},
		{name="air", prob=254, param2=0},
		{name="air", prob=254, param2=0},
		{name="vlf_core:wood", prob=254, param2=0},
		{name="air", prob=254, param2=0},
		{name="vlf_torches:torch_wall", prob=254, param2=2},
		{name="vlf_core:stonebrick", prob=254, param2=0},
		{name="air", prob=254, param2=0},
		{name="air", prob=254, param2=0},
		{name="air", prob=254, param2=0},
		{name="air", prob=254, param2=0},
		{name="air", prob=254, param2=0},
		{name="air", prob=254, param2=0},
		{name="air", prob=254, param2=0},
		{name="air", prob=254, param2=0},
		{name="vlf_core:wood", prob=254, param2=0},
		{name="air", prob=254, param2=0},
		{name="air", prob=254, param2=0},
		{name="vlf_core:glass", prob=254, param2=0},
		{name="air", prob=254, param2=0},
		{name="air", prob=254, param2=0},
		{name="air", prob=254, param2=0},
		{name="air", prob=254, param2=0},
		{name="air", prob=254, param2=0},
		{name="air", prob=254, param2=0},
		{name="air", prob=254, param2=0},
		{name="air", prob=254, param2=0},
		{name="vlf_core:glass", prob=254, param2=0},
		{name="air", prob=254, param2=0},
		{name="air", prob=254, param2=0},
		{name="vlf_core:glass", prob=254, param2=0},
		{name="air", prob=254, param2=0},
		{name="air", prob=254, param2=0},
		{name="air", prob=254, param2=0},
		{name="air", prob=254, param2=0},
		{name="air", prob=254, param2=0},
		{name="air", prob=254, param2=0},
		{name="air", prob=254, param2=0},
		{name="air", prob=254, param2=0},
		{name="vlf_core:glass", prob=254, param2=0},
		{name="air", prob=254, param2=0},
		{name="vlf_stairs:stair_wood", prob=254, param2=23},
		{name="vlf_core:wood", prob=254, param2=0},
		{name="air", prob=254, param2=0},
		{name="air", prob=254, param2=0},
		{name="air", prob=254, param2=0},
		{name="air", prob=254, param2=0},
		{name="air", prob=254, param2=0},
		{name="air", prob=254, param2=0},
		{name="air", prob=254, param2=0},
		{name="air", prob=254, param2=0},
		{name="vlf_core:wood", prob=254, param2=0},
		{name="air", prob=254, param2=0},
		{name="air", prob=254, param2=0},
		{name="vlf_stairs:slab_wood", prob=254, param2=0},
		{name="vlf_core:glass", prob=254, param2=0},
		{name="vlf_core:glass", prob=254, param2=0},
		{name="vlf_core:glass", prob=254, param2=0},
		{name="vlf_core:glass", prob=254, param2=0},
		{name="vlf_core:glass", prob=254, param2=0},
		{name="vlf_core:glass", prob=254, param2=0},
		{name="vlf_core:glass", prob=254, param2=0},
		{name="vlf_core:glass", prob=254, param2=0},
		{name="vlf_stairs:slab_wood", prob=254, param2=0},
		{name="air", prob=254, param2=0},
		{name="air", prob=254, param2=0},
		{name="air", prob=254, param2=0},
		{name="air", prob=254, param2=0},
		{name="air", prob=254, param2=0},
		{name="air", prob=254, param2=0},
		{name="air", prob=254, param2=0},
		{name="air", prob=254, param2=0},
		{name="air", prob=254, param2=0},
		{name="air", prob=254, param2=0},
		{name="air", prob=254, param2=0},
		{name="air", prob=254, param2=0},
		{name="vlf_core:dirt", prob=254, param2=0},
		{name="vlf_core:dirt", prob=254, param2=0},
		{name="vlf_core:dirt", prob=254, param2=0},
		{name="vlf_core:dirt", prob=254, param2=0},
		{name="vlf_core:dirt", prob=254, param2=0},
		{name="vlf_core:dirt", prob=254, param2=0},
		{name="vlf_core:dirt", prob=254, param2=0},
		{name="vlf_core:dirt", prob=254, param2=0},
		{name="vlf_core:dirt", prob=254, param2=0},
		{name="vlf_core:dirt", prob=254, param2=0},
		{name="vlf_core:dirt", prob=254, param2=0},
		{name="vlf_core:dirt", prob=254, param2=0},
		{name="vlf_stairs:stair_stonebrick_outer", prob=254, param2=2},
		{name="vlf_stairs:stair_stonebrick", prob=254, param2=2},
		{name="vlf_core:cobble", prob=254, param2=0},
		{name="vlf_core:stonebrick", prob=254, param2=0},
		{name="vlf_core:stonebrick", prob=254, param2=0},
		{name="vlf_core:stonebrick", prob=254, param2=0},
		{name="vlf_core:stonebrick", prob=254, param2=0},
		{name="vlf_core:stonebrick", prob=254, param2=0},
		{name="vlf_core:stonebrick", prob=254, param2=0},
		{name="vlf_core:stonebrick", prob=254, param2=0},
		{name="vlf_core:stonebrick", prob=254, param2=0},
		{name="vlf_core:cobble", prob=254, param2=0},
		{name="air", prob=254, param2=0},
		{name="air", prob=254, param2=0},
		{name="vlf_core:wood", prob=254, param2=0},
		{name="vlf_stairs:slab_wood_top", prob=254, param2=0},
		{name="vlf_books:bookshelf", prob=254, param2=0},
		{name="vlf_books:bookshelf", prob=254, param2=0},
		{name="vlf_stairs:stair_wood", prob=254, param2=0},
		{name="vlf_books:bookshelf", prob=254, param2=0},
		{name="vlf_books:bookshelf", prob=254, param2=0},
		{name="vlf_stairs:stair_wood", prob=254, param2=0},
		{name="vlf_stairs:slab_wood_top", prob=254, param2=0},
		{name="vlf_core:wood", prob=254, param2=0},
		{name="air", prob=254, param2=0},
		{name="air", prob=254, param2=0},
		{name="vlf_core:wood", prob=254, param2=0},
		{name="vlf_flowerpots:flower_pot_blue_orchid", prob=254, param2=0},
		{name="vlf_books:bookshelf", prob=254, param2=0},
		{name="vlf_books:bookshelf", prob=254, param2=0},
		{name="air", prob=254, param2=0},
		{name="vlf_books:bookshelf", prob=254, param2=0},
		{name="vlf_books:bookshelf", prob=254, param2=0},
		{name="air", prob=254, param2=0},
		{name="vlf_flowerpots:flower_pot_blue_orchid", prob=254, param2=0},
		{name="vlf_core:wood", prob=254, param2=0},
		{name="air", prob=254, param2=0},
		{name="air", prob=254, param2=0},
		{name="vlf_core:glass", prob=254, param2=0},
		{name="air", prob=254, param2=0},
		{name="air", prob=254, param2=0},
		{name="air", prob=254, param2=0},
		{name="air", prob=254, param2=0},
		{name="air", prob=254, param2=0},
		{name="air", prob=254, param2=0},
		{name="air", prob=254, param2=0},
		{name="air", prob=254, param2=0},
		{name="vlf_core:glass", prob=254, param2=0},
		{name="air", prob=254, param2=0},
		{name="air", prob=254, param2=0},
		{name="vlf_core:glass", prob=254, param2=0},
		{name="air", prob=254, param2=0},
		{name="air", prob=254, param2=0},
		{name="air", prob=254, param2=0},
		{name="air", prob=254, param2=0},
		{name="air", prob=254, param2=0},
		{name="air", prob=254, param2=0},
		{name="air", prob=254, param2=0},
		{name="air", prob=254, param2=0},
		{name="vlf_core:glass", prob=254, param2=0},
		{name="air", prob=254, param2=0},
		{name="vlf_stairs:stair_wood", prob=254, param2=23},
		{name="vlf_core:wood", prob=254, param2=0},
		{name="air", prob=254, param2=0},
		{name="air", prob=254, param2=0},
		{name="air", prob=254, param2=0},
		{name="air", prob=254, param2=0},
		{name="air", prob=254, param2=0},
		{name="air", prob=254, param2=0},
		{name="air", prob=254, param2=0},
		{name="air", prob=254, param2=0},
		{name="vlf_core:wood", prob=254, param2=0},
		{name="air", prob=254, param2=0},
		{name="air", prob=254, param2=0},
		{name="vlf_stairs:slab_wood", prob=254, param2=0},
		{name="vlf_core:glass", prob=254, param2=0},
		{name="vlf_core:glass", prob=254, param2=0},
		{name="vlf_core:glass", prob=254, param2=0},
		{name="vlf_core:glass", prob=254, param2=0},
		{name="vlf_core:glass", prob=254, param2=0},
		{name="vlf_core:glass", prob=254, param2=0},
		{name="vlf_core:glass", prob=254, param2=0},
		{name="vlf_core:glass", prob=254, param2=0},
		{name="vlf_stairs:slab_wood", prob=254, param2=0},
		{name="air", prob=254, param2=0},
		{name="air", prob=254, param2=0},
		{name="air", prob=254, param2=0},
		{name="air", prob=254, param2=0},
		{name="air", prob=254, param2=0},
		{name="air", prob=254, param2=0},
		{name="air", prob=254, param2=0},
		{name="air", prob=254, param2=0},
		{name="air", prob=254, param2=0},
		{name="air", prob=254, param2=0},
		{name="air", prob=254, param2=0},
		{name="air", prob=254, param2=0},
		{name="vlf_core:dirt", prob=254, param2=0},
		{name="vlf_core:dirt", prob=254, param2=0},
		{name="vlf_core:dirt", prob=254, param2=0},
		{name="vlf_core:dirt", prob=254, param2=0},
		{name="vlf_core:dirt", prob=254, param2=0},
		{name="vlf_core:dirt", prob=254, param2=0},
		{name="vlf_core:dirt", prob=254, param2=0},
		{name="vlf_core:dirt", prob=254, param2=0},
		{name="vlf_core:dirt", prob=254, param2=0},
		{name="vlf_core:dirt", prob=254, param2=0},
		{name="vlf_core:dirt", prob=254, param2=0},
		{name="vlf_core:dirt", prob=254, param2=0},
		{name="air", prob=254, param2=0},
		{name="air", prob=254, param2=0},
		{name="vlf_core:cobble", prob=254, param2=0},
		{name="vlf_core:cobble", prob=254, param2=0},
		{name="vlf_core:cobble", prob=254, param2=0},
		{name="vlf_core:cobble", prob=254, param2=0},
		{name="vlf_core:cobble", prob=254, param2=0},
		{name="vlf_core:cobble", prob=254, param2=0},
		{name="vlf_core:cobble", prob=254, param2=0},
		{name="vlf_core:cobble", prob=254, param2=0},
		{name="vlf_core:cobble", prob=254, param2=0},
		{name="vlf_core:cobble", prob=254, param2=0},
		{name="air", prob=254, param2=0},
		{name="air", prob=254, param2=0},
		{name="vlf_core:stonebrick", prob=254, param2=0},
		{name="vlf_core:wood", prob=254, param2=0},
		{name="vlf_core:wood", prob=254, param2=0},
		{name="vlf_core:wood", prob=254, param2=0},
		{name="vlf_core:wood", prob=254, param2=0},
		{name="vlf_core:wood", prob=254, param2=0},
		{name="vlf_core:wood", prob=254, param2=0},
		{name="vlf_core:wood", prob=254, param2=0},
		{name="vlf_core:wood", prob=254, param2=0},
		{name="vlf_core:stonebrick", prob=254, param2=0},
		{name="air", prob=254, param2=0},
		{name="air", prob=254, param2=0},
		{name="vlf_core:stonebrick", prob=254, param2=0},
		{name="vlf_core:wood", prob=254, param2=0},
		{name="vlf_core:wood", prob=254, param2=0},
		{name="vlf_core:wood", prob=254, param2=0},
		{name="vlf_core:wood", prob=254, param2=0},
		{name="vlf_core:wood", prob=254, param2=0},
		{name="vlf_core:wood", prob=254, param2=0},
		{name="vlf_core:wood", prob=254, param2=0},
		{name="vlf_core:wood", prob=254, param2=0},
		{name="vlf_core:stonebrick", prob=254, param2=0},
		{name="air", prob=254, param2=0},
		{name="air", prob=254, param2=0},
		{name="vlf_core:stonebrick", prob=254, param2=0},
		{name="vlf_core:glass", prob=254, param2=0},
		{name="vlf_core:glass", prob=254, param2=0},
		{name="vlf_core:glass", prob=254, param2=0},
		{name="vlf_core:glass", prob=254, param2=0},
		{name="vlf_core:glass", prob=254, param2=0},
		{name="vlf_core:glass", prob=254, param2=0},
		{name="vlf_core:glass", prob=254, param2=0},
		{name="vlf_core:glass", prob=254, param2=0},
		{name="vlf_core:stonebrick", prob=254, param2=0},
		{name="air", prob=254, param2=0},
		{name="air", prob=254, param2=0},
		{name="vlf_core:stonebrick", prob=254, param2=0},
		{name="vlf_core:glass", prob=254, param2=0},
		{name="vlf_core:glass", prob=254, param2=0},
		{name="vlf_core:glass", prob=254, param2=0},
		{name="vlf_core:glass", prob=254, param2=0},
		{name="vlf_core:glass", prob=254, param2=0},
		{name="vlf_core:glass", prob=254, param2=0},
		{name="vlf_core:glass", prob=254, param2=0},
		{name="vlf_core:glass", prob=254, param2=0},
		{name="vlf_core:stonebrick", prob=254, param2=0},
		{name="air", prob=254, param2=0},
		{name="air", prob=254, param2=0},
		{name="vlf_core:wood", prob=254, param2=0},
		{name="vlf_core:wood", prob=254, param2=0},
		{name="vlf_core:wood", prob=254, param2=0},
		{name="vlf_core:wood", prob=254, param2=0},
		{name="vlf_core:wood", prob=254, param2=0},
		{name="vlf_core:wood", prob=254, param2=0},
		{name="vlf_core:wood", prob=254, param2=0},
		{name="vlf_core:wood", prob=254, param2=0},
		{name="vlf_core:wood", prob=254, param2=0},
		{name="vlf_core:wood", prob=254, param2=0},
		{name="air", prob=254, param2=0},
		{name="air", prob=254, param2=0},
		{name="air", prob=254, param2=0},
		{name="vlf_stairs:slab_wood", prob=254, param2=0},
		{name="vlf_stairs:slab_wood", prob=254, param2=0},
		{name="vlf_stairs:slab_wood", prob=254, param2=0},
		{name="vlf_stairs:slab_wood", prob=254, param2=0},
		{name="vlf_stairs:slab_wood", prob=254, param2=0},
		{name="vlf_stairs:slab_wood", prob=254, param2=0},
		{name="vlf_stairs:slab_wood", prob=254, param2=0},
		{name="vlf_stairs:slab_wood", prob=254, param2=0},
		{name="air", prob=254, param2=0},
		{name="air", prob=254, param2=0},
		{name="air", prob=254, param2=0},
		{name="air", prob=254, param2=0},
		{name="air", prob=254, param2=0},
		{name="air", prob=254, param2=0},
		{name="air", prob=254, param2=0},
		{name="air", prob=254, param2=0},
		{name="air", prob=254, param2=0},
		{name="air", prob=254, param2=0},
		{name="air", prob=254, param2=0},
		{name="air", prob=254, param2=0},
		{name="air", prob=254, param2=0},
		{name="vlf_core:dirt", prob=254, param2=0},
		{name="vlf_core:dirt", prob=254, param2=0},
		{name="vlf_core:dirt", prob=254, param2=0},
		{name="vlf_core:dirt", prob=254, param2=0},
		{name="vlf_core:dirt", prob=254, param2=0},
		{name="vlf_core:dirt", prob=254, param2=0},
		{name="vlf_core:dirt", prob=254, param2=0},
		{name="vlf_core:dirt", prob=254, param2=0},
		{name="vlf_core:dirt", prob=254, param2=0},
		{name="vlf_core:dirt", prob=254, param2=0},
		{name="vlf_core:dirt", prob=254, param2=0},
		{name="vlf_core:dirt", prob=254, param2=0},
		{name="air", prob=254, param2=0},
		{name="air", prob=254, param2=0},
		{name="air", prob=254, param2=0},
		{name="air", prob=254, param2=0},
		{name="air", prob=254, param2=0},
		{name="air", prob=254, param2=0},
		{name="air", prob=254, param2=0},
		{name="air", prob=254, param2=0},
		{name="air", prob=254, param2=0},
		{name="air", prob=254, param2=0},
		{name="air", prob=254, param2=0},
		{name="air", prob=254, param2=0},
		{name="air", prob=254, param2=0},
		{name="air", prob=254, param2=0},
		{name="air", prob=254, param2=0},
		{name="air", prob=254, param2=0},
		{name="air", prob=254, param2=0},
		{name="air", prob=254, param2=0},
		{name="air", prob=254, param2=0},
		{name="air", prob=254, param2=0},
		{name="air", prob=254, param2=0},
		{name="air", prob=254, param2=0},
		{name="air", prob=254, param2=0},
		{name="air", prob=254, param2=0},
		{name="air", prob=254, param2=0},
		{name="air", prob=254, param2=0},
		{name="air", prob=254, param2=0},
		{name="air", prob=254, param2=0},
		{name="air", prob=254, param2=0},
		{name="air", prob=254, param2=0},
		{name="air", prob=254, param2=0},
		{name="air", prob=254, param2=0},
		{name="air", prob=254, param2=0},
		{name="air", prob=254, param2=0},
		{name="air", prob=254, param2=0},
		{name="air", prob=254, param2=0},
		{name="air", prob=254, param2=0},
		{name="air", prob=254, param2=0},
		{name="air", prob=254, param2=0},
		{name="air", prob=254, param2=0},
		{name="air", prob=254, param2=0},
		{name="air", prob=254, param2=0},
		{name="air", prob=254, param2=0},
		{name="air", prob=254, param2=0},
		{name="air", prob=254, param2=0},
		{name="air", prob=254, param2=0},
		{name="air", prob=254, param2=0},
		{name="air", prob=254, param2=0},
		{name="air", prob=254, param2=0},
		{name="air", prob=254, param2=0},
		{name="air", prob=254, param2=0},
		{name="air", prob=254, param2=0},
		{name="air", prob=254, param2=0},
		{name="air", prob=254, param2=0},
		{name="air", prob=254, param2=0},
		{name="air", prob=254, param2=0},
		{name="air", prob=254, param2=0},
		{name="air", prob=254, param2=0},
		{name="air", prob=254, param2=0},
		{name="air", prob=254, param2=0},
		{name="air", prob=254, param2=0},
		{name="air", prob=254, param2=0},
		{name="air", prob=254, param2=0},
		{name="air", prob=254, param2=0},
		{name="air", prob=254, param2=0},
		{name="air", prob=254, param2=0},
		{name="air", prob=254, param2=0},
		{name="air", prob=254, param2=0},
		{name="air", prob=254, param2=0},
		{name="air", prob=254, param2=0},
		{name="air", prob=254, param2=0},
		{name="air", prob=254, param2=0},
		{name="air", prob=254, param2=0},
		{name="air", prob=254, param2=0},
		{name="air", prob=254, param2=0},
		{name="air", prob=254, param2=0},
		{name="air", prob=254, param2=0},
		{name="air", prob=254, param2=0},
		{name="air", prob=254, param2=0},
		{name="air", prob=254, param2=0},
		{name="air", prob=254, param2=0},
		{name="air", prob=254, param2=0},
		{name="air", prob=254, param2=0},
		{name="air", prob=254, param2=0},
		{name="air", prob=254, param2=0},
		{name="air", prob=254, param2=0},
		{name="air", prob=254, param2=0},
		{name="air", prob=254, param2=0},
		{name="air", prob=254, param2=0},
		{name="air", prob=254, param2=0},
		{name="air", prob=254, param2=0},
		{name="air", prob=254, param2=0},
		{name="air", prob=254, param2=0},
		{name="air", prob=254, param2=0},
		{name="air", prob=254, param2=0},
		{name="air", prob=254, param2=0},
	},
}
