schematic = {
	size = {x=9, y=9, z=12},
	yslice_prob = {
		{ypos=0, prob=254},
		{ypos=1, prob=254},
		{ypos=2, prob=254},
		{ypos=3, prob=254},
		{ypos=4, prob=254},
		{ypos=5, prob=254},
		{ypos=6, prob=254},
		{ypos=7, prob=254},
		{ypos=8, prob=254},
	},
	data = {
		{name="vlf_core:dirt", prob=254, param2=0},
		{name="vlf_core:dirt", prob=254, param2=0},
		{name="vlf_core:dirt", prob=254, param2=0},
		{name="vlf_core:dirt", prob=254, param2=0},
		{name="vlf_core:dirt", prob=254, param2=0},
		{name="vlf_core:dirt", prob=254, param2=0},
		{name="vlf_core:dirt", prob=254, param2=0},
		{name="vlf_core:dirt", prob=254, param2=0},
		{name="vlf_core:dirt", prob=254, param2=0},
		{name="air", prob=254, param2=0},
		{name="air", prob=254, param2=0},
		{name="air", prob=254, param2=0},
		{name="air", prob=254, param2=0},
		{name="air", prob=254, param2=0},
		{name="air", prob=254, param2=0},
		{name="air", prob=254, param2=0},
		{name="air", prob=254, param2=0},
		{name="air", prob=254, param2=0},
		{name="air", prob=254, param2=0},
		{name="air", prob=254, param2=0},
		{name="air", prob=254, param2=0},
		{name="air", prob=254, param2=0},
		{name="air", prob=254, param2=0},
		{name="air", prob=254, param2=0},
		{name="air", prob=254, param2=0},
		{name="air", prob=254, param2=0},
		{name="air", prob=254, param2=0},
		{name="air", prob=254, param2=0},
		{name="air", prob=254, param2=0},
		{name="air", prob=254, param2=0},
		{name="air", prob=254, param2=0},
		{name="air", prob=254, param2=0},
		{name="air", prob=254, param2=0},
		{name="air", prob=254, param2=0},
		{name="air", prob=254, param2=0},
		{name="air", prob=254, param2=0},
		{name="air", prob=254, param2=0},
		{name="air", prob=254, param2=0},
		{name="air", prob=254, param2=0},
		{name="air", prob=254, param2=0},
		{name="air", prob=254, param2=0},
		{name="air", prob=254, param2=0},
		{name="air", prob=254, param2=0},
		{name="air", prob=254, param2=0},
		{name="air", prob=254, param2=0},
		{name="air", prob=254, param2=0},
		{name="air", prob=254, param2=0},
		{name="air", prob=254, param2=0},
		{name="air", prob=254, param2=0},
		{name="air", prob=254, param2=0},
		{name="air", prob=254, param2=0},
		{name="air", prob=254, param2=0},
		{name="air", prob=254, param2=0},
		{name="air", prob=254, param2=0},
		{name="air", prob=254, param2=0},
		{name="air", prob=254, param2=0},
		{name="air", prob=254, param2=0},
		{name="air", prob=254, param2=0},
		{name="air", prob=254, param2=0},
		{name="air", prob=254, param2=0},
		{name="air", prob=254, param2=0},
		{name="air", prob=254, param2=0},
		{name="air", prob=254, param2=0},
		{name="air", prob=254, param2=0},
		{name="air", prob=254, param2=0},
		{name="air", prob=254, param2=0},
		{name="air", prob=254, param2=0},
		{name="air", prob=254, param2=0},
		{name="air", prob=254, param2=0},
		{name="air", prob=254, param2=0},
		{name="air", prob=254, param2=0},
		{name="air", prob=254, param2=0},
		{name="air", prob=254, param2=0},
		{name="air", prob=254, param2=0},
		{name="air", prob=254, param2=0},
		{name="air", prob=254, param2=0},
		{name="air", prob=254, param2=0},
		{name="air", prob=254, param2=0},
		{name="air", prob=254, param2=0},
		{name="air", prob=254, param2=0},
		{name="air", prob=254, param2=0},
		{name="vlf_core:dirt", prob=254, param2=0},
		{name="vlf_core:dirt", prob=254, param2=0},
		{name="vlf_core:dirt", prob=254, param2=0},
		{name="vlf_core:dirt", prob=254, param2=0},
		{name="vlf_core:dirt", prob=254, param2=0},
		{name="vlf_core:dirt", prob=254, param2=0},
		{name="vlf_core:dirt", prob=254, param2=0},
		{name="vlf_core:dirt", prob=254, param2=0},
		{name="vlf_core:dirt", prob=254, param2=0},
		{name="air", prob=254, param2=0},
		{name="air", prob=254, param2=0},
		{name="air", prob=254, param2=0},
		{name="air", prob=254, param2=0},
		{name="air", prob=254, param2=0},
		{name="air", prob=254, param2=0},
		{name="air", prob=254, param2=0},
		{name="air", prob=254, param2=0},
		{name="air", prob=254, param2=0},
		{name="air", prob=254, param2=0},
		{name="air", prob=254, param2=0},
		{name="air", prob=254, param2=0},
		{name="air", prob=254, param2=0},
		{name="air", prob=254, param2=0},
		{name="air", prob=254, param2=0},
		{name="air", prob=254, param2=0},
		{name="air", prob=254, param2=0},
		{name="air", prob=254, param2=0},
		{name="air", prob=254, param2=0},
		{name="air", prob=254, param2=0},
		{name="air", prob=254, param2=0},
		{name="air", prob=254, param2=0},
		{name="air", prob=254, param2=0},
		{name="air", prob=254, param2=0},
		{name="air", prob=254, param2=0},
		{name="air", prob=254, param2=0},
		{name="air", prob=254, param2=0},
		{name="air", prob=254, param2=0},
		{name="air", prob=254, param2=0},
		{name="air", prob=254, param2=0},
		{name="air", prob=254, param2=0},
		{name="air", prob=254, param2=0},
		{name="air", prob=254, param2=0},
		{name="air", prob=254, param2=0},
		{name="air", prob=254, param2=0},
		{name="air", prob=254, param2=0},
		{name="air", prob=254, param2=0},
		{name="vlf_stairs:slab_wood_top", prob=254, param2=0},
		{name="vlf_stairs:slab_wood_top", prob=254, param2=0},
		{name="vlf_stairs:slab_wood_top", prob=254, param2=0},
		{name="vlf_stairs:slab_wood_top", prob=254, param2=0},
		{name="vlf_stairs:slab_wood_top", prob=254, param2=0},
		{name="vlf_stairs:slab_wood_top", prob=254, param2=0},
		{name="vlf_stairs:slab_wood_top", prob=254, param2=0},
		{name="vlf_stairs:slab_wood_top", prob=254, param2=0},
		{name="air", prob=254, param2=0},
		{name="air", prob=254, param2=0},
		{name="air", prob=254, param2=0},
		{name="air", prob=254, param2=0},
		{name="air", prob=254, param2=0},
		{name="air", prob=254, param2=0},
		{name="air", prob=254, param2=0},
		{name="air", prob=254, param2=0},
		{name="air", prob=254, param2=0},
		{name="air", prob=254, param2=0},
		{name="air", prob=254, param2=0},
		{name="air", prob=254, param2=0},
		{name="air", prob=254, param2=0},
		{name="air", prob=254, param2=0},
		{name="air", prob=254, param2=0},
		{name="air", prob=254, param2=0},
		{name="air", prob=254, param2=0},
		{name="air", prob=254, param2=0},
		{name="air", prob=254, param2=0},
		{name="air", prob=254, param2=0},
		{name="air", prob=254, param2=0},
		{name="air", prob=254, param2=0},
		{name="air", prob=254, param2=0},
		{name="air", prob=254, param2=0},
		{name="air", prob=254, param2=0},
		{name="air", prob=254, param2=0},
		{name="air", prob=254, param2=0},
		{name="vlf_core:dirt", prob=254, param2=0},
		{name="vlf_core:dirt", prob=254, param2=0},
		{name="vlf_core:dirt", prob=254, param2=0},
		{name="vlf_core:dirt", prob=254, param2=0},
		{name="vlf_core:dirt", prob=254, param2=0},
		{name="vlf_core:dirt", prob=254, param2=0},
		{name="vlf_core:dirt", prob=254, param2=0},
		{name="vlf_core:dirt", prob=254, param2=0},
		{name="vlf_core:dirt", prob=254, param2=0},
		{name="air", prob=254, param2=0},
		{name="air", prob=254, param2=0},
		{name="vlf_core:cobble", prob=254, param2=0},
		{name="vlf_core:cobble", prob=254, param2=0},
		{name="vlf_core:cobble", prob=254, param2=0},
		{name="vlf_core:cobble", prob=254, param2=0},
		{name="vlf_core:cobble", prob=254, param2=0},
		{name="vlf_core:cobble", prob=254, param2=0},
		{name="air", prob=254, param2=0},
		{name="air", prob=254, param2=0},
		{name="air", prob=254, param2=0},
		{name="vlf_core:tree", prob=254, param2=0},
		{name="vlf_core:tree", prob=254, param2=0},
		{name="vlf_core:tree", prob=254, param2=0},
		{name="vlf_core:tree", prob=254, param2=0},
		{name="vlf_core:tree", prob=254, param2=0},
		{name="vlf_core:tree", prob=254, param2=0},
		{name="air", prob=254, param2=0},
		{name="air", prob=254, param2=0},
		{name="air", prob=254, param2=0},
		{name="vlf_core:tree", prob=254, param2=0},
		{name="vlf_core:tree", prob=254, param2=0},
		{name="xpanes:pane_natural_flat", prob=254, param2=0},
		{name="xpanes:pane_natural_flat", prob=254, param2=0},
		{name="vlf_core:tree", prob=254, param2=0},
		{name="vlf_core:tree", prob=254, param2=0},
		{name="air", prob=254, param2=0},
		{name="air", prob=254, param2=0},
		{name="air", prob=254, param2=0},
		{name="vlf_core:tree", prob=254, param2=0},
		{name="vlf_core:tree", prob=254, param2=0},
		{name="xpanes:pane_natural_flat", prob=254, param2=0},
		{name="xpanes:pane_natural_flat", prob=254, param2=0},
		{name="vlf_core:tree", prob=254, param2=0},
		{name="vlf_core:tree", prob=254, param2=0},
		{name="air", prob=254, param2=0},
		{name="air", prob=254, param2=0},
		{name="vlf_stairs:slab_wood_top", prob=254, param2=0},
		{name="vlf_core:cobble", prob=254, param2=0},
		{name="vlf_core:cobble", prob=254, param2=0},
		{name="vlf_core:cobble", prob=254, param2=0},
		{name="vlf_core:cobble", prob=254, param2=0},
		{name="vlf_core:cobble", prob=254, param2=0},
		{name="vlf_core:cobble", prob=254, param2=0},
		{name="vlf_stairs:slab_wood_top", prob=254, param2=0},
		{name="air", prob=254, param2=0},
		{name="air", prob=254, param2=0},
		{name="vlf_core:tree", prob=254, param2=0},
		{name="vlf_core:wood", prob=254, param2=0},
		{name="vlf_core:wood", prob=254, param2=0},
		{name="vlf_core:wood", prob=254, param2=0},
		{name="vlf_core:wood", prob=254, param2=0},
		{name="vlf_core:tree", prob=254, param2=0},
		{name="air", prob=254, param2=0},
		{name="air", prob=254, param2=0},
		{name="air", prob=254, param2=0},
		{name="air", prob=254, param2=0},
		{name="air", prob=254, param2=0},
		{name="air", prob=254, param2=0},
		{name="air", prob=254, param2=0},
		{name="air", prob=254, param2=0},
		{name="air", prob=254, param2=0},
		{name="air", prob=254, param2=0},
		{name="air", prob=254, param2=0},
		{name="air", prob=254, param2=0},
		{name="air", prob=254, param2=0},
		{name="air", prob=254, param2=0},
		{name="air", prob=254, param2=0},
		{name="air", prob=254, param2=0},
		{name="air", prob=254, param2=0},
		{name="air", prob=254, param2=0},
		{name="air", prob=254, param2=0},
		{name="vlf_core:dirt", prob=254, param2=0},
		{name="vlf_core:dirt", prob=254, param2=0},
		{name="vlf_core:dirt", prob=254, param2=0},
		{name="vlf_core:dirt", prob=254, param2=0},
		{name="vlf_core:dirt", prob=254, param2=0},
		{name="vlf_core:dirt", prob=254, param2=0},
		{name="vlf_core:dirt", prob=254, param2=0},
		{name="vlf_core:dirt", prob=254, param2=0},
		{name="vlf_core:dirt", prob=254, param2=0},
		{name="air", prob=254, param2=0},
		{name="air", prob=254, param2=0},
		{name="vlf_core:cobble", prob=254, param2=0},
		{name="vlf_core:cobble", prob=254, param2=0},
		{name="vlf_core:cobble", prob=254, param2=0},
		{name="vlf_core:cobble", prob=254, param2=0},
		{name="vlf_core:cobble", prob=254, param2=0},
		{name="vlf_core:cobble", prob=254, param2=0},
		{name="air", prob=254, param2=0},
		{name="air", prob=254, param2=0},
		{name="air", prob=254, param2=0},
		{name="vlf_core:cobble", prob=254, param2=0},
		{name="vlf_barrels:barrel_closed", prob=254, param2=2},
		{name="air", prob=254, param2=0},
		{name="vlf_beds:bed_red_bottom", prob=254, param2=1},
		{name="vlf_beds:bed_red_top", prob=254, param2=1},
		{name="vlf_core:wood", prob=254, param2=0},
		{name="air", prob=254, param2=0},
		{name="air", prob=254, param2=0},
		{name="air", prob=254, param2=0},
		{name="vlf_core:cobble", prob=254, param2=0},
		{name="air", prob=254, param2=0},
		{name="air", prob=254, param2=0},
		{name="air", prob=254, param2=0},
		{name="air", prob=254, param2=0},
		{name="vlf_core:wood", prob=254, param2=0},
		{name="air", prob=254, param2=0},
		{name="air", prob=254, param2=0},
		{name="air", prob=254, param2=0},
		{name="vlf_core:cobble", prob=254, param2=0},
		{name="air", prob=254, param2=0},
		{name="air", prob=254, param2=0},
		{name="air", prob=254, param2=0},
		{name="air", prob=254, param2=0},
		{name="vlf_core:wood", prob=254, param2=0},
		{name="air", prob=254, param2=0},
		{name="air", prob=254, param2=0},
		{name="vlf_stairs:slab_wood_top", prob=254, param2=0},
		{name="vlf_core:tree", prob=254, param2=0},
		{name="vlf_walls:cobble_12", prob=254, param2=0},
		{name="air", prob=254, param2=0},
		{name="air", prob=254, param2=0},
		{name="vlf_walls:cobble_9", prob=254, param2=0},
		{name="vlf_core:cobble", prob=254, param2=0},
		{name="vlf_stairs:slab_wood_top", prob=254, param2=0},
		{name="air", prob=254, param2=0},
		{name="air", prob=254, param2=0},
		{name="vlf_core:wood", prob=254, param2=0},
		{name="vlf_torches:torch", prob=254, param2=1},
		{name="air", prob=254, param2=0},
		{name="air", prob=254, param2=0},
		{name="vlf_torches:torch", prob=254, param2=1},
		{name="vlf_core:wood", prob=254, param2=0},
		{name="air", prob=254, param2=0},
		{name="air", prob=254, param2=0},
		{name="air", prob=254, param2=0},
		{name="air", prob=254, param2=0},
		{name="vlf_core:tree", prob=254, param2=0},
		{name="vlf_core:wood", prob=254, param2=0},
		{name="vlf_core:wood", prob=254, param2=0},
		{name="vlf_core:tree", prob=254, param2=0},
		{name="air", prob=254, param2=0},
		{name="air", prob=254, param2=0},
		{name="air", prob=254, param2=0},
		{name="air", prob=254, param2=0},
		{name="air", prob=254, param2=0},
		{name="air", prob=254, param2=0},
		{name="air", prob=254, param2=0},
		{name="air", prob=254, param2=0},
		{name="air", prob=254, param2=0},
		{name="air", prob=254, param2=0},
		{name="air", prob=254, param2=0},
		{name="vlf_core:dirt", prob=254, param2=0},
		{name="vlf_core:dirt", prob=254, param2=0},
		{name="vlf_core:dirt", prob=254, param2=0},
		{name="vlf_core:dirt", prob=254, param2=0},
		{name="vlf_core:dirt", prob=254, param2=0},
		{name="vlf_core:dirt", prob=254, param2=0},
		{name="vlf_core:dirt", prob=254, param2=0},
		{name="vlf_core:dirt", prob=254, param2=0},
		{name="vlf_core:dirt", prob=254, param2=0},
		{name="air", prob=254, param2=0},
		{name="air", prob=254, param2=0},
		{name="vlf_core:cobble", prob=254, param2=0},
		{name="vlf_core:cobble", prob=254, param2=0},
		{name="vlf_core:cobble", prob=254, param2=0},
		{name="vlf_core:cobble", prob=254, param2=0},
		{name="vlf_core:cobble", prob=254, param2=0},
		{name="vlf_core:cobble", prob=254, param2=0},
		{name="air", prob=254, param2=0},
		{name="air", prob=254, param2=0},
		{name="air", prob=254, param2=0},
		{name="vlf_core:cobble", prob=254, param2=0},
		{name="air", prob=254, param2=0},
		{name="air", prob=254, param2=0},
		{name="air", prob=254, param2=0},
		{name="air", prob=254, param2=0},
		{name="vlf_core:wood", prob=254, param2=0},
		{name="air", prob=254, param2=0},
		{name="air", prob=254, param2=0},
		{name="air", prob=254, param2=0},
		{name="xpanes:pane_natural_flat", prob=254, param2=1},
		{name="air", prob=254, param2=0},
		{name="air", prob=254, param2=0},
		{name="air", prob=254, param2=0},
		{name="air", prob=254, param2=0},
		{name="vlf_core:wood", prob=254, param2=0},
		{name="air", prob=254, param2=0},
		{name="air", prob=254, param2=0},
		{name="air", prob=254, param2=0},
		{name="vlf_core:wood", prob=254, param2=0},
		{name="air", prob=254, param2=0},
		{name="air", prob=254, param2=0},
		{name="air", prob=254, param2=0},
		{name="air", prob=254, param2=0},
		{name="vlf_core:wood", prob=254, param2=0},
		{name="air", prob=254, param2=0},
		{name="air", prob=254, param2=0},
		{name="vlf_stairs:slab_wood_top", prob=254, param2=0},
		{name="vlf_core:tree", prob=254, param2=0},
		{name="air", prob=254, param2=0},
		{name="air", prob=254, param2=0},
		{name="air", prob=254, param2=0},
		{name="air", prob=254, param2=0},
		{name="vlf_core:cobble", prob=254, param2=0},
		{name="vlf_stairs:slab_wood_top", prob=254, param2=0},
		{name="air", prob=254, param2=0},
		{name="air", prob=254, param2=0},
		{name="vlf_core:wood", prob=254, param2=0},
		{name="air", prob=254, param2=0},
		{name="air", prob=254, param2=0},
		{name="air", prob=254, param2=0},
		{name="air", prob=254, param2=0},
		{name="vlf_core:wood", prob=254, param2=0},
		{name="air", prob=254, param2=0},
		{name="air", prob=254, param2=0},
		{name="air", prob=254, param2=0},
		{name="air", prob=254, param2=0},
		{name="vlf_core:wood", prob=254, param2=0},
		{name="vlf_core:tree", prob=254, param2=12},
		{name="vlf_core:tree", prob=254, param2=12},
		{name="vlf_core:wood", prob=254, param2=0},
		{name="air", prob=254, param2=0},
		{name="air", prob=254, param2=0},
		{name="air", prob=254, param2=0},
		{name="air", prob=254, param2=0},
		{name="air", prob=254, param2=0},
		{name="air", prob=254, param2=0},
		{name="air", prob=254, param2=0},
		{name="air", prob=254, param2=0},
		{name="air", prob=254, param2=0},
		{name="air", prob=254, param2=0},
		{name="air", prob=254, param2=0},
		{name="vlf_core:dirt", prob=254, param2=0},
		{name="vlf_core:dirt", prob=254, param2=0},
		{name="vlf_core:dirt", prob=254, param2=0},
		{name="vlf_core:dirt", prob=254, param2=0},
		{name="vlf_core:dirt", prob=254, param2=0},
		{name="vlf_core:dirt", prob=254, param2=0},
		{name="vlf_core:dirt", prob=254, param2=0},
		{name="vlf_core:dirt", prob=254, param2=0},
		{name="vlf_core:dirt", prob=254, param2=0},
		{name="air", prob=254, param2=0},
		{name="vlf_walls:cobble_1", prob=254, param2=0},
		{name="vlf_core:cobble", prob=254, param2=0},
		{name="vlf_core:cobble", prob=254, param2=0},
		{name="vlf_core:stonebrickcarved", prob=254, param2=0},
		{name="vlf_core:stonebrickcarved", prob=254, param2=0},
		{name="vlf_core:cobble", prob=254, param2=0},
		{name="vlf_core:cobble", prob=254, param2=0},
		{name="air", prob=254, param2=0},
		{name="air", prob=254, param2=0},
		{name="vlf_torches:torch", prob=254, param2=1},
		{name="vlf_core:tree", prob=254, param2=0},
		{name="air", prob=254, param2=0},
		{name="air", prob=254, param2=0},
		{name="air", prob=254, param2=0},
		{name="air", prob=254, param2=0},
		{name="vlf_core:wood", prob=254, param2=0},
		{name="air", prob=254, param2=0},
		{name="air", prob=254, param2=0},
		{name="air", prob=254, param2=0},
		{name="vlf_core:tree", prob=254, param2=0},
		{name="air", prob=254, param2=0},
		{name="air", prob=254, param2=0},
		{name="air", prob=254, param2=0},
		{name="vlf_stairs:slab_stone_top", prob=254, param2=0},
		{name="vlf_core:wood", prob=254, param2=0},
		{name="air", prob=254, param2=0},
		{name="air", prob=254, param2=0},
		{name="air", prob=254, param2=0},
		{name="vlf_core:wood", prob=254, param2=0},
		{name="air", prob=254, param2=0},
		{name="air", prob=254, param2=0},
		{name="air", prob=254, param2=0},
		{name="vlf_flowerpots:flower_pot_blue_orchid", prob=254, param2=0},
		{name="vlf_core:wood", prob=254, param2=0},
		{name="air", prob=254, param2=0},
		{name="air", prob=254, param2=0},
		{name="vlf_stairs:slab_wood_top", prob=254, param2=0},
		{name="vlf_core:cobble", prob=254, param2=0},
		{name="air", prob=254, param2=0},
		{name="air", prob=254, param2=0},
		{name="air", prob=254, param2=0},
		{name="air", prob=254, param2=0},
		{name="vlf_core:cobble", prob=254, param2=0},
		{name="vlf_stairs:slab_wood_top", prob=254, param2=0},
		{name="air", prob=254, param2=0},
		{name="air", prob=254, param2=0},
		{name="vlf_core:wood", prob=254, param2=0},
		{name="air", prob=254, param2=0},
		{name="air", prob=254, param2=0},
		{name="air", prob=254, param2=0},
		{name="air", prob=254, param2=0},
		{name="vlf_core:wood", prob=254, param2=0},
		{name="air", prob=254, param2=0},
		{name="air", prob=254, param2=0},
		{name="air", prob=254, param2=0},
		{name="air", prob=254, param2=0},
		{name="vlf_core:wood", prob=254, param2=0},
		{name="vlf_core:tree", prob=254, param2=12},
		{name="vlf_core:tree", prob=254, param2=12},
		{name="vlf_core:wood", prob=254, param2=0},
		{name="air", prob=254, param2=0},
		{name="air", prob=254, param2=0},
		{name="air", prob=254, param2=0},
		{name="air", prob=254, param2=0},
		{name="air", prob=254, param2=0},
		{name="air", prob=254, param2=0},
		{name="air", prob=254, param2=0},
		{name="air", prob=254, param2=0},
		{name="air", prob=254, param2=0},
		{name="air", prob=254, param2=0},
		{name="air", prob=254, param2=0},
		{name="vlf_core:dirt", prob=254, param2=0},
		{name="vlf_core:dirt", prob=254, param2=0},
		{name="vlf_core:dirt", prob=254, param2=0},
		{name="vlf_core:dirt", prob=254, param2=0},
		{name="vlf_core:dirt", prob=254, param2=0},
		{name="vlf_core:dirt", prob=254, param2=0},
		{name="vlf_core:dirt", prob=254, param2=0},
		{name="vlf_core:dirt", prob=254, param2=0},
		{name="vlf_core:dirt", prob=254, param2=0},
		{name="air", prob=254, param2=0},
		{name="vlf_stairs:stair_cobble", prob=254, param2=1},
		{name="vlf_core:cobble", prob=254, param2=0},
		{name="vlf_core:cobble", prob=254, param2=0},
		{name="vlf_core:stonebrickcarved", prob=254, param2=0},
		{name="vlf_core:stonebrickcarved", prob=254, param2=0},
		{name="vlf_core:cobble", prob=254, param2=0},
		{name="vlf_core:cobble", prob=254, param2=0},
		{name="air", prob=254, param2=0},
		{name="air", prob=254, param2=0},
		{name="air", prob=254, param2=0},
		{name="vlf_doors:wooden_door_b_1", prob=254, param2=1},
		{name="air", prob=254, param2=0},
		{name="air", prob=254, param2=0},
		{name="air", prob=254, param2=0},
		{name="vlf_crafting_table:crafting_table", prob=254, param2=1},
		{name="vlf_core:wood", prob=254, param2=0},
		{name="air", prob=254, param2=0},
		{name="air", prob=254, param2=0},
		{name="air", prob=254, param2=0},
		{name="vlf_doors:wooden_door_t_1", prob=254, param2=1},
		{name="air", prob=254, param2=0},
		{name="air", prob=254, param2=0},
		{name="air", prob=254, param2=0},
		{name="vlf_stairs:slab_stone_top", prob=254, param2=0},
		{name="vlf_core:wood", prob=254, param2=0},
		{name="air", prob=254, param2=0},
		{name="air", prob=254, param2=0},
		{name="air", prob=254, param2=0},
		{name="vlf_core:wood", prob=254, param2=0},
		{name="air", prob=254, param2=0},
		{name="air", prob=254, param2=0},
		{name="air", prob=254, param2=0},
		{name="vlf_flowerpots:flower_pot_blue_orchid", prob=254, param2=0},
		{name="vlf_core:wood", prob=254, param2=0},
		{name="air", prob=254, param2=0},
		{name="air", prob=254, param2=0},
		{name="vlf_stairs:slab_wood_top", prob=254, param2=0},
		{name="vlf_core:cobble", prob=254, param2=0},
		{name="air", prob=254, param2=0},
		{name="air", prob=254, param2=0},
		{name="air", prob=254, param2=0},
		{name="air", prob=254, param2=0},
		{name="vlf_core:cobble", prob=254, param2=0},
		{name="vlf_stairs:slab_wood_top", prob=254, param2=0},
		{name="air", prob=254, param2=0},
		{name="air", prob=254, param2=0},
		{name="vlf_core:wood", prob=254, param2=0},
		{name="air", prob=254, param2=0},
		{name="air", prob=254, param2=0},
		{name="air", prob=254, param2=0},
		{name="air", prob=254, param2=0},
		{name="vlf_core:wood", prob=254, param2=0},
		{name="air", prob=254, param2=0},
		{name="air", prob=254, param2=0},
		{name="air", prob=254, param2=0},
		{name="air", prob=254, param2=0},
		{name="vlf_core:wood", prob=254, param2=0},
		{name="vlf_core:tree", prob=254, param2=12},
		{name="vlf_core:tree", prob=254, param2=12},
		{name="vlf_core:wood", prob=254, param2=0},
		{name="air", prob=254, param2=0},
		{name="air", prob=254, param2=0},
		{name="air", prob=254, param2=0},
		{name="air", prob=254, param2=0},
		{name="air", prob=254, param2=0},
		{name="air", prob=254, param2=0},
		{name="air", prob=254, param2=0},
		{name="air", prob=254, param2=0},
		{name="air", prob=254, param2=0},
		{name="air", prob=254, param2=0},
		{name="air", prob=254, param2=0},
		{name="vlf_core:dirt", prob=254, param2=0},
		{name="vlf_core:dirt", prob=254, param2=0},
		{name="vlf_core:dirt", prob=254, param2=0},
		{name="vlf_core:dirt", prob=254, param2=0},
		{name="vlf_core:dirt", prob=254, param2=0},
		{name="vlf_core:dirt", prob=254, param2=0},
		{name="vlf_core:dirt", prob=254, param2=0},
		{name="vlf_core:dirt", prob=254, param2=0},
		{name="vlf_core:dirt", prob=254, param2=0},
		{name="air", prob=254, param2=0},
		{name="vlf_walls:cobble_1", prob=254, param2=0},
		{name="vlf_core:cobble", prob=254, param2=0},
		{name="vlf_core:cobble", prob=254, param2=0},
		{name="vlf_core:cobble", prob=254, param2=0},
		{name="vlf_core:cobble", prob=254, param2=0},
		{name="vlf_core:cobble", prob=254, param2=0},
		{name="vlf_core:cobble", prob=254, param2=0},
		{name="air", prob=254, param2=0},
		{name="air", prob=254, param2=0},
		{name="vlf_torches:torch", prob=254, param2=1},
		{name="vlf_core:cobble", prob=254, param2=0},
		{name="air", prob=254, param2=0},
		{name="air", prob=254, param2=0},
		{name="air", prob=254, param2=0},
		{name="air", prob=254, param2=0},
		{name="vlf_core:wood", prob=254, param2=0},
		{name="air", prob=254, param2=0},
		{name="air", prob=254, param2=0},
		{name="air", prob=254, param2=0},
		{name="xpanes:pane_natural_flat", prob=254, param2=1},
		{name="air", prob=254, param2=0},
		{name="air", prob=254, param2=0},
		{name="air", prob=254, param2=0},
		{name="air", prob=254, param2=0},
		{name="vlf_core:wood", prob=254, param2=0},
		{name="air", prob=254, param2=0},
		{name="air", prob=254, param2=0},
		{name="air", prob=254, param2=0},
		{name="vlf_core:wood", prob=254, param2=0},
		{name="air", prob=254, param2=0},
		{name="air", prob=254, param2=0},
		{name="air", prob=254, param2=0},
		{name="air", prob=254, param2=0},
		{name="vlf_core:wood", prob=254, param2=0},
		{name="air", prob=254, param2=0},
		{name="air", prob=254, param2=0},
		{name="vlf_stairs:slab_wood_top", prob=254, param2=0},
		{name="vlf_core:tree", prob=254, param2=0},
		{name="air", prob=254, param2=0},
		{name="air", prob=254, param2=0},
		{name="air", prob=254, param2=0},
		{name="air", prob=254, param2=0},
		{name="vlf_core:cobble", prob=254, param2=0},
		{name="vlf_stairs:slab_wood_top", prob=254, param2=0},
		{name="air", prob=254, param2=0},
		{name="air", prob=254, param2=0},
		{name="vlf_core:wood", prob=254, param2=0},
		{name="air", prob=254, param2=0},
		{name="air", prob=254, param2=0},
		{name="air", prob=254, param2=0},
		{name="air", prob=254, param2=0},
		{name="vlf_core:wood", prob=254, param2=0},
		{name="air", prob=254, param2=0},
		{name="air", prob=254, param2=0},
		{name="air", prob=254, param2=0},
		{name="air", prob=254, param2=0},
		{name="vlf_core:wood", prob=254, param2=0},
		{name="vlf_core:tree", prob=254, param2=12},
		{name="vlf_core:tree", prob=254, param2=12},
		{name="vlf_core:wood", prob=254, param2=0},
		{name="air", prob=254, param2=0},
		{name="air", prob=254, param2=0},
		{name="air", prob=254, param2=0},
		{name="air", prob=254, param2=0},
		{name="air", prob=254, param2=0},
		{name="air", prob=254, param2=0},
		{name="air", prob=254, param2=0},
		{name="air", prob=254, param2=0},
		{name="air", prob=254, param2=0},
		{name="air", prob=254, param2=0},
		{name="air", prob=254, param2=0},
		{name="vlf_core:dirt", prob=254, param2=0},
		{name="vlf_core:dirt", prob=254, param2=0},
		{name="vlf_core:dirt", prob=254, param2=0},
		{name="vlf_core:dirt", prob=254, param2=0},
		{name="vlf_core:dirt", prob=254, param2=0},
		{name="vlf_core:dirt", prob=254, param2=0},
		{name="vlf_core:dirt", prob=254, param2=0},
		{name="vlf_core:dirt", prob=254, param2=0},
		{name="vlf_core:dirt", prob=254, param2=0},
		{name="air", prob=254, param2=0},
		{name="air", prob=254, param2=0},
		{name="vlf_core:cobble", prob=254, param2=0},
		{name="vlf_core:cobble", prob=254, param2=0},
		{name="vlf_core:cobble", prob=254, param2=0},
		{name="vlf_core:cobble", prob=254, param2=0},
		{name="vlf_core:cobble", prob=254, param2=0},
		{name="vlf_core:cobble", prob=254, param2=0},
		{name="air", prob=254, param2=0},
		{name="air", prob=254, param2=0},
		{name="air", prob=254, param2=0},
		{name="vlf_core:cobble", prob=254, param2=0},
		{name="vlf_fletching_table:fletching_table", prob=254, param2=0},
		{name="air", prob=254, param2=0},
		{name="vlf_beds:bed_red_bottom", prob=254, param2=1},
		{name="vlf_beds:bed_red_top", prob=254, param2=1},
		{name="vlf_core:wood", prob=254, param2=0},
		{name="air", prob=254, param2=0},
		{name="air", prob=254, param2=0},
		{name="air", prob=254, param2=0},
		{name="vlf_core:cobble", prob=254, param2=0},
		{name="air", prob=254, param2=0},
		{name="air", prob=254, param2=0},
		{name="air", prob=254, param2=0},
		{name="air", prob=254, param2=0},
		{name="vlf_core:wood", prob=254, param2=0},
		{name="air", prob=254, param2=0},
		{name="air", prob=254, param2=0},
		{name="air", prob=254, param2=0},
		{name="vlf_core:cobble", prob=254, param2=0},
		{name="air", prob=254, param2=0},
		{name="air", prob=254, param2=0},
		{name="air", prob=254, param2=0},
		{name="air", prob=254, param2=0},
		{name="vlf_core:wood", prob=254, param2=0},
		{name="air", prob=254, param2=0},
		{name="air", prob=254, param2=0},
		{name="vlf_stairs:slab_wood_top", prob=254, param2=0},
		{name="vlf_core:tree", prob=254, param2=0},
		{name="vlf_walls:cobble_6", prob=254, param2=0},
		{name="air", prob=254, param2=0},
		{name="air", prob=254, param2=0},
		{name="vlf_walls:cobble_3", prob=254, param2=0},
		{name="vlf_core:cobble", prob=254, param2=0},
		{name="vlf_stairs:slab_wood_top", prob=254, param2=0},
		{name="air", prob=254, param2=0},
		{name="air", prob=254, param2=0},
		{name="vlf_core:wood", prob=254, param2=0},
		{name="vlf_torches:torch", prob=254, param2=1},
		{name="air", prob=254, param2=0},
		{name="air", prob=254, param2=0},
		{name="vlf_torches:torch", prob=254, param2=1},
		{name="vlf_core:wood", prob=254, param2=0},
		{name="air", prob=254, param2=0},
		{name="air", prob=254, param2=0},
		{name="air", prob=254, param2=0},
		{name="air", prob=254, param2=0},
		{name="vlf_core:tree", prob=254, param2=0},
		{name="vlf_core:wood", prob=254, param2=0},
		{name="vlf_core:wood", prob=254, param2=0},
		{name="vlf_core:tree", prob=254, param2=0},
		{name="air", prob=254, param2=0},
		{name="air", prob=254, param2=0},
		{name="air", prob=254, param2=0},
		{name="air", prob=254, param2=0},
		{name="air", prob=254, param2=0},
		{name="air", prob=254, param2=0},
		{name="air", prob=254, param2=0},
		{name="air", prob=254, param2=0},
		{name="air", prob=254, param2=0},
		{name="air", prob=254, param2=0},
		{name="air", prob=254, param2=0},
		{name="vlf_core:dirt", prob=254, param2=0},
		{name="vlf_core:dirt", prob=254, param2=0},
		{name="vlf_core:dirt", prob=254, param2=0},
		{name="vlf_core:dirt", prob=254, param2=0},
		{name="vlf_core:dirt", prob=254, param2=0},
		{name="vlf_core:dirt", prob=254, param2=0},
		{name="vlf_core:dirt", prob=254, param2=0},
		{name="vlf_core:dirt", prob=254, param2=0},
		{name="vlf_core:dirt", prob=254, param2=0},
		{name="air", prob=254, param2=0},
		{name="air", prob=254, param2=0},
		{name="vlf_core:cobble", prob=254, param2=0},
		{name="vlf_core:cobble", prob=254, param2=0},
		{name="vlf_core:cobble", prob=254, param2=0},
		{name="vlf_core:cobble", prob=254, param2=0},
		{name="vlf_core:cobble", prob=254, param2=0},
		{name="vlf_core:cobble", prob=254, param2=0},
		{name="air", prob=254, param2=0},
		{name="air", prob=254, param2=0},
		{name="air", prob=254, param2=0},
		{name="vlf_core:tree", prob=254, param2=0},
		{name="vlf_core:tree", prob=254, param2=0},
		{name="vlf_core:tree", prob=254, param2=0},
		{name="vlf_core:tree", prob=254, param2=0},
		{name="vlf_core:tree", prob=254, param2=0},
		{name="vlf_core:tree", prob=254, param2=0},
		{name="air", prob=254, param2=0},
		{name="air", prob=254, param2=0},
		{name="air", prob=254, param2=0},
		{name="vlf_core:tree", prob=254, param2=0},
		{name="vlf_core:tree", prob=254, param2=0},
		{name="xpanes:pane_natural_flat", prob=254, param2=0},
		{name="xpanes:pane_natural_flat", prob=254, param2=0},
		{name="vlf_core:tree", prob=254, param2=0},
		{name="vlf_core:tree", prob=254, param2=0},
		{name="air", prob=254, param2=0},
		{name="air", prob=254, param2=0},
		{name="air", prob=254, param2=0},
		{name="vlf_core:tree", prob=254, param2=0},
		{name="vlf_core:tree", prob=254, param2=0},
		{name="xpanes:pane_natural_flat", prob=254, param2=0},
		{name="xpanes:pane_natural_flat", prob=254, param2=0},
		{name="vlf_core:tree", prob=254, param2=0},
		{name="vlf_core:tree", prob=254, param2=0},
		{name="air", prob=254, param2=0},
		{name="air", prob=254, param2=0},
		{name="vlf_stairs:slab_wood_top", prob=254, param2=0},
		{name="vlf_core:cobble", prob=254, param2=0},
		{name="vlf_core:cobble", prob=254, param2=0},
		{name="vlf_core:cobble", prob=254, param2=0},
		{name="vlf_core:cobble", prob=254, param2=0},
		{name="vlf_core:cobble", prob=254, param2=0},
		{name="vlf_core:cobble", prob=254, param2=0},
		{name="vlf_stairs:slab_wood_top", prob=254, param2=0},
		{name="air", prob=254, param2=0},
		{name="air", prob=254, param2=0},
		{name="vlf_core:tree", prob=254, param2=0},
		{name="vlf_core:wood", prob=254, param2=0},
		{name="vlf_core:wood", prob=254, param2=0},
		{name="vlf_core:wood", prob=254, param2=0},
		{name="vlf_core:wood", prob=254, param2=0},
		{name="vlf_core:tree", prob=254, param2=0},
		{name="air", prob=254, param2=0},
		{name="air", prob=254, param2=0},
		{name="air", prob=254, param2=0},
		{name="air", prob=254, param2=0},
		{name="air", prob=254, param2=0},
		{name="air", prob=254, param2=0},
		{name="air", prob=254, param2=0},
		{name="air", prob=254, param2=0},
		{name="air", prob=254, param2=0},
		{name="air", prob=254, param2=0},
		{name="air", prob=254, param2=0},
		{name="air", prob=254, param2=0},
		{name="air", prob=254, param2=0},
		{name="air", prob=254, param2=0},
		{name="air", prob=254, param2=0},
		{name="air", prob=254, param2=0},
		{name="air", prob=254, param2=0},
		{name="air", prob=254, param2=0},
		{name="air", prob=254, param2=0},
		{name="vlf_core:dirt", prob=254, param2=0},
		{name="vlf_core:dirt", prob=254, param2=0},
		{name="vlf_core:dirt", prob=254, param2=0},
		{name="vlf_core:dirt", prob=254, param2=0},
		{name="vlf_core:dirt", prob=254, param2=0},
		{name="vlf_core:dirt", prob=254, param2=0},
		{name="vlf_core:dirt", prob=254, param2=0},
		{name="vlf_core:dirt", prob=254, param2=0},
		{name="vlf_core:dirt", prob=254, param2=0},
		{name="air", prob=254, param2=0},
		{name="air", prob=254, param2=0},
		{name="air", prob=254, param2=0},
		{name="air", prob=254, param2=0},
		{name="air", prob=254, param2=0},
		{name="air", prob=254, param2=0},
		{name="air", prob=254, param2=0},
		{name="air", prob=254, param2=0},
		{name="air", prob=254, param2=0},
		{name="air", prob=254, param2=0},
		{name="air", prob=254, param2=0},
		{name="air", prob=254, param2=0},
		{name="air", prob=254, param2=0},
		{name="air", prob=254, param2=0},
		{name="air", prob=254, param2=0},
		{name="air", prob=254, param2=0},
		{name="air", prob=254, param2=0},
		{name="air", prob=254, param2=0},
		{name="air", prob=254, param2=0},
		{name="air", prob=254, param2=0},
		{name="air", prob=254, param2=0},
		{name="air", prob=254, param2=0},
		{name="air", prob=254, param2=0},
		{name="air", prob=254, param2=0},
		{name="air", prob=254, param2=0},
		{name="air", prob=254, param2=0},
		{name="air", prob=254, param2=0},
		{name="air", prob=254, param2=0},
		{name="air", prob=254, param2=0},
		{name="air", prob=254, param2=0},
		{name="air", prob=254, param2=0},
		{name="air", prob=254, param2=0},
		{name="air", prob=254, param2=0},
		{name="air", prob=254, param2=0},
		{name="air", prob=254, param2=0},
		{name="air", prob=254, param2=0},
		{name="air", prob=254, param2=0},
		{name="vlf_stairs:slab_wood_top", prob=254, param2=0},
		{name="vlf_stairs:slab_wood_top", prob=254, param2=0},
		{name="vlf_stairs:slab_wood_top", prob=254, param2=0},
		{name="vlf_stairs:slab_wood_top", prob=254, param2=0},
		{name="vlf_stairs:slab_wood_top", prob=254, param2=0},
		{name="vlf_stairs:slab_wood_top", prob=254, param2=0},
		{name="vlf_stairs:slab_wood_top", prob=254, param2=0},
		{name="vlf_stairs:slab_wood_top", prob=254, param2=0},
		{name="air", prob=254, param2=0},
		{name="air", prob=254, param2=0},
		{name="air", prob=254, param2=0},
		{name="air", prob=254, param2=0},
		{name="air", prob=254, param2=0},
		{name="air", prob=254, param2=0},
		{name="air", prob=254, param2=0},
		{name="air", prob=254, param2=0},
		{name="air", prob=254, param2=0},
		{name="air", prob=254, param2=0},
		{name="air", prob=254, param2=0},
		{name="air", prob=254, param2=0},
		{name="air", prob=254, param2=0},
		{name="air", prob=254, param2=0},
		{name="air", prob=254, param2=0},
		{name="air", prob=254, param2=0},
		{name="air", prob=254, param2=0},
		{name="air", prob=254, param2=0},
		{name="air", prob=254, param2=0},
		{name="air", prob=254, param2=0},
		{name="air", prob=254, param2=0},
		{name="air", prob=254, param2=0},
		{name="air", prob=254, param2=0},
		{name="air", prob=254, param2=0},
		{name="air", prob=254, param2=0},
		{name="air", prob=254, param2=0},
		{name="air", prob=254, param2=0},
		{name="vlf_core:dirt", prob=254, param2=0},
		{name="vlf_core:dirt", prob=254, param2=0},
		{name="vlf_core:dirt", prob=254, param2=0},
		{name="vlf_core:dirt", prob=254, param2=0},
		{name="vlf_core:dirt", prob=254, param2=0},
		{name="vlf_core:dirt", prob=254, param2=0},
		{name="vlf_core:dirt", prob=254, param2=0},
		{name="vlf_core:dirt", prob=254, param2=0},
		{name="vlf_core:dirt", prob=254, param2=0},
		{name="air", prob=254, param2=0},
		{name="air", prob=254, param2=0},
		{name="air", prob=254, param2=0},
		{name="air", prob=254, param2=0},
		{name="air", prob=254, param2=0},
		{name="air", prob=254, param2=0},
		{name="air", prob=254, param2=0},
		{name="air", prob=254, param2=0},
		{name="air", prob=254, param2=0},
		{name="air", prob=254, param2=0},
		{name="air", prob=254, param2=0},
		{name="air", prob=254, param2=0},
		{name="air", prob=254, param2=0},
		{name="air", prob=254, param2=0},
		{name="air", prob=254, param2=0},
		{name="air", prob=254, param2=0},
		{name="air", prob=254, param2=0},
		{name="air", prob=254, param2=0},
		{name="air", prob=254, param2=0},
		{name="air", prob=254, param2=0},
		{name="air", prob=254, param2=0},
		{name="air", prob=254, param2=0},
		{name="air", prob=254, param2=0},
		{name="air", prob=254, param2=0},
		{name="air", prob=254, param2=0},
		{name="air", prob=254, param2=0},
		{name="air", prob=254, param2=0},
		{name="air", prob=254, param2=0},
		{name="air", prob=254, param2=0},
		{name="air", prob=254, param2=0},
		{name="air", prob=254, param2=0},
		{name="air", prob=254, param2=0},
		{name="air", prob=254, param2=0},
		{name="air", prob=254, param2=0},
		{name="air", prob=254, param2=0},
		{name="air", prob=254, param2=0},
		{name="air", prob=254, param2=0},
		{name="air", prob=254, param2=0},
		{name="air", prob=254, param2=0},
		{name="air", prob=254, param2=0},
		{name="air", prob=254, param2=0},
		{name="air", prob=254, param2=0},
		{name="air", prob=254, param2=0},
		{name="air", prob=254, param2=0},
		{name="air", prob=254, param2=0},
		{name="air", prob=254, param2=0},
		{name="air", prob=254, param2=0},
		{name="air", prob=254, param2=0},
		{name="air", prob=254, param2=0},
		{name="air", prob=254, param2=0},
		{name="air", prob=254, param2=0},
		{name="air", prob=254, param2=0},
		{name="air", prob=254, param2=0},
		{name="air", prob=254, param2=0},
		{name="air", prob=254, param2=0},
		{name="air", prob=254, param2=0},
		{name="air", prob=254, param2=0},
		{name="air", prob=254, param2=0},
		{name="air", prob=254, param2=0},
		{name="air", prob=254, param2=0},
		{name="air", prob=254, param2=0},
		{name="air", prob=254, param2=0},
		{name="air", prob=254, param2=0},
		{name="air", prob=254, param2=0},
		{name="air", prob=254, param2=0},
		{name="air", prob=254, param2=0},
		{name="air", prob=254, param2=0},
		{name="air", prob=254, param2=0},
		{name="air", prob=254, param2=0},
		{name="air", prob=254, param2=0},
		{name="air", prob=254, param2=0},
		{name="air", prob=254, param2=0},
	},
}
