schematic = {
	size = {x=12, y=13, z=10},
	yslice_prob = {
		{ypos=0, prob=254},
		{ypos=1, prob=254},
		{ypos=2, prob=254},
		{ypos=3, prob=254},
		{ypos=4, prob=254},
		{ypos=5, prob=254},
		{ypos=6, prob=254},
		{ypos=7, prob=254},
		{ypos=8, prob=254},
		{ypos=9, prob=254},
		{ypos=10, prob=254},
		{ypos=11, prob=254},
		{ypos=12, prob=254},
	},
	data = {
		{name="vlf_core:dirt", prob=254, param2=0},
		{name="vlf_core:dirt", prob=254, param2=0},
		{name="vlf_core:dirt", prob=254, param2=0},
		{name="vlf_core:dirt", prob=254, param2=0},
		{name="vlf_core:dirt", prob=254, param2=0},
		{name="vlf_core:dirt", prob=254, param2=0},
		{name="vlf_core:dirt", prob=254, param2=0},
		{name="vlf_core:dirt", prob=254, param2=0},
		{name="vlf_core:dirt", prob=254, param2=0},
		{name="vlf_core:dirt", prob=254, param2=0},
		{name="vlf_core:dirt", prob=254, param2=0},
		{name="vlf_core:dirt", prob=254, param2=0},
		{name="air", prob=254, param2=0},
		{name="air", prob=254, param2=0},
		{name="air", prob=254, param2=0},
		{name="air", prob=254, param2=0},
		{name="air", prob=254, param2=0},
		{name="air", prob=254, param2=0},
		{name="air", prob=254, param2=0},
		{name="air", prob=254, param2=0},
		{name="air", prob=254, param2=0},
		{name="air", prob=254, param2=0},
		{name="air", prob=254, param2=0},
		{name="air", prob=254, param2=0},
		{name="air", prob=254, param2=0},
		{name="air", prob=254, param2=0},
		{name="air", prob=254, param2=0},
		{name="air", prob=254, param2=0},
		{name="air", prob=254, param2=0},
		{name="air", prob=254, param2=0},
		{name="air", prob=254, param2=0},
		{name="air", prob=254, param2=0},
		{name="air", prob=254, param2=0},
		{name="air", prob=254, param2=0},
		{name="air", prob=254, param2=0},
		{name="air", prob=254, param2=0},
		{name="air", prob=254, param2=0},
		{name="air", prob=254, param2=0},
		{name="air", prob=254, param2=0},
		{name="air", prob=254, param2=0},
		{name="air", prob=254, param2=0},
		{name="air", prob=254, param2=0},
		{name="air", prob=254, param2=0},
		{name="air", prob=254, param2=0},
		{name="air", prob=254, param2=0},
		{name="air", prob=254, param2=0},
		{name="air", prob=254, param2=0},
		{name="air", prob=254, param2=0},
		{name="air", prob=254, param2=0},
		{name="air", prob=254, param2=0},
		{name="air", prob=254, param2=0},
		{name="air", prob=254, param2=0},
		{name="air", prob=254, param2=0},
		{name="air", prob=254, param2=0},
		{name="air", prob=254, param2=0},
		{name="air", prob=254, param2=0},
		{name="air", prob=254, param2=0},
		{name="air", prob=254, param2=0},
		{name="air", prob=254, param2=0},
		{name="air", prob=254, param2=0},
		{name="air", prob=254, param2=0},
		{name="air", prob=254, param2=0},
		{name="air", prob=254, param2=0},
		{name="air", prob=254, param2=0},
		{name="air", prob=254, param2=0},
		{name="air", prob=254, param2=0},
		{name="air", prob=254, param2=0},
		{name="air", prob=254, param2=0},
		{name="air", prob=254, param2=0},
		{name="air", prob=254, param2=0},
		{name="air", prob=254, param2=0},
		{name="air", prob=254, param2=0},
		{name="air", prob=254, param2=0},
		{name="air", prob=254, param2=0},
		{name="air", prob=254, param2=0},
		{name="air", prob=254, param2=0},
		{name="air", prob=254, param2=0},
		{name="air", prob=254, param2=0},
		{name="air", prob=254, param2=0},
		{name="air", prob=254, param2=0},
		{name="air", prob=254, param2=0},
		{name="air", prob=254, param2=0},
		{name="air", prob=254, param2=0},
		{name="air", prob=254, param2=0},
		{name="air", prob=254, param2=0},
		{name="air", prob=254, param2=0},
		{name="air", prob=254, param2=0},
		{name="air", prob=254, param2=0},
		{name="air", prob=254, param2=0},
		{name="air", prob=254, param2=0},
		{name="air", prob=254, param2=0},
		{name="air", prob=254, param2=0},
		{name="air", prob=254, param2=0},
		{name="air", prob=254, param2=0},
		{name="air", prob=254, param2=0},
		{name="air", prob=254, param2=0},
		{name="air", prob=254, param2=0},
		{name="air", prob=254, param2=0},
		{name="air", prob=254, param2=0},
		{name="air", prob=254, param2=0},
		{name="air", prob=254, param2=0},
		{name="air", prob=254, param2=0},
		{name="air", prob=254, param2=0},
		{name="air", prob=254, param2=0},
		{name="air", prob=254, param2=0},
		{name="air", prob=254, param2=0},
		{name="air", prob=254, param2=0},
		{name="air", prob=254, param2=0},
		{name="air", prob=254, param2=0},
		{name="air", prob=254, param2=0},
		{name="air", prob=254, param2=0},
		{name="air", prob=254, param2=0},
		{name="air", prob=254, param2=0},
		{name="air", prob=254, param2=0},
		{name="air", prob=254, param2=0},
		{name="air", prob=254, param2=0},
		{name="air", prob=254, param2=0},
		{name="air", prob=254, param2=0},
		{name="air", prob=254, param2=0},
		{name="air", prob=254, param2=0},
		{name="air", prob=254, param2=0},
		{name="air", prob=254, param2=0},
		{name="air", prob=254, param2=0},
		{name="air", prob=254, param2=0},
		{name="air", prob=254, param2=0},
		{name="air", prob=254, param2=0},
		{name="air", prob=254, param2=0},
		{name="air", prob=254, param2=0},
		{name="air", prob=254, param2=0},
		{name="air", prob=254, param2=0},
		{name="air", prob=254, param2=0},
		{name="air", prob=254, param2=0},
		{name="air", prob=254, param2=0},
		{name="air", prob=254, param2=0},
		{name="air", prob=254, param2=0},
		{name="air", prob=254, param2=0},
		{name="air", prob=254, param2=0},
		{name="air", prob=254, param2=0},
		{name="air", prob=254, param2=0},
		{name="air", prob=254, param2=0},
		{name="air", prob=254, param2=0},
		{name="air", prob=254, param2=0},
		{name="air", prob=254, param2=0},
		{name="air", prob=254, param2=0},
		{name="air", prob=254, param2=0},
		{name="air", prob=254, param2=0},
		{name="air", prob=254, param2=0},
		{name="air", prob=254, param2=0},
		{name="air", prob=254, param2=0},
		{name="air", prob=254, param2=0},
		{name="air", prob=254, param2=0},
		{name="air", prob=254, param2=0},
		{name="air", prob=254, param2=0},
		{name="air", prob=254, param2=0},
		{name="air", prob=254, param2=0},
		{name="air", prob=254, param2=0},
		{name="vlf_core:dirt", prob=254, param2=0},
		{name="vlf_core:dirt", prob=254, param2=0},
		{name="vlf_core:dirt", prob=254, param2=0},
		{name="vlf_core:dirt", prob=254, param2=0},
		{name="vlf_core:dirt", prob=254, param2=0},
		{name="vlf_core:dirt", prob=254, param2=0},
		{name="vlf_core:dirt", prob=254, param2=0},
		{name="vlf_core:dirt", prob=254, param2=0},
		{name="vlf_core:dirt", prob=254, param2=0},
		{name="vlf_core:dirt", prob=254, param2=0},
		{name="vlf_core:dirt", prob=254, param2=0},
		{name="vlf_core:dirt", prob=254, param2=0},
		{name="air", prob=254, param2=0},
		{name="air", prob=254, param2=0},
		{name="air", prob=254, param2=0},
		{name="vlf_core:cobble", prob=254, param2=0},
		{name="vlf_core:cobble", prob=254, param2=0},
		{name="vlf_core:cobble", prob=254, param2=0},
		{name="vlf_core:cobble", prob=254, param2=0},
		{name="vlf_core:cobble", prob=254, param2=0},
		{name="vlf_core:cobble", prob=254, param2=0},
		{name="vlf_core:cobble", prob=254, param2=0},
		{name="vlf_core:cobble", prob=254, param2=0},
		{name="vlf_core:cobble", prob=254, param2=0},
		{name="air", prob=254, param2=0},
		{name="air", prob=254, param2=0},
		{name="air", prob=254, param2=0},
		{name="vlf_core:wood", prob=254, param2=0},
		{name="vlf_core:cobble", prob=254, param2=0},
		{name="vlf_core:cobble", prob=254, param2=0},
		{name="vlf_core:cobble", prob=254, param2=0},
		{name="vlf_core:cobble", prob=254, param2=0},
		{name="vlf_core:cobble", prob=254, param2=0},
		{name="vlf_core:cobble", prob=254, param2=0},
		{name="vlf_core:cobble", prob=254, param2=0},
		{name="vlf_core:wood", prob=254, param2=0},
		{name="air", prob=254, param2=0},
		{name="air", prob=254, param2=0},
		{name="air", prob=254, param2=0},
		{name="vlf_core:wood", prob=254, param2=0},
		{name="vlf_core:cobble", prob=254, param2=0},
		{name="vlf_core:cobble", prob=254, param2=0},
		{name="vlf_core:cobble", prob=254, param2=0},
		{name="vlf_core:cobble", prob=254, param2=0},
		{name="vlf_core:cobble", prob=254, param2=0},
		{name="vlf_core:cobble", prob=254, param2=0},
		{name="vlf_core:cobble", prob=254, param2=0},
		{name="vlf_core:wood", prob=254, param2=0},
		{name="air", prob=254, param2=0},
		{name="air", prob=254, param2=0},
		{name="air", prob=254, param2=0},
		{name="vlf_core:wood", prob=254, param2=0},
		{name="vlf_core:cobble", prob=254, param2=0},
		{name="xpanes:pane_natural_flat", prob=254, param2=2},
		{name="xpanes:pane_natural_flat", prob=254, param2=0},
		{name="vlf_core:cobble", prob=254, param2=0},
		{name="vlf_core:cobble", prob=254, param2=0},
		{name="vlf_core:cobble", prob=254, param2=0},
		{name="vlf_core:cobble", prob=254, param2=0},
		{name="vlf_core:wood", prob=254, param2=0},
		{name="air", prob=254, param2=0},
		{name="air", prob=254, param2=0},
		{name="air", prob=254, param2=0},
		{name="vlf_core:wood", prob=254, param2=0},
		{name="vlf_core:cobble", prob=254, param2=0},
		{name="xpanes:pane_natural_flat", prob=254, param2=2},
		{name="xpanes:pane_natural_flat", prob=254, param2=0},
		{name="vlf_core:cobble", prob=254, param2=0},
		{name="vlf_core:cobble", prob=254, param2=0},
		{name="vlf_core:cobble", prob=254, param2=0},
		{name="vlf_core:cobble", prob=254, param2=0},
		{name="vlf_core:wood", prob=254, param2=0},
		{name="air", prob=254, param2=0},
		{name="air", prob=254, param2=0},
		{name="air", prob=254, param2=0},
		{name="vlf_core:wood", prob=254, param2=0},
		{name="vlf_core:cobble", prob=254, param2=0},
		{name="vlf_core:cobble", prob=254, param2=0},
		{name="vlf_core:cobble", prob=254, param2=0},
		{name="vlf_core:cobble", prob=254, param2=0},
		{name="vlf_core:cobble", prob=254, param2=0},
		{name="vlf_core:cobble", prob=254, param2=0},
		{name="vlf_core:cobble", prob=254, param2=0},
		{name="vlf_core:wood", prob=254, param2=0},
		{name="air", prob=254, param2=0},
		{name="air", prob=254, param2=0},
		{name="air", prob=254, param2=0},
		{name="vlf_core:wood", prob=254, param2=0},
		{name="vlf_core:cobble", prob=254, param2=0},
		{name="vlf_core:cobble", prob=254, param2=0},
		{name="vlf_core:cobble", prob=254, param2=0},
		{name="vlf_core:cobble", prob=254, param2=0},
		{name="vlf_core:cobble", prob=254, param2=0},
		{name="vlf_core:cobble", prob=254, param2=0},
		{name="vlf_core:cobble", prob=254, param2=0},
		{name="vlf_core:wood", prob=254, param2=0},
		{name="air", prob=254, param2=0},
		{name="air", prob=254, param2=0},
		{name="air", prob=254, param2=0},
		{name="vlf_core:wood", prob=254, param2=0},
		{name="air", prob=254, param2=0},
		{name="air", prob=254, param2=0},
		{name="air", prob=254, param2=0},
		{name="air", prob=254, param2=0},
		{name="air", prob=254, param2=0},
		{name="air", prob=254, param2=0},
		{name="air", prob=254, param2=0},
		{name="vlf_core:wood", prob=254, param2=0},
		{name="air", prob=254, param2=0},
		{name="air", prob=254, param2=0},
		{name="air", prob=254, param2=0},
		{name="air", prob=254, param2=0},
		{name="air", prob=254, param2=0},
		{name="air", prob=254, param2=0},
		{name="air", prob=254, param2=0},
		{name="air", prob=254, param2=0},
		{name="air", prob=254, param2=0},
		{name="air", prob=254, param2=0},
		{name="air", prob=254, param2=0},
		{name="air", prob=254, param2=0},
		{name="air", prob=254, param2=0},
		{name="air", prob=254, param2=0},
		{name="air", prob=254, param2=0},
		{name="air", prob=254, param2=0},
		{name="air", prob=254, param2=0},
		{name="air", prob=254, param2=0},
		{name="air", prob=254, param2=0},
		{name="air", prob=254, param2=0},
		{name="air", prob=254, param2=0},
		{name="air", prob=254, param2=0},
		{name="air", prob=254, param2=0},
		{name="air", prob=254, param2=0},
		{name="air", prob=254, param2=0},
		{name="air", prob=254, param2=0},
		{name="air", prob=254, param2=0},
		{name="air", prob=254, param2=0},
		{name="air", prob=254, param2=0},
		{name="air", prob=254, param2=0},
		{name="air", prob=254, param2=0},
		{name="air", prob=254, param2=0},
		{name="air", prob=254, param2=0},
		{name="air", prob=254, param2=0},
		{name="air", prob=254, param2=0},
		{name="air", prob=254, param2=0},
		{name="air", prob=254, param2=0},
		{name="air", prob=254, param2=0},
		{name="air", prob=254, param2=0},
		{name="air", prob=254, param2=0},
		{name="air", prob=254, param2=0},
		{name="air", prob=254, param2=0},
		{name="air", prob=254, param2=0},
		{name="air", prob=254, param2=0},
		{name="air", prob=254, param2=0},
		{name="air", prob=254, param2=0},
		{name="air", prob=254, param2=0},
		{name="air", prob=254, param2=0},
		{name="vlf_core:dirt", prob=254, param2=0},
		{name="vlf_core:dirt", prob=254, param2=0},
		{name="vlf_core:dirt", prob=254, param2=0},
		{name="vlf_core:dirt", prob=254, param2=0},
		{name="vlf_core:dirt", prob=254, param2=0},
		{name="vlf_core:dirt", prob=254, param2=0},
		{name="vlf_core:dirt", prob=254, param2=0},
		{name="vlf_core:dirt", prob=254, param2=0},
		{name="vlf_core:dirt", prob=254, param2=0},
		{name="vlf_core:dirt", prob=254, param2=0},
		{name="vlf_core:dirt", prob=254, param2=0},
		{name="vlf_core:dirt", prob=254, param2=0},
		{name="air", prob=254, param2=0},
		{name="air", prob=254, param2=0},
		{name="air", prob=254, param2=0},
		{name="vlf_core:cobble", prob=254, param2=0},
		{name="vlf_core:wood", prob=254, param2=0},
		{name="vlf_core:wood", prob=254, param2=0},
		{name="vlf_core:wood", prob=254, param2=0},
		{name="vlf_core:wood", prob=254, param2=0},
		{name="vlf_core:cobble", prob=254, param2=0},
		{name="vlf_core:cobble", prob=254, param2=0},
		{name="vlf_core:cobble", prob=254, param2=0},
		{name="vlf_core:cobble", prob=254, param2=0},
		{name="air", prob=254, param2=0},
		{name="air", prob=254, param2=0},
		{name="air", prob=254, param2=0},
		{name="vlf_core:cobble", prob=254, param2=0},
		{name="vlf_stairs:stair_wood", prob=254, param2=2},
		{name="air", prob=254, param2=0},
		{name="air", prob=254, param2=0},
		{name="vlf_jukebox:jukebox", prob=254, param2=0},
		{name="vlf_core:stonebrick", prob=254, param2=0},
		{name="air", prob=254, param2=0},
		{name="vlf_chests:chest", prob=254, param2=1},
		{name="vlf_core:cobble", prob=254, param2=0},
		{name="air", prob=254, param2=0},
		{name="air", prob=254, param2=0},
		{name="air", prob=254, param2=0},
		{name="xpanes:pane_natural_flat", prob=254, param2=3},
		{name="air", prob=254, param2=0},
		{name="air", prob=254, param2=0},
		{name="air", prob=254, param2=0},
		{name="vlf_itemframes:item_frame", prob=254, param2=1},
		{name="vlf_core:stonebrick", prob=254, param2=0},
		{name="vlf_stairs:slab_wood_top", prob=254, param2=0},
		{name="vlf_stairs:stair_wood", prob=254, param2=2},
		{name="vlf_core:cobble", prob=254, param2=0},
		{name="air", prob=254, param2=0},
		{name="air", prob=254, param2=0},
		{name="air", prob=254, param2=0},
		{name="vlf_core:cobble", prob=254, param2=0},
		{name="air", prob=254, param2=0},
		{name="air", prob=254, param2=0},
		{name="air", prob=254, param2=0},
		{name="vlf_itemframes:item_frame", prob=254, param2=1},
		{name="vlf_core:stonebrick", prob=254, param2=0},
		{name="air", prob=254, param2=0},
		{name="air", prob=254, param2=0},
		{name="vlf_core:cobble", prob=254, param2=0},
		{name="air", prob=254, param2=0},
		{name="air", prob=254, param2=0},
		{name="air", prob=254, param2=0},
		{name="vlf_core:cobble", prob=254, param2=0},
		{name="air", prob=254, param2=0},
		{name="air", prob=254, param2=0},
		{name="air", prob=254, param2=0},
		{name="air", prob=254, param2=0},
		{name="vlf_core:cobble", prob=254, param2=0},
		{name="air", prob=254, param2=0},
		{name="air", prob=254, param2=0},
		{name="vlf_core:cobble", prob=254, param2=0},
		{name="air", prob=254, param2=0},
		{name="air", prob=254, param2=0},
		{name="air", prob=254, param2=0},
		{name="vlf_core:cobble", prob=254, param2=0},
		{name="vlf_walls:cobble_12", prob=254, param2=0},
		{name="air", prob=254, param2=0},
		{name="air", prob=254, param2=0},
		{name="air", prob=254, param2=0},
		{name="vlf_torches:torch", prob=254, param2=1},
		{name="air", prob=254, param2=0},
		{name="air", prob=254, param2=0},
		{name="vlf_core:cobble", prob=254, param2=0},
		{name="air", prob=254, param2=0},
		{name="air", prob=254, param2=0},
		{name="air", prob=254, param2=0},
		{name="vlf_core:cobble", prob=254, param2=0},
		{name="vlf_torches:torch", prob=254, param2=1},
		{name="air", prob=254, param2=0},
		{name="air", prob=254, param2=0},
		{name="air", prob=254, param2=0},
		{name="air", prob=254, param2=0},
		{name="air", prob=254, param2=0},
		{name="air", prob=254, param2=0},
		{name="vlf_core:cobble", prob=254, param2=0},
		{name="air", prob=254, param2=0},
		{name="air", prob=254, param2=0},
		{name="air", prob=254, param2=0},
		{name="air", prob=254, param2=0},
		{name="vlf_core:cobble", prob=254, param2=0},
		{name="vlf_core:cobble", prob=254, param2=0},
		{name="vlf_core:cobble", prob=254, param2=0},
		{name="vlf_core:cobble", prob=254, param2=0},
		{name="vlf_core:cobble", prob=254, param2=0},
		{name="vlf_core:cobble", prob=254, param2=0},
		{name="vlf_core:cobble", prob=254, param2=0},
		{name="air", prob=254, param2=0},
		{name="air", prob=254, param2=0},
		{name="air", prob=254, param2=0},
		{name="air", prob=254, param2=0},
		{name="air", prob=254, param2=0},
		{name="vlf_stairs:stair_wood_outer", prob=254, param2=1},
		{name="vlf_stairs:stair_wood", prob=254, param2=0},
		{name="vlf_stairs:stair_wood", prob=254, param2=0},
		{name="vlf_stairs:stair_wood", prob=254, param2=0},
		{name="vlf_stairs:stair_wood", prob=254, param2=0},
		{name="vlf_stairs:stair_wood", prob=254, param2=0},
		{name="vlf_stairs:stair_wood_outer", prob=254, param2=0},
		{name="air", prob=254, param2=0},
		{name="air", prob=254, param2=0},
		{name="air", prob=254, param2=0},
		{name="air", prob=254, param2=0},
		{name="air", prob=254, param2=0},
		{name="air", prob=254, param2=0},
		{name="air", prob=254, param2=0},
		{name="air", prob=254, param2=0},
		{name="air", prob=254, param2=0},
		{name="air", prob=254, param2=0},
		{name="air", prob=254, param2=0},
		{name="air", prob=254, param2=0},
		{name="air", prob=254, param2=0},
		{name="air", prob=254, param2=0},
		{name="air", prob=254, param2=0},
		{name="air", prob=254, param2=0},
		{name="air", prob=254, param2=0},
		{name="air", prob=254, param2=0},
		{name="air", prob=254, param2=0},
		{name="air", prob=254, param2=0},
		{name="air", prob=254, param2=0},
		{name="air", prob=254, param2=0},
		{name="air", prob=254, param2=0},
		{name="air", prob=254, param2=0},
		{name="air", prob=254, param2=0},
		{name="air", prob=254, param2=0},
		{name="air", prob=254, param2=0},
		{name="air", prob=254, param2=0},
		{name="air", prob=254, param2=0},
		{name="air", prob=254, param2=0},
		{name="air", prob=254, param2=0},
		{name="air", prob=254, param2=0},
		{name="air", prob=254, param2=0},
		{name="air", prob=254, param2=0},
		{name="air", prob=254, param2=0},
		{name="air", prob=254, param2=0},
		{name="air", prob=254, param2=0},
		{name="vlf_core:dirt", prob=254, param2=0},
		{name="vlf_core:dirt", prob=254, param2=0},
		{name="vlf_core:dirt", prob=254, param2=0},
		{name="vlf_core:dirt", prob=254, param2=0},
		{name="vlf_core:dirt", prob=254, param2=0},
		{name="vlf_core:dirt", prob=254, param2=0},
		{name="vlf_core:dirt", prob=254, param2=0},
		{name="vlf_core:dirt", prob=254, param2=0},
		{name="vlf_core:dirt", prob=254, param2=0},
		{name="vlf_core:dirt", prob=254, param2=0},
		{name="vlf_core:dirt", prob=254, param2=0},
		{name="vlf_core:dirt", prob=254, param2=0},
		{name="air", prob=254, param2=0},
		{name="air", prob=254, param2=0},
		{name="air", prob=254, param2=0},
		{name="vlf_core:cobble", prob=254, param2=0},
		{name="vlf_core:wood", prob=254, param2=0},
		{name="vlf_core:wood", prob=254, param2=0},
		{name="vlf_core:wood", prob=254, param2=0},
		{name="vlf_core:wood", prob=254, param2=0},
		{name="vlf_core:cobble", prob=254, param2=0},
		{name="vlf_core:cobble", prob=254, param2=0},
		{name="vlf_core:cobble", prob=254, param2=0},
		{name="vlf_core:cobble", prob=254, param2=0},
		{name="air", prob=254, param2=0},
		{name="air", prob=254, param2=0},
		{name="air", prob=254, param2=0},
		{name="vlf_core:cobble", prob=254, param2=0},
		{name="vlf_fences:fence", prob=254, param2=0},
		{name="air", prob=254, param2=0},
		{name="air", prob=254, param2=0},
		{name="air", prob=254, param2=0},
		{name="vlf_core:stonebrick", prob=254, param2=0},
		{name="air", prob=254, param2=0},
		{name="vlf_stairs:stair_wood", prob=254, param2=2},
		{name="vlf_core:cobble", prob=254, param2=0},
		{name="air", prob=254, param2=0},
		{name="air", prob=254, param2=0},
		{name="air", prob=254, param2=0},
		{name="xpanes:pane_natural_flat", prob=254, param2=3},
		{name="mesecons_pressureplates:pressure_plate_wood_off", prob=254, param2=0},
		{name="air", prob=254, param2=0},
		{name="air", prob=254, param2=0},
		{name="vlf_itemframes:item_frame", prob=254, param2=1},
		{name="vlf_core:stonebrick", prob=254, param2=0},
		{name="air", prob=254, param2=0},
		{name="air", prob=254, param2=0},
		{name="vlf_core:cobble", prob=254, param2=0},
		{name="air", prob=254, param2=0},
		{name="air", prob=254, param2=0},
		{name="air", prob=254, param2=0},
		{name="vlf_core:cobble", prob=254, param2=0},
		{name="air", prob=254, param2=0},
		{name="air", prob=254, param2=0},
		{name="air", prob=254, param2=0},
		{name="vlf_itemframes:item_frame", prob=254, param2=1},
		{name="vlf_core:stonebrick", prob=254, param2=0},
		{name="vlf_stairs:stair_wood", prob=254, param2=0},
		{name="air", prob=254, param2=0},
		{name="vlf_core:cobble", prob=254, param2=0},
		{name="air", prob=254, param2=0},
		{name="air", prob=254, param2=0},
		{name="vlf_stairs:slab_wood_top", prob=254, param2=0},
		{name="vlf_core:cobble", prob=254, param2=0},
		{name="air", prob=254, param2=0},
		{name="air", prob=254, param2=0},
		{name="air", prob=254, param2=0},
		{name="air", prob=254, param2=0},
		{name="vlf_core:cobble", prob=254, param2=0},
		{name="air", prob=254, param2=0},
		{name="air", prob=254, param2=0},
		{name="vlf_core:cobble", prob=254, param2=0},
		{name="air", prob=254, param2=0},
		{name="air", prob=254, param2=0},
		{name="air", prob=254, param2=0},
		{name="xpanes:pane_natural_flat", prob=254, param2=1},
		{name="air", prob=254, param2=0},
		{name="air", prob=254, param2=0},
		{name="air", prob=254, param2=0},
		{name="air", prob=254, param2=0},
		{name="vlf_torches:torch", prob=254, param2=1},
		{name="air", prob=254, param2=0},
		{name="air", prob=254, param2=0},
		{name="vlf_core:cobble", prob=254, param2=0},
		{name="air", prob=254, param2=0},
		{name="air", prob=254, param2=0},
		{name="air", prob=254, param2=0},
		{name="vlf_core:cobble", prob=254, param2=0},
		{name="air", prob=254, param2=0},
		{name="air", prob=254, param2=0},
		{name="air", prob=254, param2=0},
		{name="air", prob=254, param2=0},
		{name="air", prob=254, param2=0},
		{name="air", prob=254, param2=0},
		{name="air", prob=254, param2=0},
		{name="vlf_core:cobble", prob=254, param2=0},
		{name="air", prob=254, param2=0},
		{name="air", prob=254, param2=0},
		{name="air", prob=254, param2=0},
		{name="air", prob=254, param2=0},
		{name="vlf_core:cobble", prob=254, param2=0},
		{name="air", prob=254, param2=0},
		{name="air", prob=254, param2=0},
		{name="vlf_core:cobble", prob=254, param2=0},
		{name="vlf_core:cobble", prob=254, param2=0},
		{name="vlf_core:cobble", prob=254, param2=0},
		{name="vlf_core:cobble", prob=254, param2=0},
		{name="air", prob=254, param2=0},
		{name="air", prob=254, param2=0},
		{name="air", prob=254, param2=0},
		{name="air", prob=254, param2=0},
		{name="air", prob=254, param2=0},
		{name="vlf_stairs:stair_wood", prob=254, param2=1},
		{name="vlf_core:glass", prob=254, param2=0},
		{name="vlf_core:glass", prob=254, param2=0},
		{name="vlf_core:wood", prob=254, param2=0},
		{name="vlf_core:wood", prob=254, param2=0},
		{name="vlf_core:glass", prob=254, param2=0},
		{name="vlf_stairs:stair_wood", prob=254, param2=3},
		{name="air", prob=254, param2=0},
		{name="air", prob=254, param2=0},
		{name="air", prob=254, param2=0},
		{name="air", prob=254, param2=0},
		{name="air", prob=254, param2=0},
		{name="air", prob=254, param2=0},
		{name="air", prob=254, param2=0},
		{name="air", prob=254, param2=0},
		{name="vlf_stairs:stair_wood", prob=254, param2=0},
		{name="vlf_stairs:stair_wood", prob=254, param2=0},
		{name="air", prob=254, param2=0},
		{name="air", prob=254, param2=0},
		{name="air", prob=254, param2=0},
		{name="air", prob=254, param2=0},
		{name="air", prob=254, param2=0},
		{name="air", prob=254, param2=0},
		{name="air", prob=254, param2=0},
		{name="air", prob=254, param2=0},
		{name="air", prob=254, param2=0},
		{name="air", prob=254, param2=0},
		{name="air", prob=254, param2=0},
		{name="air", prob=254, param2=0},
		{name="air", prob=254, param2=0},
		{name="air", prob=254, param2=0},
		{name="air", prob=254, param2=0},
		{name="air", prob=254, param2=0},
		{name="air", prob=254, param2=0},
		{name="air", prob=254, param2=0},
		{name="air", prob=254, param2=0},
		{name="air", prob=254, param2=0},
		{name="air", prob=254, param2=0},
		{name="air", prob=254, param2=0},
		{name="air", prob=254, param2=0},
		{name="air", prob=254, param2=0},
		{name="air", prob=254, param2=0},
		{name="air", prob=254, param2=0},
		{name="air", prob=254, param2=0},
		{name="vlf_core:dirt", prob=254, param2=0},
		{name="vlf_core:dirt", prob=254, param2=0},
		{name="vlf_core:dirt", prob=254, param2=0},
		{name="vlf_core:dirt", prob=254, param2=0},
		{name="vlf_core:dirt", prob=254, param2=0},
		{name="vlf_core:dirt", prob=254, param2=0},
		{name="vlf_core:dirt", prob=254, param2=0},
		{name="vlf_core:dirt", prob=254, param2=0},
		{name="vlf_core:dirt", prob=254, param2=0},
		{name="vlf_core:dirt", prob=254, param2=0},
		{name="vlf_core:dirt", prob=254, param2=0},
		{name="vlf_core:dirt", prob=254, param2=0},
		{name="air", prob=254, param2=0},
		{name="vlf_stairs:stair_cobble_outer", prob=254, param2=1},
		{name="vlf_stairs:stair_cobble", prob=254, param2=0},
		{name="vlf_core:cobble", prob=254, param2=0},
		{name="vlf_core:wood", prob=254, param2=0},
		{name="vlf_core:wood", prob=254, param2=0},
		{name="vlf_core:wood", prob=254, param2=0},
		{name="vlf_core:wood", prob=254, param2=0},
		{name="vlf_core:cobble", prob=254, param2=0},
		{name="vlf_core:cobble", prob=254, param2=0},
		{name="vlf_core:cobble", prob=254, param2=0},
		{name="vlf_core:cobble", prob=254, param2=0},
		{name="air", prob=254, param2=0},
		{name="air", prob=254, param2=0},
		{name="air", prob=254, param2=0},
		{name="vlf_core:cobble", prob=254, param2=0},
		{name="vlf_stairs:stair_wood", prob=254, param2=0},
		{name="air", prob=254, param2=0},
		{name="air", prob=254, param2=0},
		{name="air", prob=254, param2=0},
		{name="vlf_core:tree", prob=254, param2=0},
		{name="air", prob=254, param2=0},
		{name="air", prob=254, param2=0},
		{name="vlf_core:cobble", prob=254, param2=0},
		{name="air", prob=254, param2=0},
		{name="air", prob=254, param2=0},
		{name="vlf_walls:stonebrick_1", prob=254, param2=0},
		{name="vlf_core:cobble", prob=254, param2=0},
		{name="air", prob=254, param2=0},
		{name="air", prob=254, param2=0},
		{name="air", prob=254, param2=0},
		{name="air", prob=254, param2=0},
		{name="vlf_core:tree", prob=254, param2=0},
		{name="air", prob=254, param2=0},
		{name="air", prob=254, param2=0},
		{name="vlf_core:cobble", prob=254, param2=0},
		{name="air", prob=254, param2=0},
		{name="air", prob=254, param2=0},
		{name="vlf_torches:torch", prob=254, param2=1},
		{name="vlf_core:cobble", prob=254, param2=0},
		{name="air", prob=254, param2=0},
		{name="air", prob=254, param2=0},
		{name="air", prob=254, param2=0},
		{name="air", prob=254, param2=0},
		{name="vlf_core:tree", prob=254, param2=0},
		{name="vlf_stairs:slab_wood_top", prob=254, param2=0},
		{name="air", prob=254, param2=0},
		{name="vlf_core:cobble", prob=254, param2=0},
		{name="air", prob=254, param2=0},
		{name="air", prob=254, param2=0},
		{name="vlf_stairs:slab_wood_top", prob=254, param2=0},
		{name="vlf_core:cobble", prob=254, param2=0},
		{name="air", prob=254, param2=0},
		{name="air", prob=254, param2=0},
		{name="air", prob=254, param2=0},
		{name="air", prob=254, param2=0},
		{name="vlf_core:tree", prob=254, param2=0},
		{name="air", prob=254, param2=0},
		{name="air", prob=254, param2=0},
		{name="vlf_core:cobble", prob=254, param2=0},
		{name="air", prob=254, param2=0},
		{name="air", prob=254, param2=0},
		{name="air", prob=254, param2=0},
		{name="xpanes:pane_natural_flat", prob=254, param2=3},
		{name="air", prob=254, param2=0},
		{name="air", prob=254, param2=0},
		{name="air", prob=254, param2=0},
		{name="air", prob=254, param2=0},
		{name="vlf_core:tree", prob=254, param2=0},
		{name="air", prob=254, param2=0},
		{name="air", prob=254, param2=0},
		{name="vlf_core:cobble", prob=254, param2=0},
		{name="air", prob=254, param2=0},
		{name="air", prob=254, param2=0},
		{name="air", prob=254, param2=0},
		{name="vlf_core:cobble", prob=254, param2=0},
		{name="air", prob=254, param2=0},
		{name="air", prob=254, param2=0},
		{name="air", prob=254, param2=0},
		{name="air", prob=254, param2=0},
		{name="vlf_core:tree", prob=254, param2=0},
		{name="air", prob=254, param2=0},
		{name="air", prob=254, param2=0},
		{name="vlf_core:cobble", prob=254, param2=0},
		{name="air", prob=254, param2=0},
		{name="air", prob=254, param2=0},
		{name="air", prob=254, param2=0},
		{name="air", prob=254, param2=0},
		{name="vlf_core:cobble", prob=254, param2=0},
		{name="air", prob=254, param2=0},
		{name="air", prob=254, param2=0},
		{name="vlf_core:cobble", prob=254, param2=0},
		{name="vlf_core:cobble", prob=254, param2=0},
		{name="air", prob=254, param2=0},
		{name="vlf_core:cobble", prob=254, param2=0},
		{name="air", prob=254, param2=0},
		{name="air", prob=254, param2=0},
		{name="air", prob=254, param2=0},
		{name="air", prob=254, param2=0},
		{name="air", prob=254, param2=0},
		{name="vlf_stairs:stair_wood", prob=254, param2=1},
		{name="vlf_core:glass", prob=254, param2=0},
		{name="vlf_core:glass", prob=254, param2=0},
		{name="vlf_core:wood", prob=254, param2=0},
		{name="vlf_core:wood", prob=254, param2=0},
		{name="vlf_core:glass", prob=254, param2=0},
		{name="vlf_stairs:stair_wood", prob=254, param2=3},
		{name="air", prob=254, param2=0},
		{name="air", prob=254, param2=0},
		{name="air", prob=254, param2=0},
		{name="air", prob=254, param2=0},
		{name="air", prob=254, param2=0},
		{name="air", prob=254, param2=0},
		{name="air", prob=254, param2=0},
		{name="air", prob=254, param2=0},
		{name="vlf_core:wood", prob=254, param2=0},
		{name="vlf_core:wood", prob=254, param2=0},
		{name="air", prob=254, param2=0},
		{name="air", prob=254, param2=0},
		{name="air", prob=254, param2=0},
		{name="air", prob=254, param2=0},
		{name="air", prob=254, param2=0},
		{name="air", prob=254, param2=0},
		{name="air", prob=254, param2=0},
		{name="air", prob=254, param2=0},
		{name="air", prob=254, param2=0},
		{name="air", prob=254, param2=0},
		{name="air", prob=254, param2=0},
		{name="air", prob=254, param2=0},
		{name="air", prob=254, param2=0},
		{name="air", prob=254, param2=0},
		{name="air", prob=254, param2=0},
		{name="air", prob=254, param2=0},
		{name="air", prob=254, param2=0},
		{name="air", prob=254, param2=0},
		{name="air", prob=254, param2=0},
		{name="air", prob=254, param2=0},
		{name="air", prob=254, param2=0},
		{name="air", prob=254, param2=0},
		{name="air", prob=254, param2=0},
		{name="air", prob=254, param2=0},
		{name="air", prob=254, param2=0},
		{name="air", prob=254, param2=0},
		{name="air", prob=254, param2=0},
		{name="vlf_core:dirt", prob=254, param2=0},
		{name="vlf_core:dirt", prob=254, param2=0},
		{name="vlf_core:dirt", prob=254, param2=0},
		{name="vlf_core:dirt", prob=254, param2=0},
		{name="vlf_core:dirt", prob=254, param2=0},
		{name="vlf_core:dirt", prob=254, param2=0},
		{name="vlf_core:dirt", prob=254, param2=0},
		{name="vlf_core:dirt", prob=254, param2=0},
		{name="vlf_core:dirt", prob=254, param2=0},
		{name="vlf_core:dirt", prob=254, param2=0},
		{name="vlf_core:dirt", prob=254, param2=0},
		{name="vlf_core:dirt", prob=254, param2=0},
		{name="air", prob=254, param2=0},
		{name="vlf_stairs:stair_cobble", prob=254, param2=1},
		{name="vlf_core:wood", prob=254, param2=0},
		{name="vlf_core:wood", prob=254, param2=0},
		{name="vlf_core:wood", prob=254, param2=0},
		{name="vlf_core:wood", prob=254, param2=0},
		{name="vlf_core:stonebrickcarved", prob=254, param2=0},
		{name="vlf_core:wood", prob=254, param2=0},
		{name="vlf_core:cobble", prob=254, param2=0},
		{name="vlf_core:cobble", prob=254, param2=0},
		{name="vlf_core:cobble", prob=254, param2=0},
		{name="vlf_core:cobble", prob=254, param2=0},
		{name="air", prob=254, param2=0},
		{name="air", prob=254, param2=0},
		{name="air", prob=254, param2=0},
		{name="vlf_doors:wooden_door_b_1", prob=254, param2=1},
		{name="air", prob=254, param2=0},
		{name="air", prob=254, param2=0},
		{name="air", prob=254, param2=0},
		{name="air", prob=254, param2=0},
		{name="vlf_fences:fence_gate", prob=254, param2=1},
		{name="air", prob=254, param2=0},
		{name="air", prob=254, param2=0},
		{name="vlf_core:cobble", prob=254, param2=0},
		{name="air", prob=254, param2=0},
		{name="air", prob=254, param2=0},
		{name="air", prob=254, param2=0},
		{name="vlf_doors:wooden_door_t_1", prob=254, param2=1},
		{name="air", prob=254, param2=0},
		{name="air", prob=254, param2=0},
		{name="air", prob=254, param2=0},
		{name="air", prob=254, param2=0},
		{name="air", prob=254, param2=0},
		{name="air", prob=254, param2=0},
		{name="air", prob=254, param2=0},
		{name="vlf_core:cobble", prob=254, param2=0},
		{name="air", prob=254, param2=0},
		{name="air", prob=254, param2=0},
		{name="vlf_itemframes:item_frame", prob=254, param2=1},
		{name="vlf_core:cobble", prob=254, param2=0},
		{name="air", prob=254, param2=0},
		{name="air", prob=254, param2=0},
		{name="air", prob=254, param2=0},
		{name="air", prob=254, param2=0},
		{name="vlf_stairs:slab_wood_top", prob=254, param2=0},
		{name="vlf_stairs:slab_wood_top", prob=254, param2=0},
		{name="vlf_stairs:slab_wood_top", prob=254, param2=0},
		{name="vlf_core:cobble", prob=254, param2=0},
		{name="air", prob=254, param2=0},
		{name="air", prob=254, param2=0},
		{name="vlf_stairs:slab_wood_top", prob=254, param2=0},
		{name="vlf_core:cobble", prob=254, param2=0},
		{name="air", prob=254, param2=0},
		{name="air", prob=254, param2=0},
		{name="air", prob=254, param2=0},
		{name="air", prob=254, param2=0},
		{name="vlf_fences:fence", prob=254, param2=0},
		{name="air", prob=254, param2=0},
		{name="air", prob=254, param2=0},
		{name="vlf_core:cobble", prob=254, param2=0},
		{name="air", prob=254, param2=0},
		{name="air", prob=254, param2=0},
		{name="air", prob=254, param2=0},
		{name="xpanes:pane_natural_flat", prob=254, param2=3},
		{name="air", prob=254, param2=0},
		{name="air", prob=254, param2=0},
		{name="air", prob=254, param2=0},
		{name="air", prob=254, param2=0},
		{name="air", prob=254, param2=0},
		{name="air", prob=254, param2=0},
		{name="air", prob=254, param2=0},
		{name="vlf_core:cobble", prob=254, param2=0},
		{name="air", prob=254, param2=0},
		{name="air", prob=254, param2=0},
		{name="air", prob=254, param2=0},
		{name="vlf_core:cobble", prob=254, param2=0},
		{name="air", prob=254, param2=0},
		{name="air", prob=254, param2=0},
		{name="air", prob=254, param2=0},
		{name="air", prob=254, param2=0},
		{name="air", prob=254, param2=0},
		{name="air", prob=254, param2=0},
		{name="air", prob=254, param2=0},
		{name="vlf_core:cobble", prob=254, param2=0},
		{name="air", prob=254, param2=0},
		{name="air", prob=254, param2=0},
		{name="air", prob=254, param2=0},
		{name="air", prob=254, param2=0},
		{name="vlf_core:cobble", prob=254, param2=0},
		{name="air", prob=254, param2=0},
		{name="air", prob=254, param2=0},
		{name="vlf_core:cobble", prob=254, param2=0},
		{name="vlf_core:cobble", prob=254, param2=0},
		{name="air", prob=254, param2=0},
		{name="vlf_core:cobble", prob=254, param2=0},
		{name="air", prob=254, param2=0},
		{name="air", prob=254, param2=0},
		{name="air", prob=254, param2=0},
		{name="air", prob=254, param2=0},
		{name="air", prob=254, param2=0},
		{name="vlf_stairs:stair_wood", prob=254, param2=1},
		{name="vlf_core:glass", prob=254, param2=0},
		{name="vlf_core:glass", prob=254, param2=0},
		{name="vlf_core:wood", prob=254, param2=0},
		{name="vlf_core:wood", prob=254, param2=0},
		{name="vlf_core:glass", prob=254, param2=0},
		{name="vlf_stairs:stair_wood", prob=254, param2=3},
		{name="air", prob=254, param2=0},
		{name="air", prob=254, param2=0},
		{name="air", prob=254, param2=0},
		{name="air", prob=254, param2=0},
		{name="air", prob=254, param2=0},
		{name="air", prob=254, param2=0},
		{name="air", prob=254, param2=0},
		{name="air", prob=254, param2=0},
		{name="vlf_core:wood", prob=254, param2=0},
		{name="vlf_core:wood", prob=254, param2=0},
		{name="air", prob=254, param2=0},
		{name="air", prob=254, param2=0},
		{name="air", prob=254, param2=0},
		{name="air", prob=254, param2=0},
		{name="air", prob=254, param2=0},
		{name="air", prob=254, param2=0},
		{name="air", prob=254, param2=0},
		{name="air", prob=254, param2=0},
		{name="air", prob=254, param2=0},
		{name="air", prob=254, param2=0},
		{name="air", prob=254, param2=0},
		{name="air", prob=254, param2=0},
		{name="air", prob=254, param2=0},
		{name="air", prob=254, param2=0},
		{name="air", prob=254, param2=0},
		{name="air", prob=254, param2=0},
		{name="air", prob=254, param2=0},
		{name="air", prob=254, param2=0},
		{name="air", prob=254, param2=0},
		{name="air", prob=254, param2=0},
		{name="air", prob=254, param2=0},
		{name="air", prob=254, param2=0},
		{name="air", prob=254, param2=0},
		{name="air", prob=254, param2=0},
		{name="air", prob=254, param2=0},
		{name="air", prob=254, param2=0},
		{name="air", prob=254, param2=0},
		{name="vlf_core:dirt", prob=254, param2=0},
		{name="vlf_core:dirt", prob=254, param2=0},
		{name="vlf_core:dirt", prob=254, param2=0},
		{name="vlf_core:dirt", prob=254, param2=0},
		{name="vlf_core:dirt", prob=254, param2=0},
		{name="vlf_core:dirt", prob=254, param2=0},
		{name="vlf_core:dirt", prob=254, param2=0},
		{name="vlf_core:dirt", prob=254, param2=0},
		{name="vlf_core:dirt", prob=254, param2=0},
		{name="vlf_core:dirt", prob=254, param2=0},
		{name="vlf_core:dirt", prob=254, param2=0},
		{name="vlf_core:dirt", prob=254, param2=0},
		{name="air", prob=254, param2=0},
		{name="vlf_stairs:stair_cobble_outer", prob=254, param2=2},
		{name="vlf_stairs:stair_cobble", prob=254, param2=2},
		{name="vlf_core:cobble", prob=254, param2=0},
		{name="vlf_core:wood", prob=254, param2=0},
		{name="vlf_core:wood", prob=254, param2=0},
		{name="vlf_core:wood", prob=254, param2=0},
		{name="vlf_core:wood", prob=254, param2=0},
		{name="vlf_core:cobble", prob=254, param2=0},
		{name="vlf_core:cobble", prob=254, param2=0},
		{name="vlf_core:cobble", prob=254, param2=0},
		{name="vlf_core:cobble", prob=254, param2=0},
		{name="air", prob=254, param2=0},
		{name="air", prob=254, param2=0},
		{name="air", prob=254, param2=0},
		{name="vlf_core:cobble", prob=254, param2=0},
		{name="air", prob=254, param2=0},
		{name="air", prob=254, param2=0},
		{name="air", prob=254, param2=0},
		{name="air", prob=254, param2=0},
		{name="vlf_fences:fence", prob=254, param2=0},
		{name="air", prob=254, param2=0},
		{name="air", prob=254, param2=0},
		{name="vlf_core:cobble", prob=254, param2=0},
		{name="air", prob=254, param2=0},
		{name="air", prob=254, param2=0},
		{name="vlf_walls:stonebrick_1", prob=254, param2=0},
		{name="vlf_core:cobble", prob=254, param2=0},
		{name="air", prob=254, param2=0},
		{name="air", prob=254, param2=0},
		{name="air", prob=254, param2=0},
		{name="air", prob=254, param2=0},
		{name="air", prob=254, param2=0},
		{name="air", prob=254, param2=0},
		{name="air", prob=254, param2=0},
		{name="vlf_core:cobble", prob=254, param2=0},
		{name="air", prob=254, param2=0},
		{name="air", prob=254, param2=0},
		{name="vlf_torches:torch", prob=254, param2=1},
		{name="vlf_core:cobble", prob=254, param2=0},
		{name="air", prob=254, param2=0},
		{name="air", prob=254, param2=0},
		{name="air", prob=254, param2=0},
		{name="air", prob=254, param2=0},
		{name="vlf_stairs:slab_wood_top", prob=254, param2=0},
		{name="vlf_stairs:slab_wood_top", prob=254, param2=0},
		{name="vlf_stairs:slab_wood_top", prob=254, param2=0},
		{name="vlf_core:cobble", prob=254, param2=0},
		{name="air", prob=254, param2=0},
		{name="air", prob=254, param2=0},
		{name="vlf_stairs:slab_wood_top", prob=254, param2=0},
		{name="vlf_core:cobble", prob=254, param2=0},
		{name="air", prob=254, param2=0},
		{name="air", prob=254, param2=0},
		{name="air", prob=254, param2=0},
		{name="air", prob=254, param2=0},
		{name="vlf_fences:fence", prob=254, param2=0},
		{name="air", prob=254, param2=0},
		{name="air", prob=254, param2=0},
		{name="vlf_core:cobble", prob=254, param2=0},
		{name="air", prob=254, param2=0},
		{name="air", prob=254, param2=0},
		{name="air", prob=254, param2=0},
		{name="xpanes:pane_natural_flat", prob=254, param2=3},
		{name="air", prob=254, param2=0},
		{name="air", prob=254, param2=0},
		{name="air", prob=254, param2=0},
		{name="air", prob=254, param2=0},
		{name="air", prob=254, param2=0},
		{name="air", prob=254, param2=0},
		{name="air", prob=254, param2=0},
		{name="vlf_core:cobble", prob=254, param2=0},
		{name="air", prob=254, param2=0},
		{name="air", prob=254, param2=0},
		{name="air", prob=254, param2=0},
		{name="vlf_core:cobble", prob=254, param2=0},
		{name="air", prob=254, param2=0},
		{name="air", prob=254, param2=0},
		{name="air", prob=254, param2=0},
		{name="air", prob=254, param2=0},
		{name="air", prob=254, param2=0},
		{name="air", prob=254, param2=0},
		{name="air", prob=254, param2=0},
		{name="vlf_core:cobble", prob=254, param2=0},
		{name="air", prob=254, param2=0},
		{name="air", prob=254, param2=0},
		{name="air", prob=254, param2=0},
		{name="air", prob=254, param2=0},
		{name="vlf_core:cobble", prob=254, param2=0},
		{name="air", prob=254, param2=0},
		{name="air", prob=254, param2=0},
		{name="vlf_core:cobble", prob=254, param2=0},
		{name="vlf_core:cobble", prob=254, param2=0},
		{name="air", prob=254, param2=0},
		{name="vlf_core:cobble", prob=254, param2=0},
		{name="air", prob=254, param2=0},
		{name="air", prob=254, param2=0},
		{name="air", prob=254, param2=0},
		{name="air", prob=254, param2=0},
		{name="air", prob=254, param2=0},
		{name="vlf_stairs:stair_wood", prob=254, param2=1},
		{name="vlf_core:glass", prob=254, param2=0},
		{name="vlf_core:glass", prob=254, param2=0},
		{name="vlf_core:wood", prob=254, param2=0},
		{name="vlf_core:wood", prob=254, param2=0},
		{name="vlf_core:glass", prob=254, param2=0},
		{name="vlf_stairs:stair_wood", prob=254, param2=3},
		{name="air", prob=254, param2=0},
		{name="air", prob=254, param2=0},
		{name="air", prob=254, param2=0},
		{name="air", prob=254, param2=0},
		{name="air", prob=254, param2=0},
		{name="air", prob=254, param2=0},
		{name="air", prob=254, param2=0},
		{name="air", prob=254, param2=0},
		{name="vlf_stairs:stair_wood", prob=254, param2=2},
		{name="vlf_stairs:stair_wood", prob=254, param2=2},
		{name="air", prob=254, param2=0},
		{name="air", prob=254, param2=0},
		{name="air", prob=254, param2=0},
		{name="air", prob=254, param2=0},
		{name="air", prob=254, param2=0},
		{name="air", prob=254, param2=0},
		{name="air", prob=254, param2=0},
		{name="air", prob=254, param2=0},
		{name="air", prob=254, param2=0},
		{name="air", prob=254, param2=0},
		{name="air", prob=254, param2=0},
		{name="air", prob=254, param2=0},
		{name="air", prob=254, param2=0},
		{name="air", prob=254, param2=0},
		{name="air", prob=254, param2=0},
		{name="air", prob=254, param2=0},
		{name="air", prob=254, param2=0},
		{name="air", prob=254, param2=0},
		{name="air", prob=254, param2=0},
		{name="air", prob=254, param2=0},
		{name="air", prob=254, param2=0},
		{name="air", prob=254, param2=0},
		{name="air", prob=254, param2=0},
		{name="air", prob=254, param2=0},
		{name="air", prob=254, param2=0},
		{name="air", prob=254, param2=0},
		{name="air", prob=254, param2=0},
		{name="vlf_core:dirt", prob=254, param2=0},
		{name="vlf_core:dirt", prob=254, param2=0},
		{name="vlf_core:dirt", prob=254, param2=0},
		{name="vlf_core:dirt", prob=254, param2=0},
		{name="vlf_core:dirt", prob=254, param2=0},
		{name="vlf_core:dirt", prob=254, param2=0},
		{name="vlf_core:dirt", prob=254, param2=0},
		{name="vlf_core:dirt", prob=254, param2=0},
		{name="vlf_core:dirt", prob=254, param2=0},
		{name="vlf_core:dirt", prob=254, param2=0},
		{name="vlf_core:dirt", prob=254, param2=0},
		{name="vlf_core:dirt", prob=254, param2=0},
		{name="air", prob=254, param2=0},
		{name="air", prob=254, param2=0},
		{name="air", prob=254, param2=0},
		{name="vlf_core:cobble", prob=254, param2=0},
		{name="vlf_core:wood", prob=254, param2=0},
		{name="vlf_core:wood", prob=254, param2=0},
		{name="vlf_core:wood", prob=254, param2=0},
		{name="vlf_core:wood", prob=254, param2=0},
		{name="vlf_core:cobble", prob=254, param2=0},
		{name="vlf_core:cobble", prob=254, param2=0},
		{name="vlf_core:cobble", prob=254, param2=0},
		{name="vlf_core:cobble", prob=254, param2=0},
		{name="air", prob=254, param2=0},
		{name="air", prob=254, param2=0},
		{name="air", prob=254, param2=0},
		{name="vlf_core:cobble", prob=254, param2=0},
		{name="vlf_stairs:stair_wood", prob=254, param2=3},
		{name="vlf_fences:fence", prob=254, param2=0},
		{name="vlf_stairs:stair_wood", prob=254, param2=1},
		{name="air", prob=254, param2=0},
		{name="vlf_core:stonebrick", prob=254, param2=0},
		{name="air", prob=254, param2=0},
		{name="vlf_barrels:barrel_closed", prob=254, param2=0},
		{name="vlf_core:cobble", prob=254, param2=0},
		{name="air", prob=254, param2=0},
		{name="air", prob=254, param2=0},
		{name="air", prob=254, param2=0},
		{name="vlf_core:cobble", prob=254, param2=0},
		{name="air", prob=254, param2=0},
		{name="mesecons_pressureplates:pressure_plate_wood_off", prob=254, param2=0},
		{name="air", prob=254, param2=0},
		{name="air", prob=254, param2=0},
		{name="vlf_core:stonebrick", prob=254, param2=0},
		{name="air", prob=254, param2=0},
		{name="air", prob=254, param2=0},
		{name="vlf_core:cobble", prob=254, param2=0},
		{name="air", prob=254, param2=0},
		{name="air", prob=254, param2=0},
		{name="air", prob=254, param2=0},
		{name="vlf_core:cobble", prob=254, param2=0},
		{name="air", prob=254, param2=0},
		{name="air", prob=254, param2=0},
		{name="air", prob=254, param2=0},
		{name="air", prob=254, param2=0},
		{name="vlf_core:wood", prob=254, param2=0},
		{name="vlf_stairs:slab_wood_top", prob=254, param2=0},
		{name="vlf_stairs:slab_wood_top", prob=254, param2=0},
		{name="vlf_core:cobble", prob=254, param2=0},
		{name="air", prob=254, param2=0},
		{name="air", prob=254, param2=0},
		{name="air", prob=254, param2=0},
		{name="vlf_core:cobble", prob=254, param2=0},
		{name="air", prob=254, param2=0},
		{name="air", prob=254, param2=0},
		{name="air", prob=254, param2=0},
		{name="air", prob=254, param2=0},
		{name="vlf_fences:fence", prob=254, param2=0},
		{name="air", prob=254, param2=0},
		{name="vlf_fences:fence", prob=254, param2=0},
		{name="vlf_core:cobble", prob=254, param2=0},
		{name="air", prob=254, param2=0},
		{name="air", prob=254, param2=0},
		{name="air", prob=254, param2=0},
		{name="vlf_core:cobble", prob=254, param2=0},
		{name="vlf_walls:cobble_6", prob=254, param2=0},
		{name="air", prob=254, param2=0},
		{name="air", prob=254, param2=0},
		{name="air", prob=254, param2=0},
		{name="air", prob=254, param2=0},
		{name="air", prob=254, param2=0},
		{name="mesecons_pressureplates:pressure_plate_wood_off", prob=254, param2=0},
		{name="vlf_core:cobble", prob=254, param2=0},
		{name="air", prob=254, param2=0},
		{name="air", prob=254, param2=0},
		{name="air", prob=254, param2=0},
		{name="vlf_core:cobble", prob=254, param2=0},
		{name="vlf_torches:torch", prob=254, param2=1},
		{name="air", prob=254, param2=0},
		{name="air", prob=254, param2=0},
		{name="air", prob=254, param2=0},
		{name="air", prob=254, param2=0},
		{name="air", prob=254, param2=0},
		{name="air", prob=254, param2=0},
		{name="vlf_core:cobble", prob=254, param2=0},
		{name="air", prob=254, param2=0},
		{name="air", prob=254, param2=0},
		{name="air", prob=254, param2=0},
		{name="air", prob=254, param2=0},
		{name="vlf_core:cobble", prob=254, param2=0},
		{name="vlf_core:cobble", prob=254, param2=0},
		{name="vlf_core:cobble", prob=254, param2=0},
		{name="vlf_core:cobble", prob=254, param2=0},
		{name="vlf_core:cobble", prob=254, param2=0},
		{name="vlf_core:cobble", prob=254, param2=0},
		{name="vlf_core:cobble", prob=254, param2=0},
		{name="air", prob=254, param2=0},
		{name="air", prob=254, param2=0},
		{name="air", prob=254, param2=0},
		{name="air", prob=254, param2=0},
		{name="air", prob=254, param2=0},
		{name="vlf_stairs:stair_wood_outer", prob=254, param2=2},
		{name="vlf_stairs:stair_wood", prob=254, param2=2},
		{name="vlf_stairs:stair_wood", prob=254, param2=2},
		{name="vlf_stairs:stair_wood", prob=254, param2=2},
		{name="vlf_stairs:stair_wood", prob=254, param2=2},
		{name="vlf_stairs:stair_wood", prob=254, param2=2},
		{name="vlf_stairs:stair_wood_outer", prob=254, param2=3},
		{name="air", prob=254, param2=0},
		{name="air", prob=254, param2=0},
		{name="air", prob=254, param2=0},
		{name="air", prob=254, param2=0},
		{name="air", prob=254, param2=0},
		{name="air", prob=254, param2=0},
		{name="air", prob=254, param2=0},
		{name="air", prob=254, param2=0},
		{name="air", prob=254, param2=0},
		{name="air", prob=254, param2=0},
		{name="air", prob=254, param2=0},
		{name="air", prob=254, param2=0},
		{name="air", prob=254, param2=0},
		{name="air", prob=254, param2=0},
		{name="air", prob=254, param2=0},
		{name="air", prob=254, param2=0},
		{name="air", prob=254, param2=0},
		{name="air", prob=254, param2=0},
		{name="air", prob=254, param2=0},
		{name="air", prob=254, param2=0},
		{name="air", prob=254, param2=0},
		{name="air", prob=254, param2=0},
		{name="air", prob=254, param2=0},
		{name="air", prob=254, param2=0},
		{name="air", prob=254, param2=0},
		{name="air", prob=254, param2=0},
		{name="air", prob=254, param2=0},
		{name="air", prob=254, param2=0},
		{name="air", prob=254, param2=0},
		{name="air", prob=254, param2=0},
		{name="air", prob=254, param2=0},
		{name="air", prob=254, param2=0},
		{name="air", prob=254, param2=0},
		{name="air", prob=254, param2=0},
		{name="air", prob=254, param2=0},
		{name="air", prob=254, param2=0},
		{name="air", prob=254, param2=0},
		{name="vlf_core:dirt", prob=254, param2=0},
		{name="vlf_core:dirt", prob=254, param2=0},
		{name="vlf_core:dirt", prob=254, param2=0},
		{name="vlf_core:dirt", prob=254, param2=0},
		{name="vlf_core:dirt", prob=254, param2=0},
		{name="vlf_core:dirt", prob=254, param2=0},
		{name="vlf_core:dirt", prob=254, param2=0},
		{name="vlf_core:dirt", prob=254, param2=0},
		{name="vlf_core:dirt", prob=254, param2=0},
		{name="vlf_core:dirt", prob=254, param2=0},
		{name="vlf_core:dirt", prob=254, param2=0},
		{name="vlf_core:dirt", prob=254, param2=0},
		{name="air", prob=254, param2=0},
		{name="air", prob=254, param2=0},
		{name="air", prob=254, param2=0},
		{name="vlf_core:cobble", prob=254, param2=0},
		{name="vlf_core:cobble", prob=254, param2=0},
		{name="vlf_core:cobble", prob=254, param2=0},
		{name="vlf_core:cobble", prob=254, param2=0},
		{name="vlf_core:cobble", prob=254, param2=0},
		{name="vlf_core:cobble", prob=254, param2=0},
		{name="vlf_core:cobble", prob=254, param2=0},
		{name="vlf_core:cobble", prob=254, param2=0},
		{name="vlf_core:cobble", prob=254, param2=0},
		{name="air", prob=254, param2=0},
		{name="air", prob=254, param2=0},
		{name="air", prob=254, param2=0},
		{name="vlf_core:wood", prob=254, param2=0},
		{name="vlf_core:cobble", prob=254, param2=0},
		{name="vlf_core:cobble", prob=254, param2=0},
		{name="vlf_core:cobble", prob=254, param2=0},
		{name="vlf_core:cobble", prob=254, param2=0},
		{name="vlf_core:cobble", prob=254, param2=0},
		{name="vlf_core:cobble", prob=254, param2=0},
		{name="vlf_core:cobble", prob=254, param2=0},
		{name="vlf_core:wood", prob=254, param2=0},
		{name="air", prob=254, param2=0},
		{name="air", prob=254, param2=0},
		{name="air", prob=254, param2=0},
		{name="vlf_core:wood", prob=254, param2=0},
		{name="vlf_core:cobble", prob=254, param2=0},
		{name="vlf_core:cobble", prob=254, param2=0},
		{name="vlf_core:cobble", prob=254, param2=0},
		{name="vlf_core:cobble", prob=254, param2=0},
		{name="vlf_core:cobble", prob=254, param2=0},
		{name="vlf_core:cobble", prob=254, param2=0},
		{name="vlf_core:cobble", prob=254, param2=0},
		{name="vlf_core:wood", prob=254, param2=0},
		{name="air", prob=254, param2=0},
		{name="air", prob=254, param2=0},
		{name="air", prob=254, param2=0},
		{name="vlf_core:wood", prob=254, param2=0},
		{name="vlf_core:cobble", prob=254, param2=0},
		{name="xpanes:pane_natural_flat", prob=254, param2=2},
		{name="xpanes:pane_natural_flat", prob=254, param2=0},
		{name="vlf_core:cobble", prob=254, param2=0},
		{name="vlf_core:cobble", prob=254, param2=0},
		{name="vlf_core:cobble", prob=254, param2=0},
		{name="vlf_core:cobble", prob=254, param2=0},
		{name="vlf_core:wood", prob=254, param2=0},
		{name="air", prob=254, param2=0},
		{name="air", prob=254, param2=0},
		{name="air", prob=254, param2=0},
		{name="vlf_core:wood", prob=254, param2=0},
		{name="vlf_core:cobble", prob=254, param2=0},
		{name="xpanes:pane_natural_flat", prob=254, param2=2},
		{name="xpanes:pane_natural_flat", prob=254, param2=0},
		{name="vlf_core:cobble", prob=254, param2=0},
		{name="vlf_core:cobble", prob=254, param2=0},
		{name="vlf_core:cobble", prob=254, param2=0},
		{name="vlf_core:cobble", prob=254, param2=0},
		{name="vlf_core:wood", prob=254, param2=0},
		{name="air", prob=254, param2=0},
		{name="air", prob=254, param2=0},
		{name="air", prob=254, param2=0},
		{name="vlf_core:wood", prob=254, param2=0},
		{name="vlf_core:cobble", prob=254, param2=0},
		{name="vlf_core:cobble", prob=254, param2=0},
		{name="vlf_core:cobble", prob=254, param2=0},
		{name="vlf_core:cobble", prob=254, param2=0},
		{name="vlf_core:cobble", prob=254, param2=0},
		{name="vlf_core:cobble", prob=254, param2=0},
		{name="vlf_core:cobble", prob=254, param2=0},
		{name="vlf_core:wood", prob=254, param2=0},
		{name="air", prob=254, param2=0},
		{name="air", prob=254, param2=0},
		{name="air", prob=254, param2=0},
		{name="vlf_core:wood", prob=254, param2=0},
		{name="vlf_core:cobble", prob=254, param2=0},
		{name="vlf_core:cobble", prob=254, param2=0},
		{name="vlf_core:cobble", prob=254, param2=0},
		{name="vlf_core:cobble", prob=254, param2=0},
		{name="vlf_core:cobble", prob=254, param2=0},
		{name="vlf_core:cobble", prob=254, param2=0},
		{name="vlf_core:cobble", prob=254, param2=0},
		{name="vlf_core:wood", prob=254, param2=0},
		{name="air", prob=254, param2=0},
		{name="air", prob=254, param2=0},
		{name="air", prob=254, param2=0},
		{name="vlf_core:wood", prob=254, param2=0},
		{name="air", prob=254, param2=0},
		{name="air", prob=254, param2=0},
		{name="air", prob=254, param2=0},
		{name="air", prob=254, param2=0},
		{name="air", prob=254, param2=0},
		{name="air", prob=254, param2=0},
		{name="air", prob=254, param2=0},
		{name="vlf_core:wood", prob=254, param2=0},
		{name="air", prob=254, param2=0},
		{name="air", prob=254, param2=0},
		{name="air", prob=254, param2=0},
		{name="air", prob=254, param2=0},
		{name="air", prob=254, param2=0},
		{name="air", prob=254, param2=0},
		{name="air", prob=254, param2=0},
		{name="air", prob=254, param2=0},
		{name="air", prob=254, param2=0},
		{name="air", prob=254, param2=0},
		{name="air", prob=254, param2=0},
		{name="air", prob=254, param2=0},
		{name="air", prob=254, param2=0},
		{name="air", prob=254, param2=0},
		{name="air", prob=254, param2=0},
		{name="air", prob=254, param2=0},
		{name="air", prob=254, param2=0},
		{name="air", prob=254, param2=0},
		{name="air", prob=254, param2=0},
		{name="air", prob=254, param2=0},
		{name="air", prob=254, param2=0},
		{name="air", prob=254, param2=0},
		{name="air", prob=254, param2=0},
		{name="air", prob=254, param2=0},
		{name="air", prob=254, param2=0},
		{name="air", prob=254, param2=0},
		{name="air", prob=254, param2=0},
		{name="air", prob=254, param2=0},
		{name="air", prob=254, param2=0},
		{name="air", prob=254, param2=0},
		{name="air", prob=254, param2=0},
		{name="air", prob=254, param2=0},
		{name="air", prob=254, param2=0},
		{name="air", prob=254, param2=0},
		{name="air", prob=254, param2=0},
		{name="air", prob=254, param2=0},
		{name="air", prob=254, param2=0},
		{name="air", prob=254, param2=0},
		{name="air", prob=254, param2=0},
		{name="air", prob=254, param2=0},
		{name="air", prob=254, param2=0},
		{name="air", prob=254, param2=0},
		{name="air", prob=254, param2=0},
		{name="air", prob=254, param2=0},
		{name="air", prob=254, param2=0},
		{name="air", prob=254, param2=0},
		{name="air", prob=254, param2=0},
		{name="air", prob=254, param2=0},
		{name="vlf_core:dirt", prob=254, param2=0},
		{name="vlf_core:dirt", prob=254, param2=0},
		{name="vlf_core:dirt", prob=254, param2=0},
		{name="vlf_core:dirt", prob=254, param2=0},
		{name="vlf_core:dirt", prob=254, param2=0},
		{name="vlf_core:dirt", prob=254, param2=0},
		{name="vlf_core:dirt", prob=254, param2=0},
		{name="vlf_core:dirt", prob=254, param2=0},
		{name="vlf_core:dirt", prob=254, param2=0},
		{name="vlf_core:dirt", prob=254, param2=0},
		{name="vlf_core:dirt", prob=254, param2=0},
		{name="vlf_core:dirt", prob=254, param2=0},
		{name="air", prob=254, param2=0},
		{name="air", prob=254, param2=0},
		{name="air", prob=254, param2=0},
		{name="air", prob=254, param2=0},
		{name="air", prob=254, param2=0},
		{name="air", prob=254, param2=0},
		{name="air", prob=254, param2=0},
		{name="air", prob=254, param2=0},
		{name="air", prob=254, param2=0},
		{name="air", prob=254, param2=0},
		{name="air", prob=254, param2=0},
		{name="air", prob=254, param2=0},
		{name="air", prob=254, param2=0},
		{name="air", prob=254, param2=0},
		{name="air", prob=254, param2=0},
		{name="air", prob=254, param2=0},
		{name="air", prob=254, param2=0},
		{name="air", prob=254, param2=0},
		{name="air", prob=254, param2=0},
		{name="air", prob=254, param2=0},
		{name="air", prob=254, param2=0},
		{name="air", prob=254, param2=0},
		{name="air", prob=254, param2=0},
		{name="air", prob=254, param2=0},
		{name="air", prob=254, param2=0},
		{name="air", prob=254, param2=0},
		{name="air", prob=254, param2=0},
		{name="air", prob=254, param2=0},
		{name="air", prob=254, param2=0},
		{name="air", prob=254, param2=0},
		{name="air", prob=254, param2=0},
		{name="air", prob=254, param2=0},
		{name="air", prob=254, param2=0},
		{name="air", prob=254, param2=0},
		{name="air", prob=254, param2=0},
		{name="air", prob=254, param2=0},
		{name="air", prob=254, param2=0},
		{name="air", prob=254, param2=0},
		{name="air", prob=254, param2=0},
		{name="air", prob=254, param2=0},
		{name="air", prob=254, param2=0},
		{name="air", prob=254, param2=0},
		{name="air", prob=254, param2=0},
		{name="air", prob=254, param2=0},
		{name="air", prob=254, param2=0},
		{name="air", prob=254, param2=0},
		{name="air", prob=254, param2=0},
		{name="air", prob=254, param2=0},
		{name="air", prob=254, param2=0},
		{name="air", prob=254, param2=0},
		{name="air", prob=254, param2=0},
		{name="air", prob=254, param2=0},
		{name="air", prob=254, param2=0},
		{name="air", prob=254, param2=0},
		{name="air", prob=254, param2=0},
		{name="air", prob=254, param2=0},
		{name="air", prob=254, param2=0},
		{name="air", prob=254, param2=0},
		{name="air", prob=254, param2=0},
		{name="air", prob=254, param2=0},
		{name="air", prob=254, param2=0},
		{name="air", prob=254, param2=0},
		{name="air", prob=254, param2=0},
		{name="air", prob=254, param2=0},
		{name="air", prob=254, param2=0},
		{name="air", prob=254, param2=0},
		{name="air", prob=254, param2=0},
		{name="air", prob=254, param2=0},
		{name="air", prob=254, param2=0},
		{name="air", prob=254, param2=0},
		{name="air", prob=254, param2=0},
		{name="air", prob=254, param2=0},
		{name="air", prob=254, param2=0},
		{name="air", prob=254, param2=0},
		{name="air", prob=254, param2=0},
		{name="air", prob=254, param2=0},
		{name="air", prob=254, param2=0},
		{name="air", prob=254, param2=0},
		{name="air", prob=254, param2=0},
		{name="air", prob=254, param2=0},
		{name="air", prob=254, param2=0},
		{name="air", prob=254, param2=0},
		{name="air", prob=254, param2=0},
		{name="air", prob=254, param2=0},
		{name="air", prob=254, param2=0},
		{name="air", prob=254, param2=0},
		{name="air", prob=254, param2=0},
		{name="air", prob=254, param2=0},
		{name="air", prob=254, param2=0},
		{name="air", prob=254, param2=0},
		{name="air", prob=254, param2=0},
		{name="air", prob=254, param2=0},
		{name="air", prob=254, param2=0},
		{name="air", prob=254, param2=0},
		{name="air", prob=254, param2=0},
		{name="air", prob=254, param2=0},
		{name="air", prob=254, param2=0},
		{name="air", prob=254, param2=0},
		{name="air", prob=254, param2=0},
		{name="air", prob=254, param2=0},
		{name="air", prob=254, param2=0},
		{name="air", prob=254, param2=0},
		{name="air", prob=254, param2=0},
		{name="air", prob=254, param2=0},
		{name="air", prob=254, param2=0},
		{name="air", prob=254, param2=0},
		{name="air", prob=254, param2=0},
		{name="air", prob=254, param2=0},
		{name="air", prob=254, param2=0},
		{name="air", prob=254, param2=0},
		{name="air", prob=254, param2=0},
		{name="air", prob=254, param2=0},
		{name="air", prob=254, param2=0},
		{name="air", prob=254, param2=0},
		{name="air", prob=254, param2=0},
		{name="air", prob=254, param2=0},
		{name="air", prob=254, param2=0},
		{name="air", prob=254, param2=0},
		{name="air", prob=254, param2=0},
		{name="air", prob=254, param2=0},
		{name="air", prob=254, param2=0},
		{name="air", prob=254, param2=0},
		{name="air", prob=254, param2=0},
		{name="air", prob=254, param2=0},
		{name="air", prob=254, param2=0},
		{name="air", prob=254, param2=0},
		{name="air", prob=254, param2=0},
		{name="air", prob=254, param2=0},
		{name="air", prob=254, param2=0},
		{name="air", prob=254, param2=0},
		{name="air", prob=254, param2=0},
		{name="air", prob=254, param2=0},
		{name="air", prob=254, param2=0},
		{name="air", prob=254, param2=0},
		{name="air", prob=254, param2=0},
		{name="air", prob=254, param2=0},
		{name="air", prob=254, param2=0},
		{name="air", prob=254, param2=0},
		{name="air", prob=254, param2=0},
		{name="air", prob=254, param2=0},
		{name="air", prob=254, param2=0},
		{name="air", prob=254, param2=0},
		{name="air", prob=254, param2=0},
		{name="air", prob=254, param2=0},
	},
}
