schematic = {
	size = {x=6, y=5, z=8},
	yslice_prob = {
		{ypos=0, prob=254},
		{ypos=1, prob=254},
		{ypos=2, prob=254},
		{ypos=3, prob=254},
		{ypos=4, prob=254},
	},
	data = {
		{name="air", prob=0, param2=0},
		{name="vlf_core:sand", prob=254, param2=0},
		{name="vlf_core:sand", prob=254, param2=0},
		{name="vlf_core:sand", prob=254, param2=0},
		{name="vlf_core:sand", prob=254, param2=0},
		{name="vlf_core:sand", prob=254, param2=0},
		{name="air", prob=0, param2=0},
		{name="vlf_core:sandstonecarved", prob=254, param2=0},
		{name="air", prob=0, param2=0},
		{name="air", prob=0, param2=0},
		{name="vlf_core:sandstonecarved", prob=254, param2=0},
		{name="air", prob=0, param2=0},
		{name="air", prob=0, param2=0},
		{name="vlf_core:sandstonecarved", prob=254, param2=0},
		{name="air", prob=0, param2=0},
		{name="air", prob=0, param2=0},
		{name="vlf_core:sandstonecarved", prob=254, param2=0},
		{name="air", prob=0, param2=0},
		{name="air", prob=0, param2=0},
		{name="vlf_core:sandstonecarved", prob=254, param2=0},
		{name="air", prob=0, param2=0},
		{name="air", prob=0, param2=0},
		{name="vlf_core:sandstonecarved", prob=254, param2=0},
		{name="air", prob=0, param2=0},
		{name="air", prob=0, param2=0},
		{name="vlf_ocean:sea_lantern", prob=254, param2=3},
		{name="air", prob=0, param2=0},
		{name="air", prob=0, param2=0},
		{name="vlf_ocean:sea_lantern", prob=254, param2=0},
		{name="air", prob=0, param2=0},
		{name="vlf_core:sand", prob=254, param2=0},
		{name="vlf_core:sand", prob=254, param2=0},
		{name="vlf_core:sand", prob=254, param2=0},
		{name="vlf_core:sand", prob=254, param2=0},
		{name="vlf_core:sand", prob=254, param2=0},
		{name="vlf_core:sand", prob=254, param2=0},
		{name="air", prob=0, param2=0},
		{name="air", prob=0, param2=0},
		{name="air", prob=0, param2=0},
		{name="air", prob=0, param2=0},
		{name="air", prob=0, param2=0},
		{name="air", prob=0, param2=0},
		{name="air", prob=0, param2=0},
		{name="air", prob=0, param2=0},
		{name="air", prob=0, param2=0},
		{name="air", prob=0, param2=0},
		{name="air", prob=0, param2=0},
		{name="air", prob=0, param2=0},
		{name="air", prob=0, param2=0},
		{name="air", prob=0, param2=0},
		{name="air", prob=0, param2=0},
		{name="air", prob=0, param2=0},
		{name="air", prob=0, param2=0},
		{name="air", prob=0, param2=0},
		{name="air", prob=0, param2=0},
		{name="vlf_core:sandstonecarved", prob=254, param2=0},
		{name="vlf_core:sandstonesmooth", prob=254, param2=0},
		{name="vlf_core:sandstonesmooth", prob=254, param2=0},
		{name="vlf_core:sandstonesmooth", prob=254, param2=0},
		{name="air", prob=0, param2=0},
		{name="vlf_core:sand", prob=254, param2=0},
		{name="vlf_core:sand", prob=254, param2=0},
		{name="vlf_nether:magma", prob=254, param2=0},
		{name="vlf_core:sand", prob=254, param2=0},
		{name="vlf_nether:magma", prob=254, param2=0},
		{name="vlf_core:sand", prob=254, param2=0},
		{name="vlf_core:sandstonecarved", prob=254, param2=0},
		{name="air", prob=0, param2=0},
		{name="air", prob=0, param2=0},
		{name="air", prob=0, param2=0},
		{name="air", prob=0, param2=0},
		{name="vlf_core:sandstonecarved", prob=254, param2=0},
		{name="vlf_core:sandstonecarved", prob=254, param2=0},
		{name="air", prob=0, param2=0},
		{name="air", prob=0, param2=0},
		{name="air", prob=0, param2=0},
		{name="air", prob=0, param2=0},
		{name="vlf_core:sandstonecarved", prob=254, param2=0},
		{name="vlf_core:sandstonecarved", prob=254, param2=0},
		{name="air", prob=0, param2=0},
		{name="air", prob=0, param2=0},
		{name="air", prob=0, param2=0},
		{name="air", prob=0, param2=0},
		{name="vlf_core:sandstonecarved", prob=254, param2=0},
		{name="vlf_ocean:sea_lantern", prob=254, param2=3},
		{name="vlf_core:sandstonesmooth", prob=254, param2=0},
		{name="vlf_core:sandstone", prob=254, param2=0},
		{name="vlf_core:sandstone", prob=254, param2=0},
		{name="vlf_core:granite_smooth", prob=254, param2=0},
		{name="vlf_ocean:sea_lantern", prob=254, param2=3},
		{name="vlf_core:sand", prob=254, param2=0},
		{name="vlf_core:sand", prob=254, param2=0},
		{name="vlf_core:sand", prob=254, param2=0},
		{name="vlf_core:sand", prob=254, param2=0},
		{name="vlf_core:sand", prob=254, param2=0},
		{name="vlf_core:sand", prob=254, param2=0},
		{name="air", prob=0, param2=0},
		{name="air", prob=0, param2=0},
		{name="air", prob=0, param2=0},
		{name="vlf_chests:chest_small", prob=254, param2=1},
		{name="air", prob=0, param2=0},
		{name="air", prob=0, param2=0},
		{name="air", prob=0, param2=0},
		{name="air", prob=0, param2=0},
		{name="air", prob=0, param2=0},
		{name="air", prob=0, param2=0},
		{name="air", prob=0, param2=0},
		{name="air", prob=0, param2=0},
		{name="air", prob=0, param2=0},
		{name="air", prob=0, param2=0},
		{name="air", prob=0, param2=0},
		{name="air", prob=0, param2=0},
		{name="air", prob=0, param2=0},
		{name="air", prob=0, param2=0},
		{name="air", prob=0, param2=0},
		{name="vlf_core:sandstonecarved", prob=254, param2=0},
		{name="vlf_core:granite_smooth", prob=254, param2=0},
		{name="vlf_core:sandstonesmooth", prob=254, param2=0},
		{name="vlf_core:sandstone", prob=254, param2=0},
		{name="air", prob=0, param2=0},
		{name="vlf_core:sand", prob=254, param2=0},
		{name="vlf_nether:magma", prob=254, param2=0},
		{name="vlf_core:sand", prob=254, param2=0},
		{name="vlf_nether:magma", prob=254, param2=0},
		{name="vlf_core:sand", prob=254, param2=0},
		{name="vlf_core:sand", prob=254, param2=0},
		{name="air", prob=0, param2=0},
		{name="air", prob=0, param2=0},
		{name="air", prob=0, param2=0},
		{name="air", prob=0, param2=0},
		{name="air", prob=0, param2=0},
		{name="air", prob=0, param2=0},
		{name="air", prob=0, param2=0},
		{name="air", prob=0, param2=0},
		{name="air", prob=0, param2=0},
		{name="air", prob=0, param2=0},
		{name="air", prob=0, param2=0},
		{name="air", prob=0, param2=0},
		{name="air", prob=0, param2=0},
		{name="air", prob=0, param2=0},
		{name="air", prob=0, param2=0},
		{name="air", prob=0, param2=0},
		{name="air", prob=0, param2=0},
		{name="air", prob=0, param2=0},
		{name="air", prob=0, param2=0},
		{name="vlf_core:sandstone", prob=254, param2=0},
		{name="vlf_core:sandstone", prob=254, param2=0},
		{name="vlf_core:sandstonesmooth", prob=254, param2=0},
		{name="vlf_core:sandstonecarved", prob=254, param2=0},
		{name="air", prob=0, param2=0},
		{name="vlf_core:sand", prob=254, param2=0},
		{name="vlf_core:sand", prob=254, param2=0},
		{name="vlf_core:sand", prob=254, param2=0},
		{name="vlf_core:sand", prob=254, param2=0},
		{name="vlf_core:sand", prob=254, param2=0},
		{name="vlf_core:sand", prob=254, param2=0},
		{name="vlf_core:sandstonecarved", prob=254, param2=0},
		{name="air", prob=0, param2=0},
		{name="air", prob=0, param2=0},
		{name="air", prob=0, param2=0},
		{name="air", prob=0, param2=0},
		{name="vlf_core:sandstonecarved", prob=254, param2=0},
		{name="vlf_core:sandstonecarved", prob=254, param2=0},
		{name="air", prob=0, param2=0},
		{name="air", prob=0, param2=0},
		{name="air", prob=0, param2=0},
		{name="air", prob=0, param2=0},
		{name="vlf_core:sandstonecarved", prob=254, param2=0},
		{name="vlf_core:sandstonecarved", prob=254, param2=0},
		{name="air", prob=0, param2=0},
		{name="air", prob=0, param2=0},
		{name="air", prob=0, param2=0},
		{name="air", prob=0, param2=0},
		{name="vlf_core:sandstonecarved", prob=254, param2=0},
		{name="vlf_ocean:sea_lantern", prob=254, param2=3},
		{name="vlf_core:sandstone", prob=254, param2=0},
		{name="vlf_core:sandstone", prob=254, param2=0},
		{name="vlf_core:granite_smooth", prob=254, param2=0},
		{name="vlf_core:sandstonesmooth", prob=254, param2=0},
		{name="vlf_ocean:sea_lantern", prob=254, param2=3},
		{name="vlf_core:sand", prob=254, param2=0},
		{name="vlf_core:sand", prob=254, param2=0},
		{name="vlf_nether:magma", prob=254, param2=0},
		{name="vlf_core:sand", prob=254, param2=0},
		{name="vlf_core:sand", prob=254, param2=0},
		{name="vlf_core:sand", prob=254, param2=0},
		{name="air", prob=0, param2=0},
		{name="air", prob=0, param2=0},
		{name="air", prob=0, param2=0},
		{name="air", prob=0, param2=0},
		{name="air", prob=0, param2=0},
		{name="air", prob=0, param2=0},
		{name="air", prob=0, param2=0},
		{name="air", prob=0, param2=0},
		{name="air", prob=0, param2=0},
		{name="air", prob=0, param2=0},
		{name="air", prob=0, param2=0},
		{name="air", prob=0, param2=0},
		{name="air", prob=0, param2=0},
		{name="air", prob=0, param2=0},
		{name="air", prob=0, param2=0},
		{name="air", prob=0, param2=0},
		{name="air", prob=0, param2=0},
		{name="air", prob=0, param2=0},
		{name="air", prob=0, param2=0},
		{name="vlf_core:sandstone", prob=254, param2=0},
		{name="vlf_core:sandstone", prob=254, param2=0},
		{name="vlf_core:sandstonesmooth", prob=254, param2=0},
		{name="vlf_core:sandstonesmooth", prob=254, param2=0},
		{name="air", prob=0, param2=0},
		{name="air", prob=0, param2=0},
		{name="vlf_core:sand", prob=254, param2=0},
		{name="vlf_core:sand", prob=254, param2=0},
		{name="vlf_core:sand", prob=254, param2=0},
		{name="vlf_core:sand", prob=254, param2=0},
		{name="air", prob=0, param2=0},
		{name="air", prob=0, param2=0},
		{name="vlf_core:sandstonecarved", prob=254, param2=0},
		{name="air", prob=0, param2=0},
		{name="air", prob=0, param2=0},
		{name="vlf_core:sandstonecarved", prob=254, param2=0},
		{name="air", prob=0, param2=0},
		{name="air", prob=0, param2=0},
		{name="vlf_core:sandstonecarved", prob=254, param2=0},
		{name="air", prob=0, param2=0},
		{name="air", prob=0, param2=0},
		{name="vlf_core:sandstonecarved", prob=254, param2=0},
		{name="air", prob=0, param2=0},
		{name="air", prob=0, param2=0},
		{name="vlf_core:sandstonecarved", prob=254, param2=0},
		{name="air", prob=0, param2=0},
		{name="air", prob=0, param2=0},
		{name="vlf_core:sandstonecarved", prob=254, param2=0},
		{name="air", prob=0, param2=0},
		{name="air", prob=0, param2=0},
		{name="vlf_ocean:sea_lantern", prob=254, param2=3},
		{name="air", prob=0, param2=0},
		{name="air", prob=0, param2=0},
		{name="vlf_ocean:sea_lantern", prob=254, param2=3},
		{name="air", prob=0, param2=0},
	},
}
