schematic = {
	size = {x=5, y=3, z=5},
	yslice_prob = {
		{ypos=0, prob=254},
		{ypos=1, prob=254},
		{ypos=2, prob=254},
	},
	data = {
		{name="air", prob=254, param2=0},
		{name="air", prob=254, param2=0},
		{name="air", prob=254, param2=0},
		{name="air", prob=254, param2=0},
		{name="air", prob=254, param2=0},
		{name="air", prob=254, param2=0},
		{name="vlf_trees:leaves_oak", prob=254, param2=128},
		{name="vlf_trees:leaves_oak", prob=254, param2=96},
		{name="vlf_trees:leaves_oak", prob=254, param2=128},
		{name="air", prob=254, param2=0},
		{name="air", prob=254, param2=0},
		{name="air", prob=254, param2=0},
		{name="air", prob=254, param2=0},
		{name="air", prob=254, param2=0},
		{name="air", prob=254, param2=0},
		{name="air", prob=254, param2=0},
		{name="air", prob=254, param2=0},
		{name="air", prob=254, param2=0},
		{name="air", prob=254, param2=0},
		{name="air", prob=254, param2=0},
		{name="vlf_trees:leaves_oak", prob=254, param2=128},
		{name="vlf_trees:leaves_oak", prob=254, param2=96},
		{name="vlf_trees:leaves_oak", prob=254, param2=64},
		{name="vlf_trees:leaves_oak", prob=254, param2=96},
		{name="vlf_trees:leaves_oak", prob=254, param2=128},
		{name="air", prob=254, param2=0},
		{name="air", prob=254, param2=0},
		{name="vlf_trees:leaves_oak", prob=254, param2=96},
		{name="air", prob=254, param2=0},
		{name="air", prob=254, param2=0},
		{name="air", prob=254, param2=0},
		{name="air", prob=254, param2=0},
		{name="vlf_trees:tree_jungle", prob=254, param2=0},
		{name="air", prob=254, param2=0},
		{name="air", prob=254, param2=0},
		{name="vlf_trees:leaves_oak", prob=254, param2=96},
		{name="vlf_trees:leaves_oak", prob=254, param2=64},
		{name="vlf_trees:tree_jungle", prob=254, param2=0},
		{name="vlf_trees:leaves_oak", prob=254, param2=64},
		{name="vlf_trees:leaves_oak", prob=254, param2=96},
		{name="air", prob=254, param2=0},
		{name="vlf_trees:leaves_oak", prob=254, param2=96},
		{name="vlf_trees:leaves_oak", prob=254, param2=64},
		{name="vlf_trees:leaves_oak", prob=254, param2=96},
		{name="air", prob=254, param2=0},
		{name="air", prob=254, param2=0},
		{name="air", prob=254, param2=0},
		{name="air", prob=254, param2=0},
		{name="air", prob=254, param2=0},
		{name="air", prob=254, param2=0},
		{name="vlf_trees:leaves_oak", prob=254, param2=128},
		{name="vlf_trees:leaves_oak", prob=254, param2=96},
		{name="vlf_trees:leaves_oak", prob=254, param2=64},
		{name="vlf_trees:leaves_oak", prob=254, param2=96},
		{name="vlf_trees:leaves_oak", prob=254, param2=128},
		{name="air", prob=254, param2=0},
		{name="air", prob=254, param2=0},
		{name="vlf_trees:leaves_oak", prob=254, param2=96},
		{name="air", prob=254, param2=0},
		{name="air", prob=254, param2=0},
		{name="air", prob=254, param2=0},
		{name="air", prob=254, param2=0},
		{name="air", prob=254, param2=0},
		{name="air", prob=254, param2=0},
		{name="air", prob=254, param2=0},
		{name="air", prob=254, param2=0},
		{name="vlf_trees:leaves_oak", prob=254, param2=128},
		{name="vlf_trees:leaves_oak", prob=254, param2=96},
		{name="vlf_trees:leaves_oak", prob=254, param2=128},
		{name="air", prob=254, param2=0},
		{name="air", prob=254, param2=0},
		{name="air", prob=254, param2=0},
		{name="air", prob=254, param2=0},
		{name="air", prob=254, param2=0},
		{name="air", prob=254, param2=0},
	},
}
