schematic = {
	size = {x=20, y=14, z=17},
	yslice_prob = {
		{ypos=0, prob=254},
		{ypos=1, prob=254},
		{ypos=2, prob=254},
		{ypos=3, prob=254},
		{ypos=4, prob=254},
		{ypos=5, prob=254},
		{ypos=6, prob=254},
		{ypos=7, prob=254},
		{ypos=8, prob=254},
		{ypos=9, prob=254},
		{ypos=10, prob=254},
		{ypos=11, prob=254},
		{ypos=12, prob=254},
		{ypos=13, prob=254},
	},
	data = {
		{name="air", prob=0, param2=0},
		{name="air", prob=0, param2=0},
		{name="air", prob=0, param2=0},
		{name="air", prob=0, param2=0},
		{name="vlf_core:mossycobble", prob=254, param2=0},
		{name="vlf_core:mossycobble", prob=254, param2=0},
		{name="vlf_core:cobble", prob=254, param2=0},
		{name="vlf_core:mossycobble", prob=254, param2=0},
		{name="vlf_core:mossycobble", prob=254, param2=0},
		{name="vlf_core:cobble", prob=254, param2=0},
		{name="vlf_core:mossycobble", prob=254, param2=0},
		{name="vlf_core:mossycobble", prob=254, param2=0},
		{name="vlf_core:mossycobble", prob=254, param2=0},
		{name="vlf_core:mossycobble", prob=254, param2=0},
		{name="vlf_core:mossycobble", prob=254, param2=0},
		{name="vlf_core:cobble", prob=254, param2=0},
		{name="air", prob=0, param2=0},
		{name="air", prob=0, param2=0},
		{name="air", prob=0, param2=0},
		{name="air", prob=0, param2=0},
		{name="air", prob=0, param2=0},
		{name="air", prob=0, param2=0},
		{name="air", prob=0, param2=0},
		{name="air", prob=0, param2=0},
		{name="vlf_core:mossycobble", prob=254, param2=0},
		{name="vlf_core:mossycobble", prob=254, param2=0},
		{name="vlf_core:cobble", prob=254, param2=0},
		{name="vlf_core:mossycobble", prob=254, param2=0},
		{name="vlf_core:cobble", prob=254, param2=0},
		{name="vlf_core:mossycobble", prob=254, param2=0},
		{name="vlf_core:mossycobble", prob=254, param2=0},
		{name="vlf_core:mossycobble", prob=254, param2=0},
		{name="vlf_core:cobble", prob=254, param2=0},
		{name="vlf_core:mossycobble", prob=254, param2=0},
		{name="vlf_core:mossycobble", prob=254, param2=0},
		{name="vlf_core:cobble", prob=254, param2=0},
		{name="air", prob=0, param2=0},
		{name="air", prob=0, param2=0},
		{name="air", prob=0, param2=0},
		{name="air", prob=0, param2=0},
		{name="air", prob=0, param2=0},
		{name="air", prob=0, param2=0},
		{name="air", prob=0, param2=0},
		{name="air", prob=0, param2=0},
		{name="vlf_core:mossycobble", prob=254, param2=0},
		{name="vlf_core:mossycobble", prob=254, param2=0},
		{name="vlf_core:mossycobble", prob=254, param2=0},
		{name="vlf_core:mossycobble", prob=254, param2=0},
		{name="vlf_core:mossycobble", prob=254, param2=0},
		{name="vlf_core:mossycobble", prob=254, param2=0},
		{name="vlf_core:mossycobble", prob=254, param2=0},
		{name="vlf_core:mossycobble", prob=254, param2=0},
		{name="vlf_core:mossycobble", prob=254, param2=0},
		{name="vlf_core:cobble", prob=254, param2=0},
		{name="vlf_core:mossycobble", prob=254, param2=0},
		{name="vlf_core:mossycobble", prob=254, param2=0},
		{name="air", prob=0, param2=0},
		{name="air", prob=0, param2=0},
		{name="air", prob=0, param2=0},
		{name="air", prob=0, param2=0},
		{name="air", prob=0, param2=0},
		{name="air", prob=0, param2=0},
		{name="air", prob=0, param2=0},
		{name="air", prob=0, param2=0},
		{name="vlf_core:mossycobble", prob=254, param2=0},
		{name="vlf_core:cobble", prob=254, param2=0},
		{name="vlf_core:mossycobble", prob=254, param2=0},
		{name="vlf_core:mossycobble", prob=254, param2=0},
		{name="vlf_core:cobble", prob=254, param2=0},
		{name="vlf_core:mossycobble", prob=254, param2=0},
		{name="vlf_core:cobble", prob=254, param2=0},
		{name="vlf_core:cobble", prob=254, param2=0},
		{name="vlf_core:mossycobble", prob=254, param2=0},
		{name="vlf_core:cobble", prob=254, param2=0},
		{name="vlf_core:mossycobble", prob=254, param2=0},
		{name="vlf_core:mossycobble", prob=254, param2=0},
		{name="air", prob=0, param2=0},
		{name="air", prob=0, param2=0},
		{name="air", prob=0, param2=0},
		{name="air", prob=0, param2=0},
		{name="air", prob=0, param2=0},
		{name="air", prob=0, param2=0},
		{name="air", prob=0, param2=0},
		{name="air", prob=0, param2=0},
		{name="vlf_core:cobble", prob=254, param2=0},
		{name="vlf_core:cobble", prob=254, param2=0},
		{name="vlf_core:mossycobble", prob=254, param2=0},
		{name="vlf_core:mossycobble", prob=254, param2=0},
		{name="vlf_core:mossycobble", prob=254, param2=0},
		{name="vlf_stairs:stair_cobble", prob=254, param2=0},
		{name="vlf_stairs:stair_cobble", prob=254, param2=0},
		{name="vlf_core:cobble", prob=254, param2=0},
		{name="vlf_core:mossycobble", prob=254, param2=0},
		{name="vlf_core:mossycobble", prob=254, param2=0},
		{name="vlf_core:mossycobble", prob=254, param2=0},
		{name="vlf_core:mossycobble", prob=254, param2=0},
		{name="air", prob=0, param2=0},
		{name="air", prob=0, param2=0},
		{name="air", prob=0, param2=0},
		{name="air", prob=0, param2=0},
		{name="air", prob=0, param2=0},
		{name="air", prob=0, param2=0},
		{name="air", prob=0, param2=0},
		{name="air", prob=0, param2=0},
		{name="air", prob=0, param2=0},
		{name="air", prob=0, param2=0},
		{name="vlf_stairs:stair_cobble", prob=254, param2=1},
		{name="vlf_stairs:stair_cobble", prob=254, param2=21},
		{name="vlf_core:cobble", prob=254, param2=0},
		{name="air", prob=0, param2=0},
		{name="air", prob=0, param2=0},
		{name="vlf_core:cobble", prob=254, param2=0},
		{name="vlf_stairs:stair_cobble", prob=254, param2=23},
		{name="vlf_stairs:stair_cobble", prob=254, param2=3},
		{name="air", prob=0, param2=0},
		{name="air", prob=0, param2=0},
		{name="air", prob=0, param2=0},
		{name="air", prob=0, param2=0},
		{name="air", prob=0, param2=0},
		{name="air", prob=0, param2=0},
		{name="air", prob=0, param2=0},
		{name="air", prob=0, param2=0},
		{name="air", prob=0, param2=0},
		{name="air", prob=0, param2=0},
		{name="air", prob=0, param2=0},
		{name="air", prob=0, param2=0},
		{name="air", prob=0, param2=0},
		{name="vlf_stairs:stair_cobble", prob=254, param2=1},
		{name="vlf_core:mossycobble", prob=254, param2=0},
		{name="air", prob=0, param2=0},
		{name="air", prob=0, param2=0},
		{name="vlf_core:cobble", prob=254, param2=0},
		{name="vlf_stairs:stair_cobble", prob=254, param2=3},
		{name="air", prob=0, param2=0},
		{name="air", prob=0, param2=0},
		{name="air", prob=0, param2=0},
		{name="air", prob=0, param2=0},
		{name="air", prob=0, param2=0},
		{name="air", prob=0, param2=0},
		{name="air", prob=0, param2=0},
		{name="air", prob=0, param2=0},
		{name="air", prob=0, param2=0},
		{name="air", prob=0, param2=0},
		{name="air", prob=0, param2=0},
		{name="air", prob=0, param2=0},
		{name="air", prob=0, param2=0},
		{name="vlf_stairs:stair_mossycobble", prob=254, param2=20},
		{name="air", prob=0, param2=0},
		{name="vlf_stairs:stair_cobble", prob=254, param2=1},
		{name="vlf_core:cobble", prob=254, param2=0},
		{name="vlf_core:mossycobble", prob=254, param2=0},
		{name="vlf_stairs:stair_cobble", prob=254, param2=3},
		{name="air", prob=0, param2=0},
		{name="vlf_stairs:stair_mossycobble", prob=254, param2=20},
		{name="air", prob=0, param2=0},
		{name="air", prob=0, param2=0},
		{name="air", prob=0, param2=0},
		{name="air", prob=0, param2=0},
		{name="air", prob=0, param2=0},
		{name="air", prob=0, param2=0},
		{name="air", prob=0, param2=0},
		{name="air", prob=0, param2=0},
		{name="air", prob=0, param2=0},
		{name="air", prob=0, param2=0},
		{name="air", prob=0, param2=0},
		{name="air", prob=0, param2=0},
		{name="vlf_core:mossycobble", prob=254, param2=0},
		{name="air", prob=0, param2=0},
		{name="air", prob=0, param2=0},
		{name="air", prob=0, param2=0},
		{name="air", prob=0, param2=0},
		{name="air", prob=0, param2=0},
		{name="air", prob=0, param2=0},
		{name="vlf_core:mossycobble", prob=254, param2=0},
		{name="air", prob=0, param2=0},
		{name="air", prob=0, param2=0},
		{name="air", prob=0, param2=0},
		{name="air", prob=0, param2=0},
		{name="air", prob=0, param2=0},
		{name="air", prob=0, param2=0},
		{name="air", prob=0, param2=0},
		{name="air", prob=0, param2=0},
		{name="air", prob=0, param2=0},
		{name="air", prob=0, param2=0},
		{name="air", prob=0, param2=0},
		{name="air", prob=0, param2=0},
		{name="vlf_core:cobble", prob=254, param2=0},
		{name="air", prob=0, param2=0},
		{name="air", prob=0, param2=0},
		{name="air", prob=0, param2=0},
		{name="air", prob=0, param2=0},
		{name="air", prob=0, param2=0},
		{name="air", prob=0, param2=0},
		{name="vlf_core:mossycobble", prob=254, param2=0},
		{name="air", prob=0, param2=0},
		{name="air", prob=0, param2=0},
		{name="air", prob=0, param2=0},
		{name="air", prob=0, param2=0},
		{name="air", prob=0, param2=0},
		{name="air", prob=0, param2=0},
		{name="air", prob=0, param2=0},
		{name="air", prob=0, param2=0},
		{name="air", prob=0, param2=0},
		{name="air", prob=0, param2=0},
		{name="air", prob=0, param2=0},
		{name="air", prob=0, param2=0},
		{name="vlf_stairs:stair_mossycobble", prob=254, param2=0},
		{name="air", prob=0, param2=0},
		{name="air", prob=0, param2=0},
		{name="air", prob=0, param2=0},
		{name="air", prob=0, param2=0},
		{name="air", prob=0, param2=0},
		{name="air", prob=0, param2=0},
		{name="vlf_stairs:stair_mossycobble", prob=254, param2=0},
		{name="air", prob=0, param2=0},
		{name="air", prob=0, param2=0},
		{name="air", prob=0, param2=0},
		{name="air", prob=0, param2=0},
		{name="air", prob=0, param2=0},
		{name="air", prob=0, param2=0},
		{name="air", prob=0, param2=0},
		{name="air", prob=0, param2=0},
		{name="air", prob=0, param2=0},
		{name="air", prob=0, param2=0},
		{name="air", prob=0, param2=0},
		{name="air", prob=0, param2=0},
		{name="air", prob=0, param2=0},
		{name="air", prob=0, param2=0},
		{name="air", prob=0, param2=0},
		{name="air", prob=0, param2=0},
		{name="air", prob=0, param2=0},
		{name="air", prob=0, param2=0},
		{name="air", prob=0, param2=0},
		{name="air", prob=0, param2=0},
		{name="air", prob=0, param2=0},
		{name="air", prob=0, param2=0},
		{name="air", prob=0, param2=0},
		{name="air", prob=0, param2=0},
		{name="air", prob=0, param2=0},
		{name="air", prob=0, param2=0},
		{name="air", prob=0, param2=0},
		{name="air", prob=0, param2=0},
		{name="air", prob=0, param2=0},
		{name="air", prob=0, param2=0},
		{name="air", prob=0, param2=0},
		{name="air", prob=0, param2=0},
		{name="air", prob=0, param2=0},
		{name="air", prob=0, param2=0},
		{name="air", prob=0, param2=0},
		{name="air", prob=0, param2=0},
		{name="air", prob=0, param2=0},
		{name="air", prob=0, param2=0},
		{name="air", prob=0, param2=0},
		{name="air", prob=0, param2=0},
		{name="air", prob=0, param2=0},
		{name="air", prob=0, param2=0},
		{name="air", prob=0, param2=0},
		{name="air", prob=0, param2=0},
		{name="air", prob=0, param2=0},
		{name="air", prob=0, param2=0},
		{name="air", prob=0, param2=0},
		{name="air", prob=0, param2=0},
		{name="air", prob=0, param2=0},
		{name="air", prob=0, param2=0},
		{name="air", prob=0, param2=0},
		{name="air", prob=0, param2=0},
		{name="air", prob=0, param2=0},
		{name="air", prob=0, param2=0},
		{name="air", prob=0, param2=0},
		{name="air", prob=0, param2=0},
		{name="air", prob=0, param2=0},
		{name="air", prob=0, param2=0},
		{name="air", prob=0, param2=0},
		{name="air", prob=0, param2=0},
		{name="air", prob=0, param2=0},
		{name="air", prob=0, param2=0},
		{name="air", prob=0, param2=0},
		{name="air", prob=0, param2=0},
		{name="air", prob=0, param2=0},
		{name="air", prob=0, param2=0},
		{name="air", prob=0, param2=0},
		{name="air", prob=0, param2=0},
		{name="air", prob=0, param2=0},
		{name="air", prob=0, param2=0},
		{name="vlf_core:mossycobble", prob=254, param2=0},
		{name="vlf_core:mossycobble", prob=254, param2=0},
		{name="vlf_core:mossycobble", prob=254, param2=0},
		{name="vlf_core:mossycobble", prob=254, param2=0},
		{name="vlf_core:cobble", prob=254, param2=0},
		{name="vlf_core:mossycobble", prob=254, param2=0},
		{name="vlf_core:mossycobble", prob=254, param2=0},
		{name="vlf_core:cobble", prob=254, param2=0},
		{name="vlf_core:cobble", prob=254, param2=0},
		{name="vlf_core:mossycobble", prob=254, param2=0},
		{name="vlf_core:mossycobble", prob=254, param2=0},
		{name="vlf_core:cobble", prob=254, param2=0},
		{name="air", prob=0, param2=0},
		{name="air", prob=0, param2=0},
		{name="air", prob=0, param2=0},
		{name="air", prob=0, param2=0},
		{name="air", prob=0, param2=0},
		{name="air", prob=0, param2=0},
		{name="air", prob=0, param2=0},
		{name="air", prob=0, param2=0},
		{name="vlf_core:mossycobble", prob=254, param2=0},
		{name="vlf_core:mossycobble", prob=254, param2=0},
		{name="vlf_core:stonebrickcracked", prob=254, param2=0},
		{name="vlf_core:mossycobble", prob=254, param2=0},
		{name="air", prob=254, param2=0},
		{name="vlf_core:mossycobble", prob=254, param2=0},
		{name="air", prob=254, param2=0},
		{name="vlf_core:stonebrickcracked", prob=254, param2=0},
		{name="vlf_core:mossycobble", prob=254, param2=0},
		{name="air", prob=254, param2=0},
		{name="vlf_core:stonebrickmossy", prob=254, param2=0},
		{name="vlf_core:mossycobble", prob=254, param2=0},
		{name="air", prob=0, param2=0},
		{name="air", prob=0, param2=0},
		{name="air", prob=0, param2=0},
		{name="air", prob=0, param2=0},
		{name="air", prob=0, param2=0},
		{name="air", prob=0, param2=0},
		{name="air", prob=0, param2=0},
		{name="air", prob=0, param2=0},
		{name="vlf_core:cobble", prob=254, param2=0},
		{name="vlf_core:mossycobble", prob=254, param2=0},
		{name="vlf_core:stonebrickcracked", prob=254, param2=0},
		{name="vlf_core:cobble", prob=254, param2=0},
		{name="vlf_core:mossycobble", prob=254, param2=0},
		{name="air", prob=254, param2=0},
		{name="vlf_core:cobble", prob=254, param2=0},
		{name="vlf_core:mossycobble", prob=254, param2=0},
		{name="air", prob=254, param2=0},
		{name="vlf_core:cobble", prob=254, param2=0},
		{name="vlf_core:stonebrickcracked", prob=254, param2=0},
		{name="vlf_core:mossycobble", prob=254, param2=0},
		{name="air", prob=0, param2=0},
		{name="air", prob=0, param2=0},
		{name="air", prob=0, param2=0},
		{name="air", prob=0, param2=0},
		{name="air", prob=0, param2=0},
		{name="air", prob=0, param2=0},
		{name="air", prob=0, param2=0},
		{name="air", prob=0, param2=0},
		{name="vlf_core:mossycobble", prob=254, param2=0},
		{name="vlf_core:mossycobble", prob=254, param2=0},
		{name="vlf_core:cobble", prob=254, param2=0},
		{name="air", prob=254, param2=0},
		{name="air", prob=254, param2=0},
		{name="vlf_core:cobble", prob=254, param2=0},
		{name="air", prob=254, param2=0, force_place=true},
		{name="air", prob=254, param2=0, force_place=true},
		{name="air", prob=254, param2=0},
		{name="air", prob=254, param2=0},
		{name="air", prob=254, param2=0},
		{name="vlf_core:cobble", prob=254, param2=0},
		{name="air", prob=0, param2=0},
		{name="air", prob=0, param2=0},
		{name="air", prob=0, param2=0},
		{name="air", prob=0, param2=0},
		{name="air", prob=0, param2=0},
		{name="air", prob=0, param2=0},
		{name="air", prob=0, param2=0},
		{name="air", prob=0, param2=0},
		{name="vlf_core:mossycobble", prob=254, param2=0},
		{name="vlf_core:mossycobble", prob=254, param2=0},
		{name="vlf_core:mossycobble", prob=254, param2=0},
		{name="vlf_core:mossycobble", prob=254, param2=0},
		{name="vlf_core:mossycobble", prob=254, param2=0},
		{name="vlf_core:mossycobble", prob=254, param2=0},
		{name="vlf_core:mossycobble", prob=254, param2=0},
		{name="vlf_core:mossycobble", prob=254, param2=0},
		{name="vlf_core:mossycobble", prob=254, param2=0},
		{name="vlf_core:cobble", prob=254, param2=0},
		{name="vlf_core:mossycobble", prob=254, param2=0},
		{name="vlf_core:cobble", prob=254, param2=0},
		{name="air", prob=0, param2=0},
		{name="air", prob=0, param2=0},
		{name="air", prob=0, param2=0},
		{name="air", prob=0, param2=0},
		{name="air", prob=0, param2=0},
		{name="air", prob=0, param2=0},
		{name="air", prob=0, param2=0},
		{name="air", prob=0, param2=0},
		{name="air", prob=0, param2=0},
		{name="air", prob=0, param2=0},
		{name="air", prob=254, param2=0},
		{name="air", prob=254, param2=0},
		{name="air", prob=254, param2=0},
		{name="air", prob=0, param2=0},
		{name="air", prob=0, param2=0},
		{name="air", prob=254, param2=0},
		{name="air", prob=254, param2=0},
		{name="air", prob=254, param2=0},
		{name="air", prob=0, param2=0},
		{name="air", prob=0, param2=0},
		{name="air", prob=0, param2=0},
		{name="air", prob=0, param2=0},
		{name="air", prob=0, param2=0},
		{name="air", prob=0, param2=0},
		{name="air", prob=0, param2=0},
		{name="air", prob=0, param2=0},
		{name="air", prob=0, param2=0},
		{name="air", prob=0, param2=0},
		{name="air", prob=0, param2=0},
		{name="air", prob=0, param2=0},
		{name="air", prob=0, param2=0},
		{name="air", prob=254, param2=0},
		{name="air", prob=254, param2=0},
		{name="air", prob=0, param2=0},
		{name="air", prob=0, param2=0},
		{name="air", prob=254, param2=0},
		{name="air", prob=254, param2=0},
		{name="air", prob=0, param2=0},
		{name="air", prob=0, param2=0},
		{name="air", prob=0, param2=0},
		{name="air", prob=0, param2=0},
		{name="air", prob=0, param2=0},
		{name="air", prob=0, param2=0},
		{name="air", prob=0, param2=0},
		{name="air", prob=0, param2=0},
		{name="air", prob=0, param2=0},
		{name="air", prob=0, param2=0},
		{name="air", prob=0, param2=0},
		{name="air", prob=0, param2=0},
		{name="vlf_core:stonebrick", prob=254, param2=0},
		{name="vlf_core:mossycobble", prob=254, param2=0},
		{name="vlf_core:cobble", prob=254, param2=0},
		{name="vlf_core:stonebrickcracked", prob=254, param2=0},
		{name="vlf_core:cobble", prob=254, param2=0},
		{name="vlf_core:mossycobble", prob=254, param2=0},
		{name="vlf_core:stonebrickcracked", prob=254, param2=0},
		{name="vlf_core:mossycobble", prob=254, param2=0},
		{name="vlf_core:mossycobble", prob=254, param2=0},
		{name="vlf_core:stonebrickcracked", prob=254, param2=0},
		{name="air", prob=0, param2=0},
		{name="air", prob=0, param2=0},
		{name="air", prob=0, param2=0},
		{name="air", prob=0, param2=0},
		{name="air", prob=0, param2=0},
		{name="air", prob=0, param2=0},
		{name="air", prob=0, param2=0},
		{name="air", prob=0, param2=0},
		{name="air", prob=0, param2=0},
		{name="air", prob=0, param2=0},
		{name="vlf_core:stonebrickcracked", prob=254, param2=0},
		{name="vlf_core:mossycobble", prob=254, param2=0},
		{name="vlf_core:mossycobble", prob=254, param2=0},
		{name="vlf_core:stonebrick", prob=254, param2=0},
		{name="vlf_stairs:stair_cobble", prob=254, param2=0},
		{name="vlf_stairs:stair_cobble", prob=254, param2=0},
		{name="vlf_core:stonebrickmossy", prob=254, param2=0},
		{name="vlf_core:mossycobble", prob=254, param2=0},
		{name="vlf_core:mossycobble", prob=254, param2=0},
		{name="vlf_core:stonebrick", prob=254, param2=0},
		{name="air", prob=0, param2=0},
		{name="air", prob=0, param2=0},
		{name="air", prob=0, param2=0},
		{name="air", prob=0, param2=0},
		{name="air", prob=0, param2=0},
		{name="air", prob=0, param2=0},
		{name="air", prob=0, param2=0},
		{name="air", prob=0, param2=0},
		{name="air", prob=0, param2=0},
		{name="air", prob=0, param2=0},
		{name="vlf_core:stonebrick", prob=254, param2=0},
		{name="vlf_core:mossycobble", prob=254, param2=0},
		{name="vlf_core:cobble", prob=254, param2=0},
		{name="vlf_core:stonebrick", prob=254, param2=0},
		{name="air", prob=254, param2=0},
		{name="air", prob=254, param2=0},
		{name="vlf_core:stonebrick", prob=254, param2=0},
		{name="vlf_core:mossycobble", prob=254, param2=0},
		{name="vlf_core:cobble", prob=254, param2=0},
		{name="vlf_core:stonebrickmossy", prob=254, param2=0},
		{name="air", prob=0, param2=0},
		{name="air", prob=0, param2=0},
		{name="air", prob=0, param2=0},
		{name="air", prob=0, param2=0},
		{name="air", prob=0, param2=0},
		{name="air", prob=0, param2=0},
		{name="air", prob=0, param2=0},
		{name="air", prob=0, param2=0},
		{name="air", prob=0, param2=0},
		{name="air", prob=0, param2=0},
		{name="vlf_core:stonebrickmossy", prob=254, param2=0},
		{name="vlf_core:stonebrickmossy", prob=254, param2=0},
		{name="vlf_core:stonebrickmossy", prob=254, param2=0},
		{name="vlf_core:stonebrickcarved", prob=254, param2=0},
		{name="air", prob=254, param2=0},
		{name="air", prob=254, param2=0},
		{name="vlf_core:stonebrickcarved", prob=254, param2=0},
		{name="vlf_core:stonebrick", prob=254, param2=0},
		{name="vlf_core:stonebrickcracked", prob=254, param2=0},
		{name="vlf_core:stonebrickmossy", prob=254, param2=0},
		{name="air", prob=0, param2=0},
		{name="air", prob=0, param2=0},
		{name="air", prob=0, param2=0},
		{name="air", prob=0, param2=0},
		{name="air", prob=0, param2=0},
		{name="air", prob=0, param2=0},
		{name="air", prob=0, param2=0},
		{name="air", prob=0, param2=0},
		{name="air", prob=0, param2=0},
		{name="air", prob=0, param2=0},
		{name="air", prob=0, param2=0},
		{name="air", prob=0, param2=0},
		{name="air", prob=0, param2=0},
		{name="air", prob=0, param2=0},
		{name="air", prob=0, param2=0},
		{name="air", prob=0, param2=0},
		{name="air", prob=0, param2=0},
		{name="air", prob=0, param2=0},
		{name="air", prob=0, param2=0},
		{name="air", prob=0, param2=0},
		{name="air", prob=0, param2=0},
		{name="air", prob=0, param2=0},
		{name="air", prob=0, param2=0},
		{name="air", prob=0, param2=0},
		{name="air", prob=0, param2=0},
		{name="air", prob=0, param2=0},
		{name="air", prob=0, param2=0},
		{name="air", prob=0, param2=0},
		{name="air", prob=0, param2=0},
		{name="air", prob=0, param2=0},
		{name="air", prob=0, param2=0},
		{name="air", prob=0, param2=0},
		{name="air", prob=0, param2=0},
		{name="air", prob=0, param2=0},
		{name="air", prob=0, param2=0},
		{name="air", prob=0, param2=0},
		{name="air", prob=0, param2=0},
		{name="air", prob=0, param2=0},
		{name="air", prob=0, param2=0},
		{name="air", prob=0, param2=0},
		{name="air", prob=0, param2=0},
		{name="air", prob=0, param2=0},
		{name="air", prob=0, param2=0},
		{name="air", prob=0, param2=0},
		{name="air", prob=0, param2=0},
		{name="air", prob=0, param2=0},
		{name="air", prob=0, param2=0},
		{name="air", prob=0, param2=0},
		{name="air", prob=0, param2=0},
		{name="air", prob=0, param2=0},
		{name="air", prob=0, param2=0},
		{name="air", prob=0, param2=0},
		{name="air", prob=0, param2=0},
		{name="air", prob=0, param2=0},
		{name="air", prob=0, param2=0},
		{name="air", prob=0, param2=0},
		{name="air", prob=0, param2=0},
		{name="air", prob=0, param2=0},
		{name="air", prob=0, param2=0},
		{name="air", prob=0, param2=0},
		{name="air", prob=0, param2=0},
		{name="air", prob=0, param2=0},
		{name="air", prob=0, param2=0},
		{name="air", prob=0, param2=0},
		{name="air", prob=0, param2=0},
		{name="air", prob=0, param2=0},
		{name="air", prob=0, param2=0},
		{name="air", prob=0, param2=0},
		{name="air", prob=0, param2=0},
		{name="vlf_core:mossycobble", prob=254, param2=0},
		{name="vlf_core:cobble", prob=254, param2=0},
		{name="vlf_core:mossycobble", prob=254, param2=0},
		{name="vlf_core:mossycobble", prob=254, param2=0},
		{name="vlf_core:mossycobble", prob=254, param2=0},
		{name="vlf_core:cobble", prob=254, param2=0},
		{name="vlf_core:mossycobble", prob=254, param2=0},
		{name="vlf_core:cobble", prob=254, param2=0},
		{name="vlf_core:cobble", prob=254, param2=0},
		{name="vlf_core:mossycobble", prob=254, param2=0},
		{name="vlf_core:mossycobble", prob=254, param2=0},
		{name="vlf_core:mossycobble", prob=254, param2=0},
		{name="air", prob=0, param2=0},
		{name="air", prob=0, param2=0},
		{name="air", prob=0, param2=0},
		{name="air", prob=0, param2=0},
		{name="air", prob=0, param2=0},
		{name="air", prob=0, param2=0},
		{name="air", prob=0, param2=0},
		{name="air", prob=0, param2=0},
		{name="vlf_core:cobble", prob=254, param2=0},
		{name="vlf_core:mossycobble", prob=254, param2=0},
		{name="vlf_core:mossycobble", prob=254, param2=0},
		{name="air", prob=254, param2=0},
		{name="air", prob=254, param2=0, force_place=true},
		{name="air", prob=254, param2=0},
		{name="air", prob=254, param2=0, force_place=true},
		{name="air", prob=254, param2=0},
		{name="air", prob=254, param2=0},
		{name="air", prob=254, param2=0},
		{name="air", prob=254, param2=0},
		{name="vlf_core:cobble", prob=254, param2=0},
		{name="air", prob=0, param2=0},
		{name="air", prob=0, param2=0},
		{name="air", prob=0, param2=0},
		{name="air", prob=0, param2=0},
		{name="air", prob=0, param2=0},
		{name="air", prob=0, param2=0},
		{name="air", prob=0, param2=0},
		{name="air", prob=0, param2=0},
		{name="vlf_core:mossycobble", prob=254, param2=0},
		{name="vlf_core:cobble", prob=254, param2=0},
		{name="air", prob=254, param2=0},
		{name="air", prob=254, param2=0},
		{name="air", prob=254, param2=0},
		{name="air", prob=254, param2=0, force_place=true},
		{name="air", prob=254, param2=0},
		{name="air", prob=254, param2=0},
		{name="air", prob=254, param2=0},
		{name="air", prob=254, param2=0},
		{name="air", prob=254, param2=0},
		{name="vlf_core:cobble", prob=254, param2=0},
		{name="air", prob=0, param2=0},
		{name="air", prob=0, param2=0},
		{name="air", prob=0, param2=0},
		{name="air", prob=0, param2=0},
		{name="air", prob=0, param2=0},
		{name="air", prob=0, param2=0},
		{name="air", prob=0, param2=0},
		{name="air", prob=0, param2=0},
		{name="vlf_core:mossycobble", prob=254, param2=0},
		{name="vlf_core:mossycobble", prob=254, param2=0},
		{name="vlf_core:cobble", prob=254, param2=0},
		{name="air", prob=254, param2=0, force_place=true},
		{name="air", prob=254, param2=0, force_place=true},
		{name="air", prob=254, param2=0, force_place=true},
		{name="air", prob=254, param2=0, force_place=true},
		{name="air", prob=254, param2=0, force_place=true},
		{name="vlf_core:cobble", prob=254, param2=0},
		{name="vlf_core:mossycobble", prob=254, param2=0},
		{name="vlf_core:cobble", prob=254, param2=0},
		{name="vlf_core:mossycobble", prob=254, param2=0},
		{name="air", prob=0, param2=0},
		{name="air", prob=0, param2=0},
		{name="air", prob=0, param2=0},
		{name="air", prob=0, param2=0},
		{name="air", prob=0, param2=0},
		{name="air", prob=0, param2=0},
		{name="air", prob=0, param2=0},
		{name="air", prob=0, param2=0},
		{name="vlf_core:cobble", prob=254, param2=0},
		{name="vlf_core:cobble", prob=254, param2=0},
		{name="vlf_core:cobble", prob=254, param2=0},
		{name="vlf_core:cobble", prob=254, param2=0},
		{name="vlf_core:mossycobble", prob=254, param2=0},
		{name="vlf_core:mossycobble", prob=254, param2=0},
		{name="vlf_core:cobble", prob=254, param2=0},
		{name="vlf_core:cobble", prob=254, param2=0},
		{name="vlf_core:cobble", prob=254, param2=0},
		{name="vlf_core:cobble", prob=254, param2=0},
		{name="vlf_core:mossycobble", prob=254, param2=0},
		{name="vlf_core:mossycobble", prob=254, param2=0},
		{name="air", prob=0, param2=0},
		{name="air", prob=0, param2=0},
		{name="air", prob=0, param2=0},
		{name="air", prob=0, param2=0},
		{name="air", prob=0, param2=0},
		{name="air", prob=0, param2=0},
		{name="air", prob=0, param2=0},
		{name="air", prob=0, param2=0},
		{name="air", prob=0, param2=0},
		{name="air", prob=0, param2=0},
		{name="vlf_core:mossycobble", prob=254, param2=0},
		{name="vlf_core:mossycobble", prob=254, param2=0},
		{name="vlf_core:mossycobble", prob=254, param2=0},
		{name="air", prob=254, param2=0},
		{name="air", prob=254, param2=0},
		{name="vlf_core:cobble", prob=254, param2=0},
		{name="vlf_core:mossycobble", prob=254, param2=0},
		{name="vlf_core:mossycobble", prob=254, param2=0},
		{name="air", prob=0, param2=0},
		{name="air", prob=0, param2=0},
		{name="air", prob=0, param2=0},
		{name="air", prob=0, param2=0},
		{name="air", prob=0, param2=0},
		{name="air", prob=0, param2=0},
		{name="air", prob=0, param2=0},
		{name="air", prob=0, param2=0},
		{name="air", prob=0, param2=0},
		{name="air", prob=0, param2=0},
		{name="air", prob=0, param2=0},
		{name="air", prob=0, param2=0},
		{name="vlf_core:mossycobble", prob=254, param2=0},
		{name="vlf_core:mossycobble", prob=254, param2=0},
		{name="vlf_core:mossycobble", prob=254, param2=0},
		{name="air", prob=254, param2=0},
		{name="air", prob=254, param2=0},
		{name="vlf_core:cobble", prob=254, param2=0},
		{name="vlf_core:cobble", prob=254, param2=0},
		{name="vlf_core:cobble", prob=254, param2=0},
		{name="air", prob=0, param2=0},
		{name="air", prob=0, param2=0},
		{name="air", prob=0, param2=0},
		{name="air", prob=0, param2=0},
		{name="air", prob=0, param2=0},
		{name="air", prob=0, param2=0},
		{name="air", prob=0, param2=0},
		{name="air", prob=0, param2=0},
		{name="air", prob=0, param2=0},
		{name="air", prob=0, param2=0},
		{name="vlf_stairs:stair_cobble", prob=254, param2=23},
		{name="vlf_core:mossycobble", prob=254, param2=0},
		{name="vlf_core:mossycobble", prob=254, param2=0},
		{name="vlf_core:cobble", prob=254, param2=0},
		{name="vlf_core:mossycobble", prob=254, param2=0},
		{name="vlf_core:mossycobble", prob=254, param2=0},
		{name="vlf_core:mossycobble", prob=254, param2=0},
		{name="vlf_core:mossycobble", prob=254, param2=0},
		{name="vlf_core:cobble", prob=254, param2=0},
		{name="vlf_core:cobble", prob=254, param2=0},
		{name="vlf_core:mossycobble", prob=254, param2=0},
		{name="vlf_stairs:stair_mossycobble", prob=254, param2=21},
		{name="air", prob=0, param2=0},
		{name="air", prob=0, param2=0},
		{name="air", prob=0, param2=0},
		{name="air", prob=0, param2=0},
		{name="air", prob=0, param2=0},
		{name="air", prob=0, param2=0},
		{name="air", prob=0, param2=0},
		{name="air", prob=0, param2=0},
		{name="vlf_core:mossycobble", prob=254, param2=0},
		{name="vlf_core:cobble", prob=254, param2=0},
		{name="air", prob=254, param2=0, force_place=true},
		{name="air", prob=254, param2=0, force_place=true},
		{name="air", prob=254, param2=0, force_place=true},
		{name="air", prob=254, param2=0, force_place=true},
		{name="air", prob=254, param2=0, force_place=true},
		{name="air", prob=254, param2=0, force_place=true},
		{name="air", prob=254, param2=0, force_place=true},
		{name="air", prob=254, param2=0, force_place=true},
		{name="vlf_core:cobble", prob=254, param2=0},
		{name="vlf_core:cobble", prob=254, param2=0},
		{name="air", prob=0, param2=0},
		{name="air", prob=0, param2=0},
		{name="air", prob=0, param2=0},
		{name="air", prob=0, param2=0},
		{name="air", prob=0, param2=0},
		{name="air", prob=0, param2=0},
		{name="air", prob=0, param2=0},
		{name="air", prob=0, param2=0},
		{name="vlf_core:cobble", prob=254, param2=0},
		{name="vlf_core:cobble", prob=254, param2=0},
		{name="air", prob=254, param2=0, force_place=true},
		{name="air", prob=254, param2=0, force_place=true},
		{name="air", prob=254, param2=0, force_place=true},
		{name="vlf_stairs:stair_cobble", prob=254, param2=0},
		{name="vlf_stairs:stair_cobble", prob=254, param2=0},
		{name="air", prob=254, param2=0, force_place=true},
		{name="air", prob=254, param2=0, force_place=true},
		{name="air", prob=254, param2=0, force_place=true},
		{name="vlf_core:cobble", prob=254, param2=0},
		{name="vlf_core:cobble", prob=254, param2=0},
		{name="air", prob=0, param2=0},
		{name="air", prob=0, param2=0},
		{name="air", prob=0, param2=0},
		{name="air", prob=0, param2=0},
		{name="air", prob=0, param2=0},
		{name="air", prob=0, param2=0},
		{name="air", prob=0, param2=0},
		{name="air", prob=0, param2=0},
		{name="vlf_stairs:stair_cobble", prob=254, param2=1},
		{name="vlf_core:stonebrickmossy", prob=254, param2=0},
		{name="vlf_core:cobble", prob=254, param2=0},
		{name="vlf_core:mossycobble", prob=254, param2=0},
		{name="vlf_core:mossycobble", prob=254, param2=0},
		{name="air", prob=254, param2=0},
		{name="air", prob=254, param2=0},
		{name="vlf_core:mossycobble", prob=254, param2=0},
		{name="vlf_core:mossycobble", prob=254, param2=0},
		{name="vlf_core:cobble", prob=254, param2=0},
		{name="vlf_core:stonebrick", prob=254, param2=0},
		{name="vlf_stairs:stair_mossycobble", prob=254, param2=3},
		{name="air", prob=0, param2=0},
		{name="air", prob=0, param2=0},
		{name="air", prob=0, param2=0},
		{name="air", prob=0, param2=0},
		{name="air", prob=0, param2=0},
		{name="air", prob=0, param2=0},
		{name="air", prob=0, param2=0},
		{name="air", prob=0, param2=0},
		{name="air", prob=0, param2=0},
		{name="air", prob=0, param2=0},
		{name="air", prob=0, param2=0},
		{name="air", prob=0, param2=0},
		{name="air", prob=0, param2=0},
		{name="air", prob=0, param2=0},
		{name="air", prob=0, param2=0},
		{name="air", prob=0, param2=0},
		{name="air", prob=0, param2=0},
		{name="air", prob=0, param2=0},
		{name="air", prob=0, param2=0},
		{name="air", prob=0, param2=0},
		{name="air", prob=0, param2=0},
		{name="air", prob=0, param2=0},
		{name="air", prob=0, param2=0},
		{name="air", prob=0, param2=0},
		{name="air", prob=0, param2=0},
		{name="air", prob=0, param2=0},
		{name="air", prob=0, param2=0},
		{name="air", prob=0, param2=0},
		{name="air", prob=0, param2=0},
		{name="air", prob=0, param2=0},
		{name="air", prob=0, param2=0},
		{name="air", prob=0, param2=0},
		{name="air", prob=0, param2=0},
		{name="air", prob=0, param2=0},
		{name="air", prob=0, param2=0},
		{name="air", prob=0, param2=0},
		{name="air", prob=0, param2=0},
		{name="air", prob=0, param2=0},
		{name="air", prob=0, param2=0},
		{name="air", prob=0, param2=0},
		{name="air", prob=0, param2=0},
		{name="air", prob=0, param2=0},
		{name="air", prob=0, param2=0},
		{name="air", prob=0, param2=0},
		{name="air", prob=0, param2=0},
		{name="air", prob=0, param2=0},
		{name="air", prob=0, param2=0},
		{name="air", prob=0, param2=0},
		{name="air", prob=0, param2=0},
		{name="air", prob=0, param2=0},
		{name="air", prob=0, param2=0},
		{name="air", prob=0, param2=0},
		{name="air", prob=0, param2=0},
		{name="air", prob=0, param2=0},
		{name="air", prob=0, param2=0},
		{name="air", prob=0, param2=0},
		{name="air", prob=0, param2=0},
		{name="air", prob=0, param2=0},
		{name="air", prob=0, param2=0},
		{name="air", prob=0, param2=0},
		{name="air", prob=0, param2=0},
		{name="air", prob=0, param2=0},
		{name="air", prob=0, param2=0},
		{name="air", prob=0, param2=0},
		{name="air", prob=0, param2=0},
		{name="air", prob=0, param2=0},
		{name="air", prob=0, param2=0},
		{name="air", prob=0, param2=0},
		{name="vlf_core:cobble", prob=254, param2=0},
		{name="vlf_core:cobble", prob=254, param2=0},
		{name="vlf_core:mossycobble", prob=254, param2=0},
		{name="vlf_core:mossycobble", prob=254, param2=0},
		{name="vlf_core:mossycobble", prob=254, param2=0},
		{name="vlf_core:mossycobble", prob=254, param2=0},
		{name="vlf_core:mossycobble", prob=254, param2=0},
		{name="vlf_core:cobble", prob=254, param2=0},
		{name="vlf_core:cobble", prob=254, param2=0},
		{name="vlf_core:mossycobble", prob=254, param2=0},
		{name="vlf_core:cobble", prob=254, param2=0},
		{name="vlf_core:mossycobble", prob=254, param2=0},
		{name="air", prob=0, param2=0},
		{name="air", prob=0, param2=0},
		{name="air", prob=0, param2=0},
		{name="air", prob=0, param2=0},
		{name="air", prob=0, param2=0},
		{name="air", prob=0, param2=0},
		{name="air", prob=0, param2=0},
		{name="air", prob=0, param2=0},
		{name="vlf_core:mossycobble", prob=254, param2=0},
		{name="vlf_core:cobble", prob=254, param2=0},
		{name="air", prob=254, param2=0},
		{name="air", prob=254, param2=0},
		{name="air", prob=254, param2=0, force_place=true},
		{name="air", prob=254, param2=0},
		{name="air", prob=254, param2=0, force_place=true},
		{name="air", prob=254, param2=0},
		{name="air", prob=254, param2=0},
		{name="air", prob=254, param2=0},
		{name="vlf_core:stonebrickmossy", prob=254, param2=0},
		{name="vlf_core:mossycobble", prob=254, param2=0},
		{name="air", prob=0, param2=0},
		{name="air", prob=0, param2=0},
		{name="air", prob=0, param2=0},
		{name="air", prob=0, param2=0},
		{name="air", prob=0, param2=0},
		{name="air", prob=0, param2=0},
		{name="air", prob=0, param2=0},
		{name="air", prob=0, param2=0},
		{name="vlf_core:mossycobble", prob=254, param2=0},
		{name="vlf_core:cobble", prob=254, param2=0},
		{name="air", prob=254, param2=0},
		{name="air", prob=254, param2=0},
		{name="air", prob=254, param2=0},
		{name="air", prob=254, param2=0, force_place=true},
		{name="air", prob=254, param2=0},
		{name="air", prob=254, param2=0},
		{name="air", prob=254, param2=0},
		{name="air", prob=254, param2=0},
		{name="vlf_core:stonebrickmossy", prob=254, param2=0},
		{name="vlf_core:cobble", prob=254, param2=0},
		{name="air", prob=0, param2=0},
		{name="air", prob=0, param2=0},
		{name="air", prob=0, param2=0},
		{name="air", prob=0, param2=0},
		{name="air", prob=0, param2=0},
		{name="air", prob=0, param2=0},
		{name="air", prob=0, param2=0},
		{name="air", prob=0, param2=0},
		{name="vlf_core:cobble", prob=254, param2=0},
		{name="vlf_core:cobble", prob=254, param2=0},
		{name="vlf_core:mossycobble", prob=254, param2=0},
		{name="air", prob=254, param2=0, force_place=true},
		{name="air", prob=254, param2=0, force_place=true},
		{name="air", prob=254, param2=0, force_place=true},
		{name="air", prob=254, param2=0, force_place=true},
		{name="air", prob=254, param2=0, force_place=true},
		{name="air", prob=254, param2=0},
		{name="air", prob=254, param2=0},
		{name="air", prob=254, param2=0},
		{name="vlf_core:mossycobble", prob=254, param2=0},
		{name="air", prob=0, param2=0},
		{name="air", prob=0, param2=0},
		{name="air", prob=0, param2=0},
		{name="air", prob=0, param2=0},
		{name="air", prob=0, param2=0},
		{name="air", prob=0, param2=0},
		{name="air", prob=0, param2=0},
		{name="air", prob=0, param2=0},
		{name="vlf_core:cobble", prob=254, param2=0},
		{name="vlf_core:cobble", prob=254, param2=0},
		{name="vlf_core:mossycobble", prob=254, param2=0},
		{name="vlf_core:cobble", prob=254, param2=0},
		{name="vlf_core:mossycobble", prob=254, param2=0},
		{name="vlf_core:mossycobble", prob=254, param2=0},
		{name="vlf_core:mossycobble", prob=254, param2=0},
		{name="vlf_core:mossycobble", prob=254, param2=0},
		{name="vlf_core:mossycobble", prob=254, param2=0},
		{name="vlf_core:mossycobble", prob=254, param2=0},
		{name="vlf_core:mossycobble", prob=254, param2=0},
		{name="vlf_core:mossycobble", prob=254, param2=0},
		{name="air", prob=0, param2=0},
		{name="air", prob=0, param2=0},
		{name="air", prob=0, param2=0},
		{name="air", prob=0, param2=0},
		{name="air", prob=0, param2=0},
		{name="air", prob=0, param2=0},
		{name="air", prob=0, param2=0},
		{name="air", prob=0, param2=0},
		{name="air", prob=0, param2=0},
		{name="air", prob=0, param2=0},
		{name="vlf_core:mossycobble", prob=254, param2=0},
		{name="air", prob=254, param2=0, force_place=true},
		{name="air", prob=254, param2=0, force_place=true},
		{name="air", prob=254, param2=0, force_place=true},
		{name="air", prob=254, param2=0, force_place=true},
		{name="air", prob=254, param2=0, force_place=true},
		{name="air", prob=254, param2=0, force_place=true},
		{name="vlf_core:cobble", prob=254, param2=0},
		{name="air", prob=0, param2=0},
		{name="air", prob=0, param2=0},
		{name="air", prob=0, param2=0},
		{name="air", prob=0, param2=0},
		{name="air", prob=0, param2=0},
		{name="air", prob=0, param2=0},
		{name="air", prob=0, param2=0},
		{name="air", prob=0, param2=0},
		{name="air", prob=0, param2=0},
		{name="air", prob=0, param2=0},
		{name="air", prob=0, param2=0},
		{name="air", prob=0, param2=0},
		{name="vlf_core:cobble", prob=254, param2=0},
		{name="air", prob=254, param2=0, force_place=true},
		{name="air", prob=254, param2=0, force_place=true},
		{name="air", prob=254, param2=0, force_place=true},
		{name="air", prob=254, param2=0, force_place=true},
		{name="air", prob=254, param2=0, force_place=true},
		{name="air", prob=254, param2=0, force_place=true},
		{name="vlf_core:cobble", prob=254, param2=0},
		{name="air", prob=0, param2=0},
		{name="air", prob=0, param2=0},
		{name="air", prob=0, param2=0},
		{name="air", prob=0, param2=0},
		{name="air", prob=0, param2=0},
		{name="air", prob=0, param2=0},
		{name="air", prob=0, param2=0},
		{name="air", prob=0, param2=0},
		{name="air", prob=0, param2=0},
		{name="air", prob=0, param2=0},
		{name="air", prob=254, param2=0},
		{name="vlf_core:stonebrickmossy", prob=254, param2=0},
		{name="vlf_core:cobble", prob=254, param2=0},
		{name="vlf_core:mossycobble", prob=254, param2=0},
		{name="vlf_core:cobble", prob=254, param2=0},
		{name="vlf_core:cobble", prob=254, param2=0},
		{name="vlf_core:mossycobble", prob=254, param2=0},
		{name="vlf_core:mossycobble", prob=254, param2=0},
		{name="vlf_core:cobble", prob=254, param2=0},
		{name="vlf_core:cobble", prob=254, param2=0},
		{name="vlf_core:stonebrickmossy", prob=254, param2=0},
		{name="air", prob=254, param2=0},
		{name="air", prob=0, param2=0},
		{name="air", prob=0, param2=0},
		{name="air", prob=0, param2=0},
		{name="air", prob=0, param2=0},
		{name="air", prob=0, param2=0},
		{name="air", prob=0, param2=0},
		{name="air", prob=0, param2=0},
		{name="air", prob=0, param2=0},
		{name="air", prob=254, param2=0},
		{name="vlf_core:mossycobble", prob=254, param2=0},
		{name="air", prob=254, param2=0, force_place=true},
		{name="air", prob=254, param2=0, force_place=true},
		{name="air", prob=254, param2=0, force_place=true},
		{name="air", prob=254, param2=0, force_place=true},
		{name="air", prob=254, param2=0, force_place=true},
		{name="air", prob=254, param2=0, force_place=true},
		{name="air", prob=254, param2=0, force_place=true},
		{name="air", prob=254, param2=0, force_place=true},
		{name="vlf_core:mossycobble", prob=254, param2=0},
		{name="air", prob=254, param2=0},
		{name="air", prob=0, param2=0},
		{name="air", prob=0, param2=0},
		{name="air", prob=0, param2=0},
		{name="air", prob=0, param2=0},
		{name="air", prob=0, param2=0},
		{name="air", prob=0, param2=0},
		{name="air", prob=0, param2=0},
		{name="air", prob=0, param2=0},
		{name="air", prob=254, param2=0},
		{name="vlf_core:mossycobble", prob=254, param2=0},
		{name="air", prob=254, param2=0, force_place=true},
		{name="air", prob=254, param2=0, force_place=true},
		{name="air", prob=254, param2=0, force_place=true},
		{name="air", prob=254, param2=0, force_place=true},
		{name="air", prob=254, param2=0, force_place=true},
		{name="air", prob=254, param2=0, force_place=true},
		{name="air", prob=254, param2=0, force_place=true},
		{name="air", prob=254, param2=0, force_place=true},
		{name="vlf_core:mossycobble", prob=254, param2=0},
		{name="air", prob=254, param2=0},
		{name="air", prob=0, param2=0},
		{name="air", prob=0, param2=0},
		{name="air", prob=0, param2=0},
		{name="air", prob=0, param2=0},
		{name="air", prob=0, param2=0},
		{name="air", prob=0, param2=0},
		{name="air", prob=0, param2=0},
		{name="air", prob=0, param2=0},
		{name="air", prob=254, param2=0},
		{name="vlf_core:stonebrick", prob=254, param2=0},
		{name="vlf_core:cobble", prob=254, param2=0},
		{name="vlf_core:mossycobble", prob=254, param2=0},
		{name="vlf_core:cobble", prob=254, param2=0},
		{name="vlf_stairs:stair_cobble", prob=254, param2=0},
		{name="vlf_stairs:stair_cobble", prob=254, param2=0},
		{name="vlf_core:mossycobble", prob=254, param2=0},
		{name="vlf_core:mossycobble", prob=254, param2=0},
		{name="vlf_core:mossycobble", prob=254, param2=0},
		{name="vlf_core:stonebrickcracked", prob=254, param2=0},
		{name="air", prob=254, param2=0},
		{name="air", prob=0, param2=0},
		{name="air", prob=0, param2=0},
		{name="air", prob=0, param2=0},
		{name="air", prob=0, param2=0},
		{name="air", prob=0, param2=0},
		{name="air", prob=0, param2=0},
		{name="air", prob=0, param2=0},
		{name="air", prob=0, param2=0},
		{name="air", prob=0, param2=0},
		{name="air", prob=0, param2=0},
		{name="air", prob=0, param2=0},
		{name="vlf_core:mossycobble", prob=254, param2=0},
		{name="vlf_core:cobble", prob=254, param2=0},
		{name="air", prob=254, param2=0},
		{name="air", prob=254, param2=0},
		{name="vlf_core:mossycobble", prob=254, param2=0},
		{name="vlf_core:mossycobble", prob=254, param2=0},
		{name="air", prob=0, param2=0},
		{name="air", prob=0, param2=0},
		{name="air", prob=0, param2=0},
		{name="air", prob=0, param2=0},
		{name="air", prob=0, param2=0},
		{name="air", prob=0, param2=0},
		{name="air", prob=0, param2=0},
		{name="air", prob=0, param2=0},
		{name="air", prob=0, param2=0},
		{name="air", prob=0, param2=0},
		{name="air", prob=0, param2=0},
		{name="air", prob=0, param2=0},
		{name="air", prob=0, param2=0},
		{name="air", prob=0, param2=0},
		{name="air", prob=0, param2=0},
		{name="air", prob=0, param2=0},
		{name="air", prob=0, param2=0},
		{name="air", prob=0, param2=0},
		{name="air", prob=0, param2=0},
		{name="air", prob=0, param2=0},
		{name="air", prob=0, param2=0},
		{name="air", prob=0, param2=0},
		{name="air", prob=0, param2=0},
		{name="air", prob=0, param2=0},
		{name="air", prob=0, param2=0},
		{name="air", prob=0, param2=0},
		{name="air", prob=0, param2=0},
		{name="air", prob=0, param2=0},
		{name="air", prob=0, param2=0},
		{name="air", prob=0, param2=0},
		{name="air", prob=0, param2=0},
		{name="air", prob=0, param2=0},
		{name="air", prob=0, param2=0},
		{name="air", prob=0, param2=0},
		{name="air", prob=0, param2=0},
		{name="air", prob=0, param2=0},
		{name="air", prob=0, param2=0},
		{name="air", prob=0, param2=0},
		{name="air", prob=0, param2=0},
		{name="air", prob=0, param2=0},
		{name="air", prob=0, param2=0},
		{name="air", prob=0, param2=0},
		{name="air", prob=0, param2=0},
		{name="air", prob=0, param2=0},
		{name="air", prob=0, param2=0},
		{name="air", prob=0, param2=0},
		{name="air", prob=0, param2=0},
		{name="air", prob=0, param2=0},
		{name="air", prob=0, param2=0},
		{name="air", prob=0, param2=0},
		{name="air", prob=0, param2=0},
		{name="vlf_core:mossycobble", prob=254, param2=0},
		{name="vlf_core:cobble", prob=254, param2=0},
		{name="vlf_core:mossycobble", prob=254, param2=0},
		{name="vlf_core:mossycobble", prob=254, param2=0},
		{name="vlf_core:mossycobble", prob=254, param2=0},
		{name="vlf_core:cobble", prob=254, param2=0},
		{name="vlf_core:mossycobble", prob=254, param2=0},
		{name="vlf_core:cobble", prob=254, param2=0},
		{name="vlf_core:mossycobble", prob=254, param2=0},
		{name="vlf_core:cobble", prob=254, param2=0},
		{name="vlf_core:cobble", prob=254, param2=0},
		{name="vlf_core:cobble", prob=254, param2=0},
		{name="air", prob=0, param2=0},
		{name="air", prob=0, param2=0},
		{name="air", prob=0, param2=0},
		{name="air", prob=0, param2=0},
		{name="air", prob=0, param2=0},
		{name="air", prob=0, param2=0},
		{name="air", prob=0, param2=0},
		{name="air", prob=0, param2=0},
		{name="vlf_core:mossycobble", prob=254, param2=0},
		{name="vlf_core:mossycobble", prob=254, param2=0},
		{name="air", prob=254, param2=0},
		{name="air", prob=254, param2=0},
		{name="vlf_core:mossycobble", prob=254, param2=0},
		{name="vlf_core:mossycobble", prob=254, param2=0},
		{name="vlf_core:mossycobble", prob=254, param2=0},
		{name="vlf_core:mossycobble", prob=254, param2=0},
		{name="air", prob=254, param2=0, force_place=true},
		{name="air", prob=254, param2=0, force_place=true},
		{name="air", prob=254, param2=0},
		{name="vlf_core:cobble", prob=254, param2=0},
		{name="air", prob=0, param2=0},
		{name="air", prob=0, param2=0},
		{name="air", prob=0, param2=0},
		{name="air", prob=0, param2=0},
		{name="air", prob=0, param2=0},
		{name="air", prob=0, param2=0},
		{name="air", prob=0, param2=0},
		{name="air", prob=0, param2=0},
		{name="vlf_core:cobble", prob=254, param2=0},
		{name="vlf_core:cobble", prob=254, param2=0},
		{name="air", prob=254, param2=0},
		{name="air", prob=254, param2=0},
		{name="vlf_core:mossycobble", prob=254, param2=0},
		{name="vlf_core:mossycobble", prob=254, param2=0},
		{name="vlf_core:mossycobble", prob=254, param2=0},
		{name="vlf_core:mossycobble", prob=254, param2=0},
		{name="air", prob=254, param2=0, force_place=true},
		{name="air", prob=254, param2=0, force_place=true},
		{name="air", prob=254, param2=0},
		{name="vlf_core:cobble", prob=254, param2=0},
		{name="air", prob=0, param2=0},
		{name="air", prob=0, param2=0},
		{name="air", prob=0, param2=0},
		{name="air", prob=0, param2=0},
		{name="air", prob=0, param2=0},
		{name="air", prob=0, param2=0},
		{name="air", prob=0, param2=0},
		{name="air", prob=0, param2=0},
		{name="vlf_core:mossycobble", prob=254, param2=0},
		{name="vlf_core:mossycobble", prob=254, param2=0},
		{name="vlf_core:cobble", prob=254, param2=0},
		{name="vlf_core:mossycobble", prob=254, param2=0},
		{name="vlf_core:cobble", prob=254, param2=0},
		{name="air", prob=254, param2=0, force_place=true},
		{name="air", prob=254, param2=0, force_place=true},
		{name="air", prob=254, param2=0, force_place=true},
		{name="vlf_core:mossycobble", prob=254, param2=0},
		{name="vlf_core:cobble", prob=254, param2=0},
		{name="vlf_core:cobble", prob=254, param2=0},
		{name="vlf_core:cobble", prob=254, param2=0},
		{name="air", prob=0, param2=0},
		{name="air", prob=0, param2=0},
		{name="air", prob=0, param2=0},
		{name="air", prob=0, param2=0},
		{name="air", prob=0, param2=0},
		{name="air", prob=0, param2=0},
		{name="air", prob=0, param2=0},
		{name="air", prob=0, param2=0},
		{name="vlf_core:mossycobble", prob=254, param2=0},
		{name="vlf_core:cobble", prob=254, param2=0},
		{name="vlf_core:mossycobble", prob=254, param2=0},
		{name="vlf_core:cobble", prob=254, param2=0},
		{name="vlf_core:mossycobble", prob=254, param2=0},
		{name="vlf_core:mossycobble", prob=254, param2=0},
		{name="vlf_core:mossycobble", prob=254, param2=0},
		{name="vlf_core:mossycobble", prob=254, param2=0},
		{name="vlf_core:mossycobble", prob=254, param2=0},
		{name="vlf_core:cobble", prob=254, param2=0},
		{name="vlf_core:mossycobble", prob=254, param2=0},
		{name="vlf_core:mossycobble", prob=254, param2=0},
		{name="air", prob=0, param2=0},
		{name="air", prob=0, param2=0},
		{name="air", prob=0, param2=0},
		{name="air", prob=0, param2=0},
		{name="air", prob=0, param2=0},
		{name="air", prob=0, param2=0},
		{name="air", prob=0, param2=0},
		{name="air", prob=0, param2=0},
		{name="air", prob=0, param2=0},
		{name="air", prob=0, param2=0},
		{name="vlf_core:mossycobble", prob=254, param2=0},
		{name="air", prob=254, param2=0, force_place=true},
		{name="air", prob=254, param2=0, force_place=true},
		{name="air", prob=254, param2=0, force_place=true},
		{name="air", prob=254, param2=0, force_place=true},
		{name="air", prob=254, param2=0, force_place=true},
		{name="air", prob=254, param2=0, force_place=true},
		{name="vlf_core:mossycobble", prob=254, param2=0},
		{name="air", prob=0, param2=0},
		{name="air", prob=0, param2=0},
		{name="air", prob=0, param2=0},
		{name="air", prob=0, param2=0},
		{name="air", prob=0, param2=0},
		{name="air", prob=0, param2=0},
		{name="air", prob=0, param2=0},
		{name="air", prob=0, param2=0},
		{name="air", prob=0, param2=0},
		{name="air", prob=0, param2=0},
		{name="air", prob=0, param2=0},
		{name="air", prob=0, param2=0},
		{name="vlf_core:cobble", prob=254, param2=0},
		{name="air", prob=254, param2=0, force_place=true},
		{name="air", prob=254, param2=0, force_place=true},
		{name="air", prob=254, param2=0, force_place=true},
		{name="air", prob=254, param2=0, force_place=true},
		{name="air", prob=254, param2=0, force_place=true},
		{name="air", prob=254, param2=0, force_place=true},
		{name="vlf_core:cobble", prob=254, param2=0},
		{name="air", prob=0, param2=0},
		{name="air", prob=0, param2=0},
		{name="air", prob=0, param2=0},
		{name="air", prob=0, param2=0},
		{name="air", prob=0, param2=0},
		{name="air", prob=0, param2=0},
		{name="air", prob=0, param2=0},
		{name="air", prob=0, param2=0},
		{name="air", prob=0, param2=0},
		{name="air", prob=0, param2=0},
		{name="vlf_stairs:stair_mossycobble", prob=254, param2=23},
		{name="vlf_core:mossycobble", prob=254, param2=0},
		{name="vlf_core:cobble", prob=254, param2=0},
		{name="vlf_core:cobble", prob=254, param2=0},
		{name="vlf_core:mossycobble", prob=254, param2=0},
		{name="vlf_core:mossycobble", prob=254, param2=0},
		{name="vlf_core:cobble", prob=254, param2=0},
		{name="vlf_core:mossycobble", prob=254, param2=0},
		{name="vlf_core:cobble", prob=254, param2=0},
		{name="vlf_core:mossycobble", prob=254, param2=0},
		{name="vlf_core:mossycobble", prob=254, param2=0},
		{name="vlf_stairs:stair_mossycobble", prob=254, param2=21},
		{name="air", prob=0, param2=0},
		{name="air", prob=0, param2=0},
		{name="air", prob=0, param2=0},
		{name="air", prob=0, param2=0},
		{name="air", prob=0, param2=0},
		{name="air", prob=0, param2=0},
		{name="air", prob=0, param2=0},
		{name="air", prob=0, param2=0},
		{name="vlf_core:mossycobble", prob=254, param2=0},
		{name="vlf_core:mossycobble", prob=254, param2=0},
		{name="air", prob=254, param2=0, force_place=true},
		{name="air", prob=254, param2=0, force_place=true},
		{name="air", prob=254, param2=0, force_place=true},
		{name="air", prob=254, param2=0, force_place=true},
		{name="air", prob=254, param2=0, force_place=true},
		{name="air", prob=254, param2=0, force_place=true},
		{name="air", prob=254, param2=0, force_place=true},
		{name="air", prob=254, param2=0, force_place=true},
		{name="vlf_core:cobble", prob=254, param2=0},
		{name="vlf_core:mossycobble", prob=254, param2=0},
		{name="air", prob=0, param2=0},
		{name="air", prob=0, param2=0},
		{name="air", prob=0, param2=0},
		{name="air", prob=0, param2=0},
		{name="air", prob=0, param2=0},
		{name="air", prob=0, param2=0},
		{name="air", prob=0, param2=0},
		{name="air", prob=0, param2=0},
		{name="vlf_core:mossycobble", prob=254, param2=0},
		{name="vlf_core:cobble", prob=254, param2=0},
		{name="air", prob=254, param2=0, force_place=true},
		{name="air", prob=254, param2=0, force_place=true},
		{name="air", prob=254, param2=0, force_place=true},
		{name="air", prob=254, param2=0, force_place=true},
		{name="air", prob=254, param2=0, force_place=true},
		{name="air", prob=254, param2=0, force_place=true},
		{name="air", prob=254, param2=0, force_place=true},
		{name="air", prob=254, param2=0, force_place=true},
		{name="vlf_core:cobble", prob=254, param2=0},
		{name="vlf_core:cobble", prob=254, param2=0},
		{name="air", prob=0, param2=0},
		{name="air", prob=0, param2=0},
		{name="air", prob=0, param2=0},
		{name="air", prob=0, param2=0},
		{name="air", prob=0, param2=0},
		{name="air", prob=0, param2=0},
		{name="air", prob=0, param2=0},
		{name="air", prob=0, param2=0},
		{name="vlf_stairs:stair_cobble", prob=254, param2=1},
		{name="vlf_core:stonebrick", prob=254, param2=0},
		{name="vlf_core:mossycobble", prob=254, param2=0},
		{name="vlf_core:mossycobble", prob=254, param2=0},
		{name="vlf_core:mossycobble", prob=254, param2=0},
		{name="vlf_core:cobble", prob=254, param2=0},
		{name="vlf_core:mossycobble", prob=254, param2=0},
		{name="vlf_core:cobble", prob=254, param2=0},
		{name="vlf_core:cobble", prob=254, param2=0},
		{name="vlf_core:mossycobble", prob=254, param2=0},
		{name="vlf_core:stonebrickmossy", prob=254, param2=0},
		{name="vlf_stairs:stair_cobble", prob=254, param2=0},
		{name="air", prob=0, param2=0},
		{name="air", prob=0, param2=0},
		{name="air", prob=0, param2=0},
		{name="air", prob=0, param2=0},
		{name="air", prob=0, param2=0},
		{name="air", prob=0, param2=0},
		{name="air", prob=0, param2=0},
		{name="air", prob=0, param2=0},
		{name="air", prob=0, param2=0},
		{name="air", prob=0, param2=0},
		{name="air", prob=0, param2=0},
		{name="vlf_core:cobble", prob=254, param2=0},
		{name="vlf_core:mossycobble", prob=254, param2=0},
		{name="vlf_stairs:stair_cobble", prob=254, param2=0},
		{name="vlf_stairs:stair_cobble", prob=254, param2=0},
		{name="vlf_core:cobble", prob=254, param2=0},
		{name="vlf_core:mossycobble", prob=254, param2=0},
		{name="air", prob=0, param2=0},
		{name="air", prob=0, param2=0},
		{name="air", prob=0, param2=0},
		{name="air", prob=0, param2=0},
		{name="air", prob=0, param2=0},
		{name="air", prob=0, param2=0},
		{name="air", prob=0, param2=0},
		{name="air", prob=0, param2=0},
		{name="air", prob=0, param2=0},
		{name="air", prob=0, param2=0},
		{name="air", prob=0, param2=0},
		{name="air", prob=0, param2=0},
		{name="air", prob=0, param2=0},
		{name="air", prob=0, param2=0},
		{name="air", prob=0, param2=0},
		{name="vlf_core:cobble", prob=254, param2=0},
		{name="air", prob=254, param2=0},
		{name="air", prob=254, param2=0},
		{name="vlf_core:mossycobble", prob=254, param2=0},
		{name="air", prob=0, param2=0},
		{name="air", prob=0, param2=0},
		{name="air", prob=0, param2=0},
		{name="air", prob=0, param2=0},
		{name="air", prob=0, param2=0},
		{name="air", prob=0, param2=0},
		{name="air", prob=0, param2=0},
		{name="air", prob=0, param2=0},
		{name="air", prob=0, param2=0},
		{name="air", prob=0, param2=0},
		{name="air", prob=0, param2=0},
		{name="air", prob=0, param2=0},
		{name="air", prob=0, param2=0},
		{name="air", prob=0, param2=0},
		{name="air", prob=0, param2=0},
		{name="air", prob=0, param2=0},
		{name="vlf_core:stonebrickcarved", prob=254, param2=0},
		{name="air", prob=254, param2=0},
		{name="air", prob=254, param2=0},
		{name="vlf_core:stonebrickcarved", prob=254, param2=0},
		{name="air", prob=0, param2=0},
		{name="air", prob=0, param2=0},
		{name="air", prob=0, param2=0},
		{name="air", prob=0, param2=0},
		{name="air", prob=0, param2=0},
		{name="air", prob=0, param2=0},
		{name="air", prob=0, param2=0},
		{name="air", prob=0, param2=0},
		{name="air", prob=0, param2=0},
		{name="air", prob=0, param2=0},
		{name="air", prob=0, param2=0},
		{name="air", prob=0, param2=0},
		{name="vlf_core:cobble", prob=254, param2=0},
		{name="vlf_core:cobble", prob=254, param2=0},
		{name="vlf_core:mossycobble", prob=254, param2=0},
		{name="vlf_core:mossycobble", prob=254, param2=0},
		{name="vlf_core:cobble", prob=254, param2=0},
		{name="vlf_core:cobble", prob=254, param2=0},
		{name="vlf_core:mossycobble", prob=254, param2=0},
		{name="vlf_core:mossycobble", prob=254, param2=0},
		{name="vlf_core:mossycobble", prob=254, param2=0},
		{name="vlf_core:mossycobble", prob=254, param2=0},
		{name="vlf_core:mossycobble", prob=254, param2=0},
		{name="vlf_core:cobble", prob=254, param2=0},
		{name="air", prob=0, param2=0},
		{name="air", prob=0, param2=0},
		{name="air", prob=0, param2=0},
		{name="air", prob=0, param2=0},
		{name="air", prob=0, param2=0},
		{name="air", prob=0, param2=0},
		{name="air", prob=0, param2=0},
		{name="air", prob=0, param2=0},
		{name="vlf_core:mossycobble", prob=254, param2=0},
		{name="vlf_core:mossycobble", prob=254, param2=0},
		{name="air", prob=254, param2=0},
		{name="air", prob=254, param2=0},
		{name="vlf_core:mossycobble", prob=254, param2=0},
		{name="air", prob=254, param2=0},
		{name="air", prob=254, param2=0},
		{name="air", prob=254, param2=0, force_place=true},
		{name="air", prob=254, param2=0, force_place=true},
		{name="air", prob=254, param2=0, force_place=true},
		{name="vlf_core:stonebrickmossy", prob=254, param2=0},
		{name="vlf_core:cobble", prob=254, param2=0},
		{name="air", prob=0, param2=0},
		{name="air", prob=0, param2=0},
		{name="air", prob=0, param2=0},
		{name="air", prob=0, param2=0},
		{name="air", prob=0, param2=0},
		{name="air", prob=0, param2=0},
		{name="air", prob=0, param2=0},
		{name="air", prob=0, param2=0},
		{name="vlf_core:cobble", prob=254, param2=0},
		{name="vlf_core:mossycobble", prob=254, param2=0},
		{name="air", prob=254, param2=0, force_place=true},
		{name="air", prob=254, param2=0, force_place=true},
		{name="air", prob=254, param2=0},
		{name="air", prob=254, param2=0},
		{name="air", prob=254, param2=0},
		{name="air", prob=254, param2=0},
		{name="air", prob=254, param2=0},
		{name="air", prob=254, param2=0},
		{name="vlf_core:stonebrickmossy", prob=254, param2=0},
		{name="vlf_core:mossycobble", prob=254, param2=0},
		{name="air", prob=0, param2=0},
		{name="air", prob=0, param2=0},
		{name="air", prob=0, param2=0},
		{name="air", prob=0, param2=0},
		{name="air", prob=0, param2=0},
		{name="air", prob=0, param2=0},
		{name="air", prob=0, param2=0},
		{name="air", prob=0, param2=0},
		{name="vlf_core:mossycobble", prob=254, param2=0},
		{name="vlf_core:mossycobble", prob=254, param2=0},
		{name="vlf_core:mossycobble", prob=254, param2=0},
		{name="vlf_core:mossycobble", prob=254, param2=0},
		{name="vlf_core:cobble", prob=254, param2=0},
		{name="vlf_core:cobble", prob=254, param2=0},
		{name="vlf_core:mossycobble", prob=254, param2=0},
		{name="air", prob=254, param2=0, force_place=true},
		{name="air", prob=254, param2=0},
		{name="air", prob=254, param2=0},
		{name="air", prob=254, param2=0},
		{name="vlf_core:mossycobble", prob=254, param2=0},
		{name="air", prob=0, param2=0},
		{name="air", prob=0, param2=0},
		{name="air", prob=0, param2=0},
		{name="air", prob=0, param2=0},
		{name="air", prob=0, param2=0},
		{name="air", prob=0, param2=0},
		{name="air", prob=0, param2=0},
		{name="air", prob=0, param2=0},
		{name="vlf_core:mossycobble", prob=254, param2=0},
		{name="vlf_core:cobble", prob=254, param2=0},
		{name="vlf_core:mossycobble", prob=254, param2=0},
		{name="vlf_core:mossycobble", prob=254, param2=0},
		{name="vlf_core:mossycobble", prob=254, param2=0},
		{name="vlf_core:cobble", prob=254, param2=0},
		{name="vlf_core:mossycobble", prob=254, param2=0},
		{name="vlf_core:mossycobble", prob=254, param2=0},
		{name="vlf_core:cobble", prob=254, param2=0},
		{name="vlf_core:cobble", prob=254, param2=0},
		{name="vlf_core:cobble", prob=254, param2=0},
		{name="vlf_core:cobble", prob=254, param2=0},
		{name="air", prob=0, param2=0},
		{name="air", prob=0, param2=0},
		{name="air", prob=0, param2=0},
		{name="air", prob=0, param2=0},
		{name="air", prob=0, param2=0},
		{name="air", prob=0, param2=0},
		{name="air", prob=0, param2=0},
		{name="air", prob=0, param2=0},
		{name="air", prob=0, param2=0},
		{name="air", prob=0, param2=0},
		{name="vlf_core:cobble", prob=254, param2=0},
		{name="air", prob=254, param2=0, force_place=true},
		{name="air", prob=254, param2=0, force_place=true},
		{name="air", prob=254, param2=0, force_place=true},
		{name="air", prob=254, param2=0, force_place=true},
		{name="air", prob=254, param2=0, force_place=true},
		{name="air", prob=254, param2=0, force_place=true},
		{name="vlf_core:cobble", prob=254, param2=0},
		{name="air", prob=0, param2=0},
		{name="air", prob=0, param2=0},
		{name="air", prob=0, param2=0},
		{name="air", prob=0, param2=0},
		{name="air", prob=0, param2=0},
		{name="air", prob=0, param2=0},
		{name="air", prob=0, param2=0},
		{name="air", prob=0, param2=0},
		{name="air", prob=0, param2=0},
		{name="air", prob=0, param2=0},
		{name="air", prob=0, param2=0},
		{name="air", prob=0, param2=0},
		{name="vlf_core:mossycobble", prob=254, param2=0},
		{name="air", prob=254, param2=0, force_place=true},
		{name="air", prob=254, param2=0, force_place=true},
		{name="air", prob=254, param2=0, force_place=true},
		{name="air", prob=254, param2=0, force_place=true},
		{name="air", prob=254, param2=0, force_place=true},
		{name="air", prob=254, param2=0, force_place=true},
		{name="vlf_core:mossycobble", prob=254, param2=0},
		{name="air", prob=0, param2=0},
		{name="air", prob=0, param2=0},
		{name="air", prob=0, param2=0},
		{name="air", prob=0, param2=0},
		{name="air", prob=0, param2=0},
		{name="air", prob=0, param2=0},
		{name="air", prob=0, param2=0},
		{name="air", prob=0, param2=0},
		{name="air", prob=0, param2=0},
		{name="air", prob=0, param2=0},
		{name="air", prob=254, param2=0},
		{name="vlf_core:stonebrickmossy", prob=254, param2=0},
		{name="vlf_core:mossycobble", prob=254, param2=0},
		{name="vlf_core:mossycobble", prob=254, param2=0},
		{name="vlf_core:cobble", prob=254, param2=0},
		{name="vlf_core:mossycobble", prob=254, param2=0},
		{name="vlf_core:mossycobble", prob=254, param2=0},
		{name="vlf_core:cobble", prob=254, param2=0},
		{name="vlf_core:cobble", prob=254, param2=0},
		{name="vlf_core:mossycobble", prob=254, param2=0},
		{name="vlf_core:stonebrickmossy", prob=254, param2=0},
		{name="air", prob=254, param2=0},
		{name="air", prob=0, param2=0},
		{name="air", prob=0, param2=0},
		{name="air", prob=0, param2=0},
		{name="air", prob=0, param2=0},
		{name="air", prob=0, param2=0},
		{name="air", prob=0, param2=0},
		{name="air", prob=0, param2=0},
		{name="air", prob=0, param2=0},
		{name="air", prob=254, param2=0},
		{name="vlf_core:mossycobble", prob=254, param2=0},
		{name="air", prob=254, param2=0},
		{name="air", prob=254, param2=0},
		{name="vlf_stairs:stair_cobble", prob=254, param2=0},
		{name="vlf_core:mossycobble", prob=254, param2=0},
		{name="vlf_core:mossycobble", prob=254, param2=0},
		{name="vlf_stairs:stair_cobble", prob=254, param2=0},
		{name="air", prob=254, param2=0},
		{name="air", prob=254, param2=0},
		{name="vlf_core:mossycobble", prob=254, param2=0},
		{name="air", prob=254, param2=0},
		{name="air", prob=0, param2=0},
		{name="air", prob=0, param2=0},
		{name="air", prob=0, param2=0},
		{name="air", prob=0, param2=0},
		{name="air", prob=0, param2=0},
		{name="air", prob=0, param2=0},
		{name="air", prob=0, param2=0},
		{name="air", prob=0, param2=0},
		{name="air", prob=254, param2=0},
		{name="air", prob=254, param2=0},
		{name="air", prob=254, param2=0, force_place=true},
		{name="air", prob=254, param2=0, force_place=true},
		{name="air", prob=254, param2=0, force_place=true},
		{name="air", prob=254, param2=0, force_place=true},
		{name="air", prob=254, param2=0, force_place=true},
		{name="air", prob=254, param2=0, force_place=true},
		{name="air", prob=254, param2=0, force_place=true},
		{name="air", prob=254, param2=0, force_place=true},
		{name="air", prob=254, param2=0},
		{name="air", prob=254, param2=0},
		{name="air", prob=0, param2=0},
		{name="air", prob=0, param2=0},
		{name="air", prob=0, param2=0},
		{name="air", prob=0, param2=0},
		{name="air", prob=0, param2=0},
		{name="air", prob=0, param2=0},
		{name="air", prob=0, param2=0},
		{name="air", prob=0, param2=0},
		{name="vlf_core:mossycobble", prob=254, param2=0},
		{name="vlf_core:stonebrickcracked", prob=254, param2=0},
		{name="vlf_core:cobble", prob=254, param2=0},
		{name="vlf_core:cobble", prob=254, param2=0},
		{name="air", prob=254, param2=0, force_place=true},
		{name="air", prob=254, param2=0, force_place=true},
		{name="air", prob=254, param2=0, force_place=true},
		{name="air", prob=254, param2=0, force_place=true},
		{name="vlf_core:cobble", prob=254, param2=0},
		{name="vlf_core:mossycobble", prob=254, param2=0},
		{name="vlf_core:stonebrick", prob=254, param2=0},
		{name="vlf_core:cobble", prob=254, param2=0},
		{name="air", prob=0, param2=0},
		{name="air", prob=0, param2=0},
		{name="air", prob=0, param2=0},
		{name="air", prob=0, param2=0},
		{name="air", prob=0, param2=0},
		{name="air", prob=0, param2=0},
		{name="air", prob=0, param2=0},
		{name="air", prob=0, param2=0},
		{name="air", prob=0, param2=0},
		{name="air", prob=0, param2=0},
		{name="air", prob=0, param2=0},
		{name="vlf_core:mossycobble", prob=254, param2=0},
		{name="vlf_core:mossycobble", prob=254, param2=0},
		{name="vlf_core:mossycobble", prob=254, param2=0},
		{name="vlf_core:mossycobble", prob=254, param2=0},
		{name="vlf_core:mossycobble", prob=254, param2=0},
		{name="vlf_core:mossycobble", prob=254, param2=0},
		{name="air", prob=0, param2=0},
		{name="air", prob=0, param2=0},
		{name="air", prob=0, param2=0},
		{name="air", prob=0, param2=0},
		{name="air", prob=0, param2=0},
		{name="air", prob=0, param2=0},
		{name="air", prob=0, param2=0},
		{name="air", prob=0, param2=0},
		{name="air", prob=0, param2=0},
		{name="air", prob=0, param2=0},
		{name="air", prob=0, param2=0},
		{name="air", prob=0, param2=0},
		{name="air", prob=0, param2=0},
		{name="air", prob=0, param2=0},
		{name="air", prob=0, param2=0},
		{name="vlf_core:mossycobble", prob=254, param2=0},
		{name="vlf_stairs:stair_cobble", prob=254, param2=0},
		{name="vlf_stairs:stair_cobble", prob=254, param2=0},
		{name="vlf_core:mossycobble", prob=254, param2=0},
		{name="air", prob=0, param2=0},
		{name="air", prob=0, param2=0},
		{name="air", prob=0, param2=0},
		{name="air", prob=0, param2=0},
		{name="air", prob=0, param2=0},
		{name="air", prob=0, param2=0},
		{name="air", prob=0, param2=0},
		{name="air", prob=0, param2=0},
		{name="air", prob=0, param2=0},
		{name="air", prob=0, param2=0},
		{name="air", prob=0, param2=0},
		{name="air", prob=0, param2=0},
		{name="air", prob=0, param2=0},
		{name="air", prob=0, param2=0},
		{name="air", prob=0, param2=0},
		{name="air", prob=0, param2=0},
		{name="air", prob=254, param2=0},
		{name="air", prob=254, param2=0, force_place=true},
		{name="air", prob=254, param2=0, force_place=true},
		{name="air", prob=254, param2=0},
		{name="air", prob=0, param2=0},
		{name="air", prob=0, param2=0},
		{name="air", prob=0, param2=0},
		{name="air", prob=0, param2=0},
		{name="air", prob=0, param2=0},
		{name="air", prob=0, param2=0},
		{name="air", prob=0, param2=0},
		{name="air", prob=0, param2=0},
		{name="air", prob=0, param2=0},
		{name="air", prob=0, param2=0},
		{name="air", prob=0, param2=0},
		{name="air", prob=0, param2=0},
		{name="vlf_core:cobble", prob=254, param2=0},
		{name="vlf_core:cobble", prob=254, param2=0},
		{name="vlf_core:cobble", prob=254, param2=0},
		{name="vlf_core:mossycobble", prob=254, param2=0},
		{name="vlf_core:mossycobble", prob=254, param2=0},
		{name="vlf_core:mossycobble", prob=254, param2=0},
		{name="vlf_core:mossycobble", prob=254, param2=0},
		{name="vlf_core:cobble", prob=254, param2=0},
		{name="vlf_core:mossycobble", prob=254, param2=0},
		{name="vlf_core:mossycobble", prob=254, param2=0},
		{name="vlf_core:mossycobble", prob=254, param2=0},
		{name="vlf_core:mossycobble", prob=254, param2=0},
		{name="air", prob=0, param2=0},
		{name="air", prob=0, param2=0},
		{name="air", prob=0, param2=0},
		{name="air", prob=0, param2=0},
		{name="air", prob=0, param2=0},
		{name="air", prob=0, param2=0},
		{name="air", prob=0, param2=0},
		{name="air", prob=0, param2=0},
		{name="vlf_core:cobble", prob=254, param2=0},
		{name="vlf_core:cobble", prob=254, param2=0},
		{name="vlf_chests:trapped_chest_small", prob=254, param2=0},
		{name="air", prob=254, param2=0},
		{name="vlf_core:mossycobble", prob=254, param2=0},
		{name="vlf_core:mossycobble", prob=254, param2=0},
		{name="air", prob=254, param2=0},
		{name="air", prob=254, param2=0, force_place=true},
		{name="air", prob=254, param2=0, force_place=true},
		{name="air", prob=254, param2=0, force_place=true},
		{name="air", prob=254, param2=0},
		{name="vlf_core:mossycobble", prob=254, param2=0},
		{name="air", prob=0, param2=0},
		{name="air", prob=0, param2=0},
		{name="air", prob=0, param2=0},
		{name="air", prob=0, param2=0},
		{name="air", prob=0, param2=0},
		{name="air", prob=0, param2=0},
		{name="air", prob=0, param2=0},
		{name="air", prob=0, param2=0},
		{name="vlf_core:mossycobble", prob=254, param2=0},
		{name="vlf_core:mossycobble", prob=254, param2=0},
		{name="air", prob=254, param2=0},
		{name="air", prob=254, param2=0},
		{name="vlf_core:mossycobble", prob=254, param2=0},
		{name="vlf_core:mossycobble", prob=254, param2=0},
		{name="air", prob=254, param2=0},
		{name="air", prob=254, param2=0},
		{name="air", prob=254, param2=0, force_place=true},
		{name="air", prob=254, param2=0, force_place=true},
		{name="air", prob=254, param2=0},
		{name="vlf_core:mossycobble", prob=254, param2=0},
		{name="air", prob=0, param2=0},
		{name="air", prob=0, param2=0},
		{name="air", prob=0, param2=0},
		{name="air", prob=0, param2=0},
		{name="air", prob=0, param2=0},
		{name="air", prob=0, param2=0},
		{name="air", prob=0, param2=0},
		{name="air", prob=0, param2=0},
		{name="vlf_core:mossycobble", prob=254, param2=0},
		{name="vlf_core:cobble", prob=254, param2=0},
		{name="vlf_core:cobble", prob=254, param2=0},
		{name="vlf_core:mossycobble", prob=254, param2=0},
		{name="vlf_core:mossycobble", prob=254, param2=0},
		{name="vlf_core:cobble", prob=254, param2=0},
		{name="vlf_core:mossycobble", prob=254, param2=0},
		{name="vlf_core:cobble", prob=254, param2=0},
		{name="vlf_core:cobble", prob=254, param2=0},
		{name="vlf_core:mossycobble", prob=254, param2=0},
		{name="vlf_core:mossycobble", prob=254, param2=0},
		{name="vlf_core:mossycobble", prob=254, param2=0},
		{name="air", prob=0, param2=0},
		{name="air", prob=0, param2=0},
		{name="air", prob=0, param2=0},
		{name="air", prob=0, param2=0},
		{name="air", prob=0, param2=0},
		{name="air", prob=0, param2=0},
		{name="air", prob=0, param2=0},
		{name="air", prob=0, param2=0},
		{name="vlf_core:cobble", prob=254, param2=0},
		{name="vlf_core:mossycobble", prob=254, param2=0},
		{name="vlf_core:cobble", prob=254, param2=0},
		{name="vlf_core:mossycobble", prob=254, param2=0},
		{name="vlf_core:mossycobble", prob=254, param2=0},
		{name="vlf_stairs:stair_cobble", prob=254, param2=2},
		{name="vlf_stairs:stair_cobble", prob=254, param2=2},
		{name="vlf_core:mossycobble", prob=254, param2=0},
		{name="vlf_core:cobble", prob=254, param2=0},
		{name="vlf_core:mossycobble", prob=254, param2=0},
		{name="vlf_core:cobble", prob=254, param2=0},
		{name="vlf_core:cobble", prob=254, param2=0},
		{name="air", prob=0, param2=0},
		{name="air", prob=0, param2=0},
		{name="air", prob=0, param2=0},
		{name="air", prob=0, param2=0},
		{name="air", prob=0, param2=0},
		{name="air", prob=0, param2=0},
		{name="air", prob=0, param2=0},
		{name="air", prob=0, param2=0},
		{name="air", prob=0, param2=0},
		{name="air", prob=0, param2=0},
		{name="vlf_core:cobble", prob=254, param2=0},
		{name="air", prob=254, param2=0, force_place=true},
		{name="air", prob=254, param2=0, force_place=true},
		{name="air", prob=254, param2=0, force_place=true},
		{name="air", prob=254, param2=0, force_place=true},
		{name="air", prob=254, param2=0, force_place=true},
		{name="air", prob=254, param2=0, force_place=true},
		{name="vlf_core:mossycobble", prob=254, param2=0},
		{name="air", prob=0, param2=0},
		{name="air", prob=0, param2=0},
		{name="air", prob=0, param2=0},
		{name="air", prob=0, param2=0},
		{name="air", prob=0, param2=0},
		{name="air", prob=0, param2=0},
		{name="air", prob=0, param2=0},
		{name="air", prob=0, param2=0},
		{name="air", prob=0, param2=0},
		{name="air", prob=0, param2=0},
		{name="air", prob=0, param2=0},
		{name="air", prob=0, param2=0},
		{name="vlf_core:cobble", prob=254, param2=0},
		{name="air", prob=254, param2=0, force_place=true},
		{name="air", prob=254, param2=0, force_place=true},
		{name="air", prob=254, param2=0, force_place=true},
		{name="air", prob=254, param2=0, force_place=true},
		{name="air", prob=254, param2=0, force_place=true},
		{name="air", prob=254, param2=0, force_place=true},
		{name="vlf_core:cobble", prob=254, param2=0},
		{name="air", prob=0, param2=0},
		{name="air", prob=0, param2=0},
		{name="air", prob=0, param2=0},
		{name="air", prob=0, param2=0},
		{name="air", prob=0, param2=0},
		{name="air", prob=0, param2=0},
		{name="air", prob=0, param2=0},
		{name="air", prob=0, param2=0},
		{name="air", prob=0, param2=0},
		{name="air", prob=0, param2=0},
		{name="vlf_stairs:stair_cobble", prob=254, param2=23},
		{name="vlf_core:mossycobble", prob=254, param2=0},
		{name="vlf_core:mossycobble", prob=254, param2=0},
		{name="vlf_core:cobble", prob=254, param2=0},
		{name="air", prob=254, param2=0, force_place=true},
		{name="air", prob=254, param2=0, force_place=true},
		{name="air", prob=254, param2=0, force_place=true},
		{name="air", prob=254, param2=0, force_place=true},
		{name="vlf_core:mossycobble", prob=254, param2=0},
		{name="vlf_core:mossycobble", prob=254, param2=0},
		{name="vlf_core:cobble", prob=254, param2=0},
		{name="vlf_stairs:stair_mossycobble", prob=254, param2=21},
		{name="air", prob=0, param2=0},
		{name="air", prob=0, param2=0},
		{name="air", prob=0, param2=0},
		{name="air", prob=0, param2=0},
		{name="air", prob=0, param2=0},
		{name="air", prob=0, param2=0},
		{name="air", prob=0, param2=0},
		{name="air", prob=0, param2=0},
		{name="vlf_core:mossycobble", prob=254, param2=0},
		{name="vlf_core:mossycobble", prob=254, param2=0},
		{name="air", prob=254, param2=0, force_place=true},
		{name="air", prob=254, param2=0, force_place=true},
		{name="air", prob=254, param2=0, force_place=true},
		{name="air", prob=254, param2=0, force_place=true},
		{name="air", prob=254, param2=0, force_place=true},
		{name="air", prob=254, param2=0, force_place=true},
		{name="air", prob=254, param2=0, force_place=true},
		{name="air", prob=254, param2=0, force_place=true},
		{name="vlf_core:cobble", prob=254, param2=0},
		{name="vlf_core:mossycobble", prob=254, param2=0},
		{name="air", prob=0, param2=0},
		{name="air", prob=0, param2=0},
		{name="air", prob=0, param2=0},
		{name="air", prob=0, param2=0},
		{name="air", prob=0, param2=0},
		{name="air", prob=0, param2=0},
		{name="air", prob=0, param2=0},
		{name="air", prob=0, param2=0},
		{name="vlf_core:cobble", prob=254, param2=0},
		{name="vlf_core:cobble", prob=254, param2=0},
		{name="air", prob=254, param2=0, force_place=true},
		{name="air", prob=254, param2=0, force_place=true},
		{name="air", prob=254, param2=0, force_place=true},
		{name="air", prob=254, param2=0, force_place=true},
		{name="air", prob=254, param2=0, force_place=true},
		{name="air", prob=254, param2=0, force_place=true},
		{name="air", prob=254, param2=0, force_place=true},
		{name="air", prob=254, param2=0, force_place=true},
		{name="vlf_core:cobble", prob=254, param2=0},
		{name="vlf_core:cobble", prob=254, param2=0},
		{name="air", prob=0, param2=0},
		{name="air", prob=0, param2=0},
		{name="air", prob=0, param2=0},
		{name="air", prob=0, param2=0},
		{name="air", prob=0, param2=0},
		{name="air", prob=0, param2=0},
		{name="air", prob=0, param2=0},
		{name="air", prob=0, param2=0},
		{name="air", prob=0, param2=0},
		{name="vlf_core:stonebrickcracked", prob=254, param2=0},
		{name="vlf_core:mossycobble", prob=254, param2=0},
		{name="vlf_core:mossycobble", prob=254, param2=0},
		{name="air", prob=254, param2=0, force_place=true},
		{name="air", prob=254, param2=0, force_place=true},
		{name="air", prob=254, param2=0, force_place=true},
		{name="air", prob=254, param2=0, force_place=true},
		{name="vlf_core:mossycobble", prob=254, param2=0},
		{name="vlf_core:cobble", prob=254, param2=0},
		{name="vlf_core:stonebrickmossy", prob=254, param2=0},
		{name="vlf_stairs:stair_mossycobble", prob=254, param2=2},
		{name="air", prob=0, param2=0},
		{name="air", prob=0, param2=0},
		{name="air", prob=0, param2=0},
		{name="air", prob=0, param2=0},
		{name="air", prob=0, param2=0},
		{name="air", prob=0, param2=0},
		{name="air", prob=0, param2=0},
		{name="air", prob=0, param2=0},
		{name="air", prob=0, param2=0},
		{name="air", prob=0, param2=0},
		{name="air", prob=0, param2=0},
		{name="vlf_core:mossycobble", prob=254, param2=0},
		{name="vlf_core:mossycobble", prob=254, param2=0},
		{name="air", prob=254, param2=0},
		{name="air", prob=254, param2=0},
		{name="vlf_core:mossycobble", prob=254, param2=0},
		{name="vlf_core:mossycobble", prob=254, param2=0},
		{name="air", prob=0, param2=0},
		{name="air", prob=0, param2=0},
		{name="air", prob=0, param2=0},
		{name="air", prob=0, param2=0},
		{name="air", prob=0, param2=0},
		{name="air", prob=0, param2=0},
		{name="air", prob=0, param2=0},
		{name="air", prob=0, param2=0},
		{name="air", prob=0, param2=0},
		{name="air", prob=0, param2=0},
		{name="air", prob=0, param2=0},
		{name="air", prob=0, param2=0},
		{name="air", prob=0, param2=0},
		{name="air", prob=0, param2=0},
		{name="air", prob=0, param2=0},
		{name="vlf_core:cobble", prob=254, param2=0},
		{name="vlf_core:cobble", prob=254, param2=0},
		{name="vlf_core:mossycobble", prob=254, param2=0},
		{name="vlf_core:mossycobble", prob=254, param2=0},
		{name="air", prob=0, param2=0},
		{name="air", prob=0, param2=0},
		{name="air", prob=0, param2=0},
		{name="air", prob=0, param2=0},
		{name="air", prob=0, param2=0},
		{name="air", prob=0, param2=0},
		{name="air", prob=0, param2=0},
		{name="air", prob=0, param2=0},
		{name="air", prob=0, param2=0},
		{name="air", prob=0, param2=0},
		{name="air", prob=0, param2=0},
		{name="air", prob=0, param2=0},
		{name="air", prob=0, param2=0},
		{name="air", prob=0, param2=0},
		{name="air", prob=0, param2=0},
		{name="air", prob=0, param2=0},
		{name="air", prob=254, param2=0},
		{name="vlf_stairs:stair_cobble", prob=254, param2=0},
		{name="vlf_stairs:stair_cobble", prob=254, param2=0},
		{name="air", prob=254, param2=0},
		{name="air", prob=0, param2=0},
		{name="air", prob=0, param2=0},
		{name="air", prob=0, param2=0},
		{name="air", prob=0, param2=0},
		{name="air", prob=0, param2=0},
		{name="air", prob=0, param2=0},
		{name="air", prob=0, param2=0},
		{name="air", prob=0, param2=0},
		{name="air", prob=0, param2=0},
		{name="air", prob=0, param2=0},
		{name="air", prob=0, param2=0},
		{name="air", prob=0, param2=0},
		{name="vlf_core:cobble", prob=254, param2=0},
		{name="vlf_core:mossycobble", prob=254, param2=0},
		{name="vlf_core:mossycobble", prob=254, param2=0},
		{name="vlf_core:cobble", prob=254, param2=0},
		{name="vlf_core:cobble", prob=254, param2=0},
		{name="vlf_core:cobble", prob=254, param2=0},
		{name="vlf_core:mossycobble", prob=254, param2=0},
		{name="vlf_core:cobble", prob=254, param2=0},
		{name="vlf_core:mossycobble", prob=254, param2=0},
		{name="vlf_core:mossycobble", prob=254, param2=0},
		{name="vlf_core:mossycobble", prob=254, param2=0},
		{name="vlf_core:mossycobble", prob=254, param2=0},
		{name="air", prob=0, param2=0},
		{name="air", prob=0, param2=0},
		{name="air", prob=0, param2=0},
		{name="air", prob=0, param2=0},
		{name="air", prob=0, param2=0},
		{name="air", prob=0, param2=0},
		{name="air", prob=0, param2=0},
		{name="air", prob=0, param2=0},
		{name="vlf_core:cobble", prob=254, param2=0},
		{name="vlf_core:mossycobble", prob=254, param2=0},
		{name="vlf_core:mossycobble", prob=254, param2=0},
		{name="vlf_core:cobble", prob=254, param2=0},
		{name="vlf_core:mossycobble", prob=254, param2=0},
		{name="vlf_core:cobble", prob=254, param2=0},
		{name="vlf_core:stonebrickmossy", prob=254, param2=0},
		{name="air", prob=254, param2=0, force_place=true},
		{name="air", prob=254, param2=0, force_place=true},
		{name="air", prob=254, param2=0, force_place=true},
		{name="vlf_core:stonebrickmossy", prob=254, param2=0},
		{name="vlf_core:cobble", prob=254, param2=0},
		{name="air", prob=0, param2=0},
		{name="air", prob=0, param2=0},
		{name="air", prob=0, param2=0},
		{name="air", prob=0, param2=0},
		{name="air", prob=0, param2=0},
		{name="air", prob=0, param2=0},
		{name="air", prob=0, param2=0},
		{name="air", prob=0, param2=0},
		{name="vlf_core:cobble", prob=254, param2=0},
		{name="vlf_core:mossycobble", prob=254, param2=0},
		{name="vlf_core:mossycobble", prob=254, param2=0},
		{name="vlf_core:mossycobble", prob=254, param2=0},
		{name="vlf_core:mossycobble", prob=254, param2=0},
		{name="vlf_core:mossycobble", prob=254, param2=0},
		{name="vlf_core:stonebrickmossy", prob=254, param2=0},
		{name="air", prob=254, param2=0},
		{name="air", prob=254, param2=0},
		{name="mesecons_walllever:wall_lever_off", prob=254, param2=1},
		{name="vlf_core:stonebrickcarved", prob=254, param2=0},
		{name="vlf_core:mossycobble", prob=254, param2=0},
		{name="air", prob=0, param2=0},
		{name="air", prob=0, param2=0},
		{name="air", prob=0, param2=0},
		{name="air", prob=0, param2=0},
		{name="air", prob=0, param2=0},
		{name="air", prob=0, param2=0},
		{name="air", prob=0, param2=0},
		{name="air", prob=0, param2=0},
		{name="vlf_core:mossycobble", prob=254, param2=0},
		{name="vlf_core:mossycobble", prob=254, param2=0},
		{name="vlf_core:mossycobble", prob=254, param2=0},
		{name="vlf_core:mossycobble", prob=254, param2=0},
		{name="vlf_core:mossycobble", prob=254, param2=0},
		{name="vlf_stairs:stair_cobble", prob=254, param2=2},
		{name="vlf_stairs:stair_cobble", prob=254, param2=2},
		{name="vlf_core:cobble", prob=254, param2=0},
		{name="air", prob=254, param2=0},
		{name="air", prob=254, param2=0},
		{name="vlf_core:stonebrickcracked", prob=254, param2=0},
		{name="vlf_core:mossycobble", prob=254, param2=0},
		{name="air", prob=0, param2=0},
		{name="air", prob=0, param2=0},
		{name="air", prob=0, param2=0},
		{name="air", prob=0, param2=0},
		{name="air", prob=0, param2=0},
		{name="air", prob=0, param2=0},
		{name="air", prob=0, param2=0},
		{name="air", prob=0, param2=0},
		{name="vlf_core:mossycobble", prob=254, param2=0},
		{name="vlf_core:mossycobble", prob=254, param2=0},
		{name="vlf_core:mossycobble", prob=254, param2=0},
		{name="vlf_core:cobble", prob=254, param2=0},
		{name="vlf_core:cobble", prob=254, param2=0},
		{name="air", prob=254, param2=0},
		{name="air", prob=254, param2=0},
		{name="vlf_core:cobble", prob=254, param2=0},
		{name="vlf_core:mossycobble", prob=254, param2=0},
		{name="vlf_core:mossycobble", prob=254, param2=0},
		{name="vlf_core:mossycobble", prob=254, param2=0},
		{name="vlf_core:mossycobble", prob=254, param2=0},
		{name="air", prob=0, param2=0},
		{name="air", prob=0, param2=0},
		{name="air", prob=0, param2=0},
		{name="air", prob=0, param2=0},
		{name="vlf_stairs:stair_cobble", prob=254, param2=1},
		{name="vlf_core:mossycobble", prob=254, param2=0},
		{name="vlf_core:mossycobble", prob=254, param2=0},
		{name="vlf_core:mossycobble", prob=254, param2=0},
		{name="vlf_core:cobble", prob=254, param2=0},
		{name="vlf_core:mossycobble", prob=254, param2=0},
		{name="vlf_core:mossycobble", prob=254, param2=0},
		{name="air", prob=254, param2=0, force_place=true},
		{name="air", prob=254, param2=0, force_place=true},
		{name="air", prob=254, param2=0, force_place=true},
		{name="air", prob=254, param2=0, force_place=true},
		{name="air", prob=254, param2=0, force_place=true},
		{name="air", prob=254, param2=0, force_place=true},
		{name="vlf_core:cobble", prob=254, param2=0},
		{name="vlf_core:cobble", prob=254, param2=0},
		{name="vlf_core:cobble", prob=254, param2=0},
		{name="vlf_core:cobble", prob=254, param2=0},
		{name="vlf_core:mossycobble", prob=254, param2=0},
		{name="vlf_core:mossycobble", prob=254, param2=0},
		{name="vlf_stairs:stair_cobble", prob=254, param2=3},
		{name="air", prob=0, param2=0},
		{name="vlf_stairs:stair_cobble", prob=254, param2=1},
		{name="vlf_core:cobble", prob=254, param2=0},
		{name="vlf_core:cobble", prob=254, param2=0},
		{name="vlf_core:mossycobble", prob=254, param2=0},
		{name="vlf_core:mossycobble", prob=254, param2=0},
		{name="vlf_core:mossycobble", prob=254, param2=0},
		{name="air", prob=254, param2=0, force_place=true},
		{name="air", prob=254, param2=0, force_place=true},
		{name="air", prob=254, param2=0, force_place=true},
		{name="air", prob=254, param2=0, force_place=true},
		{name="air", prob=254, param2=0, force_place=true},
		{name="air", prob=254, param2=0, force_place=true},
		{name="vlf_core:mossycobble", prob=254, param2=0},
		{name="vlf_core:cobble", prob=254, param2=0},
		{name="vlf_core:mossycobble", prob=254, param2=0},
		{name="vlf_core:cobble", prob=254, param2=0},
		{name="vlf_core:cobble", prob=254, param2=0},
		{name="vlf_stairs:stair_cobble", prob=254, param2=3},
		{name="air", prob=0, param2=0},
		{name="air", prob=0, param2=0},
		{name="air", prob=0, param2=0},
		{name="vlf_stairs:stair_cobble", prob=254, param2=1},
		{name="vlf_core:mossycobble", prob=254, param2=0},
		{name="vlf_core:cobble", prob=254, param2=0},
		{name="vlf_core:mossycobble", prob=254, param2=0},
		{name="vlf_core:mossycobble", prob=254, param2=0},
		{name="vlf_core:mossycobble", prob=254, param2=0},
		{name="air", prob=254, param2=0, force_place=true},
		{name="air", prob=254, param2=0, force_place=true},
		{name="air", prob=254, param2=0, force_place=true},
		{name="air", prob=254, param2=0, force_place=true},
		{name="vlf_core:mossycobble", prob=254, param2=0},
		{name="vlf_core:mossycobble", prob=254, param2=0},
		{name="vlf_core:stonebrickcracked", prob=254, param2=0},
		{name="vlf_core:mossycobble", prob=254, param2=0},
		{name="vlf_core:cobble", prob=254, param2=0},
		{name="vlf_stairs:stair_mossycobble", prob=254, param2=3},
		{name="air", prob=0, param2=0},
		{name="air", prob=0, param2=0},
		{name="air", prob=0, param2=0},
		{name="air", prob=0, param2=0},
		{name="air", prob=0, param2=0},
		{name="vlf_stairs:stair_cobble", prob=254, param2=1},
		{name="vlf_core:mossycobble", prob=254, param2=0},
		{name="vlf_core:cobble", prob=254, param2=0},
		{name="air", prob=254, param2=0, force_place=true},
		{name="air", prob=254, param2=0, force_place=true},
		{name="air", prob=254, param2=0, force_place=true},
		{name="air", prob=254, param2=0, force_place=true},
		{name="air", prob=254, param2=0, force_place=true},
		{name="air", prob=254, param2=0, force_place=true},
		{name="air", prob=254, param2=0, force_place=true},
		{name="air", prob=254, param2=0, force_place=true},
		{name="vlf_core:mossycobble", prob=254, param2=0},
		{name="vlf_core:mossycobble", prob=254, param2=0},
		{name="vlf_stairs:stair_cobble", prob=254, param2=3},
		{name="air", prob=0, param2=0},
		{name="air", prob=0, param2=0},
		{name="air", prob=0, param2=0},
		{name="air", prob=0, param2=0},
		{name="air", prob=0, param2=0},
		{name="air", prob=0, param2=0},
		{name="air", prob=0, param2=0},
		{name="vlf_stairs:stair_cobble", prob=254, param2=1},
		{name="vlf_core:mossycobble", prob=254, param2=0},
		{name="air", prob=254, param2=0, force_place=true},
		{name="air", prob=254, param2=0, force_place=true},
		{name="air", prob=254, param2=0, force_place=true},
		{name="air", prob=254, param2=0, force_place=true},
		{name="air", prob=254, param2=0, force_place=true},
		{name="air", prob=254, param2=0, force_place=true},
		{name="air", prob=254, param2=0, force_place=true},
		{name="air", prob=254, param2=0, force_place=true},
		{name="vlf_core:cobble", prob=254, param2=0},
		{name="vlf_stairs:stair_cobble", prob=254, param2=3},
		{name="air", prob=0, param2=0},
		{name="air", prob=0, param2=0},
		{name="air", prob=0, param2=0},
		{name="air", prob=0, param2=0},
		{name="air", prob=0, param2=0},
		{name="air", prob=0, param2=0},
		{name="air", prob=0, param2=0},
		{name="air", prob=0, param2=0},
		{name="air", prob=0, param2=0},
		{name="vlf_stairs:stair_cobble", prob=254, param2=1},
		{name="vlf_core:cobble", prob=254, param2=0},
		{name="vlf_core:mossycobble", prob=254, param2=0},
		{name="air", prob=254, param2=0, force_place=true},
		{name="air", prob=254, param2=0, force_place=true},
		{name="air", prob=254, param2=0, force_place=true},
		{name="air", prob=254, param2=0, force_place=true},
		{name="vlf_core:cobble", prob=254, param2=0},
		{name="vlf_core:mossycobble", prob=254, param2=0},
		{name="vlf_stairs:stair_mossycobble", prob=254, param2=3},
		{name="air", prob=254, param2=0},
		{name="air", prob=0, param2=0},
		{name="air", prob=0, param2=0},
		{name="air", prob=0, param2=0},
		{name="air", prob=0, param2=0},
		{name="air", prob=0, param2=0},
		{name="air", prob=0, param2=0},
		{name="air", prob=0, param2=0},
		{name="air", prob=0, param2=0},
		{name="air", prob=0, param2=0},
		{name="air", prob=0, param2=0},
		{name="vlf_stairs:stair_cobble", prob=254, param2=1},
		{name="vlf_core:mossycobble", prob=254, param2=0},
		{name="vlf_core:cobble", prob=254, param2=0},
		{name="air", prob=254, param2=0},
		{name="air", prob=254, param2=0},
		{name="vlf_core:cobble", prob=254, param2=0},
		{name="vlf_core:cobble", prob=254, param2=0},
		{name="vlf_stairs:stair_mossycobble", prob=254, param2=3},
		{name="air", prob=0, param2=0},
		{name="air", prob=0, param2=0},
		{name="air", prob=0, param2=0},
		{name="air", prob=0, param2=0},
		{name="air", prob=0, param2=0},
		{name="air", prob=0, param2=0},
		{name="air", prob=0, param2=0},
		{name="air", prob=0, param2=0},
		{name="air", prob=0, param2=0},
		{name="air", prob=0, param2=0},
		{name="air", prob=0, param2=0},
		{name="air", prob=0, param2=0},
		{name="air", prob=0, param2=0},
		{name="vlf_stairs:stair_cobble", prob=254, param2=1},
		{name="vlf_core:cobble", prob=254, param2=0},
		{name="vlf_core:mossycobble", prob=254, param2=0},
		{name="vlf_core:mossycobble", prob=254, param2=0},
		{name="vlf_core:cobble", prob=254, param2=0},
		{name="vlf_stairs:stair_mossycobble", prob=254, param2=3},
		{name="air", prob=0, param2=0},
		{name="air", prob=0, param2=0},
		{name="air", prob=0, param2=0},
		{name="air", prob=0, param2=0},
		{name="air", prob=0, param2=0},
		{name="air", prob=0, param2=0},
		{name="air", prob=0, param2=0},
		{name="air", prob=0, param2=0},
		{name="air", prob=0, param2=0},
		{name="air", prob=0, param2=0},
		{name="air", prob=0, param2=0},
		{name="air", prob=0, param2=0},
		{name="air", prob=0, param2=0},
		{name="air", prob=0, param2=0},
		{name="air", prob=0, param2=0},
		{name="vlf_stairs:stair_cobble", prob=254, param2=1},
		{name="vlf_core:mossycobble", prob=254, param2=0},
		{name="vlf_core:cobble", prob=254, param2=0},
		{name="vlf_stairs:stair_cobble", prob=254, param2=3},
		{name="air", prob=0, param2=0},
		{name="air", prob=0, param2=0},
		{name="air", prob=0, param2=0},
		{name="air", prob=0, param2=0},
		{name="air", prob=0, param2=0},
		{name="air", prob=0, param2=0},
		{name="air", prob=0, param2=0},
		{name="air", prob=0, param2=0},
		{name="air", prob=0, param2=0},
		{name="air", prob=0, param2=0},
		{name="air", prob=0, param2=0},
		{name="air", prob=0, param2=0},
		{name="vlf_core:cobble", prob=254, param2=0},
		{name="vlf_core:cobble", prob=254, param2=0},
		{name="vlf_core:mossycobble", prob=254, param2=0},
		{name="vlf_core:cobble", prob=254, param2=0},
		{name="vlf_core:mossycobble", prob=254, param2=0},
		{name="vlf_core:mossycobble", prob=254, param2=0},
		{name="vlf_core:mossycobble", prob=254, param2=0},
		{name="vlf_core:cobble", prob=254, param2=0},
		{name="vlf_core:cobble", prob=254, param2=0},
		{name="vlf_core:mossycobble", prob=254, param2=0},
		{name="vlf_core:mossycobble", prob=254, param2=0},
		{name="vlf_core:cobble", prob=254, param2=0},
		{name="air", prob=0, param2=0},
		{name="air", prob=0, param2=0},
		{name="air", prob=0, param2=0},
		{name="air", prob=0, param2=0},
		{name="air", prob=0, param2=0},
		{name="air", prob=0, param2=0},
		{name="air", prob=0, param2=0},
		{name="air", prob=0, param2=0},
		{name="vlf_core:cobble", prob=254, param2=0},
		{name="vlf_core:mossycobble", prob=254, param2=0},
		{name="air", prob=254, param2=0},
		{name="vlf_core:mossycobble", prob=254, param2=0},
		{name="vlf_core:mossycobble", prob=254, param2=0},
		{name="vlf_core:mossycobble", prob=254, param2=0},
		{name="vlf_core:stonebrickcracked", prob=254, param2=0},
		{name="air", prob=254, param2=0, force_place=true},
		{name="air", prob=254, param2=0, force_place=true},
		{name="air", prob=254, param2=0, force_place=true},
		{name="air", prob=254, param2=0},
		{name="vlf_core:cobble", prob=254, param2=0},
		{name="air", prob=0, param2=0},
		{name="air", prob=0, param2=0},
		{name="air", prob=0, param2=0},
		{name="air", prob=0, param2=0},
		{name="air", prob=0, param2=0},
		{name="air", prob=0, param2=0},
		{name="air", prob=0, param2=0},
		{name="air", prob=0, param2=0},
		{name="vlf_core:mossycobble", prob=254, param2=0},
		{name="mesecons_pistons:piston_sticky_off", prob=254, param2=3},
		{name="mesecons_pistons:piston_up_sticky_off", prob=254, param2=0},
		{name="air", prob=254, param2=0},
		{name="vlf_core:cobble", prob=254, param2=0},
		{name="vlf_stairs:stair_cobble", prob=254, param2=2},
		{name="vlf_stairs:stair_cobble", prob=254, param2=2},
		{name="air", prob=254, param2=0, force_place=true},
		{name="air", prob=254, param2=0, force_place=true},
		{name="air", prob=254, param2=0},
		{name="air", prob=254, param2=0},
		{name="vlf_core:cobble", prob=254, param2=0},
		{name="air", prob=0, param2=0},
		{name="air", prob=0, param2=0},
		{name="air", prob=0, param2=0},
		{name="air", prob=0, param2=0},
		{name="air", prob=0, param2=0},
		{name="air", prob=0, param2=0},
		{name="air", prob=0, param2=0},
		{name="air", prob=0, param2=0},
		{name="vlf_core:mossycobble", prob=254, param2=0},
		{name="mesecons_pistons:piston_sticky_off", prob=254, param2=3},
		{name="air", prob=254, param2=0},
		{name="air", prob=254, param2=0},
		{name="vlf_core:cobble", prob=254, param2=0},
		{name="air", prob=254, param2=0},
		{name="air", prob=254, param2=0},
		{name="vlf_core:mossycobble", prob=254, param2=0},
		{name="air", prob=254, param2=0},
		{name="air", prob=254, param2=0},
		{name="air", prob=254, param2=0},
		{name="vlf_core:mossycobble", prob=254, param2=0},
		{name="air", prob=0, param2=0},
		{name="air", prob=0, param2=0},
		{name="air", prob=0, param2=0},
		{name="air", prob=0, param2=0},
		{name="air", prob=0, param2=0},
		{name="air", prob=0, param2=0},
		{name="air", prob=0, param2=0},
		{name="air", prob=0, param2=0},
		{name="vlf_core:mossycobble", prob=254, param2=0},
		{name="vlf_core:mossycobble", prob=254, param2=0},
		{name="vlf_core:cobble", prob=254, param2=0},
		{name="vlf_core:mossycobble", prob=254, param2=0},
		{name="vlf_core:cobble", prob=254, param2=0},
		{name="air", prob=254, param2=0},
		{name="air", prob=254, param2=0},
		{name="vlf_core:cobble", prob=254, param2=0},
		{name="vlf_core:mossycobble", prob=254, param2=0},
		{name="vlf_core:cobble", prob=254, param2=0},
		{name="vlf_core:cobble", prob=254, param2=0},
		{name="vlf_core:mossycobble", prob=254, param2=0},
		{name="air", prob=0, param2=0},
		{name="air", prob=0, param2=0},
		{name="air", prob=0, param2=0},
		{name="air", prob=0, param2=0},
		{name="air", prob=0, param2=0},
		{name="air", prob=0, param2=0},
		{name="air", prob=0, param2=0},
		{name="air", prob=0, param2=0},
		{name="air", prob=0, param2=0},
		{name="air", prob=0, param2=0},
		{name="vlf_core:mossycobble", prob=254, param2=0},
		{name="air", prob=254, param2=0},
		{name="vlf_stairs:stair_cobble", prob=254, param2=0},
		{name="air", prob=254, param2=0},
		{name="air", prob=254, param2=0},
		{name="vlf_stairs:stair_cobble", prob=254, param2=0},
		{name="air", prob=254, param2=0},
		{name="vlf_core:mossycobble", prob=254, param2=0},
		{name="air", prob=0, param2=0},
		{name="air", prob=0, param2=0},
		{name="air", prob=0, param2=0},
		{name="air", prob=0, param2=0},
		{name="air", prob=0, param2=0},
		{name="air", prob=0, param2=0},
		{name="air", prob=0, param2=0},
		{name="air", prob=0, param2=0},
		{name="air", prob=0, param2=0},
		{name="air", prob=0, param2=0},
		{name="air", prob=0, param2=0},
		{name="air", prob=0, param2=0},
		{name="vlf_core:mossycobble", prob=254, param2=0},
		{name="air", prob=254, param2=0, force_place=true},
		{name="air", prob=254, param2=0, force_place=true},
		{name="air", prob=254, param2=0, force_place=true},
		{name="air", prob=254, param2=0, force_place=true},
		{name="air", prob=254, param2=0, force_place=true},
		{name="air", prob=254, param2=0, force_place=true},
		{name="vlf_core:mossycobble", prob=254, param2=0},
		{name="air", prob=0, param2=0},
		{name="air", prob=0, param2=0},
		{name="air", prob=0, param2=0},
		{name="air", prob=0, param2=0},
		{name="air", prob=0, param2=0},
		{name="air", prob=0, param2=0},
		{name="air", prob=0, param2=0},
		{name="air", prob=0, param2=0},
		{name="air", prob=0, param2=0},
		{name="air", prob=0, param2=0},
		{name="vlf_stairs:stair_cobble", prob=254, param2=23},
		{name="vlf_core:cobble", prob=254, param2=0},
		{name="vlf_core:mossycobble", prob=254, param2=0},
		{name="vlf_core:mossycobble", prob=254, param2=0},
		{name="air", prob=254, param2=0, force_place=true},
		{name="air", prob=254, param2=0, force_place=true},
		{name="air", prob=254, param2=0, force_place=true},
		{name="air", prob=254, param2=0, force_place=true},
		{name="vlf_core:mossycobble", prob=254, param2=0},
