schematic = {
	size = {x=9, y=14, z=10},
	yslice_prob = {
		{ypos=0, prob=254},
		{ypos=1, prob=254},
		{ypos=2, prob=254},
		{ypos=3, prob=254},
		{ypos=4, prob=254},
		{ypos=5, prob=254},
		{ypos=6, prob=254},
		{ypos=7, prob=254},
		{ypos=8, prob=254},
		{ypos=9, prob=254},
		{ypos=10, prob=254},
		{ypos=11, prob=254},
		{ypos=12, prob=254},
		{ypos=13, prob=254},
	},
	data = {
		{name="air", prob=0, param2=0},
		{name="air", prob=0, param2=0},
		{name="air", prob=0, param2=0},
		{name="air", prob=0, param2=0},
		{name="air", prob=0, param2=0},
		{name="air", prob=0, param2=0},
		{name="air", prob=0, param2=0},
		{name="air", prob=0, param2=0},
		{name="air", prob=0, param2=0},
		{name="air", prob=0, param2=0},
		{name="air", prob=0, param2=0},
		{name="air", prob=0, param2=0},
		{name="air", prob=0, param2=0},
		{name="air", prob=0, param2=0},
		{name="air", prob=0, param2=0},
		{name="air", prob=0, param2=0},
		{name="air", prob=0, param2=0},
		{name="air", prob=0, param2=0},
		{name="air", prob=0, param2=0},
		{name="air", prob=0, param2=0},
		{name="air", prob=0, param2=0},
		{name="air", prob=0, param2=0},
		{name="vlf_core:vine", prob=254, param2=4},
		{name="air", prob=0, param2=0},
		{name="air", prob=0, param2=0},
		{name="air", prob=0, param2=0},
		{name="air", prob=0, param2=0},
		{name="air", prob=0, param2=0},
		{name="air", prob=0, param2=0},
		{name="air", prob=0, param2=0},
		{name="air", prob=0, param2=0},
		{name="vlf_core:vine", prob=254, param2=4},
		{name="air", prob=0, param2=0},
		{name="air", prob=0, param2=0},
		{name="air", prob=0, param2=0},
		{name="air", prob=0, param2=0},
		{name="air", prob=0, param2=0},
		{name="air", prob=0, param2=0},
		{name="air", prob=0, param2=0},
		{name="air", prob=0, param2=0},
		{name="vlf_core:vine", prob=254, param2=4},
		{name="air", prob=0, param2=0},
		{name="air", prob=0, param2=0},
		{name="air", prob=0, param2=0},
		{name="air", prob=0, param2=0},
		{name="air", prob=0, param2=0},
		{name="air", prob=0, param2=0},
		{name="air", prob=0, param2=0},
		{name="air", prob=0, param2=0},
		{name="air", prob=0, param2=0},
		{name="air", prob=0, param2=0},
		{name="air", prob=0, param2=0},
		{name="air", prob=0, param2=0},
		{name="air", prob=0, param2=0},
		{name="air", prob=0, param2=0},
		{name="air", prob=0, param2=0},
		{name="air", prob=0, param2=0},
		{name="air", prob=0, param2=0},
		{name="air", prob=0, param2=0},
		{name="air", prob=0, param2=0},
		{name="air", prob=0, param2=0},
		{name="air", prob=0, param2=0},
		{name="air", prob=0, param2=0},
		{name="air", prob=0, param2=0},
		{name="air", prob=0, param2=0},
		{name="air", prob=0, param2=0},
		{name="air", prob=0, param2=0},
		{name="air", prob=0, param2=0},
		{name="air", prob=0, param2=0},
		{name="air", prob=0, param2=0},
		{name="air", prob=0, param2=0},
		{name="air", prob=0, param2=0},
		{name="air", prob=0, param2=0},
		{name="air", prob=0, param2=0},
		{name="air", prob=0, param2=0},
		{name="air", prob=0, param2=0},
		{name="air", prob=0, param2=0},
		{name="air", prob=0, param2=0},
		{name="air", prob=0, param2=0},
		{name="air", prob=0, param2=0},
		{name="air", prob=0, param2=0},
		{name="air", prob=0, param2=0},
		{name="air", prob=0, param2=0},
		{name="air", prob=0, param2=0},
		{name="air", prob=0, param2=0},
		{name="air", prob=0, param2=0},
		{name="air", prob=0, param2=0},
		{name="air", prob=0, param2=0},
		{name="air", prob=0, param2=0},
		{name="air", prob=0, param2=0},
		{name="air", prob=0, param2=0},
		{name="air", prob=0, param2=0},
		{name="air", prob=0, param2=0},
		{name="air", prob=0, param2=0},
		{name="air", prob=0, param2=0},
		{name="air", prob=0, param2=0},
		{name="air", prob=0, param2=0},
		{name="air", prob=0, param2=0},
		{name="air", prob=0, param2=0},
		{name="air", prob=0, param2=0},
		{name="air", prob=0, param2=0},
		{name="air", prob=0, param2=0},
		{name="air", prob=0, param2=0},
		{name="air", prob=0, param2=0},
		{name="air", prob=0, param2=0},
		{name="air", prob=0, param2=0},
		{name="air", prob=0, param2=0},
		{name="air", prob=0, param2=0},
		{name="air", prob=0, param2=0},
		{name="air", prob=0, param2=0},
		{name="air", prob=0, param2=0},
		{name="air", prob=0, param2=0},
		{name="air", prob=0, param2=0},
		{name="air", prob=0, param2=0},
		{name="air", prob=0, param2=0},
		{name="air", prob=0, param2=0},
		{name="air", prob=0, param2=0},
		{name="air", prob=0, param2=0},
		{name="air", prob=0, param2=0},
		{name="air", prob=0, param2=0},
		{name="air", prob=0, param2=0},
		{name="air", prob=0, param2=0},
		{name="air", prob=0, param2=0},
		{name="air", prob=0, param2=0},
		{name="air", prob=0, param2=0},
		{name="air", prob=0, param2=0},
		{name="air", prob=0, param2=0},
		{name="air", prob=0, param2=0},
		{name="air", prob=0, param2=0},
		{name="air", prob=0, param2=0},
		{name="vlf_mangrove:mangrove_roots", prob=254, param2=1},
		{name="air", prob=0, param2=0},
		{name="air", prob=0, param2=0},
		{name="air", prob=0, param2=0},
		{name="air", prob=0, param2=0},
		{name="air", prob=0, param2=0},
		{name="air", prob=0, param2=0},
		{name="vlf_core:vine", prob=254, param2=4},
		{name="air", prob=0, param2=0},
		{name="vlf_mangrove:mangrove_roots", prob=254, param2=1},
		{name="air", prob=0, param2=0},
		{name="air", prob=0, param2=0},
		{name="air", prob=0, param2=0},
		{name="air", prob=0, param2=0},
		{name="air", prob=0, param2=0},
		{name="air", prob=0, param2=0},
		{name="vlf_core:vine", prob=254, param2=4},
		{name="vlf_trees:leaves_mangrove", prob=254, param2=96},
		{name="vlf_trees:leaves_mangrove", prob=254, param2=64},
		{name="vlf_trees:leaves_mangrove", prob=254, param2=96},
		{name="vlf_core:vine", prob=254, param2=3},
		{name="air", prob=0, param2=0},
		{name="air", prob=0, param2=0},
		{name="air", prob=0, param2=0},
		{name="air", prob=0, param2=0},
		{name="air", prob=0, param2=0},
		{name="air", prob=0, param2=0},
		{name="vlf_trees:leaves_mangrove", prob=254, param2=96},
		{name="vlf_trees:leaves_mangrove", prob=254, param2=128},
		{name="vlf_core:vine", prob=254, param2=3},
		{name="air", prob=0, param2=0},
		{name="air", prob=0, param2=0},
		{name="air", prob=0, param2=0},
		{name="air", prob=0, param2=0},
		{name="air", prob=0, param2=0},
		{name="air", prob=0, param2=0},
		{name="vlf_trees:leaves_mangrove", prob=254, param2=128},
		{name="air", prob=0, param2=0},
		{name="air", prob=0, param2=0},
		{name="air", prob=0, param2=0},
		{name="air", prob=0, param2=0},
		{name="air", prob=0, param2=0},
		{name="air", prob=0, param2=0},
		{name="air", prob=0, param2=0},
		{name="air", prob=0, param2=0},
		{name="air", prob=0, param2=0},
		{name="air", prob=0, param2=0},
		{name="air", prob=0, param2=0},
		{name="air", prob=0, param2=0},
		{name="air", prob=0, param2=0},
		{name="air", prob=0, param2=0},
		{name="air", prob=0, param2=0},
		{name="air", prob=0, param2=0},
		{name="air", prob=0, param2=0},
		{name="air", prob=0, param2=0},
		{name="air", prob=0, param2=0},
		{name="air", prob=0, param2=0},
		{name="air", prob=0, param2=0},
		{name="air", prob=0, param2=0},
		{name="air", prob=0, param2=0},
		{name="air", prob=0, param2=0},
		{name="air", prob=0, param2=0},
		{name="air", prob=0, param2=0},
		{name="air", prob=0, param2=0},
		{name="air", prob=0, param2=0},
		{name="air", prob=0, param2=0},
		{name="air", prob=0, param2=0},
		{name="air", prob=0, param2=0},
		{name="air", prob=0, param2=0},
		{name="air", prob=0, param2=0},
		{name="air", prob=0, param2=0},
		{name="air", prob=0, param2=0},
		{name="air", prob=0, param2=0},
		{name="air", prob=0, param2=0},
		{name="air", prob=0, param2=0},
		{name="air", prob=0, param2=0},
		{name="air", prob=0, param2=0},
		{name="air", prob=0, param2=0},
		{name="air", prob=0, param2=0},
		{name="air", prob=0, param2=0},
		{name="air", prob=0, param2=0},
		{name="air", prob=0, param2=0},
		{name="air", prob=0, param2=0},
		{name="air", prob=0, param2=0},
		{name="air", prob=0, param2=0},
		{name="air", prob=0, param2=0},
		{name="air", prob=0, param2=0},
		{name="air", prob=0, param2=0},
		{name="air", prob=0, param2=0},
		{name="air", prob=0, param2=0},
		{name="air", prob=0, param2=0},
		{name="air", prob=0, param2=0},
		{name="air", prob=0, param2=0},
		{name="air", prob=0, param2=0},
		{name="air", prob=0, param2=0},
		{name="air", prob=0, param2=0},
		{name="air", prob=0, param2=0},
		{name="air", prob=0, param2=0},
		{name="air", prob=0, param2=0},
		{name="vlf_trees:leaves_mangrove", prob=254, param2=128},
		{name="air", prob=0, param2=0},
		{name="air", prob=0, param2=0},
		{name="air", prob=0, param2=0},
		{name="air", prob=0, param2=0},
		{name="air", prob=0, param2=0},
		{name="air", prob=0, param2=0},
		{name="air", prob=0, param2=0},
		{name="air", prob=0, param2=0},
		{name="air", prob=0, param2=0},
		{name="air", prob=0, param2=0},
		{name="air", prob=0, param2=0},
		{name="air", prob=0, param2=0},
		{name="air", prob=0, param2=0},
		{name="air", prob=0, param2=0},
		{name="air", prob=0, param2=0},
		{name="air", prob=0, param2=0},
		{name="air", prob=0, param2=0},
		{name="air", prob=0, param2=0},
		{name="air", prob=0, param2=0},
		{name="air", prob=0, param2=0},
		{name="air", prob=0, param2=0},
		{name="air", prob=0, param2=0},
		{name="air", prob=0, param2=0},
		{name="air", prob=0, param2=0},
		{name="air", prob=0, param2=0},
		{name="air", prob=0, param2=0},
		{name="air", prob=0, param2=0},
		{name="air", prob=0, param2=0},
		{name="air", prob=0, param2=0},
		{name="air", prob=0, param2=0},
		{name="air", prob=0, param2=0},
		{name="air", prob=0, param2=0},
		{name="vlf_core:vine", prob=254, param2=4},
		{name="air", prob=0, param2=0},
		{name="air", prob=0, param2=0},
		{name="vlf_mangrove:mangrove_roots", prob=254, param2=1},
		{name="air", prob=0, param2=0},
		{name="air", prob=0, param2=0},
		{name="air", prob=0, param2=0},
		{name="air", prob=0, param2=0},
		{name="air", prob=0, param2=0},
		{name="vlf_core:vine", prob=254, param2=4},
		{name="vlf_trees:leaves_mangrove", prob=254, param2=96},
		{name="vlf_trees:leaves_mangrove", prob=254, param2=64},
		{name="vlf_trees:tree_mangrove", prob=254, param2=8},
		{name="vlf_trees:leaves_mangrove", prob=254, param2=64},
		{name="vlf_trees:leaves_mangrove", prob=254, param2=96},
		{name="air", prob=0, param2=0},
		{name="air", prob=0, param2=0},
		{name="air", prob=0, param2=0},
		{name="vlf_core:vine", prob=254, param2=4},
		{name="air", prob=0, param2=0},
		{name="vlf_trees:leaves_mangrove", prob=254, param2=96},
		{name="vlf_trees:leaves_mangrove", prob=254, param2=64},
		{name="vlf_trees:leaves_mangrove", prob=254, param2=96},
		{name="air", prob=0, param2=0},
		{name="air", prob=0, param2=0},
		{name="air", prob=0, param2=0},
		{name="air", prob=0, param2=0},
		{name="vlf_core:vine", prob=254, param2=4},
		{name="air", prob=0, param2=0},
		{name="air", prob=0, param2=0},
		{name="vlf_trees:leaves_mangrove", prob=254, param2=96},
		{name="air", prob=0, param2=0},
		{name="air", prob=0, param2=0},
		{name="air", prob=0, param2=0},
		{name="air", prob=0, param2=0},
		{name="air", prob=0, param2=0},
		{name="air", prob=0, param2=0},
		{name="air", prob=0, param2=0},
		{name="air", prob=0, param2=0},
		{name="air", prob=0, param2=0},
		{name="air", prob=0, param2=0},
		{name="air", prob=0, param2=0},
		{name="air", prob=0, param2=0},
		{name="air", prob=0, param2=0},
		{name="air", prob=0, param2=0},
		{name="air", prob=0, param2=0},
		{name="air", prob=0, param2=0},
		{name="air", prob=0, param2=0},
		{name="air", prob=0, param2=0},
		{name="air", prob=0, param2=0},
		{name="air", prob=0, param2=0},
		{name="air", prob=0, param2=0},
		{name="air", prob=0, param2=0},
		{name="air", prob=0, param2=0},
		{name="air", prob=0, param2=0},
		{name="air", prob=0, param2=0},
		{name="air", prob=0, param2=0},
		{name="air", prob=0, param2=0},
		{name="air", prob=0, param2=0},
		{name="air", prob=0, param2=0},
		{name="air", prob=0, param2=0},
		{name="air", prob=0, param2=0},
		{name="air", prob=0, param2=0},
		{name="air", prob=0, param2=0},
		{name="air", prob=0, param2=0},
		{name="air", prob=0, param2=0},
		{name="vlf_trees:leaves_mangrove", prob=254, param2=96},
		{name="air", prob=0, param2=0},
		{name="air", prob=0, param2=0},
		{name="air", prob=0, param2=0},
		{name="air", prob=0, param2=0},
		{name="air", prob=0, param2=0},
		{name="air", prob=0, param2=0},
		{name="air", prob=0, param2=0},
		{name="air", prob=0, param2=0},
		{name="vlf_trees:leaves_mangrove", prob=254, param2=96},
		{name="air", prob=0, param2=0},
		{name="vlf_trees:leaves_mangrove", prob=254, param2=128},
		{name="air", prob=0, param2=0},
		{name="air", prob=0, param2=0},
		{name="air", prob=0, param2=0},
		{name="air", prob=0, param2=0},
		{name="air", prob=0, param2=0},
		{name="air", prob=0, param2=0},
		{name="vlf_trees:leaves_mangrove", prob=254, param2=96},
		{name="vlf_trees:leaves_mangrove", prob=254, param2=96},
		{name="air", prob=0, param2=0},
		{name="air", prob=0, param2=0},
		{name="air", prob=0, param2=0},
		{name="air", prob=0, param2=0},
		{name="air", prob=0, param2=0},
		{name="air", prob=0, param2=0},
		{name="air", prob=0, param2=0},
		{name="vlf_trees:leaves_mangrove", prob=254, param2=96},
		{name="air", prob=0, param2=0},
		{name="air", prob=0, param2=0},
		{name="air", prob=0, param2=0},
		{name="air", prob=0, param2=0},
		{name="air", prob=0, param2=0},
		{name="air", prob=0, param2=0},
		{name="air", prob=0, param2=0},
		{name="vlf_trees:leaves_mangrove", prob=254, param2=128},
		{name="vlf_trees:leaves_mangrove", prob=254, param2=96},
		{name="air", prob=0, param2=0},
		{name="air", prob=0, param2=0},
		{name="air", prob=0, param2=0},
		{name="air", prob=0, param2=0},
		{name="air", prob=0, param2=0},
		{name="air", prob=0, param2=0},
		{name="air", prob=0, param2=0},
		{name="air", prob=0, param2=0},
		{name="air", prob=0, param2=0},
		{name="air", prob=0, param2=0},
		{name="air", prob=0, param2=0},
		{name="air", prob=0, param2=0},
		{name="air", prob=0, param2=0},
		{name="air", prob=0, param2=0},
		{name="air", prob=0, param2=0},
		{name="air", prob=0, param2=0},
		{name="vlf_mangrove:mangrove_roots", prob=254, param2=1},
		{name="vlf_mangrove:mangrove_roots", prob=254, param2=1},
		{name="air", prob=0, param2=0},
		{name="air", prob=0, param2=0},
		{name="air", prob=0, param2=0},
		{name="air", prob=0, param2=0},
		{name="air", prob=0, param2=0},
		{name="air", prob=0, param2=0},
		{name="air", prob=0, param2=0},
		{name="vlf_mangrove:mangrove_roots", prob=254, param2=1},
		{name="air", prob=0, param2=0},
		{name="air", prob=0, param2=0},
		{name="air", prob=0, param2=0},
		{name="air", prob=0, param2=0},
		{name="air", prob=0, param2=0},
		{name="vlf_core:vine", prob=254, param2=2},
		{name="air", prob=0, param2=0},
		{name="vlf_trees:leaves_mangrove", prob=254, param2=96},
		{name="vlf_trees:leaves_mangrove", prob=254, param2=64},
		{name="vlf_trees:tree_mangrove", prob=254, param2=8},
		{name="vlf_trees:leaves_mangrove", prob=254, param2=64},
		{name="vlf_trees:leaves_mangrove", prob=254, param2=64},
		{name="vlf_trees:leaves_mangrove", prob=254, param2=96},
		{name="air", prob=0, param2=0},
		{name="vlf_core:vine", prob=254, param2=2},
		{name="air", prob=0, param2=0},
		{name="vlf_trees:leaves_mangrove", prob=254, param2=64},
		{name="vlf_trees:leaves_mangrove", prob=254, param2=64},
		{name="vlf_trees:leaves_mangrove", prob=254, param2=64},
		{name="air", prob=0, param2=0},
		{name="vlf_trees:leaves_mangrove", prob=254, param2=96},
		{name="vlf_core:vine", prob=254, param2=3},
		{name="air", prob=0, param2=0},
		{name="vlf_core:vine", prob=254, param2=2},
		{name="vlf_trees:leaves_mangrove", prob=254, param2=128},
		{name="vlf_trees:leaves_mangrove", prob=254, param2=96},
		{name="vlf_trees:leaves_mangrove", prob=254, param2=96},
		{name="vlf_trees:leaves_mangrove", prob=254, param2=64},
		{name="vlf_trees:leaves_mangrove", prob=254, param2=96},
		{name="air", prob=0, param2=0},
		{name="air", prob=0, param2=0},
		{name="air", prob=0, param2=0},
		{name="air", prob=0, param2=0},
		{name="air", prob=0, param2=0},
		{name="vlf_trees:leaves_mangrove", prob=254, param2=128},
		{name="vlf_trees:leaves_mangrove", prob=254, param2=96},
		{name="vlf_trees:leaves_mangrove", prob=254, param2=64},
		{name="air", prob=0, param2=0},
		{name="air", prob=0, param2=0},
		{name="air", prob=0, param2=0},
		{name="air", prob=0, param2=0},
		{name="air", prob=0, param2=0},
		{name="air", prob=0, param2=0},
		{name="vlf_trees:leaves_mangrove", prob=254, param2=128},
		{name="vlf_trees:leaves_mangrove", prob=254, param2=96},
		{name="vlf_trees:leaves_mangrove", prob=254, param2=64},
		{name="air", prob=0, param2=0},
		{name="air", prob=0, param2=0},
		{name="air", prob=0, param2=0},
		{name="air", prob=0, param2=0},
		{name="air", prob=0, param2=0},
		{name="air", prob=0, param2=0},
		{name="air", prob=0, param2=0},
		{name="air", prob=0, param2=0},
		{name="vlf_trees:leaves_mangrove", prob=254, param2=64},
		{name="air", prob=0, param2=0},
		{name="air", prob=0, param2=0},
		{name="air", prob=0, param2=0},
		{name="air", prob=0, param2=0},
		{name="air", prob=0, param2=0},
		{name="air", prob=0, param2=0},
		{name="air", prob=0, param2=0},
		{name="vlf_trees:leaves_mangrove", prob=254, param2=96},
		{name="vlf_trees:leaves_mangrove", prob=254, param2=64},
		{name="air", prob=0, param2=0},
		{name="air", prob=0, param2=0},
		{name="air", prob=0, param2=0},
		{name="air", prob=0, param2=0},
		{name="air", prob=0, param2=0},
		{name="air", prob=0, param2=0},
		{name="air", prob=0, param2=0},
		{name="air", prob=0, param2=0},
		{name="vlf_trees:leaves_mangrove", prob=254, param2=64},
		{name="vlf_trees:leaves_mangrove", prob=254, param2=96},
		{name="vlf_trees:leaves_mangrove", prob=254, param2=96},
		{name="air", prob=0, param2=0},
		{name="air", prob=0, param2=0},
		{name="air", prob=0, param2=0},
		{name="air", prob=0, param2=0},
		{name="air", prob=0, param2=0},
		{name="vlf_trees:leaves_mangrove", prob=254, param2=96},
		{name="vlf_trees:leaves_mangrove", prob=254, param2=64},
		{name="vlf_trees:leaves_mangrove", prob=254, param2=64},
		{name="vlf_trees:leaves_mangrove", prob=254, param2=64},
		{name="air", prob=0, param2=0},
		{name="air", prob=0, param2=0},
		{name="air", prob=0, param2=0},
		{name="air", prob=0, param2=0},
		{name="air", prob=0, param2=0},
		{name="vlf_trees:leaves_mangrove", prob=254, param2=96},
		{name="vlf_trees:leaves_mangrove", prob=254, param2=64},
		{name="vlf_trees:leaves_mangrove", prob=254, param2=96},
		{name="air", prob=0, param2=0},
		{name="air", prob=0, param2=0},
		{name="air", prob=0, param2=0},
		{name="air", prob=0, param2=0},
		{name="air", prob=0, param2=0},
		{name="air", prob=0, param2=0},
		{name="vlf_trees:leaves_mangrove", prob=254, param2=96},
		{name="vlf_trees:leaves_mangrove", prob=254, param2=64},
		{name="air", prob=0, param2=0},
		{name="air", prob=0, param2=0},
		{name="air", prob=0, param2=0},
		{name="air", prob=0, param2=0},
		{name="air", prob=0, param2=0},
		{name="air", prob=0, param2=0},
		{name="air", prob=0, param2=0},
		{name="air", prob=0, param2=0},
		{name="vlf_trees:leaves_mangrove", prob=254, param2=96},
		{name="air", prob=0, param2=0},
		{name="air", prob=0, param2=0},
		{name="air", prob=0, param2=0},
		{name="air", prob=0, param2=0},
		{name="air", prob=0, param2=0},
		{name="vlf_mangrove:mangrove_roots", prob=254, param2=1},
		{name="air", prob=0, param2=0},
		{name="air", prob=0, param2=0},
		{name="vlf_trees:tree_mangrove", prob=254, param2=2},
		{name="vlf_mangrove:mangrove_roots", prob=254, param2=1},
		{name="air", prob=0, param2=0},
		{name="air", prob=0, param2=0},
		{name="air", prob=0, param2=0},
		{name="air", prob=0, param2=0},
		{name="vlf_mangrove:mangrove_roots", prob=254, param2=1},
		{name="vlf_trees:leaves_mangrove", prob=254, param2=96},
		{name="vlf_mangrove:mangrove_roots", prob=254, param2=1},
		{name="vlf_trees:tree_mangrove", prob=254, param2=2},
		{name="vlf_trees:leaves_mangrove", prob=254, param2=64},
		{name="vlf_trees:leaves_mangrove", prob=254, param2=64},
		{name="vlf_trees:leaves_mangrove", prob=254, param2=96},
		{name="air", prob=0, param2=0},
		{name="air", prob=0, param2=0},
		{name="vlf_mangrove:mangrove_roots", prob=254, param2=1},
		{name="vlf_trees:leaves_mangrove", prob=254, param2=64},
		{name="vlf_trees:leaves_mangrove", prob=254, param2=64},
		{name="vlf_trees:tree_mangrove", prob=254, param2=2},
		{name="vlf_trees:tree_mangrove", prob=254, param2=18},
		{name="vlf_trees:tree_mangrove", prob=254, param2=18},
		{name="vlf_trees:leaves_mangrove", prob=254, param2=64},
		{name="vlf_core:vine", prob=254, param2=3},
		{name="air", prob=0, param2=0},
		{name="vlf_trees:leaves_mangrove", prob=254, param2=64},
		{name="vlf_trees:tree_mangrove", prob=254, param2=18},
		{name="vlf_trees:tree_mangrove", prob=254, param2=18},
		{name="vlf_trees:tree_mangrove", prob=254, param2=2},
		{name="vlf_trees:leaves_mangrove", prob=254, param2=64},
		{name="vlf_trees:leaves_mangrove", prob=254, param2=64},
		{name="vlf_trees:leaves_mangrove", prob=254, param2=96},
		{name="air", prob=0, param2=0},
		{name="air", prob=0, param2=0},
		{name="vlf_trees:leaves_mangrove", prob=254, param2=96},
		{name="vlf_trees:leaves_mangrove", prob=254, param2=64},
		{name="vlf_trees:leaves_mangrove", prob=254, param2=64},
		{name="vlf_trees:tree_mangrove", prob=254, param2=0},
		{name="vlf_trees:leaves_mangrove", prob=254, param2=64},
		{name="vlf_trees:leaves_mangrove", prob=254, param2=96},
		{name="air", prob=0, param2=0},
		{name="air", prob=0, param2=0},
		{name="air", prob=0, param2=0},
		{name="vlf_trees:leaves_mangrove", prob=254, param2=128},
		{name="vlf_trees:leaves_mangrove", prob=254, param2=96},
		{name="vlf_trees:leaves_mangrove", prob=254, param2=64},
		{name="vlf_trees:tree_mangrove", prob=254, param2=0},
		{name="air", prob=0, param2=0},
		{name="air", prob=0, param2=0},
		{name="air", prob=0, param2=0},
		{name="air", prob=0, param2=0},
		{name="air", prob=0, param2=0},
		{name="air", prob=0, param2=0},
		{name="vlf_trees:leaves_mangrove", prob=254, param2=96},
		{name="vlf_trees:leaves_mangrove", prob=254, param2=64},
		{name="vlf_trees:tree_mangrove", prob=254, param2=0},
		{name="vlf_beehives:bee_nest_5", prob=254, param2=3},
		{name="air", prob=0, param2=0},
		{name="air", prob=0, param2=0},
		{name="air", prob=0, param2=0},
		{name="air", prob=0, param2=0},
		{name="air", prob=0, param2=0},
		{name="air", prob=0, param2=0},
		{name="vlf_trees:leaves_mangrove", prob=254, param2=64},
		{name="vlf_trees:tree_mangrove", prob=254, param2=0},
		{name="vlf_trees:tree_mangrove", prob=254, param2=12},
		{name="air", prob=0, param2=0},
		{name="air", prob=0, param2=0},
		{name="air", prob=0, param2=0},
		{name="air", prob=0, param2=0},
		{name="air", prob=0, param2=0},
		{name="vlf_trees:leaves_mangrove", prob=254, param2=96},
		{name="vlf_trees:leaves_mangrove", prob=254, param2=64},
		{name="vlf_trees:tree_mangrove", prob=254, param2=0},
		{name="vlf_trees:leaves_mangrove", prob=254, param2=64},
		{name="air", prob=0, param2=0},
		{name="air", prob=0, param2=0},
		{name="air", prob=0, param2=0},
		{name="air", prob=0, param2=0},
		{name="air", prob=0, param2=0},
		{name="air", prob=0, param2=0},
		{name="vlf_trees:leaves_mangrove", prob=254, param2=64},
		{name="vlf_trees:tree_mangrove", prob=254, param2=0},
		{name="vlf_trees:leaves_mangrove", prob=254, param2=64},
		{name="vlf_trees:leaves_mangrove", prob=254, param2=64},
		{name="vlf_trees:leaves_mangrove", prob=254, param2=96},
		{name="air", prob=0, param2=0},
		{name="air", prob=0, param2=0},
		{name="air", prob=0, param2=0},
		{name="vlf_trees:leaves_mangrove", prob=254, param2=96},
		{name="vlf_trees:leaves_mangrove", prob=254, param2=64},
		{name="vlf_trees:tree_mangrove", prob=254, param2=0},
		{name="vlf_trees:tree_mangrove", prob=254, param2=12},
		{name="vlf_trees:tree_mangrove", prob=254, param2=12},
		{name="vlf_trees:leaves_mangrove", prob=254, param2=64},
		{name="air", prob=0, param2=0},
		{name="air", prob=0, param2=0},
		{name="air", prob=0, param2=0},
		{name="air", prob=0, param2=0},
		{name="vlf_trees:leaves_mangrove", prob=254, param2=64},
		{name="vlf_trees:tree_mangrove", prob=254, param2=0},
		{name="vlf_trees:leaves_mangrove", prob=254, param2=64},
		{name="vlf_trees:leaves_mangrove", prob=254, param2=64},
		{name="vlf_trees:leaves_mangrove", prob=254, param2=96},
		{name="air", prob=0, param2=0},
		{name="air", prob=0, param2=0},
		{name="air", prob=0, param2=0},
		{name="air", prob=0, param2=0},
		{name="vlf_trees:leaves_mangrove", prob=254, param2=64},
		{name="vlf_trees:tree_mangrove", prob=254, param2=0},
		{name="vlf_trees:leaves_mangrove", prob=254, param2=64},
		{name="air", prob=0, param2=0},
		{name="air", prob=0, param2=0},
		{name="air", prob=0, param2=0},
		{name="air", prob=0, param2=0},
		{name="air", prob=0, param2=0},
		{name="air", prob=0, param2=0},
		{name="air", prob=0, param2=0},
		{name="vlf_trees:leaves_mangrove", prob=254, param2=64},
		{name="air", prob=0, param2=0},
		{name="air", prob=0, param2=0},
		{name="air", prob=0, param2=0},
		{name="air", prob=0, param2=0},
		{name="air", prob=0, param2=0},
		{name="air", prob=0, param2=0},
		{name="air", prob=0, param2=0},
		{name="air", prob=0, param2=0},
		{name="air", prob=0, param2=0},
		{name="air", prob=0, param2=0},
		{name="air", prob=0, param2=0},
		{name="air", prob=0, param2=0},
		{name="vlf_core:vine", prob=254, param2=3},
		{name="air", prob=0, param2=0},
		{name="air", prob=0, param2=0},
		{name="vlf_trees:leaves_mangrove", prob=254, param2=128},
		{name="vlf_trees:leaves_mangrove", prob=254, param2=96},
		{name="vlf_trees:leaves_mangrove", prob=254, param2=64},
		{name="vlf_trees:leaves_mangrove", prob=254, param2=96},
		{name="vlf_trees:leaves_mangrove", prob=254, param2=96},
		{name="vlf_trees:leaves_mangrove", prob=254, param2=128},
		{name="vlf_core:vine", prob=254, param2=3},
		{name="vlf_core:vine", prob=254, param2=2},
		{name="air", prob=0, param2=0},
		{name="vlf_trees:leaves_mangrove", prob=254, param2=96},
		{name="vlf_trees:leaves_mangrove", prob=254, param2=96},
		{name="vlf_trees:leaves_mangrove", prob=254, param2=64},
		{name="vlf_trees:leaves_mangrove", prob=254, param2=64},
		{name="vlf_trees:leaves_mangrove", prob=254, param2=64},
		{name="air", prob=0, param2=0},
		{name="air", prob=0, param2=0},
		{name="vlf_core:vine", prob=254, param2=2},
		{name="vlf_trees:leaves_mangrove", prob=254, param2=96},
		{name="vlf_trees:leaves_mangrove", prob=254, param2=64},
		{name="vlf_trees:leaves_mangrove", prob=254, param2=64},
		{name="vlf_trees:leaves_mangrove", prob=254, param2=64},
		{name="vlf_trees:leaves_mangrove", prob=254, param2=96},
		{name="vlf_trees:leaves_mangrove", prob=254, param2=96},
		{name="vlf_trees:leaves_mangrove", prob=254, param2=128},
		{name="vlf_core:vine", prob=254, param2=3},
		{name="vlf_core:vine", prob=254, param2=2},
		{name="vlf_trees:leaves_mangrove", prob=254, param2=128},
		{name="vlf_trees:leaves_mangrove", prob=254, param2=96},
		{name="vlf_trees:leaves_mangrove", prob=254, param2=64},
		{name="vlf_trees:tree_mangrove", prob=254, param2=8},
		{name="vlf_trees:leaves_mangrove", prob=254, param2=64},
		{name="vlf_trees:leaves_mangrove", prob=254, param2=96},
		{name="air", prob=0, param2=0},
		{name="air", prob=0, param2=0},
		{name="air", prob=0, param2=0},
		{name="vlf_trees:leaves_mangrove", prob=254, param2=160},
		{name="vlf_trees:leaves_mangrove", prob=254, param2=128},
		{name="vlf_trees:leaves_mangrove", prob=254, param2=96},
		{name="vlf_trees:leaves_mangrove", prob=254, param2=64},
		{name="air", prob=0, param2=0},
		{name="air", prob=0, param2=0},
		{name="air", prob=0, param2=0},
		{name="air", prob=0, param2=0},
		{name="air", prob=0, param2=0},
		{name="air", prob=0, param2=0},
		{name="air", prob=0, param2=0},
		{name="vlf_trees:leaves_mangrove", prob=254, param2=96},
		{name="vlf_trees:leaves_mangrove", prob=254, param2=64},
		{name="air", prob=0, param2=0},
		{name="air", prob=0, param2=0},
		{name="air", prob=0, param2=0},
		{name="air", prob=0, param2=0},
		{name="air", prob=0, param2=0},
		{name="air", prob=0, param2=0},
		{name="vlf_trees:leaves_mangrove", prob=254, param2=128},
		{name="vlf_trees:leaves_mangrove", prob=254, param2=96},
		{name="vlf_trees:leaves_mangrove", prob=254, param2=64},
		{name="vlf_trees:leaves_mangrove", prob=254, param2=64},
		{name="air", prob=0, param2=0},
		{name="air", prob=0, param2=0},
		{name="air", prob=0, param2=0},
		{name="air", prob=0, param2=0},
		{name="air", prob=0, param2=0},
		{name="air", prob=0, param2=0},
		{name="vlf_trees:leaves_mangrove", prob=254, param2=96},
		{name="vlf_trees:leaves_mangrove", prob=254, param2=64},
		{name="air", prob=0, param2=0},
		{name="air", prob=0, param2=0},
		{name="air", prob=0, param2=0},
		{name="air", prob=0, param2=0},
		{name="air", prob=0, param2=0},
		{name="air", prob=0, param2=0},
		{name="air", prob=0, param2=0},
		{name="air", prob=0, param2=0},
		{name="vlf_trees:leaves_mangrove", prob=254, param2=64},
		{name="vlf_trees:leaves_mangrove", prob=254, param2=96},
		{name="vlf_trees:leaves_mangrove", prob=254, param2=96},
		{name="air", prob=0, param2=0},
		{name="air", prob=0, param2=0},
		{name="air", prob=0, param2=0},
		{name="air", prob=0, param2=0},
		{name="air", prob=0, param2=0},
		{name="vlf_trees:leaves_mangrove", prob=254, param2=96},
		{name="vlf_trees:leaves_mangrove", prob=254, param2=64},
		{name="vlf_trees:leaves_mangrove", prob=254, param2=64},
		{name="vlf_trees:leaves_mangrove", prob=254, param2=64},
		{name="air", prob=0, param2=0},
		{name="air", prob=0, param2=0},
		{name="air", prob=0, param2=0},
		{name="air", prob=0, param2=0},
		{name="vlf_trees:leaves_mangrove", prob=254, param2=128},
		{name="vlf_trees:leaves_mangrove", prob=254, param2=96},
		{name="vlf_trees:leaves_mangrove", prob=254, param2=64},
		{name="vlf_trees:leaves_mangrove", prob=254, param2=96},
		{name="air", prob=0, param2=0},
		{name="air", prob=0, param2=0},
		{name="air", prob=0, param2=0},
		{name="air", prob=0, param2=0},
		{name="air", prob=0, param2=0},
		{name="vlf_trees:leaves_mangrove", prob=254, param2=128},
		{name="vlf_trees:leaves_mangrove", prob=254, param2=96},
		{name="vlf_trees:leaves_mangrove", prob=254, param2=64},
		{name="vlf_trees:leaves_mangrove", prob=254, param2=96},
		{name="air", prob=0, param2=0},
		{name="air", prob=0, param2=0},
		{name="air", prob=0, param2=0},
		{name="air", prob=0, param2=0},
		{name="air", prob=0, param2=0},
		{name="air", prob=0, param2=0},
		{name="air", prob=0, param2=0},
		{name="vlf_trees:leaves_mangrove", prob=254, param2=96},
		{name="air", prob=0, param2=0},
		{name="air", prob=0, param2=0},
		{name="air", prob=0, param2=0},
		{name="air", prob=0, param2=0},
		{name="air", prob=0, param2=0},
		{name="air", prob=0, param2=0},
		{name="air", prob=0, param2=0},
		{name="air", prob=0, param2=0},
		{name="air", prob=0, param2=0},
		{name="air", prob=0, param2=0},
		{name="air", prob=0, param2=0},
		{name="air", prob=0, param2=0},
		{name="air", prob=0, param2=0},
		{name="vlf_core:vine", prob=254, param2=2},
		{name="vlf_trees:leaves_mangrove", prob=254, param2=192},
		{name="air", prob=0, param2=0},
		{name="air", prob=0, param2=0},
		{name="vlf_trees:leaves_mangrove", prob=254, param2=96},
		{name="air", prob=0, param2=0},
		{name="air", prob=0, param2=0},
		{name="air", prob=0, param2=0},
		{name="air", prob=0, param2=0},
		{name="vlf_core:vine", prob=254, param2=2},
		{name="vlf_trees:leaves_mangrove", prob=254, param2=160},
		{name="vlf_trees:leaves_mangrove", prob=254, param2=128},
		{name="vlf_trees:leaves_mangrove", prob=254, param2=128},
		{name="vlf_trees:leaves_mangrove", prob=254, param2=96},
		{name="vlf_trees:leaves_mangrove", prob=254, param2=96},
		{name="vlf_trees:leaves_mangrove", prob=254, param2=96},
		{name="vlf_trees:leaves_mangrove", prob=254, param2=128},
		{name="vlf_core:vine", prob=254, param2=3},
		{name="air", prob=0, param2=0},
		{name="vlf_trees:leaves_mangrove", prob=254, param2=128},
		{name="vlf_trees:leaves_mangrove", prob=254, param2=96},
		{name="vlf_trees:leaves_mangrove", prob=254, param2=96},
		{name="vlf_trees:leaves_mangrove", prob=254, param2=96},
		{name="vlf_trees:leaves_mangrove", prob=254, param2=128},
		{name="vlf_trees:leaves_mangrove", prob=254, param2=128},
		{name="air", prob=0, param2=0},
		{name="air", prob=0, param2=0},
		{name="air", prob=0, param2=0},
		{name="vlf_trees:leaves_mangrove", prob=254, param2=160},
		{name="vlf_trees:leaves_mangrove", prob=254, param2=128},
		{name="vlf_trees:leaves_mangrove", prob=254, param2=96},
		{name="vlf_trees:leaves_mangrove", prob=254, param2=64},
		{name="vlf_trees:leaves_mangrove", prob=254, param2=96},
		{name="air", prob=0, param2=0},
		{name="air", prob=0, param2=0},
		{name="air", prob=0, param2=0},
		{name="air", prob=0, param2=0},
		{name="air", prob=0, param2=0},
		{name="vlf_trees:leaves_mangrove", prob=254, param2=160},
		{name="vlf_trees:leaves_mangrove", prob=254, param2=128},
		{name="vlf_trees:leaves_mangrove", prob=254, param2=96},
		{name="vlf_trees:leaves_mangrove", prob=254, param2=128},
		{name="air", prob=0, param2=0},
		{name="air", prob=0, param2=0},
		{name="air", prob=0, param2=0},
		{name="air", prob=0, param2=0},
		{name="air", prob=0, param2=0},
		{name="air", prob=0, param2=0},
		{name="vlf_trees:leaves_mangrove", prob=254, param2=128},
		{name="air", prob=0, param2=0},
		{name="air", prob=0, param2=0},
		{name="air", prob=0, param2=0},
		{name="air", prob=0, param2=0},
		{name="air", prob=0, param2=0},
		{name="air", prob=0, param2=0},
		{name="air", prob=0, param2=0},
		{name="air", prob=0, param2=0},
		{name="air", prob=0, param2=0},
		{name="air", prob=0, param2=0},
		{name="air", prob=0, param2=0},
		{name="air", prob=0, param2=0},
		{name="air", prob=0, param2=0},
		{name="air", prob=0, param2=0},
		{name="air", prob=0, param2=0},
		{name="air", prob=0, param2=0},
		{name="air", prob=0, param2=0},
		{name="vlf_trees:leaves_mangrove", prob=254, param2=128},
		{name="vlf_trees:leaves_mangrove", prob=254, param2=96},
		{name="vlf_trees:leaves_mangrove", prob=254, param2=128},
		{name="air", prob=0, param2=0},
		{name="air", prob=0, param2=0},
		{name="air", prob=0, param2=0},
		{name="air", prob=0, param2=0},
		{name="air", prob=0, param2=0},
		{name="air", prob=0, param2=0},
		{name="air", prob=0, param2=0},
		{name="air", prob=0, param2=0},
		{name="air", prob=0, param2=0},
		{name="air", prob=0, param2=0},
		{name="air", prob=0, param2=0},
		{name="air", prob=0, param2=0},
		{name="air", prob=0, param2=0},
		{name="air", prob=0, param2=0},
		{name="air", prob=0, param2=0},
		{name="vlf_trees:leaves_mangrove", prob=254, param2=128},
		{name="vlf_trees:leaves_mangrove", prob=254, param2=96},
		{name="air", prob=0, param2=0},
		{name="air", prob=0, param2=0},
		{name="air", prob=0, param2=0},
		{name="air", prob=0, param2=0},
		{name="air", prob=0, param2=0},
		{name="air", prob=0, param2=0},
		{name="air", prob=0, param2=0},
		{name="vlf_trees:leaves_mangrove", prob=254, param2=128},
		{name="air", prob=0, param2=0},
		{name="air", prob=0, param2=0},
		{name="air", prob=0, param2=0},
		{name="air", prob=0, param2=0},
		{name="air", prob=0, param2=0},
		{name="air", prob=0, param2=0},
		{name="air", prob=0, param2=0},
		{name="air", prob=0, param2=0},
		{name="vlf_trees:leaves_mangrove", prob=254, param2=128},
		{name="vlf_trees:leaves_mangrove", prob=254, param2=96},
		{name="air", prob=0, param2=0},
		{name="air", prob=0, param2=0},
		{name="air", prob=0, param2=0},
		{name="air", prob=0, param2=0},
		{name="air", prob=0, param2=0},
		{name="air", prob=0, param2=0},
		{name="air", prob=0, param2=0},
		{name="air", prob=0, param2=0},
		{name="air", prob=0, param2=0},
		{name="air", prob=0, param2=0},
		{name="air", prob=0, param2=0},
		{name="air", prob=0, param2=0},
		{name="air", prob=0, param2=0},
		{name="air", prob=0, param2=0},
		{name="air", prob=0, param2=0},
		{name="air", prob=0, param2=0},
		{name="air", prob=0, param2=0},
		{name="air", prob=0, param2=0},
		{name="air", prob=0, param2=0},
		{name="air", prob=0, param2=0},
		{name="air", prob=0, param2=0},
		{name="air", prob=0, param2=0},
		{name="air", prob=0, param2=0},
		{name="air", prob=0, param2=0},
		{name="air", prob=0, param2=0},
		{name="air", prob=0, param2=0},
		{name="air", prob=0, param2=0},
		{name="air", prob=0, param2=0},
		{name="air", prob=0, param2=0},
		{name="air", prob=0, param2=0},
		{name="air", prob=0, param2=0},
		{name="air", prob=0, param2=0},
		{name="air", prob=0, param2=0},
		{name="air", prob=0, param2=0},
		{name="vlf_trees:leaves_mangrove", prob=254, param2=160},
		{name="vlf_trees:leaves_mangrove", prob=254, param2=128},
		{name="vlf_trees:leaves_mangrove", prob=254, param2=128},
		{name="vlf_core:vine", prob=254, param2=3},
		{name="vlf_core:vine", prob=254, param2=5},
		{name="air", prob=0, param2=0},
		{name="air", prob=0, param2=0},
		{name="air", prob=0, param2=0},
		{name="vlf_trees:leaves_mangrove", prob=254, param2=128},
		{name="vlf_trees:leaves_mangrove", prob=254, param2=128},
		{name="vlf_trees:leaves_mangrove", prob=254, param2=128},
		{name="vlf_trees:leaves_mangrove", prob=254, param2=160},
		{name="air", prob=0, param2=0},
		{name="air", prob=0, param2=0},
		{name="air", prob=0, param2=0},
		{name="air", prob=0, param2=0},
		{name="air", prob=0, param2=0},
		{name="vlf_trees:leaves_mangrove", prob=254, param2=160},
		{name="vlf_trees:leaves_mangrove", prob=254, param2=128},
		{name="vlf_trees:leaves_mangrove", prob=254, param2=96},
		{name="air", prob=0, param2=0},
		{name="air", prob=0, param2=0},
		{name="air", prob=0, param2=0},
		{name="air", prob=0, param2=0},
		{name="air", prob=0, param2=0},
		{name="air", prob=0, param2=0},
		{name="air", prob=0, param2=0},
		{name="vlf_trees:leaves_mangrove", prob=254, param2=160},
		{name="air", prob=0, param2=0},
		{name="air", prob=0, param2=0},
		{name="air", prob=0, param2=0},
		{name="air", prob=0, param2=0},
		{name="air", prob=0, param2=0},
		{name="air", prob=0, param2=0},
		{name="air", prob=0, param2=0},
		{name="air", prob=0, param2=0},
		{name="air", prob=0, param2=0},
		{name="air", prob=0, param2=0},
		{name="air", prob=0, param2=0},
		{name="air", prob=0, param2=0},
		{name="air", prob=0, param2=0},
		{name="air", prob=0, param2=0},
		{name="air", prob=0, param2=0},
		{name="air", prob=0, param2=0},
		{name="air", prob=0, param2=0},
		{name="air", prob=0, param2=0},
		{name="air", prob=0, param2=0},
		{name="air", prob=0, param2=0},
		{name="air", prob=0, param2=0},
		{name="air", prob=0, param2=0},
		{name="air", prob=0, param2=0},
		{name="air", prob=0, param2=0},
		{name="air", prob=0, param2=0},
		{name="air", prob=0, param2=0},
		{name="air", prob=0, param2=0},
		{name="vlf_trees:leaves_mangrove", prob=254, param2=128},
		{name="air", prob=0, param2=0},
		{name="air", prob=0, param2=0},
		{name="air", prob=0, param2=0},
		{name="air", prob=0, param2=0},
		{name="air", prob=0, param2=0},
		{name="air", prob=0, param2=0},
		{name="air", prob=0, param2=0},
		{name="air", prob=0, param2=0},
		{name="air", prob=0, param2=0},
		{name="air", prob=0, param2=0},
		{name="air", prob=0, param2=0},
		{name="air", prob=0, param2=0},
		{name="air", prob=0, param2=0},
		{name="air", prob=0, param2=0},
		{name="air", prob=0, param2=0},
		{name="air", prob=0, param2=0},
		{name="vlf_trees:leaves_mangrove", prob=254, param2=160},
		{name="air", prob=0, param2=0},
		{name="air", prob=0, param2=0},
		{name="air", prob=0, param2=0},
		{name="air", prob=0, param2=0},
		{name="air", prob=0, param2=0},
		{name="air", prob=0, param2=0},
		{name="air", prob=0, param2=0},
		{name="air", prob=0, param2=0},
		{name="air", prob=0, param2=0},
		{name="air", prob=0, param2=0},
		{name="air", prob=0, param2=0},
		{name="air", prob=0, param2=0},
		{name="air", prob=0, param2=0},
		{name="air", prob=0, param2=0},
		{name="air", prob=0, param2=0},
		{name="air", prob=0, param2=0},
		{name="air", prob=0, param2=0},
		{name="air", prob=0, param2=0},
		{name="air", prob=0, param2=0},
		{name="air", prob=0, param2=0},
		{name="air", prob=0, param2=0},
		{name="air", prob=0, param2=0},
		{name="air", prob=0, param2=0},
		{name="air", prob=0, param2=0},
		{name="air", prob=0, param2=0},
		{name="air", prob=0, param2=0},
		{name="air", prob=0, param2=0},
		{name="air", prob=0, param2=0},
		{name="air", prob=0, param2=0},
		{name="air", prob=0, param2=0},
		{name="air", prob=0, param2=0},
		{name="air", prob=0, param2=0},
		{name="air", prob=0, param2=0},
		{name="air", prob=0, param2=0},
		{name="air", prob=0, param2=0},
		{name="vlf_mangrove:mangrove_roots", prob=254, param2=1},
		{name="air", prob=0, param2=0},
		{name="air", prob=0, param2=0},
		{name="air", prob=0, param2=0},
		{name="air", prob=0, param2=0},
		{name="air", prob=0, param2=0},
		{name="air", prob=0, param2=0},
		{name="air", prob=0, param2=0},
		{name="air", prob=0, param2=0},
		{name="vlf_mangrove:mangrove_roots", prob=254, param2=1},
		{name="air", prob=0, param2=0},
		{name="air", prob=0, param2=0},
		{name="air", prob=0, param2=0},
		{name="air", prob=0, param2=0},
		{name="air", prob=0, param2=0},
		{name="air", prob=0, param2=0},
		{name="air", prob=0, param2=0},
		{name="vlf_core:vine", prob=254, param2=5},
		{name="vlf_mangrove:mangrove_roots", prob=254, param2=1},
		{name="air", prob=0, param2=0},
		{name="air", prob=0, param2=0},
		{name="air", prob=0, param2=0},
		{name="air", prob=0, param2=0},
		{name="air", prob=0, param2=0},
		{name="air", prob=0, param2=0},
		{name="air", prob=0, param2=0},
		{name="vlf_core:vine", prob=254, param2=5},
		{name="vlf_trees:leaves_mangrove", prob=254, param2=160},
		{name="vlf_trees:leaves_mangrove", prob=254, param2=160},
		{name="air", prob=0, param2=0},
		{name="air", prob=0, param2=0},
		{name="air", prob=0, param2=0},
		{name="air", prob=0, param2=0},
		{name="air", prob=0, param2=0},
		{name="air", prob=0, param2=0},
		{name="air", prob=0, param2=0},
		{name="vlf_trees:leaves_mangrove", prob=254, param2=160},
		{name="air", prob=0, param2=0},
		{name="air", prob=0, param2=0},
		{name="air", prob=0, param2=0},
		{name="air", prob=0, param2=0},
		{name="air", prob=0, param2=0},
		{name="air", prob=0, param2=0},
		{name="air", prob=0, param2=0},
		{name="air", prob=0, param2=0},
		{name="air", prob=0, param2=0},
		{name="air", prob=0, param2=0},
		{name="air", prob=0, param2=0},
		{name="air", prob=0, param2=0},
		{name="air", prob=0, param2=0},
		{name="air", prob=0, param2=0},
		{name="air", prob=0, param2=0},
		{name="air", prob=0, param2=0},
		{name="air", prob=0, param2=0},
		{name="air", prob=0, param2=0},
		{name="air", prob=0, param2=0},
		{name="air", prob=0, param2=0},
		{name="air", prob=0, param2=0},
		{name="air", prob=0, param2=0},
		{name="air", prob=0, param2=0},
		{name="air", prob=0, param2=0},
		{name="air", prob=0, param2=0},
		{name="air", prob=0, param2=0},
		{name="air", prob=0, param2=0},
		{name="air", prob=0, param2=0},
		{name="air", prob=0, param2=0},
		{name="air", prob=0, param2=0},
		{name="air", prob=0, param2=0},
		{name="air", prob=0, param2=0},
		{name="air", prob=0, param2=0},
		{name="air", prob=0, param2=0},
		{name="air", prob=0, param2=0},
		{name="air", prob=0, param2=0},
		{name="air", prob=0, param2=0},
		{name="air", prob=0, param2=0},
		{name="air", prob=0, param2=0},
		{name="air", prob=0, param2=0},
		{name="air", prob=0, param2=0},
		{name="air", prob=0, param2=0},
		{name="air", prob=0, param2=0},
		{name="air", prob=0, param2=0},
		{name="air", prob=0, param2=0},
		{name="air", prob=0, param2=0},
		{name="air", prob=0, param2=0},
		{name="air", prob=0, param2=0},
		{name="air", prob=0, param2=0},
		{name="air", prob=0, param2=0},
		{name="air", prob=0, param2=0},
		{name="air", prob=0, param2=0},
		{name="air", prob=0, param2=0},
		{name="air", prob=0, param2=0},
		{name="air", prob=0, param2=0},
		{name="air", prob=0, param2=0},
		{name="air", prob=0, param2=0},
		{name="air", prob=0, param2=0},
		{name="air", prob=0, param2=0},
		{name="air", prob=0, param2=0},
		{name="air", prob=0, param2=0},
		{name="air", prob=0, param2=0},
		{name="air", prob=0, param2=0},
		{name="air", prob=0, param2=0},
		{name="air", prob=0, param2=0},
		{name="air", prob=0, param2=0},
		{name="air", prob=0, param2=0},
		{name="air", prob=0, param2=0},
		{name="air", prob=0, param2=0},
		{name="air", prob=0, param2=0},
		{name="air", prob=0, param2=0},
		{name="air", prob=0, param2=0},
		{name="air", prob=0, param2=0},
		{name="air", prob=0, param2=0},
		{name="air", prob=0, param2=0},
		{name="air", prob=0, param2=0},
		{name="air", prob=0, param2=0},
		{name="air", prob=0, param2=0},
		{name="air", prob=0, param2=0},
		{name="air", prob=0, param2=0},
		{name="air", prob=0, param2=0},
		{name="air", prob=0, param2=0},
		{name="air", prob=0, param2=0},
		{name="air", prob=0, param2=0},
		{name="air", prob=0, param2=0},
		{name="air", prob=0, param2=0},
		{name="air", prob=0, param2=0},
		{name="air", prob=0, param2=0},
		{name="air", prob=0, param2=0},
		{name="air", prob=0, param2=0},
		{name="air", prob=0, param2=0},
		{name="air", prob=0, param2=0},
		{name="air", prob=0, param2=0},
		{name="air", prob=0, param2=0},
		{name="air", prob=0, param2=0},
		{name="air", prob=0, param2=0},
		{name="air", prob=0, param2=0},
		{name="air", prob=0, param2=0},
		{name="air", prob=0, param2=0},
		{name="air", prob=0, param2=0},
		{name="air", prob=0, param2=0},
		{name="air", prob=0, param2=0},
		{name="air", prob=0, param2=0},
		{name="air", prob=0, param2=0},
		{name="air", prob=0, param2=0},
		{name="air", prob=0, param2=0},
		{name="air", prob=0, param2=0},
		{name="air", prob=0, param2=0},
		{name="air", prob=0, param2=0},
		{name="air", prob=0, param2=0},
		{name="air", prob=0, param2=0},
		{name="air", prob=0, param2=0},
		{name="air", prob=0, param2=0},
		{name="air", prob=0, param2=0},
		{name="air", prob=0, param2=0},
		{name="air", prob=0, param2=0},
		{name="air", prob=0, param2=0},
		{name="vlf_core:vine", prob=254, param2=5},
		{name="air", prob=0, param2=0},
		{name="air", prob=0, param2=0},
		{name="air", prob=0, param2=0},
		{name="air", prob=0, param2=0},
		{name="air", prob=0, param2=0},
		{name="air", prob=0, param2=0},
		{name="air", prob=0, param2=0},
		{name="air", prob=0, param2=0},
		{name="air", prob=0, param2=0},
		{name="air", prob=0, param2=0},
		{name="air", prob=0, param2=0},
		{name="air", prob=0, param2=0},
		{name="air", prob=0, param2=0},
		{name="air", prob=0, param2=0},
		{name="air", prob=0, param2=0},
		{name="air", prob=0, param2=0},
		{name="air", prob=0, param2=0},
		{name="air", prob=0, param2=0},
		{name="air", prob=0, param2=0},
		{name="air", prob=0, param2=0},
		{name="air", prob=0, param2=0},
		{name="air", prob=0, param2=0},
		{name="air", prob=0, param2=0},
		{name="air", prob=0, param2=0},
		{name="air", prob=0, param2=0},
		{name="air", prob=0, param2=0},
		{name="air", prob=0, param2=0},
		{name="air", prob=0, param2=0},
		{name="air", prob=0, param2=0},
		{name="air", prob=0, param2=0},
		{name="air", prob=0, param2=0},
		{name="air", prob=0, param2=0},
		{name="air", prob=0, param2=0},
		{name="air", prob=0, param2=0},
		{name="air", prob=0, param2=0},
		{name="air", prob=0, param2=0},
		{name="air", prob=0, param2=0},
		{name="air", prob=0, param2=0},
		{name="air", prob=0, param2=0},
		{name="air", prob=0, param2=0},
		{name="air", prob=0, param2=0},
		{name="air", prob=0, param2=0},
		{name="air", prob=0, param2=0},
		{name="air", prob=0, param2=0},
		{name="air", prob=0, param2=0},
		{name="air", prob=0, param2=0},
		{name="air", prob=0, param2=0},
		{name="air", prob=0, param2=0},
		{name="air", prob=0, param2=0},
		{name="air", prob=0, param2=0},
		{name="air", prob=0, param2=0},
		{name="air", prob=0, param2=0},
		{name="air", prob=0, param2=0},
		{name="air", prob=0, param2=0},
		{name="air", prob=0, param2=0},
		{name="air", prob=0, param2=0},
		{name="air", prob=0, param2=0},
		{name="air", prob=0, param2=0},
		{name="air", prob=0, param2=0},
		{name="air", prob=0, param2=0},
		{name="air", prob=0, param2=0},
		{name="air", prob=0, param2=0},
		{name="air", prob=0, param2=0},
		{name="air", prob=0, param2=0},
		{name="air", prob=0, param2=0},
		{name="air", prob=0, param2=0},
		{name="air", prob=0, param2=0},
		{name="air", prob=0, param2=0},
		{name="air", prob=0, param2=0},
		{name="air", prob=0, param2=0},
		{name="air", prob=0, param2=0},
		{name="air", prob=0, param2=0},
		{name="air", prob=0, param2=0},
		{name="air", prob=0, param2=0},
		{name="air", prob=0, param2=0},
		{name="air", prob=0, param2=0},
		{name="air", prob=0, param2=0},
		{name="air", prob=0, param2=0},
		{name="air", prob=0, param2=0},
		{name="air", prob=0, param2=0},
		{name="air", prob=0, param2=0},
		{name="air", prob=0, param2=0},
		{name="air", prob=0, param2=0},
		{name="air", prob=0, param2=0},
		{name="air", prob=0, param2=0},
		{name="air", prob=0, param2=0},
		{name="air", prob=0, param2=0},
		{name="air", prob=0, param2=0},
		{name="air", prob=0, param2=0},
		{name="air", prob=0, param2=0},
		{name="air", prob=0, param2=0},
		{name="air", prob=0, param2=0},
		{name="air", prob=0, param2=0},
		{name="air", prob=0, param2=0},
	},
}
