schematic = {
	size = {x=3, y=4, z=3},
	yslice_prob = {
		{ypos=0, prob=254},
		{ypos=1, prob=240},
		{ypos=2, prob=220},
		{ypos=3, prob=254},
	},
	data = {
		{name="air", prob=0, param2=0},
		{name="vlf_core:mossycobble", prob=254, param2=0},
		{name="air", prob=0, param2=0},
		{name="air", prob=0, param2=0},
		{name="vlf_core:mossycobble", prob=254, param2=0},
		{name="air", prob=0, param2=0},
		{name="vlf_core:mossycobble", prob=202, param2=0},
		{name="vlf_core:mossycobble", prob=254, param2=0},
		{name="vlf_core:mossycobble", prob=202, param2=0},
		{name="air", prob=0, param2=0},
		{name="vlf_core:mossycobble", prob=202, param2=0},
		{name="air", prob=0, param2=0},
		{name="vlf_core:mossycobble", prob=254, param2=0},
		{name="vlf_core:mossycobble", prob=254, param2=0},
		{name="vlf_core:mossycobble", prob=254, param2=0},
		{name="vlf_core:mossycobble", prob=254, param2=0},
		{name="vlf_core:mossycobble", prob=254, param2=0},
		{name="vlf_core:mossycobble", prob=254, param2=0},
		{name="vlf_core:mossycobble", prob=254, param2=0},
		{name="vlf_core:mossycobble", prob=254, param2=0},
		{name="vlf_core:mossycobble", prob=254, param2=0},
		{name="vlf_core:mossycobble", prob=202, param2=0},
		{name="vlf_core:mossycobble", prob=254, param2=0},
		{name="vlf_core:mossycobble", prob=202, param2=0},
		{name="air", prob=0, param2=0},
		{name="vlf_core:mossycobble", prob=254, param2=0},
		{name="air", prob=0, param2=0},
		{name="air", prob=0, param2=0},
		{name="vlf_core:mossycobble", prob=254, param2=0},
		{name="air", prob=0, param2=0},
		{name="vlf_core:mossycobble", prob=202, param2=0},
		{name="vlf_core:mossycobble", prob=254, param2=0},
		{name="vlf_core:mossycobble", prob=202, param2=0},
		{name="air", prob=0, param2=0},
		{name="vlf_core:mossycobble", prob=202, param2=0},
		{name="air", prob=0, param2=0},
	},
}
