schematic = {
	size = {x=9, y=19, z=9},
	yslice_prob = {
		{ypos=0, prob=254},
		{ypos=1, prob=254},
		{ypos=2, prob=254},
		{ypos=3, prob=254},
		{ypos=4, prob=254},
		{ypos=5, prob=254},
		{ypos=6, prob=254},
		{ypos=7, prob=254},
		{ypos=8, prob=254},
		{ypos=9, prob=254},
		{ypos=10, prob=254},
		{ypos=11, prob=254},
		{ypos=12, prob=254},
		{ypos=13, prob=254},
		{ypos=14, prob=254},
		{ypos=15, prob=254},
		{ypos=16, prob=254},
		{ypos=17, prob=254},
		{ypos=18, prob=254},
	},
	data = {
		{name="vlf_blackstone:blackstone_brick_polished", prob=254, param2=0},
		{name="vlf_blackstone:blackstone_brick_polished", prob=254, param2=0},
		{name="vlf_blackstone:blackstone_brick_polished", prob=254, param2=0},
		{name="air", prob=254, param2=0},
		{name="air", prob=254, param2=0},
		{name="air", prob=254, param2=0},
		{name="vlf_blackstone:blackstone_brick_polished", prob=254, param2=0},
		{name="vlf_blackstone:blackstone_brick_polished", prob=254, param2=0},
		{name="vlf_blackstone:blackstone_brick_polished", prob=254, param2=0},
		{name="vlf_blackstone:basalt", prob=254, param2=0},
		{name="air", prob=254, param2=0},
		{name="air", prob=254, param2=0},
		{name="air", prob=254, param2=0},
		{name="air", prob=254, param2=0},
		{name="air", prob=254, param2=0},
		{name="air", prob=254, param2=0},
		{name="air", prob=254, param2=0},
		{name="vlf_blackstone:basalt", prob=254, param2=0},
		{name="vlf_blackstone:basalt", prob=254, param2=0},
		{name="air", prob=254, param2=0},
		{name="air", prob=254, param2=0},
		{name="air", prob=254, param2=0},
		{name="air", prob=254, param2=0},
		{name="air", prob=254, param2=0},
		{name="air", prob=254, param2=0},
		{name="air", prob=254, param2=0},
		{name="vlf_blackstone:basalt", prob=254, param2=0},
		{name="vlf_blackstone:basalt", prob=254, param2=0},
		{name="air", prob=254, param2=0},
		{name="air", prob=254, param2=0},
		{name="air", prob=254, param2=0},
		{name="air", prob=254, param2=0},
		{name="air", prob=254, param2=0},
		{name="air", prob=254, param2=0},
		{name="air", prob=254, param2=0},
		{name="vlf_blackstone:basalt", prob=254, param2=0},
		{name="vlf_blackstone:blackstone_brick_polished", prob=254, param2=0},
		{name="vlf_blackstone:blackstone_brick_polished", prob=254, param2=0},
		{name="vlf_blackstone:blackstone_brick_polished", prob=254, param2=0},
		{name="vlf_stairs:stair_blackstone_brick_polished", prob=254, param2=0},
		{name="vlf_stairs:stair_blackstone_brick_polished", prob=254, param2=0},
		{name="vlf_blackstone:blackstone_brick_polished", prob=254, param2=0},
		{name="vlf_blackstone:blackstone_brick_polished", prob=254, param2=0},
		{name="vlf_blackstone:blackstone_brick_polished", prob=254, param2=0},
		{name="vlf_blackstone:blackstone_brick_polished", prob=254, param2=0},
		{name="vlf_blackstone:basalt", prob=254, param2=0},
		{name="air", prob=254, param2=0},
		{name="air", prob=254, param2=0},
		{name="air", prob=254, param2=0},
		{name="air", prob=254, param2=0},
		{name="air", prob=254, param2=0},
		{name="air", prob=254, param2=0},
		{name="vlf_blackstone:blackstone", prob=254, param2=0},
		{name="vlf_blackstone:basalt", prob=254, param2=0},
		{name="vlf_blackstone:basalt", prob=254, param2=0},
		{name="air", prob=254, param2=0},
		{name="air", prob=254, param2=0},
		{name="air", prob=254, param2=0},
		{name="air", prob=254, param2=0},
		{name="air", prob=254, param2=0},
		{name="air", prob=254, param2=0},
		{name="vlf_stairs:stair_blackstone_brick_polished", prob=254, param2=1},
		{name="vlf_blackstone:basalt", prob=254, param2=0},
		{name="vlf_blackstone:basalt", prob=254, param2=0},
		{name="air", prob=254, param2=0},
		{name="air", prob=254, param2=0},
		{name="air", prob=254, param2=0},
		{name="air", prob=254, param2=0},
		{name="air", prob=254, param2=0},
		{name="air", prob=254, param2=0},
		{name="vlf_stairs:stair_blackstone_brick_polished", prob=254, param2=23},
		{name="vlf_blackstone:basalt", prob=254, param2=0},
		{name="vlf_blackstone:blackstone_brick_polished", prob=254, param2=0},
		{name="vlf_blackstone:blackstone_brick_polished", prob=254, param2=0},
		{name="vlf_blackstone:blackstone_brick_polished", prob=254, param2=0},
		{name="air", prob=254, param2=0},
		{name="air", prob=254, param2=0},
		{name="air", prob=254, param2=0},
		{name="air", prob=254, param2=0},
		{name="vlf_blackstone:blackstone_brick_polished", prob=254, param2=0},
		{name="vlf_blackstone:blackstone_brick_polished", prob=254, param2=0},
		{name="vlf_blackstone:basalt", prob=254, param2=0},
		{name="air", prob=254, param2=0},
		{name="vlf_stairs:stair_blackstone_brick_polished", prob=254, param2=1},
		{name="air", prob=254, param2=0},
		{name="vlf_blackstone:basalt_smooth", prob=254, param2=0},
		{name="vlf_blackstone:basalt_smooth", prob=254, param2=0},
		{name="vlf_blackstone:basalt_smooth", prob=254, param2=0},
		{name="air", prob=254, param2=0},
		{name="vlf_blackstone:basalt", prob=254, param2=0},
		{name="vlf_blackstone:basalt", prob=254, param2=0},
		{name="air", prob=254, param2=0},
		{name="air", prob=254, param2=0},
		{name="air", prob=254, param2=0},
		{name="air", prob=254, param2=0},
		{name="vlf_stairs:stair_blackstone_brick_polished", prob=254, param2=0},
		{name="air", prob=254, param2=0},
		{name="air", prob=254, param2=0},
		{name="vlf_blackstone:basalt", prob=254, param2=0},
		{name="vlf_blackstone:basalt", prob=254, param2=0},
		{name="air", prob=254, param2=0},
		{name="air", prob=254, param2=0},
		{name="air", prob=254, param2=0},
		{name="vlf_stairs:stair_blackstone_brick_polished", prob=254, param2=23},
		{name="air", prob=254, param2=0},
		{name="air", prob=254, param2=0},
		{name="air", prob=254, param2=0},
		{name="vlf_blackstone:basalt", prob=254, param2=0},
		{name="vlf_blackstone:blackstone_brick_polished", prob=254, param2=0},
		{name="vlf_blackstone:blackstone_brick_polished", prob=254, param2=0},
		{name="vlf_blackstone:blackstone_brick_polished", prob=254, param2=0},
		{name="vlf_blackstone:blackstone_brick_polished", prob=254, param2=0},
		{name="vlf_blackstone:blackstone_brick_polished", prob=254, param2=0},
		{name="vlf_blackstone:blackstone_brick_polished", prob=254, param2=0},
		{name="vlf_blackstone:blackstone_brick_polished", prob=254, param2=0},
		{name="vlf_blackstone:blackstone_brick_polished", prob=254, param2=0},
		{name="vlf_blackstone:blackstone_brick_polished", prob=254, param2=0},
		{name="vlf_blackstone:basalt", prob=254, param2=0},
		{name="air", prob=254, param2=0},
		{name="air", prob=254, param2=0},
		{name="air", prob=254, param2=0},
		{name="air", prob=254, param2=0},
		{name="air", prob=254, param2=0},
		{name="air", prob=254, param2=0},
		{name="air", prob=254, param2=0},
		{name="vlf_blackstone:basalt", prob=254, param2=0},
		{name="vlf_blackstone:basalt", prob=254, param2=0},
		{name="air", prob=254, param2=0},
		{name="air", prob=254, param2=0},
		{name="air", prob=254, param2=0},
		{name="air", prob=254, param2=0},
		{name="air", prob=254, param2=0},
		{name="air", prob=254, param2=0},
		{name="air", prob=254, param2=0},
		{name="vlf_blackstone:basalt", prob=254, param2=0},
		{name="vlf_blackstone:basalt", prob=254, param2=0},
		{name="air", prob=254, param2=0},
		{name="air", prob=254, param2=0},
		{name="air", prob=254, param2=0},
		{name="air", prob=254, param2=0},
		{name="air", prob=254, param2=0},
		{name="air", prob=254, param2=0},
		{name="air", prob=254, param2=0},
		{name="vlf_blackstone:basalt", prob=254, param2=0},
		{name="vlf_blackstone:blackstone_brick_polished", prob=254, param2=0},
		{name="vlf_blackstone:blackstone_brick_polished", prob=254, param2=0},
		{name="air", prob=254, param2=0},
		{name="air", prob=254, param2=0},
		{name="vlf_blackstone:blackstone_brick_polished", prob=254, param2=0},
		{name="vlf_blackstone:blackstone_brick_polished", prob=254, param2=0},
		{name="vlf_blackstone:blackstone_brick_polished", prob=254, param2=0},
		{name="vlf_blackstone:blackstone_brick_polished", prob=254, param2=0},
		{name="vlf_blackstone:blackstone_brick_polished", prob=254, param2=0},
		{name="air", prob=254, param2=0},
		{name="air", prob=254, param2=0},
		{name="air", prob=254, param2=0},
		{name="air", prob=254, param2=0},
		{name="air", prob=254, param2=0},
		{name="air", prob=254, param2=0},
		{name="vlf_blackstone:blackstone", prob=254, param2=0},
		{name="vlf_blackstone:blackstone", prob=254, param2=0},
		{name="air", prob=254, param2=0},
		{name="air", prob=254, param2=0},
		{name="air", prob=254, param2=0},
		{name="air", prob=254, param2=0},
		{name="air", prob=254, param2=0},
		{name="air", prob=254, param2=0},
		{name="air", prob=254, param2=0},
		{name="vlf_blackstone:blackstone", prob=254, param2=0},
		{name="air", prob=254, param2=0},
		{name="air", prob=254, param2=0},
		{name="vlf_blackstone:blackstone_brick_polished", prob=254, param2=0},
		{name="vlf_blackstone:blackstone_chiseled_polished", prob=254, param2=0},
		{name="vlf_blackstone:basalt_smooth", prob=254, param2=0},
		{name="vlf_blackstone:blackstone_chiseled_polished", prob=254, param2=0},
		{name="air", prob=254, param2=0},
		{name="air", prob=254, param2=0},
		{name="vlf_blackstone:basalt_smooth", prob=254, param2=0},
		{name="vlf_blackstone:blackstone_chiseled_polished", prob=254, param2=0},
		{name="vlf_blackstone:blackstone_brick_polished", prob=254, param2=0},
		{name="vlf_blackstone:basalt_smooth", prob=254, param2=0},
		{name="air", prob=254, param2=0},
		{name="vlf_blackstone:blackstone", prob=254, param2=0},
		{name="air", prob=254, param2=0},
		{name="air", prob=254, param2=0},
		{name="air", prob=254, param2=0},
		{name="air", prob=254, param2=0},
		{name="air", prob=254, param2=0},
		{name="air", prob=254, param2=0},
		{name="air", prob=254, param2=0},
		{name="air", prob=254, param2=0},
		{name="air", prob=254, param2=0},
		{name="air", prob=254, param2=0},
		{name="air", prob=254, param2=0},
		{name="air", prob=254, param2=0},
		{name="air", prob=254, param2=0},
		{name="air", prob=254, param2=0},
		{name="air", prob=254, param2=0},
		{name="air", prob=254, param2=0},
		{name="air", prob=254, param2=0},
		{name="air", prob=254, param2=0},
		{name="air", prob=254, param2=0},
		{name="air", prob=254, param2=0},
		{name="air", prob=254, param2=0},
		{name="air", prob=254, param2=0},
		{name="air", prob=254, param2=0},
		{name="air", prob=254, param2=0},
		{name="vlf_blackstone:blackstone_brick_polished", prob=254, param2=0},
		{name="vlf_blackstone:blackstone_chiseled_polished", prob=254, param2=0},
		{name="vlf_stairs:stair_blackstone_brick_polished", prob=254, param2=0},
		{name="vlf_stairs:stair_blackstone_brick_polished", prob=254, param2=1},
		{name="vlf_blackstone:basalt_smooth", prob=254, param2=0},
		{name="vlf_blackstone:blackstone_chiseled_polished", prob=254, param2=0},
		{name="vlf_blackstone:basalt_smooth", prob=254, param2=0},
		{name="vlf_blackstone:blackstone_chiseled_polished", prob=254, param2=0},
		{name="air", prob=254, param2=0},
		{name="air", prob=254, param2=0},
		{name="air", prob=254, param2=0},
		{name="air", prob=254, param2=0},
		{name="air", prob=254, param2=0},
		{name="vlf_stairs:stair_blackstone_brick_polished", prob=254, param2=1},
		{name="vlf_blackstone:blackstone", prob=254, param2=0},
		{name="vlf_stairs:stair_blackstone_brick_polished", prob=254, param2=0},
		{name="vlf_blackstone:blackstone", prob=254, param2=0},
		{name="air", prob=254, param2=0},
		{name="air", prob=254, param2=0},
		{name="air", prob=254, param2=0},
		{name="air", prob=254, param2=0},
		{name="air", prob=254, param2=0},
		{name="air", prob=254, param2=0},
		{name="vlf_blackstone:blackstone", prob=254, param2=0},
		{name="air", prob=254, param2=0},
		{name="vlf_blackstone:blackstone", prob=254, param2=0},
		{name="air", prob=254, param2=0},
		{name="vlf_stairs:slab_blackstone_brick_polished_top", prob=254, param2=0},
		{name="air", prob=254, param2=0},
		{name="air", prob=254, param2=0},
		{name="air", prob=254, param2=0},
		{name="air", prob=254, param2=0},
		{name="vlf_blackstone:blackstone", prob=254, param2=0},
		{name="vlf_stairs:stair_blackstone_brick_polished", prob=254, param2=20},
		{name="air", prob=254, param2=0},
		{name="air", prob=254, param2=0},
		{name="vlf_stairs:slab_blackstone_brick_polished", prob=254, param2=0},
		{name="vlf_blackstone:blackstone_chiseled_polished", prob=254, param2=0},
		{name="air", prob=254, param2=0},
		{name="air", prob=254, param2=0},
		{name="air", prob=254, param2=0},
		{name="vlf_blackstone:blackstone", prob=254, param2=0},
		{name="vlf_blackstone:basalt_smooth", prob=254, param2=0},
		{name="vlf_blackstone:blackstone_chiseled_polished", prob=254, param2=0},
		{name="vlf_blackstone:blackstone_brick_polished", prob=254, param2=0},
		{name="air", prob=254, param2=0},
		{name="air", prob=254, param2=0},
		{name="air", prob=254, param2=0},
		{name="air", prob=254, param2=0},
		{name="air", prob=254, param2=0},
		{name="vlf_blackstone:blackstone", prob=254, param2=0},
		{name="vlf_blackstone:basalt_smooth", prob=254, param2=0},
		{name="air", prob=254, param2=0},
		{name="vlf_stairs:slab_blackstone_brick_polished", prob=254, param2=0},
		{name="air", prob=254, param2=0},
		{name="air", prob=254, param2=0},
		{name="air", prob=254, param2=0},
		{name="air", prob=254, param2=0},
		{name="air", prob=254, param2=0},
		{name="vlf_blackstone:basalt_smooth", prob=254, param2=0},
		{name="vlf_stairs:stair_blackstone_brick_polished", prob=254, param2=0},
		{name="air", prob=254, param2=0},
		{name="air", prob=254, param2=0},
		{name="air", prob=254, param2=0},
		{name="air", prob=254, param2=0},
		{name="air", prob=254, param2=0},
		{name="air", prob=254, param2=0},
		{name="air", prob=254, param2=0},
		{name="air", prob=254, param2=0},
		{name="air", prob=254, param2=0},
		{name="air", prob=254, param2=0},
		{name="air", prob=254, param2=0},
		{name="vlf_blackstone:blackstone_brick_polished", prob=254, param2=0},
		{name="vlf_blackstone:blackstone_chiseled_polished", prob=254, param2=0},
		{name="vlf_blackstone:basalt_smooth", prob=254, param2=0},
		{name="vlf_blackstone:blackstone_chiseled_polished", prob=254, param2=0},
		{name="vlf_blackstone:basalt_smooth", prob=254, param2=0},
		{name="vlf_blackstone:blackstone_chiseled_polished", prob=254, param2=0},
		{name="vlf_blackstone:basalt_smooth", prob=254, param2=0},
		{name="vlf_blackstone:blackstone_chiseled_polished", prob=254, param2=0},
		{name="vlf_blackstone:blackstone_brick_polished", prob=254, param2=0},
		{name="air", prob=254, param2=0},
		{name="air", prob=254, param2=0},
		{name="vlf_chests:chest_small", prob=254, param2=0},
		{name="air", prob=254, param2=0},
		{name="air", prob=254, param2=0},
		{name="air", prob=254, param2=0},
		{name="air", prob=254, param2=0},
		{name="air", prob=254, param2=0},
		{name="air", prob=254, param2=0},
		{name="air", prob=254, param2=0},
		{name="air", prob=254, param2=0},
		{name="air", prob=254, param2=0},
		{name="air", prob=254, param2=0},
		{name="air", prob=254, param2=0},
		{name="air", prob=254, param2=0},
		{name="air", prob=254, param2=0},
		{name="air", prob=254, param2=0},
		{name="air", prob=254, param2=0},
		{name="vlf_stairs:slab_blackstone_brick_polished_top", prob=254, param2=0},
		{name="air", prob=254, param2=0},
		{name="air", prob=254, param2=0},
		{name="air", prob=254, param2=0},
		{name="air", prob=254, param2=0},
		{name="air", prob=254, param2=0},
		{name="air", prob=254, param2=0},
		{name="air", prob=254, param2=0},
		{name="air", prob=254, param2=0},
		{name="vlf_stairs:slab_blackstone_brick_polished", prob=254, param2=0},
		{name="vlf_blackstone:blackstone_chiseled_polished", prob=254, param2=0},
		{name="vlf_blackstone:basalt_smooth", prob=254, param2=0},
		{name="air", prob=254, param2=0},
		{name="air", prob=254, param2=0},
		{name="air", prob=254, param2=0},
		{name="vlf_blackstone:basalt_smooth", prob=254, param2=0},
		{name="vlf_blackstone:blackstone_chiseled_polished", prob=254, param2=0},
		{name="vlf_blackstone:blackstone_brick_polished", prob=254, param2=0},
		{name="air", prob=254, param2=0},
		{name="air", prob=254, param2=0},
		{name="air", prob=254, param2=0},
		{name="air", prob=254, param2=0},
		{name="air", prob=254, param2=0},
		{name="air", prob=254, param2=0},
		{name="air", prob=254, param2=0},
		{name="air", prob=254, param2=0},
		{name="air", prob=254, param2=0},
		{name="air", prob=254, param2=0},
		{name="air", prob=254, param2=0},
		{name="air", prob=254, param2=0},
		{name="air", prob=254, param2=0},
		{name="air", prob=254, param2=0},
		{name="air", prob=254, param2=0},
		{name="air", prob=254, param2=0},
		{name="air", prob=254, param2=0},
		{name="air", prob=254, param2=0},
		{name="vlf_blackstone:blackstone_brick_polished", prob=254, param2=0},
		{name="vlf_blackstone:basalt_smooth", prob=254, param2=0},
		{name="vlf_blackstone:blackstone_chiseled_polished", prob=254, param2=0},
		{name="vlf_blackstone:basalt_smooth", prob=254, param2=0},
		{name="vlf_blackstone:blackstone_gilded", prob=254, param2=0},
		{name="vlf_blackstone:basalt_smooth", prob=254, param2=0},
		{name="vlf_blackstone:blackstone_chiseled_polished", prob=254, param2=0},
		{name="vlf_blackstone:basalt_smooth", prob=254, param2=0},
		{name="vlf_blackstone:blackstone_brick_polished", prob=254, param2=0},
		{name="vlf_blackstone:blackstone", prob=254, param2=0},
		{name="vlf_blackstone:basalt", prob=254, param2=0},
		{name="vlf_blackstone:basalt", prob=254, param2=0},
		{name="vlf_blackstone:basalt", prob=254, param2=0},
		{name="air", prob=254, param2=0},
		{name="air", prob=254, param2=0},
		{name="air", prob=254, param2=0},
		{name="air", prob=254, param2=0},
		{name="air", prob=254, param2=0},
		{name="vlf_blackstone:basalt_smooth", prob=254, param2=0},
		{name="air", prob=254, param2=0},
		{name="air", prob=254, param2=0},
		{name="air", prob=254, param2=0},
		{name="air", prob=254, param2=0},
		{name="air", prob=254, param2=0},
		{name="air", prob=254, param2=0},
		{name="air", prob=254, param2=0},
		{name="air", prob=254, param2=0},
		{name="air", prob=254, param2=0},
		{name="air", prob=254, param2=0},
		{name="air", prob=254, param2=0},
		{name="air", prob=254, param2=0},
		{name="air", prob=254, param2=0},
		{name="air", prob=254, param2=0},
		{name="air", prob=254, param2=0},
		{name="air", prob=254, param2=0},
		{name="air", prob=254, param2=0},
		{name="air", prob=254, param2=0},
		{name="air", prob=254, param2=0},
		{name="vlf_blackstone:blackstone_chiseled_polished", prob=254, param2=0},
		{name="vlf_stairs:stair_blackstone_brick_polished", prob=254, param2=0},
		{name="vlf_stairs:stair_blackstone_brick_polished", prob=254, param2=1},
		{name="vlf_blackstone:basalt_smooth", prob=254, param2=0},
		{name="vlf_blackstone:blackstone_chiseled_polished", prob=254, param2=0},
		{name="vlf_blackstone:basalt_smooth", prob=254, param2=0},
		{name="air", prob=254, param2=0},
		{name="air", prob=254, param2=0},
		{name="air", prob=254, param2=0},
		{name="air", prob=254, param2=0},
		{name="air", prob=254, param2=0},
		{name="air", prob=254, param2=0},
		{name="vlf_blackstone:blackstone", prob=254, param2=0},
		{name="vlf_chests:chest_small", prob=254, param2=0},
		{name="vlf_blackstone:blackstone_brick_polished", prob=254, param2=0},
		{name="air", prob=254, param2=0},
		{name="air", prob=254, param2=0},
		{name="air", prob=254, param2=0},
		{name="air", prob=254, param2=0},
		{name="air", prob=254, param2=0},
		{name="air", prob=254, param2=0},
		{name="vlf_blackstone:blackstone", prob=254, param2=0},
		{name="air", prob=254, param2=0},
		{name="vlf_blackstone:blackstone", prob=254, param2=0},
		{name="air", prob=254, param2=0},
		{name="vlf_stairs:slab_blackstone_brick_polished_double", prob=254, param2=0},
		{name="air", prob=254, param2=0},
		{name="air", prob=254, param2=0},
		{name="air", prob=254, param2=0},
		{name="air", prob=254, param2=0},
		{name="air", prob=254, param2=0},
		{name="air", prob=254, param2=0},
		{name="air", prob=254, param2=0},
		{name="air", prob=254, param2=0},
		{name="air", prob=254, param2=0},
		{name="vlf_blackstone:basalt_smooth", prob=254, param2=0},
		{name="air", prob=254, param2=0},
		{name="air", prob=254, param2=0},
		{name="vlf_blackstone:blackstone_chiseled_polished", prob=254, param2=0},
		{name="vlf_blackstone:basalt_smooth", prob=254, param2=0},
		{name="vlf_blackstone:blackstone_chiseled_polished", prob=254, param2=0},
		{name="vlf_blackstone:basalt_smooth", prob=254, param2=0},
		{name="vlf_blackstone:blackstone_brick_polished", prob=254, param2=0},
		{name="air", prob=254, param2=0},
		{name="air", prob=254, param2=0},
		{name="air", prob=254, param2=0},
		{name="air", prob=254, param2=0},
		{name="vlf_blackstone:blackstone", prob=254, param2=0},
		{name="vlf_blackstone:blackstone", prob=254, param2=0},
		{name="vlf_blackstone:basalt_smooth", prob=254, param2=0},
		{name="air", prob=254, param2=0},
		{name="vlf_stairs:slab_blackstone_brick_polished_double", prob=254, param2=0},
		{name="air", prob=254, param2=0},
		{name="air", prob=254, param2=0},
		{name="air", prob=254, param2=0},
		{name="air", prob=254, param2=0},
		{name="vlf_blackstone:blackstone", prob=254, param2=0},
		{name="vlf_blackstone:basalt_smooth", prob=254, param2=0},
		{name="air", prob=254, param2=0},
		{name="air", prob=254, param2=0},
		{name="air", prob=254, param2=0},
		{name="air", prob=254, param2=0},
		{name="air", prob=254, param2=0},
		{name="air", prob=254, param2=0},
		{name="air", prob=254, param2=0},
		{name="air", prob=254, param2=0},
		{name="air", prob=254, param2=0},
		{name="air", prob=254, param2=0},
		{name="air", prob=254, param2=0},
		{name="air", prob=254, param2=0},
		{name="vlf_blackstone:blackstone_brick_polished", prob=254, param2=0},
		{name="vlf_blackstone:basalt_smooth", prob=254, param2=0},
		{name="vlf_blackstone:blackstone_chiseled_polished", prob=254, param2=0},
		{name="vlf_blackstone:basalt_smooth", prob=254, param2=0},
		{name="vlf_blackstone:blackstone_chiseled_polished", prob=254, param2=0},
		{name="vlf_blackstone:basalt_smooth", prob=254, param2=0},
		{name="air", prob=254, param2=0},
		{name="air", prob=254, param2=0},
		{name="air", prob=254, param2=0},
		{name="air", prob=254, param2=0},
		{name="vlf_chests:chest_small", prob=254, param2=1},
		{name="vlf_blackstone:basalt_smooth", prob=254, param2=0},
		{name="vlf_blackstone:basalt", prob=254, param2=0},
		{name="air", prob=254, param2=0},
		{name="air", prob=254, param2=0},
		{name="air", prob=254, param2=0},
		{name="air", prob=254, param2=0},
		{name="air", prob=254, param2=0},
		{name="air", prob=254, param2=0},
		{name="air", prob=254, param2=0},
		{name="vlf_blackstone:basalt_smooth", prob=254, param2=0},
		{name="vlf_blackstone:basalt", prob=254, param2=0},
		{name="air", prob=254, param2=0},
		{name="air", prob=254, param2=0},
		{name="air", prob=254, param2=0},
		{name="air", prob=254, param2=0},
		{name="air", prob=254, param2=0},
		{name="vlf_stairs:slab_blackstone_brick_polished_double", prob=254, param2=0},
		{name="air", prob=254, param2=0},
		{name="vlf_blackstone:basalt_smooth", prob=254, param2=0},
		{name="vlf_blackstone:basalt", prob=254, param2=0},
		{name="air", prob=254, param2=0},
		{name="air", prob=254, param2=0},
		{name="air", prob=254, param2=0},
		{name="air", prob=254, param2=0},
		{name="air", prob=254, param2=0},
		{name="air", prob=254, param2=0},
		{name="vlf_blackstone:basalt_smooth", prob=254, param2=0},
		{name="vlf_blackstone:blackstone_chiseled_polished", prob=254, param2=0},
		{name="vlf_blackstone:basalt_smooth", prob=254, param2=0},
		{name="vlf_blackstone:blackstone_chiseled_polished", prob=254, param2=0},
		{name="vlf_blackstone:blackstone", prob=254, param2=0},
		{name="air", prob=254, param2=0},
		{name="vlf_blackstone:basalt_smooth", prob=254, param2=0},
		{name="vlf_blackstone:blackstone_brick_polished", prob=254, param2=0},
		{name="air", prob=254, param2=0},
		{name="air", prob=254, param2=0},
		{name="vlf_blackstone:blackstone", prob=254, param2=0},
		{name="air", prob=254, param2=0},
		{name="vlf_blackstone:blackstone", prob=254, param2=0},
		{name="air", prob=254, param2=0},
		{name="air", prob=254, param2=0},
		{name="vlf_blackstone:blackstone_brick_polished", prob=254, param2=0},
		{name="vlf_blackstone:blackstone_brick_polished", prob=254, param2=0},
		{name="air", prob=254, param2=0},
		{name="air", prob=254, param2=0},
		{name="air", prob=254, param2=0},
		{name="air", prob=254, param2=0},
		{name="air", prob=254, param2=0},
		{name="air", prob=254, param2=0},
		{name="air", prob=254, param2=0},
		{name="air", prob=254, param2=0},
		{name="vlf_blackstone:blackstone_brick_polished", prob=254, param2=0},
		{name="vlf_blackstone:blackstone_brick_polished", prob=254, param2=0},
		{name="vlf_blackstone:blackstone_chiseled_polished", prob=254, param2=0},
		{name="vlf_blackstone:basalt_smooth", prob=254, param2=0},
		{name="vlf_blackstone:blackstone_chiseled_polished", prob=254, param2=0},
		{name="vlf_blackstone:basalt_smooth", prob=254, param2=0},
		{name="vlf_blackstone:blackstone_chiseled_polished", prob=254, param2=0},
		{name="vlf_blackstone:basalt_smooth", prob=254, param2=0},
		{name="vlf_blackstone:blackstone_chiseled_polished", prob=254, param2=0},
		{name="vlf_blackstone:blackstone_brick_polished", prob=254, param2=0},
		{name="vlf_blackstone:blackstone", prob=254, param2=0},
		{name="vlf_blackstone:basalt", prob=254, param2=0},
		{name="vlf_blackstone:basalt", prob=254, param2=0},
		{name="vlf_blackstone:basalt", prob=254, param2=0},
		{name="vlf_blackstone:basalt", prob=254, param2=0},
		{name="air", prob=254, param2=0},
		{name="air", prob=254, param2=0},
		{name="air", prob=254, param2=0},
		{name="air", prob=254, param2=0},
		{name="vlf_blackstone:blackstone", prob=254, param2=0},
		{name="vlf_blackstone:blackstone", prob=254, param2=0},
		{name="vlf_blackstone:blackstone_gilded", prob=254, param2=0},
		{name="vlf_blackstone:basalt", prob=254, param2=0},
		{name="air", prob=254, param2=0},
		{name="air", prob=254, param2=0},
		{name="air", prob=254, param2=0},
		{name="air", prob=254, param2=0},
		{name="air", prob=254, param2=0},
		{name="vlf_blackstone:basalt_smooth", prob=254, param2=0},
		{name="vlf_blackstone:blackstone_gilded", prob=254, param2=0},
		{name="vlf_blackstone:blackstone_gilded", prob=254, param2=0},
		{name="vlf_blackstone:basalt", prob=254, param2=0},
		{name="air", prob=254, param2=0},
		{name="air", prob=254, param2=0},
		{name="air", prob=254, param2=0},
		{name="air", prob=254, param2=0},
		{name="air", prob=254, param2=0},
		{name="vlf_blackstone:blackstone_brick_polished", prob=254, param2=0},
		{name="vlf_stairs:stair_blackstone_brick_polished", prob=254, param2=2},
		{name="vlf_blackstone:basalt_smooth", prob=254, param2=0},
		{name="vlf_blackstone:blackstone_chiseled_polished", prob=254, param2=0},
		{name="vlf_blackstone:basalt_smooth", prob=254, param2=0},
		{name="vlf_blackstone:blackstone_chiseled_polished", prob=254, param2=0},
		{name="vlf_blackstone:basalt_smooth", prob=254, param2=0},
		{name="vlf_blackstone:blackstone_chiseled_polished", prob=254, param2=0},
		{name="air", prob=254, param2=0},
		{name="air", prob=254, param2=0},
		{name="air", prob=254, param2=0},
		{name="air", prob=254, param2=0},
		{name="vlf_blackstone:blackstone", prob=254, param2=0},
		{name="vlf_blackstone:blackstone", prob=254, param2=0},
		{name="vlf_blackstone:basalt", prob=254, param2=0},
		{name="vlf_blackstone:blackstone_brick_polished", prob=254, param2=0},
		{name="air", prob=254, param2=0},
		{name="air", prob=254, param2=0},
		{name="vlf_stairs:slab_blackstone_brick_polished_top", prob=254, param2=0},
		{name="air", prob=254, param2=0},
		{name="air", prob=254, param2=0},
		{name="vlf_blackstone:blackstone", prob=254, param2=0},
		{name="vlf_blackstone:blackstone", prob=254, param2=0},
		{name="vlf_blackstone:basalt", prob=254, param2=0},
		{name="vlf_blackstone:blackstone_brick_polished", prob=254, param2=0},
		{name="air", prob=254, param2=0},
		{name="air", prob=254, param2=0},
		{name="vlf_stairs:slab_blackstone_brick_polished", prob=254, param2=0},
		{name="air", prob=254, param2=0},
		{name="air", prob=254, param2=0},
		{name="air", prob=254, param2=0},
		{name="air", prob=254, param2=0},
		{name="air", prob=254, param2=0},
		{name="air", prob=254, param2=0},
		{name="air", prob=254, param2=0},
		{name="vlf_stairs:stair_blackstone_brick_polished", prob=254, param2=20},
		{name="vlf_stairs:stair_blackstone_brick_polished", prob=254, param2=23},
		{name="vlf_blackstone:blackstone_chiseled_polished", prob=254, param2=0},
		{name="vlf_blackstone:basalt_smooth", prob=254, param2=0},
		{name="vlf_blackstone:blackstone_chiseled_polished", prob=254, param2=0},
		{name="vlf_blackstone:basalt_smooth", prob=254, param2=0},
		{name="vlf_blackstone:blackstone_chiseled_polished", prob=254, param2=0},
		{name="vlf_blackstone:basalt_smooth", prob=254, param2=0},
		{name="vlf_blackstone:blackstone_chiseled_polished", prob=254, param2=0},
		{name="vlf_blackstone:blackstone_brick_polished", prob=254, param2=0},
		{name="air", prob=254, param2=0},
		{name="vlf_stairs:stair_blackstone_brick_polished", prob=254, param2=0},
		{name="vlf_blackstone:basalt", prob=254, param2=0},
		{name="vlf_blackstone:blackstone", prob=254, param2=0},
		{name="vlf_core:goldblock", prob=254, param2=0},
		{name="vlf_core:goldblock", prob=254, param2=0},
		{name="vlf_blackstone:basalt", prob=254, param2=0},
		{name="air", prob=254, param2=0},
		{name="air", prob=254, param2=0},
		{name="air", prob=254, param2=0},
		{name="air", prob=254, param2=0},
		{name="vlf_blackstone:basalt", prob=254, param2=0},
		{name="vlf_blackstone:blackstone", prob=254, param2=0},
		{name="vlf_core:goldblock", prob=254, param2=0},
		{name="vlf_core:goldblock", prob=254, param2=0},
		{name="vlf_blackstone:basalt", prob=254, param2=0},
		{name="air", prob=254, param2=0},
		{name="vlf_stairs:slab_blackstone_brick_polished", prob=254, param2=0},
		{name="air", prob=254, param2=0},
		{name="air", prob=254, param2=0},
		{name="vlf_blackstone:basalt", prob=254, param2=6},
		{name="vlf_blackstone:basalt", prob=254, param2=12},
		{name="vlf_blackstone:basalt", prob=254, param2=12},
		{name="vlf_blackstone:basalt", prob=254, param2=12},
		{name="vlf_blackstone:basalt", prob=254, param2=12},
		{name="air", prob=254, param2=0},
		{name="air", prob=254, param2=0},
		{name="vlf_blackstone:blackstone_brick_polished", prob=254, param2=0},
		{name="vlf_blackstone:blackstone_chiseled_polished", prob=254, param2=0},
		{name="vlf_blackstone:basalt_smooth", prob=254, param2=0},
		{name="vlf_blackstone:blackstone_chiseled_polished", prob=254, param2=0},
		{name="vlf_blackstone:basalt_smooth", prob=254, param2=0},
		{name="air", prob=254, param2=0},
		{name="air", prob=254, param2=0},
		{name="vlf_blackstone:blackstone_chiseled_polished", prob=254, param2=0},
		{name="air", prob=254, param2=0},
		{name="air", prob=254, param2=0},
		{name="vlf_blackstone:basalt", prob=254, param2=0},
		{name="vlf_blackstone:basalt_smooth", prob=254, param2=0},
		{name="vlf_blackstone:basalt", prob=254, param2=0},
		{name="air", prob=254, param2=0},
		{name="air", prob=254, param2=0},
		{name="air", prob=254, param2=0},
		{name="air", prob=254, param2=0},
		{name="air", prob=254, param2=0},
		{name="air", prob=254, param2=0},
		{name="air", prob=254, param2=0},
		{name="air", prob=254, param2=0},
		{name="air", prob=254, param2=0},
		{name="air", prob=254, param2=0},
		{name="air", prob=254, param2=0},
		{name="air", prob=254, param2=0},
		{name="air", prob=254, param2=0},
		{name="air", prob=254, param2=0},
		{name="vlf_stairs:slab_blackstone_brick_polished", prob=254, param2=0},
		{name="air", prob=254, param2=0},
		{name="air", prob=254, param2=0},
		{name="air", prob=254, param2=0},
		{name="air", prob=254, param2=0},
		{name="air", prob=254, param2=0},
		{name="air", prob=254, param2=0},
		{name="air", prob=254, param2=0},
		{name="air", prob=254, param2=0},
		{name="air", prob=254, param2=0},
		{name="vlf_blackstone:blackstone_chiseled_polished", prob=254, param2=0},
		{name="vlf_blackstone:basalt_smooth", prob=254, param2=0},
		{name="air", prob=254, param2=0},
		{name="vlf_blackstone:basalt_smooth", prob=254, param2=0},
		{name="vlf_blackstone:blackstone", prob=254, param2=0},
		{name="vlf_blackstone:basalt_smooth", prob=254, param2=0},
		{name="air", prob=254, param2=0},
		{name="air", prob=254, param2=0},
		{name="air", prob=254, param2=0},
		{name="air", prob=254, param2=0},
		{name="air", prob=254, param2=0},
		{name="air", prob=254, param2=0},
		{name="vlf_stairs:stair_blackstone_brick_polished", prob=254, param2=2},
		{name="vlf_blackstone:blackstone", prob=254, param2=0},
		{name="air", prob=254, param2=0},
		{name="air", prob=254, param2=0},
		{name="air", prob=254, param2=0},
		{name="air", prob=254, param2=0},
		{name="air", prob=254, param2=0},
		{name="air", prob=254, param2=0},
		{name="air", prob=254, param2=0},
		{name="air", prob=254, param2=0},
		{name="air", prob=254, param2=0},
		{name="air", prob=254, param2=0},
		{name="air", prob=254, param2=0},
		{name="air", prob=254, param2=0},
		{name="vlf_blackstone:blackstone_brick_polished", prob=254, param2=0},
		{name="vlf_blackstone:basalt_smooth", prob=254, param2=0},
		{name="vlf_blackstone:blackstone_chiseled_polished", prob=254, param2=0},
		{name="vlf_blackstone:basalt_smooth", prob=254, param2=0},
		{name="vlf_blackstone:blackstone_chiseled_polished", prob=254, param2=0},
		{name="vlf_blackstone:basalt_smooth", prob=254, param2=0},
		{name="air", prob=254, param2=0},
		{name="vlf_blackstone:basalt_smooth", prob=254, param2=0},
		{name="vlf_blackstone:blackstone_brick_polished", prob=254, param2=0},
		{name="vlf_blackstone:blackstone_brick_polished", prob=254, param2=0},
		{name="vlf_blackstone:blackstone_brick_polished", prob=254, param2=0},
		{name="vlf_blackstone:blackstone_brick_polished", prob=254, param2=0},
		{name="vlf_blackstone:blackstone_brick_polished", prob=254, param2=0},
		{name="vlf_blackstone:basalt", prob=254, param2=0},
		{name="air", prob=254, param2=0},
		{name="air", prob=254, param2=0},
		{name="air", prob=254, param2=0},
		{name="air", prob=254, param2=0},
		{name="vlf_blackstone:blackstone_brick_polished", prob=254, param2=0},
		{name="vlf_blackstone:blackstone_brick_polished", prob=254, param2=0},
		{name="vlf_blackstone:blackstone_brick_polished", prob=254, param2=0},
		{name="vlf_blackstone:blackstone_brick_polished", prob=254, param2=0},
		{name="vlf_blackstone:blackstone_brick_polished", prob=254, param2=0},
		{name="air", prob=254, param2=0},
		{name="air", prob=254, param2=0},
		{name="air", prob=254, param2=0},
		{name="air", prob=254, param2=0},
		{name="vlf_blackstone:blackstone_brick_polished", prob=254, param2=0},
		{name="vlf_blackstone:blackstone_brick_polished", prob=254, param2=0},
		{name="vlf_blackstone:blackstone_brick_polished", prob=254, param2=0},
		{name="vlf_blackstone:blackstone_brick_polished", prob=254, param2=0},
		{name="air", prob=254, param2=0},
		{name="air", prob=254, param2=0},
		{name="air", prob=254, param2=0},
		{name="air", prob=254, param2=0},
		{name="air", prob=254, param2=0},
		{name="vlf_blackstone:blackstone_brick_polished", prob=254, param2=0},
		{name="vlf_stairs:stair_blackstone_brick_polished", prob=254, param2=0},
		{name="vlf_blackstone:blackstone_chiseled_polished", prob=254, param2=0},
		{name="vlf_blackstone:basalt_smooth", prob=254, param2=0},
		{name="vlf_blackstone:blackstone_chiseled_polished", prob=254, param2=0},
		{name="vlf_blackstone:basalt_smooth", prob=254, param2=0},
		{name="vlf_blackstone:blackstone_chiseled_polished", prob=254, param2=0},
		{name="vlf_blackstone:basalt_smooth", prob=254, param2=0},
		{name="air", prob=254, param2=0},
		{name="air", prob=254, param2=0},
		{name="air", prob=254, param2=0},
		{name="vlf_blackstone:blackstone", prob=254, param2=0},
		{name="vlf_blackstone:blackstone", prob=254, param2=0},
		{name="vlf_blackstone:blackstone", prob=254, param2=0},
		{name="vlf_blackstone:blackstone", prob=254, param2=0},
		{name="vlf_blackstone:blackstone_brick_polished", prob=254, param2=0},
		{name="air", prob=254, param2=0},
		{name="air", prob=254, param2=0},
		{name="vlf_stairs:slab_blackstone_brick_polished_double", prob=254, param2=0},
		{name="air", prob=254, param2=0},
		{name="air", prob=254, param2=0},
		{name="vlf_blackstone:blackstone", prob=254, param2=0},
		{name="vlf_blackstone:blackstone", prob=254, param2=0},
		{name="vlf_core:goldblock", prob=254, param2=0},
		{name="air", prob=254, param2=0},
		{name="air", prob=254, param2=0},
		{name="air", prob=254, param2=0},
		{name="air", prob=254, param2=0},
		{name="air", prob=254, param2=0},
		{name="air", prob=254, param2=0},
		{name="vlf_blackstone:blackstone", prob=254, param2=0},
		{name="vlf_blackstone:blackstone", prob=254, param2=0},
		{name="vlf_core:goldblock", prob=254, param2=0},
		{name="air", prob=254, param2=0},
		{name="air", prob=254, param2=0},
		{name="vlf_stairs:stair_blackstone_brick_polished", prob=254, param2=20},
		{name="air", prob=254, param2=0},
		{name="vlf_blackstone:basalt_smooth", prob=254, param2=0},
		{name="vlf_blackstone:blackstone_chiseled_polished", prob=254, param2=0},
		{name="vlf_blackstone:basalt_smooth", prob=254, param2=0},
		{name="vlf_blackstone:blackstone_chiseled_polished", prob=254, param2=0},
		{name="vlf_blackstone:basalt_smooth", prob=254, param2=0},
		{name="vlf_blackstone:blackstone_chiseled_polished", prob=254, param2=0},
		{name="vlf_blackstone:basalt_smooth", prob=254, param2=0},
		{name="vlf_stairs:stair_blackstone_brick_polished", prob=254, param2=2},
		{name="air", prob=254, param2=0},
		{name="air", prob=254, param2=0},
		{name="air", prob=254, param2=0},
		{name="vlf_blackstone:blackstone", prob=254, param2=0},
		{name="vlf_core:goldblock", prob=254, param2=0},
		{name="vlf_core:goldblock", prob=254, param2=0},
		{name="vlf_blackstone:blackstone_brick_polished", prob=254, param2=0},
		{name="vlf_blackstone:blackstone", prob=254, param2=0},
		{name="air", prob=254, param2=0},
		{name="air", prob=254, param2=0},
		{name="air", prob=254, param2=0},
		{name="air", prob=254, param2=0},
		{name="vlf_blackstone:blackstone", prob=254, param2=0},
		{name="vlf_core:goldblock", prob=254, param2=0},
		{name="vlf_stairs:slab_blackstone_brick_polished", prob=254, param2=0},
		{name="air", prob=254, param2=0},
		{name="air", prob=254, param2=0},
		{name="air", prob=254, param2=0},
		{name="air", prob=254, param2=0},
		{name="air", prob=254, param2=0},
		{name="vlf_blackstone:basalt", prob=254, param2=0},
		{name="air", prob=254, param2=0},
		{name="vlf_stairs:slab_blackstone_brick_polished", prob=254, param2=0},
		{name="air", prob=254, param2=0},
		{name="air", prob=254, param2=0},
		{name="air", prob=254, param2=0},
		{name="air", prob=254, param2=0},
		{name="vlf_blackstone:blackstone_brick_polished", prob=254, param2=0},
		{name="vlf_blackstone:basalt_smooth", prob=254, param2=0},
		{name="vlf_blackstone:blackstone_chiseled_polished", prob=254, param2=0},
		{name="vlf_blackstone:basalt_smooth", prob=254, param2=0},
		{name="vlf_stairs:stair_blackstone_brick_polished", prob=254, param2=2},
		{name="air", prob=254, param2=0},
		{name="air", prob=254, param2=0},
		{name="air", prob=254, param2=0},
		{name="air", prob=254, param2=0},
		{name="air", prob=254, param2=0},
		{name="air", prob=254, param2=0},
		{name="vlf_blackstone:basalt", prob=254, param2=0},
		{name="air", prob=254, param2=0},
		{name="air", prob=254, param2=0},
		{name="air", prob=254, param2=0},
		{name="air", prob=254, param2=0},
		{name="air", prob=254, param2=0},
		{name="air", prob=254, param2=0},
		{name="air", prob=254, param2=0},
		{name="air", prob=254, param2=0},
		{name="air", prob=254, param2=0},
		{name="air", prob=254, param2=0},
		{name="air", prob=254, param2=0},
		{name="air", prob=254, param2=0},
		{name="air", prob=254, param2=0},
		{name="air", prob=254, param2=0},
		{name="air", prob=254, param2=0},
		{name="air", prob=254, param2=0},
		{name="air", prob=254, param2=0},
		{name="air", prob=254, param2=0},
		{name="air", prob=254, param2=0},
		{name="air", prob=254, param2=0},
		{name="air", prob=254, param2=0},
		{name="air", prob=254, param2=0},
		{name="air", prob=254, param2=0},
		{name="air", prob=254, param2=0},
		{name="air", prob=254, param2=0},
		{name="vlf_blackstone:basalt_smooth", prob=254, param2=0},
		{name="vlf_blackstone:blackstone_chiseled_polished", prob=254, param2=0},
		{name="air", prob=254, param2=0},
		{name="vlf_blackstone:blackstone_chiseled_polished", prob=254, param2=0},
		{name="vlf_blackstone:basalt_smooth", prob=254, param2=0},
		{name="vlf_blackstone:blackstone_chiseled_polished", prob=254, param2=0},
		{name="air", prob=254, param2=0},
		{name="air", prob=254, param2=0},
		{name="air", prob=254, param2=0},
		{name="air", prob=254, param2=0},
		{name="vlf_blackstone:blackstone", prob=254, param2=0},
		{name="air", prob=254, param2=0},
		{name="air", prob=254, param2=0},
		{name="air", prob=254, param2=0},
		{name="air", prob=254, param2=0},
		{name="air", prob=254, param2=0},
		{name="air", prob=254, param2=0},
		{name="air", prob=254, param2=0},
		{name="air", prob=254, param2=0},
		{name="air", prob=254, param2=0},
		{name="air", prob=254, param2=0},
		{name="air", prob=254, param2=0},
		{name="air", prob=254, param2=0},
		{name="air", prob=254, param2=0},
		{name="air", prob=254, param2=0},
		{name="air", prob=254, param2=0},
		{name="vlf_blackstone:blackstone_brick_polished", prob=254, param2=0},
		{name="vlf_blackstone:blackstone_chiseled_polished", prob=254, param2=0},
		{name="vlf_blackstone:basalt_smooth", prob=254, param2=0},
		{name="vlf_blackstone:blackstone_chiseled_polished", prob=254, param2=0},
		{name="vlf_blackstone:basalt_smooth", prob=254, param2=0},
		{name="air", prob=254, param2=0},
		{name="vlf_blackstone:blackstone_gilded", prob=254, param2=0},
		{name="vlf_blackstone:blackstone_chiseled_polished", prob=254, param2=0},
		{name="vlf_blackstone:blackstone_brick_polished", prob=254, param2=0},
		{name="vlf_chests:chest_small", prob=254, param2=3},
		{name="air", prob=254, param2=0},
		{name="air", prob=254, param2=0},
		{name="vlf_blackstone:blackstone_brick_polished", prob=254, param2=0},
		{name="vlf_blackstone:blackstone", prob=254, param2=0},
		{name="air", prob=254, param2=0},
		{name="air", prob=254, param2=0},
		{name="air", prob=254, param2=0},
		{name="air", prob=254, param2=0},
		{name="vlf_chests:chest_small", prob=254, param2=3},
		{name="air", prob=254, param2=0},
		{name="air", prob=254, param2=0},
		{name="vlf_blackstone:blackstone_brick_polished", prob=254, param2=0},
		{name="vlf_blackstone:blackstone", prob=254, param2=0},
		{name="air", prob=254, param2=0},
		{name="air", prob=254, param2=0},
		{name="air", prob=254, param2=0},
		{name="vlf_stairs:slab_blackstone_brick_polished_top", prob=254, param2=0},
		{name="vlf_chests:chest_small", prob=254, param2=3},
		{name="air", prob=254, param2=0},
		{name="air", prob=254, param2=0},
		{name="vlf_blackstone:blackstone_brick_polished", prob=254, param2=0},
		{name="air", prob=254, param2=0},
		{name="air", prob=254, param2=0},
		{name="air", prob=254, param2=0},
		{name="air", prob=254, param2=0},
		{name="air", prob=254, param2=0},
		{name="air", prob=254, param2=0},
		{name="vlf_blackstone:blackstone_chiseled_polished", prob=254, param2=0},
		{name="vlf_blackstone:basalt_smooth", prob=254, param2=0},
		{name="vlf_blackstone:blackstone_chiseled_polished", prob=254, param2=0},
		{name="vlf_blackstone:basalt_smooth", prob=254, param2=0},
		{name="vlf_blackstone:blackstone_chiseled_polished", prob=254, param2=0},
		{name="vlf_blackstone:basalt_smooth", prob=254, param2=0},
		{name="vlf_blackstone:blackstone_chiseled_polished", prob=254, param2=0},
		{name="air", prob=254, param2=0},
		{name="vlf_stairs:slab_blackstone_brick_polished_top", prob=254, param2=0},
		{name="air", prob=254, param2=0},
		{name="air", prob=254, param2=0},
		{name="vlf_blackstone:blackstone_brick_polished", prob=254, param2=0},
		{name="vlf_blackstone:blackstone_brick_polished", prob=254, param2=0},
		{name="vlf_blackstone:blackstone_brick_polished", prob=254, param2=0},
		{name="air", prob=254, param2=0},
		{name="air", prob=254, param2=0},
		{name="air", prob=254, param2=0},
		{name="vlf_stairs:slab_blackstone_brick_polished", prob=254, param2=0},
		{name="air", prob=254, param2=0},
		{name="air", prob=254, param2=0},
		{name="air", prob=254, param2=0},
		{name="vlf_blackstone:blackstone_brick_polished", prob=254, param2=0},
		{name="air", prob=254, param2=0},
		{name="air", prob=254, param2=0},
		{name="air", prob=254, param2=0},
		{name="air", prob=254, param2=0},
		{name="air", prob=254, param2=0},
		{name="air", prob=254, param2=0},
		{name="air", prob=254, param2=0},
		{name="air", prob=254, param2=0},
		{name="vlf_blackstone:blackstone_brick_polished", prob=254, param2=0},
		{name="air", prob=254, param2=0},
		{name="air", prob=254, param2=0},
		{name="air", prob=254, param2=0},
		{name="air", prob=254, param2=0},
		{name="air", prob=254, param2=0},
		{name="vlf_blackstone:blackstone_chiseled_polished", prob=254, param2=0},
		{name="vlf_blackstone:basalt_smooth", prob=254, param2=0},
		{name="vlf_blackstone:blackstone_chiseled_polished", prob=254, param2=0},
		{name="vlf_blackstone:basalt_smooth", prob=254, param2=0},
		{name="vlf_blackstone:blackstone_chiseled_polished", prob=254, param2=0},
		{name="vlf_blackstone:basalt_smooth", prob=254, param2=0},
		{name="air", prob=254, param2=0},
		{name="air", prob=254, param2=0},
		{name="air", prob=254, param2=0},
		{name="air", prob=254, param2=0},
		{name="air", prob=254, param2=0},
		{name="air", prob=254, param2=0},
		{name="vlf_blackstone:basalt_smooth", prob=254, param2=0},
		{name="vlf_chests:chest_small", prob=254, param2=2},
		{name="vlf_blackstone:blackstone_brick_polished", prob=254, param2=0},
		{name="air", prob=254, param2=0},
		{name="air", prob=254, param2=0},
		{name="air", prob=254, param2=0},
		{name="air", prob=254, param2=0},
		{name="air", prob=254, param2=0},
		{name="air", prob=254, param2=0},
		{name="vlf_blackstone:basalt_smooth", prob=254, param2=0},
		{name="air", prob=254, param2=0},
		{name="vlf_blackstone:blackstone_brick_polished", prob=254, param2=0},
		{name="air", prob=254, param2=0},
		{name="vlf_stairs:slab_blackstone_brick_polished_top", prob=254, param2=0},
		{name="air", prob=254, param2=0},
		{name="air", prob=254, param2=0},
		{name="air", prob=254, param2=0},
		{name="air", prob=254, param2=0},
		{name="vlf_stairs:stair_blackstone_brick_polished", prob=254, param2=1},
		{name="vlf_stairs:stair_blackstone_brick_polished", prob=254, param2=2},
		{name="air", prob=254, param2=0},
		{name="air", prob=254, param2=0},
		{name="vlf_stairs:slab_blackstone_brick_polished", prob=254, param2=0},
		{name="vlf_blackstone:blackstone_brick_polished", prob=254, param2=0},
		{name="vlf_blackstone:blackstone_chiseled_polished", prob=254, param2=0},
		{name="vlf_blackstone:basalt_smooth", prob=254, param2=0},
		{name="air", prob=254, param2=0},
		{name="air", prob=254, param2=0},
		{name="vlf_blackstone:blackstone_chiseled_polished", prob=254, param2=0},
		{name="vlf_blackstone:basalt_smooth", prob=254, param2=0},
		{name="vlf_blackstone:blackstone_chiseled_polished", prob=254, param2=0},
		{name="air", prob=254, param2=0},
		{name="vlf_stairs:slab_blackstone_brick_polished_top", prob=254, param2=0},
		{name="air", prob=254, param2=0},
		{name="air", prob=254, param2=0},
		{name="air", prob=254, param2=0},
		{name="air", prob=254, param2=0},
		{name="vlf_stairs:stair_blackstone_brick_polished", prob=254, param2=2},
		{name="air", prob=254, param2=0},
		{name="air", prob=254, param2=0},
		{name="air", prob=254, param2=0},
		{name="vlf_stairs:slab_blackstone_brick_polished", prob=254, param2=0},
		{name="air", prob=254, param2=0},
		{name="air", prob=254, param2=0},
		{name="air", prob=254, param2=0},
		{name="air", prob=254, param2=0},
		{name="air", prob=254, param2=0},
		{name="air", prob=254, param2=0},
		{name="air", prob=254, param2=0},
		{name="air", prob=254, param2=0},
		{name="air", prob=254, param2=0},
		{name="air", prob=254, param2=0},
		{name="air", prob=254, param2=0},
		{name="air", prob=254, param2=0},
		{name="air", prob=254, param2=0},
		{name="air", prob=254, param2=0},
		{name="air", prob=254, param2=0},
		{name="air", prob=254, param2=0},
		{name="air", prob=254, param2=0},
		{name="air", prob=254, param2=0},
		{name="vlf_blackstone:blackstone_chiseled_polished", prob=254, param2=0},
		{name="vlf_blackstone:basalt_smooth", prob=254, param2=0},
		{name="air", prob=254, param2=0},
		{name="air", prob=254, param2=0},
		{name="air", prob=254, param2=0},
		{name="air", prob=254, param2=0},
		{name="vlf_blackstone:blackstone_chiseled_polished", prob=254, param2=0},
		{name="air", prob=254, param2=0},
		{name="air", prob=254, param2=0},
		{name="air", prob=254, param2=0},
		{name="vlf_stairs:stair_blackstone_brick_polished", prob=254, param2=2},
		{name="air", prob=254, param2=0},
		{name="air", prob=254, param2=0},
		{name="air", prob=254, param2=0},
		{name="air", prob=254, param2=0},
		{name="air", prob=254, param2=0},
		{name="air", prob=254, param2=0},
		{name="air", prob=254, param2=0},
		{name="air", prob=254, param2=0},
		{name="air", prob=254, param2=0},
		{name="air", prob=254, param2=0},
		{name="air", prob=254, param2=0},
		{name="air", prob=254, param2=0},
		{name="air", prob=254, param2=0},
		{name="air", prob=254, param2=0},
		{name="air", prob=254, param2=0},
		{name="vlf_blackstone:blackstone_brick_polished", prob=254, param2=0},
		{name="vlf_blackstone:basalt_smooth", prob=254, param2=0},
		{name="vlf_blackstone:blackstone_chiseled_polished", prob=254, param2=0},
		{name="vlf_blackstone:basalt_smooth", prob=254, param2=0},
		{name="vlf_blackstone:blackstone_chiseled_polished", prob=254, param2=0},
		{name="vlf_blackstone:basalt_smooth", prob=254, param2=0},
		{name="vlf_blackstone:blackstone_chiseled_polished", prob=254, param2=0},
		{name="vlf_blackstone:basalt_smooth", prob=254, param2=0},
		{name="vlf_blackstone:blackstone_brick_polished", prob=254, param2=0},
		{name="air", prob=254, param2=0},
		{name="air", prob=254, param2=0},
		{name="vlf_stairs:slab_blackstone_brick_polished_double", prob=254, param2=0},
		{name="vlf_doors:iron_door_b_1", prob=254, param2=1},
		{name="vlf_blackstone:blackstone", prob=254, param2=0},
		{name="vlf_blackstone:basalt", prob=254, param2=0},
		{name="air", prob=254, param2=0},
		{name="air", prob=254, param2=0},
		{name="air", prob=254, param2=0},
		{name="air", prob=254, param2=0},
		{name="air", prob=254, param2=0},
		{name="vlf_stairs:slab_blackstone_brick_polished_double", prob=254, param2=0},
		{name="vlf_doors:iron_door_t_1", prob=254, param2=1},
		{name="vlf_blackstone:blackstone", prob=254, param2=0},
		{name="vlf_blackstone:basalt", prob=254, param2=0},
		{name="air", prob=254, param2=0},
		{name="air", prob=254, param2=0},
		{name="air", prob=254, param2=0},
		{name="air", prob=254, param2=0},
		{name="air", prob=254, param2=0},
		{name="vlf_stairs:slab_blackstone_brick_polished", prob=254, param2=0},
		{name="vlf_stairs:stair_blackstone_polished", prob=254, param2=21},
		{name="vlf_blackstone:blackstone", prob=254, param2=0},
		{name="vlf_blackstone:blackstone_brick_polished", prob=254, param2=0},
		{name="air", prob=254, param2=0},
		{name="air", prob=254, param2=0},
		{name="air", prob=254, param2=0},
		{name="vlf_blackstone:blackstone_brick_polished", prob=254, param2=0},
		{name="vlf_blackstone:basalt_smooth", prob=254, param2=0},
		{name="vlf_blackstone:blackstone_chiseled_polished", prob=254, param2=0},
		{name="vlf_blackstone:basalt_smooth", prob=254, param2=0},
		{name="vlf_blackstone:blackstone_chiseled_polished", prob=254, param2=0},
		{name="vlf_blackstone:blackstone_brick_polished", prob=254, param2=0},
		{name="air", prob=254, param2=0},
		{name="air", prob=254, param2=0},
		{name="air", prob=254, param2=0},
		{name="vlf_stairs:slab_blackstone_brick_polished_double", prob=254, param2=0},
		{name="air", prob=254, param2=0},
		{name="air", prob=254, param2=0},
		{name="air", prob=254, param2=0},
		{name="vlf_stairs:stair_blackstone_brick_polished", prob=254, param2=2},
		{name="air", prob=254, param2=0},
		{name="air", prob=254, param2=0},
		{name="air", prob=254, param2=0},
		{name="air", prob=254, param2=0},
		{name="air", prob=254, param2=0},
		{name="air", prob=254, param2=0},
		{name="air", prob=254, param2=0},
		{name="air", prob=254, param2=0},
		{name="air", prob=254, param2=0},
		{name="air", prob=254, param2=0},
		{name="air", prob=254, param2=0},
		{name="air", prob=254, param2=0},
		{name="air", prob=254, param2=0},
		{name="air", prob=254, param2=0},
		{name="air", prob=254, param2=0},
		{name="air", prob=254, param2=0},
		{name="air", prob=254, param2=0},
		{name="air", prob=254, param2=0},
		{name="vlf_stairs:slab_blackstone_brick_polished_top", prob=254, param2=0},
		{name="air", prob=254, param2=0},
		{name="air", prob=254, param2=0},
		{name="air", prob=254, param2=0},
		{name="air", prob=254, param2=0},
		{name="vlf_blackstone:basalt_smooth", prob=254, param2=0},
		{name="vlf_blackstone:blackstone_chiseled_polished", prob=254, param2=0},
		{name="vlf_blackstone:basalt_smooth", prob=254, param2=0},
		{name="vlf_blackstone:blackstone_chiseled_polished", prob=254, param2=0},
		{name="vlf_blackstone:basalt_smooth", prob=254, param2=0},
		{name="vlf_blackstone:blackstone_chiseled_polished", prob=254, param2=0},
		{name="vlf_blackstone:basalt_smooth", prob=254, param2=0},
		{name="vlf_blackstone:blackstone_brick_polished", prob=254, param2=0},
		{name="air", prob=254, param2=0},
		{name="air", prob=254, param2=0},
		{name="air", prob=254, param2=0},
		{name="air", prob=254, param2=0},
		{name="vlf_stairs:stair_blackstone_brick_polished", prob=254, param2=1},
		{name="air", prob=254, param2=0},
		{name="air", prob=254, param2=0},
		{name="air", prob=254, param2=0},
		{name="air", prob=254, param2=0},
		{name="air", prob=254, param2=0},
		{name="air", prob=254, param2=0},
		{name="air", prob=254, param2=0},
		{name="air", prob=254, param2=0},
		{name="air", prob=254, param2=0},
		{name="air", prob=254, param2=0},
		{name="air", prob=254, param2=0},
		{name="air", prob=254, param2=0},
		{name="air", prob=254, param2=0},
		{name="air", prob=254, param2=0},
		{name="air", prob=254, param2=0},
		{name="air", prob=254, param2=0},
		{name="air", prob=254, param2=0},
		{name="air", prob=254, param2=0},
		{name="air", prob=254, param2=0},
		{name="air", prob=254, param2=0},
		{name="air", prob=254, param2=0},
		{name="vlf_stairs:slab_blackstone_brick_polished_double", prob=254, param2=0},
		{name="vlf_blackstone:blackstone_brick_polished", prob=254, param2=0},
		{name="air", prob=254, param2=0},
		{name="vlf_blackstone:blackstone_chiseled_polished", prob=254, param2=0},
		{name="air", prob=254, param2=0},
		{name="air", prob=254, param2=0},
		{name="air", prob=254, param2=0},
		{name="vlf_blackstone:blackstone_chiseled_polished", prob=254, param2=0},
		{name="vlf_blackstone:basalt_smooth", prob=254, param2=0},
		{name="air", prob=254, param2=0},
		{name="vlf_stairs:slab_blackstone_brick_polished_double", prob=254, param2=0},
		{name="air", prob=254, param2=0},
		{name="air", prob=254, param2=0},
		{name="air", prob=254, param2=0},
		{name="air", prob=254, param2=0},
		{name="air", prob=254, param2=0},
		{name="air", prob=254, param2=0},
		{name="air", prob=254, param2=0},
		{name="air", prob=254, param2=0},
		{name="air", prob=254, param2=0},
		{name="air", prob=254, param2=0},
		{name="air", prob=254, param2=0},
		{name="air", prob=254, param2=0},
		{name="air", prob=254, param2=0},
		{name="air", prob=254, param2=0},
		{name="air", prob=254, param2=0},
		{name="air", prob=254, param2=0},
		{name="air", prob=254, param2=0},
		{name="air", prob=254, param2=0},
		{name="air", prob=254, param2=0},
		{name="air", prob=254, param2=0},
		{name="air", prob=254, param2=0},
		{name="air", prob=254, param2=0},
		{name="air", prob=254, param2=0},
		{name="air", prob=254, param2=0},
		{name="air", prob=254, param2=0},
		{name="air", prob=254, param2=0},
		{name="air", prob=254, param2=0},
		{name="vlf_blackstone:basalt_smooth", prob=254, param2=0},
		{name="vlf_blackstone:blackstone_chiseled_polished", prob=254, param2=0},
		{name="air", prob=254, param2=0},
		{name="air", prob=254, param2=0},
		{name="air", prob=254, param2=0},
		{name="vlf_blackstone:blackstone_chiseled_polished", prob=254, param2=0},
		{name="vlf_blackstone:basalt_smooth", prob=254, param2=0},
		{name="vlf_blackstone:blackstone_brick_polished", prob=254, param2=0},
		{name="air", prob=254, param2=0},
		{name="air", prob=254, param2=0},
		{name="air", prob=254, param2=0},
		{name="air", prob=254, param2=0},
		{name="air", prob=254, param2=0},
		{name="air", prob=254, param2=0},
		{name="air", prob=254, param2=0},
		{name="air", prob=254, param2=0},
		{name="air", prob=254, param2=0},
		{name="air", prob=254, param2=0},
		{name="air", prob=254, param2=0},
		{name="air", prob=254, param2=0},
		{name="air", prob=254, param2=0},
		{name="air", prob=254, param2=0},
		{name="air", prob=254, param2=0},
		{name="air", prob=254, param2=0},
		{name="air", prob=254, param2=0},
		{name="air", prob=254, param2=0},
		{name="vlf_blackstone:blackstone_brick_polished", prob=254, param2=0},
		{name="vlf_blackstone:blackstone_chiseled_polished", prob=254, param2=0},
		{name="vlf_blackstone:basalt_smooth", prob=254, param2=0},
		{name="vlf_blackstone:blackstone_chiseled_polished", prob=254, param2=0},
		{name="air", prob=254, param2=0},
		{name="air", prob=254, param2=0},
		{name="vlf_blackstone:basalt_smooth", prob=254, param2=0},
		{name="vlf_blackstone:blackstone_chiseled_polished", prob=254, param2=0},
		{name="vlf_blackstone:blackstone_brick_polished", prob=254, param2=0},
		{name="vlf_chests:chest_small", prob=254, param2=3},
		{name="air", prob=254, param2=0},
		{name="air", prob=254, param2=0},
		{name="vlf_blackstone:blackstone_brick_polished", prob=254, param2=0},
		{name="vlf_blackstone:blackstone", prob=254, param2=0},
		{name="air", prob=254, param2=0},
		{name="air", prob=254, param2=0},
		{name="air", prob=254, param2=0},
		{name="air", prob=254, param2=0},
		{name="vlf_chests:chest_small", prob=254, param2=3},
		{name="air", prob=254, param2=0},
		{name="air", prob=254, param2=0},
		{name="vlf_blackstone:blackstone_brick_polished", prob=254, param2=0},
		{name="vlf_blackstone:blackstone_gilded", prob=254, param2=0},
		{name="air", prob=254, param2=0},
		{name="air", prob=254, param2=0},
		{name="air", prob=254, param2=0},
		{name="air", prob=254, param2=0},
		{name="vlf_chests:chest_small", prob=254, param2=3},
		{name="air", prob=254, param2=0},
		{name="air", prob=254, param2=0},
		{name="vlf_blackstone:blackstone_brick_polished", prob=254, param2=0},
		{name="air", prob=254, param2=0},
		{name="air", prob=254, param2=0},
		{name="air", prob=254, param2=0},
		{name="air", prob=254, param2=0},
		{name="vlf_stairs:slab_blackstone_brick_polished_top", prob=254, param2=0},
		{name="vlf_blackstone:blackstone_brick_polished", prob=254, param2=0},
		{name="vlf_blackstone:blackstone_chiseled_polished", prob=254, param2=0},
		{name="vlf_stairs:stair_blackstone_brick_polished", prob=254, param2=2},
		{name="vlf_stairs:stair_blackstone_brick_polished", prob=254, param2=1},
		{name="vlf_blackstone:basalt_smooth", prob=254, param2=0},
		{name="vlf_blackstone:blackstone_chiseled_polished", prob=254, param2=0},
		{name="air", prob=254, param2=0},
		{name="vlf_blackstone:blackstone_chiseled_polished", prob=254, param2=0},
		{name="vlf_stairs:slab_blackstone_brick_polished", prob=254, param2=0},
		{name="vlf_stairs:slab_blackstone_brick_polished", prob=254, param2=0},
		{name="air", prob=254, param2=0},
		{name="air", prob=254, param2=0},
		{name="air", prob=254, param2=0},
		{name="air", prob=254, param2=0},
		{name="air", prob=254, param2=0},
		{name="air", prob=254, param2=0},
		{name="air", prob=254, param2=0},
		{name="air", prob=254, param2=0},
		{name="air", prob=254, param2=0},
		{name="air", prob=254, param2=0},
		{name="air", prob=254, param2=0},
		{name="air", prob=254, param2=0},
		{name="air", prob=254, param2=0},
		{name="air", prob=254, param2=0},
		{name="air", prob=254, param2=0},
		{name="air", prob=254, param2=0},
		{name="air", prob=254, param2=0},
		{name="air", prob=254, param2=0},
		{name="air", prob=254, param2=0},
		{name="air", prob=254, param2=0},
		{name="air", prob=254, param2=0},
		{name="air", prob=254, param2=0},
		{name="air", prob=254, param2=0},
		{name="air", prob=254, param2=0},
		{name="air", prob=254, param2=0},
		{name="air", prob=254, param2=0},
		{name="air", prob=254, param2=0},
		{name="vlf_blackstone:blackstone_chiseled_polished", prob=254, param2=0},
		{name="vlf_stairs:stair_blackstone_brick_polished", prob=254, param2=0},
		{name="vlf_stairs:stair_blackstone_brick_polished", prob=254, param2=20},
		{name="vlf_blackstone:basalt_smooth", prob=254, param2=0},
		{name="vlf_blackstone:blackstone_chiseled_polished", prob=254, param2=0},
		{name="vlf_blackstone:basalt_smooth", prob=254, param2=0},
		{name="vlf_blackstone:blackstone_chiseled_polished", prob=254, param2=0},
		{name="vlf_blackstone:blackstone_brick_polished", prob=254, param2=0},
		{name="air", prob=254, param2=0},
		{name="air", prob=254, param2=0},
		{name="air", prob=254, param2=0},
		{name="air", prob=254, param2=0},
		{name="air", prob=254, param2=0},
		{name="air", prob=254, param2=0},
		{name="vlf_blackstone:blackstone_brick_polished", prob=254, param2=0},
		{name="air", prob=254, param2=0},
		{name="vlf_blackstone:blackstone", prob=254, param2=0},
		{name="air", prob=254, param2=0},
		{name="air", prob=254, param2=0},
		{name="air", prob=254, param2=0},
		{name="air", prob=254, param2=0},
		{name="air", prob=254, param2=0},
		{name="air", prob=254, param2=0},
		{name="vlf_blackstone:blackstone_brick_polished", prob=254, param2=0},
		{name="air", prob=254, param2=0},
		{name="air", prob=254, param2=0},
		{name="air", prob=254, param2=0},
		{name="air", prob=254, param2=0},
		{name="air", prob=254, param2=0},
		{name="air", prob=254, param2=0},
		{name="air", prob=254, param2=0},
		{name="air", prob=254, param2=0},
		{name="vlf_blackstone:blackstone_brick_polished", prob=254, param2=0},
		{name="air", prob=254, param2=0},
		{name="vlf_stairs:slab_blackstone_brick_polished_top", prob=254, param2=0},
		{name="vlf_blackstone:blackstone_brick_polished", prob=254, param2=0},
		{name="vlf_blackstone:blackstone_chiseled_polished", prob=254, param2=0},
		{name="air", prob=254, param2=0},
		{name="air", prob=254, param2=0},
		{name="air", prob=254, param2=0},
		{name="vlf_blackstone:blackstone_chiseled_polished", prob=254, param2=0},
		{name="vlf_blackstone:basalt_smooth", prob=254, param2=0},
		{name="vlf_blackstone:blackstone_chiseled_polished", prob=254, param2=0},
		{name="vlf_stairs:slab_blackstone_brick_polished", prob=254, param2=0},
		{name="vlf_stairs:slab_blackstone_brick_polished", prob=254, param2=0},
		{name="vlf_stairs:stair_blackstone_brick_polished", prob=254, param2=3},
		{name="air", prob=254, param2=0},
		{name="air", prob=254, param2=0},
		{name="air", prob=254, param2=0},
		{name="air", prob=254, param2=0},
		{name="vlf_stairs:stair_blackstone_brick_polished", prob=254, param2=1},
		{name="air", prob=254, param2=0},
		{name="air", prob=254, param2=0},
		{name="air", prob=254, param2=0},
		{name="air", prob=254, param2=0},
		{name="air", prob=254, param2=0},
		{name="air", prob=254, param2=0},
		{name="air", prob=254, param2=0},
		{name="air", prob=254, param2=0},
		{name="air", prob=254, param2=0},
		{name="air", prob=254, param2=0},
		{name="air", prob=254, param2=0},
		{name="air", prob=254, param2=0},
		{name="air", prob=254, param2=0},
		{name="air", prob=254, param2=0},
		{name="air", prob=254, param2=0},
		{name="air", prob=254, param2=0},
		{name="air", prob=254, param2=0},
		{name="air", prob=254, param2=0},
		{name="air", prob=254, param2=0},
		{name="air", prob=254, param2=0},
		{name="air", prob=254, param2=0},
		{name="vlf_blackstone:blackstone_chiseled_polished", prob=254, param2=0},
		{name="air", prob=254, param2=0},
		{name="air", prob=254, param2=0},
		{name="air", prob=254, param2=0},
		{name="vlf_blackstone:blackstone_chiseled_polished", prob=254, param2=0},
		{name="air", prob=254, param2=0},
		{name="vlf_blackstone:blackstone_chiseled_polished", prob=254, param2=0},
		{name="air", prob=254, param2=0},
		{name="air", prob=254, param2=0},
		{name="air", prob=254, param2=0},
		{name="air", prob=254, param2=0},
		{name="air", prob=254, param2=0},
		{name="air", prob=254, param2=0},
		{name="air", prob=254, param2=0},
		{name="air", prob=254, param2=0},
		{name="air", prob=254, param2=0},
		{name="air", prob=254, param2=0},
		{name="air", prob=254, param2=0},
		{name="air", prob=254, param2=0},
		{name="air", prob=254, param2=0},
		{name="air", prob=254, param2=0},
		{name="air", prob=254, param2=0},
		{name="air", prob=254, param2=0},
		{name="air", prob=254, param2=0},
		{name="air", prob=254, param2=0},
		{name="air", prob=254, param2=0},
		{name="vlf_blackstone:blackstone_brick_polished", prob=254, param2=0},
		{name="vlf_blackstone:blackstone_brick_polished", prob=254, param2=0},
		{name="vlf_blackstone:blackstone_brick_polished", prob=254, param2=0},
		{name="vlf_blackstone:blackstone_brick_polished", prob=254, param2=0},
		{name="vlf_blackstone:blackstone_brick_polished", prob=254, param2=0},
		{name="vlf_blackstone:blackstone_brick_polished", prob=254, param2=0},
		{name="vlf_blackstone:blackstone_brick_polished", prob=254, param2=0},
		{name="vlf_blackstone:blackstone_brick_polished", prob=254, param2=0},
		{name="vlf_blackstone:blackstone_brick_polished", prob=254, param2=0},
		{name="vlf_blackstone:basalt", prob=254, param2=0},
		{name="air", prob=254, param2=0},
		{name="air", prob=254, param2=0},
		{name="air", prob=254, param2=0},
		{name="air", prob=254, param2=0},
		{name="air", prob=254, param2=0},
		{name="air", prob=254, param2=0},
		{name="air", prob=254, param2=0},
		{name="vlf_blackstone:basalt", prob=254, param2=0},
		{name="vlf_blackstone:basalt", prob=254, param2=0},
		{name="vlf_stairs:slab_blackstone_brick_polished_double", prob=254, param2=0},
		{name="vlf_stairs:slab_blackstone_brick_polished", prob=254, param2=0},
		{name="air", prob=254, param2=0},
		{name="air", prob=254, param2=0},
		{name="air", prob=254, param2=0},
		{name="air", prob=254, param2=0},
		{name="air", prob=254, param2=0},
		{name="vlf_blackstone:basalt", prob=254, param2=0},
		{name="vlf_blackstone:basalt", prob=254, param2=0},
		{name="vlf_stairs:slab_blackstone_brick_polished", prob=254, param2=0},
		{name="air", prob=254, param2=0},
		{name="air", prob=254, param2=0},
		{name="air", prob=254, param2=0},
		{name="air", prob=254, param2=0},
		{name="vlf_stairs:slab_blackstone_brick_polished_top", prob=254, param2=0},
		{name="air", prob=254, param2=0},
		{name="vlf_blackstone:basalt", prob=254, param2=0},
		{name="vlf_blackstone:blackstone_brick_polished", prob=254, param2=0},
		{name="vlf_blackstone:blackstone_brick_polished", prob=254, param2=0},
		{name="vlf_blackstone:blackstone_brick_polished", prob=254, param2=0},
		{name="air", prob=254, param2=0},
		{name="air", prob=254, param2=0},
		{name="air", prob=254, param2=0},
		{name="vlf_stairs:slab_blackstone_brick_polished", prob=254, param2=0},
		{name="vlf_blackstone:blackstone_brick_polished", prob=254, param2=0},
		{name="vlf_blackstone:blackstone_brick_polished", prob=254, param2=0},
		{name="vlf_blackstone:basalt", prob=254, param2=0},
		{name="air", prob=254, param2=0},
		{name="air", prob=254, param2=0},
		{name="air", prob=254, param2=0},
		{name="air", prob=254, param2=0},
		{name="air", prob=254, param2=0},
		{name="air", prob=254, param2=0},
		{name="air", prob=254, param2=0},
		{name="vlf_blackstone:basalt", prob=254, param2=0},
		{name="vlf_blackstone:basalt", prob=254, param2=0},
		{name="air", prob=254, param2=0},
		{name="air", prob=254, param2=0},
		{name="air", prob=254, param2=0},
		{name="air", prob=254, param2=0},
		{name="air", prob=254, param2=0},
		{name="air", prob=254, param2=0},
		{name="air", prob=254, param2=0},
		{name="vlf_blackstone:basalt", prob=254, param2=0},
		{name="vlf_blackstone:basalt", prob=254, param2=0},
		{name="air", prob=254, param2=0},
		{name="air", prob=254, param2=0},
		{name="air", prob=254, param2=0},
		{name="air", prob=254, param2=0},
		{name="air", prob=254, param2=0},
		{name="air", prob=254, param2=0},
		{name="air", prob=254, param2=0},
		{name="vlf_blackstone:basalt", prob=254, param2=0},
		{name="vlf_blackstone:blackstone_brick_polished", prob=254, param2=0},
		{name="vlf_blackstone:blackstone_brick_polished", prob=254, param2=0},
		{name="vlf_blackstone:blackstone_brick_polished", prob=254, param2=0},
		{name="vlf_blackstone:blackstone_brick_polished", prob=254, param2=0},
		{name="vlf_blackstone:blackstone_brick_polished", prob=254, param2=0},
		{name="vlf_blackstone:blackstone_brick_polished", prob=254, param2=0},
		{name="vlf_blackstone:blackstone_brick_polished", prob=254, param2=0},
		{name="vlf_blackstone:blackstone_brick_polished", prob=254, param2=0},
		{name="vlf_blackstone:blackstone_brick_polished", prob=254, param2=0},
		{name="vlf_blackstone:basalt", prob=254, param2=0},
		{name="air", prob=254, param2=0},
		{name="air", prob=254, param2=0},
		{name="vlf_blackstone:blackstone_brick_polished", prob=254, param2=0},
		{name="vlf_blackstone:blackstone_brick_polished", prob=254, param2=0},
		{name="vlf_core:goldblock", prob=254, param2=0},
		{name="vlf_blackstone:blackstone_brick_polished", prob=254, param2=0},
		{name="air", prob=254, param2=0},
		{name="vlf_blackstone:basalt", prob=254, param2=0},
		{name="vlf_blackstone:basalt", prob=254, param2=0},
		{name="air", prob=254, param2=0},
		{name="air", prob=254, param2=0},
		{name="air", prob=254, param2=0},
		{name="vlf_blackstone:blackstone_brick_polished", prob=254, param2=0},
		{name="air", prob=254, param2=0},
		{name="vlf_blackstone:blackstone_brick_polished", prob=254, param2=0},
		{name="air", prob=254, param2=0},
		{name="vlf_blackstone:basalt", prob=254, param2=0},
		{name="vlf_blackstone:basalt", prob=254, param2=0},
		{name="air", prob=254, param2=0},
		{name="air", prob=254, param2=0},
		{name="air", prob=254, param2=0},
		{name="vlf_blackstone:blackstone_brick_polished", prob=254, param2=0},
		{name="air", prob=254, param2=0},
		{name="air", prob=254, param2=0},
		{name="air", prob=254, param2=0},
		{name="vlf_blackstone:basalt", prob=254, param2=0},
		{name="vlf_blackstone:blackstone_brick_polished", prob=254, param2=0},
		{name="vlf_blackstone:blackstone_brick_polished", prob=254, param2=0},
		{name="air", prob=254, param2=0},
		{name="vlf_blackstone:blackstone_brick_polished", prob=254, param2=0},
		{name="air", prob=254, param2=0},
		{name="vlf_blackstone:blackstone_brick_polished", prob=254, param2=0},
		{name="vlf_blackstone:blackstone_brick_polished", prob=254, param2=0},
		{name="vlf_blackstone:blackstone_brick_polished", prob=254, param2=0},
		{name="vlf_blackstone:blackstone_brick_polished", prob=254, param2=0},
		{name="vlf_blackstone:basalt", prob=254, param2=0},
		{name="air", prob=254, param2=0},
		{name="air", prob=254, param2=0},
		{name="air", prob=254, param2=0},
		{name="air", prob=254, param2=0},
		{name="air", prob=254, param2=0},
		{name="air", prob=254, param2=0},
		{name="vlf_stairs:stair_blackstone_brick_polished", prob=254, param2=1},
		{name="vlf_blackstone:basalt", prob=254, param2=0},
		{name="vlf_blackstone:basalt", prob=254, param2=0},
		{name="air", prob=254, param2=0},
		{name="air", prob=254, param2=0},
		{name="air", prob=254, param2=0},
		{name="air", prob=254, param2=0},
		{name="air", prob=254, param2=0},
		{name="air", prob=254, param2=0},
		{name="air", prob=254, param2=0},
		{name="vlf_blackstone:basalt", prob=254, param2=0},
		{name="vlf_blackstone:basalt", prob=254, param2=0},
		{name="air", prob=254, param2=0},
		{name="air", prob=254, param2=0},
		{name="air", prob=254, param2=0},
		{name="air", prob=254, param2=0},
		{name="air", prob=254, param2=0},
		{name="air", prob=254, param2=0},
		{name="vlf_stairs:stair_blackstone_brick_polished", prob=254, param2=23},
		{name="vlf_blackstone:basalt", prob=254, param2=0},
		{name="vlf_blackstone:blackstone_brick_polished", prob=254, param2=0},
		{name="vlf_blackstone:blackstone_brick_polished", prob=254, param2=0},
		{name="air", prob=254, param2=0},
		{name="air", prob=254, param2=0},
		{name="air", prob=254, param2=0},
		{name="vlf_blackstone:blackstone_brick_polished", prob=254, param2=0},
		{name="air", prob=254, param2=0},
		{name="vlf_blackstone:blackstone_brick_polished", prob=254, param2=0},
		{name="vlf_blackstone:blackstone_brick_polished", prob=254, param2=0},
		{name="air", prob=254, param2=0},
		{name="air", prob=254, param2=0},
		{name="air", prob=254, param2=0},
		{name="air", prob=254, param2=0},
		{name="air", prob=254, param2=0},
		{name="air", prob=254, param2=0},
		{name="air", prob=254, param2=0},
		{name="air", prob=254, param2=0},
		{name="air", prob=254, param2=0},
		{name="air", prob=254, param2=0},
		{name="air", prob=254, param2=0},
		{name="air", prob=254, param2=0},
		{name="air", prob=254, param2=0},
		{name="air", prob=254, param2=0},
		{name="air", prob=254, param2=0},
		{name="air", prob=254, param2=0},
		{name="air", prob=254, param2=0},
		{name="air", prob=254, param2=0},
	},
}
