schematic = {
	size = {x=23, y=18, z=19},
	yslice_prob = {
		{ypos=0, prob=254},
		{ypos=1, prob=254},
		{ypos=2, prob=254},
		{ypos=3, prob=254},
		{ypos=4, prob=254},
		{ypos=5, prob=254},
		{ypos=6, prob=254},
		{ypos=7, prob=254},
		{ypos=8, prob=254},
		{ypos=9, prob=254},
		{ypos=10, prob=254},
		{ypos=11, prob=254},
		{ypos=12, prob=254},
		{ypos=13, prob=254},
		{ypos=14, prob=254},
		{ypos=15, prob=254},
		{ypos=16, prob=254},
		{ypos=17, prob=254},
	},
	data = {
		{name="air", prob=254, param2=0},
		{name="air", prob=254, param2=0},
		{name="air", prob=254, param2=0},
		{name="air", prob=254, param2=0},
		{name="air", prob=254, param2=0},
		{name="air", prob=254, param2=0},
		{name="air", prob=254, param2=0},
		{name="air", prob=254, param2=0},
		{name="air", prob=254, param2=0},
		{name="air", prob=254, param2=0},
		{name="air", prob=254, param2=0},
		{name="air", prob=254, param2=0},
		{name="air", prob=254, param2=0},
		{name="air", prob=254, param2=0},
		{name="air", prob=254, param2=0},
		{name="air", prob=254, param2=0},
		{name="air", prob=254, param2=0},
		{name="air", prob=254, param2=0},
		{name="air", prob=254, param2=0},
		{name="air", prob=254, param2=0},
		{name="air", prob=254, param2=0},
		{name="air", prob=254, param2=0},
		{name="air", prob=254, param2=0},
		{name="air", prob=254, param2=0},
		{name="air", prob=254, param2=0},
		{name="air", prob=254, param2=0},
		{name="air", prob=254, param2=0},
		{name="air", prob=254, param2=0},
		{name="air", prob=254, param2=0},
		{name="air", prob=254, param2=0},
		{name="air", prob=254, param2=0},
		{name="air", prob=254, param2=0},
		{name="air", prob=254, param2=0},
		{name="air", prob=254, param2=0},
		{name="air", prob=254, param2=0},
		{name="air", prob=254, param2=0},
		{name="air", prob=254, param2=0},
		{name="air", prob=254, param2=0},
		{name="air", prob=254, param2=0},
		{name="air", prob=254, param2=0},
		{name="air", prob=254, param2=0},
		{name="air", prob=254, param2=0},
		{name="air", prob=254, param2=0},
		{name="air", prob=254, param2=0},
		{name="air", prob=254, param2=0},
		{name="air", prob=254, param2=0},
		{name="air", prob=254, param2=0},
		{name="air", prob=254, param2=0},
		{name="air", prob=254, param2=0},
		{name="air", prob=254, param2=0},
		{name="air", prob=254, param2=0},
		{name="air", prob=254, param2=0},
		{name="air", prob=254, param2=0},
		{name="air", prob=254, param2=0},
		{name="air", prob=254, param2=0},
		{name="air", prob=254, param2=0},
		{name="air", prob=254, param2=0},
		{name="air", prob=254, param2=0},
		{name="air", prob=254, param2=0},
		{name="air", prob=254, param2=0},
		{name="air", prob=254, param2=0},
		{name="air", prob=254, param2=0},
		{name="air", prob=254, param2=0},
		{name="air", prob=254, param2=0},
		{name="air", prob=254, param2=0},
		{name="air", prob=254, param2=0},
		{name="air", prob=254, param2=0},
		{name="air", prob=254, param2=0},
		{name="air", prob=254, param2=0},
		{name="air", prob=254, param2=0},
		{name="air", prob=254, param2=0},
		{name="air", prob=254, param2=0},
		{name="air", prob=254, param2=0},
		{name="air", prob=254, param2=0},
		{name="air", prob=254, param2=0},
		{name="air", prob=254, param2=0},
		{name="air", prob=254, param2=0},
		{name="air", prob=254, param2=0},
		{name="air", prob=254, param2=0},
		{name="air", prob=254, param2=0},
		{name="air", prob=254, param2=0},
		{name="air", prob=254, param2=0},
		{name="air", prob=254, param2=0},
		{name="air", prob=254, param2=0},
		{name="air", prob=254, param2=0},
		{name="air", prob=254, param2=0},
		{name="air", prob=254, param2=0},
		{name="air", prob=254, param2=0},
		{name="air", prob=254, param2=0},
		{name="air", prob=254, param2=0},
		{name="air", prob=254, param2=0},
		{name="air", prob=254, param2=0},
		{name="air", prob=254, param2=0},
		{name="air", prob=254, param2=0},
		{name="air", prob=254, param2=0},
		{name="air", prob=254, param2=0},
		{name="air", prob=254, param2=0},
		{name="air", prob=254, param2=0},
		{name="air", prob=254, param2=0},
		{name="air", prob=254, param2=0},
		{name="air", prob=254, param2=0},
		{name="air", prob=254, param2=0},
		{name="air", prob=254, param2=0},
		{name="air", prob=254, param2=0},
		{name="air", prob=254, param2=0},
		{name="air", prob=254, param2=0},
		{name="air", prob=254, param2=0},
		{name="air", prob=254, param2=0},
		{name="air", prob=254, param2=0},
		{name="air", prob=254, param2=0},
		{name="air", prob=254, param2=0},
		{name="air", prob=254, param2=0},
		{name="air", prob=254, param2=0},
		{name="air", prob=254, param2=0},
		{name="air", prob=254, param2=0},
		{name="air", prob=254, param2=0},
		{name="air", prob=254, param2=0},
		{name="air", prob=254, param2=0},
		{name="air", prob=254, param2=0},
		{name="air", prob=254, param2=0},
		{name="air", prob=254, param2=0},
		{name="air", prob=254, param2=0},
		{name="air", prob=254, param2=0},
		{name="air", prob=254, param2=0},
		{name="air", prob=254, param2=0},
		{name="vlf_lanterns:soul_lantern_ceiling", prob=254, param2=0},
		{name="air", prob=254, param2=0},
		{name="air", prob=254, param2=0},
		{name="air", prob=254, param2=0},
		{name="air", prob=254, param2=0},
		{name="air", prob=254, param2=0},
		{name="air", prob=254, param2=0},
		{name="air", prob=254, param2=0},
		{name="vlf_core:vine", prob=254, param2=4},
		{name="air", prob=254, param2=0},
		{name="vlf_lanterns:soul_lantern_ceiling", prob=254, param2=0},
		{name="air", prob=254, param2=0},
		{name="air", prob=254, param2=0},
		{name="air", prob=254, param2=0},
		{name="air", prob=254, param2=0},
		{name="air", prob=254, param2=0},
		{name="air", prob=254, param2=0},
		{name="air", prob=254, param2=0},
		{name="air", prob=254, param2=0},
		{name="air", prob=254, param2=0},
		{name="air", prob=254, param2=0},
		{name="air", prob=254, param2=0},
		{name="air", prob=254, param2=0},
		{name="vlf_lanterns:chain", prob=254, param2=20},
		{name="vlf_core:vine", prob=254, param2=4},
		{name="air", prob=254, param2=0},
		{name="air", prob=254, param2=0},
		{name="vlf_core:vine", prob=254, param2=4},
		{name="air", prob=254, param2=0},
		{name="air", prob=254, param2=0},
		{name="air", prob=254, param2=0},
		{name="vlf_core:vine", prob=254, param2=4},
		{name="air", prob=254, param2=0},
		{name="vlf_lanterns:chain", prob=254, param2=20},
		{name="air", prob=254, param2=0},
		{name="air", prob=254, param2=0},
		{name="air", prob=254, param2=0},
		{name="air", prob=254, param2=0},
		{name="air", prob=254, param2=0},
		{name="air", prob=254, param2=0},
		{name="air", prob=254, param2=0},
		{name="air", prob=254, param2=0},
		{name="air", prob=254, param2=0},
		{name="air", prob=254, param2=0},
		{name="air", prob=254, param2=0},
		{name="air", prob=254, param2=0},
		{name="vlf_fences:dark_oak_fence", prob=254, param2=0},
		{name="vlf_core:vine", prob=254, param2=4},
		{name="air", prob=254, param2=0},
		{name="air", prob=254, param2=0},
		{name="vlf_core:vine", prob=254, param2=4},
		{name="air", prob=254, param2=0},
		{name="air", prob=254, param2=0},
		{name="air", prob=254, param2=0},
		{name="vlf_core:vine", prob=254, param2=4},
		{name="air", prob=254, param2=0},
		{name="vlf_fences:dark_oak_fence", prob=254, param2=0},
		{name="air", prob=254, param2=0},
		{name="air", prob=254, param2=0},
		{name="air", prob=254, param2=0},
		{name="air", prob=254, param2=0},
		{name="air", prob=254, param2=0},
		{name="air", prob=254, param2=0},
		{name="air", prob=254, param2=0},
		{name="air", prob=254, param2=0},
		{name="air", prob=254, param2=0},
		{name="air", prob=254, param2=0},
		{name="air", prob=254, param2=0},
		{name="air", prob=254, param2=0},
		{name="vlf_core:vine", prob=254, param2=4},
		{name="vlf_core:vine", prob=254, param2=4},
		{name="air", prob=254, param2=0},
		{name="air", prob=254, param2=0},
		{name="vlf_core:vine", prob=254, param2=4},
		{name="air", prob=254, param2=0},
		{name="air", prob=254, param2=0},
		{name="air", prob=254, param2=0},
		{name="vlf_core:vine", prob=254, param2=4},
		{name="air", prob=254, param2=0},
		{name="air", prob=254, param2=0},
		{name="air", prob=254, param2=0},
		{name="air", prob=254, param2=0},
		{name="air", prob=254, param2=0},
		{name="air", prob=254, param2=0},
		{name="air", prob=254, param2=0},
		{name="air", prob=254, param2=0},
		{name="air", prob=254, param2=0},
		{name="air", prob=254, param2=0},
		{name="air", prob=254, param2=0},
		{name="air", prob=254, param2=0},
		{name="air", prob=254, param2=0},
		{name="air", prob=254, param2=0},
		{name="vlf_core:vine", prob=254, param2=4},
		{name="air", prob=254, param2=0},
		{name="air", prob=254, param2=0},
		{name="air", prob=254, param2=0},
		{name="vlf_core:vine", prob=254, param2=4},
		{name="air", prob=254, param2=0},
		{name="air", prob=254, param2=0},
		{name="air", prob=254, param2=0},
		{name="vlf_core:vine", prob=254, param2=4},
		{name="air", prob=254, param2=0},
		{name="air", prob=254, param2=0},
		{name="vlf_lanterns:soul_lantern_ceiling", prob=254, param2=0},
		{name="air", prob=254, param2=0},
		{name="air", prob=254, param2=0},
		{name="air", prob=254, param2=0},
		{name="air", prob=254, param2=0},
		{name="air", prob=254, param2=0},
		{name="air", prob=254, param2=0},
		{name="air", prob=254, param2=0},
		{name="air", prob=254, param2=0},
		{name="air", prob=254, param2=0},
		{name="air", prob=254, param2=0},
		{name="air", prob=254, param2=0},
		{name="vlf_core:vine", prob=254, param2=4},
		{name="air", prob=254, param2=0},
		{name="air", prob=254, param2=0},
		{name="vlf_core:vine", prob=254, param2=4},
		{name="vlf_core:vine", prob=254, param2=4},
		{name="air", prob=254, param2=0},
		{name="air", prob=254, param2=0},
		{name="air", prob=254, param2=0},
		{name="vlf_core:vine", prob=254, param2=4},
		{name="air", prob=254, param2=0},
		{name="air", prob=254, param2=0},
		{name="vlf_lanterns:chain", prob=254, param2=20},
		{name="air", prob=254, param2=0},
		{name="air", prob=254, param2=0},
		{name="air", prob=254, param2=0},
		{name="air", prob=254, param2=0},
		{name="air", prob=254, param2=0},
		{name="air", prob=254, param2=0},
		{name="air", prob=254, param2=0},
		{name="air", prob=254, param2=0},
		{name="air", prob=254, param2=0},
		{name="air", prob=254, param2=0},
		{name="vlf_lanterns:soul_lantern_ceiling", prob=254, param2=0},
		{name="vlf_core:vine", prob=254, param2=4},
		{name="air", prob=254, param2=0},
		{name="air", prob=254, param2=0},
		{name="vlf_core:vine", prob=254, param2=4},
		{name="vlf_core:vine", prob=254, param2=4},
		{name="air", prob=254, param2=0},
		{name="air", prob=254, param2=0},
		{name="air", prob=254, param2=0},
		{name="vlf_core:vine", prob=254, param2=4},
		{name="vlf_core:vine", prob=254, param2=4},
		{name="air", prob=254, param2=0},
		{name="vlf_lanterns:chain", prob=254, param2=20},
		{name="air", prob=254, param2=0},
		{name="air", prob=254, param2=0},
		{name="air", prob=254, param2=0},
		{name="air", prob=254, param2=0},
		{name="air", prob=254, param2=0},
		{name="air", prob=254, param2=0},
		{name="air", prob=254, param2=0},
		{name="air", prob=254, param2=0},
		{name="air", prob=254, param2=0},
		{name="air", prob=254, param2=0},
		{name="vlf_trees:tree_dark_oak", prob=254, param2=6},
		{name="vlf_core:vine", prob=254, param2=4},
		{name="air", prob=254, param2=0},
		{name="vlf_core:vine", prob=254, param2=4},
		{name="vlf_core:vine", prob=254, param2=4},
		{name="vlf_core:vine", prob=254, param2=4},
		{name="air", prob=254, param2=0},
		{name="air", prob=254, param2=0},
		{name="air", prob=254, param2=0},
		{name="vlf_core:vine", prob=254, param2=4},
		{name="vlf_core:vine", prob=254, param2=4},
		{name="vlf_core:vine", prob=254, param2=4},
		{name="vlf_trees:tree_dark_oak", prob=254, param2=6},
		{name="air", prob=254, param2=0},
		{name="air", prob=254, param2=0},
		{name="air", prob=254, param2=0},
		{name="air", prob=254, param2=0},
		{name="air", prob=254, param2=0},
		{name="air", prob=254, param2=0},
		{name="air", prob=254, param2=0},
		{name="air", prob=254, param2=0},
		{name="air", prob=254, param2=0},
		{name="air", prob=254, param2=0},
		{name="air", prob=254, param2=0},
		{name="air", prob=254, param2=0},
		{name="air", prob=254, param2=0},
		{name="vlf_core:vine", prob=254, param2=4},
		{name="air", prob=254, param2=0},
		{name="vlf_core:vine", prob=254, param2=4},
		{name="air", prob=254, param2=0},
		{name="air", prob=254, param2=0},
		{name="air", prob=254, param2=0},
		{name="vlf_core:vine", prob=254, param2=4},
		{name="vlf_core:vine", prob=254, param2=4},
		{name="vlf_core:vine", prob=254, param2=4},
		{name="air", prob=254, param2=0},
		{name="air", prob=254, param2=0},
		{name="air", prob=254, param2=0},
		{name="air", prob=254, param2=0},
		{name="air", prob=254, param2=0},
		{name="air", prob=254, param2=0},
		{name="air", prob=254, param2=0},
		{name="air", prob=254, param2=0},
		{name="air", prob=254, param2=0},
		{name="air", prob=254, param2=0},
		{name="air", prob=254, param2=0},
		{name="air", prob=254, param2=0},
		{name="air", prob=254, param2=0},
		{name="air", prob=254, param2=0},
		{name="air", prob=254, param2=0},
		{name="air", prob=254, param2=0},
		{name="air", prob=254, param2=0},
		{name="air", prob=254, param2=0},
		{name="air", prob=254, param2=0},
		{name="air", prob=254, param2=0},
		{name="air", prob=254, param2=0},
		{name="air", prob=254, param2=0},
		{name="air", prob=254, param2=0},
		{name="air", prob=254, param2=0},
		{name="air", prob=254, param2=0},
		{name="air", prob=254, param2=0},
		{name="air", prob=254, param2=0},
		{name="air", prob=254, param2=0},
		{name="air", prob=254, param2=0},
		{name="air", prob=254, param2=0},
		{name="air", prob=254, param2=0},
		{name="air", prob=254, param2=0},
		{name="air", prob=254, param2=0},
		{name="vlf_stairs:slab_dark_oak", prob=254, param2=0},
		{name="vlf_stairs:stair_dark_oak", prob=254, param2=1},
		{name="vlf_stairs:slab_dark_oak_top", prob=254, param2=0},
		{name="air", prob=254, param2=0},
		{name="air", prob=254, param2=0},
		{name="air", prob=254, param2=0},
		{name="air", prob=254, param2=0},
		{name="air", prob=254, param2=0},
		{name="air", prob=254, param2=0},
		{name="air", prob=254, param2=0},
		{name="air", prob=254, param2=0},
		{name="air", prob=254, param2=0},
		{name="vlf_stairs:slab_dark_oak_top", prob=254, param2=0},
		{name="vlf_stairs:stair_dark_oak", prob=254, param2=3},
		{name="vlf_stairs:slab_dark_oak", prob=254, param2=0},
		{name="air", prob=254, param2=0},
		{name="air", prob=254, param2=0},
		{name="air", prob=254, param2=0},
		{name="air", prob=254, param2=0},
		{name="air", prob=254, param2=0},
		{name="air", prob=254, param2=0},
		{name="air", prob=254, param2=0},
		{name="air", prob=254, param2=0},
		{name="air", prob=254, param2=0},
		{name="air", prob=254, param2=0},
		{name="air", prob=254, param2=0},
		{name="vlf_stairs:slab_dark_oak", prob=254, param2=0},
		{name="vlf_stairs:stair_dark_oak", prob=254, param2=1},
		{name="vlf_stairs:slab_dark_oak_top", prob=254, param2=0},
		{name="air", prob=254, param2=0},
		{name="air", prob=254, param2=0},
		{name="air", prob=254, param2=0},
		{name="vlf_stairs:slab_dark_oak_top", prob=254, param2=0},
		{name="vlf_stairs:stair_dark_oak", prob=254, param2=3},
		{name="vlf_stairs:slab_dark_oak", prob=254, param2=0},
		{name="air", prob=254, param2=0},
		{name="air", prob=254, param2=0},
		{name="air", prob=254, param2=0},
		{name="air", prob=254, param2=0},
		{name="air", prob=254, param2=0},
		{name="air", prob=254, param2=0},
		{name="air", prob=254, param2=0},
		{name="air", prob=254, param2=0},
		{name="air", prob=254, param2=0},
		{name="air", prob=254, param2=0},
		{name="air", prob=254, param2=0},
		{name="air", prob=254, param2=0},
		{name="air", prob=254, param2=0},
		{name="air", prob=254, param2=0},
		{name="air", prob=254, param2=0},
		{name="air", prob=254, param2=0},
		{name="air", prob=254, param2=0},
		{name="vlf_stairs:slab_dark_oak", prob=254, param2=0},
		{name="vlf_stairs:slab_dark_oak_top", prob=254, param2=0},
		{name="vlf_stairs:slab_dark_oak", prob=254, param2=0},
		{name="air", prob=254, param2=0},
		{name="air", prob=254, param2=0},
		{name="air", prob=254, param2=0},
		{name="air", prob=254, param2=0},
		{name="air", prob=254, param2=0},
		{name="air", prob=254, param2=0},
		{name="air", prob=254, param2=0},
		{name="air", prob=254, param2=0},
		{name="air", prob=254, param2=0},
		{name="air", prob=254, param2=0},
		{name="air", prob=254, param2=0},
		{name="air", prob=254, param2=0},
		{name="air", prob=254, param2=0},
		{name="air", prob=254, param2=0},
		{name="air", prob=254, param2=0},
		{name="air", prob=254, param2=0},
		{name="air", prob=254, param2=0},
		{name="air", prob=254, param2=0},
		{name="air", prob=254, param2=0},
		{name="vlf_core:vine", prob=254, param2=4},
		{name="air", prob=254, param2=0},
		{name="air", prob=254, param2=0},
		{name="vlf_core:vine", prob=254, param2=4},
		{name="vlf_core:vine", prob=254, param2=4},
		{name="air", prob=254, param2=0},
		{name="air", prob=254, param2=0},
		{name="air", prob=254, param2=0},
		{name="air", prob=254, param2=0},
		{name="air", prob=254, param2=0},
		{name="air", prob=254, param2=0},
		{name="air", prob=254, param2=0},
		{name="air", prob=254, param2=0},
		{name="air", prob=254, param2=0},
		{name="air", prob=254, param2=0},
		{name="air", prob=254, param2=0},
		{name="air", prob=254, param2=0},
		{name="air", prob=254, param2=0},
		{name="air", prob=254, param2=0},
		{name="air", prob=254, param2=0},
		{name="air", prob=254, param2=0},
		{name="air", prob=254, param2=0},
		{name="air", prob=254, param2=0},
		{name="vlf_core:vine", prob=254, param2=4},
		{name="vlf_core:vine", prob=254, param2=4},
		{name="vlf_core:vine", prob=254, param2=4},
		{name="vlf_core:vine", prob=254, param2=4},
		{name="vlf_core:vine", prob=254, param2=4},
		{name="air", prob=254, param2=0},
		{name="air", prob=254, param2=0},
		{name="air", prob=254, param2=0},
		{name="air", prob=254, param2=0},
		{name="air", prob=254, param2=0},
		{name="air", prob=254, param2=0},
		{name="air", prob=254, param2=0},
		{name="air", prob=254, param2=0},
		{name="air", prob=254, param2=0},
		{name="air", prob=254, param2=0},
		{name="air", prob=254, param2=0},
		{name="air", prob=254, param2=0},
		{name="air", prob=254, param2=0},
		{name="air", prob=254, param2=0},
		{name="air", prob=254, param2=0},
		{name="air", prob=254, param2=0},
		{name="air", prob=254, param2=0},
		{name="air", prob=254, param2=0},
		{name="vlf_core:vine", prob=254, param2=4},
		{name="vlf_core:vine", prob=254, param2=4},
		{name="vlf_core:vine", prob=254, param2=4},
		{name="vlf_core:vine", prob=254, param2=4},
		{name="air", prob=254, param2=0},
		{name="air", prob=254, param2=0},
		{name="air", prob=254, param2=0},
		{name="air", prob=254, param2=0},
		{name="air", prob=254, param2=0},
		{name="air", prob=254, param2=0},
		{name="air", prob=254, param2=0},
		{name="air", prob=254, param2=0},
		{name="air", prob=254, param2=0},
		{name="air", prob=254, param2=0},
		{name="air", prob=254, param2=0},
		{name="air", prob=254, param2=0},
		{name="air", prob=254, param2=0},
		{name="air", prob=254, param2=0},
		{name="air", prob=254, param2=0},
		{name="air", prob=254, param2=0},
		{name="air", prob=254, param2=0},
		{name="vlf_core:vine", prob=254, param2=4},
		{name="air", prob=254, param2=0},
		{name="vlf_core:vine", prob=254, param2=4},
		{name="vlf_core:vine", prob=254, param2=4},
		{name="air", prob=254, param2=0},
		{name="air", prob=254, param2=0},
		{name="vlf_core:vine", prob=254, param2=4},
		{name="air", prob=254, param2=0},
		{name="vlf_core:vine", prob=254, param2=4},
		{name="air", prob=254, param2=0},
		{name="air", prob=254, param2=0},
		{name="air", prob=254, param2=0},
		{name="air", prob=254, param2=0},
		{name="air", prob=254, param2=0},
		{name="air", prob=254, param2=0},
		{name="air", prob=254, param2=0},
		{name="air", prob=254, param2=0},
		{name="air", prob=254, param2=0},
		{name="air", prob=254, param2=0},
		{name="air", prob=254, param2=0},
		{name="air", prob=254, param2=0},
		{name="air", prob=254, param2=0},
		{name="air", prob=254, param2=0},
		{name="vlf_core:vine", prob=254, param2=4},
		{name="air", prob=254, param2=0},
		{name="vlf_core:vine", prob=254, param2=4},
		{name="air", prob=254, param2=0},
		{name="air", prob=254, param2=0},
		{name="air", prob=254, param2=0},
		{name="vlf_core:vine", prob=254, param2=4},
		{name="air", prob=254, param2=0},
		{name="vlf_core:vine", prob=254, param2=4},
		{name="air", prob=254, param2=0},
		{name="air", prob=254, param2=0},
		{name="air", prob=254, param2=0},
		{name="air", prob=254, param2=0},
		{name="air", prob=254, param2=0},
		{name="air", prob=254, param2=0},
		{name="air", prob=254, param2=0},
		{name="air", prob=254, param2=0},
		{name="air", prob=254, param2=0},
		{name="air", prob=254, param2=0},
		{name="air", prob=254, param2=0},
		{name="air", prob=254, param2=0},
		{name="air", prob=254, param2=0},
		{name="air", prob=254, param2=0},
		{name="vlf_core:vine", prob=254, param2=4},
		{name="air", prob=254, param2=0},
		{name="air", prob=254, param2=0},
		{name="air", prob=254, param2=0},
		{name="air", prob=254, param2=0},
		{name="vlf_core:vine", prob=254, param2=4},
		{name="vlf_core:vine", prob=254, param2=4},
		{name="vlf_core:vine", prob=254, param2=4},
		{name="vlf_core:vine", prob=254, param2=4},
		{name="air", prob=254, param2=0},
		{name="air", prob=254, param2=0},
		{name="air", prob=254, param2=0},
		{name="air", prob=254, param2=0},
		{name="air", prob=254, param2=0},
		{name="air", prob=254, param2=0},
		{name="air", prob=254, param2=0},
		{name="air", prob=254, param2=0},
		{name="air", prob=254, param2=0},
		{name="air", prob=254, param2=0},
		{name="air", prob=254, param2=0},
		{name="air", prob=254, param2=0},
		{name="air", prob=254, param2=0},
		{name="vlf_core:vine", prob=254, param2=4},
		{name="vlf_core:vine", prob=254, param2=4},
		{name="air", prob=254, param2=0},
		{name="air", prob=254, param2=0},
		{name="air", prob=254, param2=0},
		{name="air", prob=254, param2=0},
		{name="vlf_core:vine", prob=254, param2=4},
		{name="vlf_core:vine", prob=254, param2=4},
		{name="vlf_core:vine", prob=254, param2=4},
		{name="vlf_core:vine", prob=254, param2=4},
		{name="air", prob=254, param2=0},
		{name="air", prob=254, param2=0},
		{name="air", prob=254, param2=0},
		{name="air", prob=254, param2=0},
		{name="air", prob=254, param2=0},
		{name="air", prob=254, param2=0},
		{name="air", prob=254, param2=0},
		{name="air", prob=254, param2=0},
		{name="air", prob=254, param2=0},
		{name="air", prob=254, param2=0},
		{name="air", prob=254, param2=0},
		{name="air", prob=254, param2=0},
		{name="vlf_stairs:stair_dark_oak", prob=254, param2=23},
		{name="vlf_trees:tree_dark_oak", prob=254, param2=6},
		{name="vlf_stairs:stair_dark_oak", prob=254, param2=20},
		{name="vlf_stairs:stair_dark_oak", prob=254, param2=20},
		{name="vlf_stairs:stair_dark_oak", prob=254, param2=20},
		{name="vlf_stairs:stair_dark_oak", prob=254, param2=20},
		{name="vlf_stairs:stair_dark_oak", prob=254, param2=20},
		{name="vlf_stairs:stair_dark_oak", prob=254, param2=20},
		{name="vlf_stairs:stair_dark_oak", prob=254, param2=20},
		{name="vlf_stairs:stair_dark_oak", prob=254, param2=20},
		{name="vlf_stairs:stair_dark_oak", prob=254, param2=20},
		{name="vlf_trees:tree_dark_oak", prob=254, param2=6},
		{name="vlf_stairs:stair_dark_oak", prob=254, param2=21},
		{name="vlf_core:vine", prob=254, param2=3},
		{name="air", prob=254, param2=0},
		{name="air", prob=254, param2=0},
		{name="air", prob=254, param2=0},
		{name="air", prob=254, param2=0},
		{name="air", prob=254, param2=0},
		{name="air", prob=254, param2=0},
		{name="air", prob=254, param2=0},
		{name="air", prob=254, param2=0},
		{name="air", prob=254, param2=0},
		{name="vlf_trees:tree_dark_oak", prob=254, param2=0},
		{name="vlf_trees:stripped_dark_oak", prob=254, param2=0},
		{name="vlf_trees:stripped_dark_oak", prob=254, param2=0},
		{name="vlf_trees:stripped_dark_oak", prob=254, param2=0},
		{name="vlf_trees:stripped_dark_oak", prob=254, param2=0},
		{name="vlf_trees:stripped_dark_oak", prob=254, param2=0},
		{name="vlf_trees:stripped_dark_oak", prob=254, param2=0},
		{name="vlf_trees:stripped_dark_oak", prob=254, param2=0},
		{name="vlf_trees:stripped_dark_oak", prob=254, param2=0},
		{name="vlf_trees:stripped_dark_oak", prob=254, param2=0},
		{name="vlf_trees:stripped_dark_oak", prob=254, param2=0},
		{name="vlf_trees:stripped_dark_oak", prob=254, param2=0},
		{name="vlf_trees:tree_dark_oak", prob=254, param2=0},
		{name="vlf_core:vine", prob=254, param2=3},
		{name="air", prob=254, param2=0},
		{name="air", prob=254, param2=0},
		{name="air", prob=254, param2=0},
		{name="air", prob=254, param2=0},
		{name="air", prob=254, param2=0},
		{name="air", prob=254, param2=0},
		{name="air", prob=254, param2=0},
		{name="air", prob=254, param2=0},
		{name="air", prob=254, param2=0},
		{name="vlf_trees:tree_dark_oak", prob=254, param2=0},
		{name="vlf_trees:stripped_dark_oak", prob=254, param2=0},
		{name="vlf_panes:pane_black_flat", prob=254, param2=0},
		{name="vlf_trees:stripped_dark_oak", prob=254, param2=0},
		{name="vlf_panes:pane_black_flat", prob=254, param2=0},
		{name="vlf_trees:stripped_dark_oak", prob=254, param2=0},
		{name="vlf_panes:pane_black_flat", prob=254, param2=0},
		{name="vlf_trees:stripped_dark_oak", prob=254, param2=0},
		{name="vlf_panes:pane_black_flat", prob=254, param2=0},
		{name="vlf_trees:stripped_dark_oak", prob=254, param2=0},
		{name="vlf_panes:pane_black_flat", prob=254, param2=0},
		{name="vlf_trees:stripped_dark_oak", prob=254, param2=0},
		{name="vlf_trees:tree_dark_oak", prob=254, param2=0},
		{name="vlf_core:vine", prob=254, param2=3},
		{name="air", prob=254, param2=0},
		{name="air", prob=254, param2=0},
		{name="air", prob=254, param2=0},
		{name="air", prob=254, param2=0},
		{name="air", prob=254, param2=0},
		{name="air", prob=254, param2=0},
		{name="air", prob=254, param2=0},
		{name="air", prob=254, param2=0},
		{name="vlf_lanterns:soul_lantern_ceiling", prob=254, param2=0},
		{name="vlf_trees:tree_dark_oak", prob=254, param2=0},
		{name="vlf_trees:stripped_dark_oak", prob=254, param2=0},
		{name="vlf_panes:pane_black_flat", prob=254, param2=0},
		{name="vlf_trees:stripped_dark_oak", prob=254, param2=0},
		{name="vlf_panes:pane_black_flat", prob=254, param2=0},
		{name="vlf_trees:stripped_dark_oak", prob=254, param2=0},
		{name="vlf_panes:pane_black_flat", prob=254, param2=0},
		{name="vlf_trees:stripped_dark_oak", prob=254, param2=0},
		{name="vlf_panes:pane_black_flat", prob=254, param2=0},
		{name="vlf_trees:stripped_dark_oak", prob=254, param2=0},
		{name="vlf_panes:pane_black_flat", prob=254, param2=0},
		{name="vlf_trees:stripped_dark_oak", prob=254, param2=0},
		{name="vlf_trees:tree_dark_oak", prob=254, param2=0},
		{name="vlf_lanterns:soul_lantern_ceiling", prob=254, param2=0},
		{name="air", prob=254, param2=0},
		{name="air", prob=254, param2=0},
		{name="air", prob=254, param2=0},
		{name="air", prob=254, param2=0},
		{name="air", prob=254, param2=0},
		{name="air", prob=254, param2=0},
		{name="air", prob=254, param2=0},
		{name="air", prob=254, param2=0},
		{name="vlf_lanterns:chain", prob=254, param2=20},
		{name="vlf_trees:tree_dark_oak", prob=254, param2=0},
		{name="vlf_trees:stripped_dark_oak", prob=254, param2=0},
		{name="vlf_panes:pane_black_flat", prob=254, param2=0},
		{name="vlf_trees:stripped_dark_oak", prob=254, param2=0},
		{name="vlf_panes:pane_black_flat", prob=254, param2=0},
		{name="vlf_trees:stripped_dark_oak", prob=254, param2=0},
		{name="vlf_panes:pane_black_flat", prob=254, param2=0},
		{name="vlf_trees:stripped_dark_oak", prob=254, param2=0},
		{name="vlf_panes:pane_black_flat", prob=254, param2=0},
		{name="vlf_trees:stripped_dark_oak", prob=254, param2=0},
		{name="vlf_panes:pane_black_flat", prob=254, param2=0},
		{name="vlf_trees:stripped_dark_oak", prob=254, param2=0},
		{name="vlf_trees:tree_dark_oak", prob=254, param2=0},
		{name="vlf_lanterns:chain", prob=254, param2=20},
		{name="air", prob=254, param2=0},
		{name="air", prob=254, param2=0},
		{name="air", prob=254, param2=0},
		{name="air", prob=254, param2=0},
		{name="air", prob=254, param2=0},
		{name="air", prob=254, param2=0},
		{name="air", prob=254, param2=0},
		{name="air", prob=254, param2=0},
		{name="vlf_lanterns:chain", prob=254, param2=20},
		{name="vlf_trees:tree_dark_oak", prob=254, param2=6},
		{name="vlf_trees:stripped_dark_oak", prob=254, param2=0},
		{name="vlf_trees:stripped_dark_oak", prob=254, param2=0},
		{name="vlf_trees:stripped_dark_oak", prob=254, param2=0},
		{name="vlf_trees:stripped_dark_oak", prob=254, param2=0},
		{name="vlf_trees:stripped_dark_oak", prob=254, param2=0},
		{name="vlf_trees:stripped_dark_oak", prob=254, param2=0},
		{name="vlf_trees:stripped_dark_oak", prob=254, param2=0},
		{name="vlf_trees:stripped_dark_oak", prob=254, param2=0},
		{name="vlf_trees:stripped_dark_oak", prob=254, param2=0},
		{name="vlf_trees:stripped_dark_oak", prob=254, param2=0},
		{name="vlf_trees:stripped_dark_oak", prob=254, param2=0},
		{name="vlf_trees:tree_dark_oak", prob=254, param2=6},
		{name="vlf_lanterns:chain", prob=254, param2=20},
		{name="air", prob=254, param2=0},
		{name="air", prob=254, param2=0},
		{name="air", prob=254, param2=0},
		{name="air", prob=254, param2=0},
		{name="air", prob=254, param2=0},
		{name="air", prob=254, param2=0},
		{name="air", prob=254, param2=0},
		{name="air", prob=254, param2=0},
		{name="vlf_trees:tree_dark_oak", prob=254, param2=12},
		{name="vlf_trees:tree_dark_oak", prob=254, param2=12},
		{name="vlf_trees:tree_dark_oak", prob=254, param2=12},
		{name="vlf_trees:tree_dark_oak", prob=254, param2=12},
		{name="vlf_trees:tree_dark_oak", prob=254, param2=12},
		{name="vlf_trees:tree_dark_oak", prob=254, param2=12},
		{name="vlf_trees:tree_dark_oak", prob=254, param2=12},
		{name="vlf_trees:tree_dark_oak", prob=254, param2=12},
		{name="vlf_trees:tree_dark_oak", prob=254, param2=12},
		{name="vlf_trees:tree_dark_oak", prob=254, param2=12},
		{name="vlf_trees:tree_dark_oak", prob=254, param2=12},
		{name="vlf_trees:tree_dark_oak", prob=254, param2=12},
		{name="vlf_trees:tree_dark_oak", prob=254, param2=12},
		{name="vlf_trees:tree_dark_oak", prob=254, param2=12},
		{name="vlf_trees:tree_dark_oak", prob=254, param2=12},
		{name="air", prob=254, param2=0},
		{name="air", prob=254, param2=0},
		{name="air", prob=254, param2=0},
		{name="air", prob=254, param2=0},
		{name="air", prob=254, param2=0},
		{name="air", prob=254, param2=0},
		{name="air", prob=254, param2=0},
		{name="air", prob=254, param2=0},
		{name="air", prob=254, param2=0},
		{name="vlf_stairs:stair_oak", prob=254, param2=23},
		{name="vlf_stairs:stair_oak", prob=254, param2=20},
		{name="vlf_stairs:stair_oak", prob=254, param2=20},
		{name="vlf_stairs:stair_oak", prob=254, param2=20},
		{name="vlf_stairs:stair_oak", prob=254, param2=20},
		{name="vlf_stairs:stair_oak", prob=254, param2=20},
		{name="vlf_stairs:stair_oak", prob=254, param2=20},
		{name="vlf_stairs:stair_oak", prob=254, param2=20},
		{name="vlf_stairs:stair_oak", prob=254, param2=20},
		{name="vlf_stairs:stair_oak", prob=254, param2=20},
		{name="vlf_stairs:stair_oak", prob=254, param2=20},
		{name="vlf_stairs:stair_oak", prob=254, param2=20},
		{name="vlf_stairs:stair_oak", prob=254, param2=21},
		{name="air", prob=254, param2=0},
		{name="air", prob=254, param2=0},
		{name="air", prob=254, param2=0},
		{name="air", prob=254, param2=0},
		{name="air", prob=254, param2=0},
		{name="air", prob=254, param2=0},
		{name="air", prob=254, param2=0},
		{name="air", prob=254, param2=0},
		{name="air", prob=254, param2=0},
		{name="vlf_stairs:slab_dark_oak", prob=254, param2=0},
		{name="vlf_stairs:stair_dark_oak", prob=254, param2=1},
		{name="vlf_trees:wood_dark_oak", prob=254, param2=0},
		{name="vlf_panes:pane_black_flat", prob=254, param2=0},
		{name="vlf_panes:pane_black_flat", prob=254, param2=0},
		{name="vlf_panes:pane_black_flat", prob=254, param2=0},
		{name="vlf_panes:pane_black_flat", prob=254, param2=0},
		{name="vlf_panes:pane_black_flat", prob=254, param2=0},
		{name="vlf_panes:pane_black_flat", prob=254, param2=0},
		{name="vlf_panes:pane_black_flat", prob=254, param2=0},
		{name="vlf_panes:pane_black_flat", prob=254, param2=0},
		{name="vlf_panes:pane_black_flat", prob=254, param2=0},
		{name="vlf_trees:wood_dark_oak", prob=254, param2=0},
		{name="vlf_stairs:stair_dark_oak", prob=254, param2=3},
		{name="vlf_stairs:slab_dark_oak", prob=254, param2=0},
		{name="air", prob=254, param2=0},
		{name="air", prob=254, param2=0},
		{name="air", prob=254, param2=0},
		{name="air", prob=254, param2=0},
		{name="air", prob=254, param2=0},
		{name="air", prob=254, param2=0},
		{name="air", prob=254, param2=0},
		{name="air", prob=254, param2=0},
		{name="air", prob=254, param2=0},
		{name="air", prob=254, param2=0},
		{name="air", prob=254, param2=0},
		{name="vlf_stairs:slab_dark_oak", prob=254, param2=0},
		{name="vlf_stairs:stair_dark_oak", prob=254, param2=1},
		{name="vlf_trees:wood_dark_oak", prob=254, param2=0},
		{name="vlf_panes:pane_black_flat", prob=254, param2=0},
		{name="vlf_panes:pane_black_flat", prob=254, param2=0},
		{name="vlf_panes:pane_black_flat", prob=254, param2=0},
		{name="vlf_trees:wood_dark_oak", prob=254, param2=0},
		{name="vlf_stairs:stair_dark_oak", prob=254, param2=3},
		{name="vlf_stairs:slab_dark_oak", prob=254, param2=0},
		{name="air", prob=254, param2=0},
		{name="air", prob=254, param2=0},
		{name="air", prob=254, param2=0},
		{name="air", prob=254, param2=0},
		{name="air", prob=254, param2=0},
		{name="air", prob=254, param2=0},
		{name="air", prob=254, param2=0},
		{name="air", prob=254, param2=0},
		{name="air", prob=254, param2=0},
		{name="air", prob=254, param2=0},
		{name="air", prob=254, param2=0},
		{name="air", prob=254, param2=0},
		{name="air", prob=254, param2=0},
		{name="air", prob=254, param2=0},
		{name="air", prob=254, param2=0},
		{name="air", prob=254, param2=0},
		{name="air", prob=254, param2=0},
		{name="vlf_stairs:slab_dark_oak", prob=254, param2=0},
		{name="vlf_trees:wood_dark_oak", prob=254, param2=0},
		{name="vlf_stairs:slab_dark_oak", prob=254, param2=0},
		{name="air", prob=254, param2=0},
		{name="air", prob=254, param2=0},
		{name="air", prob=254, param2=0},
		{name="air", prob=254, param2=0},
		{name="air", prob=254, param2=0},
		{name="air", prob=254, param2=0},
		{name="air", prob=254, param2=0},
		{name="air", prob=254, param2=0},
		{name="air", prob=254, param2=0},
		{name="air", prob=254, param2=0},
		{name="air", prob=254, param2=0},
		{name="air", prob=254, param2=0},
		{name="air", prob=254, param2=0},
		{name="air", prob=254, param2=0},
		{name="air", prob=254, param2=0},
		{name="air", prob=254, param2=0},
		{name="vlf_trees:tree_dark_oak", prob=254, param2=0},
		{name="vlf_core:stonebrick", prob=254, param2=0},
		{name="vlf_core:mossycobble", prob=254, param2=0},
		{name="vlf_core:stonebrick", prob=254, param2=0},
		{name="vlf_core:stonebrickcracked", prob=254, param2=0},
		{name="vlf_core:stonebrickmossy", prob=254, param2=0},
		{name="vlf_core:stonebrick", prob=254, param2=0},
		{name="vlf_core:stonebrick", prob=254, param2=0},
		{name="vlf_core:stonebrickcracked", prob=254, param2=0},
		{name="vlf_core:stonebrickmossy", prob=254, param2=0},
		{name="vlf_trees:tree_dark_oak", prob=254, param2=0},
		{name="air", prob=254, param2=0},
		{name="air", prob=254, param2=0},
		{name="air", prob=254, param2=0},
		{name="air", prob=254, param2=0},
		{name="air", prob=254, param2=0},
		{name="air", prob=254, param2=0},
		{name="air", prob=254, param2=0},
		{name="air", prob=254, param2=0},
		{name="air", prob=254, param2=0},
		{name="air", prob=254, param2=0},
		{name="air", prob=254, param2=0},
		{name="air", prob=254, param2=0},
		{name="vlf_trees:tree_dark_oak", prob=254, param2=0},
		{name="vlf_core:stonebrickmossy", prob=254, param2=0},
		{name="vlf_core:stonebrickcracked", prob=254, param2=0},
		{name="vlf_core:stonebrick", prob=254, param2=0},
		{name="vlf_core:mossycobble", prob=254, param2=0},
		{name="vlf_core:stonebrick", prob=254, param2=0},
		{name="vlf_core:stonebrickcracked", prob=254, param2=0},
		{name="vlf_core:stonebrickmossy", prob=254, param2=0},
		{name="vlf_core:mossycobble", prob=254, param2=0},
		{name="vlf_core:stonebrick", prob=254, param2=0},
		{name="vlf_trees:tree_dark_oak", prob=254, param2=0},
		{name="air", prob=254, param2=0},
		{name="air", prob=254, param2=0},
		{name="air", prob=254, param2=0},
		{name="air", prob=254, param2=0},
		{name="air", prob=254, param2=0},
		{name="air", prob=254, param2=0},
		{name="air", prob=254, param2=0},
		{name="air", prob=254, param2=0},
		{name="air", prob=254, param2=0},
		{name="air", prob=254, param2=0},
		{name="air", prob=254, param2=0},
		{name="air", prob=254, param2=0},
		{name="vlf_trees:tree_dark_oak", prob=254, param2=0},
		{name="vlf_trees:tree_dark_oak", prob=254, param2=12},
		{name="vlf_trees:tree_dark_oak", prob=254, param2=12},
		{name="vlf_trees:tree_dark_oak", prob=254, param2=12},
		{name="vlf_trees:tree_dark_oak", prob=254, param2=12},
		{name="vlf_trees:tree_dark_oak", prob=254, param2=12},
		{name="vlf_trees:tree_dark_oak", prob=254, param2=12},
		{name="vlf_trees:tree_dark_oak", prob=254, param2=12},
		{name="vlf_trees:tree_dark_oak", prob=254, param2=12},
		{name="vlf_trees:tree_dark_oak", prob=254, param2=12},
		{name="vlf_trees:tree_dark_oak", prob=254, param2=0},
		{name="air", prob=254, param2=0},
		{name="air", prob=254, param2=0},
		{name="air", prob=254, param2=0},
		{name="air", prob=254, param2=0},
		{name="air", prob=254, param2=0},
		{name="air", prob=254, param2=0},
		{name="air", prob=254, param2=0},
		{name="air", prob=254, param2=0},
		{name="air", prob=254, param2=0},
		{name="air", prob=254, param2=0},
		{name="air", prob=254, param2=0},
		{name="air", prob=254, param2=0},
		{name="vlf_trees:tree_dark_oak", prob=254, param2=0},
		{name="vlf_trees:stripped_dark_oak", prob=254, param2=0},
		{name="vlf_trees:stripped_dark_oak", prob=254, param2=0},
		{name="vlf_trees:stripped_dark_oak", prob=254, param2=0},
		{name="vlf_trees:stripped_dark_oak", prob=254, param2=0},
		{name="vlf_trees:stripped_dark_oak", prob=254, param2=0},
		{name="vlf_trees:stripped_dark_oak", prob=254, param2=0},
		{name="vlf_trees:stripped_dark_oak", prob=254, param2=0},
		{name="vlf_trees:stripped_dark_oak", prob=254, param2=0},
		{name="vlf_trees:stripped_dark_oak", prob=254, param2=0},
		{name="vlf_trees:tree_dark_oak", prob=254, param2=0},
		{name="air", prob=254, param2=0},
		{name="air", prob=254, param2=0},
		{name="air", prob=254, param2=0},
		{name="air", prob=254, param2=0},
		{name="air", prob=254, param2=0},
		{name="air", prob=254, param2=0},
		{name="air", prob=254, param2=0},
		{name="air", prob=254, param2=0},
		{name="air", prob=254, param2=0},
		{name="air", prob=254, param2=0},
		{name="air", prob=254, param2=0},
		{name="air", prob=254, param2=0},
		{name="vlf_trees:tree_dark_oak", prob=254, param2=0},
		{name="vlf_trees:stripped_dark_oak", prob=254, param2=0},
		{name="vlf_trees:stripped_dark_oak", prob=254, param2=0},
		{name="vlf_trees:stripped_dark_oak", prob=254, param2=0},
		{name="vlf_trees:stripped_dark_oak", prob=254, param2=0},
		{name="vlf_trees:stripped_dark_oak", prob=254, param2=0},
		{name="vlf_trees:stripped_dark_oak", prob=254, param2=0},
		{name="vlf_trees:stripped_dark_oak", prob=254, param2=0},
		{name="vlf_trees:stripped_dark_oak", prob=254, param2=0},
		{name="vlf_trees:stripped_dark_oak", prob=254, param2=0},
		{name="vlf_trees:tree_dark_oak", prob=254, param2=0},
		{name="air", prob=254, param2=0},
		{name="air", prob=254, param2=0},
		{name="air", prob=254, param2=0},
		{name="air", prob=254, param2=0},
		{name="air", prob=254, param2=0},
		{name="air", prob=254, param2=0},
		{name="air", prob=254, param2=0},
		{name="air", prob=254, param2=0},
		{name="air", prob=254, param2=0},
		{name="air", prob=254, param2=0},
		{name="vlf_lanterns:soul_lantern_ceiling", prob=254, param2=0},
		{name="air", prob=254, param2=0},
		{name="vlf_trees:tree_dark_oak", prob=254, param2=0},
		{name="vlf_trees:stripped_dark_oak", prob=254, param2=0},
		{name="vlf_trees:stripped_dark_oak", prob=254, param2=0},
		{name="vlf_trees:stripped_dark_oak", prob=254, param2=0},
		{name="vlf_trees:stripped_dark_oak", prob=254, param2=0},
		{name="vlf_trees:stripped_dark_oak", prob=254, param2=0},
		{name="vlf_trees:stripped_dark_oak", prob=254, param2=0},
		{name="vlf_trees:stripped_dark_oak", prob=254, param2=0},
		{name="vlf_trees:stripped_dark_oak", prob=254, param2=0},
		{name="vlf_trees:stripped_dark_oak", prob=254, param2=0},
		{name="vlf_trees:tree_dark_oak", prob=254, param2=0},
		{name="air", prob=254, param2=0},
		{name="vlf_lanterns:soul_lantern_ceiling", prob=254, param2=0},
		{name="air", prob=254, param2=0},
		{name="air", prob=254, param2=0},
		{name="air", prob=254, param2=0},
		{name="air", prob=254, param2=0},
		{name="air", prob=254, param2=0},
		{name="air", prob=254, param2=0},
		{name="air", prob=254, param2=0},
		{name="air", prob=254, param2=0},
		{name="vlf_lanterns:chain", prob=254, param2=20},
		{name="air", prob=254, param2=0},
		{name="vlf_trees:tree_dark_oak", prob=254, param2=0},
		{name="vlf_trees:stripped_dark_oak", prob=254, param2=0},
		{name="vlf_trees:stripped_dark_oak", prob=254, param2=0},
		{name="vlf_trees:stripped_dark_oak", prob=254, param2=0},
		{name="vlf_trees:stripped_dark_oak", prob=254, param2=0},
		{name="vlf_trees:stripped_dark_oak", prob=254, param2=0},
		{name="vlf_trees:stripped_dark_oak", prob=254, param2=0},
		{name="vlf_trees:stripped_dark_oak", prob=254, param2=0},
		{name="vlf_trees:stripped_dark_oak", prob=254, param2=0},
		{name="vlf_trees:stripped_dark_oak", prob=254, param2=0},
		{name="vlf_trees:tree_dark_oak", prob=254, param2=0},
		{name="air", prob=254, param2=0},
		{name="vlf_lanterns:chain", prob=254, param2=20},
		{name="air", prob=254, param2=0},
		{name="air", prob=254, param2=0},
		{name="air", prob=254, param2=0},
		{name="air", prob=254, param2=0},
		{name="air", prob=254, param2=0},
		{name="air", prob=254, param2=0},
		{name="air", prob=254, param2=0},
		{name="air", prob=254, param2=0},
		{name="vlf_fences:dark_oak_fence", prob=254, param2=0},
		{name="vlf_trees:tree_dark_oak", prob=254, param2=12},
		{name="vlf_trees:tree_dark_oak", prob=254, param2=0},
		{name="vlf_trees:tree_dark_oak", prob=254, param2=12},
		{name="vlf_trees:tree_dark_oak", prob=254, param2=12},
		{name="vlf_trees:tree_dark_oak", prob=254, param2=12},
		{name="vlf_trees:tree_dark_oak", prob=254, param2=12},
		{name="vlf_trees:tree_dark_oak", prob=254, param2=12},
		{name="vlf_trees:tree_dark_oak", prob=254, param2=12},
		{name="vlf_trees:tree_dark_oak", prob=254, param2=12},
		{name="vlf_trees:tree_dark_oak", prob=254, param2=12},
		{name="vlf_trees:tree_dark_oak", prob=254, param2=12},
		{name="vlf_trees:tree_dark_oak", prob=254, param2=0},
		{name="vlf_trees:tree_dark_oak", prob=254, param2=12},
		{name="vlf_fences:dark_oak_fence", prob=254, param2=0},
		{name="air", prob=254, param2=0},
		{name="air", prob=254, param2=0},
		{name="air", prob=254, param2=0},
		{name="air", prob=254, param2=0},
		{name="air", prob=254, param2=0},
		{name="air", prob=254, param2=0},
		{name="air", prob=254, param2=0},
		{name="air", prob=254, param2=0},
		{name="air", prob=254, param2=0},
		{name="vlf_trees:stripped_dark_oak", prob=254, param2=0},
		{name="vlf_stairs:slab_dark_oak_top", prob=254, param2=0},
		{name="vlf_stairs:slab_dark_oak_top", prob=254, param2=0},
		{name="vlf_stairs:slab_dark_oak_top", prob=254, param2=0},
		{name="vlf_chests:chest_small", prob=254, param2=2},
		{name="vlf_fences:dark_oak_fence", prob=254, param2=0},
		{name="air", prob=254, param2=0},
		{name="air", prob=254, param2=0},
		{name="air", prob=254, param2=0},
		{name="air", prob=254, param2=0},
		{name="air", prob=254, param2=0},
		{name="air", prob=254, param2=0},
		{name="vlf_trees:stripped_dark_oak", prob=254, param2=0},
		{name="vlf_core:vine", prob=254, param2=3},
		{name="air", prob=254, param2=0},
		{name="air", prob=254, param2=0},
		{name="air", prob=254, param2=0},
		{name="air", prob=254, param2=0},
		{name="air", prob=254, param2=0},
		{name="air", prob=254, param2=0},
		{name="air", prob=254, param2=0},
		{name="air", prob=254, param2=0},
		{name="air", prob=254, param2=0},
		{name="vlf_trees:stripped_dark_oak", prob=254, param2=0},
		{name="vlf_flowerpots:flower_pot_dandelion", prob=254, param2=0},
		{name="vlf_flowerpots:flower_pot_poppy", prob=254, param2=0},
		{name="vlf_flowerpots:flower_pot_blue_orchid", prob=254, param2=0},
		{name="air", prob=254, param2=0},
		{name="air", prob=254, param2=0},
		{name="air", prob=254, param2=0},
		{name="air", prob=254, param2=0},
		{name="air", prob=254, param2=0},
		{name="air", prob=254, param2=0},
		{name="air", prob=254, param2=0},
		{name="air", prob=254, param2=0},
		{name="vlf_trees:stripped_dark_oak", prob=254, param2=0},
		{name="vlf_core:vine", prob=254, param2=3},
		{name="air", prob=254, param2=0},
		{name="air", prob=254, param2=0},
		{name="air", prob=254, param2=0},
		{name="air", prob=254, param2=0},
		{name="air", prob=254, param2=0},
		{name="air", prob=254, param2=0},
		{name="air", prob=254, param2=0},
		{name="air", prob=254, param2=0},
		{name="air", prob=254, param2=0},
		{name="vlf_trees:stripped_dark_oak", prob=254, param2=0},
		{name="air", prob=254, param2=0},
		{name="air", prob=254, param2=0},
		{name="air", prob=254, param2=0},
		{name="air", prob=254, param2=0},
		{name="air", prob=254, param2=0},
		{name="air", prob=254, param2=0},
		{name="air", prob=254, param2=0},
		{name="air", prob=254, param2=0},
		{name="air", prob=254, param2=0},
		{name="air", prob=254, param2=0},
		{name="air", prob=254, param2=0},
		{name="vlf_trees:stripped_dark_oak", prob=254, param2=0},
		{name="air", prob=254, param2=0},
		{name="air", prob=254, param2=0},
		{name="air", prob=254, param2=0},
		{name="air", prob=254, param2=0},
		{name="air", prob=254, param2=0},
		{name="air", prob=254, param2=0},
		{name="air", prob=254, param2=0},
		{name="air", prob=254, param2=0},
		{name="air", prob=254, param2=0},
		{name="air", prob=254, param2=0},
		{name="vlf_trees:stripped_dark_oak", prob=254, param2=0},
		{name="air", prob=254, param2=0},
		{name="air", prob=254, param2=0},
		{name="air", prob=254, param2=0},
		{name="air", prob=254, param2=0},
		{name="air", prob=254, param2=0},
		{name="air", prob=254, param2=0},
		{name="air", prob=254, param2=0},
		{name="air", prob=254, param2=0},
		{name="air", prob=254, param2=0},
		{name="air", prob=254, param2=0},
		{name="air", prob=254, param2=0},
		{name="vlf_trees:stripped_dark_oak", prob=254, param2=0},
		{name="air", prob=254, param2=0},
		{name="air", prob=254, param2=0},
		{name="air", prob=254, param2=0},
		{name="air", prob=254, param2=0},
		{name="air", prob=254, param2=0},
		{name="air", prob=254, param2=0},
		{name="air", prob=254, param2=0},
		{name="air", prob=254, param2=0},
		{name="air", prob=254, param2=0},
		{name="air", prob=254, param2=0},
		{name="vlf_trees:tree_dark_oak", prob=254, param2=6},
		{name="vlf_trees:stripped_oak", prob=254, param2=12},
		{name="vlf_trees:stripped_oak", prob=254, param2=12},
		{name="vlf_trees:stripped_oak", prob=254, param2=12},
		{name="air", prob=254, param2=0},
		{name="air", prob=254, param2=0},
		{name="air", prob=254, param2=0},
		{name="air", prob=254, param2=0},
		{name="air", prob=254, param2=0},
		{name="air", prob=254, param2=0},
		{name="air", prob=254, param2=0},
		{name="air", prob=254, param2=0},
		{name="vlf_trees:tree_dark_oak", prob=254, param2=6},
		{name="air", prob=254, param2=0},
		{name="air", prob=254, param2=0},
		{name="air", prob=254, param2=0},
		{name="air", prob=254, param2=0},
		{name="air", prob=254, param2=0},
		{name="air", prob=254, param2=0},
		{name="air", prob=254, param2=0},
		{name="air", prob=254, param2=0},
		{name="air", prob=254, param2=0},
		{name="air", prob=254, param2=0},
		{name="vlf_stairs:stair_oak", prob=254, param2=1},
		{name="air", prob=254, param2=0},
		{name="air", prob=254, param2=0},
		{name="air", prob=254, param2=0},
		{name="air", prob=254, param2=0},
		{name="air", prob=254, param2=0},
		{name="air", prob=254, param2=0},
		{name="air", prob=254, param2=0},
		{name="air", prob=254, param2=0},
		{name="air", prob=254, param2=0},
		{name="air", prob=254, param2=0},
		{name="air", prob=254, param2=0},
		{name="vlf_stairs:stair_oak", prob=254, param2=3},
		{name="air", prob=254, param2=0},
		{name="air", prob=254, param2=0},
		{name="air", prob=254, param2=0},
		{name="air", prob=254, param2=0},
		{name="air", prob=254, param2=0},
		{name="air", prob=254, param2=0},
		{name="air", prob=254, param2=0},
		{name="air", prob=254, param2=0},
		{name="air", prob=254, param2=0},
		{name="air", prob=254, param2=0},
		{name="vlf_stairs:stair_oak", prob=254, param2=23},
		{name="air", prob=254, param2=0},
		{name="air", prob=254, param2=0},
		{name="air", prob=254, param2=0},
		{name="air", prob=254, param2=0},
		{name="air", prob=254, param2=0},
		{name="air", prob=254, param2=0},
		{name="air", prob=254, param2=0},
		{name="air", prob=254, param2=0},
		{name="air", prob=254, param2=0},
		{name="air", prob=254, param2=0},
		{name="air", prob=254, param2=0},
		{name="vlf_stairs:stair_oak", prob=254, param2=21},
		{name="air", prob=254, param2=0},
		{name="air", prob=254, param2=0},
		{name="air", prob=254, param2=0},
		{name="air", prob=254, param2=0},
		{name="air", prob=254, param2=0},
		{name="air", prob=254, param2=0},
		{name="air", prob=254, param2=0},
		{name="air", prob=254, param2=0},
		{name="air", prob=254, param2=0},
		{name="vlf_stairs:slab_dark_oak", prob=254, param2=0},
		{name="vlf_stairs:stair_dark_oak", prob=254, param2=1},
		{name="vlf_stairs:slab_dark_oak_top", prob=254, param2=0},
		{name="air", prob=254, param2=0},
		{name="air", prob=254, param2=0},
		{name="air", prob=254, param2=0},
		{name="air", prob=254, param2=0},
		{name="air", prob=254, param2=0},
		{name="air", prob=254, param2=0},
		{name="air", prob=254, param2=0},
		{name="air", prob=254, param2=0},
		{name="air", prob=254, param2=0},
		{name="vlf_stairs:slab_dark_oak_top", prob=254, param2=0},
		{name="vlf_stairs:stair_dark_oak", prob=254, param2=3},
		{name="vlf_stairs:slab_dark_oak", prob=254, param2=0},
		{name="air", prob=254, param2=0},
		{name="air", prob=254, param2=0},
		{name="air", prob=254, param2=0},
		{name="air", prob=254, param2=0},
		{name="air", prob=254, param2=0},
		{name="air", prob=254, param2=0},
		{name="air", prob=254, param2=0},
		{name="air", prob=254, param2=0},
		{name="air", prob=254, param2=0},
		{name="air", prob=254, param2=0},
		{name="air", prob=254, param2=0},
		{name="vlf_stairs:slab_dark_oak", prob=254, param2=0},
		{name="vlf_stairs:stair_dark_oak", prob=254, param2=1},
		{name="vlf_stairs:slab_dark_oak_top", prob=254, param2=0},
		{name="air", prob=254, param2=0},
		{name="air", prob=254, param2=0},
		{name="air", prob=254, param2=0},
		{name="vlf_stairs:slab_dark_oak_top", prob=254, param2=0},
		{name="vlf_stairs:stair_dark_oak", prob=254, param2=3},
		{name="vlf_stairs:slab_dark_oak", prob=254, param2=0},
		{name="air", prob=254, param2=0},
		{name="air", prob=254, param2=0},
		{name="air", prob=254, param2=0},
		{name="air", prob=254, param2=0},
		{name="air", prob=254, param2=0},
		{name="air", prob=254, param2=0},
		{name="air", prob=254, param2=0},
		{name="air", prob=254, param2=0},
		{name="air", prob=254, param2=0},
		{name="air", prob=254, param2=0},
		{name="air", prob=254, param2=0},
		{name="air", prob=254, param2=0},
		{name="air", prob=254, param2=0},
		{name="air", prob=254, param2=0},
		{name="air", prob=254, param2=0},
		{name="air", prob=254, param2=0},
		{name="air", prob=254, param2=0},
		{name="vlf_stairs:slab_dark_oak", prob=254, param2=0},
		{name="vlf_stairs:slab_dark_oak_top", prob=254, param2=0},
		{name="vlf_stairs:slab_dark_oak", prob=254, param2=0},
		{name="air", prob=254, param2=0},
		{name="air", prob=254, param2=0},
		{name="air", prob=254, param2=0},
		{name="air", prob=254, param2=0},
		{name="air", prob=254, param2=0},
		{name="air", prob=254, param2=0},
		{name="air", prob=254, param2=0},
		{name="air", prob=254, param2=0},
		{name="air", prob=254, param2=0},
		{name="air", prob=254, param2=0},
		{name="air", prob=254, param2=0},
		{name="air", prob=254, param2=0},
		{name="air", prob=254, param2=0},
		{name="air", prob=254, param2=0},
		{name="air", prob=254, param2=0},
		{name="air", prob=254, param2=0},
		{name="vlf_core:stonebrickcracked", prob=254, param2=0},
		{name="vlf_core:dirt", prob=254, param2=0},
		{name="vlf_core:dirt", prob=254, param2=0},
		{name="vlf_core:dirt", prob=254, param2=0},
		{name="vlf_core:dirt", prob=254, param2=0},
		{name="vlf_core:dirt", prob=254, param2=0},
		{name="vlf_core:dirt", prob=254, param2=0},
		{name="vlf_core:dirt", prob=254, param2=0},
		{name="vlf_core:dirt", prob=254, param2=0},
		{name="vlf_core:dirt", prob=254, param2=0},
		{name="vlf_core:stonebrickmossy", prob=254, param2=0},
		{name="air", prob=254, param2=0},
		{name="air", prob=254, param2=0},
		{name="air", prob=254, param2=0},
		{name="air", prob=254, param2=0},
		{name="air", prob=254, param2=0},
		{name="air", prob=254, param2=0},
		{name="air", prob=254, param2=0},
		{name="air", prob=254, param2=0},
		{name="air", prob=254, param2=0},
		{name="air", prob=254, param2=0},
		{name="air", prob=254, param2=0},
		{name="air", prob=254, param2=0},
		{name="vlf_core:stonebrick", prob=254, param2=0},
		{name="vlf_core:dirt", prob=254, param2=0},
		{name="vlf_core:dirt", prob=254, param2=0},
		{name="vlf_core:dirt", prob=254, param2=0},
		{name="vlf_core:dirt", prob=254, param2=0},
		{name="vlf_core:dirt", prob=254, param2=0},
		{name="vlf_core:dirt", prob=254, param2=0},
		{name="vlf_core:dirt", prob=254, param2=0},
		{name="vlf_core:dirt", prob=254, param2=0},
		{name="vlf_core:dirt", prob=254, param2=0},
		{name="vlf_core:stonebrickcracked", prob=254, param2=0},
		{name="air", prob=254, param2=0},
		{name="air", prob=254, param2=0},
		{name="air", prob=254, param2=0},
		{name="air", prob=254, param2=0},
		{name="air", prob=254, param2=0},
		{name="air", prob=254, param2=0},
		{name="air", prob=254, param2=0},
		{name="air", prob=254, param2=0},
		{name="air", prob=254, param2=0},
		{name="air", prob=254, param2=0},
		{name="air", prob=254, param2=0},
		{name="air", prob=254, param2=0},
		{name="vlf_trees:tree_dark_oak", prob=254, param2=6},
		{name="vlf_trees:wood_dark_oak", prob=254, param2=0},
		{name="vlf_trees:wood_dark_oak", prob=254, param2=0},
		{name="vlf_trees:wood_dark_oak", prob=254, param2=0},
		{name="vlf_trees:wood_dark_oak", prob=254, param2=0},
		{name="vlf_trees:wood_dark_oak", prob=254, param2=0},
		{name="vlf_trees:wood_dark_oak", prob=254, param2=0},
		{name="vlf_trees:wood_dark_oak", prob=254, param2=0},
		{name="vlf_trees:wood_dark_oak", prob=254, param2=0},
		{name="vlf_trees:wood_dark_oak", prob=254, param2=0},
		{name="vlf_trees:tree_dark_oak", prob=254, param2=6},
		{name="air", prob=254, param2=0},
		{name="air", prob=254, param2=0},
		{name="air", prob=254, param2=0},
		{name="air", prob=254, param2=0},
		{name="air", prob=254, param2=0},
		{name="air", prob=254, param2=0},
		{name="air", prob=254, param2=0},
		{name="air", prob=254, param2=0},
		{name="air", prob=254, param2=0},
		{name="air", prob=254, param2=0},
		{name="air", prob=254, param2=0},
		{name="air", prob=254, param2=0},
		{name="vlf_trees:stripped_dark_oak", prob=254, param2=0},
		{name="vlf_books:bookshelf", prob=254, param2=0},
		{name="air", prob=254, param2=0},
		{name="air", prob=254, param2=0},
		{name="air", prob=254, param2=0},
		{name="vlf_stairs:stair_dark_oak", prob=254, param2=1},
		{name="vlf_stairs:stair_dark_oak", prob=254, param2=1},
		{name="vlf_books:bookshelf", prob=254, param2=0},
		{name="vlf_books:bookshelf", prob=254, param2=0},
		{name="vlf_books:bookshelf", prob=254, param2=0},
		{name="vlf_trees:stripped_dark_oak", prob=254, param2=0},
		{name="air", prob=254, param2=0},
		{name="air", prob=254, param2=0},
		{name="vlf_lanterns:soul_lantern_ceiling", prob=254, param2=0},
		{name="air", prob=254, param2=0},
		{name="air", prob=254, param2=0},
		{name="air", prob=254, param2=0},
		{name="air", prob=254, param2=0},
		{name="air", prob=254, param2=0},
		{name="air", prob=254, param2=0},
		{name="air", prob=254, param2=0},
		{name="air", prob=254, param2=0},
		{name="air", prob=254, param2=0},
		{name="vlf_trees:stripped_dark_oak", prob=254, param2=0},
		{name="vlf_books:bookshelf", prob=254, param2=0},
		{name="air", prob=254, param2=0},
		{name="air", prob=254, param2=0},
		{name="air", prob=254, param2=0},
		{name="air", prob=254, param2=0},
		{name="vlf_stairs:stair_dark_oak", prob=254, param2=1},
		{name="vlf_stairs:stair_dark_oak", prob=254, param2=1},
		{name="vlf_books:bookshelf", prob=254, param2=0},
		{name="vlf_books:bookshelf", prob=254, param2=0},
		{name="vlf_trees:stripped_dark_oak", prob=254, param2=0},
		{name="air", prob=254, param2=0},
		{name="air", prob=254, param2=0},
		{name="vlf_lanterns:chain", prob=254, param2=20},
		{name="air", prob=254, param2=0},
		{name="air", prob=254, param2=0},
		{name="air", prob=254, param2=0},
		{name="air", prob=254, param2=0},
		{name="air", prob=254, param2=0},
		{name="air", prob=254, param2=0},
		{name="air", prob=254, param2=0},
		{name="air", prob=254, param2=0},
		{name="air", prob=254, param2=0},
		{name="vlf_trees:stripped_dark_oak", prob=254, param2=0},
		{name="vlf_lanterns:lantern_ceiling", prob=254, param2=0},
		{name="air", prob=254, param2=0},
		{name="air", prob=254, param2=0},
		{name="air", prob=254, param2=0},
		{name="air", prob=254, param2=0},
		{name="air", prob=254, param2=0},
		{name="vlf_stairs:stair_dark_oak", prob=254, param2=1},
		{name="vlf_stairs:stair_dark_oak", prob=254, param2=1},
		{name="vlf_books:bookshelf", prob=254, param2=0},
		{name="vlf_trees:stripped_dark_oak", prob=254, param2=0},
		{name="air", prob=254, param2=0},
		{name="air", prob=254, param2=0},
		{name="vlf_stairs:slab_dark_oak", prob=254, param2=0},
		{name="vlf_stairs:slab_dark_oak", prob=254, param2=0},
		{name="vlf_stairs:slab_dark_oak", prob=254, param2=0},
		{name="vlf_stairs:slab_dark_oak", prob=254, param2=0},
		{name="vlf_stairs:slab_dark_oak", prob=254, param2=0},
		{name="vlf_stairs:slab_dark_oak", prob=254, param2=0},
		{name="vlf_stairs:slab_dark_oak", prob=254, param2=0},
		{name="vlf_stairs:slab_dark_oak", prob=254, param2=0},
		{name="vlf_stairs:slab_dark_oak", prob=254, param2=0},
		{name="vlf_stairs:slab_dark_oak", prob=254, param2=0},
		{name="vlf_trees:stripped_dark_oak", prob=254, param2=0},
		{name="vlf_fences:dark_oak_fence", prob=254, param2=0},
		{name="air", prob=254, param2=0},
		{name="air", prob=254, param2=0},
		{name="air", prob=254, param2=0},
		{name="air", prob=254, param2=0},
		{name="air", prob=254, param2=0},
		{name="air", prob=254, param2=0},
		{name="vlf_stairs:stair_dark_oak", prob=254, param2=1},
		{name="vlf_stairs:stair_dark_oak", prob=254, param2=1},
		{name="vlf_trees:stripped_dark_oak", prob=254, param2=0},
		{name="air", prob=254, param2=0},
		{name="air", prob=254, param2=0},
		{name="air", prob=254, param2=0},
		{name="air", prob=254, param2=0},
		{name="air", prob=254, param2=0},
		{name="air", prob=254, param2=0},
		{name="air", prob=254, param2=0},
		{name="air", prob=254, param2=0},
		{name="air", prob=254, param2=0},
		{name="air", prob=254, param2=0},
		{name="vlf_core:vine", prob=254, param2=2},
		{name="vlf_stairs:stair_dark_oak", prob=254, param2=23},
		{name="vlf_trees:tree_dark_oak", prob=254, param2=6},
		{name="vlf_trees:wood_dark_oak", prob=254, param2=0},
		{name="vlf_trees:wood_dark_oak", prob=254, param2=0},
		{name="vlf_trees:wood_dark_oak", prob=254, param2=0},
		{name="vlf_trees:wood_dark_oak", prob=254, param2=0},
		{name="air", prob=254, param2=0},
		{name="air", prob=254, param2=0},
		{name="air", prob=254, param2=0},
		{name="air", prob=254, param2=0},
		{name="vlf_stairs:stair_dark_oak", prob=254, param2=1},
		{name="vlf_trees:tree_dark_oak", prob=254, param2=6},
		{name="vlf_stairs:stair_dark_oak", prob=254, param2=21},
		{name="air", prob=254, param2=0},
		{name="air", prob=254, param2=0},
		{name="air", prob=254, param2=0},
		{name="air", prob=254, param2=0},
		{name="air", prob=254, param2=0},
		{name="air", prob=254, param2=0},
		{name="air", prob=254, param2=0},
		{name="air", prob=254, param2=0},
		{name="air", prob=254, param2=0},
		{name="vlf_core:vine", prob=254, param2=2},
		{name="vlf_trees:stripped_dark_oak", prob=254, param2=0},
		{name="vlf_stairs:slab_dark_oak_top", prob=254, param2=0},
		{name="air", prob=254, param2=0},
		{name="air", prob=254, param2=0},
		{name="air", prob=254, param2=0},
		{name="vlf_fences:dark_oak_fence", prob=254, param2=0},
		{name="air", prob=254, param2=0},
		{name="air", prob=254, param2=0},
		{name="air", prob=254, param2=0},
		{name="air", prob=254, param2=0},
		{name="air", prob=254, param2=0},
		{name="air", prob=254, param2=0},
		{name="vlf_trees:stripped_dark_oak", prob=254, param2=0},
		{name="air", prob=254, param2=0},
		{name="air", prob=254, param2=0},
		{name="air", prob=254, param2=0},
		{name="air", prob=254, param2=0},
		{name="air", prob=254, param2=0},
		{name="air", prob=254, param2=0},
		{name="air", prob=254, param2=0},
		{name="air", prob=254, param2=0},
		{name="air", prob=254, param2=0},
		{name="vlf_core:vine", prob=254, param2=2},
		{name="vlf_panes:pane_black_flat", prob=254, param2=3},
		{name="vlf_flowerpots:flower_pot_azure_bluet", prob=254, param2=0},
		{name="air", prob=254, param2=0},
		{name="air", prob=254, param2=0},
		{name="air", prob=254, param2=0},
		{name="air", prob=254, param2=0},
		{name="air", prob=254, param2=0},
		{name="air", prob=254, param2=0},
		{name="air", prob=254, param2=0},
		{name="air", prob=254, param2=0},
		{name="air", prob=254, param2=0},
		{name="air", prob=254, param2=0},
		{name="vlf_panes:pane_black_flat", prob=254, param2=3},
		{name="air", prob=254, param2=0},
		{name="air", prob=254, param2=0},
		{name="air", prob=254, param2=0},
		{name="air", prob=254, param2=0},
		{name="air", prob=254, param2=0},
		{name="air", prob=254, param2=0},
		{name="air", prob=254, param2=0},
		{name="air", prob=254, param2=0},
		{name="air", prob=254, param2=0},
		{name="vlf_core:vine", prob=254, param2=2},
		{name="vlf_panes:pane_black_flat", prob=254, param2=3},
		{name="air", prob=254, param2=0},
		{name="air", prob=254, param2=0},
		{name="vlf_core:vine", prob=254, param2=5},
		{name="air", prob=254, param2=0},
		{name="air", prob=254, param2=0},
		{name="air", prob=254, param2=0},
		{name="air", prob=254, param2=0},
		{name="air", prob=254, param2=0},
		{name="air", prob=254, param2=0},
		{name="air", prob=254, param2=0},
		{name="air", prob=254, param2=0},
		{name="vlf_panes:pane_black_flat", prob=254, param2=3},
		{name="vlf_core:vine", prob=254, param2=3},
		{name="air", prob=254, param2=0},
		{name="air", prob=254, param2=0},
		{name="air", prob=254, param2=0},
		{name="air", prob=254, param2=0},
		{name="air", prob=254, param2=0},
		{name="air", prob=254, param2=0},
		{name="air", prob=254, param2=0},
		{name="air", prob=254, param2=0},
		{name="vlf_core:vine", prob=254, param2=2},
		{name="vlf_trees:stripped_dark_oak", prob=254, param2=0},
		{name="vlf_core:vine", prob=254, param2=5},
		{name="vlf_core:vine", prob=254, param2=5},
		{name="vlf_core:vine", prob=254, param2=5},
		{name="air", prob=254, param2=0},
		{name="air", prob=254, param2=0},
		{name="air", prob=254, param2=0},
		{name="air", prob=254, param2=0},
		{name="air", prob=254, param2=0},
		{name="air", prob=254, param2=0},
		{name="air", prob=254, param2=0},
		{name="air", prob=254, param2=0},
		{name="vlf_trees:stripped_dark_oak", prob=254, param2=0},
		{name="vlf_core:vine", prob=254, param2=3},
		{name="air", prob=254, param2=0},
		{name="air", prob=254, param2=0},
		{name="air", prob=254, param2=0},
		{name="air", prob=254, param2=0},
		{name="air", prob=254, param2=0},
		{name="air", prob=254, param2=0},
		{name="air", prob=254, param2=0},
		{name="air", prob=254, param2=0},
		{name="vlf_core:vine", prob=254, param2=2},
		{name="vlf_trees:tree_dark_oak", prob=254, param2=6},
		{name="vlf_core:vine", prob=254, param2=5},
		{name="vlf_core:vine", prob=254, param2=5},
		{name="vlf_core:vine", prob=254, param2=5},
		{name="air", prob=254, param2=0},
		{name="air", prob=254, param2=0},
		{name="air", prob=254, param2=0},
		{name="air", prob=254, param2=0},
		{name="air", prob=254, param2=0},
		{name="air", prob=254, param2=0},
		{name="air", prob=254, param2=0},
		{name="air", prob=254, param2=0},
		{name="vlf_trees:tree_dark_oak", prob=254, param2=6},
		{name="air", prob=254, param2=0},
		{name="air", prob=254, param2=0},
		{name="air", prob=254, param2=0},
		{name="air", prob=254, param2=0},
		{name="air", prob=254, param2=0},
		{name="air", prob=254, param2=0},
		{name="air", prob=254, param2=0},
		{name="air", prob=254, param2=0},
		{name="air", prob=254, param2=0},
		{name="air", prob=254, param2=0},
		{name="vlf_stairs:stair_oak", prob=254, param2=1},
		{name="air", prob=254, param2=0},
		{name="air", prob=254, param2=0},
		{name="air", prob=254, param2=0},
		{name="air", prob=254, param2=0},
		{name="air", prob=254, param2=0},
		{name="air", prob=254, param2=0},
		{name="air", prob=254, param2=0},
		{name="air", prob=254, param2=0},
		{name="air", prob=254, param2=0},
		{name="air", prob=254, param2=0},
		{name="air", prob=254, param2=0},
		{name="vlf_stairs:stair_oak", prob=254, param2=3},
		{name="air", prob=254, param2=0},
		{name="air", prob=254, param2=0},
		{name="air", prob=254, param2=0},
		{name="air", prob=254, param2=0},
		{name="air", prob=254, param2=0},
		{name="air", prob=254, param2=0},
		{name="air", prob=254, param2=0},
		{name="air", prob=254, param2=0},
		{name="air", prob=254, param2=0},
		{name="air", prob=254, param2=0},
		{name="vlf_stairs:stair_oak", prob=254, param2=23},
		{name="air", prob=254, param2=0},
		{name="air", prob=254, param2=0},
		{name="air", prob=254, param2=0},
		{name="air", prob=254, param2=0},
		{name="air", prob=254, param2=0},
		{name="air", prob=254, param2=0},
		{name="air", prob=254, param2=0},
		{name="air", prob=254, param2=0},
		{name="air", prob=254, param2=0},
		{name="air", prob=254, param2=0},
		{name="air", prob=254, param2=0},
		{name="vlf_stairs:stair_oak", prob=254, param2=21},
		{name="air", prob=254, param2=0},
		{name="air", prob=254, param2=0},
		{name="air", prob=254, param2=0},
		{name="air", prob=254, param2=0},
		{name="air", prob=254, param2=0},
		{name="air", prob=254, param2=0},
		{name="air", prob=254, param2=0},
		{name="air", prob=254, param2=0},
		{name="air", prob=254, param2=0},
		{name="vlf_stairs:slab_dark_oak", prob=254, param2=0},
		{name="vlf_stairs:stair_dark_oak", prob=254, param2=1},
		{name="vlf_stairs:slab_dark_oak_top", prob=254, param2=0},
		{name="air", prob=254, param2=0},
		{name="air", prob=254, param2=0},
		{name="air", prob=254, param2=0},
		{name="air", prob=254, param2=0},
		{name="air", prob=254, param2=0},
		{name="air", prob=254, param2=0},
		{name="air", prob=254, param2=0},
		{name="air", prob=254, param2=0},
		{name="air", prob=254, param2=0},
		{name="vlf_stairs:slab_dark_oak_top", prob=254, param2=0},
		{name="vlf_stairs:stair_dark_oak", prob=254, param2=3},
		{name="vlf_stairs:slab_dark_oak", prob=254, param2=0},
		{name="air", prob=254, param2=0},
		{name="air", prob=254, param2=0},
		{name="air", prob=254, param2=0},
		{name="air", prob=254, param2=0},
		{name="air", prob=254, param2=0},
		{name="air", prob=254, param2=0},
		{name="air", prob=254, param2=0},
		{name="air", prob=254, param2=0},
		{name="air", prob=254, param2=0},
		{name="air", prob=254, param2=0},
		{name="air", prob=254, param2=0},
		{name="vlf_stairs:slab_dark_oak", prob=254, param2=0},
		{name="vlf_stairs:stair_dark_oak", prob=254, param2=1},
		{name="vlf_stairs:slab_dark_oak_top", prob=254, param2=0},
		{name="air", prob=254, param2=0},
		{name="air", prob=254, param2=0},
		{name="air", prob=254, param2=0},
		{name="vlf_stairs:slab_dark_oak_top", prob=254, param2=0},
		{name="vlf_stairs:stair_dark_oak", prob=254, param2=3},
		{name="vlf_stairs:slab_dark_oak", prob=254, param2=0},
		{name="air", prob=254, param2=0},
		{name="air", prob=254, param2=0},
		{name="air", prob=254, param2=0},
		{name="air", prob=254, param2=0},
		{name="air", prob=254, param2=0},
		{name="air", prob=254, param2=0},
		{name="air", prob=254, param2=0},
		{name="air", prob=254, param2=0},
		{name="air", prob=254, param2=0},
		{name="air", prob=254, param2=0},
		{name="air", prob=254, param2=0},
		{name="air", prob=254, param2=0},
		{name="air", prob=254, param2=0},
		{name="air", prob=254, param2=0},
		{name="air", prob=254, param2=0},
		{name="air", prob=254, param2=0},
		{name="air", prob=254, param2=0},
		{name="vlf_stairs:slab_dark_oak", prob=254, param2=0},
		{name="vlf_stairs:slab_dark_oak_top", prob=254, param2=0},
		{name="vlf_stairs:slab_dark_oak", prob=254, param2=0},
		{name="air", prob=254, param2=0},
		{name="air", prob=254, param2=0},
		{name="air", prob=254, param2=0},
		{name="air", prob=254, param2=0},
		{name="air", prob=254, param2=0},
		{name="air", prob=254, param2=0},
		{name="air", prob=254, param2=0},
		{name="vlf_trees:tree_dark_oak", prob=254, param2=0},
		{name="vlf_core:stonebrickmossy", prob=254, param2=0},
		{name="vlf_core:stonebrick", prob=254, param2=0},
		{name="vlf_core:stonebrickcracked", prob=254, param2=0},
		{name="vlf_core:stonebrick", prob=254, param2=0},
		{name="vlf_core:stonebrick", prob=254, param2=0},
		{name="vlf_core:stonebrickmossy", prob=254, param2=0},
		{name="vlf_core:stonebrickcracked", prob=254, param2=0},
		{name="vlf_core:stonebrick", prob=254, param2=0},
		{name="vlf_core:mossycobble", prob=254, param2=0},
		{name="vlf_core:dirt", prob=254, param2=0},
		{name="vlf_core:dirt", prob=254, param2=0},
		{name="vlf_core:dirt", prob=254, param2=0},
		{name="vlf_core:dirt", prob=254, param2=0},
		{name="vlf_core:dirt", prob=254, param2=0},
		{name="vlf_core:dirt", prob=254, param2=0},
		{name="vlf_core:dirt", prob=254, param2=0},
		{name="vlf_core:dirt", prob=254, param2=0},
		{name="vlf_core:dirt", prob=254, param2=0},
		{name="vlf_core:stonebrick", prob=254, param2=0},
		{name="air", prob=254, param2=0},
		{name="air", prob=254, param2=0},
		{name="air", prob=254, param2=0},
		{name="vlf_trees:tree_dark_oak", prob=254, param2=0},
		{name="vlf_core:stonebrick", prob=254, param2=0},
		{name="vlf_core:stonebrickcracked", prob=254, param2=0},
		{name="vlf_core:stonebrickmossy", prob=254, param2=0},
		{name="vlf_core:stonebrick", prob=254, param2=0},
		{name="vlf_core:stonebrick", prob=254, param2=0},
		{name="vlf_core:stonebrick", prob=254, param2=0},
		{name="vlf_core:stonebrick", prob=254, param2=0},
		{name="vlf_core:stonebrickmossy", prob=254, param2=0},
		{name="vlf_core:stonebrickmossy", prob=254, param2=0},
		{name="vlf_core:dirt", prob=254, param2=0},
		{name="vlf_core:dirt", prob=254, param2=0},
		{name="vlf_core:dirt", prob=254, param2=0},
		{name="vlf_core:dirt", prob=254, param2=0},
		{name="vlf_core:dirt", prob=254, param2=0},
		{name="vlf_core:dirt", prob=254, param2=0},
		{name="vlf_core:dirt", prob=254, param2=0},
		{name="vlf_core:dirt", prob=254, param2=0},
		{name="vlf_core:dirt", prob=254, param2=0},
		{name="vlf_core:stonebrick", prob=254, param2=0},
		{name="air", prob=254, param2=0},
		{name="air", prob=254, param2=0},
		{name="air", prob=254, param2=0},
		{name="vlf_trees:tree_dark_oak", prob=254, param2=0},
		{name="vlf_trees:tree_dark_oak", prob=254, param2=12},
		{name="vlf_trees:tree_dark_oak", prob=254, param2=12},
		{name="vlf_trees:tree_dark_oak", prob=254, param2=12},
		{name="vlf_trees:tree_dark_oak", prob=254, param2=12},
		{name="vlf_trees:tree_dark_oak", prob=254, param2=12},
		{name="vlf_trees:tree_dark_oak", prob=254, param2=12},
		{name="vlf_trees:tree_dark_oak", prob=254, param2=12},
		{name="vlf_trees:tree_dark_oak", prob=254, param2=12},
		{name="vlf_trees:tree_dark_oak", prob=254, param2=6},
		{name="vlf_trees:wood_dark_oak", prob=254, param2=0},
		{name="vlf_trees:wood_dark_oak", prob=254, param2=0},
		{name="vlf_trees:wood_dark_oak", prob=254, param2=0},
		{name="vlf_trees:wood_dark_oak", prob=254, param2=0},
		{name="vlf_trees:wood_dark_oak", prob=254, param2=0},
		{name="vlf_trees:wood_dark_oak", prob=254, param2=0},
		{name="vlf_trees:wood_dark_oak", prob=254, param2=0},
		{name="vlf_trees:wood_dark_oak", prob=254, param2=0},
		{name="vlf_trees:wood_dark_oak", prob=254, param2=0},
		{name="vlf_trees:tree_dark_oak", prob=254, param2=6},
		{name="air", prob=254, param2=0},
		{name="air", prob=254, param2=0},
		{name="air", prob=254, param2=0},
		{name="vlf_trees:tree_dark_oak", prob=254, param2=0},
		{name="vlf_trees:stripped_dark_oak", prob=254, param2=0},
		{name="vlf_trees:stripped_dark_oak", prob=254, param2=0},
		{name="vlf_trees:stripped_dark_oak", prob=254, param2=0},
		{name="vlf_trees:stripped_dark_oak", prob=254, param2=0},
		{name="vlf_trees:stripped_dark_oak", prob=254, param2=0},
		{name="vlf_trees:stripped_dark_oak", prob=254, param2=0},
		{name="vlf_trees:stripped_dark_oak", prob=254, param2=0},
		{name="vlf_trees:stripped_dark_oak", prob=254, param2=12},
		{name="vlf_trees:stripped_dark_oak", prob=254, param2=0},
		{name="vlf_chests:chest_small", prob=254, param2=3},
		{name="air", prob=254, param2=0},
		{name="air", prob=254, param2=0},
		{name="air", prob=254, param2=0},
		{name="vlf_fences:dark_oak_fence", prob=254, param2=0},
		{name="vlf_fences:dark_oak_fence", prob=254, param2=0},
		{name="air", prob=254, param2=0},
		{name="air", prob=254, param2=0},
		{name="vlf_chests:chest_small", prob=254, param2=2},
		{name="vlf_trees:stripped_dark_oak", prob=254, param2=0},
		{name="air", prob=254, param2=0},
		{name="air", prob=254, param2=0},
		{name="air", prob=254, param2=0},
		{name="vlf_trees:tree_dark_oak", prob=254, param2=0},
		{name="vlf_trees:stripped_dark_oak", prob=254, param2=0},
		{name="vlf_fences:oak_fence", prob=254, param2=0},
		{name="vlf_trees:stripped_dark_oak", prob=254, param2=0},
		{name="vlf_fences:oak_fence", prob=254, param2=0},
		{name="vlf_fences:oak_fence", prob=254, param2=0},
		{name="vlf_trees:stripped_dark_oak", prob=254, param2=0},
		{name="vlf_fences:oak_fence", prob=254, param2=0},
		{name="vlf_trees:stripped_dark_oak", prob=254, param2=0},
		{name="vlf_trees:stripped_dark_oak", prob=254, param2=0},
		{name="air", prob=254, param2=0},
		{name="air", prob=254, param2=0},
		{name="air", prob=254, param2=0},
		{name="air", prob=254, param2=0},
		{name="vlf_fences:dark_oak_fence", prob=254, param2=0},
		{name="vlf_fences:dark_oak_fence", prob=254, param2=0},
		{name="vlf_fences:dark_oak_fence", prob=254, param2=0},
		{name="air", prob=254, param2=0},
		{name="air", prob=254, param2=0},
		{name="vlf_panes:pane_black_flat", prob=254, param2=3},
		{name="air", prob=254, param2=0},
		{name="air", prob=254, param2=0},
		{name="air", prob=254, param2=0},
		{name="vlf_trees:tree_dark_oak", prob=254, param2=0},
		{name="vlf_trees:stripped_dark_oak", prob=254, param2=0},
		{name="vlf_trees:stripped_dark_oak", prob=254, param2=0},
		{name="vlf_trees:stripped_dark_oak", prob=254, param2=0},
		{name="vlf_trees:stripped_dark_oak", prob=254, param2=0},
		{name="vlf_trees:stripped_dark_oak", prob=254, param2=0},
		{name="vlf_trees:stripped_dark_oak", prob=254, param2=0},
		{name="vlf_trees:stripped_dark_oak", prob=254, param2=0},
		{name="vlf_trees:stripped_dark_oak", prob=254, param2=0},
		{name="vlf_trees:stripped_dark_oak", prob=254, param2=0},
		{name="air", prob=254, param2=0},
		{name="air", prob=254, param2=0},
		{name="air", prob=254, param2=0},
		{name="air", prob=254, param2=0},
		{name="air", prob=254, param2=0},
		{name="vlf_fences:dark_oak_fence", prob=254, param2=0},
		{name="vlf_fences:dark_oak_fence", prob=254, param2=0},
		{name="vlf_fences:dark_oak_fence", prob=254, param2=0},
		{name="air", prob=254, param2=0},
		{name="vlf_panes:pane_black_flat", prob=254, param2=3},
		{name="air", prob=254, param2=0},
		{name="air", prob=254, param2=0},
		{name="vlf_stairs:slab_dark_oak", prob=254, param2=0},
		{name="vlf_trees:wood_dark_oak", prob=254, param2=0},
		{name="vlf_trees:wood_dark_oak", prob=254, param2=0},
		{name="vlf_trees:wood_dark_oak", prob=254, param2=0},
		{name="vlf_trees:wood_dark_oak", prob=254, param2=0},
		{name="vlf_trees:wood_dark_oak", prob=254, param2=0},
		{name="vlf_trees:wood_dark_oak", prob=254, param2=0},
		{name="vlf_trees:wood_dark_oak", prob=254, param2=0},
		{name="vlf_trees:wood_dark_oak", prob=254, param2=0},
		{name="vlf_stairs:slab_dark_oak", prob=254, param2=0},
		{name="vlf_trees:stripped_dark_oak", prob=254, param2=0},
		{name="air", prob=254, param2=0},
		{name="air", prob=254, param2=0},
		{name="air", prob=254, param2=0},
		{name="air", prob=254, param2=0},
		{name="air", prob=254, param2=0},
		{name="air", prob=254, param2=0},
		{name="vlf_fences:dark_oak_fence", prob=254, param2=0},
		{name="vlf_fences:dark_oak_fence", prob=254, param2=0},
		{name="vlf_fences:dark_oak_fence", prob=254, param2=0},
		{name="vlf_trees:stripped_dark_oak", prob=254, param2=0},
		{name="air", prob=254, param2=0},
		{name="air", prob=254, param2=0},
		{name="air", prob=254, param2=0},
		{name="air", prob=254, param2=0},
		{name="air", prob=254, param2=0},
		{name="air", prob=254, param2=0},
		{name="air", prob=254, param2=0},
		{name="air", prob=254, param2=0},
		{name="air", prob=254, param2=0},
		{name="air", prob=254, param2=0},
		{name="air", prob=254, param2=0},
		{name="vlf_stairs:stair_dark_oak", prob=254, param2=23},
		{name="vlf_trees:tree_dark_oak", prob=254, param2=6},
		{name="vlf_trees:wood_dark_oak", prob=254, param2=0},
		{name="vlf_trees:wood_dark_oak", prob=254, param2=0},
		{name="vlf_trees:wood_dark_oak", prob=254, param2=0},
		{name="vlf_trees:wood_dark_oak", prob=254, param2=0},
		{name="vlf_trees:wood_dark_oak", prob=254, param2=0},
		{name="vlf_trees:wood_dark_oak", prob=254, param2=0},
		{name="vlf_trees:wood_dark_oak", prob=254, param2=0},
		{name="vlf_trees:wood_dark_oak", prob=254, param2=0},
		{name="vlf_trees:wood_dark_oak", prob=254, param2=0},
		{name="vlf_trees:tree_dark_oak", prob=254, param2=6},
		{name="vlf_stairs:stair_dark_oak", prob=254, param2=21},
		{name="air", prob=254, param2=0},
		{name="air", prob=254, param2=0},
		{name="air", prob=254, param2=0},
		{name="air", prob=254, param2=0},
		{name="air", prob=254, param2=0},
		{name="air", prob=254, param2=0},
		{name="air", prob=254, param2=0},
		{name="air", prob=254, param2=0},
		{name="air", prob=254, param2=0},
		{name="vlf_core:vine", prob=254, param2=2},
		{name="vlf_trees:stripped_dark_oak", prob=254, param2=0},
		{name="vlf_stairs:slab_dark_oak_top", prob=254, param2=0},
		{name="air", prob=254, param2=0},
		{name="air", prob=254, param2=0},
		{name="air", prob=254, param2=0},
		{name="vlf_fences:dark_oak_fence", prob=254, param2=0},
		{name="vlf_fences:dark_oak_fence", prob=254, param2=0},
		{name="vlf_fences:dark_oak_fence", prob=254, param2=0},
		{name="vlf_fences:dark_oak_fence", prob=254, param2=0},
		{name="air", prob=254, param2=0},
		{name="air", prob=254, param2=0},
		{name="vlf_fences:dark_oak_fence", prob=254, param2=0},
		{name="vlf_trees:stripped_dark_oak", prob=254, param2=0},
		{name="air", prob=254, param2=0},
		{name="air", prob=254, param2=0},
		{name="air", prob=254, param2=0},
		{name="air", prob=254, param2=0},
		{name="air", prob=254, param2=0},
		{name="air", prob=254, param2=0},
		{name="air", prob=254, param2=0},
		{name="air", prob=254, param2=0},
		{name="air", prob=254, param2=0},
		{name="vlf_core:vine", prob=254, param2=2},
		{name="vlf_trees:stripped_dark_oak", prob=254, param2=0},
		{name="vlf_flowerpots:flower_pot_tulip_orange", prob=254, param2=0},
		{name="air", prob=254, param2=0},
		{name="air", prob=254, param2=0},
		{name="air", prob=254, param2=0},
		{name="air", prob=254, param2=0},
		{name="air", prob=254, param2=0},
		{name="air", prob=254, param2=0},
		{name="air", prob=254, param2=0},
		{name="air", prob=254, param2=0},
		{name="air", prob=254, param2=0},
		{name="air", prob=254, param2=0},
		{name="vlf_trees:stripped_dark_oak", prob=254, param2=0},
		{name="air", prob=254, param2=0},
		{name="air", prob=254, param2=0},
		{name="air", prob=254, param2=0},
		{name="air", prob=254, param2=0},
		{name="air", prob=254, param2=0},
		{name="air", prob=254, param2=0},
		{name="air", prob=254, param2=0},
		{name="air", prob=254, param2=0},
		{name="air", prob=254, param2=0},
		{name="vlf_core:vine", prob=254, param2=2},
		{name="vlf_trees:stripped_dark_oak", prob=254, param2=0},
		{name="air", prob=254, param2=0},
		{name="air", prob=254, param2=0},
		{name="air", prob=254, param2=0},
		{name="air", prob=254, param2=0},
		{name="air", prob=254, param2=0},
		{name="air", prob=254, param2=0},
		{name="air", prob=254, param2=0},
		{name="air", prob=254, param2=0},
		{name="air", prob=254, param2=0},
		{name="air", prob=254, param2=0},
		{name="air", prob=254, param2=0},
		{name="vlf_trees:stripped_dark_oak", prob=254, param2=0},
		{name="vlf_core:vine", prob=254, param2=3},
		{name="air", prob=254, param2=0},
		{name="air", prob=254, param2=0},
		{name="air", prob=254, param2=0},
		{name="air", prob=254, param2=0},
		{name="air", prob=254, param2=0},
		{name="air", prob=254, param2=0},
		{name="air", prob=254, param2=0},
		{name="air", prob=254, param2=0},
		{name="vlf_core:vine", prob=254, param2=2},
		{name="vlf_trees:stripped_dark_oak", prob=254, param2=0},
		{name="air", prob=254, param2=0},
		{name="air", prob=254, param2=0},
		{name="air", prob=254, param2=0},
		{name="air", prob=254, param2=0},
		{name="air", prob=254, param2=0},
		{name="air", prob=254, param2=0},
		{name="air", prob=254, param2=0},
		{name="air", prob=254, param2=0},
		{name="air", prob=254, param2=0},
		{name="air", prob=254, param2=0},
		{name="air", prob=254, param2=0},
		{name="vlf_trees:stripped_dark_oak", prob=254, param2=0},
		{name="vlf_core:vine", prob=254, param2=3},
		{name="air", prob=254, param2=0},
		{name="air", prob=254, param2=0},
		{name="air", prob=254, param2=0},
		{name="air", prob=254, param2=0},
		{name="air", prob=254, param2=0},
		{name="air", prob=254, param2=0},
		{name="air", prob=254, param2=0},
		{name="air", prob=254, param2=0},
		{name="air", prob=254, param2=0},
		{name="vlf_trees:tree_dark_oak", prob=254, param2=6},
		{name="air", prob=254, param2=0},
		{name="air", prob=254, param2=0},
		{name="air", prob=254, param2=0},
		{name="air", prob=254, param2=0},
		{name="air", prob=254, param2=0},
		{name="air", prob=254, param2=0},
		{name="air", prob=254, param2=0},
		{name="air", prob=254, param2=0},
		{name="air", prob=254, param2=0},
		{name="air", prob=254, param2=0},
		{name="air", prob=254, param2=0},
		{name="vlf_trees:tree_dark_oak", prob=254, param2=6},
		{name="air", prob=254, param2=0},
		{name="air", prob=254, param2=0},
		{name="air", prob=254, param2=0},
		{name="air", prob=254, param2=0},
		{name="air", prob=254, param2=0},
		{name="air", prob=254, param2=0},
		{name="air", prob=254, param2=0},
		{name="air", prob=254, param2=0},
		{name="air", prob=254, param2=0},
		{name="air", prob=254, param2=0},
		{name="vlf_stairs:stair_oak", prob=254, param2=1},
		{name="air", prob=254, param2=0},
		{name="air", prob=254, param2=0},
		{name="air", prob=254, param2=0},
		{name="air", prob=254, param2=0},
		{name="air", prob=254, param2=0},
		{name="air", prob=254, param2=0},
		{name="air", prob=254, param2=0},
		{name="air", prob=254, param2=0},
		{name="air", prob=254, param2=0},
		{name="air", prob=254, param2=0},
		{name="air", prob=254, param2=0},
		{name="vlf_stairs:stair_oak", prob=254, param2=3},
		{name="air", prob=254, param2=0},
		{name="air", prob=254, param2=0},
		{name="air", prob=254, param2=0},
		{name="air", prob=254, param2=0},
		{name="air", prob=254, param2=0},
		{name="air", prob=254, param2=0},
		{name="air", prob=254, param2=0},
		{name="air", prob=254, param2=0},
		{name="air", prob=254, param2=0},
		{name="air", prob=254, param2=0},
		{name="vlf_stairs:stair_oak", prob=254, param2=23},
		{name="air", prob=254, param2=0},
		{name="air", prob=254, param2=0},
		{name="air", prob=254, param2=0},
		{name="air", prob=254, param2=0},
		{name="air", prob=254, param2=0},
		{name="air", prob=254, param2=0},
		{name="air", prob=254, param2=0},
		{name="air", prob=254, param2=0},
		{name="air", prob=254, param2=0},
		{name="air", prob=254, param2=0},
		{name="air", prob=254, param2=0},
		{name="vlf_stairs:stair_oak", prob=254, param2=21},
		{name="air", prob=254, param2=0},
		{name="air", prob=254, param2=0},
		{name="air", prob=254, param2=0},
		{name="air", prob=254, param2=0},
		{name="air", prob=254, param2=0},
		{name="air", prob=254, param2=0},
		{name="air", prob=254, param2=0},
		{name="air", prob=254, param2=0},
		{name="air", prob=254, param2=0},
		{name="vlf_stairs:slab_dark_oak", prob=254, param2=0},
		{name="vlf_stairs:stair_dark_oak", prob=254, param2=1},
		{name="vlf_stairs:slab_dark_oak_top", prob=254, param2=0},
		{name="air", prob=254, param2=0},
		{name="air", prob=254, param2=0},
		{name="air", prob=254, param2=0},
		{name="air", prob=254, param2=0},
		{name="air", prob=254, param2=0},
		{name="air", prob=254, param2=0},
		{name="air", prob=254, param2=0},
		{name="air", prob=254, param2=0},
		{name="air", prob=254, param2=0},
		{name="vlf_stairs:slab_dark_oak_top", prob=254, param2=0},
		{name="vlf_stairs:stair_dark_oak", prob=254, param2=3},
		{name="vlf_stairs:slab_dark_oak", prob=254, param2=0},
		{name="air", prob=254, param2=0},
		{name="air", prob=254, param2=0},
		{name="air", prob=254, param2=0},
		{name="air", prob=254, param2=0},
		{name="air", prob=254, param2=0},
		{name="air", prob=254, param2=0},
		{name="air", prob=254, param2=0},
		{name="air", prob=254, param2=0},
		{name="air", prob=254, param2=0},
		{name="air", prob=254, param2=0},
		{name="air", prob=254, param2=0},
		{name="vlf_stairs:slab_dark_oak", prob=254, param2=0},
		{name="vlf_stairs:stair_dark_oak", prob=254, param2=1},
		{name="vlf_stairs:slab_dark_oak_top", prob=254, param2=0},
		{name="air", prob=254, param2=0},
		{name="air", prob=254, param2=0},
		{name="air", prob=254, param2=0},
		{name="vlf_stairs:slab_dark_oak_top", prob=254, param2=0},
		{name="vlf_stairs:stair_dark_oak", prob=254, param2=3},
		{name="vlf_stairs:slab_dark_oak", prob=254, param2=0},
		{name="air", prob=254, param2=0},
		{name="air", prob=254, param2=0},
		{name="air", prob=254, param2=0},
		{name="air", prob=254, param2=0},
		{name="air", prob=254, param2=0},
		{name="air", prob=254, param2=0},
		{name="air", prob=254, param2=0},
		{name="air", prob=254, param2=0},
		{name="air", prob=254, param2=0},
		{name="air", prob=254, param2=0},
		{name="air", prob=254, param2=0},
		{name="air", prob=254, param2=0},
		{name="air", prob=254, param2=0},
		{name="air", prob=254, param2=0},
		{name="air", prob=254, param2=0},
		{name="air", prob=254, param2=0},
		{name="air", prob=254, param2=0},
		{name="vlf_stairs:slab_dark_oak", prob=254, param2=0},
		{name="vlf_stairs:slab_dark_oak_top", prob=254, param2=0},
		{name="vlf_stairs:slab_dark_oak", prob=254, param2=0},
		{name="air", prob=254, param2=0},
		{name="air", prob=254, param2=0},
		{name="air", prob=254, param2=0},
		{name="air", prob=254, param2=0},
		{name="air", prob=254, param2=0},
		{name="air", prob=254, param2=0},
		{name="air", prob=254, param2=0},
		{name="vlf_core:stonebrick", prob=254, param2=0},
		{name="vlf_core:dirt", prob=254, param2=0},
		{name="vlf_core:dirt", prob=254, param2=0},
		{name="vlf_core:dirt", prob=254, param2=0},
		{name="vlf_core:dirt", prob=254, param2=0},
		{name="vlf_core:dirt", prob=254, param2=0},
		{name="vlf_core:dirt", prob=254, param2=0},
		{name="vlf_core:dirt", prob=254, param2=0},
		{name="vlf_core:dirt", prob=254, param2=0},
		{name="vlf_core:stonebrickmossy", prob=254, param2=0},
		{name="vlf_core:dirt", prob=254, param2=0},
		{name="vlf_core:dirt", prob=254, param2=0},
		{name="vlf_core:dirt", prob=254, param2=0},
		{name="vlf_core:dirt", prob=254, param2=0},
		{name="vlf_core:dirt", prob=254, param2=0},
		{name="vlf_core:dirt", prob=254, param2=0},
		{name="vlf_core:dirt", prob=254, param2=0},
		{name="vlf_core:dirt", prob=254, param2=0},
		{name="vlf_core:dirt", prob=254, param2=0},
		{name="vlf_core:stonebrickcracked", prob=254, param2=0},
		{name="air", prob=254, param2=0},
		{name="air", prob=254, param2=0},
		{name="air", prob=254, param2=0},
		{name="vlf_core:stonebrickcracked", prob=254, param2=0},
		{name="vlf_core:dirt", prob=254, param2=0},
		{name="vlf_core:dirt", prob=254, param2=0},
		{name="vlf_core:dirt", prob=254, param2=0},
		{name="vlf_core:dirt", prob=254, param2=0},
		{name="vlf_core:dirt", prob=254, param2=0},
		{name="vlf_core:dirt", prob=254, param2=0},
		{name="vlf_core:dirt", prob=254, param2=0},
		{name="vlf_core:dirt", prob=254, param2=0},
		{name="vlf_core:stonebrickcracked", prob=254, param2=0},
		{name="vlf_core:dirt", prob=254, param2=0},
		{name="vlf_core:dirt", prob=254, param2=0},
		{name="vlf_core:dirt", prob=254, param2=0},
		{name="vlf_core:dirt", prob=254, param2=0},
		{name="vlf_core:dirt", prob=254, param2=0},
		{name="vlf_core:dirt", prob=254, param2=0},
		{name="vlf_core:dirt", prob=254, param2=0},
		{name="vlf_core:dirt", prob=254, param2=0},
		{name="vlf_core:dirt", prob=254, param2=0},
		{name="vlf_core:mossycobble", prob=254, param2=0},
		{name="air", prob=254, param2=0},
		{name="air", prob=254, param2=0},
		{name="air", prob=254, param2=0},
		{name="vlf_trees:tree_dark_oak", prob=254, param2=6},
		{name="vlf_trees:wood_dark_oak", prob=254, param2=0},
		{name="vlf_trees:wood_dark_oak", prob=254, param2=0},
		{name="vlf_trees:wood_dark_oak", prob=254, param2=0},
		{name="vlf_trees:wood_dark_oak", prob=254, param2=0},
		{name="vlf_trees:wood_dark_oak", prob=254, param2=0},
		{name="vlf_trees:wood_dark_oak", prob=254, param2=0},
		{name="vlf_trees:wood_dark_oak", prob=254, param2=0},
		{name="vlf_trees:wood_dark_oak", prob=254, param2=0},
		{name="vlf_trees:tree_dark_oak", prob=254, param2=6},
		{name="vlf_trees:wood_dark_oak", prob=254, param2=0},
		{name="vlf_trees:wood_dark_oak", prob=254, param2=0},
		{name="vlf_trees:wood_dark_oak", prob=254, param2=0},
		{name="vlf_trees:wood_dark_oak", prob=254, param2=0},
		{name="vlf_trees:wood_dark_oak", prob=254, param2=0},
		{name="vlf_trees:wood_dark_oak", prob=254, param2=0},
		{name="vlf_trees:wood_dark_oak", prob=254, param2=0},
		{name="vlf_trees:wood_dark_oak", prob=254, param2=0},
		{name="vlf_trees:wood_dark_oak", prob=254, param2=0},
		{name="vlf_trees:tree_dark_oak", prob=254, param2=6},
		{name="air", prob=254, param2=0},
		{name="air", prob=254, param2=0},
		{name="air", prob=254, param2=0},
		{name="vlf_trees:stripped_dark_oak", prob=254, param2=0},
		{name="vlf_farming:soil_wet", prob=254, param2=0},
		{name="vlf_farming:soil_wet", prob=254, param2=0},
		{name="vlf_farming:soil_wet", prob=254, param2=0},
		{name="vlf_farming:soil_wet", prob=254, param2=0},
		{name="vlf_farming:soil_wet", prob=254, param2=0},
		{name="vlf_farming:soil_wet", prob=254, param2=0},
		{name="vlf_farming:soil_wet", prob=254, param2=0},
		{name="air", prob=254, param2=0},
		{name="vlf_trees:tree_dark_oak", prob=254, param2=0},
		{name="air", prob=254, param2=0},
		{name="air", prob=254, param2=0},
		{name="air", prob=254, param2=0},
		{name="air", prob=254, param2=0},
		{name="air", prob=254, param2=0},
		{name="air", prob=254, param2=0},
		{name="air", prob=254, param2=0},
		{name="air", prob=254, param2=0},
		{name="air", prob=254, param2=0},
		{name="vlf_trees:stripped_dark_oak", prob=254, param2=0},
		{name="air", prob=254, param2=0},
		{name="air", prob=254, param2=0},
		{name="air", prob=254, param2=0},
		{name="vlf_trees:stripped_dark_oak", prob=254, param2=0},
		{name="vlf_farming:pumpkintige_linked_t", prob=254, param2=0},
		{name="vlf_farming:pumpkintige_linked_t", prob=254, param2=0},
		{name="vlf_farming:pumpkintige_linked_t", prob=254, param2=0},
		{name="vlf_farming:pumpkintige_linked_t", prob=254, param2=0},
		{name="vlf_farming:melontige_linked_t", prob=254, param2=0},
		{name="vlf_farming:melontige_linked_t", prob=254, param2=0},
		{name="vlf_farming:melontige_linked_t", prob=254, param2=0},
		{name="air", prob=254, param2=0},
		{name="vlf_trees:tree_dark_oak", prob=254, param2=0},
		{name="air", prob=254, param2=0},
		{name="air", prob=254, param2=0},
		{name="air", prob=254, param2=0},
		{name="air", prob=254, param2=0},
		{name="air", prob=254, param2=0},
		{name="air", prob=254, param2=0},
		{name="air", prob=254, param2=0},
		{name="air", prob=254, param2=0},
		{name="air", prob=254, param2=0},
		{name="vlf_panes:pane_black_flat", prob=254, param2=3},
		{name="air", prob=254, param2=0},
		{name="air", prob=254, param2=0},
		{name="air", prob=254, param2=0},
		{name="vlf_trees:stripped_dark_oak", prob=254, param2=0},
		{name="air", prob=254, param2=0},
		{name="vlf_torches:torch_wall", prob=254, param2=5},
		{name="air", prob=254, param2=0},
		{name="air", prob=254, param2=0},
		{name="air", prob=254, param2=0},
		{name="air", prob=254, param2=0},
		{name="vlf_torches:torch_wall", prob=254, param2=5},
		{name="air", prob=254, param2=0},
		{name="vlf_trees:tree_dark_oak", prob=254, param2=0},
		{name="air", prob=254, param2=0},
		{name="air", prob=254, param2=0},
		{name="air", prob=254, param2=0},
		{name="air", prob=254, param2=0},
		{name="air", prob=254, param2=0},
		{name="air", prob=254, param2=0},
		{name="air", prob=254, param2=0},
		{name="air", prob=254, param2=0},
		{name="air", prob=254, param2=0},
		{name="vlf_panes:pane_black_flat", prob=254, param2=3},
		{name="air", prob=254, param2=0},
		{name="air", prob=254, param2=0},
		{name="vlf_stairs:slab_dark_oak", prob=254, param2=0},
		{name="vlf_trees:wood_dark_oak", prob=254, param2=0},
		{name="vlf_stairs:slab_dark_oak_top", prob=254, param2=0},
		{name="vlf_stairs:slab_dark_oak_top", prob=254, param2=0},
		{name="vlf_stairs:slab_dark_oak_top", prob=254, param2=0},
		{name="vlf_stairs:slab_dark_oak_top", prob=254, param2=0},
		{name="vlf_stairs:slab_dark_oak_top", prob=254, param2=0},
		{name="vlf_stairs:slab_dark_oak_top", prob=254, param2=0},
		{name="vlf_trees:wood_dark_oak", prob=254, param2=0},
		{name="vlf_stairs:slab_dark_oak", prob=254, param2=0},
		{name="vlf_trees:tree_dark_oak", prob=254, param2=0},
		{name="air", prob=254, param2=0},
		{name="air", prob=254, param2=0},
		{name="air", prob=254, param2=0},
		{name="air", prob=254, param2=0},
		{name="air", prob=254, param2=0},
		{name="air", prob=254, param2=0},
		{name="air", prob=254, param2=0},
		{name="air", prob=254, param2=0},
		{name="air", prob=254, param2=0},
		{name="vlf_trees:stripped_dark_oak", prob=254, param2=0},
		{name="air", prob=254, param2=0},
		{name="air", prob=254, param2=0},
		{name="air", prob=254, param2=0},
		{name="air", prob=254, param2=0},
		{name="vlf_stairs:slab_dark_oak", prob=254, param2=0},
		{name="vlf_stairs:slab_dark_oak", prob=254, param2=0},
		{name="vlf_stairs:slab_dark_oak", prob=254, param2=0},
		{name="vlf_stairs:slab_dark_oak", prob=254, param2=0},
		{name="vlf_stairs:slab_dark_oak", prob=254, param2=0},
		{name="vlf_stairs:slab_dark_oak", prob=254, param2=0},
		{name="air", prob=254, param2=0},
		{name="vlf_stairs:stair_dark_oak", prob=254, param2=23},
		{name="vlf_trees:tree_dark_oak", prob=254, param2=6},
		{name="vlf_trees:wood_dark_oak", prob=254, param2=0},
		{name="vlf_trees:wood_dark_oak", prob=254, param2=0},
		{name="vlf_trees:wood_dark_oak", prob=254, param2=0},
		{name="vlf_trees:wood_dark_oak", prob=254, param2=0},
		{name="vlf_trees:wood_dark_oak", prob=254, param2=0},
		{name="vlf_trees:wood_dark_oak", prob=254, param2=0},
		{name="vlf_trees:wood_dark_oak", prob=254, param2=0},
		{name="vlf_trees:wood_dark_oak", prob=254, param2=0},
		{name="vlf_trees:wood_dark_oak", prob=254, param2=0},
		{name="vlf_trees:tree_dark_oak", prob=254, param2=6},
		{name="vlf_stairs:stair_dark_oak", prob=254, param2=21},
		{name="air", prob=254, param2=0},
		{name="air", prob=254, param2=0},
		{name="air", prob=254, param2=0},
		{name="air", prob=254, param2=0},
		{name="air", prob=254, param2=0},
		{name="air", prob=254, param2=0},
		{name="air", prob=254, param2=0},
		{name="air", prob=254, param2=0},
		{name="air", prob=254, param2=0},
		{name="air", prob=254, param2=0},
		{name="vlf_trees:stripped_dark_oak", prob=254, param2=0},
		{name="vlf_wool:red_carpet", prob=254, param2=0},
		{name="air", prob=254, param2=0},
		{name="air", prob=254, param2=0},
		{name="air", prob=254, param2=0},
		{name="air", prob=254, param2=0},
		{name="air", prob=254, param2=0},
		{name="air", prob=254, param2=0},
		{name="air", prob=254, param2=0},
		{name="air", prob=254, param2=0},
		{name="air", prob=254, param2=0},
		{name="vlf_wool:red_carpet", prob=254, param2=0},
		{name="vlf_trees:stripped_dark_oak", prob=254, param2=0},
		{name="air", prob=254, param2=0},
		{name="air", prob=254, param2=0},
		{name="air", prob=254, param2=0},
		{name="air", prob=254, param2=0},
		{name="air", prob=254, param2=0},
		{name="air", prob=254, param2=0},
		{name="air", prob=254, param2=0},
		{name="air", prob=254, param2=0},
		{name="air", prob=254, param2=0},
		{name="air", prob=254, param2=0},
		{name="vlf_panes:pane_black_flat", prob=254, param2=3},
		{name="air", prob=254, param2=0},
		{name="air", prob=254, param2=0},
		{name="air", prob=254, param2=0},
		{name="air", prob=254, param2=0},
		{name="air", prob=254, param2=0},
		{name="air", prob=254, param2=0},
		{name="air", prob=254, param2=0},
		{name="air", prob=254, param2=0},
		{name="air", prob=254, param2=0},
		{name="air", prob=254, param2=0},
		{name="air", prob=254, param2=0},
		{name="vlf_panes:pane_black_flat", prob=254, param2=3},
		{name="air", prob=254, param2=0},
		{name="air", prob=254, param2=0},
		{name="air", prob=254, param2=0},
		{name="air", prob=254, param2=0},
		{name="air", prob=254, param2=0},
		{name="air", prob=254, param2=0},
		{name="air", prob=254, param2=0},
		{name="air", prob=254, param2=0},
		{name="air", prob=254, param2=0},
		{name="air", prob=254, param2=0},
		{name="vlf_panes:pane_black_flat", prob=254, param2=3},
		{name="air", prob=254, param2=0},
		{name="air", prob=254, param2=0},
		{name="air", prob=254, param2=0},
		{name="air", prob=254, param2=0},
		{name="air", prob=254, param2=0},
		{name="air", prob=254, param2=0},
		{name="air", prob=254, param2=0},
		{name="air", prob=254, param2=0},
		{name="air", prob=254, param2=0},
		{name="air", prob=254, param2=0},
		{name="air", prob=254, param2=0},
		{name="vlf_panes:pane_black_flat", prob=254, param2=3},
		{name="air", prob=254, param2=0},
		{name="air", prob=254, param2=0},
		{name="air", prob=254, param2=0},
		{name="air", prob=254, param2=0},
		{name="air", prob=254, param2=0},
		{name="air", prob=254, param2=0},
		{name="air", prob=254, param2=0},
		{name="air", prob=254, param2=0},
		{name="air", prob=254, param2=0},
		{name="air", prob=254, param2=0},
		{name="vlf_trees:stripped_dark_oak", prob=254, param2=0},
		{name="air", prob=254, param2=0},
		{name="air", prob=254, param2=0},
		{name="air", prob=254, param2=0},
		{name="air", prob=254, param2=0},
