schematic = {
	size = {x=7, y=5, z=7},
	yslice_prob = {
		{ypos=0, prob=254},
		{ypos=1, prob=254},
		{ypos=2, prob=254},
		{ypos=3, prob=254},
		{ypos=4, prob=254},
	},
	data = {
		{name="air", prob=0, param2=0},
		{name="air", prob=0, param2=0},
		{name="vlf_end:end_stone", prob=254, param2=0},
		{name="vlf_end:end_stone", prob=254, param2=0},
		{name="vlf_end:end_stone", prob=254, param2=0},
		{name="air", prob=0, param2=0},
		{name="air", prob=0, param2=0},
		{name="air", prob=0, param2=0},
		{name="air", prob=0, param2=0},
		{name="vlf_core:bedrock", prob=254, param2=0},
		{name="vlf_core:bedrock", prob=254, param2=0},
		{name="vlf_core:bedrock", prob=254, param2=0},
		{name="air", prob=0, param2=0},
		{name="air", prob=0, param2=0},
		{name="air", prob=0, param2=0},
		{name="air", prob=0, param2=0},
		{name="air", prob=254, param2=0},
		{name="air", prob=254, param2=0},
		{name="air", prob=254, param2=0},
		{name="air", prob=0, param2=0},
		{name="air", prob=0, param2=0},
		{name="air", prob=0, param2=0},
		{name="air", prob=0, param2=0},
		{name="air", prob=254, param2=0},
		{name="air", prob=254, param2=0},
		{name="air", prob=254, param2=0},
		{name="air", prob=0, param2=0},
		{name="air", prob=0, param2=0},
		{name="air", prob=0, param2=0},
		{name="air", prob=0, param2=0},
		{name="air", prob=254, param2=0},
		{name="air", prob=254, param2=0},
		{name="air", prob=254, param2=0},
		{name="air", prob=0, param2=0},
		{name="air", prob=0, param2=0},
		{name="air", prob=0, param2=0},
		{name="vlf_end:end_stone", prob=254, param2=0},
		{name="vlf_core:bedrock", prob=254, param2=0},
		{name="vlf_core:bedrock", prob=254, param2=0},
		{name="vlf_core:bedrock", prob=254, param2=0},
		{name="vlf_end:end_stone", prob=254, param2=0},
		{name="air", prob=0, param2=0},
		{name="air", prob=0, param2=0},
		{name="vlf_core:bedrock", prob=254, param2=0},
		{name="vlf_portals:portal_end", prob=254, param2=3},
		{name="vlf_portals:portal_end", prob=254, param2=3},
		{name="vlf_portals:portal_end", prob=254, param2=2},
		{name="vlf_core:bedrock", prob=254, param2=0},
		{name="air", prob=0, param2=0},
		{name="air", prob=0, param2=0},
		{name="air", prob=254, param2=0},
		{name="air", prob=254, param2=0},
		{name="air", prob=254, param2=0},
		{name="air", prob=254, param2=0},
		{name="air", prob=254, param2=0},
		{name="air", prob=0, param2=0},
		{name="air", prob=0, param2=0},
		{name="air", prob=254, param2=0},
		{name="air", prob=254, param2=0},
		{name="air", prob=254, param2=0},
		{name="air", prob=254, param2=0},
		{name="air", prob=254, param2=0},
		{name="air", prob=0, param2=0},
		{name="air", prob=0, param2=0},
		{name="air", prob=254, param2=0},
		{name="air", prob=254, param2=0},
		{name="air", prob=254, param2=0},
		{name="air", prob=254, param2=0},
		{name="air", prob=254, param2=0},
		{name="air", prob=0, param2=0},
		{name="vlf_end:end_stone", prob=254, param2=0},
		{name="vlf_core:bedrock", prob=254, param2=0},
		{name="vlf_core:bedrock", prob=254, param2=0},
		{name="vlf_core:bedrock", prob=254, param2=0},
		{name="vlf_core:bedrock", prob=254, param2=0},
		{name="vlf_core:bedrock", prob=254, param2=0},
		{name="vlf_end:end_stone", prob=254, param2=0},
		{name="vlf_core:bedrock", prob=254, param2=0},
		{name="vlf_portals:portal_end", prob=254, param2=3},
		{name="vlf_portals:portal_end", prob=254, param2=3},
		{name="vlf_portals:portal_end", prob=254, param2=3},
		{name="vlf_portals:portal_end", prob=254, param2=2},
		{name="vlf_portals:portal_end", prob=254, param2=2},
		{name="vlf_core:bedrock", prob=254, param2=0},
		{name="air", prob=254, param2=0},
		{name="air", prob=254, param2=0},
		{name="air", prob=254, param2=0},
		{name="air", prob=254, param2=0},
		{name="air", prob=254, param2=0},
		{name="air", prob=254, param2=0},
		{name="air", prob=254, param2=0},
		{name="air", prob=254, param2=0},
		{name="air", prob=254, param2=0},
		{name="air", prob=254, param2=0},
		{name="vlf_torches:torch_wall", prob=254, param2=4},
		{name="air", prob=254, param2=0},
		{name="air", prob=254, param2=0},
		{name="air", prob=254, param2=0},
		{name="air", prob=254, param2=0},
		{name="air", prob=254, param2=0},
		{name="air", prob=254, param2=0},
		{name="air", prob=254, param2=0},
		{name="air", prob=254, param2=0},
		{name="air", prob=254, param2=0},
		{name="air", prob=254, param2=0},
		{name="vlf_end:end_stone", prob=254, param2=0},
		{name="vlf_core:bedrock", prob=254, param2=0},
		{name="vlf_core:bedrock", prob=254, param2=0},
		{name="vlf_core:bedrock", prob=254, param2=0},
		{name="vlf_core:bedrock", prob=254, param2=0},
		{name="vlf_core:bedrock", prob=254, param2=0},
		{name="vlf_end:end_stone", prob=254, param2=0},
		{name="vlf_core:bedrock", prob=254, param2=0},
		{name="vlf_portals:portal_end", prob=254, param2=0},
		{name="vlf_portals:portal_end", prob=254, param2=2},
		{name="vlf_core:bedrock", prob=254, param2=0},
		{name="vlf_portals:portal_end", prob=254, param2=3},
		{name="vlf_portals:portal_end", prob=254, param2=2},
		{name="vlf_core:bedrock", prob=254, param2=0},
		{name="air", prob=254, param2=0},
		{name="air", prob=254, param2=0},
		{name="air", prob=254, param2=0},
		{name="vlf_core:bedrock", prob=254, param2=0},
		{name="air", prob=254, param2=0},
		{name="air", prob=254, param2=0},
		{name="air", prob=254, param2=0},
		{name="air", prob=254, param2=0},
		{name="air", prob=254, param2=0},
		{name="vlf_torches:torch_wall", prob=254, param2=2},
		{name="vlf_core:bedrock", prob=254, param2=0},
		{name="vlf_torches:torch_wall", prob=254, param2=3},
		{name="air", prob=254, param2=0},
		{name="air", prob=254, param2=0},
		{name="air", prob=254, param2=0},
		{name="air", prob=254, param2=0},
		{name="air", prob=254, param2=0},
		{name="vlf_core:bedrock", prob=254, param2=0},
		{name="air", prob=254, param2=0},
		{name="air", prob=254, param2=0},
		{name="air", prob=254, param2=0},
		{name="vlf_end:end_stone", prob=254, param2=0},
		{name="vlf_core:bedrock", prob=254, param2=0},
		{name="vlf_core:bedrock", prob=254, param2=0},
		{name="vlf_core:bedrock", prob=254, param2=0},
		{name="vlf_core:bedrock", prob=254, param2=0},
		{name="vlf_core:bedrock", prob=254, param2=0},
		{name="vlf_end:end_stone", prob=254, param2=0},
		{name="vlf_core:bedrock", prob=254, param2=0},
		{name="vlf_portals:portal_end", prob=254, param2=2},
		{name="vlf_portals:portal_end", prob=254, param2=2},
		{name="vlf_portals:portal_end", prob=254, param2=1},
		{name="vlf_portals:portal_end", prob=254, param2=1},
		{name="vlf_portals:portal_end", prob=254, param2=1},
		{name="vlf_core:bedrock", prob=254, param2=0},
		{name="air", prob=254, param2=0},
		{name="air", prob=254, param2=0},
		{name="air", prob=254, param2=0},
		{name="air", prob=254, param2=0},
		{name="air", prob=254, param2=0},
		{name="air", prob=254, param2=0},
		{name="air", prob=254, param2=0},
		{name="air", prob=254, param2=0},
		{name="air", prob=254, param2=0},
		{name="air", prob=254, param2=0},
		{name="vlf_torches:torch_wall", prob=254, param2=5},
		{name="air", prob=254, param2=0},
		{name="air", prob=254, param2=0},
		{name="air", prob=254, param2=0},
		{name="air", prob=254, param2=0},
		{name="air", prob=254, param2=0},
		{name="air", prob=254, param2=0},
		{name="air", prob=254, param2=0},
		{name="air", prob=254, param2=0},
		{name="air", prob=254, param2=0},
		{name="air", prob=254, param2=0},
		{name="air", prob=0, param2=0},
		{name="vlf_end:end_stone", prob=254, param2=0},
		{name="vlf_core:bedrock", prob=254, param2=0},
		{name="vlf_core:bedrock", prob=254, param2=0},
		{name="vlf_core:bedrock", prob=254, param2=0},
		{name="vlf_end:end_stone", prob=254, param2=0},
		{name="air", prob=0, param2=0},
		{name="air", prob=0, param2=0},
		{name="vlf_core:bedrock", prob=254, param2=0},
		{name="vlf_portals:portal_end", prob=254, param2=2},
		{name="vlf_portals:portal_end", prob=254, param2=1},
		{name="vlf_portals:portal_end", prob=254, param2=1},
		{name="vlf_core:bedrock", prob=254, param2=0},
		{name="air", prob=0, param2=0},
		{name="air", prob=0, param2=0},
		{name="air", prob=254, param2=0},
		{name="air", prob=254, param2=0},
		{name="air", prob=254, param2=0},
		{name="air", prob=254, param2=0},
		{name="air", prob=254, param2=0},
		{name="air", prob=0, param2=0},
		{name="air", prob=0, param2=0},
		{name="air", prob=254, param2=0},
		{name="air", prob=254, param2=0},
		{name="air", prob=254, param2=0},
		{name="air", prob=254, param2=0},
		{name="air", prob=254, param2=0},
		{name="air", prob=0, param2=0},
		{name="air", prob=0, param2=0},
		{name="air", prob=254, param2=0},
		{name="air", prob=254, param2=0},
		{name="air", prob=254, param2=0},
		{name="air", prob=254, param2=0},
		{name="air", prob=254, param2=0},
		{name="air", prob=0, param2=0},
		{name="air", prob=0, param2=0},
		{name="air", prob=0, param2=0},
		{name="vlf_end:end_stone", prob=254, param2=0},
		{name="vlf_end:end_stone", prob=254, param2=0},
		{name="vlf_end:end_stone", prob=254, param2=0},
		{name="air", prob=0, param2=0},
		{name="air", prob=0, param2=0},
		{name="air", prob=0, param2=0},
		{name="air", prob=0, param2=0},
		{name="vlf_core:bedrock", prob=254, param2=0},
		{name="vlf_core:bedrock", prob=254, param2=0},
		{name="vlf_core:bedrock", prob=254, param2=0},
		{name="air", prob=0, param2=0},
		{name="air", prob=0, param2=0},
		{name="air", prob=0, param2=0},
		{name="air", prob=0, param2=0},
		{name="air", prob=254, param2=0},
		{name="air", prob=254, param2=0},
		{name="air", prob=254, param2=0},
		{name="air", prob=0, param2=0},
		{name="air", prob=0, param2=0},
		{name="air", prob=0, param2=0},
		{name="air", prob=0, param2=0},
		{name="air", prob=254, param2=0},
		{name="air", prob=254, param2=0},
		{name="air", prob=254, param2=0},
		{name="air", prob=0, param2=0},
		{name="air", prob=0, param2=0},
		{name="air", prob=0, param2=0},
		{name="air", prob=0, param2=0},
		{name="air", prob=254, param2=0},
		{name="air", prob=254, param2=0},
		{name="air", prob=254, param2=0},
		{name="air", prob=254, param2=0},
		{name="air", prob=0, param2=0},
	},
}
