schematic = {
	size = {x=3, y=5, z=4},
	yslice_prob = {
		{ypos=0, prob=254},
		{ypos=1, prob=254},
		{ypos=2, prob=254},
		{ypos=3, prob=254},
		{ypos=4, prob=254},
	},
	data = {
		{name="air", prob=0, param2=0},
		{name="vlf_core:obsidian", prob=254, param2=0},
		{name="air", prob=0, param2=0},
		{name="air", prob=0, param2=0},
		{name="vlf_core:obsidian", prob=254, param2=0},
		{name="air", prob=0, param2=0},
		{name="air", prob=0, param2=0},
		{name="vlf_core:obsidian", prob=254, param2=0},
		{name="air", prob=0, param2=0},
		{name="air", prob=0, param2=0},
		{name="vlf_core:obsidian", prob=254, param2=0},
		{name="air", prob=0, param2=0},
		{name="air", prob=0, param2=0},
		{name="vlf_core:obsidian", prob=254, param2=0},
		{name="air", prob=0, param2=0},
		{name="vlf_core:obsidian", prob=254, param2=0},
		{name="vlf_core:obsidian", prob=254, param2=0},
		{name="vlf_core:obsidian", prob=254, param2=0},
		{name="air", prob=0, param2=0},
		{name="vlf_portals:portal", prob=254, param2=1},
		{name="air", prob=0, param2=0},
		{name="air", prob=0, param2=0},
		{name="vlf_portals:portal", prob=254, param2=1},
		{name="air", prob=0, param2=0},
		{name="air", prob=0, param2=0},
		{name="vlf_portals:portal", prob=254, param2=1},
		{name="air", prob=0, param2=0},
		{name="air", prob=0, param2=0},
		{name="vlf_core:obsidian", prob=254, param2=0},
		{name="air", prob=0, param2=0},
		{name="vlf_core:obsidian", prob=254, param2=0},
		{name="vlf_core:obsidian", prob=254, param2=0},
		{name="vlf_core:obsidian", prob=254, param2=0},
		{name="air", prob=0, param2=0},
		{name="vlf_portals:portal", prob=254, param2=1},
		{name="air", prob=0, param2=0},
		{name="air", prob=0, param2=0},
		{name="vlf_portals:portal", prob=254, param2=1},
		{name="air", prob=0, param2=0},
		{name="air", prob=0, param2=0},
		{name="vlf_portals:portal", prob=254, param2=1},
		{name="air", prob=0, param2=0},
		{name="air", prob=0, param2=0},
		{name="vlf_core:obsidian", prob=254, param2=0},
		{name="air", prob=0, param2=0},
		{name="air", prob=0, param2=0},
		{name="vlf_core:obsidian", prob=254, param2=0},
		{name="air", prob=0, param2=0},
		{name="air", prob=0, param2=0},
		{name="vlf_core:obsidian", prob=254, param2=0},
		{name="air", prob=0, param2=0},
		{name="air", prob=0, param2=0},
		{name="vlf_core:obsidian", prob=254, param2=0},
		{name="air", prob=0, param2=0},
		{name="air", prob=0, param2=0},
		{name="vlf_core:obsidian", prob=254, param2=0},
		{name="air", prob=0, param2=0},
		{name="air", prob=0, param2=0},
		{name="vlf_core:obsidian", prob=254, param2=0},
		{name="air", prob=0, param2=0},
	},
}
