schematic = {
	size = {x=5, y=7, z=5},
	yslice_prob = {
		{ypos=0, prob=254},
		{ypos=1, prob=254},
		{ypos=2, prob=254},
		{ypos=3, prob=254},
		{ypos=4, prob=254},
		{ypos=5, prob=254},
		{ypos=6, prob=254},
	},
	data = {
		{name="air", prob=0, param2=0},
		{name="air", prob=0, param2=0},
		{name="air", prob=0, param2=0},
		{name="air", prob=0, param2=0},
		{name="air", prob=0, param2=0},
		{name="air", prob=0, param2=0},
		{name="air", prob=0, param2=0},
		{name="air", prob=0, param2=0},
		{name="air", prob=0, param2=0},
		{name="air", prob=0, param2=0},
		{name="air", prob=0, param2=0},
		{name="air", prob=0, param2=0},
		{name="air", prob=0, param2=0},
		{name="air", prob=0, param2=0},
		{name="air", prob=0, param2=0},
		{name="air", prob=0, param2=0},
		{name="vlf_trees:leaves_oak", prob=254, param2=128},
		{name="air", prob=0, param2=0},
		{name="air", prob=0, param2=0},
		{name="air", prob=0, param2=0},
		{name="air", prob=0, param2=0},
		{name="air", prob=0, param2=0},
		{name="vlf_trees:leaves_oak", prob=254, param2=160},
		{name="vlf_trees:leaves_oak", prob=254, param2=128},
		{name="air", prob=0, param2=0},
		{name="air", prob=0, param2=0},
		{name="vlf_trees:leaves_oak", prob=254, param2=160},
		{name="air", prob=0, param2=0},
		{name="vlf_trees:leaves_oak", prob=254, param2=160},
		{name="air", prob=0, param2=0},
		{name="air", prob=0, param2=0},
		{name="vlf_trees:leaves_oak", prob=254, param2=192},
		{name="vlf_trees:leaves_oak", prob=254, param2=160},
		{name="vlf_trees:leaves_oak", prob=254, param2=192},
		{name="air", prob=0, param2=0},
		{name="air", prob=0, param2=0},
		{name="air", prob=0, param2=0},
		{name="air", prob=0, param2=0},
		{name="air", prob=0, param2=0},
		{name="air", prob=0, param2=0},
		{name="air", prob=0, param2=0},
		{name="air", prob=0, param2=0},
		{name="air", prob=0, param2=0},
		{name="air", prob=0, param2=0},
		{name="air", prob=0, param2=0},
		{name="air", prob=0, param2=0},
		{name="air", prob=0, param2=0},
		{name="air", prob=0, param2=0},
		{name="air", prob=0, param2=0},
		{name="air", prob=0, param2=0},
		{name="vlf_trees:leaves_oak", prob=254, param2=128},
		{name="vlf_trees:leaves_oak", prob=254, param2=96},
		{name="air", prob=0, param2=0},
		{name="vlf_trees:leaves_oak", prob=254, param2=96},
		{name="vlf_trees:leaves_oak", prob=254, param2=128},
		{name="air", prob=0, param2=0},
		{name="vlf_trees:leaves_oak", prob=254, param2=96},
		{name="air", prob=0, param2=0},
		{name="vlf_trees:leaves_oak", prob=254, param2=96},
		{name="vlf_trees:leaves_oak", prob=254, param2=128},
		{name="vlf_trees:leaves_oak", prob=254, param2=160},
		{name="vlf_trees:leaves_oak", prob=254, param2=128},
		{name="vlf_trees:leaves_oak", prob=254, param2=96},
		{name="vlf_trees:leaves_oak", prob=254, param2=128},
		{name="vlf_trees:leaves_oak", prob=254, param2=160},
		{name="vlf_trees:leaves_oak", prob=254, param2=192},
		{name="vlf_trees:leaves_oak", prob=254, param2=160},
		{name="vlf_trees:leaves_oak", prob=254, param2=128},
		{name="vlf_trees:leaves_oak", prob=254, param2=160},
		{name="vlf_trees:leaves_oak", prob=254, param2=192},
		{name="air", prob=0, param2=0},
		{name="air", prob=0, param2=0},
		{name="vlf_trees:tree_oak", prob=254, param2=0},
		{name="air", prob=0, param2=0},
		{name="air", prob=0, param2=0},
		{name="air", prob=0, param2=0},
		{name="air", prob=0, param2=0},
		{name="vlf_trees:tree_oak", prob=254, param2=0},
		{name="air", prob=0, param2=0},
		{name="air", prob=0, param2=0},
		{name="air", prob=0, param2=0},
		{name="air", prob=0, param2=0},
		{name="vlf_trees:tree_oak", prob=254, param2=0},
		{name="air", prob=0, param2=0},
		{name="air", prob=0, param2=0},
		{name="vlf_trees:leaves_oak", prob=254, param2=96},
		{name="vlf_trees:leaves_oak", prob=254, param2=64},
		{name="vlf_trees:tree_oak", prob=254, param2=0},
		{name="vlf_trees:leaves_oak", prob=254, param2=64},
		{name="vlf_trees:leaves_oak", prob=254, param2=96},
		{name="vlf_trees:leaves_oak", prob=254, param2=96},
		{name="vlf_trees:leaves_oak", prob=254, param2=64},
		{name="vlf_trees:tree_oak", prob=254, param2=0},
		{name="vlf_trees:leaves_oak", prob=254, param2=64},
		{name="vlf_trees:leaves_oak", prob=254, param2=96},
		{name="vlf_trees:leaves_oak", prob=254, param2=128},
		{name="vlf_trees:leaves_oak", prob=254, param2=96},
		{name="vlf_trees:leaves_oak", prob=254, param2=64},
		{name="vlf_trees:leaves_oak", prob=254, param2=96},
		{name="air", prob=0, param2=0},
		{name="vlf_trees:leaves_oak", prob=254, param2=160},
		{name="vlf_trees:leaves_oak", prob=254, param2=128},
		{name="vlf_trees:leaves_oak", prob=254, param2=96},
		{name="vlf_trees:leaves_oak", prob=254, param2=128},
		{name="air", prob=0, param2=0},
		{name="air", prob=0, param2=0},
		{name="air", prob=0, param2=0},
		{name="air", prob=0, param2=0},
		{name="air", prob=0, param2=0},
		{name="air", prob=0, param2=0},
		{name="air", prob=0, param2=0},
		{name="air", prob=0, param2=0},
		{name="air", prob=0, param2=0},
		{name="air", prob=0, param2=0},
		{name="air", prob=0, param2=0},
		{name="air", prob=0, param2=0},
		{name="air", prob=0, param2=0},
		{name="air", prob=0, param2=0},
		{name="air", prob=0, param2=0},
		{name="air", prob=0, param2=0},
		{name="air", prob=0, param2=0},
		{name="vlf_trees:leaves_oak", prob=254, param2=96},
		{name="vlf_trees:leaves_oak", prob=254, param2=64},
		{name="vlf_trees:leaves_oak", prob=254, param2=96},
		{name="vlf_trees:leaves_oak", prob=254, param2=128},
		{name="air", prob=0, param2=0},
		{name="vlf_trees:leaves_oak", prob=254, param2=96},
		{name="vlf_trees:leaves_oak", prob=254, param2=64},
		{name="vlf_trees:leaves_oak", prob=254, param2=96},
		{name="vlf_trees:leaves_oak", prob=254, param2=128},
		{name="air", prob=0, param2=0},
		{name="vlf_trees:leaves_oak", prob=254, param2=128},
		{name="vlf_trees:leaves_oak", prob=254, param2=96},
		{name="vlf_trees:leaves_oak", prob=254, param2=128},
		{name="vlf_trees:leaves_oak", prob=254, param2=160},
		{name="air", prob=0, param2=0},
		{name="vlf_trees:leaves_oak", prob=254, param2=160},
		{name="vlf_trees:leaves_oak", prob=254, param2=128},
		{name="vlf_trees:leaves_oak", prob=254, param2=160},
		{name="vlf_trees:leaves_oak", prob=254, param2=192},
		{name="air", prob=0, param2=0},
		{name="air", prob=0, param2=0},
		{name="air", prob=0, param2=0},
		{name="air", prob=0, param2=0},
		{name="air", prob=0, param2=0},
		{name="air", prob=0, param2=0},
		{name="air", prob=0, param2=0},
		{name="air", prob=0, param2=0},
		{name="air", prob=0, param2=0},
		{name="air", prob=0, param2=0},
		{name="air", prob=0, param2=0},
		{name="air", prob=0, param2=0},
		{name="air", prob=0, param2=0},
		{name="air", prob=0, param2=0},
		{name="air", prob=0, param2=0},
		{name="air", prob=0, param2=0},
		{name="air", prob=0, param2=0},
		{name="air", prob=0, param2=0},
		{name="vlf_trees:leaves_oak", prob=254, param2=128},
		{name="air", prob=0, param2=0},
		{name="air", prob=0, param2=0},
		{name="vlf_trees:leaves_oak", prob=254, param2=128},
		{name="vlf_trees:leaves_oak", prob=254, param2=96},
		{name="vlf_trees:leaves_oak", prob=254, param2=128},
		{name="air", prob=0, param2=0},
		{name="air", prob=0, param2=0},
		{name="vlf_trees:leaves_oak", prob=254, param2=160},
		{name="vlf_trees:leaves_oak", prob=254, param2=128},
		{name="vlf_trees:leaves_oak", prob=254, param2=160},
		{name="air", prob=0, param2=0},
		{name="air", prob=0, param2=0},
		{name="air", prob=0, param2=0},
		{name="vlf_trees:leaves_oak", prob=254, param2=160},
		{name="air", prob=0, param2=0},
		{name="air", prob=0, param2=0},
	},
}
