schematic = {
	size = {x=13, y=8, z=13},
	yslice_prob = {
		{ypos=0, prob=254},
		{ypos=1, prob=254},
		{ypos=2, prob=254},
		{ypos=3, prob=254},
		{ypos=4, prob=254},
		{ypos=5, prob=254},
		{ypos=6, prob=254},
		{ypos=7, prob=254},
	},
	data = {
		{name="vlf_core:stonebrick", prob=254, param2=0},
		{name="vlf_core:stonebrick", prob=254, param2=0},
		{name="vlf_core:stonebrick", prob=254, param2=0},
		{name="vlf_core:stonebrick", prob=254, param2=0},
		{name="vlf_core:stonebrick", prob=254, param2=0},
		{name="vlf_core:stonebrick", prob=254, param2=0},
		{name="vlf_core:stonebrick", prob=254, param2=0},
		{name="vlf_core:stonebrick", prob=254, param2=0},
		{name="vlf_core:stonebrick", prob=254, param2=0},
		{name="vlf_core:stonebrick", prob=254, param2=0},
		{name="vlf_core:stonebrick", prob=254, param2=0},
		{name="vlf_core:stonebrick", prob=254, param2=0},
		{name="vlf_core:stonebrick", prob=254, param2=0},
		{name="vlf_core:stonebrick", prob=254, param2=0},
		{name="vlf_core:stonebrick", prob=254, param2=0},
		{name="vlf_core:stonebrick", prob=254, param2=0},
		{name="vlf_core:stonebrick", prob=254, param2=0},
		{name="vlf_core:stonebrick", prob=254, param2=0},
		{name="vlf_core:stonebrick", prob=254, param2=0},
		{name="air", prob=254, param2=0},
		{name="vlf_core:stonebrick", prob=254, param2=0},
		{name="vlf_core:stonebrick", prob=254, param2=0},
		{name="vlf_core:stonebrick", prob=254, param2=0},
		{name="vlf_core:stonebrick", prob=254, param2=0},
		{name="vlf_core:stonebrick", prob=254, param2=0},
		{name="vlf_core:stonebrick", prob=254, param2=0},
		{name="vlf_core:stonebrick", prob=254, param2=0},
		{name="vlf_core:stonebrick", prob=254, param2=0},
		{name="xpanes:bar_flat", prob=254, param2=0},
		{name="vlf_core:stonebrick", prob=254, param2=0},
		{name="xpanes:bar_flat", prob=254, param2=0},
		{name="vlf_core:stonebrick", prob=254, param2=0},
		{name="air", prob=254, param2=0},
		{name="vlf_core:stonebrick", prob=254, param2=0},
		{name="xpanes:bar_flat", prob=254, param2=0},
		{name="vlf_core:stonebrick", prob=254, param2=0},
		{name="xpanes:bar_flat", prob=254, param2=0},
		{name="vlf_core:stonebrick", prob=254, param2=0},
		{name="vlf_core:stonebrick", prob=254, param2=0},
		{name="vlf_core:stonebrick", prob=254, param2=0},
		{name="vlf_core:stonebrick", prob=254, param2=0},
		{name="xpanes:bar_flat", prob=254, param2=0},
		{name="vlf_core:stonebrick", prob=254, param2=0},
		{name="xpanes:bar_flat", prob=254, param2=0},
		{name="vlf_core:stonebrick", prob=254, param2=0},
		{name="vlf_core:stonebrick", prob=254, param2=0},
		{name="vlf_core:stonebrick", prob=254, param2=0},
		{name="xpanes:bar_flat", prob=254, param2=0},
		{name="vlf_core:stonebrick", prob=254, param2=0},
		{name="xpanes:bar_flat", prob=254, param2=0},
		{name="vlf_core:stonebrick", prob=254, param2=0},
		{name="vlf_core:stonebrick", prob=254, param2=0},
		{name="vlf_core:stonebrick", prob=254, param2=0},
		{name="vlf_core:stonebrick", prob=254, param2=0},
		{name="vlf_core:stonebrick", prob=254, param2=0},
		{name="vlf_core:stonebrick", prob=254, param2=0},
		{name="vlf_core:stonebrick", prob=254, param2=0},
		{name="vlf_core:stonebrick", prob=254, param2=0},
		{name="vlf_core:stonebrick", prob=254, param2=0},
		{name="vlf_core:stonebrick", prob=254, param2=0},
		{name="vlf_core:stonebrick", prob=254, param2=0},
		{name="vlf_core:stonebrick", prob=254, param2=0},
		{name="vlf_core:stonebrick", prob=254, param2=0},
		{name="vlf_core:stonebrick", prob=254, param2=0},
		{name="vlf_core:stonebrick", prob=254, param2=0},
		{name="vlf_core:stonebrick", prob=254, param2=0},
		{name="vlf_core:stonebrick", prob=254, param2=0},
		{name="vlf_core:stonebrick", prob=254, param2=0},
		{name="vlf_core:stonebrick", prob=254, param2=0},
		{name="vlf_core:stonebrick", prob=254, param2=0},
		{name="vlf_core:stonebrick", prob=254, param2=0},
		{name="vlf_core:stonebrick", prob=254, param2=0},
		{name="vlf_core:stonebrick", prob=254, param2=0},
		{name="vlf_core:stonebrick", prob=254, param2=0},
		{name="vlf_core:stonebrick", prob=254, param2=0},
		{name="vlf_core:stonebrick", prob=254, param2=0},
		{name="vlf_core:stonebrick", prob=254, param2=0},
		{name="vlf_core:stonebrick", prob=254, param2=0},
		{name="vlf_core:stonebrick", prob=254, param2=0},
		{name="vlf_core:stonebrick", prob=254, param2=0},
		{name="vlf_core:stonebrick", prob=254, param2=0},
		{name="vlf_core:stonebrick", prob=254, param2=0},
		{name="vlf_core:stonebrick", prob=254, param2=0},
		{name="vlf_core:stonebrick", prob=254, param2=0},
		{name="vlf_core:stonebrick", prob=254, param2=0},
		{name="vlf_core:stonebrick", prob=254, param2=0},
		{name="vlf_core:stonebrick", prob=254, param2=0},
		{name="vlf_core:stonebrick", prob=254, param2=0},
		{name="vlf_core:stonebrick", prob=254, param2=0},
		{name="vlf_core:stonebrick", prob=254, param2=0},
		{name="vlf_core:stonebrick", prob=254, param2=0},
		{name="vlf_core:stonebrick", prob=254, param2=0},
		{name="vlf_core:stonebrick", prob=254, param2=0},
		{name="vlf_core:stonebrick", prob=254, param2=0},
		{name="vlf_core:stonebrick", prob=254, param2=0},
		{name="vlf_core:stonebrick", prob=254, param2=0},
		{name="vlf_core:stonebrick", prob=254, param2=0},
		{name="vlf_core:stonebrick", prob=254, param2=0},
		{name="vlf_core:stonebrick", prob=254, param2=0},
		{name="vlf_core:stonebrick", prob=254, param2=0},
		{name="vlf_core:stonebrick", prob=254, param2=0},
		{name="vlf_core:stonebrick", prob=254, param2=0},
		{name="vlf_core:stonebrick", prob=254, param2=0},
		{name="vlf_core:stonebrick", prob=254, param2=0},
		{name="vlf_core:stonebrick", prob=254, param2=0},
		{name="vlf_core:stonebrick", prob=254, param2=0},
		{name="vlf_core:stonebrick", prob=254, param2=0},
		{name="vlf_core:stonebrick", prob=254, param2=0},
		{name="vlf_core:stonebrick", prob=254, param2=0},
		{name="vlf_core:stonebrick", prob=254, param2=0},
		{name="vlf_core:stonebrick", prob=254, param2=0},
		{name="vlf_core:stonebrick", prob=254, param2=0},
		{name="vlf_core:stonebrick", prob=254, param2=0},
		{name="vlf_core:stonebrick", prob=254, param2=0},
		{name="vlf_core:stonebrick", prob=254, param2=0},
		{name="vlf_core:stonebrick", prob=254, param2=0},
		{name="vlf_core:stonebrick", prob=254, param2=0},
		{name="vlf_core:stonebrick", prob=254, param2=0},
		{name="vlf_core:lava_source", prob=254, param2=3},
		{name="vlf_core:stonebrick", prob=254, param2=0},
		{name="air", prob=254, param2=0},
		{name="air", prob=254, param2=0},
		{name="air", prob=254, param2=0},
		{name="air", prob=254, param2=0},
		{name="air", prob=254, param2=0},
		{name="air", prob=254, param2=0},
		{name="air", prob=254, param2=0},
		{name="vlf_core:stonebrick", prob=254, param2=0},
		{name="vlf_core:lava_source", prob=254, param2=3},
		{name="vlf_core:stonebrick", prob=254, param2=0},
		{name="vlf_core:stonebrick", prob=254, param2=0},
		{name="air", prob=254, param2=0},
		{name="air", prob=254, param2=0},
		{name="air", prob=254, param2=0},
		{name="air", prob=254, param2=0},
		{name="air", prob=254, param2=0},
		{name="air", prob=254, param2=0},
		{name="air", prob=254, param2=0},
		{name="air", prob=254, param2=0},
		{name="air", prob=254, param2=0},
		{name="air", prob=254, param2=0},
		{name="air", prob=254, param2=0},
		{name="vlf_core:stonebrick", prob=254, param2=0},
		{name="vlf_core:stonebrick", prob=254, param2=0},
		{name="air", prob=254, param2=0},
		{name="air", prob=254, param2=0},
		{name="air", prob=254, param2=0},
		{name="air", prob=254, param2=0},
		{name="air", prob=254, param2=0},
		{name="air", prob=254, param2=0},
		{name="air", prob=254, param2=0},
		{name="air", prob=254, param2=0},
		{name="air", prob=254, param2=0},
		{name="air", prob=254, param2=0},
		{name="air", prob=254, param2=0},
		{name="vlf_core:stonebrick", prob=254, param2=0},
		{name="vlf_core:stonebrick", prob=254, param2=0},
		{name="air", prob=254, param2=0},
		{name="air", prob=254, param2=0},
		{name="air", prob=254, param2=0},
		{name="air", prob=254, param2=0},
		{name="air", prob=254, param2=0},
		{name="air", prob=254, param2=0},
		{name="air", prob=254, param2=0},
		{name="air", prob=254, param2=0},
		{name="air", prob=254, param2=0},
		{name="air", prob=254, param2=0},
		{name="air", prob=254, param2=0},
		{name="vlf_core:stonebrick", prob=254, param2=0},
		{name="vlf_core:stonebrick", prob=254, param2=0},
		{name="air", prob=254, param2=0},
		{name="air", prob=254, param2=0},
		{name="air", prob=254, param2=0},
		{name="air", prob=254, param2=0},
		{name="air", prob=254, param2=0},
		{name="air", prob=254, param2=0},
		{name="air", prob=254, param2=0},
		{name="air", prob=254, param2=0},
		{name="air", prob=254, param2=0},
		{name="air", prob=254, param2=0},
		{name="air", prob=254, param2=0},
		{name="vlf_core:stonebrick", prob=254, param2=0},
		{name="vlf_core:stonebrick", prob=254, param2=0},
		{name="air", prob=254, param2=0},
		{name="air", prob=254, param2=0},
		{name="air", prob=254, param2=0},
		{name="air", prob=254, param2=0},
		{name="air", prob=254, param2=0},
		{name="air", prob=254, param2=0},
		{name="air", prob=254, param2=0},
		{name="air", prob=254, param2=0},
		{name="air", prob=254, param2=0},
		{name="air", prob=254, param2=0},
		{name="air", prob=254, param2=0},
		{name="vlf_core:stonebrick", prob=254, param2=0},
		{name="vlf_core:stonebrick", prob=254, param2=0},
		{name="vlf_core:stonebrick", prob=254, param2=0},
		{name="vlf_core:stonebrick", prob=254, param2=0},
		{name="vlf_core:stonebrick", prob=254, param2=0},
		{name="vlf_core:stonebrick", prob=254, param2=0},
		{name="vlf_core:stonebrick", prob=254, param2=0},
		{name="vlf_core:stonebrick", prob=254, param2=0},
		{name="vlf_core:stonebrick", prob=254, param2=0},
		{name="vlf_core:stonebrick", prob=254, param2=0},
		{name="vlf_core:stonebrick", prob=254, param2=0},
		{name="vlf_core:stonebrick", prob=254, param2=0},
		{name="vlf_core:stonebrick", prob=254, param2=0},
		{name="vlf_core:stonebrick", prob=254, param2=0},
		{name="vlf_core:stonebrick", prob=254, param2=0},
		{name="vlf_core:stonebrick", prob=254, param2=0},
		{name="vlf_core:stonebrick", prob=254, param2=0},
		{name="vlf_core:stonebrick", prob=254, param2=0},
		{name="vlf_core:stonebrick", prob=254, param2=0},
		{name="vlf_core:stonebrick", prob=254, param2=0},
		{name="vlf_core:stonebrick", prob=254, param2=0},
		{name="vlf_core:stonebrick", prob=254, param2=0},
		{name="vlf_core:stonebrick", prob=254, param2=0},
		{name="vlf_core:stonebrick", prob=254, param2=0},
		{name="vlf_core:stonebrick", prob=254, param2=0},
		{name="vlf_core:stonebrick", prob=254, param2=0},
		{name="vlf_core:stonebrick", prob=254, param2=0},
		{name="vlf_core:stonebrick", prob=254, param2=0},
		{name="vlf_core:stonebrick", prob=254, param2=0},
		{name="air", prob=254, param2=0},
		{name="air", prob=254, param2=0},
		{name="air", prob=254, param2=0},
		{name="air", prob=254, param2=0},
		{name="air", prob=254, param2=0},
		{name="air", prob=254, param2=0},
		{name="air", prob=254, param2=0},
		{name="air", prob=254, param2=0},
		{name="air", prob=254, param2=0},
		{name="vlf_core:stonebrick", prob=254, param2=0},
		{name="vlf_core:stonebrick", prob=254, param2=0},
		{name="xpanes:bar_flat", prob=254, param2=3},
		{name="air", prob=254, param2=0},
		{name="air", prob=254, param2=0},
		{name="air", prob=254, param2=0},
		{name="air", prob=254, param2=0},
		{name="air", prob=254, param2=0},
		{name="air", prob=254, param2=0},
		{name="air", prob=254, param2=0},
		{name="air", prob=254, param2=0},
		{name="air", prob=254, param2=0},
		{name="air", prob=254, param2=0},
		{name="air", prob=254, param2=0},
		{name="xpanes:bar_flat", prob=254, param2=3},
		{name="xpanes:bar_flat", prob=254, param2=3},
		{name="air", prob=254, param2=0},
		{name="air", prob=254, param2=0},
		{name="air", prob=254, param2=0},
		{name="air", prob=254, param2=0},
		{name="air", prob=254, param2=0},
		{name="air", prob=254, param2=0},
		{name="air", prob=254, param2=0},
		{name="air", prob=254, param2=0},
		{name="air", prob=254, param2=0},
		{name="air", prob=254, param2=0},
		{name="air", prob=254, param2=0},
		{name="xpanes:bar_flat", prob=254, param2=3},
		{name="vlf_core:stonebrick", prob=254, param2=0},
		{name="air", prob=254, param2=0},
		{name="air", prob=254, param2=0},
		{name="air", prob=254, param2=0},
		{name="air", prob=254, param2=0},
		{name="air", prob=254, param2=0},
		{name="air", prob=254, param2=0},
		{name="air", prob=254, param2=0},
		{name="air", prob=254, param2=0},
		{name="air", prob=254, param2=0},
		{name="air", prob=254, param2=0},
		{name="air", prob=254, param2=0},
		{name="vlf_core:stonebrick", prob=254, param2=0},
		{name="vlf_core:stonebrick", prob=254, param2=0},
		{name="air", prob=254, param2=0},
		{name="air", prob=254, param2=0},
		{name="air", prob=254, param2=0},
		{name="air", prob=254, param2=0},
		{name="air", prob=254, param2=0},
		{name="air", prob=254, param2=0},
		{name="air", prob=254, param2=0},
		{name="air", prob=254, param2=0},
		{name="air", prob=254, param2=0},
		{name="air", prob=254, param2=0},
		{name="air", prob=254, param2=0},
		{name="vlf_core:stonebrick", prob=254, param2=0},
		{name="vlf_core:stonebrick", prob=254, param2=0},
		{name="air", prob=254, param2=0},
		{name="air", prob=254, param2=0},
		{name="air", prob=254, param2=0},
		{name="air", prob=254, param2=0},
		{name="air", prob=254, param2=0},
		{name="air", prob=254, param2=0},
		{name="air", prob=254, param2=0},
		{name="air", prob=254, param2=0},
		{name="air", prob=254, param2=0},
		{name="air", prob=254, param2=0},
		{name="air", prob=254, param2=0},
		{name="vlf_core:stonebrick", prob=254, param2=0},
		{name="vlf_core:stonebrick", prob=254, param2=0},
		{name="vlf_core:stonebrick", prob=254, param2=0},
		{name="vlf_core:stonebrick", prob=254, param2=0},
		{name="vlf_core:stonebrick", prob=254, param2=0},
		{name="vlf_core:stonebrick", prob=254, param2=0},
		{name="vlf_core:stonebrick", prob=254, param2=0},
		{name="vlf_core:stonebrick", prob=254, param2=0},
		{name="vlf_core:stonebrick", prob=254, param2=0},
		{name="vlf_core:stonebrick", prob=254, param2=0},
		{name="vlf_core:stonebrick", prob=254, param2=0},
		{name="vlf_core:stonebrick", prob=254, param2=0},
		{name="vlf_core:stonebrick", prob=254, param2=0},
		{name="vlf_core:stonebrick", prob=254, param2=0},
		{name="vlf_core:stonebrick", prob=254, param2=0},
		{name="vlf_core:stonebrick", prob=254, param2=0},
		{name="vlf_core:stonebrick", prob=254, param2=0},
		{name="vlf_core:stonebrick", prob=254, param2=0},
		{name="vlf_core:stonebrick", prob=254, param2=0},
		{name="vlf_core:stonebrick", prob=254, param2=0},
		{name="vlf_core:stonebrick", prob=254, param2=0},
		{name="vlf_core:stonebrick", prob=254, param2=0},
		{name="vlf_core:stonebrick", prob=254, param2=0},
		{name="vlf_core:stonebrick", prob=254, param2=0},
		{name="vlf_core:stonebrick", prob=254, param2=0},
		{name="vlf_core:stonebrick", prob=254, param2=0},
		{name="vlf_core:stonebrick", prob=254, param2=0},
		{name="vlf_core:stonebrick", prob=254, param2=0},
		{name="air", prob=254, param2=0},
		{name="air", prob=254, param2=0},
		{name="vlf_stairs:stair_stonebrick_outer", prob=254, param2=1},
		{name="vlf_stairs:stair_stonebrick", prob=254, param2=0},
		{name="vlf_stairs:stair_stonebrick", prob=254, param2=0},
		{name="vlf_stairs:stair_stonebrick", prob=254, param2=0},
		{name="vlf_stairs:stair_stonebrick", prob=254, param2=0},
		{name="vlf_stairs:stair_stonebrick", prob=254, param2=0},
		{name="vlf_stairs:stair_stonebrick_outer", prob=254, param2=0},
		{name="air", prob=254, param2=0},
		{name="air", prob=254, param2=0},
		{name="vlf_core:stonebrick", prob=254, param2=0},
		{name="vlf_core:stonebrick", prob=254, param2=0},
		{name="air", prob=254, param2=0},
		{name="air", prob=254, param2=0},
		{name="air", prob=254, param2=0},
		{name="air", prob=254, param2=0},
		{name="air", prob=254, param2=0},
		{name="air", prob=254, param2=0},
		{name="air", prob=254, param2=0},
		{name="air", prob=254, param2=0},
		{name="air", prob=254, param2=0},
		{name="air", prob=254, param2=0},
		{name="air", prob=254, param2=0},
		{name="vlf_core:stonebrick", prob=254, param2=0},
		{name="vlf_core:stonebrick", prob=254, param2=0},
		{name="air", prob=254, param2=0},
		{name="air", prob=254, param2=0},
		{name="air", prob=254, param2=0},
		{name="air", prob=254, param2=0},
		{name="air", prob=254, param2=0},
		{name="air", prob=254, param2=0},
		{name="air", prob=254, param2=0},
		{name="air", prob=254, param2=0},
		{name="air", prob=254, param2=0},
		{name="air", prob=254, param2=0},
		{name="air", prob=254, param2=0},
		{name="vlf_core:stonebrick", prob=254, param2=0},
		{name="vlf_core:stonebrick", prob=254, param2=0},
		{name="air", prob=254, param2=0},
		{name="air", prob=254, param2=0},
		{name="air", prob=254, param2=0},
		{name="air", prob=254, param2=0},
		{name="air", prob=254, param2=0},
		{name="air", prob=254, param2=0},
		{name="air", prob=254, param2=0},
		{name="air", prob=254, param2=0},
		{name="air", prob=254, param2=0},
		{name="air", prob=254, param2=0},
		{name="air", prob=254, param2=0},
		{name="vlf_core:stonebrick", prob=254, param2=0},
		{name="vlf_core:stonebrick", prob=254, param2=0},
		{name="air", prob=254, param2=0},
		{name="air", prob=254, param2=0},
		{name="air", prob=254, param2=0},
		{name="air", prob=254, param2=0},
		{name="air", prob=254, param2=0},
		{name="air", prob=254, param2=0},
		{name="air", prob=254, param2=0},
		{name="air", prob=254, param2=0},
		{name="air", prob=254, param2=0},
		{name="air", prob=254, param2=0},
		{name="air", prob=254, param2=0},
		{name="vlf_core:stonebrick", prob=254, param2=0},
		{name="vlf_core:stonebrick", prob=254, param2=0},
		{name="air", prob=254, param2=0},
		{name="air", prob=254, param2=0},
		{name="air", prob=254, param2=0},
		{name="air", prob=254, param2=0},
		{name="air", prob=254, param2=0},
		{name="air", prob=254, param2=0},
		{name="air", prob=254, param2=0},
		{name="air", prob=254, param2=0},
		{name="air", prob=254, param2=0},
		{name="air", prob=254, param2=0},
		{name="air", prob=254, param2=0},
		{name="vlf_core:stonebrick", prob=254, param2=0},
		{name="vlf_core:stonebrick", prob=254, param2=0},
		{name="vlf_core:stonebrick", prob=254, param2=0},
		{name="vlf_core:stonebrick", prob=254, param2=0},
		{name="vlf_core:stonebrick", prob=254, param2=0},
		{name="vlf_core:stonebrick", prob=254, param2=0},
		{name="vlf_core:stonebrick", prob=254, param2=0},
		{name="vlf_core:stonebrick", prob=254, param2=0},
		{name="vlf_core:stonebrick", prob=254, param2=0},
		{name="vlf_core:stonebrick", prob=254, param2=0},
		{name="vlf_core:stonebrick", prob=254, param2=0},
		{name="vlf_core:stonebrick", prob=254, param2=0},
		{name="vlf_core:stonebrick", prob=254, param2=0},
		{name="vlf_core:stonebrick", prob=254, param2=0},
		{name="vlf_core:stonebrick", prob=254, param2=0},
		{name="vlf_core:stonebrick", prob=254, param2=0},
		{name="vlf_core:stonebrick", prob=254, param2=0},
		{name="vlf_core:stonebrick", prob=254, param2=0},
		{name="vlf_core:stonebrick", prob=254, param2=0},
		{name="vlf_core:stonebrick", prob=254, param2=0},
		{name="vlf_core:stonebrick", prob=254, param2=0},
		{name="vlf_core:stonebrick", prob=254, param2=0},
		{name="vlf_core:stonebrick", prob=254, param2=0},
		{name="vlf_core:stonebrick", prob=254, param2=0},
		{name="vlf_core:stonebrick", prob=254, param2=0},
		{name="vlf_core:stonebrick", prob=254, param2=0},
		{name="vlf_core:stonebrick", prob=254, param2=0},
		{name="vlf_core:stonebrick", prob=254, param2=0},
		{name="air", prob=254, param2=0},
		{name="air", prob=254, param2=0},
		{name="vlf_stairs:stair_stonebrick", prob=254, param2=1},
		{name="vlf_core:stonebrick", prob=254, param2=0},
		{name="vlf_core:stonebrick", prob=254, param2=0},
		{name="vlf_core:stonebrick", prob=254, param2=0},
		{name="vlf_core:stonebrick", prob=254, param2=0},
		{name="vlf_core:stonebrick", prob=254, param2=0},
		{name="vlf_stairs:stair_stonebrick", prob=254, param2=3},
		{name="air", prob=254, param2=0},
		{name="air", prob=254, param2=0},
		{name="vlf_core:stonebrick", prob=254, param2=0},
		{name="xpanes:bar_flat", prob=254, param2=3},
		{name="air", prob=254, param2=0},
		{name="air", prob=254, param2=0},
		{name="air", prob=254, param2=0},
		{name="air", prob=254, param2=0},
		{name="vlf_portals:end_portal_frame", prob=254, param2=0},
		{name="vlf_portals:end_portal_frame", prob=254, param2=0},
		{name="vlf_portals:end_portal_frame", prob=254, param2=0},
		{name="air", prob=254, param2=0},
		{name="air", prob=254, param2=0},
		{name="air", prob=254, param2=0},
		{name="air", prob=254, param2=0},
		{name="xpanes:bar_flat", prob=254, param2=3},
		{name="xpanes:bar_flat", prob=254, param2=3},
		{name="air", prob=254, param2=0},
		{name="air", prob=254, param2=0},
		{name="air", prob=254, param2=0},
		{name="air", prob=254, param2=0},
		{name="air", prob=254, param2=0},
		{name="air", prob=254, param2=0},
		{name="air", prob=254, param2=0},
		{name="air", prob=254, param2=0},
		{name="air", prob=254, param2=0},
		{name="air", prob=254, param2=0},
		{name="air", prob=254, param2=0},
		{name="xpanes:bar_flat", prob=254, param2=3},
		{name="vlf_core:stonebrick", prob=254, param2=0},
		{name="air", prob=254, param2=0},
		{name="air", prob=254, param2=0},
		{name="air", prob=254, param2=0},
		{name="air", prob=254, param2=0},
		{name="air", prob=254, param2=0},
		{name="air", prob=254, param2=0},
		{name="air", prob=254, param2=0},
		{name="air", prob=254, param2=0},
		{name="air", prob=254, param2=0},
		{name="air", prob=254, param2=0},
		{name="air", prob=254, param2=0},
		{name="vlf_core:stonebrick", prob=254, param2=0},
		{name="vlf_core:stonebrick", prob=254, param2=0},
		{name="air", prob=254, param2=0},
		{name="air", prob=254, param2=0},
		{name="air", prob=254, param2=0},
		{name="air", prob=254, param2=0},
		{name="air", prob=254, param2=0},
		{name="air", prob=254, param2=0},
		{name="air", prob=254, param2=0},
		{name="air", prob=254, param2=0},
		{name="air", prob=254, param2=0},
		{name="air", prob=254, param2=0},
		{name="air", prob=254, param2=0},
		{name="vlf_core:stonebrick", prob=254, param2=0},
		{name="vlf_core:stonebrick", prob=254, param2=0},
		{name="air", prob=254, param2=0},
		{name="air", prob=254, param2=0},
		{name="air", prob=254, param2=0},
		{name="air", prob=254, param2=0},
		{name="air", prob=254, param2=0},
		{name="air", prob=254, param2=0},
		{name="air", prob=254, param2=0},
		{name="air", prob=254, param2=0},
		{name="air", prob=254, param2=0},
		{name="air", prob=254, param2=0},
		{name="air", prob=254, param2=0},
		{name="vlf_core:stonebrick", prob=254, param2=0},
		{name="vlf_core:stonebrick", prob=254, param2=0},
		{name="vlf_core:stonebrick", prob=254, param2=0},
		{name="vlf_core:stonebrick", prob=254, param2=0},
		{name="vlf_core:stonebrick", prob=254, param2=0},
		{name="vlf_core:stonebrick", prob=254, param2=0},
		{name="vlf_core:stonebrick", prob=254, param2=0},
		{name="vlf_core:stonebrick", prob=254, param2=0},
		{name="vlf_core:stonebrick", prob=254, param2=0},
		{name="vlf_core:stonebrick", prob=254, param2=0},
		{name="vlf_core:stonebrick", prob=254, param2=0},
		{name="vlf_core:stonebrick", prob=254, param2=0},
		{name="vlf_core:stonebrick", prob=254, param2=0},
		{name="vlf_core:stonebrick", prob=254, param2=0},
		{name="vlf_core:stonebrick", prob=254, param2=0},
		{name="vlf_core:stonebrick", prob=254, param2=0},
		{name="vlf_core:stonebrick", prob=254, param2=0},
		{name="vlf_core:stonebrick", prob=254, param2=0},
		{name="vlf_core:stonebrick", prob=254, param2=0},
		{name="vlf_core:stonebrick", prob=254, param2=0},
		{name="vlf_core:stonebrick", prob=254, param2=0},
		{name="vlf_core:stonebrick", prob=254, param2=0},
		{name="vlf_core:stonebrick", prob=254, param2=0},
		{name="vlf_core:stonebrick", prob=254, param2=0},
		{name="vlf_core:stonebrick", prob=254, param2=0},
		{name="vlf_core:stonebrick", prob=254, param2=0},
		{name="vlf_core:stonebrick", prob=254, param2=0},
		{name="vlf_core:stonebrick", prob=254, param2=0},
		{name="air", prob=254, param2=0},
		{name="air", prob=254, param2=0},
		{name="vlf_stairs:stair_stonebrick", prob=254, param2=1},
		{name="vlf_core:stonebrick", prob=254, param2=0},
		{name="vlf_core:bedrock", prob=254, param2=0},
		{name="vlf_core:bedrock", prob=254, param2=0},
		{name="vlf_core:bedrock", prob=254, param2=0},
		{name="vlf_core:stonebrick", prob=254, param2=0},
		{name="vlf_stairs:stair_stonebrick", prob=254, param2=3},
		{name="air", prob=254, param2=0},
		{name="air", prob=254, param2=0},
		{name="vlf_core:stonebrick", prob=254, param2=0},
		{name="vlf_core:stonebrick", prob=254, param2=0},
		{name="air", prob=254, param2=0},
		{name="air", prob=254, param2=0},
		{name="air", prob=254, param2=0},
		{name="vlf_portals:end_portal_frame", prob=254, param2=1},
		{name="air", prob=254, param2=0},
		{name="air", prob=254, param2=0},
		{name="air", prob=254, param2=0},
		{name="vlf_portals:end_portal_frame", prob=254, param2=3},
		{name="air", prob=254, param2=0},
		{name="air", prob=254, param2=0},
		{name="air", prob=254, param2=0},
		{name="vlf_core:stonebrick", prob=254, param2=0},
		{name="vlf_core:stonebrick", prob=254, param2=0},
		{name="air", prob=254, param2=0},
		{name="air", prob=254, param2=0},
		{name="air", prob=254, param2=0},
		{name="air", prob=254, param2=0},
		{name="air", prob=254, param2=0},
		{name="air", prob=254, param2=0},
		{name="air", prob=254, param2=0},
		{name="air", prob=254, param2=0},
		{name="air", prob=254, param2=0},
		{name="air", prob=254, param2=0},
		{name="air", prob=254, param2=0},
		{name="vlf_core:stonebrick", prob=254, param2=0},
		{name="vlf_core:stonebrick", prob=254, param2=0},
		{name="air", prob=254, param2=0},
		{name="air", prob=254, param2=0},
		{name="air", prob=254, param2=0},
		{name="air", prob=254, param2=0},
		{name="air", prob=254, param2=0},
		{name="air", prob=254, param2=0},
		{name="air", prob=254, param2=0},
		{name="air", prob=254, param2=0},
		{name="air", prob=254, param2=0},
		{name="air", prob=254, param2=0},
		{name="air", prob=254, param2=0},
		{name="vlf_core:stonebrick", prob=254, param2=0},
		{name="vlf_core:stonebrick", prob=254, param2=0},
		{name="air", prob=254, param2=0},
		{name="air", prob=254, param2=0},
		{name="air", prob=254, param2=0},
		{name="air", prob=254, param2=0},
		{name="air", prob=254, param2=0},
		{name="air", prob=254, param2=0},
		{name="air", prob=254, param2=0},
		{name="air", prob=254, param2=0},
		{name="air", prob=254, param2=0},
		{name="air", prob=254, param2=0},
		{name="air", prob=254, param2=0},
		{name="vlf_core:stonebrick", prob=254, param2=0},
		{name="vlf_core:stonebrick", prob=254, param2=0},
		{name="air", prob=254, param2=0},
		{name="air", prob=254, param2=0},
		{name="air", prob=254, param2=0},
		{name="air", prob=254, param2=0},
		{name="air", prob=254, param2=0},
		{name="air", prob=254, param2=0},
		{name="air", prob=254, param2=0},
		{name="air", prob=254, param2=0},
		{name="air", prob=254, param2=0},
		{name="air", prob=254, param2=0},
		{name="air", prob=254, param2=0},
		{name="vlf_core:stonebrick", prob=254, param2=0},
		{name="vlf_core:stonebrick", prob=254, param2=0},
		{name="vlf_core:stonebrick", prob=254, param2=0},
		{name="vlf_core:stonebrick", prob=254, param2=0},
		{name="vlf_core:stonebrick", prob=254, param2=0},
		{name="vlf_core:stonebrick", prob=254, param2=0},
		{name="vlf_core:stonebrick", prob=254, param2=0},
		{name="vlf_core:stonebrick", prob=254, param2=0},
		{name="vlf_core:stonebrick", prob=254, param2=0},
		{name="vlf_core:stonebrick", prob=254, param2=0},
		{name="vlf_core:stonebrick", prob=254, param2=0},
		{name="vlf_core:stonebrick", prob=254, param2=0},
		{name="vlf_core:stonebrick", prob=254, param2=0},
		{name="vlf_core:stonebrick", prob=254, param2=0},
		{name="vlf_core:stonebrick", prob=254, param2=0},
		{name="vlf_core:stonebrick", prob=254, param2=0},
		{name="vlf_core:stonebrick", prob=254, param2=0},
		{name="vlf_core:stonebrick", prob=254, param2=0},
		{name="vlf_core:stonebrick", prob=254, param2=0},
		{name="vlf_core:stonebrick", prob=254, param2=0},
		{name="vlf_core:stonebrick", prob=254, param2=0},
		{name="vlf_core:stonebrick", prob=254, param2=0},
		{name="vlf_core:stonebrick", prob=254, param2=0},
		{name="vlf_core:stonebrick", prob=254, param2=0},
		{name="vlf_core:stonebrick", prob=254, param2=0},
		{name="vlf_core:stonebrick", prob=254, param2=0},
		{name="vlf_core:stonebrick", prob=254, param2=0},
		{name="air", prob=254, param2=0},
		{name="air", prob=254, param2=0},
		{name="air", prob=254, param2=0},
		{name="vlf_stairs:stair_stonebrick", prob=254, param2=1},
		{name="vlf_core:stonebrick", prob=254, param2=0},
		{name="vlf_core:bedrock", prob=254, param2=0},
		{name="vlf_core:bedrock", prob=254, param2=0},
		{name="vlf_core:bedrock", prob=254, param2=0},
		{name="vlf_core:stonebrick", prob=254, param2=0},
		{name="vlf_stairs:stair_stonebrick", prob=254, param2=3},
		{name="air", prob=254, param2=0},
		{name="air", prob=254, param2=0},
		{name="air", prob=254, param2=0},
		{name="air", prob=254, param2=0},
		{name="air", prob=254, param2=0},
		{name="air", prob=254, param2=0},
		{name="air", prob=254, param2=0},
		{name="vlf_portals:end_portal_frame", prob=254, param2=1},
		{name="air", prob=254, param2=0},
		{name="air", prob=254, param2=0},
		{name="air", prob=254, param2=0},
		{name="vlf_portals:end_portal_frame", prob=254, param2=3},
		{name="air", prob=254, param2=0},
		{name="air", prob=254, param2=0},
		{name="air", prob=254, param2=0},
		{name="air", prob=254, param2=0},
		{name="vlf_core:stonebrick", prob=254, param2=0},
		{name="air", prob=254, param2=0},
		{name="air", prob=254, param2=0},
		{name="air", prob=254, param2=0},
		{name="air", prob=254, param2=0},
		{name="air", prob=254, param2=0},
		{name="air", prob=254, param2=0},
		{name="air", prob=254, param2=0},
		{name="air", prob=254, param2=0},
		{name="air", prob=254, param2=0},
		{name="air", prob=254, param2=0},
		{name="air", prob=254, param2=0},
		{name="vlf_core:stonebrick", prob=254, param2=0},
		{name="vlf_core:stonebrick", prob=254, param2=0},
		{name="air", prob=254, param2=0},
		{name="air", prob=254, param2=0},
		{name="air", prob=254, param2=0},
		{name="air", prob=254, param2=0},
		{name="air", prob=254, param2=0},
		{name="air", prob=254, param2=0},
		{name="air", prob=254, param2=0},
		{name="air", prob=254, param2=0},
		{name="air", prob=254, param2=0},
		{name="air", prob=254, param2=0},
		{name="air", prob=254, param2=0},
		{name="vlf_core:stonebrick", prob=254, param2=0},
		{name="vlf_core:stonebrick", prob=254, param2=0},
		{name="air", prob=254, param2=0},
		{name="air", prob=254, param2=0},
		{name="air", prob=254, param2=0},
		{name="air", prob=254, param2=0},
		{name="air", prob=254, param2=0},
		{name="air", prob=254, param2=0},
		{name="air", prob=254, param2=0},
		{name="air", prob=254, param2=0},
		{name="air", prob=254, param2=0},
		{name="air", prob=254, param2=0},
		{name="air", prob=254, param2=0},
		{name="vlf_core:stonebrick", prob=254, param2=0},
		{name="vlf_core:stonebrick", prob=254, param2=0},
		{name="air", prob=254, param2=0},
		{name="air", prob=254, param2=0},
		{name="air", prob=254, param2=0},
		{name="air", prob=254, param2=0},
		{name="air", prob=254, param2=0},
		{name="air", prob=254, param2=0},
		{name="air", prob=254, param2=0},
		{name="air", prob=254, param2=0},
		{name="air", prob=254, param2=0},
		{name="air", prob=254, param2=0},
		{name="air", prob=254, param2=0},
		{name="vlf_core:stonebrick", prob=254, param2=0},
		{name="vlf_core:stonebrick", prob=254, param2=0},
		{name="vlf_core:stonebrick", prob=254, param2=0},
		{name="vlf_core:stonebrick", prob=254, param2=0},
		{name="vlf_core:stonebrick", prob=254, param2=0},
		{name="vlf_core:stonebrick", prob=254, param2=0},
		{name="vlf_core:stonebrick", prob=254, param2=0},
		{name="vlf_core:stonebrick", prob=254, param2=0},
		{name="vlf_core:stonebrick", prob=254, param2=0},
		{name="vlf_core:stonebrick", prob=254, param2=0},
		{name="vlf_core:stonebrick", prob=254, param2=0},
		{name="vlf_core:stonebrick", prob=254, param2=0},
		{name="vlf_core:stonebrick", prob=254, param2=0},
		{name="vlf_core:stonebrick", prob=254, param2=0},
		{name="vlf_core:stonebrick", prob=254, param2=0},
		{name="vlf_core:stonebrick", prob=254, param2=0},
		{name="vlf_core:stonebrick", prob=254, param2=0},
		{name="vlf_core:stonebrick", prob=254, param2=0},
		{name="vlf_core:stonebrick", prob=254, param2=0},
		{name="vlf_core:stonebrick", prob=254, param2=0},
		{name="vlf_core:stonebrick", prob=254, param2=0},
		{name="vlf_core:stonebrick", prob=254, param2=0},
		{name="vlf_core:stonebrick", prob=254, param2=0},
		{name="vlf_core:stonebrick", prob=254, param2=0},
		{name="vlf_core:stonebrick", prob=254, param2=0},
		{name="vlf_core:stonebrick", prob=254, param2=0},
		{name="vlf_core:stonebrick", prob=254, param2=0},
		{name="vlf_core:stonebrick", prob=254, param2=0},
		{name="air", prob=254, param2=0},
		{name="air", prob=254, param2=0},
		{name="vlf_stairs:stair_stonebrick", prob=254, param2=1},
		{name="vlf_core:stonebrick", prob=254, param2=0},
		{name="vlf_core:bedrock", prob=254, param2=0},
		{name="vlf_core:bedrock", prob=254, param2=0},
		{name="vlf_core:bedrock", prob=254, param2=0},
		{name="vlf_core:stonebrick", prob=254, param2=0},
		{name="vlf_stairs:stair_stonebrick", prob=254, param2=3},
		{name="air", prob=254, param2=0},
		{name="air", prob=254, param2=0},
		{name="vlf_core:stonebrick", prob=254, param2=0},
		{name="vlf_core:stonebrick", prob=254, param2=0},
		{name="air", prob=254, param2=0},
		{name="air", prob=254, param2=0},
		{name="air", prob=254, param2=0},
		{name="vlf_portals:end_portal_frame", prob=254, param2=1},
		{name="air", prob=254, param2=0},
		{name="air", prob=254, param2=0},
		{name="air", prob=254, param2=0},
		{name="vlf_portals:end_portal_frame", prob=254, param2=3},
		{name="air", prob=254, param2=0},
		{name="air", prob=254, param2=0},
		{name="air", prob=254, param2=0},
		{name="vlf_core:stonebrick", prob=254, param2=0},
		{name="vlf_core:stonebrick", prob=254, param2=0},
		{name="air", prob=254, param2=0},
		{name="air", prob=254, param2=0},
		{name="air", prob=254, param2=0},
		{name="air", prob=254, param2=0},
		{name="air", prob=254, param2=0},
		{name="air", prob=254, param2=0},
		{name="air", prob=254, param2=0},
		{name="air", prob=254, param2=0},
		{name="air", prob=254, param2=0},
		{name="air", prob=254, param2=0},
		{name="air", prob=254, param2=0},
		{name="vlf_core:stonebrick", prob=254, param2=0},
		{name="vlf_core:stonebrick", prob=254, param2=0},
		{name="air", prob=254, param2=0},
		{name="air", prob=254, param2=0},
		{name="air", prob=254, param2=0},
		{name="air", prob=254, param2=0},
		{name="air", prob=254, param2=0},
		{name="air", prob=254, param2=0},
		{name="air", prob=254, param2=0},
		{name="air", prob=254, param2=0},
		{name="air", prob=254, param2=0},
		{name="air", prob=254, param2=0},
		{name="air", prob=254, param2=0},
		{name="vlf_core:stonebrick", prob=254, param2=0},
		{name="vlf_core:stonebrick", prob=254, param2=0},
		{name="air", prob=254, param2=0},
		{name="air", prob=254, param2=0},
		{name="air", prob=254, param2=0},
		{name="air", prob=254, param2=0},
		{name="air", prob=254, param2=0},
		{name="air", prob=254, param2=0},
		{name="air", prob=254, param2=0},
		{name="air", prob=254, param2=0},
		{name="air", prob=254, param2=0},
		{name="air", prob=254, param2=0},
		{name="air", prob=254, param2=0},
		{name="vlf_core:stonebrick", prob=254, param2=0},
		{name="vlf_core:stonebrick", prob=254, param2=0},
		{name="air", prob=254, param2=0},
		{name="air", prob=254, param2=0},
		{name="air", prob=254, param2=0},
		{name="air", prob=254, param2=0},
		{name="air", prob=254, param2=0},
		{name="air", prob=254, param2=0},
		{name="air", prob=254, param2=0},
		{name="air", prob=254, param2=0},
		{name="air", prob=254, param2=0},
		{name="air", prob=254, param2=0},
		{name="air", prob=254, param2=0},
		{name="vlf_core:stonebrick", prob=254, param2=0},
		{name="vlf_core:stonebrick", prob=254, param2=0},
		{name="vlf_core:stonebrick", prob=254, param2=0},
		{name="vlf_core:stonebrick", prob=254, param2=0},
		{name="vlf_core:stonebrick", prob=254, param2=0},
		{name="vlf_core:stonebrick", prob=254, param2=0},
		{name="vlf_core:stonebrick", prob=254, param2=0},
		{name="vlf_core:stonebrick", prob=254, param2=0},
		{name="vlf_core:stonebrick", prob=254, param2=0},
		{name="vlf_core:stonebrick", prob=254, param2=0},
		{name="vlf_core:stonebrick", prob=254, param2=0},
		{name="vlf_core:stonebrick", prob=254, param2=0},
		{name="vlf_core:stonebrick", prob=254, param2=0},
		{name="vlf_core:stonebrick", prob=254, param2=0},
		{name="vlf_core:stonebrick", prob=254, param2=0},
		{name="vlf_core:stonebrick", prob=254, param2=0},
		{name="vlf_core:stonebrick", prob=254, param2=0},
		{name="vlf_core:stonebrick", prob=254, param2=0},
		{name="vlf_core:stonebrick", prob=254, param2=0},
		{name="vlf_core:stonebrick", prob=254, param2=0},
		{name="vlf_core:stonebrick", prob=254, param2=0},
		{name="vlf_core:stonebrick", prob=254, param2=0},
		{name="vlf_core:stonebrick", prob=254, param2=0},
		{name="vlf_core:stonebrick", prob=254, param2=0},
		{name="vlf_core:stonebrick", prob=254, param2=0},
		{name="vlf_core:stonebrick", prob=254, param2=0},
		{name="vlf_core:stonebrick", prob=254, param2=0},
		{name="vlf_core:stonebrick", prob=254, param2=0},
		{name="air", prob=254, param2=0},
		{name="air", prob=254, param2=0},
		{name="vlf_stairs:stair_stonebrick", prob=254, param2=1},
		{name="vlf_mobspawners:spawner", prob=254, param2=0},
		{name="vlf_core:stonebrick", prob=254, param2=0},
		{name="vlf_core:stonebrick", prob=254, param2=0},
		{name="vlf_core:stonebrick", prob=254, param2=0},
		{name="vlf_core:stonebrick", prob=254, param2=0},
		{name="vlf_stairs:stair_stonebrick", prob=254, param2=3},
		{name="air", prob=254, param2=0},
		{name="air", prob=254, param2=0},
		{name="vlf_core:stonebrick", prob=254, param2=0},
		{name="xpanes:bar_flat", prob=254, param2=3},
		{name="air", prob=254, param2=0},
		{name="air", prob=254, param2=0},
		{name="air", prob=254, param2=0},
		{name="air", prob=254, param2=0},
		{name="vlf_portals:end_portal_frame", prob=254, param2=2},
		{name="vlf_portals:end_portal_frame", prob=254, param2=2},
		{name="vlf_portals:end_portal_frame", prob=254, param2=2},
		{name="air", prob=254, param2=0},
		{name="air", prob=254, param2=0},
		{name="air", prob=254, param2=0},
		{name="air", prob=254, param2=0},
		{name="xpanes:bar_flat", prob=254, param2=3},
		{name="xpanes:bar_flat", prob=254, param2=3},
		{name="air", prob=254, param2=0},
		{name="air", prob=254, param2=0},
		{name="air", prob=254, param2=0},
		{name="air", prob=254, param2=0},
		{name="air", prob=254, param2=0},
		{name="air", prob=254, param2=0},
		{name="air", prob=254, param2=0},
		{name="air", prob=254, param2=0},
		{name="air", prob=254, param2=0},
		{name="air", prob=254, param2=0},
		{name="air", prob=254, param2=0},
		{name="xpanes:bar_flat", prob=254, param2=3},
		{name="vlf_core:stonebrick", prob=254, param2=0},
		{name="air", prob=254, param2=0},
		{name="air", prob=254, param2=0},
		{name="air", prob=254, param2=0},
		{name="air", prob=254, param2=0},
		{name="air", prob=254, param2=0},
		{name="air", prob=254, param2=0},
		{name="air", prob=254, param2=0},
		{name="air", prob=254, param2=0},
		{name="air", prob=254, param2=0},
		{name="air", prob=254, param2=0},
		{name="air", prob=254, param2=0},
		{name="vlf_core:stonebrick", prob=254, param2=0},
		{name="vlf_core:stonebrick", prob=254, param2=0},
		{name="air", prob=254, param2=0},
		{name="air", prob=254, param2=0},
		{name="air", prob=254, param2=0},
		{name="air", prob=254, param2=0},
		{name="air", prob=254, param2=0},
		{name="air", prob=254, param2=0},
		{name="air", prob=254, param2=0},
		{name="air", prob=254, param2=0},
		{name="air", prob=254, param2=0},
		{name="air", prob=254, param2=0},
		{name="air", prob=254, param2=0},
		{name="vlf_core:stonebrick", prob=254, param2=0},
		{name="vlf_core:stonebrick", prob=254, param2=0},
		{name="air", prob=254, param2=0},
		{name="air", prob=254, param2=0},
		{name="air", prob=254, param2=0},
		{name="air", prob=254, param2=0},
		{name="air", prob=254, param2=0},
		{name="air", prob=254, param2=0},
		{name="air", prob=254, param2=0},
		{name="air", prob=254, param2=0},
		{name="air", prob=254, param2=0},
		{name="air", prob=254, param2=0},
		{name="air", prob=254, param2=0},
		{name="vlf_core:stonebrick", prob=254, param2=0},
		{name="vlf_core:stonebrick", prob=254, param2=0},
		{name="vlf_core:stonebrick", prob=254, param2=0},
		{name="vlf_core:stonebrick", prob=254, param2=0},
		{name="vlf_core:stonebrick", prob=254, param2=0},
		{name="vlf_core:stonebrick", prob=254, param2=0},
		{name="vlf_core:stonebrick", prob=254, param2=0},
		{name="vlf_core:stonebrick", prob=254, param2=0},
		{name="vlf_core:stonebrick", prob=254, param2=0},
		{name="vlf_core:stonebrick", prob=254, param2=0},
		{name="vlf_core:stonebrick", prob=254, param2=0},
		{name="vlf_core:stonebrick", prob=254, param2=0},
		{name="vlf_core:stonebrick", prob=254, param2=0},
		{name="vlf_core:stonebrick", prob=254, param2=0},
		{name="vlf_core:stonebrick", prob=254, param2=0},
		{name="vlf_core:stonebrick", prob=254, param2=0},
		{name="vlf_core:stonebrick", prob=254, param2=0},
		{name="vlf_core:stonebrick", prob=254, param2=0},
		{name="vlf_core:stonebrick", prob=254, param2=0},
		{name="vlf_core:stonebrick", prob=254, param2=0},
		{name="vlf_core:stonebrick", prob=254, param2=0},
		{name="vlf_core:stonebrick", prob=254, param2=0},
		{name="vlf_core:stonebrick", prob=254, param2=0},
		{name="vlf_core:stonebrick", prob=254, param2=0},
		{name="vlf_core:stonebrick", prob=254, param2=0},
		{name="vlf_core:stonebrick", prob=254, param2=0},
		{name="vlf_core:stonebrick", prob=254, param2=0},
		{name="vlf_core:stonebrick", prob=254, param2=0},
		{name="air", prob=254, param2=0},
		{name="air", prob=254, param2=0},
		{name="vlf_stairs:stair_stonebrick_outer", prob=254, param2=2},
		{name="vlf_stairs:stair_stonebrick", prob=254, param2=2},
		{name="vlf_stairs:stair_stonebrick", prob=254, param2=2},
		{name="vlf_stairs:stair_stonebrick", prob=254, param2=2},
		{name="vlf_stairs:stair_stonebrick", prob=254, param2=2},
		{name="vlf_stairs:stair_stonebrick", prob=254, param2=2},
		{name="vlf_stairs:stair_stonebrick_outer", prob=254, param2=3},
		{name="air", prob=254, param2=0},
		{name="air", prob=254, param2=0},
		{name="vlf_core:stonebrick", prob=254, param2=0},
		{name="vlf_core:stonebrick", prob=254, param2=0},
		{name="air", prob=254, param2=0},
		{name="air", prob=254, param2=0},
		{name="air", prob=254, param2=0},
		{name="air", prob=254, param2=0},
		{name="air", prob=254, param2=0},
		{name="air", prob=254, param2=0},
		{name="air", prob=254, param2=0},
		{name="air", prob=254, param2=0},
		{name="air", prob=254, param2=0},
		{name="air", prob=254, param2=0},
		{name="air", prob=254, param2=0},
		{name="vlf_core:stonebrick", prob=254, param2=0},
		{name="vlf_core:stonebrick", prob=254, param2=0},
		{name="air", prob=254, param2=0},
		{name="air", prob=254, param2=0},
		{name="air", prob=254, param2=0},
		{name="air", prob=254, param2=0},
		{name="air", prob=254, param2=0},
		{name="air", prob=254, param2=0},
		{name="air", prob=254, param2=0},
		{name="air", prob=254, param2=0},
		{name="air", prob=254, param2=0},
		{name="air", prob=254, param2=0},
		{name="air", prob=254, param2=0},
		{name="vlf_core:stonebrick", prob=254, param2=0},
		{name="vlf_core:stonebrick", prob=254, param2=0},
		{name="air", prob=254, param2=0},
		{name="air", prob=254, param2=0},
		{name="air", prob=254, param2=0},
		{name="air", prob=254, param2=0},
		{name="air", prob=254, param2=0},
		{name="air", prob=254, param2=0},
		{name="air", prob=254, param2=0},
		{name="air", prob=254, param2=0},
		{name="air", prob=254, param2=0},
		{name="air", prob=254, param2=0},
		{name="air", prob=254, param2=0},
		{name="vlf_core:stonebrick", prob=254, param2=0},
		{name="vlf_core:stonebrick", prob=254, param2=0},
		{name="air", prob=254, param2=0},
		{name="air", prob=254, param2=0},
		{name="air", prob=254, param2=0},
		{name="air", prob=254, param2=0},
		{name="air", prob=254, param2=0},
		{name="air", prob=254, param2=0},
		{name="air", prob=254, param2=0},
		{name="air", prob=254, param2=0},
		{name="air", prob=254, param2=0},
		{name="air", prob=254, param2=0},
		{name="air", prob=254, param2=0},
		{name="vlf_core:stonebrick", prob=254, param2=0},
		{name="vlf_core:stonebrick", prob=254, param2=0},
		{name="air", prob=254, param2=0},
		{name="air", prob=254, param2=0},
		{name="air", prob=254, param2=0},
		{name="air", prob=254, param2=0},
		{name="air", prob=254, param2=0},
		{name="air", prob=254, param2=0},
		{name="air", prob=254, param2=0},
		{name="air", prob=254, param2=0},
		{name="air", prob=254, param2=0},
		{name="air", prob=254, param2=0},
		{name="air", prob=254, param2=0},
		{name="vlf_core:stonebrick", prob=254, param2=0},
		{name="vlf_core:stonebrick", prob=254, param2=0},
		{name="vlf_core:stonebrick", prob=254, param2=0},
		{name="vlf_core:stonebrick", prob=254, param2=0},
		{name="vlf_core:stonebrick", prob=254, param2=0},
		{name="vlf_core:stonebrick", prob=254, param2=0},
		{name="vlf_core:stonebrick", prob=254, param2=0},
		{name="vlf_core:stonebrick", prob=254, param2=0},
		{name="vlf_core:stonebrick", prob=254, param2=0},
		{name="vlf_core:stonebrick", prob=254, param2=0},
		{name="vlf_core:stonebrick", prob=254, param2=0},
		{name="vlf_core:stonebrick", prob=254, param2=0},
		{name="vlf_core:stonebrick", prob=254, param2=0},
		{name="vlf_core:stonebrick", prob=254, param2=0},
		{name="vlf_core:stonebrick", prob=254, param2=0},
		{name="vlf_core:stonebrick", prob=254, param2=0},
		{name="vlf_core:stonebrick", prob=254, param2=0},
		{name="vlf_core:stonebrick", prob=254, param2=0},
		{name="vlf_core:stonebrick", prob=254, param2=0},
		{name="vlf_core:stonebrick", prob=254, param2=0},
		{name="vlf_core:stonebrick", prob=254, param2=0},
		{name="vlf_core:stonebrick", prob=254, param2=0},
		{name="vlf_core:stonebrick", prob=254, param2=0},
		{name="vlf_core:stonebrick", prob=254, param2=0},
		{name="vlf_core:stonebrick", prob=254, param2=0},
		{name="vlf_core:stonebrick", prob=254, param2=0},
		{name="vlf_core:stonebrick", prob=254, param2=0},
		{name="vlf_core:stonebrick", prob=254, param2=0},
		{name="vlf_core:stonebrick", prob=254, param2=0},
		{name="air", prob=254, param2=0},
		{name="air", prob=254, param2=0},
		{name="air", prob=254, param2=0},
		{name="air", prob=254, param2=0},
		{name="air", prob=254, param2=0},
		{name="air", prob=254, param2=0},
		{name="air", prob=254, param2=0},
		{name="air", prob=254, param2=0},
		{name="air", prob=254, param2=0},
		{name="vlf_core:stonebrick", prob=254, param2=0},
		{name="vlf_core:stonebrick", prob=254, param2=0},
		{name="xpanes:bar_flat", prob=254, param2=3},
		{name="air", prob=254, param2=0},
		{name="air", prob=254, param2=0},
		{name="air", prob=254, param2=0},
		{name="air", prob=254, param2=0},
		{name="air", prob=254, param2=0},
		{name="air", prob=254, param2=0},
		{name="air", prob=254, param2=0},
		{name="air", prob=254, param2=0},
		{name="air", prob=254, param2=0},
		{name="air", prob=254, param2=0},
		{name="air", prob=254, param2=0},
		{name="xpanes:bar_flat", prob=254, param2=3},
		{name="xpanes:bar_flat", prob=254, param2=3},
		{name="air", prob=254, param2=0},
		{name="air", prob=254, param2=0},
		{name="air", prob=254, param2=0},
		{name="air", prob=254, param2=0},
		{name="air", prob=254, param2=0},
		{name="air", prob=254, param2=0},
		{name="air", prob=254, param2=0},
		{name="air", prob=254, param2=0},
		{name="air", prob=254, param2=0},
		{name="air", prob=254, param2=0},
		{name="air", prob=254, param2=0},
		{name="xpanes:bar_flat", prob=254, param2=3},
		{name="vlf_core:stonebrick", prob=254, param2=0},
		{name="air", prob=254, param2=0},
		{name="air", prob=254, param2=0},
		{name="air", prob=254, param2=0},
		{name="air", prob=254, param2=0},
		{name="air", prob=254, param2=0},
		{name="air", prob=254, param2=0},
		{name="air", prob=254, param2=0},
		{name="air", prob=254, param2=0},
		{name="air", prob=254, param2=0},
		{name="air", prob=254, param2=0},
		{name="air", prob=254, param2=0},
		{name="vlf_core:stonebrick", prob=254, param2=0},
		{name="vlf_core:stonebrick", prob=254, param2=0},
		{name="air", prob=254, param2=0},
		{name="air", prob=254, param2=0},
		{name="air", prob=254, param2=0},
		{name="air", prob=254, param2=0},
		{name="air", prob=254, param2=0},
		{name="air", prob=254, param2=0},
		{name="air", prob=254, param2=0},
		{name="air", prob=254, param2=0},
		{name="air", prob=254, param2=0},
		{name="air", prob=254, param2=0},
		{name="air", prob=254, param2=0},
		{name="vlf_core:stonebrick", prob=254, param2=0},
		{name="vlf_core:stonebrick", prob=254, param2=0},
		{name="air", prob=254, param2=0},
		{name="air", prob=254, param2=0},
		{name="air", prob=254, param2=0},
		{name="air", prob=254, param2=0},
		{name="air", prob=254, param2=0},
		{name="air", prob=254, param2=0},
		{name="air", prob=254, param2=0},
		{name="air", prob=254, param2=0},
		{name="air", prob=254, param2=0},
		{name="air", prob=254, param2=0},
		{name="air", prob=254, param2=0},
		{name="vlf_core:stonebrick", prob=254, param2=0},
		{name="vlf_core:stonebrick", prob=254, param2=0},
		{name="vlf_core:stonebrick", prob=254, param2=0},
		{name="vlf_core:stonebrick", prob=254, param2=0},
		{name="vlf_core:stonebrick", prob=254, param2=0},
		{name="vlf_core:stonebrick", prob=254, param2=0},
		{name="vlf_core:stonebrick", prob=254, param2=0},
		{name="vlf_core:stonebrick", prob=254, param2=0},
		{name="vlf_core:stonebrick", prob=254, param2=0},
		{name="vlf_core:stonebrick", prob=254, param2=0},
		{name="vlf_core:stonebrick", prob=254, param2=0},
		{name="vlf_core:stonebrick", prob=254, param2=0},
		{name="vlf_core:stonebrick", prob=254, param2=0},
		{name="vlf_core:stonebrick", prob=254, param2=0},
		{name="vlf_core:stonebrick", prob=254, param2=0},
		{name="vlf_core:stonebrick", prob=254, param2=0},
		{name="vlf_core:stonebrick", prob=254, param2=0},
		{name="vlf_core:stonebrick", prob=254, param2=0},
		{name="vlf_core:stonebrick", prob=254, param2=0},
		{name="vlf_core:stonebrick", prob=254, param2=0},
		{name="vlf_core:stonebrick", prob=254, param2=0},
		{name="vlf_core:stonebrick", prob=254, param2=0},
		{name="vlf_core:stonebrick", prob=254, param2=0},
		{name="vlf_core:stonebrick", prob=254, param2=0},
		{name="vlf_core:stonebrick", prob=254, param2=0},
		{name="vlf_core:stonebrick", prob=254, param2=0},
		{name="vlf_core:stonebrick", prob=254, param2=0},
		{name="vlf_core:stonebrick", prob=254, param2=0},
		{name="vlf_core:lava_source", prob=254, param2=3},
		{name="vlf_core:stonebrick", prob=254, param2=0},
		{name="air", prob=254, param2=0},
		{name="air", prob=254, param2=0},
		{name="air", prob=254, param2=0},
		{name="air", prob=254, param2=0},
		{name="air", prob=254, param2=0},
		{name="air", prob=254, param2=0},
		{name="air", prob=254, param2=0},
		{name="vlf_core:stonebrick", prob=254, param2=0},
		{name="vlf_core:lava_source", prob=254, param2=3},
		{name="vlf_core:stonebrick", prob=254, param2=0},
		{name="vlf_core:stonebrick", prob=254, param2=0},
		{name="air", prob=254, param2=0},
		{name="air", prob=254, param2=0},
		{name="air", prob=254, param2=0},
		{name="air", prob=254, param2=0},
		{name="air", prob=254, param2=0},
		{name="air", prob=254, param2=0},
		{name="air", prob=254, param2=0},
		{name="air", prob=254, param2=0},
		{name="air", prob=254, param2=0},
		{name="air", prob=254, param2=0},
		{name="air", prob=254, param2=0},
		{name="vlf_core:stonebrick", prob=254, param2=0},
		{name="vlf_core:stonebrick", prob=254, param2=0},
		{name="air", prob=254, param2=0},
		{name="air", prob=254, param2=0},
		{name="air", prob=254, param2=0},
		{name="air", prob=254, param2=0},
		{name="air", prob=254, param2=0},
		{name="air", prob=254, param2=0},
		{name="air", prob=254, param2=0},
		{name="air", prob=254, param2=0},
		{name="air", prob=254, param2=0},
		{name="air", prob=254, param2=0},
		{name="air", prob=254, param2=0},
		{name="vlf_core:stonebrick", prob=254, param2=0},
		{name="vlf_core:stonebrick", prob=254, param2=0},
		{name="air", prob=254, param2=0},
		{name="air", prob=254, param2=0},
		{name="air", prob=254, param2=0},
		{name="air", prob=254, param2=0},
		{name="air", prob=254, param2=0},
		{name="air", prob=254, param2=0},
		{name="air", prob=254, param2=0},
		{name="air", prob=254, param2=0},
		{name="air", prob=254, param2=0},
		{name="air", prob=254, param2=0},
		{name="air", prob=254, param2=0},
		{name="vlf_core:stonebrick", prob=254, param2=0},
		{name="vlf_core:stonebrick", prob=254, param2=0},
		{name="air", prob=254, param2=0},
		{name="air", prob=254, param2=0},
		{name="air", prob=254, param2=0},
		{name="air", prob=254, param2=0},
		{name="air", prob=254, param2=0},
		{name="air", prob=254, param2=0},
		{name="air", prob=254, param2=0},
		{name="air", prob=254, param2=0},
		{name="air", prob=254, param2=0},
		{name="air", prob=254, param2=0},
		{name="air", prob=254, param2=0},
		{name="vlf_core:stonebrick", prob=254, param2=0},
		{name="vlf_core:stonebrick", prob=254, param2=0},
		{name="air", prob=254, param2=0},
		{name="air", prob=254, param2=0},
		{name="air", prob=254, param2=0},
		{name="air", prob=254, param2=0},
		{name="air", prob=254, param2=0},
		{name="air", prob=254, param2=0},
		{name="air", prob=254, param2=0},
		{name="air", prob=254, param2=0},
		{name="air", prob=254, param2=0},
		{name="air", prob=254, param2=0},
		{name="air", prob=254, param2=0},
		{name="vlf_core:stonebrick", prob=254, param2=0},
		{name="vlf_core:stonebrick", prob=254, param2=0},
		{name="vlf_core:stonebrick", prob=254, param2=0},
		{name="vlf_core:stonebrick", prob=254, param2=0},
		{name="vlf_core:stonebrick", prob=254, param2=0},
		{name="vlf_core:stonebrick", prob=254, param2=0},
		{name="vlf_core:stonebrick", prob=254, param2=0},
		{name="vlf_core:stonebrick", prob=254, param2=0},
		{name="vlf_core:stonebrick", prob=254, param2=0},
		{name="vlf_core:stonebrick", prob=254, param2=0},
		{name="vlf_core:stonebrick", prob=254, param2=0},
		{name="vlf_core:stonebrick", prob=254, param2=0},
		{name="vlf_core:stonebrick", prob=254, param2=0},
		{name="vlf_core:stonebrick", prob=254, param2=0},
		{name="vlf_core:stonebrick", prob=254, param2=0},
		{name="vlf_core:stonebrick", prob=254, param2=0},
		{name="vlf_core:stonebrick", prob=254, param2=0},
		{name="vlf_core:stonebrick", prob=254, param2=0},
		{name="vlf_core:stonebrick", prob=254, param2=0},
		{name="vlf_core:stonebrick", prob=254, param2=0},
		{name="vlf_core:stonebrick", prob=254, param2=0},
		{name="vlf_core:stonebrick", prob=254, param2=0},
		{name="vlf_core:stonebrick", prob=254, param2=0},
		{name="vlf_core:stonebrick", prob=254, param2=0},
		{name="vlf_core:stonebrick", prob=254, param2=0},
		{name="vlf_core:stonebrick", prob=254, param2=0},
		{name="vlf_core:stonebrick", prob=254, param2=0},
		{name="vlf_core:stonebrick", prob=254, param2=0},
		{name="vlf_core:stonebrick", prob=254, param2=0},
		{name="vlf_core:stonebrick", prob=254, param2=0},
		{name="vlf_core:stonebrick", prob=254, param2=0},
		{name="vlf_core:stonebrick", prob=254, param2=0},
		{name="vlf_core:stonebrick", prob=254, param2=0},
		{name="air", prob=254, param2=0},
		{name="vlf_core:stonebrick", prob=254, param2=0},
		{name="vlf_core:stonebrick", prob=254, param2=0},
		{name="vlf_core:stonebrick", prob=254, param2=0},
		{name="vlf_core:stonebrick", prob=254, param2=0},
		{name="vlf_core:stonebrick", prob=254, param2=0},
		{name="vlf_core:stonebrick", prob=254, param2=0},
		{name="vlf_core:stonebrick", prob=254, param2=0},
		{name="vlf_core:stonebrick", prob=254, param2=0},
		{name="xpanes:bar_flat", prob=254, param2=0},
		{name="vlf_core:stonebrick", prob=254, param2=0},
		{name="xpanes:bar_flat", prob=254, param2=0},
		{name="vlf_core:stonebrick", prob=254, param2=0},
		{name="air", prob=254, param2=0},
		{name="vlf_core:stonebrick", prob=254, param2=0},
		{name="xpanes:bar_flat", prob=254, param2=0},
		{name="vlf_core:stonebrick", prob=254, param2=0},
		{name="xpanes:bar_flat", prob=254, param2=0},
		{name="vlf_core:stonebrick", prob=254, param2=0},
		{name="vlf_core:stonebrick", prob=254, param2=0},
		{name="vlf_core:stonebrick", prob=254, param2=0},
		{name="vlf_core:stonebrick", prob=254, param2=0},
		{name="xpanes:bar_flat", prob=254, param2=0},
		{name="vlf_core:stonebrick", prob=254, param2=0},
		{name="xpanes:bar_flat", prob=254, param2=0},
		{name="vlf_core:stonebrick", prob=254, param2=0},
		{name="vlf_core:stonebrick", prob=254, param2=0},
		{name="vlf_core:stonebrick", prob=254, param2=0},
		{name="xpanes:bar_flat", prob=254, param2=0},
		{name="vlf_core:stonebrick", prob=254, param2=0},
		{name="xpanes:bar_flat", prob=254, param2=0},
		{name="vlf_core:stonebrick", prob=254, param2=0},
		{name="vlf_core:stonebrick", prob=254, param2=0},
		{name="vlf_core:stonebrick", prob=254, param2=0},
		{name="vlf_core:stonebrick", prob=254, param2=0},
		{name="vlf_core:stonebrick", prob=254, param2=0},
		{name="vlf_core:stonebrick", prob=254, param2=0},
		{name="vlf_core:stonebrick", prob=254, param2=0},
		{name="vlf_core:stonebrick", prob=254, param2=0},
		{name="vlf_core:stonebrick", prob=254, param2=0},
		{name="vlf_core:stonebrick", prob=254, param2=0},
		{name="vlf_core:stonebrick", prob=254, param2=0},
		{name="vlf_core:stonebrick", prob=254, param2=0},
		{name="vlf_core:stonebrick", prob=254, param2=0},
		{name="vlf_core:stonebrick", prob=254, param2=0},
		{name="vlf_core:stonebrick", prob=254, param2=0},
		{name="vlf_core:stonebrick", prob=254, param2=0},
		{name="vlf_core:stonebrick", prob=254, param2=0},
		{name="vlf_core:stonebrick", prob=254, param2=0},
		{name="vlf_core:stonebrick", prob=254, param2=0},
		{name="vlf_core:stonebrick", prob=254, param2=0},
		{name="vlf_core:stonebrick", prob=254, param2=0},
		{name="vlf_core:stonebrick", prob=254, param2=0},
		{name="vlf_core:stonebrick", prob=254, param2=0},
		{name="vlf_core:stonebrick", prob=254, param2=0},
		{name="vlf_core:stonebrick", prob=254, param2=0},
		{name="vlf_core:stonebrick", prob=254, param2=0},
		{name="vlf_core:stonebrick", prob=254, param2=0},
		{name="vlf_core:stonebrick", prob=254, param2=0},
		{name="vlf_core:stonebrick", prob=254, param2=0},
		{name="vlf_core:stonebrick", prob=254, param2=0},
		{name="vlf_core:stonebrick", prob=254, param2=0},
		{name="vlf_core:stonebrick", prob=254, param2=0},
		{name="vlf_core:stonebrick", prob=254, param2=0},
		{name="vlf_core:stonebrick", prob=254, param2=0},
		{name="vlf_core:stonebrick", prob=254, param2=0},
		{name="vlf_core:stonebrick", prob=254, param2=0},
		{name="vlf_core:stonebrick", prob=254, param2=0},
		{name="vlf_core:stonebrick", prob=254, param2=0},
		{name="vlf_core:stonebrick", prob=254, param2=0},
		{name="vlf_core:stonebrick", prob=254, param2=0},
		{name="vlf_core:stonebrick", prob=254, param2=0},
		{name="vlf_core:stonebrick", prob=254, param2=0},
		{name="vlf_core:stonebrick", prob=254, param2=0},
		{name="vlf_core:stonebrick", prob=254, param2=0},
		{name="vlf_core:stonebrick", prob=254, param2=0},
		{name="vlf_core:stonebrick", prob=254, param2=0},
		{name="vlf_core:stonebrick", prob=254, param2=0},
		{name="vlf_core:stonebrick", prob=254, param2=0},
		{name="vlf_core:stonebrick", prob=254, param2=0},
		{name="vlf_core:stonebrick", prob=254, param2=0},
		{name="vlf_core:stonebrick", prob=254, param2=0},
		{name="vlf_core:stonebrick", prob=254, param2=0},
		{name="vlf_core:stonebrick", prob=254, param2=0},
		{name="vlf_core:stonebrick", prob=254, param2=0},
	},
}
