schematic = {
	size = {x=6, y=2, z=10},
	yslice_prob = {
		{ypos=0, prob=254},
		{ypos=1, prob=254},
	},
	data = {
		{name="air", prob=0, param2=0},
		{name="air", prob=0, param2=0},
		{name="air", prob=0, param2=0},
		{name="air", prob=0, param2=0},
		{name="air", prob=0, param2=0},
		{name="air", prob=0, param2=0},
		{name="vlf_stairs:stair_purpur_block_outer", prob=254, param2=20},
		{name="vlf_stairs:stair_purpur_block", prob=254, param2=20},
		{name="vlf_stairs:stair_purpur_block", prob=254, param2=20},
		{name="vlf_stairs:stair_purpur_block", prob=254, param2=20},
		{name="vlf_stairs:stair_purpur_block", prob=254, param2=20},
		{name="vlf_stairs:stair_purpur_block_outer", prob=254, param2=21},
		{name="air", prob=0, param2=0},
		{name="vlf_end:purpur_block", prob=254, param2=0},
		{name="vlf_end:purpur_block", prob=254, param2=0},
		{name="vlf_end:purpur_block", prob=254, param2=0},
		{name="vlf_end:purpur_block", prob=254, param2=0},
		{name="air", prob=0, param2=0},
		{name="vlf_stairs:stair_purpur_block", prob=254, param2=23},
		{name="vlf_chests:chest_small", prob=254, param2=2},
		{name="vlf_chests:ender_chest_small", prob=254, param2=2},
		{name="vlf_chests:chest_small", prob=254, param2=2},
		{name="vlf_brewing:stand_000", prob=254, param2=2},
		{name="vlf_stairs:stair_purpur_block", prob=254, param2=21},
		{name="air", prob=0, param2=0},
		{name="vlf_end:purpur_block", prob=254, param2=0},
		{name="vlf_end:purpur_block", prob=254, param2=0},
		{name="vlf_end:purpur_block", prob=254, param2=0},
		{name="vlf_end:purpur_block", prob=254, param2=0},
		{name="air", prob=0, param2=0},
		{name="vlf_stairs:stair_purpur_block", prob=254, param2=23},
		{name="air", prob=0, param2=0},
		{name="air", prob=0, param2=0},
		{name="air", prob=0, param2=0},
		{name="air", prob=0, param2=0},
		{name="vlf_stairs:stair_purpur_block", prob=254, param2=21},
		{name="air", prob=0, param2=0},
		{name="vlf_end:purpur_block", prob=254, param2=0},
		{name="vlf_end:purpur_block", prob=254, param2=0},
		{name="vlf_end:purpur_block", prob=254, param2=0},
		{name="vlf_end:purpur_block", prob=254, param2=0},
		{name="air", prob=0, param2=0},
		{name="vlf_stairs:stair_purpur_block", prob=254, param2=23},
		{name="air", prob=0, param2=0},
		{name="air", prob=0, param2=0},
		{name="air", prob=0, param2=0},
		{name="air", prob=0, param2=0},
		{name="vlf_stairs:stair_purpur_block", prob=254, param2=21},
		{name="air", prob=0, param2=0},
		{name="vlf_end:purpur_block", prob=254, param2=0},
		{name="vlf_end:purpur_block", prob=254, param2=0},
		{name="vlf_end:purpur_block", prob=254, param2=0},
		{name="vlf_end:purpur_block", prob=254, param2=0},
		{name="air", prob=0, param2=0},
		{name="vlf_stairs:stair_purpur_block", prob=254, param2=23},
		{name="air", prob=0, param2=0},
		{name="air", prob=0, param2=0},
		{name="air", prob=0, param2=0},
		{name="air", prob=0, param2=0},
		{name="vlf_stairs:stair_purpur_block", prob=254, param2=21},
		{name="air", prob=0, param2=0},
		{name="vlf_end:purpur_block", prob=254, param2=0},
		{name="vlf_end:purpur_block", prob=254, param2=0},
		{name="vlf_end:purpur_block", prob=254, param2=0},
		{name="vlf_end:purpur_block", prob=254, param2=0},
		{name="air", prob=0, param2=0},
		{name="vlf_stairs:stair_purpur_block", prob=254, param2=23},
		{name="air", prob=0, param2=0},
		{name="air", prob=0, param2=0},
		{name="air", prob=0, param2=0},
		{name="air", prob=0, param2=0},
		{name="vlf_stairs:stair_purpur_block", prob=254, param2=21},
		{name="air", prob=0, param2=0},
		{name="vlf_end:purpur_block", prob=254, param2=0},
		{name="vlf_end:purpur_block", prob=254, param2=0},
		{name="vlf_end:purpur_block", prob=254, param2=0},
		{name="vlf_end:purpur_block", prob=254, param2=0},
		{name="air", prob=0, param2=0},
		{name="vlf_stairs:stair_purpur_block", prob=254, param2=23},
		{name="air", prob=0, param2=0},
		{name="air", prob=0, param2=0},
		{name="air", prob=0, param2=0},
		{name="air", prob=0, param2=0},
		{name="vlf_stairs:stair_purpur_block", prob=254, param2=21},
		{name="air", prob=0, param2=0},
		{name="vlf_end:purpur_block", prob=254, param2=0},
		{name="vlf_end:purpur_block", prob=254, param2=0},
		{name="vlf_end:purpur_block", prob=254, param2=0},
		{name="vlf_end:purpur_block", prob=254, param2=0},
		{name="air", prob=0, param2=0},
		{name="vlf_stairs:stair_purpur_block", prob=254, param2=23},
		{name="air", prob=0, param2=0},
		{name="air", prob=0, param2=0},
		{name="air", prob=0, param2=0},
		{name="air", prob=0, param2=0},
		{name="vlf_stairs:stair_purpur_block", prob=254, param2=21},
		{name="air", prob=0, param2=0},
		{name="air", prob=0, param2=0},
		{name="vlf_end:purpur_block", prob=254, param2=0},
		{name="vlf_end:purpur_block", prob=254, param2=0},
		{name="air", prob=0, param2=0},
		{name="air", prob=0, param2=0},
		{name="vlf_stairs:stair_purpur_block", prob=254, param2=23},
		{name="vlf_end:purpur_block", prob=254, param2=0},
		{name="air", prob=0, param2=0},
		{name="air", prob=0, param2=0},
		{name="vlf_end:purpur_block", prob=254, param2=0},
		{name="vlf_stairs:stair_purpur_block", prob=254, param2=21},
		{name="air", prob=0, param2=0},
		{name="air", prob=0, param2=0},
		{name="air", prob=0, param2=0},
		{name="air", prob=0, param2=0},
		{name="air", prob=0, param2=0},
		{name="air", prob=0, param2=0},
		{name="air", prob=0, param2=0},
		{name="vlf_stairs:stair_purpur_block", prob=254, param2=22},
		{name="vlf_stairs:stair_purpur_block", prob=254, param2=22},
		{name="vlf_stairs:stair_purpur_block", prob=254, param2=22},
		{name="vlf_stairs:stair_purpur_block", prob=254, param2=22},
		{name="air", prob=0, param2=0},
	},
}
