schematic = {
	size = {x=9, y=6, z=7},
	yslice_prob = {
		{ypos=0, prob=254},
		{ypos=1, prob=254},
		{ypos=2, prob=254},
		{ypos=3, prob=254},
		{ypos=4, prob=254},
		{ypos=5, prob=254},
	},
	data = {
		{name="air", prob=0, param2=0},
		{name="air", prob=0, param2=0},
		{name="air", prob=0, param2=0},
		{name="vlf_core:snowblock", prob=254, param2=0},
		{name="vlf_core:snowblock", prob=254, param2=0},
		{name="vlf_core:snowblock", prob=254, param2=0},
		{name="air", prob=0, param2=0},
		{name="air", prob=0, param2=0},
		{name="air", prob=0, param2=0},
		{name="air", prob=0, param2=0},
		{name="air", prob=0, param2=0},
		{name="air", prob=0, param2=0},
		{name="vlf_core:snowblock", prob=254, param2=0},
		{name="vlf_core:snowblock", prob=254, param2=0},
		{name="vlf_core:snowblock", prob=254, param2=0},
		{name="air", prob=0, param2=0},
		{name="air", prob=0, param2=0},
		{name="air", prob=0, param2=0},
		{name="air", prob=254, param2=0},
		{name="air", prob=254, param2=0},
		{name="air", prob=254, param2=0},
		{name="vlf_core:snowblock", prob=254, param2=0},
		{name="vlf_core:snowblock", prob=254, param2=0},
		{name="vlf_core:snowblock", prob=254, param2=0},
		{name="air", prob=254, param2=0},
		{name="air", prob=254, param2=0},
		{name="air", prob=254, param2=0},
		{name="air", prob=254, param2=0},
		{name="air", prob=254, param2=0},
		{name="air", prob=254, param2=0},
		{name="vlf_core:snowblock", prob=254, param2=0},
		{name="vlf_core:snowblock", prob=254, param2=0},
		{name="vlf_core:snowblock", prob=254, param2=0},
		{name="air", prob=254, param2=0},
		{name="air", prob=254, param2=0},
		{name="air", prob=254, param2=0},
		{name="air", prob=254, param2=0},
		{name="air", prob=254, param2=0},
		{name="air", prob=254, param2=0},
		{name="air", prob=254, param2=0},
		{name="air", prob=254, param2=0},
		{name="air", prob=254, param2=0},
		{name="air", prob=254, param2=0},
		{name="air", prob=254, param2=0},
		{name="air", prob=254, param2=0},
		{name="air", prob=254, param2=0},
		{name="air", prob=254, param2=0},
		{name="air", prob=254, param2=0},
		{name="air", prob=254, param2=0},
		{name="air", prob=254, param2=0},
		{name="air", prob=254, param2=0},
		{name="air", prob=254, param2=0},
		{name="air", prob=254, param2=0},
		{name="air", prob=254, param2=0},
		{name="air", prob=0, param2=0},
		{name="air", prob=0, param2=0},
		{name="vlf_core:snowblock", prob=254, param2=0},
		{name="vlf_core:snowblock", prob=254, param2=0},
		{name="vlf_core:snowblock", prob=254, param2=0},
		{name="vlf_core:snowblock", prob=254, param2=0},
		{name="vlf_core:snowblock", prob=254, param2=0},
		{name="vlf_core:snowblock", prob=254, param2=0},
		{name="air", prob=0, param2=0},
		{name="air", prob=0, param2=0},
		{name="air", prob=0, param2=0},
		{name="vlf_core:snowblock", prob=254, param2=0},
		{name="vlf_furnaces:furnace", prob=254, param2=2},
		{name="mesecons_torch:mesecon_torch_on", prob=254, param2=1},
		{name="vlf_crafting_table:crafting_table", prob=254, param2=2},
		{name="vlf_core:snowblock", prob=254, param2=0},
		{name="vlf_core:snowblock", prob=254, param2=0},
		{name="air", prob=0, param2=0},
		{name="air", prob=254, param2=0},
		{name="air", prob=254, param2=0},
		{name="vlf_core:snowblock", prob=254, param2=0},
		{name="air", prob=254, param2=0},
		{name="air", prob=254, param2=0},
		{name="air", prob=254, param2=0},
		{name="vlf_core:snowblock", prob=254, param2=0},
		{name="vlf_core:snowblock", prob=254, param2=0},
		{name="air", prob=254, param2=0},
		{name="air", prob=254, param2=0},
		{name="air", prob=254, param2=0},
		{name="vlf_core:snowblock", prob=254, param2=0},
		{name="air", prob=254, param2=0},
		{name="air", prob=254, param2=0},
		{name="air", prob=254, param2=0},
		{name="vlf_core:snowblock", prob=254, param2=0},
		{name="air", prob=254, param2=0},
		{name="air", prob=254, param2=0},
		{name="air", prob=254, param2=0},
		{name="air", prob=254, param2=0},
		{name="air", prob=254, param2=0},
		{name="vlf_core:snowblock", prob=254, param2=0},
		{name="vlf_core:snowblock", prob=254, param2=0},
		{name="vlf_core:snowblock", prob=254, param2=0},
		{name="air", prob=254, param2=0},
		{name="air", prob=254, param2=0},
		{name="air", prob=254, param2=0},
		{name="air", prob=254, param2=0},
		{name="air", prob=254, param2=0},
		{name="air", prob=254, param2=0},
		{name="air", prob=254, param2=0},
		{name="air", prob=254, param2=0},
		{name="air", prob=254, param2=0},
		{name="air", prob=254, param2=0},
		{name="air", prob=254, param2=0},
		{name="air", prob=254, param2=0},
		{name="vlf_core:snowblock", prob=254, param2=0},
		{name="vlf_core:snowblock", prob=254, param2=0},
		{name="vlf_core:snowblock", prob=254, param2=0},
		{name="vlf_core:snowblock", prob=254, param2=0},
		{name="vlf_core:snowblock", prob=254, param2=0},
		{name="vlf_core:snowblock", prob=254, param2=0},
		{name="vlf_core:snowblock", prob=254, param2=0},
		{name="vlf_core:snowblock", prob=254, param2=0},
		{name="vlf_core:snowblock", prob=254, param2=0},
		{name="vlf_core:snowblock", prob=254, param2=0},
		{name="vlf_core:snowblock", prob=254, param2=0},
		{name="vlf_core:snowblock", prob=254, param2=0},
		{name="vlf_wool:white_carpet", prob=254, param2=0},
		{name="vlf_wool:white_carpet", prob=254, param2=0},
		{name="vlf_wool:white_carpet", prob=254, param2=0},
		{name="vlf_wool:white_carpet", prob=254, param2=0},
		{name="vlf_wool:white_carpet", prob=254, param2=0},
		{name="vlf_core:snowblock", prob=254, param2=0},
		{name="vlf_core:snowblock", prob=254, param2=0},
		{name="vlf_core:snowblock", prob=254, param2=0},
		{name="vlf_core:snowblock", prob=254, param2=0},
		{name="air", prob=254, param2=0},
		{name="air", prob=254, param2=0},
		{name="air", prob=254, param2=0},
		{name="air", prob=254, param2=0},
		{name="air", prob=254, param2=0},
		{name="vlf_core:snowblock", prob=254, param2=0},
		{name="vlf_core:snowblock", prob=254, param2=0},
		{name="vlf_core:snowblock", prob=254, param2=0},
		{name="vlf_core:snowblock", prob=254, param2=0},
		{name="air", prob=254, param2=0},
		{name="air", prob=254, param2=0},
		{name="air", prob=254, param2=0},
		{name="air", prob=254, param2=0},
		{name="vlf_core:snowblock", prob=254, param2=0},
		{name="air", prob=254, param2=0},
		{name="air", prob=254, param2=0},
		{name="air", prob=254, param2=0},
		{name="vlf_core:snowblock", prob=254, param2=0},
		{name="air", prob=254, param2=0},
		{name="air", prob=254, param2=0},
		{name="air", prob=254, param2=0},
		{name="vlf_core:snowblock", prob=254, param2=0},
		{name="air", prob=254, param2=0},
		{name="air", prob=254, param2=0},
		{name="air", prob=254, param2=0},
		{name="air", prob=254, param2=0},
		{name="air", prob=254, param2=0},
		{name="vlf_core:snowblock", prob=254, param2=0},
		{name="vlf_core:snowblock", prob=254, param2=0},
		{name="vlf_core:snowblock", prob=254, param2=0},
		{name="air", prob=254, param2=0},
		{name="air", prob=254, param2=0},
		{name="air", prob=254, param2=0},
		{name="vlf_core:snowblock", prob=254, param2=0},
		{name="vlf_core:snowblock", prob=254, param2=0},
		{name="vlf_core:snowblock", prob=254, param2=0},
		{name="vlf_core:snowblock", prob=254, param2=0},
		{name="vlf_core:snowblock", prob=254, param2=0},
		{name="vlf_core:snowblock", prob=254, param2=0},
		{name="vlf_core:snowblock", prob=254, param2=0},
		{name="vlf_core:snowblock", prob=254, param2=0},
		{name="vlf_core:snowblock", prob=254, param2=0},
		{name="vlf_core:snowblock", prob=254, param2=0},
		{name="vlf_core:snowblock", prob=254, param2=0},
		{name="vlf_core:snowblock", prob=254, param2=0},
		{name="vlf_wool:white_carpet", prob=254, param2=0},
		{name="vlf_wool:white_carpet", prob=254, param2=0},
		{name="vlf_wool:white_carpet", prob=254, param2=0},
		{name="vlf_wool:white_carpet", prob=254, param2=0},
		{name="vlf_wool:white_carpet", prob=254, param2=0},
		{name="vlf_core:snowblock", prob=254, param2=0},
		{name="air", prob=254, param2=0},
		{name="air", prob=254, param2=0},
		{name="air", prob=254, param2=0},
		{name="air", prob=254, param2=0},
		{name="air", prob=254, param2=0},
		{name="air", prob=254, param2=0},
		{name="air", prob=254, param2=0},
		{name="air", prob=254, param2=0},
		{name="vlf_core:snowblock", prob=254, param2=0},
		{name="air", prob=254, param2=0},
		{name="air", prob=254, param2=0},
		{name="air", prob=254, param2=0},
		{name="air", prob=254, param2=0},
		{name="air", prob=254, param2=0},
		{name="air", prob=254, param2=0},
		{name="air", prob=254, param2=0},
		{name="vlf_core:snowblock", prob=254, param2=0},
		{name="air", prob=254, param2=0},
		{name="vlf_core:snowblock", prob=254, param2=0},
		{name="vlf_core:snowblock", prob=254, param2=0},
		{name="vlf_core:snowblock", prob=254, param2=0},
		{name="air", prob=254, param2=0},
		{name="air", prob=254, param2=0},
		{name="air", prob=254, param2=0},
		{name="vlf_core:snowblock", prob=254, param2=0},
		{name="air", prob=254, param2=0},
		{name="air", prob=254, param2=0},
		{name="air", prob=254, param2=0},
		{name="air", prob=254, param2=0},
		{name="air", prob=254, param2=0},
		{name="vlf_core:snowblock", prob=254, param2=0},
		{name="vlf_core:snowblock", prob=254, param2=0},
		{name="vlf_core:snowblock", prob=254, param2=0},
		{name="air", prob=254, param2=0},
		{name="air", prob=254, param2=0},
		{name="air", prob=254, param2=0},
		{name="vlf_core:snowblock", prob=254, param2=0},
		{name="vlf_core:snowblock", prob=254, param2=0},
		{name="vlf_core:snowblock", prob=254, param2=0},
		{name="vlf_core:snowblock", prob=254, param2=0},
		{name="vlf_core:snowblock", prob=254, param2=0},
		{name="vlf_core:snowblock", prob=254, param2=0},
		{name="vlf_core:snowblock", prob=254, param2=0},
		{name="vlf_core:snowblock", prob=254, param2=0},
		{name="vlf_core:snowblock", prob=254, param2=0},
		{name="vlf_core:snowblock", prob=254, param2=0},
		{name="vlf_core:snowblock", prob=254, param2=0},
		{name="vlf_core:snowblock", prob=254, param2=0},
		{name="vlf_wool:white_carpet", prob=254, param2=0},
		{name="vlf_wool:white_carpet", prob=254, param2=0},
		{name="vlf_wool:white_carpet", prob=254, param2=0},
		{name="vlf_wool:white_carpet", prob=254, param2=0},
		{name="vlf_wool:white_carpet", prob=254, param2=0},
		{name="vlf_core:snowblock", prob=254, param2=0},
		{name="vlf_core:snowblock", prob=254, param2=0},
		{name="vlf_core:snowblock", prob=254, param2=0},
		{name="vlf_core:snowblock", prob=254, param2=0},
		{name="air", prob=254, param2=0},
		{name="air", prob=254, param2=0},
		{name="air", prob=254, param2=0},
		{name="air", prob=254, param2=0},
		{name="air", prob=254, param2=0},
		{name="vlf_core:snowblock", prob=254, param2=0},
		{name="vlf_core:snowblock", prob=254, param2=0},
		{name="vlf_core:snowblock", prob=254, param2=0},
		{name="vlf_core:snowblock", prob=254, param2=0},
		{name="air", prob=254, param2=0},
		{name="air", prob=254, param2=0},
		{name="air", prob=254, param2=0},
		{name="air", prob=254, param2=0},
		{name="vlf_core:snowblock", prob=254, param2=0},
		{name="air", prob=254, param2=0},
		{name="air", prob=254, param2=0},
		{name="air", prob=254, param2=0},
		{name="vlf_core:snowblock", prob=254, param2=0},
		{name="air", prob=254, param2=0},
		{name="air", prob=254, param2=0},
		{name="air", prob=254, param2=0},
		{name="vlf_core:snowblock", prob=254, param2=0},
		{name="air", prob=254, param2=0},
		{name="air", prob=254, param2=0},
		{name="air", prob=254, param2=0},
		{name="air", prob=254, param2=0},
		{name="air", prob=254, param2=0},
		{name="vlf_core:snowblock", prob=254, param2=0},
		{name="vlf_core:snowblock", prob=254, param2=0},
		{name="vlf_core:snowblock", prob=254, param2=0},
		{name="air", prob=254, param2=0},
		{name="air", prob=254, param2=0},
		{name="air", prob=254, param2=0},
		{name="air", prob=0, param2=0},
		{name="air", prob=0, param2=0},
		{name="vlf_core:snowblock", prob=254, param2=0},
		{name="vlf_core:snowblock", prob=254, param2=0},
		{name="vlf_core:snowblock", prob=254, param2=0},
		{name="vlf_core:snowblock", prob=254, param2=0},
		{name="vlf_core:snowblock", prob=254, param2=0},
		{name="vlf_core:snowblock", prob=254, param2=0},
		{name="air", prob=0, param2=0},
		{name="air", prob=0, param2=0},
		{name="air", prob=0, param2=0},
		{name="vlf_core:snowblock", prob=254, param2=0},
		{name="vlf_books:bookshelf", prob=254, param2=0},
		{name="vlf_beds:bed_red_bottom", prob=254, param2=1},
		{name="vlf_beds:bed_red_top", prob=254, param2=1},
		{name="vlf_core:snowblock", prob=254, param2=0},
		{name="vlf_core:snowblock", prob=254, param2=0},
		{name="air", prob=0, param2=0},
		{name="air", prob=254, param2=0},
		{name="air", prob=254, param2=0},
		{name="vlf_core:snowblock", prob=254, param2=0},
		{name="air", prob=254, param2=0},
		{name="air", prob=254, param2=0},
		{name="air", prob=254, param2=0},
		{name="vlf_core:snowblock", prob=254, param2=0},
		{name="vlf_core:snowblock", prob=254, param2=0},
		{name="air", prob=254, param2=0},
		{name="air", prob=254, param2=0},
		{name="air", prob=254, param2=0},
		{name="vlf_core:snowblock", prob=254, param2=0},
		{name="air", prob=254, param2=0},
		{name="air", prob=254, param2=0},
		{name="air", prob=254, param2=0},
		{name="vlf_core:snowblock", prob=254, param2=0},
		{name="air", prob=254, param2=0},
		{name="air", prob=254, param2=0},
		{name="air", prob=254, param2=0},
		{name="air", prob=254, param2=0},
		{name="air", prob=254, param2=0},
		{name="vlf_core:snowblock", prob=254, param2=0},
		{name="vlf_core:snowblock", prob=254, param2=0},
		{name="vlf_core:snowblock", prob=254, param2=0},
		{name="air", prob=254, param2=0},
		{name="air", prob=254, param2=0},
		{name="air", prob=254, param2=0},
		{name="air", prob=254, param2=0},
		{name="air", prob=254, param2=0},
		{name="air", prob=254, param2=0},
		{name="air", prob=254, param2=0},
		{name="air", prob=254, param2=0},
		{name="air", prob=254, param2=0},
		{name="air", prob=254, param2=0},
		{name="air", prob=254, param2=0},
		{name="air", prob=254, param2=0},
		{name="air", prob=0, param2=0},
		{name="air", prob=0, param2=0},
		{name="air", prob=0, param2=0},
		{name="vlf_core:snowblock", prob=254, param2=0},
		{name="vlf_core:snowblock", prob=254, param2=0},
		{name="vlf_core:snowblock", prob=254, param2=0},
		{name="air", prob=0, param2=0},
		{name="air", prob=0, param2=0},
		{name="air", prob=0, param2=0},
		{name="air", prob=0, param2=0},
		{name="air", prob=0, param2=0},
		{name="air", prob=0, param2=0},
		{name="vlf_core:snowblock", prob=254, param2=0},
		{name="vlf_core:snowblock", prob=254, param2=0},
		{name="vlf_core:snowblock", prob=254, param2=0},
		{name="air", prob=0, param2=0},
		{name="air", prob=0, param2=0},
		{name="air", prob=0, param2=0},
		{name="air", prob=254, param2=0},
		{name="air", prob=254, param2=0},
		{name="air", prob=254, param2=0},
		{name="vlf_core:snowblock", prob=254, param2=0},
		{name="vlf_core:snowblock", prob=254, param2=0},
		{name="vlf_core:snowblock", prob=254, param2=0},
		{name="air", prob=254, param2=0},
		{name="air", prob=254, param2=0},
		{name="air", prob=254, param2=0},
		{name="air", prob=254, param2=0},
		{name="air", prob=254, param2=0},
		{name="air", prob=254, param2=0},
		{name="vlf_core:snowblock", prob=254, param2=0},
		{name="vlf_core:snowblock", prob=254, param2=0},
		{name="vlf_core:snowblock", prob=254, param2=0},
		{name="air", prob=254, param2=0},
		{name="air", prob=254, param2=0},
		{name="air", prob=254, param2=0},
		{name="air", prob=254, param2=0},
		{name="air", prob=254, param2=0},
		{name="air", prob=254, param2=0},
		{name="air", prob=254, param2=0},
		{name="air", prob=254, param2=0},
		{name="air", prob=254, param2=0},
		{name="air", prob=254, param2=0},
		{name="air", prob=254, param2=0},
		{name="air", prob=254, param2=0},
		{name="air", prob=254, param2=0},
		{name="air", prob=254, param2=0},
		{name="air", prob=254, param2=0},
		{name="air", prob=254, param2=0},
		{name="air", prob=254, param2=0},
		{name="air", prob=254, param2=0},
		{name="air", prob=254, param2=0},
		{name="air", prob=254, param2=0},
		{name="air", prob=254, param2=0},
	},
}
