schematic = {
	size = {x=5, y=9, z=5},
	yslice_prob = {
		{ypos=0, prob=254},
		{ypos=1, prob=126},
		{ypos=2, prob=126},
		{ypos=3, prob=254},
		{ypos=4, prob=254},
		{ypos=5, prob=254},
		{ypos=6, prob=254},
		{ypos=7, prob=254},
		{ypos=8, prob=254},
	},
	data = {
		{name="air", prob=0, param2=0},
		{name="air", prob=0, param2=0},
		{name="air", prob=0, param2=0},
		{name="air", prob=0, param2=0},
		{name="air", prob=0, param2=0},
		{name="air", prob=0, param2=0},
		{name="air", prob=0, param2=0},
		{name="air", prob=0, param2=0},
		{name="air", prob=0, param2=0},
		{name="air", prob=0, param2=0},
		{name="air", prob=0, param2=0},
		{name="air", prob=0, param2=0},
		{name="air", prob=0, param2=0},
		{name="air", prob=0, param2=0},
		{name="air", prob=0, param2=0},
		{name="air", prob=0, param2=0},
		{name="air", prob=0, param2=0},
		{name="air", prob=0, param2=0},
		{name="air", prob=0, param2=0},
		{name="air", prob=0, param2=0},
		{name="air", prob=0, param2=0},
		{name="air", prob=0, param2=0},
		{name="air", prob=0, param2=0},
		{name="air", prob=0, param2=0},
		{name="air", prob=0, param2=0},
		{name="vlf_mushrooms:red_mushroom_block_cap_000101", prob=254, param2=0, force_place=true},
		{name="vlf_mushrooms:red_mushroom_block_cap_000001", prob=254, param2=0, force_place=true},
		{name="vlf_mushrooms:red_mushroom_block_cap_000001", prob=254, param2=0, force_place=true},
		{name="vlf_mushrooms:red_mushroom_block_cap_000001", prob=254, param2=0, force_place=true},
		{name="vlf_mushrooms:red_mushroom_block_cap_001001", prob=254, param2=0, force_place=true},
		{name="vlf_mushrooms:red_mushroom_block_cap_100101", prob=254, param2=0, force_place=true},
		{name="vlf_mushrooms:red_mushroom_block_cap_000001", prob=254, param2=0, force_place=true},
		{name="vlf_mushrooms:red_mushroom_block_cap_000001", prob=254, param2=0, force_place=true},
		{name="vlf_mushrooms:red_mushroom_block_cap_000001", prob=254, param2=0, force_place=true},
		{name="vlf_mushrooms:red_mushroom_block_cap_101001", prob=254, param2=0, force_place=true},
		{name="air", prob=254, param2=0},
		{name="vlf_mushrooms:red_mushroom_block_cap_100101", prob=254, param2=0, force_place=true},
		{name="vlf_mushrooms:red_mushroom_block_cap_100001", prob=254, param2=0, force_place=true},
		{name="vlf_mushrooms:red_mushroom_block_cap_101001", prob=254, param2=0, force_place=true},
		{name="air", prob=254, param2=0},
		{name="air", prob=254, param2=0},
		{name="air", prob=254, param2=0},
		{name="air", prob=254, param2=0},
		{name="air", prob=254, param2=0},
		{name="air", prob=254, param2=0},
		{name="air", prob=0, param2=0},
		{name="air", prob=0, param2=0},
		{name="air", prob=0, param2=0},
		{name="air", prob=0, param2=0},
		{name="air", prob=0, param2=0},
		{name="air", prob=0, param2=0},
		{name="air", prob=0, param2=0},
		{name="air", prob=0, param2=0},
		{name="air", prob=0, param2=0},
		{name="air", prob=0, param2=0},
		{name="air", prob=0, param2=0},
		{name="air", prob=0, param2=0},
		{name="air", prob=0, param2=0},
		{name="air", prob=0, param2=0},
		{name="air", prob=0, param2=0},
		{name="air", prob=0, param2=0},
		{name="air", prob=0, param2=0},
		{name="air", prob=0, param2=0},
		{name="air", prob=0, param2=0},
		{name="air", prob=0, param2=0},
		{name="air", prob=0, param2=0},
		{name="air", prob=0, param2=0},
		{name="air", prob=0, param2=0},
		{name="air", prob=0, param2=0},
		{name="air", prob=0, param2=0},
		{name="vlf_mushrooms:red_mushroom_block_cap_000100", prob=254, param2=0, force_place=true},
		{name="air", prob=254, param2=0},
		{name="air", prob=254, param2=0},
		{name="air", prob=254, param2=0},
		{name="vlf_mushrooms:red_mushroom_block_cap_001000", prob=254, param2=0, force_place=true},
		{name="vlf_mushrooms:red_mushroom_block_cap_000100", prob=254, param2=0, force_place=true},
		{name="air", prob=254, param2=0},
		{name="air", prob=254, param2=0},
		{name="air", prob=254, param2=0},
		{name="vlf_mushrooms:red_mushroom_block_cap_001000", prob=254, param2=0, force_place=true},
		{name="vlf_mushrooms:red_mushroom_block_cap_100101", prob=254, param2=0, force_place=true},
		{name="air", prob=254, param2=0},
		{name="air", prob=254, param2=0},
		{name="air", prob=254, param2=0},
		{name="vlf_mushrooms:red_mushroom_block_cap_101001", prob=254, param2=0, force_place=true},
		{name="air", prob=254, param2=0},
		{name="vlf_mushrooms:red_mushroom_block_cap_100101", prob=254, param2=0, force_place=true},
		{name="vlf_mushrooms:red_mushroom_block_cap_100001", prob=254, param2=0, force_place=true},
		{name="vlf_mushrooms:red_mushroom_block_cap_101001", prob=254, param2=0, force_place=true},
		{name="air", prob=254, param2=0},
		{name="air", prob=0, param2=0},
		{name="air", prob=0, param2=0},
		{name="vlf_mushrooms:red_mushroom_block_stem", prob=254, param2=0},
		{name="air", prob=0, param2=0},
		{name="air", prob=0, param2=0},
		{name="air", prob=0, param2=0},
		{name="air", prob=0, param2=0},
		{name="vlf_mushrooms:red_mushroom_block_stem", prob=254, param2=0, force_place=true},
		{name="air", prob=0, param2=0},
		{name="air", prob=0, param2=0},
		{name="air", prob=0, param2=0},
		{name="air", prob=0, param2=0},
		{name="vlf_mushrooms:red_mushroom_block_stem", prob=254, param2=0, force_place=true},
		{name="air", prob=0, param2=0},
		{name="air", prob=0, param2=0},
		{name="air", prob=0, param2=0},
		{name="air", prob=0, param2=0},
		{name="vlf_mushrooms:red_mushroom_block_stem", prob=254, param2=0, force_place=true},
		{name="air", prob=0, param2=0},
		{name="air", prob=0, param2=0},
		{name="air", prob=0, param2=0},
		{name="air", prob=0, param2=0},
		{name="vlf_mushrooms:red_mushroom_block_stem", prob=254, param2=0, force_place=true},
		{name="air", prob=0, param2=0},
		{name="air", prob=0, param2=0},
		{name="vlf_mushrooms:red_mushroom_block_cap_000100", prob=254, param2=0, force_place=true},
		{name="air", prob=254, param2=0},
		{name="vlf_mushrooms:red_mushroom_block_stem", prob=254, param2=0, force_place=true},
		{name="air", prob=254, param2=0},
		{name="vlf_mushrooms:red_mushroom_block_cap_001000", prob=254, param2=0, force_place=true},
		{name="vlf_mushrooms:red_mushroom_block_cap_000100", prob=254, param2=0, force_place=true},
		{name="air", prob=254, param2=0},
		{name="vlf_mushrooms:red_mushroom_block_stem", prob=254, param2=0, force_place=true},
		{name="air", prob=254, param2=0},
		{name="vlf_mushrooms:red_mushroom_block_cap_001000", prob=254, param2=0, force_place=true},
		{name="vlf_mushrooms:red_mushroom_block_cap_100100", prob=254, param2=0, force_place=true},
		{name="air", prob=254, param2=0},
		{name="vlf_mushrooms:red_mushroom_block_stem", prob=254, param2=0, force_place=true},
		{name="air", prob=254, param2=0},
		{name="vlf_mushrooms:red_mushroom_block_cap_101000", prob=254, param2=0, force_place=true},
		{name="air", prob=254, param2=0},
		{name="vlf_mushrooms:red_mushroom_block_cap_100100", prob=254, param2=0, force_place=true},
		{name="vlf_mushrooms:red_mushroom_block_cap_100000", prob=254, param2=0, force_place=true},
		{name="vlf_mushrooms:red_mushroom_block_cap_101000", prob=254, param2=0, force_place=true},
		{name="air", prob=254, param2=0},
		{name="air", prob=0, param2=0},
		{name="air", prob=0, param2=0},
		{name="air", prob=0, param2=0},
		{name="air", prob=0, param2=0},
		{name="air", prob=0, param2=0},
		{name="air", prob=0, param2=0},
		{name="air", prob=0, param2=0},
		{name="air", prob=0, param2=0},
		{name="air", prob=0, param2=0},
		{name="air", prob=0, param2=0},
		{name="air", prob=0, param2=0},
		{name="air", prob=0, param2=0},
		{name="air", prob=0, param2=0},
		{name="air", prob=0, param2=0},
		{name="air", prob=0, param2=0},
		{name="air", prob=0, param2=0},
		{name="air", prob=0, param2=0},
		{name="air", prob=0, param2=0},
		{name="air", prob=0, param2=0},
		{name="air", prob=0, param2=0},
		{name="air", prob=0, param2=0},
		{name="air", prob=0, param2=0},
		{name="air", prob=0, param2=0},
		{name="air", prob=0, param2=0},
		{name="air", prob=0, param2=0},
		{name="vlf_mushrooms:red_mushroom_block_cap_000100", prob=254, param2=0, force_place=true},
		{name="air", prob=254, param2=0},
		{name="air", prob=254, param2=0},
		{name="air", prob=254, param2=0},
		{name="vlf_mushrooms:red_mushroom_block_cap_001000", prob=254, param2=0, force_place=true},
		{name="vlf_mushrooms:red_mushroom_block_cap_000100", prob=254, param2=0, force_place=true},
		{name="air", prob=254, param2=0},
		{name="air", prob=254, param2=0},
		{name="air", prob=254, param2=0},
		{name="vlf_mushrooms:red_mushroom_block_cap_001000", prob=254, param2=0, force_place=true},
		{name="vlf_mushrooms:red_mushroom_block_cap_100110", prob=254, param2=0, force_place=true},
		{name="air", prob=254, param2=0},
		{name="air", prob=254, param2=0},
		{name="air", prob=254, param2=0},
		{name="vlf_mushrooms:red_mushroom_block_cap_101010", prob=254, param2=0, force_place=true},
		{name="air", prob=254, param2=0},
		{name="vlf_mushrooms:red_mushroom_block_cap_100110", prob=254, param2=0, force_place=true},
		{name="vlf_mushrooms:red_mushroom_block_cap_100010", prob=254, param2=0, force_place=true},
		{name="vlf_mushrooms:red_mushroom_block_cap_101010", prob=254, param2=0, force_place=true},
		{name="air", prob=254, param2=0},
		{name="air", prob=0, param2=0},
		{name="air", prob=0, param2=0},
		{name="air", prob=0, param2=0},
		{name="air", prob=0, param2=0},
		{name="air", prob=0, param2=0},
		{name="air", prob=0, param2=0},
		{name="air", prob=0, param2=0},
		{name="air", prob=0, param2=0},
		{name="air", prob=0, param2=0},
		{name="air", prob=0, param2=0},
		{name="air", prob=0, param2=0},
		{name="air", prob=0, param2=0},
		{name="air", prob=0, param2=0},
		{name="air", prob=0, param2=0},
		{name="air", prob=0, param2=0},
		{name="air", prob=0, param2=0},
		{name="air", prob=0, param2=0},
		{name="air", prob=0, param2=0},
		{name="air", prob=0, param2=0},
		{name="air", prob=0, param2=0},
		{name="air", prob=0, param2=0},
		{name="air", prob=0, param2=0},
		{name="air", prob=0, param2=0},
		{name="air", prob=0, param2=0},
		{name="air", prob=0, param2=0},
		{name="vlf_mushrooms:red_mushroom_block_cap_000110", prob=254, param2=0, force_place=true},
		{name="vlf_mushrooms:red_mushroom_block_cap_000010", prob=254, param2=0, force_place=true},
		{name="vlf_mushrooms:red_mushroom_block_cap_000010", prob=254, param2=0, force_place=true},
		{name="vlf_mushrooms:red_mushroom_block_cap_000010", prob=254, param2=0, force_place=true},
		{name="vlf_mushrooms:red_mushroom_block_cap_001010", prob=254, param2=0, force_place=true},
		{name="vlf_mushrooms:red_mushroom_block_cap_100110", prob=254, param2=0, force_place=true},
		{name="vlf_mushrooms:red_mushroom_block_cap_000010", prob=254, param2=0, force_place=true},
		{name="vlf_mushrooms:red_mushroom_block_cap_000010", prob=254, param2=0, force_place=true},
		{name="vlf_mushrooms:red_mushroom_block_cap_000010", prob=254, param2=0, force_place=true},
		{name="vlf_mushrooms:red_mushroom_block_cap_101010", prob=254, param2=0, force_place=true},
		{name="air", prob=254, param2=0},
		{name="vlf_mushrooms:red_mushroom_block_cap_100110", prob=254, param2=0, force_place=true},
		{name="vlf_mushrooms:red_mushroom_block_cap_100010", prob=254, param2=0, force_place=true},
		{name="vlf_mushrooms:red_mushroom_block_cap_101010", prob=254, param2=0, force_place=true},
		{name="air", prob=254, param2=0},
		{name="air", prob=254, param2=0},
		{name="air", prob=254, param2=0},
		{name="air", prob=254, param2=0},
		{name="air", prob=254, param2=0},
		{name="air", prob=254, param2=0},
	},
}
