schematic = {
	size = {x=16, y=16, z=31},
	yslice_prob = {
		{ypos=0, prob=254},
		{ypos=1, prob=254},
		{ypos=2, prob=254},
		{ypos=3, prob=254},
		{ypos=4, prob=254},
		{ypos=5, prob=254},
		{ypos=6, prob=254},
		{ypos=7, prob=254},
		{ypos=8, prob=254},
		{ypos=9, prob=254},
		{ypos=10, prob=254},
		{ypos=11, prob=254},
		{ypos=12, prob=254},
		{ypos=13, prob=254},
		{ypos=14, prob=254},
		{ypos=15, prob=254},
	},
	data = {
		{name="vlf_deepslate:deepslate", prob=254, param2=0},
		{name="vlf_sculk:sculk", prob=254, param2=0},
		{name="vlf_sculk:sculk", prob=254, param2=0},
		{name="vlf_sculk:sculk", prob=254, param2=0},
		{name="vlf_sculk:sculk", prob=254, param2=0},
		{name="vlf_sculk:sculk", prob=254, param2=0},
		{name="vlf_sculk:sculk", prob=254, param2=0},
		{name="vlf_sculk:sculk", prob=254, param2=0},
		{name="vlf_sculk:sculk", prob=254, param2=0},
		{name="vlf_sculk:sculk", prob=254, param2=0},
		{name="vlf_sculk:sculk", prob=254, param2=0},
		{name="vlf_sculk:sculk", prob=254, param2=0},
		{name="vlf_sculk:vein", prob=254, param2=1},
		{name="vlf_sculk:sculk", prob=254, param2=0},
		{name="vlf_deepslate:deepslate", prob=254, param2=0},
		{name="vlf_deepslate:deepslate", prob=254, param2=0},
		{name="vlf_sculk:sculk", prob=254, param2=0},
		{name="air", prob=254, param2=0},
		{name="air", prob=254, param2=0},
		{name="air", prob=254, param2=0},
		{name="air", prob=254, param2=0},
		{name="air", prob=254, param2=0},
		{name="air", prob=254, param2=0},
		{name="air", prob=254, param2=0},
		{name="air", prob=254, param2=0},
		{name="air", prob=254, param2=0},
		{name="air", prob=254, param2=0},
		{name="air", prob=254, param2=0},
		{name="vlf_deepslate:deepslate_tiles_cracked", prob=254, param2=0},
		{name="vlf_deepslate:deepslate_tiles_cracked", prob=254, param2=0},
		{name="vlf_deepslate:deepslate_tiles_cracked", prob=254, param2=0},
		{name="vlf_deepslate:deepslate_tiles_cracked", prob=254, param2=0},
		{name="air", prob=254, param2=0},
		{name="air", prob=254, param2=0},
		{name="air", prob=254, param2=0},
		{name="air", prob=254, param2=0},
		{name="air", prob=254, param2=0},
		{name="air", prob=254, param2=0},
		{name="air", prob=254, param2=0},
		{name="air", prob=254, param2=0},
		{name="air", prob=254, param2=0},
		{name="air", prob=254, param2=0},
		{name="air", prob=254, param2=0},
		{name="air", prob=254, param2=0},
		{name="air", prob=254, param2=0},
		{name="air", prob=254, param2=0},
		{name="air", prob=254, param2=0},
		{name="air", prob=254, param2=0},
		{name="air", prob=254, param2=0},
		{name="air", prob=254, param2=0},
		{name="air", prob=254, param2=0},
		{name="air", prob=254, param2=0},
		{name="air", prob=254, param2=0},
		{name="air", prob=254, param2=0},
		{name="air", prob=254, param2=0},
		{name="air", prob=254, param2=0},
		{name="air", prob=254, param2=0},
		{name="air", prob=254, param2=0},
		{name="air", prob=254, param2=0},
		{name="air", prob=254, param2=0},
		{name="air", prob=254, param2=0},
		{name="air", prob=254, param2=0},
		{name="air", prob=254, param2=0},
		{name="air", prob=254, param2=0},
		{name="air", prob=254, param2=0},
		{name="air", prob=254, param2=0},
		{name="air", prob=254, param2=0},
		{name="air", prob=254, param2=0},
		{name="air", prob=254, param2=0},
		{name="air", prob=254, param2=0},
		{name="air", prob=254, param2=0},
		{name="air", prob=254, param2=0},
		{name="air", prob=254, param2=0},
		{name="air", prob=254, param2=0},
		{name="air", prob=254, param2=0},
		{name="air", prob=254, param2=0},
		{name="air", prob=254, param2=0},
		{name="air", prob=254, param2=0},
		{name="air", prob=254, param2=0},
		{name="air", prob=254, param2=0},
		{name="air", prob=254, param2=0},
		{name="air", prob=254, param2=0},
		{name="air", prob=254, param2=0},
		{name="air", prob=254, param2=0},
		{name="air", prob=254, param2=0},
		{name="air", prob=254, param2=0},
		{name="air", prob=254, param2=0},
		{name="air", prob=254, param2=0},
		{name="air", prob=254, param2=0},
		{name="air", prob=254, param2=0},
		{name="air", prob=254, param2=0},
		{name="air", prob=254, param2=0},
		{name="air", prob=254, param2=0},
		{name="air", prob=254, param2=0},
		{name="air", prob=254, param2=0},
		{name="air", prob=254, param2=0},
		{name="air", prob=254, param2=0},
		{name="air", prob=254, param2=0},
		{name="air", prob=254, param2=0},
		{name="air", prob=254, param2=0},
		{name="air", prob=254, param2=0},
		{name="air", prob=254, param2=0},
		{name="air", prob=254, param2=0},
		{name="air", prob=254, param2=0},
		{name="air", prob=254, param2=0},
		{name="air", prob=254, param2=0},
		{name="air", prob=254, param2=0},
		{name="air", prob=254, param2=0},
		{name="air", prob=254, param2=0},
		{name="air", prob=254, param2=0},
		{name="air", prob=254, param2=0},
		{name="air", prob=254, param2=0},
		{name="air", prob=254, param2=0},
		{name="air", prob=254, param2=0},
		{name="air", prob=254, param2=0},
		{name="air", prob=254, param2=0},
		{name="air", prob=254, param2=0},
		{name="air", prob=254, param2=0},
		{name="air", prob=254, param2=0},
		{name="air", prob=254, param2=0},
		{name="air", prob=254, param2=0},
		{name="air", prob=254, param2=0},
		{name="air", prob=254, param2=0},
		{name="air", prob=254, param2=0},
		{name="air", prob=254, param2=0},
		{name="air", prob=254, param2=0},
		{name="air", prob=254, param2=0},
		{name="air", prob=254, param2=0},
		{name="air", prob=254, param2=0},
		{name="air", prob=254, param2=0},
		{name="air", prob=254, param2=0},
		{name="air", prob=254, param2=0},
		{name="air", prob=254, param2=0},
		{name="air", prob=254, param2=0},
		{name="air", prob=254, param2=0},
		{name="air", prob=254, param2=0},
		{name="air", prob=254, param2=0},
		{name="air", prob=254, param2=0},
		{name="air", prob=254, param2=0},
		{name="air", prob=254, param2=0},
		{name="air", prob=254, param2=0},
		{name="air", prob=254, param2=0},
		{name="air", prob=254, param2=0},
		{name="air", prob=254, param2=0},
		{name="air", prob=254, param2=0},
		{name="air", prob=254, param2=0},
		{name="air", prob=254, param2=0},
		{name="air", prob=254, param2=0},
		{name="air", prob=254, param2=0},
		{name="air", prob=254, param2=0},
		{name="air", prob=254, param2=0},
		{name="air", prob=254, param2=0},
		{name="air", prob=254, param2=0},
		{name="air", prob=254, param2=0},
		{name="air", prob=254, param2=0},
		{name="air", prob=254, param2=0},
		{name="air", prob=254, param2=0},
		{name="air", prob=254, param2=0},
		{name="air", prob=254, param2=0},
		{name="air", prob=254, param2=0},
		{name="air", prob=254, param2=0},
		{name="air", prob=254, param2=0},
		{name="air", prob=254, param2=0},
		{name="air", prob=254, param2=0},
		{name="air", prob=254, param2=0},
		{name="air", prob=254, param2=0},
		{name="air", prob=254, param2=0},
		{name="air", prob=254, param2=0},
		{name="air", prob=254, param2=0},
		{name="air", prob=254, param2=0},
		{name="air", prob=254, param2=0},
		{name="air", prob=254, param2=0},
		{name="air", prob=254, param2=0},
		{name="air", prob=254, param2=0},
		{name="air", prob=254, param2=0},
		{name="air", prob=254, param2=0},
		{name="air", prob=254, param2=0},
		{name="air", prob=254, param2=0},
		{name="air", prob=254, param2=0},
		{name="air", prob=254, param2=0},
		{name="air", prob=254, param2=0},
		{name="air", prob=254, param2=0},
		{name="air", prob=254, param2=0},
		{name="air", prob=254, param2=0},
		{name="air", prob=254, param2=0},
		{name="air", prob=254, param2=0},
		{name="air", prob=254, param2=0},
		{name="air", prob=254, param2=0},
		{name="air", prob=254, param2=0},
		{name="air", prob=254, param2=0},
		{name="air", prob=254, param2=0},
		{name="air", prob=254, param2=0},
		{name="air", prob=254, param2=0},
		{name="air", prob=254, param2=0},
		{name="air", prob=254, param2=0},
		{name="air", prob=254, param2=0},
		{name="air", prob=254, param2=0},
		{name="air", prob=254, param2=0},
		{name="air", prob=254, param2=0},
		{name="air", prob=254, param2=0},
		{name="air", prob=254, param2=0},
		{name="air", prob=254, param2=0},
		{name="air", prob=254, param2=0},
		{name="air", prob=254, param2=0},
		{name="air", prob=254, param2=0},
		{name="air", prob=254, param2=0},
		{name="air", prob=254, param2=0},
		{name="air", prob=254, param2=0},
		{name="air", prob=254, param2=0},
		{name="air", prob=254, param2=0},
		{name="air", prob=254, param2=0},
		{name="air", prob=254, param2=0},
		{name="air", prob=254, param2=0},
		{name="air", prob=254, param2=0},
		{name="air", prob=254, param2=0},
		{name="air", prob=254, param2=0},
		{name="air", prob=254, param2=0},
		{name="air", prob=254, param2=0},
		{name="air", prob=254, param2=0},
		{name="air", prob=254, param2=0},
		{name="air", prob=254, param2=0},
		{name="air", prob=254, param2=0},
		{name="air", prob=254, param2=0},
		{name="air", prob=254, param2=0},
		{name="air", prob=254, param2=0},
		{name="air", prob=254, param2=0},
		{name="air", prob=254, param2=0},
		{name="air", prob=254, param2=0},
		{name="air", prob=254, param2=0},
		{name="air", prob=254, param2=0},
		{name="air", prob=254, param2=0},
		{name="air", prob=254, param2=0},
		{name="air", prob=254, param2=0},
		{name="air", prob=254, param2=0},
		{name="vlf_sculk:sculk", prob=254, param2=0},
		{name="air", prob=254, param2=0},
		{name="air", prob=254, param2=0},
		{name="air", prob=254, param2=0},
		{name="air", prob=254, param2=0},
		{name="air", prob=254, param2=0},
		{name="air", prob=254, param2=0},
		{name="air", prob=254, param2=0},
		{name="air", prob=254, param2=0},
		{name="air", prob=254, param2=0},
		{name="air", prob=254, param2=0},
		{name="air", prob=254, param2=0},
		{name="air", prob=254, param2=0},
		{name="air", prob=254, param2=0},
		{name="air", prob=254, param2=0},
		{name="air", prob=254, param2=0},
		{name="air", prob=254, param2=0},
		{name="air", prob=254, param2=0},
		{name="air", prob=254, param2=0},
		{name="air", prob=254, param2=0},
		{name="air", prob=254, param2=0},
		{name="air", prob=254, param2=0},
		{name="vlf_deepslate:deepslate", prob=254, param2=0},
		{name="vlf_deepslate:deepslate_tiles", prob=254, param2=0},
		{name="vlf_deepslate:deepslate_tiles", prob=254, param2=0},
		{name="vlf_deepslate:deepslate_tiles", prob=254, param2=0},
		{name="vlf_deepslate:deepslate_tiles", prob=254, param2=0},
		{name="vlf_deepslate:deepslate_tiles", prob=254, param2=0},
		{name="vlf_deepslate:deepslate_tiles", prob=254, param2=0},
		{name="vlf_deepslate:deepslate_tiles", prob=254, param2=0},
		{name="vlf_deepslate:deepslate_tiles", prob=254, param2=0},
		{name="vlf_deepslate:deepslate_tiles", prob=254, param2=0},
		{name="vlf_deepslate:deepslate_tiles", prob=254, param2=0},
		{name="vlf_deepslate:deepslate_tiles", prob=254, param2=0},
		{name="vlf_sculk:sculk", prob=254, param2=0},
		{name="vlf_deepslate:deepslate", prob=254, param2=0},
		{name="vlf_deepslate:deepslate", prob=254, param2=0},
		{name="vlf_deepslate:deepslate", prob=254, param2=0},
		{name="vlf_sculk:sculk", prob=254, param2=0},
		{name="vlf_deepslate:deepslate_tiles", prob=254, param2=0},
		{name="vlf_deepslate:deepslate_tiles", prob=254, param2=0},
		{name="vlf_deepslate:deepslate_tiles", prob=254, param2=0},
		{name="vlf_deepslate:deepslate_tiles", prob=254, param2=0},
		{name="vlf_deepslate:deepslate_tiles", prob=254, param2=0},
		{name="vlf_deepslate:deepslate_tiles", prob=254, param2=0},
		{name="vlf_deepslate:deepslate_tiles", prob=254, param2=0},
		{name="vlf_deepslate:deepslate_tiles", prob=254, param2=0},
		{name="vlf_deepslate:deepslate_tiles_cracked", prob=254, param2=0},
		{name="vlf_deepslate:deepslate_tiles", prob=254, param2=0},
		{name="vlf_deepslate:deepslate_tiles", prob=254, param2=0},
		{name="vlf_deepslate:deepslate_tiles", prob=254, param2=0},
		{name="vlf_deepslate:deepslate_tiles", prob=254, param2=0},
		{name="vlf_deepslate:deepslate_tiles", prob=254, param2=0},
		{name="vlf_deepslate:deepslate_tiles_cracked", prob=254, param2=0},
		{name="air", prob=254, param2=0},
		{name="vlf_deepslate:deepslate_tiles", prob=254, param2=0},
		{name="vlf_deepslate:deepslate_tiles", prob=254, param2=0},
		{name="vlf_deepslate:deepslate_tiles", prob=254, param2=0},
		{name="vlf_deepslate:deepslate_tiles", prob=254, param2=0},
		{name="vlf_deepslate:deepslate_tiles", prob=254, param2=0},
		{name="vlf_deepslate:deepslate_tiles", prob=254, param2=0},
		{name="vlf_deepslate:deepslate_tiles", prob=254, param2=0},
		{name="vlf_deepslate:deepslate_tiles", prob=254, param2=0},
		{name="vlf_deepslate:deepslate_tiles_cracked", prob=254, param2=0},
		{name="vlf_deepslate:deepslate_tiles", prob=254, param2=0},
		{name="vlf_deepslate:deepslate_tiles", prob=254, param2=0},
		{name="vlf_deepslate:deepslate_tiles_cracked", prob=254, param2=0},
		{name="vlf_deepslate:deepslate_tiles", prob=254, param2=0},
		{name="vlf_deepslate:deepslate_tiles", prob=254, param2=0},
		{name="air", prob=254, param2=0},
		{name="air", prob=254, param2=0},
		{name="vlf_deepslate:deepslate_tiles", prob=254, param2=0},
		{name="vlf_deepslate:deepslate_tiles", prob=254, param2=0},
		{name="vlf_deepslate:deepslate_tiles", prob=254, param2=0},
		{name="vlf_deepslate:deepslate_tiles", prob=254, param2=0},
		{name="vlf_deepslate:deepslate_tiles", prob=254, param2=0},
		{name="vlf_deepslate:deepslate_tiles", prob=254, param2=0},
		{name="vlf_deepslate:deepslate_tiles", prob=254, param2=0},
		{name="vlf_deepslate:deepslate_tiles_cracked", prob=254, param2=0},
		{name="vlf_deepslate:deepslate_tiles", prob=254, param2=0},
		{name="vlf_deepslate:deepslate_tiles", prob=254, param2=0},
		{name="vlf_deepslate:deepslate_tiles", prob=254, param2=0},
		{name="vlf_deepslate:deepslate_tiles_cracked", prob=254, param2=0},
		{name="vlf_deepslate:deepslate_tiles_cracked", prob=254, param2=0},
		{name="vlf_deepslate:deepslate_tiles", prob=254, param2=0},
		{name="air", prob=254, param2=0},
		{name="air", prob=254, param2=0},
		{name="vlf_deepslate:deepslate_tiles", prob=254, param2=0},
		{name="vlf_deepslate:deepslate_tiles", prob=254, param2=0},
		{name="vlf_deepslate:deepslate_tiles", prob=254, param2=0},
		{name="vlf_deepslate:deepslate_tiles", prob=254, param2=0},
		{name="vlf_deepslate:deepslate_tiles", prob=254, param2=0},
		{name="vlf_deepslate:deepslate_tiles", prob=254, param2=0},
		{name="vlf_deepslate:deepslate_tiles", prob=254, param2=0},
		{name="vlf_deepslate:deepslate_tiles", prob=254, param2=0},
		{name="vlf_deepslate:deepslate_tiles", prob=254, param2=0},
		{name="vlf_deepslate:deepslate_tiles", prob=254, param2=0},
		{name="vlf_deepslate:deepslate_tiles", prob=254, param2=0},
		{name="vlf_deepslate:deepslate_tiles", prob=254, param2=0},
		{name="vlf_deepslate:deepslate_tiles_cracked", prob=254, param2=0},
		{name="vlf_deepslate:deepslate_tiles", prob=254, param2=0},
		{name="air", prob=254, param2=0},
		{name="air", prob=254, param2=0},
		{name="vlf_deepslate:deepslate_tiles", prob=254, param2=0},
		{name="vlf_deepslate:deepslate_tiles", prob=254, param2=0},
		{name="vlf_deepslate:deepslate_tiles", prob=254, param2=0},
		{name="vlf_deepslate:deepslate_tiles", prob=254, param2=0},
		{name="vlf_deepslate:deepslate_tiles", prob=254, param2=0},
		{name="vlf_deepslate:deepslate_tiles", prob=254, param2=0},
		{name="vlf_deepslate:deepslate_tiles", prob=254, param2=0},
		{name="vlf_deepslate:deepslate_tiles", prob=254, param2=0},
		{name="vlf_deepslate:deepslate_tiles", prob=254, param2=0},
		{name="vlf_deepslate:deepslate_tiles", prob=254, param2=0},
		{name="vlf_deepslate:deepslate_tiles", prob=254, param2=0},
		{name="vlf_deepslate:deepslate_tiles_cracked", prob=254, param2=0},
		{name="vlf_deepslate:deepslate_tiles", prob=254, param2=0},
		{name="vlf_deepslate:deepslate_tiles", prob=254, param2=0},
		{name="air", prob=254, param2=0},
		{name="air", prob=254, param2=0},
		{name="vlf_deepslate:deepslate_tiles", prob=254, param2=0},
		{name="vlf_deepslate:deepslate_tiles", prob=254, param2=0},
		{name="vlf_deepslate:deepslate_tiles", prob=254, param2=0},
		{name="vlf_deepslate:deepslate_tiles", prob=254, param2=0},
		{name="vlf_deepslate:deepslate_tiles", prob=254, param2=0},
		{name="vlf_deepslate:deepslate_tiles", prob=254, param2=0},
		{name="vlf_deepslate:deepslate_tiles", prob=254, param2=0},
		{name="vlf_deepslate:deepslate_tiles_cracked", prob=254, param2=0},
		{name="vlf_deepslate:deepslate_tiles_cracked", prob=254, param2=0},
		{name="vlf_deepslate:deepslate_tiles", prob=254, param2=0},
		{name="vlf_deepslate:deepslate_tiles", prob=254, param2=0},
		{name="vlf_deepslate:deepslate_tiles", prob=254, param2=0},
		{name="vlf_deepslate:deepslate_tiles", prob=254, param2=0},
		{name="vlf_deepslate:deepslate_tiles", prob=254, param2=0},
		{name="vlf_deepslate:deepslate_tiles_cracked", prob=254, param2=0},
		{name="air", prob=254, param2=0},
		{name="vlf_deepslate:deepslate_tiles", prob=254, param2=0},
		{name="vlf_deepslate:deepslate_tiles", prob=254, param2=0},
		{name="vlf_deepslate:deepslate_tiles", prob=254, param2=0},
		{name="vlf_deepslate:deepslate_tiles", prob=254, param2=0},
		{name="vlf_deepslate:deepslate_tiles", prob=254, param2=0},
		{name="vlf_deepslate:deepslate_tiles", prob=254, param2=0},
		{name="vlf_deepslate:deepslate_tiles", prob=254, param2=0},
		{name="vlf_deepslate:deepslate_tiles_cracked", prob=254, param2=0},
		{name="vlf_deepslate:deepslate_tiles_cracked", prob=254, param2=0},
		{name="vlf_deepslate:deepslate_tiles_cracked", prob=254, param2=0},
		{name="vlf_deepslate:deepslate_cobbled", prob=254, param2=0},
		{name="vlf_deepslate:deepslate_cobbled", prob=254, param2=0},
		{name="air", prob=254, param2=0},
		{name="air", prob=254, param2=0},
		{name="vlf_deepslate:deepslate_tiles_cracked", prob=254, param2=0},
		{name="air", prob=254, param2=0},
		{name="air", prob=254, param2=0},
		{name="air", prob=254, param2=0},
		{name="air", prob=254, param2=0},
		{name="vlf_deepslate:deepslate_cobbled", prob=254, param2=0},
		{name="vlf_deepslate:deepslate_cobbled", prob=254, param2=0},
		{name="air", prob=254, param2=0},
		{name="vlf_deepslate:deepslate_cobbled", prob=254, param2=0},
		{name="vlf_deepslate:deepslate_cobbled", prob=254, param2=0},
		{name="vlf_deepslate:deepslate_cobbled", prob=254, param2=0},
		{name="air", prob=254, param2=0},
		{name="vlf_deepslate:deepslate_cobbled", prob=254, param2=0},
		{name="vlf_deepslate:deepslate_cobbled", prob=254, param2=0},
		{name="air", prob=254, param2=0},
		{name="air", prob=254, param2=0},
		{name="air", prob=254, param2=0},
		{name="air", prob=254, param2=0},
		{name="air", prob=254, param2=0},
		{name="air", prob=254, param2=0},
		{name="air", prob=254, param2=0},
		{name="air", prob=254, param2=0},
		{name="vlf_deepslate:deepslate_cobbled", prob=254, param2=0},
		{name="air", prob=254, param2=0},
		{name="vlf_deepslate:deepslate_cobbled", prob=254, param2=0},
		{name="vlf_deepslate:deepslate_cobbled", prob=254, param2=0},
		{name="vlf_deepslate:deepslate_cobbled", prob=254, param2=0},
		{name="air", prob=254, param2=0},
		{name="vlf_deepslate:deepslate_cobbled", prob=254, param2=0},
		{name="air", prob=254, param2=0},
		{name="air", prob=254, param2=0},
		{name="air", prob=254, param2=0},
		{name="air", prob=254, param2=0},
		{name="air", prob=254, param2=0},
		{name="air", prob=254, param2=0},
		{name="air", prob=254, param2=0},
		{name="air", prob=254, param2=0},
		{name="air", prob=254, param2=0},
		{name="air", prob=254, param2=0},
		{name="air", prob=254, param2=0},
		{name="vlf_deepslate:deepslate_cobbled", prob=254, param2=0},
		{name="vlf_deepslate:deepslate_cobbled", prob=254, param2=0},
		{name="vlf_deepslate:deepslate_cobbled", prob=254, param2=0},
		{name="air", prob=254, param2=0},
		{name="air", prob=254, param2=0},
		{name="air", prob=254, param2=0},
		{name="air", prob=254, param2=0},
		{name="air", prob=254, param2=0},
		{name="air", prob=254, param2=0},
		{name="air", prob=254, param2=0},
		{name="air", prob=254, param2=0},
		{name="air", prob=254, param2=0},
		{name="air", prob=254, param2=0},
		{name="air", prob=254, param2=0},
		{name="air", prob=254, param2=0},
		{name="air", prob=254, param2=0},
		{name="vlf_deepslate:deepslate_cobbled", prob=254, param2=0},
		{name="vlf_deepslate:deepslate_cobbled", prob=254, param2=0},
		{name="vlf_deepslate:deepslate_cobbled", prob=254, param2=0},
		{name="air", prob=254, param2=0},
		{name="air", prob=254, param2=0},
		{name="air", prob=254, param2=0},
		{name="air", prob=254, param2=0},
		{name="air", prob=254, param2=0},
		{name="air", prob=254, param2=0},
		{name="air", prob=254, param2=0},
		{name="air", prob=254, param2=0},
		{name="air", prob=254, param2=0},
		{name="air", prob=254, param2=0},
		{name="air", prob=254, param2=0},
		{name="air", prob=254, param2=0},
		{name="air", prob=254, param2=0},
		{name="air", prob=254, param2=0},
		{name="vlf_deepslate:deepslate_cobbled", prob=254, param2=0},
		{name="air", prob=254, param2=0},
		{name="air", prob=254, param2=0},
		{name="air", prob=254, param2=0},
		{name="air", prob=254, param2=0},
		{name="air", prob=254, param2=0},
		{name="air", prob=254, param2=0},
		{name="air", prob=254, param2=0},
		{name="air", prob=254, param2=0},
		{name="air", prob=254, param2=0},
		{name="air", prob=254, param2=0},
		{name="air", prob=254, param2=0},
		{name="air", prob=254, param2=0},
		{name="air", prob=254, param2=0},
		{name="air", prob=254, param2=0},
		{name="air", prob=254, param2=0},
		{name="air", prob=254, param2=0},
		{name="air", prob=254, param2=0},
		{name="air", prob=254, param2=0},
		{name="air", prob=254, param2=0},
		{name="air", prob=254, param2=0},
		{name="air", prob=254, param2=0},
		{name="air", prob=254, param2=0},
		{name="air", prob=254, param2=0},
		{name="air", prob=254, param2=0},
		{name="air", prob=254, param2=0},
		{name="air", prob=254, param2=0},
		{name="air", prob=254, param2=0},
		{name="air", prob=254, param2=0},
		{name="air", prob=254, param2=0},
		{name="air", prob=254, param2=0},
		{name="air", prob=254, param2=0},
		{name="air", prob=254, param2=0},
		{name="air", prob=254, param2=0},
		{name="air", prob=254, param2=0},
		{name="air", prob=254, param2=0},
		{name="air", prob=254, param2=0},
		{name="air", prob=254, param2=0},
		{name="air", prob=254, param2=0},
		{name="air", prob=254, param2=0},
		{name="air", prob=254, param2=0},
		{name="air", prob=254, param2=0},
		{name="air", prob=254, param2=0},
		{name="air", prob=254, param2=0},
		{name="air", prob=254, param2=0},
		{name="air", prob=254, param2=0},
		{name="air", prob=254, param2=0},
		{name="air", prob=254, param2=0},
		{name="air", prob=254, param2=0},
		{name="air", prob=254, param2=0},
		{name="air", prob=254, param2=0},
		{name="air", prob=254, param2=0},
		{name="air", prob=254, param2=0},
		{name="air", prob=254, param2=0},
		{name="air", prob=254, param2=0},
		{name="air", prob=254, param2=0},
		{name="vlf_deepslate:deepslate_tiles", prob=254, param2=0},
		{name="vlf_deepslate:deepslate_tiles", prob=254, param2=0},
		{name="vlf_deepslate:deepslate_bricks", prob=254, param2=0},
		{name="air", prob=254, param2=0},
		{name="vlf_wool:silver_carpet", prob=254, param2=0},
		{name="air", prob=254, param2=0},
		{name="vlf_deepslate:deepslate_bricks", prob=254, param2=0},
		{name="air", prob=254, param2=0},
		{name="air", prob=254, param2=0},
		{name="air", prob=254, param2=0},
		{name="vlf_deepslate:deepslate_bricks", prob=254, param2=0},
		{name="air", prob=254, param2=0},
		{name="vlf_deepslate:deepslate_tiles_cracked", prob=254, param2=0},
		{name="vlf_deepslate:deepslate_tiles_cracked", prob=254, param2=0},
		{name="vlf_sculk:sculk", prob=254, param2=0},
		{name="vlf_deepslate:deepslate", prob=254, param2=0},
		{name="vlf_deepslate:deepslate_tiles", prob=254, param2=0},
		{name="vlf_deepslate:deepslate_tiles", prob=254, param2=0},
		{name="vlf_deepslate:deepslate_bricks", prob=254, param2=0},
		{name="air", prob=254, param2=0},
		{name="air", prob=254, param2=0},
		{name="air", prob=254, param2=0},
		{name="vlf_deepslate:deepslate_bricks", prob=254, param2=0},
		{name="air", prob=254, param2=0},
		{name="air", prob=254, param2=0},
		{name="air", prob=254, param2=0},
		{name="vlf_deepslate:deepslate_bricks", prob=254, param2=0},
		{name="air", prob=254, param2=0},
		{name="air", prob=254, param2=0},
		{name="air", prob=254, param2=0},
		{name="vlf_deepslate:deepslate_bricks", prob=254, param2=0},
		{name="vlf_deepslate:deepslate_tiles", prob=254, param2=0},
		{name="vlf_deepslate:deepslate_tiles", prob=254, param2=0},
		{name="vlf_deepslate:deepslate_tiles", prob=254, param2=0},
		{name="vlf_deepslate:deepslate_bricks", prob=254, param2=0},
		{name="air", prob=254, param2=0},
		{name="air", prob=254, param2=0},
		{name="air", prob=254, param2=0},
		{name="vlf_deepslate:deepslate_bricks", prob=254, param2=0},
		{name="air", prob=254, param2=0},
		{name="air", prob=254, param2=0},
		{name="air", prob=254, param2=0},
		{name="vlf_deepslate:deepslate_bricks", prob=254, param2=0},
		{name="air", prob=254, param2=0},
		{name="air", prob=254, param2=0},
		{name="air", prob=254, param2=0},
		{name="vlf_deepslate:deepslate_bricks", prob=254, param2=0},
		{name="vlf_deepslate:deepslate_tiles", prob=254, param2=0},
		{name="vlf_deepslate:deepslate_tiles", prob=254, param2=0},
		{name="vlf_deepslate:deepslate_tiles", prob=254, param2=0},
		{name="vlf_deepslate:deepslate_bricks", prob=254, param2=0},
		{name="air", prob=254, param2=0},
		{name="air", prob=254, param2=0},
		{name="air", prob=254, param2=0},
		{name="vlf_deepslate:deepslate_bricks", prob=254, param2=0},
		{name="air", prob=254, param2=0},
		{name="air", prob=254, param2=0},
		{name="air", prob=254, param2=0},
		{name="vlf_deepslate:deepslate_bricks", prob=254, param2=0},
		{name="air", prob=254, param2=0},
		{name="air", prob=254, param2=0},
		{name="air", prob=254, param2=0},
		{name="vlf_deepslate:deepslate_bricks", prob=254, param2=0},
		{name="vlf_deepslate:deepslate_tiles", prob=254, param2=0},
		{name="air", prob=254, param2=0},
		{name="vlf_deepslate:deepslate_tiles", prob=254, param2=0},
		{name="vlf_deepslate:deepslate_bricks", prob=254, param2=0},
		{name="air", prob=254, param2=0},
		{name="air", prob=254, param2=0},
		{name="air", prob=254, param2=0},
		{name="vlf_deepslate:deepslate_bricks", prob=254, param2=0},
		{name="air", prob=254, param2=0},
		{name="air", prob=254, param2=0},
		{name="air", prob=254, param2=0},
		{name="vlf_deepslate:deepslate_bricks", prob=254, param2=0},
		{name="air", prob=254, param2=0},
		{name="air", prob=254, param2=0},
		{name="air", prob=254, param2=0},
		{name="vlf_deepslate:deepslate_bricks", prob=254, param2=0},
		{name="vlf_deepslate:deepslate_tiles", prob=254, param2=0},
		{name="air", prob=254, param2=0},
		{name="vlf_deepslate:deepslate_tiles", prob=254, param2=0},
		{name="vlf_deepslate:deepslate_bricks", prob=254, param2=0},
		{name="air", prob=254, param2=0},
		{name="air", prob=254, param2=0},
		{name="air", prob=254, param2=0},
		{name="vlf_deepslate:deepslate_bricks", prob=254, param2=0},
		{name="air", prob=254, param2=0},
		{name="air", prob=254, param2=0},
		{name="air", prob=254, param2=0},
		{name="vlf_deepslate:deepslate_bricks", prob=254, param2=0},
		{name="air", prob=254, param2=0},
		{name="air", prob=254, param2=0},
		{name="air", prob=254, param2=0},
		{name="vlf_deepslate:deepslate_bricks", prob=254, param2=0},
		{name="vlf_deepslate:deepslate_tiles", prob=254, param2=0},
		{name="air", prob=254, param2=0},
		{name="vlf_deepslate:deepslate_tiles", prob=254, param2=0},
		{name="vlf_deepslate:deepslate_bricks", prob=254, param2=0},
		{name="air", prob=254, param2=0},
		{name="air", prob=254, param2=0},
		{name="air", prob=254, param2=0},
		{name="vlf_deepslate:deepslate_bricks", prob=254, param2=0},
		{name="air", prob=254, param2=0},
		{name="air", prob=254, param2=0},
		{name="air", prob=254, param2=0},
		{name="vlf_deepslate:deepslate_bricks", prob=254, param2=0},
		{name="air", prob=254, param2=0},
		{name="air", prob=254, param2=0},
		{name="air", prob=254, param2=0},
		{name="vlf_deepslate:deepslate_bricks", prob=254, param2=0},
		{name="vlf_deepslate:deepslate_tiles", prob=254, param2=0},
		{name="air", prob=254, param2=0},
		{name="vlf_deepslate:deepslate_tiles", prob=254, param2=0},
		{name="vlf_deepslate:deepslate_bricks", prob=254, param2=0},
		{name="vlf_deepslate:deepslate_bricks", prob=254, param2=0},
		{name="vlf_deepslate:deepslate_bricks", prob=254, param2=0},
		{name="vlf_deepslate:deepslate_bricks", prob=254, param2=0},
		{name="vlf_deepslate:deepslate_bricks", prob=254, param2=0},
		{name="vlf_deepslate:deepslate_bricks", prob=254, param2=0},
		{name="vlf_deepslate:deepslate_bricks", prob=254, param2=0},
		{name="vlf_deepslate:deepslate_bricks", prob=254, param2=0},
		{name="vlf_deepslate:deepslate_bricks", prob=254, param2=0},
		{name="vlf_deepslate:deepslate_bricks", prob=254, param2=0},
		{name="vlf_deepslate:deepslate_bricks", prob=254, param2=0},
		{name="vlf_deepslate:deepslate_bricks", prob=254, param2=0},
		{name="vlf_deepslate:deepslate_bricks", prob=254, param2=0},
		{name="vlf_deepslate:deepslate_tiles_cracked", prob=254, param2=0},
		{name="air", prob=254, param2=0},
		{name="vlf_stairs:stair_deepslate_tiles", prob=254, param2=1},
		{name="vlf_deepslate:deepslate_tiles_cracked", prob=254, param2=0},
		{name="vlf_deepslate:deepslate_tiles_cracked", prob=254, param2=0},
		{name="air", prob=254, param2=0},
		{name="air", prob=254, param2=0},
		{name="vlf_deepslate:deepslate_bricks", prob=254, param2=0},
		{name="air", prob=254, param2=0},
		{name="air", prob=254, param2=0},
		{name="air", prob=254, param2=0},
		{name="vlf_deepslate:deepslate_bricks", prob=254, param2=0},
		{name="air", prob=254, param2=0},
		{name="air", prob=254, param2=0},
		{name="vlf_deepslate:deepslate_tiles_cracked", prob=254, param2=0},
		{name="vlf_deepslate:deepslate_tiles_cracked", prob=254, param2=0},
		{name="vlf_stairs:stair_deepslate_tiles", prob=254, param2=3},
		{name="air", prob=254, param2=0},
		{name="air", prob=254, param2=0},
		{name="vlf_stairs:stair_deepslate_tiles", prob=254, param2=1},
		{name="vlf_deepslate:deepslate_tiles_cracked", prob=254, param2=0},
		{name="vlf_deepslate:deepslate_tiles_cracked", prob=254, param2=0},
		{name="air", prob=254, param2=0},
		{name="vlf_deepslate:deepslate_bricks", prob=254, param2=0},
		{name="air", prob=254, param2=0},
		{name="air", prob=254, param2=0},
		{name="air", prob=254, param2=0},
		{name="vlf_deepslate:deepslate_bricks", prob=254, param2=0},
		{name="air", prob=254, param2=0},
		{name="vlf_deepslate:deepslate_tiles_cracked", prob=254, param2=0},
		{name="vlf_deepslate:deepslate_tiles_cracked", prob=254, param2=0},
		{name="vlf_stairs:stair_deepslate_tiles", prob=254, param2=3},
		{name="air", prob=254, param2=0},
		{name="air", prob=254, param2=0},
		{name="air", prob=254, param2=0},
		{name="air", prob=254, param2=0},
		{name="vlf_stairs:stair_deepslate_tiles", prob=254, param2=1},
		{name="vlf_deepslate:deepslate_tiles_cracked", prob=254, param2=0},
		{name="vlf_deepslate:deepslate_tiles_cracked", prob=254, param2=0},
		{name="vlf_deepslate:deepslate_bricks", prob=254, param2=0},
		{name="air", prob=254, param2=0},
		{name="air", prob=254, param2=0},
		{name="air", prob=254, param2=0},
		{name="vlf_deepslate:deepslate_bricks", prob=254, param2=0},
		{name="vlf_deepslate:deepslate_tiles_cracked", prob=254, param2=0},
		{name="vlf_deepslate:deepslate_tiles_cracked", prob=254, param2=0},
		{name="vlf_stairs:stair_deepslate_tiles", prob=254, param2=3},
		{name="air", prob=254, param2=0},
		{name="air", prob=254, param2=0},
		{name="air", prob=254, param2=0},
		{name="air", prob=254, param2=0},
		{name="air", prob=254, param2=0},
		{name="air", prob=254, param2=0},
		{name="vlf_stairs:stair_deepslate_tiles", prob=254, param2=1},
		{name="vlf_deepslate:deepslate_tiles_cracked", prob=254, param2=0},
		{name="vlf_deepslate:deepslate_tiles_cracked", prob=254, param2=0},
		{name="air", prob=254, param2=0},
		{name="air", prob=254, param2=0},
		{name="air", prob=254, param2=0},
		{name="vlf_deepslate:deepslate_tiles_cracked", prob=254, param2=0},
		{name="vlf_deepslate:deepslate_tiles_cracked", prob=254, param2=0},
		{name="vlf_stairs:stair_deepslate_tiles", prob=254, param2=3},
		{name="air", prob=254, param2=0},
		{name="air", prob=254, param2=0},
		{name="air", prob=254, param2=0},
		{name="air", prob=254, param2=0},
		{name="air", prob=254, param2=0},
		{name="air", prob=254, param2=0},
		{name="air", prob=254, param2=0},
		{name="air", prob=254, param2=0},
		{name="vlf_stairs:stair_deepslate_tiles", prob=254, param2=1},
		{name="vlf_deepslate:deepslate_tiles_cracked", prob=254, param2=0},
		{name="vlf_deepslate:deepslate_tiles_cracked", prob=254, param2=0},
		{name="air", prob=254, param2=0},
		{name="vlf_deepslate:deepslate_tiles_cracked", prob=254, param2=0},
		{name="vlf_deepslate:deepslate_tiles_cracked", prob=254, param2=0},
		{name="vlf_stairs:stair_deepslate_tiles", prob=254, param2=3},
		{name="air", prob=254, param2=0},
		{name="air", prob=254, param2=0},
		{name="air", prob=254, param2=0},
		{name="air", prob=254, param2=0},
		{name="air", prob=254, param2=0},
		{name="air", prob=254, param2=0},
		{name="air", prob=254, param2=0},
		{name="air", prob=254, param2=0},
		{name="air", prob=254, param2=0},
		{name="air", prob=254, param2=0},
		{name="vlf_stairs:stair_deepslate_tiles", prob=254, param2=1},
		{name="vlf_deepslate:deepslate_tiles_cracked", prob=254, param2=0},
		{name="vlf_deepslate:deepslate_tiles_cracked", prob=254, param2=0},
		{name="vlf_deepslate:deepslate_tiles_cracked", prob=254, param2=0},
		{name="vlf_stairs:stair_deepslate_tiles", prob=254, param2=3},
		{name="air", prob=254, param2=0},
		{name="air", prob=254, param2=0},
		{name="air", prob=254, param2=0},
		{name="air", prob=254, param2=0},
		{name="air", prob=254, param2=0},
		{name="air", prob=254, param2=0},
		{name="air", prob=254, param2=0},
		{name="air", prob=254, param2=0},
		{name="air", prob=254, param2=0},
		{name="air", prob=254, param2=0},
		{name="air", prob=254, param2=0},
		{name="air", prob=254, param2=0},
		{name="vlf_stairs:stair_deepslate_tiles", prob=254, param2=1},
		{name="vlf_deepslate:deepslate_tiles_cracked", prob=254, param2=0},
		{name="vlf_stairs:stair_deepslate_tiles", prob=254, param2=3},
		{name="air", prob=254, param2=0},
		{name="air", prob=254, param2=0},
		{name="air", prob=254, param2=0},
		{name="air", prob=254, param2=0},
		{name="air", prob=254, param2=0},
		{name="air", prob=254, param2=0},
		{name="air", prob=254, param2=0},
		{name="air", prob=254, param2=0},
		{name="air", prob=254, param2=0},
		{name="air", prob=254, param2=0},
		{name="air", prob=254, param2=0},
		{name="air", prob=254, param2=0},
		{name="air", prob=254, param2=0},
		{name="air", prob=254, param2=0},
		{name="air", prob=254, param2=0},
		{name="air", prob=254, param2=0},
		{name="air", prob=254, param2=0},
		{name="air", prob=254, param2=0},
		{name="air", prob=254, param2=0},
		{name="air", prob=254, param2=0},
		{name="air", prob=254, param2=0},
		{name="air", prob=254, param2=0},
		{name="vlf_deepslate:deepslate_tiles", prob=254, param2=0},
		{name="vlf_deepslate:deepslate_tiles", prob=254, param2=0},
		{name="air", prob=254, param2=0},
		{name="air", prob=254, param2=0},
		{name="air", prob=254, param2=0},
		{name="air", prob=254, param2=0},
		{name="air", prob=254, param2=0},
		{name="vlf_wool:silver_carpet", prob=254, param2=0},
		{name="air", prob=254, param2=0},
		{name="vlf_wool:silver_carpet", prob=254, param2=0},
		{name="air", prob=254, param2=0},
		{name="air", prob=254, param2=0},
		{name="vlf_deepslate:deepslate_tiles_cracked", prob=254, param2=0},
		{name="vlf_deepslate:deepslate_tiles_cracked", prob=254, param2=0},
		{name="vlf_deepslate:deepslate_tiles_cracked", prob=254, param2=0},
		{name="vlf_deepslate:deepslate", prob=254, param2=0},
		{name="vlf_deepslate:deepslate_tiles", prob=254, param2=0},
		{name="vlf_deepslate:deepslate_tiles", prob=254, param2=0},
		{name="air", prob=254, param2=0},
		{name="air", prob=254, param2=0},
		{name="air", prob=254, param2=0},
		{name="air", prob=254, param2=0},
		{name="air", prob=254, param2=0},
		{name="air", prob=254, param2=0},
		{name="air", prob=254, param2=0},
		{name="air", prob=254, param2=0},
		{name="air", prob=254, param2=0},
		{name="air", prob=254, param2=0},
		{name="air", prob=254, param2=0},
		{name="air", prob=254, param2=0},
		{name="air", prob=254, param2=0},
		{name="vlf_deepslate:deepslate_tiles", prob=254, param2=0},
		{name="vlf_deepslate:deepslate_tiles", prob=254, param2=0},
		{name="vlf_deepslate:deepslate_tiles", prob=254, param2=0},
		{name="air", prob=254, param2=0},
		{name="air", prob=254, param2=0},
		{name="air", prob=254, param2=0},
		{name="air", prob=254, param2=0},
		{name="air", prob=254, param2=0},
		{name="air", prob=254, param2=0},
		{name="air", prob=254, param2=0},
		{name="air", prob=254, param2=0},
		{name="air", prob=254, param2=0},
		{name="air", prob=254, param2=0},
		{name="air", prob=254, param2=0},
		{name="air", prob=254, param2=0},
		{name="air", prob=254, param2=0},
		{name="vlf_deepslate:deepslate_tiles", prob=254, param2=0},
		{name="air", prob=254, param2=0},
		{name="vlf_deepslate:deepslate_tiles", prob=254, param2=0},
		{name="air", prob=254, param2=0},
		{name="air", prob=254, param2=0},
		{name="air", prob=254, param2=0},
		{name="air", prob=254, param2=0},
		{name="air", prob=254, param2=0},
		{name="air", prob=254, param2=0},
		{name="air", prob=254, param2=0},
		{name="air", prob=254, param2=0},
		{name="air", prob=254, param2=0},
		{name="air", prob=254, param2=0},
		{name="air", prob=254, param2=0},
		{name="air", prob=254, param2=0},
		{name="air", prob=254, param2=0},
		{name="vlf_deepslate:deepslate_tiles_cracked", prob=254, param2=0},
		{name="air", prob=254, param2=0},
		{name="vlf_deepslate:deepslate_tiles", prob=254, param2=0},
		{name="air", prob=254, param2=0},
		{name="air", prob=254, param2=0},
		{name="air", prob=254, param2=0},
		{name="air", prob=254, param2=0},
		{name="air", prob=254, param2=0},
		{name="air", prob=254, param2=0},
		{name="air", prob=254, param2=0},
		{name="air", prob=254, param2=0},
		{name="air", prob=254, param2=0},
		{name="air", prob=254, param2=0},
		{name="air", prob=254, param2=0},
		{name="air", prob=254, param2=0},
		{name="air", prob=254, param2=0},
		{name="vlf_deepslate:deepslate_tiles_cracked", prob=254, param2=0},
		{name="air", prob=254, param2=0},
		{name="vlf_deepslate:deepslate_tiles", prob=254, param2=0},
		{name="air", prob=254, param2=0},
		{name="air", prob=254, param2=0},
		{name="air", prob=254, param2=0},
		{name="air", prob=254, param2=0},
		{name="air", prob=254, param2=0},
		{name="air", prob=254, param2=0},
		{name="air", prob=254, param2=0},
		{name="air", prob=254, param2=0},
		{name="air", prob=254, param2=0},
		{name="air", prob=254, param2=0},
		{name="air", prob=254, param2=0},
		{name="air", prob=254, param2=0},
		{name="air", prob=254, param2=0},
		{name="vlf_deepslate:deepslate_tiles", prob=254, param2=0},
		{name="air", prob=254, param2=0},
		{name="vlf_deepslate:deepslate_tiles", prob=254, param2=0},
		{name="air", prob=254, param2=0},
		{name="air", prob=254, param2=0},
		{name="air", prob=254, param2=0},
		{name="air", prob=254, param2=0},
		{name="air", prob=254, param2=0},
		{name="air", prob=254, param2=0},
		{name="air", prob=254, param2=0},
		{name="air", prob=254, param2=0},
		{name="air", prob=254, param2=0},
		{name="air", prob=254, param2=0},
		{name="air", prob=254, param2=0},
		{name="air", prob=254, param2=0},
		{name="air", prob=254, param2=0},
		{name="vlf_deepslate:deepslate_tiles", prob=254, param2=0},
		{name="air", prob=254, param2=0},
		{name="vlf_deepslate:deepslate_tiles", prob=254, param2=0},
		{name="air", prob=254, param2=0},
		{name="air", prob=254, param2=0},
		{name="air", prob=254, param2=0},
		{name="air", prob=254, param2=0},
		{name="air", prob=254, param2=0},
		{name="air", prob=254, param2=0},
		{name="air", prob=254, param2=0},
		{name="air", prob=254, param2=0},
		{name="air", prob=254, param2=0},
		{name="air", prob=254, param2=0},
		{name="air", prob=254, param2=0},
		{name="air", prob=254, param2=0},
		{name="air", prob=254, param2=0},
		{name="vlf_deepslate:deepslate_tiles_cracked", prob=254, param2=0},
		{name="air", prob=254, param2=0},
		{name="air", prob=254, param2=0},
		{name="vlf_deepslate:deepslate_cobbled", prob=254, param2=0},
		{name="air", prob=254, param2=0},
		{name="air", prob=254, param2=0},
		{name="air", prob=254, param2=0},
		{name="air", prob=254, param2=0},
		{name="air", prob=254, param2=0},
		{name="air", prob=254, param2=0},
		{name="air", prob=254, param2=0},
		{name="air", prob=254, param2=0},
		{name="air", prob=254, param2=0},
		{name="air", prob=254, param2=0},
		{name="air", prob=254, param2=0},
		{name="vlf_deepslate:deepslate_cobbled", prob=254, param2=0},
		{name="air", prob=254, param2=0},
		{name="air", prob=254, param2=0},
		{name="air", prob=254, param2=0},
		{name="air", prob=254, param2=0},
		{name="vlf_deepslate:deepslate_cobbled", prob=254, param2=0},
		{name="air", prob=254, param2=0},
		{name="air", prob=254, param2=0},
		{name="air", prob=254, param2=0},
		{name="air", prob=254, param2=0},
		{name="air", prob=254, param2=0},
		{name="air", prob=254, param2=0},
		{name="air", prob=254, param2=0},
		{name="air", prob=254, param2=0},
		{name="air", prob=254, param2=0},
		{name="vlf_deepslate:deepslate_cobbled", prob=254, param2=0},
		{name="air", prob=254, param2=0},
		{name="air", prob=254, param2=0},
		{name="air", prob=254, param2=0},
		{name="air", prob=254, param2=0},
		{name="air", prob=254, param2=0},
		{name="air", prob=254, param2=0},
		{name="vlf_deepslate:deepslate_cobbled", prob=254, param2=0},
		{name="air", prob=254, param2=0},
		{name="air", prob=254, param2=0},
		{name="air", prob=254, param2=0},
		{name="air", prob=254, param2=0},
		{name="air", prob=254, param2=0},
		{name="air", prob=254, param2=0},
		{name="air", prob=254, param2=0},
		{name="vlf_deepslate:deepslate_cobbled", prob=254, param2=0},
		{name="air", prob=254, param2=0},
		{name="air", prob=254, param2=0},
		{name="air", prob=254, param2=0},
		{name="air", prob=254, param2=0},
		{name="air", prob=254, param2=0},
		{name="air", prob=254, param2=0},
		{name="air", prob=254, param2=0},
		{name="air", prob=254, param2=0},
		{name="vlf_deepslate:deepslate_cobbled", prob=254, param2=0},
		{name="air", prob=254, param2=0},
		{name="air", prob=254, param2=0},
		{name="air", prob=254, param2=0},
		{name="air", prob=254, param2=0},
		{name="air", prob=254, param2=0},
		{name="vlf_deepslate:deepslate_cobbled", prob=254, param2=0},
		{name="air", prob=254, param2=0},
		{name="air", prob=254, param2=0},
		{name="air", prob=254, param2=0},
		{name="air", prob=254, param2=0},
		{name="air", prob=254, param2=0},
		{name="air", prob=254, param2=0},
		{name="air", prob=254, param2=0},
		{name="air", prob=254, param2=0},
		{name="air", prob=254, param2=0},
		{name="air", prob=254, param2=0},
		{name="vlf_deepslate:deepslate_cobbled", prob=254, param2=0},
		{name="air", prob=254, param2=0},
		{name="air", prob=254, param2=0},
		{name="air", prob=254, param2=0},
		{name="vlf_deepslate:deepslate_cobbled", prob=254, param2=0},
		{name="air", prob=254, param2=0},
		{name="air", prob=254, param2=0},
		{name="air", prob=254, param2=0},
		{name="air", prob=254, param2=0},
		{name="air", prob=254, param2=0},
		{name="air", prob=254, param2=0},
		{name="air", prob=254, param2=0},
		{name="air", prob=254, param2=0},
		{name="air", prob=254, param2=0},
		{name="air", prob=254, param2=0},
		{name="air", prob=254, param2=0},
		{name="air", prob=254, param2=0},
		{name="vlf_deepslate:deepslate_cobbled", prob=254, param2=0},
		{name="air", prob=254, param2=0},
		{name="vlf_deepslate:deepslate_cobbled", prob=254, param2=0},
		{name="air", prob=254, param2=0},
		{name="air", prob=254, param2=0},
		{name="air", prob=254, param2=0},
		{name="air", prob=254, param2=0},
		{name="air", prob=254, param2=0},
		{name="air", prob=254, param2=0},
		{name="air", prob=254, param2=0},
		{name="air", prob=254, param2=0},
		{name="air", prob=254, param2=0},
		{name="air", prob=254, param2=0},
		{name="air", prob=254, param2=0},
		{name="air", prob=254, param2=0},
		{name="air", prob=254, param2=0},
		{name="air", prob=254, param2=0},
		{name="vlf_deepslate:deepslate_tiles_cracked", prob=254, param2=0},
		{name="air", prob=254, param2=0},
		{name="air", prob=254, param2=0},
		{name="air", prob=254, param2=0},
		{name="air", prob=254, param2=0},
		{name="air", prob=254, param2=0},
		{name="air", prob=254, param2=0},
		{name="air", prob=254, param2=0},
		{name="air", prob=254, param2=0},
		{name="air", prob=254, param2=0},
		{name="air", prob=254, param2=0},
		{name="air", prob=254, param2=0},
		{name="air", prob=254, param2=0},
		{name="air", prob=254, param2=0},
		{name="air", prob=254, param2=0},
		{name="air", prob=254, param2=0},
		{name="air", prob=254, param2=0},
		{name="air", prob=254, param2=0},
		{name="air", prob=254, param2=0},
		{name="air", prob=254, param2=0},
		{name="air", prob=254, param2=0},
		{name="air", prob=254, param2=0},
		{name="air", prob=254, param2=0},
		{name="air", prob=254, param2=0},
		{name="vlf_deepslate:deepslate_tiles", prob=254, param2=0},
		{name="vlf_deepslate:deepslate_tiles", prob=254, param2=0},
		{name="air", prob=254, param2=0},
		{name="air", prob=254, param2=0},
		{name="air", prob=254, param2=0},
		{name="air", prob=254, param2=0},
		{name="air", prob=254, param2=0},
		{name="air", prob=254, param2=0},
		{name="air", prob=254, param2=0},
		{name="air", prob=254, param2=0},
		{name="air", prob=254, param2=0},
		{name="vlf_chests:chest_small", prob=254, param2=1},
		{name="vlf_deepslate:deepslate_tiles_cracked", prob=254, param2=0},
		{name="vlf_deepslate:deepslate_tiles_cracked", prob=254, param2=0},
		{name="vlf_deepslate:deepslate_tiles_cracked", prob=254, param2=0},
		{name="vlf_deepslate:deepslate_tiles_cracked", prob=254, param2=0},
		{name="vlf_deepslate:deepslate_tiles", prob=254, param2=0},
		{name="vlf_deepslate:deepslate_tiles", prob=254, param2=0},
		{name="air", prob=254, param2=0},
		{name="air", prob=254, param2=0},
		{name="air", prob=254, param2=0},
		{name="air", prob=254, param2=0},
		{name="air", prob=254, param2=0},
		{name="air", prob=254, param2=0},
		{name="air", prob=254, param2=0},
		{name="air", prob=254, param2=0},
		{name="air", prob=254, param2=0},
		{name="air", prob=254, param2=0},
		{name="air", prob=254, param2=0},
		{name="air", prob=254, param2=0},
		{name="air", prob=254, param2=0},
		{name="vlf_deepslate:deepslate_tiles", prob=254, param2=0},
		{name="vlf_deepslate:deepslate_tiles", prob=254, param2=0},
		{name="vlf_deepslate:deepslate_tiles", prob=254, param2=0},
		{name="air", prob=254, param2=0},
		{name="air", prob=254, param2=0},
		{name="air", prob=254, param2=0},
		{name="air", prob=254, param2=0},
		{name="air", prob=254, param2=0},
		{name="air", prob=254, param2=0},
		{name="air", prob=254, param2=0},
		{name="air", prob=254, param2=0},
		{name="air", prob=254, param2=0},
		{name="air", prob=254, param2=0},
		{name="air", prob=254, param2=0},
		{name="air", prob=254, param2=0},
		{name="air", prob=254, param2=0},
		{name="vlf_deepslate:deepslate_tiles", prob=254, param2=0},
		{name="air", prob=254, param2=0},
		{name="vlf_deepslate:deepslate_tiles", prob=254, param2=0},
		{name="air", prob=254, param2=0},
		{name="air", prob=254, param2=0},
		{name="air", prob=254, param2=0},
		{name="air", prob=254, param2=0},
		{name="air", prob=254, param2=0},
		{name="air", prob=254, param2=0},
		{name="air", prob=254, param2=0},
		{name="air", prob=254, param2=0},
		{name="air", prob=254, param2=0},
		{name="air", prob=254, param2=0},
		{name="air", prob=254, param2=0},
		{name="air", prob=254, param2=0},
		{name="air", prob=254, param2=0},
		{name="vlf_deepslate:deepslate_tiles_cracked", prob=254, param2=0},
		{name="air", prob=254, param2=0},
		{name="vlf_deepslate:deepslate_tiles", prob=254, param2=0},
		{name="air", prob=254, param2=0},
		{name="air", prob=254, param2=0},
		{name="air", prob=254, param2=0},
		{name="air", prob=254, param2=0},
		{name="air", prob=254, param2=0},
		{name="air", prob=254, param2=0},
		{name="air", prob=254, param2=0},
		{name="air", prob=254, param2=0},
		{name="air", prob=254, param2=0},
		{name="air", prob=254, param2=0},
		{name="air", prob=254, param2=0},
		{name="air", prob=254, param2=0},
		{name="air", prob=254, param2=0},
		{name="vlf_deepslate:deepslate_tiles_cracked", prob=254, param2=0},
		{name="air", prob=254, param2=0},
		{name="vlf_deepslate:deepslate_tiles", prob=254, param2=0},
		{name="air", prob=254, param2=0},
		{name="air", prob=254, param2=0},
		{name="air", prob=254, param2=0},
		{name="air", prob=254, param2=0},
		{name="air", prob=254, param2=0},
		{name="air", prob=254, param2=0},
		{name="air", prob=254, param2=0},
		{name="air", prob=254, param2=0},
		{name="air", prob=254, param2=0},
		{name="air", prob=254, param2=0},
		{name="air", prob=254, param2=0},
		{name="air", prob=254, param2=0},
		{name="air", prob=254, param2=0},
		{name="vlf_deepslate:deepslate_tiles_cracked", prob=254, param2=0},
		{name="air", prob=254, param2=0},
		{name="vlf_deepslate:deepslate_tiles", prob=254, param2=0},
		{name="air", prob=254, param2=0},
		{name="air", prob=254, param2=0},
		{name="air", prob=254, param2=0},
		{name="air", prob=254, param2=0},
		{name="air", prob=254, param2=0},
		{name="air", prob=254, param2=0},
		{name="air", prob=254, param2=0},
		{name="air", prob=254, param2=0},
		{name="air", prob=254, param2=0},
		{name="air", prob=254, param2=0},
		{name="air", prob=254, param2=0},
		{name="air", prob=254, param2=0},
		{name="air", prob=254, param2=0},
		{name="vlf_deepslate:deepslate_tiles", prob=254, param2=0},
		{name="air", prob=254, param2=0},
		{name="vlf_deepslate:deepslate_tiles", prob=254, param2=0},
		{name="air", prob=254, param2=0},
		{name="air", prob=254, param2=0},
		{name="air", prob=254, param2=0},
		{name="air", prob=254, param2=0},
		{name="air", prob=254, param2=0},
		{name="air", prob=254, param2=0},
		{name="air", prob=254, param2=0},
		{name="air", prob=254, param2=0},
		{name="air", prob=254, param2=0},
		{name="air", prob=254, param2=0},
		{name="air", prob=254, param2=0},
		{name="air", prob=254, param2=0},
		{name="air", prob=254, param2=0},
		{name="vlf_deepslate:deepslate_tiles_cracked", prob=254, param2=0},
		{name="air", prob=254, param2=0},
		{name="air", prob=254, param2=0},
		{name="vlf_deepslate:deepslate_cobbled", prob=254, param2=0},
		{name="air", prob=254, param2=0},
		{name="air", prob=254, param2=0},
		{name="air", prob=254, param2=0},
		{name="air", prob=254, param2=0},
		{name="air", prob=254, param2=0},
		{name="air", prob=254, param2=0},
		{name="air", prob=254, param2=0},
		{name="air", prob=254, param2=0},
		{name="air", prob=254, param2=0},
		{name="air", prob=254, param2=0},
		{name="air", prob=254, param2=0},
		{name="vlf_deepslate:deepslate_cobbled", prob=254, param2=0},
		{name="air", prob=254, param2=0},
		{name="air", prob=254, param2=0},
		{name="air", prob=254, param2=0},
		{name="air", prob=254, param2=0},
		{name="vlf_deepslate:deepslate_cobbled", prob=254, param2=0},
		{name="air", prob=254, param2=0},
		{name="air", prob=254, param2=0},
		{name="air", prob=254, param2=0},
		{name="air", prob=254, param2=0},
		{name="air", prob=254, param2=0},
		{name="air", prob=254, param2=0},
		{name="air", prob=254, param2=0},
		{name="air", prob=254, param2=0},
		{name="air", prob=254, param2=0},
		{name="vlf_deepslate:deepslate_cobbled", prob=254, param2=0},
		{name="air", prob=254, param2=0},
		{name="air", prob=254, param2=0},
		{name="air", prob=254, param2=0},
		{name="air", prob=254, param2=0},
		{name="air", prob=254, param2=0},
		{name="air", prob=254, param2=0},
		{name="vlf_deepslate:deepslate_cobbled", prob=254, param2=0},
		{name="air", prob=254, param2=0},
		{name="air", prob=254, param2=0},
		{name="air", prob=254, param2=0},
		{name="air", prob=254, param2=0},
		{name="air", prob=254, param2=0},
		{name="air", prob=254, param2=0},
		{name="air", prob=254, param2=0},
		{name="vlf_deepslate:deepslate_cobbled", prob=254, param2=0},
		{name="air", prob=254, param2=0},
		{name="air", prob=254, param2=0},
		{name="air", prob=254, param2=0},
		{name="air", prob=254, param2=0},
		{name="air", prob=254, param2=0},
		{name="air", prob=254, param2=0},
		{name="air", prob=254, param2=0},
		{name="air", prob=254, param2=0},
		{name="vlf_deepslate:deepslate_cobbled", prob=254, param2=0},
		{name="air", prob=254, param2=0},
		{name="air", prob=254, param2=0},
		{name="air", prob=254, param2=0},
		{name="air", prob=254, param2=0},
		{name="air", prob=254, param2=0},
		{name="vlf_deepslate:deepslate_cobbled", prob=254, param2=0},
		{name="air", prob=254, param2=0},
		{name="air", prob=254, param2=0},
		{name="air", prob=254, param2=0},
		{name="air", prob=254, param2=0},
		{name="air", prob=254, param2=0},
		{name="air", prob=254, param2=0},
		{name="air", prob=254, param2=0},
		{name="air", prob=254, param2=0},
		{name="air", prob=254, param2=0},
		{name="air", prob=254, param2=0},
		{name="vlf_deepslate:deepslate_cobbled", prob=254, param2=0},
		{name="air", prob=254, param2=0},
		{name="air", prob=254, param2=0},
		{name="air", prob=254, param2=0},
		{name="vlf_deepslate:deepslate_cobbled", prob=254, param2=0},
		{name="air", prob=254, param2=0},
		{name="air", prob=254, param2=0},
		{name="air", prob=254, param2=0},
		{name="air", prob=254, param2=0},
		{name="air", prob=254, param2=0},
		{name="air", prob=254, param2=0},
		{name="air", prob=254, param2=0},
		{name="air", prob=254, param2=0},
		{name="air", prob=254, param2=0},
		{name="air", prob=254, param2=0},
		{name="air", prob=254, param2=0},
		{name="air", prob=254, param2=0},
		{name="vlf_deepslate:deepslate_cobbled", prob=254, param2=0},
		{name="air", prob=254, param2=0},
		{name="vlf_deepslate:deepslate_cobbled", prob=254, param2=0},
		{name="air", prob=254, param2=0},
		{name="air", prob=254, param2=0},
		{name="air", prob=254, param2=0},
		{name="air", prob=254, param2=0},
		{name="air", prob=254, param2=0},
		{name="air", prob=254, param2=0},
		{name="air", prob=254, param2=0},
		{name="air", prob=254, param2=0},
		{name="air", prob=254, param2=0},
		{name="air", prob=254, param2=0},
		{name="air", prob=254, param2=0},
		{name="air", prob=254, param2=0},
		{name="air", prob=254, param2=0},
		{name="air", prob=254, param2=0},
		{name="vlf_deepslate:deepslate_tiles_cracked", prob=254, param2=0},
		{name="air", prob=254, param2=0},
		{name="air", prob=254, param2=0},
		{name="air", prob=254, param2=0},
		{name="air", prob=254, param2=0},
		{name="air", prob=254, param2=0},
		{name="air", prob=254, param2=0},
		{name="air", prob=254, param2=0},
		{name="air", prob=254, param2=0},
		{name="air", prob=254, param2=0},
		{name="air", prob=254, param2=0},
		{name="air", prob=254, param2=0},
		{name="air", prob=254, param2=0},
		{name="air", prob=254, param2=0},
		{name="air", prob=254, param2=0},
		{name="air", prob=254, param2=0},
		{name="air", prob=254, param2=0},
		{name="air", prob=254, param2=0},
		{name="air", prob=254, param2=0},
		{name="air", prob=254, param2=0},
		{name="air", prob=254, param2=0},
		{name="air", prob=254, param2=0},
		{name="air", prob=254, param2=0},
		{name="air", prob=254, param2=0},
		{name="vlf_deepslate:deepslate_tiles", prob=254, param2=0},
		{name="vlf_deepslate:deepslate_tiles", prob=254, param2=0},
		{name="vlf_deepslate:deepslate_polished", prob=254, param2=0},
		{name="vlf_deepslate:deepslate_polished", prob=254, param2=0},
		{name="vlf_deepslate:deepslate_polished", prob=254, param2=0},
		{name="vlf_deepslate:deepslate_polished", prob=254, param2=0},
		{name="vlf_deepslate:deepslate_polished", prob=254, param2=0},
		{name="vlf_deepslate:deepslate_polished", prob=254, param2=0},
		{name="vlf_deepslate:deepslate_polished", prob=254, param2=0},
		{name="vlf_deepslate:deepslate_polished", prob=254, param2=0},
		{name="vlf_deepslate:deepslate_polished", prob=254, param2=0},
		{name="vlf_deepslate:deepslate_polished", prob=254, param2=0},
		{name="vlf_deepslate:deepslate_chiseled", prob=254, param2=0},
		{name="vlf_deepslate:deepslate_tiles_cracked", prob=254, param2=0},
		{name="vlf_deepslate:deepslate_tiles_cracked", prob=254, param2=0},
		{name="vlf_deepslate:deepslate_tiles_cracked", prob=254, param2=0},
		{name="vlf_deepslate:deepslate_tiles", prob=254, param2=0},
		{name="vlf_deepslate:deepslate_tiles", prob=254, param2=0},
		{name="vlf_deepslate:deepslate_polished", prob=254, param2=0},
		{name="vlf_deepslate:deepslate_chiseled", prob=254, param2=0},
		{name="vlf_deepslate:deepslate_reinforced", prob=254, param2=12},
		{name="vlf_deepslate:deepslate_reinforced", prob=254, param2=12},
		{name="vlf_deepslate:deepslate_reinforced", prob=254, param2=12},
		{name="vlf_deepslate:deepslate_reinforced", prob=254, param2=12},
		{name="vlf_deepslate:deepslate_reinforced", prob=254, param2=12},
		{name="vlf_deepslate:deepslate_reinforced", prob=254, param2=12},
		{name="vlf_deepslate:deepslate_reinforced", prob=254, param2=12},
		{name="vlf_deepslate:deepslate_reinforced", prob=254, param2=12},
		{name="vlf_deepslate:deepslate_chiseled", prob=254, param2=0},
		{name="vlf_deepslate:deepslate_polished", prob=254, param2=0},
		{name="air", prob=254, param2=0},
		{name="vlf_deepslate:deepslate_tiles", prob=254, param2=0},
		{name="vlf_deepslate:deepslate_tiles", prob=254, param2=0},
		{name="vlf_deepslate:deepslate_tiles", prob=254, param2=0},
		{name="vlf_deepslate:deepslate_polished", prob=254, param2=0},
		{name="vlf_deepslate:deepslate_reinforced", prob=254, param2=0},
		{name="air", prob=254, param2=0},
		{name="air", prob=254, param2=0},
		{name="air", prob=254, param2=0},
		{name="air", prob=254, param2=0},
		{name="air", prob=254, param2=0},
		{name="air", prob=254, param2=0},
		{name="air", prob=254, param2=0},
		{name="air", prob=254, param2=0},
		{name="vlf_deepslate:deepslate_reinforced", prob=254, param2=0},
		{name="vlf_deepslate:deepslate_polished", prob=254, param2=0},
		{name="air", prob=254, param2=0},
		{name="vlf_deepslate:deepslate_tiles", prob=254, param2=0},
		{name="air", prob=254, param2=0},
		{name="vlf_deepslate:deepslate_tiles", prob=254, param2=0},
		{name="vlf_deepslate:deepslate_polished", prob=254, param2=0},
		{name="vlf_deepslate:deepslate_reinforced", prob=254, param2=0},
		{name="air", prob=254, param2=0},
		{name="air", prob=254, param2=0},
		{name="air", prob=254, param2=0},
		{name="air", prob=254, param2=0},
		{name="air", prob=254, param2=0},
		{name="air", prob=254, param2=0},
		{name="air", prob=254, param2=0},
		{name="air", prob=254, param2=0},
		{name="vlf_deepslate:deepslate_reinforced", prob=254, param2=0},
		{name="vlf_deepslate:deepslate_polished", prob=254, param2=0},
		{name="air", prob=254, param2=0},
		{name="vlf_deepslate:deepslate_tiles", prob=254, param2=0},
		{name="air", prob=254, param2=0},
		{name="vlf_deepslate:deepslate_tiles", prob=254, param2=0},
		{name="vlf_deepslate:deepslate_polished", prob=254, param2=0},
		{name="vlf_deepslate:deepslate_reinforced", prob=254, param2=0},
		{name="air", prob=254, param2=0},
		{name="air", prob=254, param2=0},
		{name="air", prob=254, param2=0},
		{name="air", prob=254, param2=0},
		{name="air", prob=254, param2=0},
		{name="air", prob=254, param2=0},
		{name="air", prob=254, param2=0},
		{name="air", prob=254, param2=0},
		{name="vlf_deepslate:deepslate_reinforced", prob=254, param2=0},
		{name="vlf_deepslate:deepslate_polished", prob=254, param2=0},
		{name="air", prob=254, param2=0},
		{name="vlf_deepslate:deepslate_tiles_cracked", prob=254, param2=0},
		{name="air", prob=254, param2=0},
		{name="vlf_deepslate:deepslate_tiles", prob=254, param2=0},
		{name="vlf_deepslate:deepslate_polished", prob=254, param2=0},
		{name="vlf_deepslate:deepslate_reinforced", prob=254, param2=0},
		{name="air", prob=254, param2=0},
		{name="air", prob=254, param2=0},
		{name="air", prob=254, param2=0},
		{name="air", prob=254, param2=0},
		{name="air", prob=254, param2=0},
		{name="air", prob=254, param2=0},
		{name="air", prob=254, param2=0},
		{name="air", prob=254, param2=0},
		{name="vlf_deepslate:deepslate_reinforced", prob=254, param2=0},
		{name="vlf_deepslate:deepslate_polished", prob=254, param2=0},
		{name="air", prob=254, param2=0},
		{name="vlf_deepslate:deepslate_tiles", prob=254, param2=0},
		{name="air", prob=254, param2=0},
		{name="vlf_deepslate:deepslate_tiles", prob=254, param2=0},
		{name="vlf_deepslate:deepslate_polished", prob=254, param2=0},
		{name="vlf_deepslate:deepslate_reinforced", prob=254, param2=0},
		{name="air", prob=254, param2=0},
		{name="air", prob=254, param2=0},
		{name="air", prob=254, param2=0},
		{name="air", prob=254, param2=0},
		{name="air", prob=254, param2=0},
		{name="air", prob=254, param2=0},
		{name="air", prob=254, param2=0},
		{name="air", prob=254, param2=0},
		{name="vlf_deepslate:deepslate_reinforced", prob=254, param2=0},
		{name="vlf_deepslate:deepslate_polished", prob=254, param2=0},
		{name="air", prob=254, param2=0},
		{name="vlf_deepslate:deepslate_tiles", prob=254, param2=0},
		{name="air", prob=254, param2=0},
		{name="vlf_deepslate:deepslate_tiles", prob=254, param2=0},
		{name="vlf_deepslate:deepslate_polished", prob=254, param2=0},
		{name="vlf_deepslate:deepslate_reinforced", prob=254, param2=0},
		{name="air", prob=254, param2=0},
		{name="air", prob=254, param2=0},
		{name="air", prob=254, param2=0},
		{name="air", prob=254, param2=0},
		{name="air", prob=254, param2=0},
		{name="air", prob=254, param2=0},
		{name="air", prob=254, param2=0},
		{name="air", prob=254, param2=0},
		{name="vlf_deepslate:deepslate_reinforced", prob=254, param2=0},
		{name="vlf_deepslate:deepslate_polished", prob=254, param2=0},
		{name="air", prob=254, param2=0},
		{name="vlf_deepslate:deepslate_tiles_cracked", prob=254, param2=0},
		{name="air", prob=254, param2=0},
		{name="air", prob=254, param2=0},
		{name="vlf_deepslate:deepslate_cobbled", prob=254, param2=0},
		{name="vlf_deepslate:deepslate_chiseled", prob=254, param2=0},
		{name="vlf_deepslate:deepslate_reinforced", prob=254, param2=12},
		{name="vlf_deepslate:deepslate_reinforced", prob=254, param2=12},
		{name="vlf_deepslate:deepslate_reinforced", prob=254, param2=12},
		{name="vlf_deepslate:deepslate_reinforced", prob=254, param2=12},
		{name="vlf_deepslate:deepslate_reinforced", prob=254, param2=12},
		{name="vlf_deepslate:deepslate_reinforced", prob=254, param2=12},
		{name="vlf_deepslate:deepslate_reinforced", prob=254, param2=12},
		{name="vlf_deepslate:deepslate_reinforced", prob=254, param2=12},
		{name="vlf_deepslate:deepslate_chiseled", prob=254, param2=0},
		{name="vlf_deepslate:deepslate_polished", prob=254, param2=0},
		{name="vlf_deepslate:deepslate_cobbled", prob=254, param2=0},
		{name="air", prob=254, param2=0},
		{name="air", prob=254, param2=0},
		{name="air", prob=254, param2=0},
		{name="air", prob=254, param2=0},
		{name="vlf_deepslate:deepslate_cobbled", prob=254, param2=0},
		{name="vlf_deepslate:deepslate_polished", prob=254, param2=0},
		{name="vlf_deepslate:deepslate_polished", prob=254, param2=0},
		{name="vlf_deepslate:deepslate_polished", prob=254, param2=0},
		{name="vlf_deepslate:deepslate_polished", prob=254, param2=0},
		{name="vlf_deepslate:deepslate_polished", prob=254, param2=0},
		{name="vlf_deepslate:deepslate_polished", prob=254, param2=0},
		{name="vlf_deepslate:deepslate_polished", prob=254, param2=0},
		{name="vlf_deepslate:deepslate_polished", prob=254, param2=0},
		{name="vlf_deepslate:deepslate_polished", prob=254, param2=0},
		{name="vlf_deepslate:deepslate_cobbled", prob=254, param2=0},
		{name="air", prob=254, param2=0},
		{name="air", prob=254, param2=0},
		{name="air", prob=254, param2=0},
		{name="air", prob=254, param2=0},
		{name="air", prob=254, param2=0},
		{name="air", prob=254, param2=0},
		{name="vlf_deepslate:deepslate_cobbled", prob=254, param2=0},
		{name="air", prob=254, param2=0},
		{name="air", prob=254, param2=0},
		{name="air", prob=254, param2=0},
		{name="air", prob=254, param2=0},
		{name="air", prob=254, param2=0},
		{name="air", prob=254, param2=0},
		{name="air", prob=254, param2=0},
		{name="vlf_deepslate:deepslate_cobbled", prob=254, param2=0},
		{name="air", prob=254, param2=0},
		{name="air", prob=254, param2=0},
		{name="air", prob=254, param2=0},
		{name="air", prob=254, param2=0},
		{name="air", prob=254, param2=0},
		{name="air", prob=254, param2=0},
		{name="air", prob=254, param2=0},
		{name="air", prob=254, param2=0},
		{name="vlf_deepslate:deepslate_cobbled", prob=254, param2=0},
		{name="air", prob=254, param2=0},
		{name="air", prob=254, param2=0},
		{name="air", prob=254, param2=0},
		{name="air", prob=254, param2=0},
		{name="air", prob=254, param2=0},
		{name="vlf_deepslate:deepslate_cobbled", prob=254, param2=0},
		{name="air", prob=254, param2=0},
		{name="air", prob=254, param2=0},
		{name="air", prob=254, param2=0},
		{name="air", prob=254, param2=0},
		{name="air", prob=254, param2=0},
		{name="air", prob=254, param2=0},
		{name="air", prob=254, param2=0},
		{name="air", prob=254, param2=0},
		{name="air", prob=254, param2=0},
		{name="air", prob=254, param2=0},
		{name="vlf_deepslate:deepslate_cobbled", prob=254, param2=0},
		{name="air", prob=254, param2=0},
		{name="air", prob=254, param2=0},
		{name="air", prob=254, param2=0},
		{name="vlf_deepslate:deepslate_cobbled", prob=254, param2=0},
		{name="air", prob=254, param2=0},
		{name="air", prob=254, param2=0},
		{name="air", prob=254, param2=0},
		{name="air", prob=254, param2=0},
		{name="air", prob=254, param2=0},
		{name="air", prob=254, param2=0},
		{name="air", prob=254, param2=0},
		{name="air", prob=254, param2=0},
		{name="air", prob=254, param2=0},
		{name="air", prob=254, param2=0},
		{name="air", prob=254, param2=0},
		{name="air", prob=254, param2=0},
		{name="vlf_deepslate:deepslate_cobbled", prob=254, param2=0},
		{name="air", prob=254, param2=0},
		{name="vlf_deepslate:deepslate_cobbled", prob=254, param2=0},
		{name="air", prob=254, param2=0},
		{name="air", prob=254, param2=0},
		{name="air", prob=254, param2=0},
		{name="air", prob=254, param2=0},
		{name="air", prob=254, param2=0},
		{name="air", prob=254, param2=0},
		{name="air", prob=254, param2=0},
		{name="air", prob=254, param2=0},
		{name="air", prob=254, param2=0},
		{name="air", prob=254, param2=0},
		{name="air", prob=254, param2=0},
		{name="air", prob=254, param2=0},
		{name="air", prob=254, param2=0},
		{name="air", prob=254, param2=0},
		{name="vlf_deepslate:deepslate_tiles_cracked", prob=254, param2=0},
		{name="air", prob=254, param2=0},
		{name="air", prob=254, param2=0},
		{name="air", prob=254, param2=0},
		{name="air", prob=254, param2=0},
		{name="air", prob=254, param2=0},
		{name="air", prob=254, param2=0},
		{name="air", prob=254, param2=0},
		{name="vlf_deepslate:deepslate", prob=254, param2=0},
		{name="air", prob=254, param2=0},
		{name="air", prob=254, param2=0},
		{name="air", prob=254, param2=0},
		{name="air", prob=254, param2=0},
		{name="air", prob=254, param2=0},
		{name="air", prob=254, param2=0},
		{name="air", prob=254, param2=0},
		{name="air", prob=254, param2=0},
		{name="air", prob=254, param2=0},
		{name="air", prob=254, param2=0},
		{name="air", prob=254, param2=0},
		{name="air", prob=254, param2=0},
		{name="air", prob=254, param2=0},
		{name="air", prob=254, param2=0},
		{name="air", prob=254, param2=0},
		{name="vlf_deepslate:deepslate_tiles", prob=254, param2=0},
		{name="vlf_deepslate:deepslate_tiles", prob=254, param2=0},
		{name="vlf_deepslate:deepslate_bricks", prob=254, param2=0},
		{name="vlf_deepslate:deepslate_cobbled", prob=254, param2=0},
		{name="vlf_deepslate:deepslate_cobbled", prob=254, param2=0},
		{name="vlf_deepslate:deepslate_cobbled", prob=254, param2=0},
		{name="vlf_deepslate:deepslate_cobbled", prob=254, param2=0},
		{name="vlf_deepslate:deepslate_cobbled", prob=254, param2=0},
		{name="vlf_deepslate:deepslate_cobbled", prob=254, param2=0},
		{name="vlf_deepslate:deepslate_cobbled", prob=254, param2=0},
		{name="vlf_deepslate:deepslate_cobbled", prob=254, param2=0},
		{name="vlf_deepslate:deepslate_cobbled", prob=254, param2=0},
		{name="vlf_deepslate:deepslate_tiles_cracked", prob=254, param2=0},
		{name="vlf_deepslate:deepslate_tiles_cracked", prob=254, param2=0},
		{name="vlf_deepslate:deepslate_tiles_cracked", prob=254, param2=0},
		{name="vlf_deepslate:deepslate_tiles_cracked", prob=254, param2=0},
		{name="vlf_deepslate:deepslate_tiles", prob=254, param2=0},
		{name="vlf_deepslate:deepslate_tiles", prob=254, param2=0},
		{name="vlf_deepslate:deepslate_bricks", prob=254, param2=0},
		{name="vlf_stairs:stair_deepslate_tiles", prob=254, param2=2},
		{name="vlf_stairs:stair_deepslate_tiles", prob=254, param2=2},
		{name="vlf_stairs:stair_deepslate_tiles", prob=254, param2=2},
		{name="vlf_stairs:stair_deepslate_tiles", prob=254, param2=2},
		{name="vlf_stairs:stair_deepslate_tiles", prob=254, param2=2},
		{name="vlf_stairs:stair_deepslate_tiles", prob=254, param2=2},
		{name="vlf_stairs:stair_deepslate_tiles", prob=254, param2=2},
		{name="vlf_stairs:stair_deepslate_tiles", prob=254, param2=2},
		{name="vlf_stairs:stair_deepslate_tiles", prob=254, param2=2},
		{name="air", prob=254, param2=0},
		{name="air", prob=254, param2=0},
		{name="vlf_deepslate:deepslate_bricks", prob=254, param2=0},
		{name="vlf_deepslate:deepslate_tiles", prob=254, param2=0},
		{name="vlf_deepslate:deepslate_tiles", prob=254, param2=0},
		{name="vlf_deepslate:deepslate_tiles", prob=254, param2=0},
		{name="vlf_deepslate:deepslate_bricks", prob=254, param2=0},
		{name="air", prob=254, param2=0},
		{name="air", prob=254, param2=0},
		{name="air", prob=254, param2=0},
		{name="air", prob=254, param2=0},
		{name="air", prob=254, param2=0},
		{name="air", prob=254, param2=0},
		{name="air", prob=254, param2=0},
		{name="air", prob=254, param2=0},
		{name="air", prob=254, param2=0},
		{name="air", prob=254, param2=0},
		{name="air", prob=254, param2=0},
		{name="vlf_deepslate:deepslate_bricks", prob=254, param2=0},
		{name="vlf_deepslate:deepslate_tiles", prob=254, param2=0},
		{name="vlf_deepslate:deepslate_tiles", prob=254, param2=0},
		{name="vlf_deepslate:deepslate_tiles", prob=254, param2=0},
		{name="vlf_deepslate:deepslate_bricks", prob=254, param2=0},
		{name="air", prob=254, param2=0},
		{name="air", prob=254, param2=0},
		{name="air", prob=254, param2=0},
		{name="air", prob=254, param2=0},
		{name="air", prob=254, param2=0},
		{name="air", prob=254, param2=0},
		{name="air", prob=254, param2=0},
		{name="air", prob=254, param2=0},
		{name="air", prob=254, param2=0},
		{name="air", prob=254, param2=0},
		{name="air", prob=254, param2=0},
		{name="vlf_deepslate:deepslate_bricks", prob=254, param2=0},
		{name="vlf_deepslate:deepslate_tiles", prob=254, param2=0},
		{name="air", prob=254, param2=0},
		{name="vlf_deepslate:deepslate_tiles", prob=254, param2=0},
		{name="vlf_deepslate:deepslate_bricks", prob=254, param2=0},
		{name="air", prob=254, param2=0},
		{name="air", prob=254, param2=0},
		{name="air", prob=254, param2=0},
		{name="air", prob=254, param2=0},
		{name="air", prob=254, param2=0},
		{name="air", prob=254, param2=0},
		{name="air", prob=254, param2=0},
		{name="air", prob=254, param2=0},
		{name="air", prob=254, param2=0},
		{name="air", prob=254, param2=0},
		{name="air", prob=254, param2=0},
		{name="vlf_deepslate:deepslate_bricks", prob=254, param2=0},
		{name="vlf_deepslate:deepslate_tiles", prob=254, param2=0},
		{name="air", prob=254, param2=0},
		{name="vlf_deepslate:deepslate_tiles", prob=254, param2=0},
		{name="vlf_deepslate:deepslate_bricks", prob=254, param2=0},
		{name="air", prob=254, param2=0},
		{name="air", prob=254, param2=0},
		{name="air", prob=254, param2=0},
		{name="air", prob=254, param2=0},
		{name="air", prob=254, param2=0},
		{name="air", prob=254, param2=0},
		{name="air", prob=254, param2=0},
		{name="air", prob=254, param2=0},
		{name="air", prob=254, param2=0},
		{name="air", prob=254, param2=0},
		{name="air", prob=254, param2=0},
		{name="vlf_deepslate:deepslate_bricks", prob=254, param2=0},
		{name="vlf_deepslate:deepslate_tiles", prob=254, param2=0},
		{name="air", prob=254, param2=0},
		{name="vlf_deepslate:deepslate_tiles", prob=254, param2=0},
		{name="vlf_deepslate:deepslate_bricks", prob=254, param2=0},
		{name="air", prob=254, param2=0},
		{name="air", prob=254, param2=0},
		{name="air", prob=254, param2=0},
		{name="air", prob=254, param2=0},
		{name="air", prob=254, param2=0},
		{name="air", prob=254, param2=0},
		{name="air", prob=254, param2=0},
		{name="air", prob=254, param2=0},
		{name="air", prob=254, param2=0},
		{name="air", prob=254, param2=0},
		{name="air", prob=254, param2=0},
		{name="vlf_deepslate:deepslate_bricks", prob=254, param2=0},
		{name="vlf_deepslate:deepslate_tiles", prob=254, param2=0},
		{name="air", prob=254, param2=0},
		{name="vlf_deepslate:deepslate_tiles", prob=254, param2=0},
		{name="vlf_deepslate:deepslate_bricks", prob=254, param2=0},
		{name="air", prob=254, param2=0},
		{name="air", prob=254, param2=0},
		{name="air", prob=254, param2=0},
		{name="air", prob=254, param2=0},
		{name="air", prob=254, param2=0},
		{name="air", prob=254, param2=0},
		{name="air", prob=254, param2=0},
		{name="air", prob=254, param2=0},
		{name="air", prob=254, param2=0},
		{name="air", prob=254, param2=0},
		{name="air", prob=254, param2=0},
		{name="vlf_deepslate:deepslate_bricks", prob=254, param2=0},
		{name="vlf_deepslate:deepslate_tiles_cracked", prob=254, param2=0},
		{name="air", prob=254, param2=0},
		{name="air", prob=254, param2=0},
		{name="vlf_deepslate:deepslate_cobbled", prob=254, param2=0},
		{name="air", prob=254, param2=0},
		{name="air", prob=254, param2=0},
		{name="air", prob=254, param2=0},
		{name="air", prob=254, param2=0},
		{name="air", prob=254, param2=0},
		{name="air", prob=254, param2=0},
		{name="air", prob=254, param2=0},
		{name="air", prob=254, param2=0},
		{name="air", prob=254, param2=0},
		{name="air", prob=254, param2=0},
		{name="air", prob=254, param2=0},
		{name="vlf_deepslate:deepslate_cobbled", prob=254, param2=0},
		{name="air", prob=254, param2=0},
		{name="air", prob=254, param2=0},
		{name="air", prob=254, param2=0},
		{name="air", prob=254, param2=0},
		{name="vlf_deepslate:deepslate_cobbled", prob=254, param2=0},
		{name="air", prob=254, param2=0},
		{name="air", prob=254, param2=0},
		{name="air", prob=254, param2=0},
		{name="air", prob=254, param2=0},
		{name="air", prob=254, param2=0},
		{name="air", prob=254, param2=0},
		{name="air", prob=254, param2=0},
		{name="air", prob=254, param2=0},
		{name="air", prob=254, param2=0},
		{name="vlf_deepslate:deepslate_cobbled", prob=254, param2=0},
		{name="air", prob=254, param2=0},
		{name="air", prob=254, param2=0},
		{name="air", prob=254, param2=0},
		{name="air", prob=254, param2=0},
		{name="air", prob=254, param2=0},
		{name="air", prob=254, param2=0},
		{name="vlf_deepslate:deepslate_cobbled", prob=254, param2=0},
		{name="air", prob=254, param2=0},
		{name="air", prob=254, param2=0},
		{name="air", prob=254, param2=0},
		{name="air", prob=254, param2=0},
		{name="air", prob=254, param2=0},
		{name="air", prob=254, param2=0},
		{name="air", prob=254, param2=0},
		{name="vlf_deepslate:deepslate_cobbled", prob=254, param2=0},
		{name="air", prob=254, param2=0},
		{name="air", prob=254, param2=0},
		{name="air", prob=254, param2=0},
		{name="air", prob=254, param2=0},
		{name="air", prob=254, param2=0},
		{name="air", prob=254, param2=0},
		{name="air", prob=254, param2=0},
		{name="air", prob=254, param2=0},
		{name="vlf_deepslate:deepslate_cobbled", prob=254, param2=0},
		{name="air", prob=254, param2=0},
		{name="air", prob=254, param2=0},
		{name="air", prob=254, param2=0},
		{name="air", prob=254, param2=0},
		{name="air", prob=254, param2=0},
		{name="vlf_deepslate:deepslate_cobbled", prob=254, param2=0},
		{name="air", prob=254, param2=0},
		{name="air", prob=254, param2=0},
		{name="air", prob=254, param2=0},
		{name="air", prob=254, param2=0},
		{name="air", prob=254, param2=0},
		{name="air", prob=254, param2=0},
		{name="air", prob=254, param2=0},
		{name="air", prob=254, param2=0},
		{name="air", prob=254, param2=0},
		{name="air", prob=254, param2=0},
		{name="vlf_deepslate:deepslate_cobbled", prob=254, param2=0},
		{name="air", prob=254, param2=0},
		{name="air", prob=254, param2=0},
		{name="air", prob=254, param2=0},
		{name="vlf_deepslate:deepslate_cobbled", prob=254, param2=0},
		{name="air", prob=254, param2=0},
		{name="air", prob=254, param2=0},
		{name="air", prob=254, param2=0},
		{name="air", prob=254, param2=0},
		{name="air", prob=254, param2=0},
		{name="air", prob=254, param2=0},
		{name="air", prob=254, param2=0},
		{name="air", prob=254, param2=0},
		{name="air", prob=254, param2=0},
		{name="air", prob=254, param2=0},
		{name="air", prob=254, param2=0},
		{name="air", prob=254, param2=0},
		{name="vlf_deepslate:deepslate_cobbled", prob=254, param2=0},
		{name="air", prob=254, param2=0},
		{name="vlf_deepslate:deepslate_cobbled", prob=254, param2=0},
		{name="air", prob=254, param2=0},
		{name="air", prob=254, param2=0},
		{name="air", prob=254, param2=0},
		{name="air", prob=254, param2=0},
		{name="air", prob=254, param2=0},
		{name="air", prob=254, param2=0},
		{name="air", prob=254, param2=0},
		{name="air", prob=254, param2=0},
		{name="air", prob=254, param2=0},
		{name="air", prob=254, param2=0},
		{name="air", prob=254, param2=0},
		{name="air", prob=254, param2=0},
		{name="air", prob=254, param2=0},
		{name="air", prob=254, param2=0},
		{name="vlf_deepslate:deepslate_tiles_cracked", prob=254, param2=0},
		{name="air", prob=254, param2=0},
		{name="air", prob=254, param2=0},
		{name="air", prob=254, param2=0},
		{name="air", prob=254, param2=0},
		{name="air", prob=254, param2=0},
		{name="air", prob=254, param2=0},
		{name="air", prob=254, param2=0},
		{name="vlf_deepslate:deepslate", prob=254, param2=0},
		{name="air", prob=254, param2=0},
		{name="air", prob=254, param2=0},
		{name="air", prob=254, param2=0},
		{name="air", prob=254, param2=0},
		{name="air", prob=254, param2=0},
		{name="air", prob=254, param2=0},
		{name="air", prob=254, param2=0},
		{name="air", prob=254, param2=0},
		{name="air", prob=254, param2=0},
		{name="air", prob=254, param2=0},
		{name="air", prob=254, param2=0},
		{name="air", prob=254, param2=0},
		{name="air", prob=254, param2=0},
		{name="air", prob=254, param2=0},
		{name="air", prob=254, param2=0},
		{name="vlf_deepslate:deepslate_tiles", prob=254, param2=0},
		{name="vlf_deepslate:deepslate_tiles", prob=254, param2=0},
		{name="air", prob=254, param2=0},
		{name="vlf_stairs:stair_deepslate_tiles", prob=254, param2=2},
		{name="vlf_stairs:stair_deepslate_tiles", prob=254, param2=2},
		{name="vlf_stairs:stair_deepslate_tiles", prob=254, param2=2},
		{name="vlf_stairs:stair_deepslate_tiles", prob=254, param2=2},
		{name="vlf_stairs:stair_deepslate_tiles", prob=254, param2=2},
		{name="vlf_stairs:stair_deepslate_tiles", prob=254, param2=2},
		{name="vlf_stairs:stair_deepslate_tiles", prob=254, param2=2},
		{name="vlf_stairs:stair_deepslate_tiles", prob=254, param2=2},
		{name="vlf_stairs:stair_deepslate_tiles", prob=254, param2=2},
		{name="vlf_deepslate:deepslate_tiles_cracked", prob=254, param2=0},
		{name="vlf_deepslate:deepslate_tiles_cracked", prob=254, param2=0},
		{name="vlf_deepslate:deepslate_tiles_cracked", prob=254, param2=0},
		{name="vlf_deepslate:deepslate_tiles_cracked", prob=254, param2=0},
		{name="vlf_deepslate:deepslate_tiles", prob=254, param2=0},
		{name="vlf_deepslate:deepslate_tiles", prob=254, param2=0},
		{name="air", prob=254, param2=0},
		{name="air", prob=254, param2=0},
		{name="air", prob=254, param2=0},
		{name="air", prob=254, param2=0},
		{name="air", prob=254, param2=0},
		{name="air", prob=254, param2=0},
		{name="air", prob=254, param2=0},
		{name="air", prob=254, param2=0},
		{name="air", prob=254, param2=0},
		{name="air", prob=254, param2=0},
		{name="air", prob=254, param2=0},
		{name="air", prob=254, param2=0},
		{name="air", prob=254, param2=0},
		{name="vlf_deepslate:deepslate_tiles", prob=254, param2=0},
		{name="vlf_deepslate:deepslate_tiles", prob=254, param2=0},
		{name="vlf_deepslate:deepslate_tiles", prob=254, param2=0},
		{name="air", prob=254, param2=0},
		{name="air", prob=254, param2=0},
		{name="air", prob=254, param2=0},
		{name="air", prob=254, param2=0},
		{name="air", prob=254, param2=0},
		{name="air", prob=254, param2=0},
		{name="air", prob=254, param2=0},
		{name="air", prob=254, param2=0},
		{name="air", prob=254, param2=0},
		{name="air", prob=254, param2=0},
		{name="air", prob=254, param2=0},
		{name="air", prob=254, param2=0},
		{name="air", prob=254, param2=0},
		{name="vlf_deepslate:deepslate_tiles", prob=254, param2=0},
		{name="vlf_deepslate:deepslate_tiles", prob=254, param2=0},
		{name="vlf_deepslate:deepslate_tiles", prob=254, param2=0},
		{name="air", prob=254, param2=0},
		{name="air", prob=254, param2=0},
		{name="air", prob=254, param2=0},
		{name="air", prob=254, param2=0},
		{name="air", prob=254, param2=0},
		{name="air", prob=254, param2=0},
		{name="air", prob=254, param2=0},
		{name="air", prob=254, param2=0},
		{name="air", prob=254, param2=0},
		{name="air", prob=254, param2=0},
		{name="air", prob=254, param2=0},
		{name="air", prob=254, param2=0},
		{name="air", prob=254, param2=0},
		{name="vlf_deepslate:deepslate_tiles", prob=254, param2=0},
		{name="vlf_deepslate:deepslate_tiles", prob=254, param2=0},
		{name="vlf_deepslate:deepslate_tiles", prob=254, param2=0},
		{name="air", prob=254, param2=0},
		{name="air", prob=254, param2=0},
		{name="air", prob=254, param2=0},
		{name="air", prob=254, param2=0},
		{name="air", prob=254, param2=0},
		{name="air", prob=254, param2=0},
		{name="air", prob=254, param2=0},
		{name="air", prob=254, param2=0},
		{name="air", prob=254, param2=0},
		{name="air", prob=254, param2=0},
		{name="air", prob=254, param2=0},
		{name="air", prob=254, param2=0},
		{name="air", prob=254, param2=0},
		{name="vlf_deepslate:deepslate_tiles", prob=254, param2=0},
		{name="air", prob=254, param2=0},
		{name="vlf_deepslate:deepslate_tiles", prob=254, param2=0},
		{name="air", prob=254, param2=0},
		{name="air", prob=254, param2=0},
		{name="air", prob=254, param2=0},
		{name="air", prob=254, param2=0},
		{name="air", prob=254, param2=0},
		{name="air", prob=254, param2=0},
		{name="air", prob=254, param2=0},
		{name="air", prob=254, param2=0},
		{name="air", prob=254, param2=0},
		{name="air", prob=254, param2=0},
		{name="air", prob=254, param2=0},
		{name="air", prob=254, param2=0},
		{name="air", prob=254, param2=0},
		{name="vlf_deepslate:deepslate_tiles", prob=254, param2=0},
		{name="air", prob=254, param2=0},
		{name="vlf_deepslate:deepslate_tiles", prob=254, param2=0},
		{name="air", prob=254, param2=0},
		{name="air", prob=254, param2=0},
		{name="air", prob=254, param2=0},
		{name="air", prob=254, param2=0},
		{name="air", prob=254, param2=0},
		{name="air", prob=254, param2=0},
		{name="air", prob=254, param2=0},
		{name="air", prob=254, param2=0},
		{name="air", prob=254, param2=0},
		{name="air", prob=254, param2=0},
		{name="air", prob=254, param2=0},
		{name="air", prob=254, param2=0},
		{name="air", prob=254, param2=0},
		{name="vlf_deepslate:deepslate_tiles", prob=254, param2=0},
		{name="air", prob=254, param2=0},
		{name="vlf_deepslate:deepslate_tiles", prob=254, param2=0},
		{name="air", prob=254, param2=0},
		{name="air", prob=254, param2=0},
		{name="air", prob=254, param2=0},
		{name="air", prob=254, param2=0},
		{name="air", prob=254, param2=0},
		{name="air", prob=254, param2=0},
		{name="air", prob=254, param2=0},
		{name="air", prob=254, param2=0},
		{name="air", prob=254, param2=0},
		{name="air", prob=254, param2=0},
		{name="air", prob=254, param2=0},
		{name="air", prob=254, param2=0},
		{name="air", prob=254, param2=0},
		{name="vlf_deepslate:deepslate_tiles_cracked", prob=254, param2=0},
		{name="air", prob=254, param2=0},
		{name="air", prob=254, param2=0},
		{name="vlf_deepslate:deepslate_cobbled", prob=254, param2=0},
		{name="air", prob=254, param2=0},
		{name="air", prob=254, param2=0},
		{name="air", prob=254, param2=0},
		{name="air", prob=254, param2=0},
		{name="air", prob=254, param2=0},
		{name="air", prob=254, param2=0},
		{name="air", prob=254, param2=0},
		{name="air", prob=254, param2=0},
		{name="air", prob=254, param2=0},
		{name="air", prob=254, param2=0},
		{name="air", prob=254, param2=0},
		{name="vlf_deepslate:deepslate_cobbled", prob=254, param2=0},
		{name="air", prob=254, param2=0},
		{name="air", prob=254, param2=0},
		{name="air", prob=254, param2=0},
		{name="air", prob=254, param2=0},
		{name="vlf_deepslate:deepslate_cobbled", prob=254, param2=0},
		{name="air", prob=254, param2=0},
		{name="air", prob=254, param2=0},
		{name="air", prob=254, param2=0},
		{name="air", prob=254, param2=0},
		{name="air", prob=254, param2=0},
		{name="air", prob=254, param2=0},
		{name="air", prob=254, param2=0},
		{name="air", prob=254, param2=0},
		{name="air", prob=254, param2=0},
		{name="vlf_deepslate:deepslate_cobbled", prob=254, param2=0},
		{name="air", prob=254, param2=0},
		{name="air", prob=254, param2=0},
		{name="air", prob=254, param2=0},
		{name="air", prob=254, param2=0},
		{name="air", prob=254, param2=0},
		{name="air", prob=254, param2=0},
		{name="vlf_deepslate:deepslate_cobbled", prob=254, param2=0},
		{name="air", prob=254, param2=0},
		{name="air", prob=254, param2=0},
		{name="air", prob=254, param2=0},
		{name="air", prob=254, param2=0},
		{name="air", prob=254, param2=0},
		{name="air", prob=254, param2=0},
		{name="air", prob=254, param2=0},
		{name="vlf_deepslate:deepslate_cobbled", prob=254, param2=0},
		{name="air", prob=254, param2=0},
		{name="air", prob=254, param2=0},
		{name="air", prob=254, param2=0},
		{name="air", prob=254, param2=0},
		{name="air", prob=254, param2=0},
		{name="air", prob=254, param2=0},
		{name="air", prob=254, param2=0},
		{name="air", prob=254, param2=0},
		{name="vlf_deepslate:deepslate_cobbled", prob=254, param2=0},
		{name="air", prob=254, param2=0},
		{name="air", prob=254, param2=0},
		{name="air", prob=254, param2=0},
		{name="air", prob=254, param2=0},
		{name="vlf_deepslate:deepslate_cobbled", prob=254, param2=0},
		{name="vlf_deepslate:deepslate_cobbled", prob=254, param2=0},
		{name="air", prob=254, param2=0},
		{name="air", prob=254, param2=0},
		{name="air", prob=254, param2=0},
		{name="air", prob=254, param2=0},
		{name="air", prob=254, param2=0},
		{name="air", prob=254, param2=0},
		{name="air", prob=254, param2=0},
		{name="air", prob=254, param2=0},
		{name="air", prob=254, param2=0},
		{name="air", prob=254, param2=0},
		{name="vlf_deepslate:deepslate_cobbled", prob=254, param2=0},
		{name="air", prob=254, param2=0},
		{name="air", prob=254, param2=0},
		{name="air", prob=254, param2=0},
		{name="vlf_deepslate:deepslate_cobbled", prob=254, param2=0},
		{name="air", prob=254, param2=0},
		{name="air", prob=254, param2=0},
		{name="air", prob=254, param2=0},
		{name="air", prob=254, param2=0},
		{name="air", prob=254, param2=0},
		{name="air", prob=254, param2=0},
		{name="air", prob=254, param2=0},
		{name="air", prob=254, param2=0},
		{name="air", prob=254, param2=0},
		{name="air", prob=254, param2=0},
		{name="air", prob=254, param2=0},
		{name="air", prob=254, param2=0},
		{name="vlf_deepslate:deepslate_cobbled", prob=254, param2=0},
		{name="air", prob=254, param2=0},
		{name="vlf_deepslate:deepslate_cobbled", prob=254, param2=0},
		{name="air", prob=254, param2=0},
		{name="air", prob=254, param2=0},
		{name="air", prob=254, param2=0},
		{name="air", prob=254, param2=0},
		{name="air", prob=254, param2=0},
		{name="air", prob=254, param2=0},
		{name="air", prob=254, param2=0},
		{name="air", prob=254, param2=0},
		{name="air", prob=254, param2=0},
		{name="air", prob=254, param2=0},
		{name="air", prob=254, param2=0},
		{name="air", prob=254, param2=0},
		{name="air", prob=254, param2=0},
		{name="air", prob=254, param2=0},
		{name="vlf_deepslate:deepslate_tiles_cracked", prob=254, param2=0},
		{name="air", prob=254, param2=0},
		{name="air", prob=254, param2=0},
		{name="air", prob=254, param2=0},
		{name="air", prob=254, param2=0},
		{name="air", prob=254, param2=0},
		{name="air", prob=254, param2=0},
		{name="air", prob=254, param2=0},
		{name="vlf_deepslate:deepslate", prob=254, param2=0},
		{name="air", prob=254, param2=0},
		{name="air", prob=254, param2=0},
		{name="air", prob=254, param2=0},
		{name="air", prob=254, param2=0},
		{name="air", prob=254, param2=0},
		{name="air", prob=254, param2=0},
		{name="air", prob=254, param2=0},
		{name="air", prob=254, param2=0},
		{name="air", prob=254, param2=0},
		{name="air", prob=254, param2=0},
		{name="air", prob=254, param2=0},
		{name="air", prob=254, param2=0},
		{name="air", prob=254, param2=0},
		{name="air", prob=254, param2=0},
		{name="air", prob=254, param2=0},
		{name="vlf_deepslate:deepslate_tiles", prob=254, param2=0},
		{name="vlf_deepslate:deepslate_tiles", prob=254, param2=0},
		{name="air", prob=254, param2=0},
		{name="air", prob=254, param2=0},
		{name="air", prob=254, param2=0},
		{name="air", prob=254, param2=0},
		{name="air", prob=254, param2=0},
		{name="air", prob=254, param2=0},
		{name="air", prob=254, param2=0},
		{name="air", prob=254, param2=0},
		{name="air", prob=254, param2=0},
		{name="air", prob=254, param2=0},
		{name="vlf_deepslate:deepslate_tiles_cracked", prob=254, param2=0},
		{name="vlf_deepslate:deepslate_tiles_cracked", prob=254, param2=0},
		{name="vlf_deepslate:deepslate_tiles_cracked", prob=254, param2=0},
		{name="vlf_deepslate:deepslate_tiles_cracked", prob=254, param2=0},
		{name="vlf_deepslate:deepslate_tiles", prob=254, param2=0},
		{name="vlf_deepslate:deepslate_tiles", prob=254, param2=0},
		{name="air", prob=254, param2=0},
		{name="air", prob=254, param2=0},
		{name="air", prob=254, param2=0},
		{name="air", prob=254, param2=0},
		{name="air", prob=254, param2=0},
		{name="air", prob=254, param2=0},
		{name="air", prob=254, param2=0},
		{name="air", prob=254, param2=0},
		{name="air", prob=254, param2=0},
		{name="air", prob=254, param2=0},
		{name="air", prob=254, param2=0},
		{name="air", prob=254, param2=0},
		{name="air", prob=254, param2=0},
		{name="vlf_deepslate:deepslate_tiles", prob=254, param2=0},
		{name="vlf_deepslate:deepslate_tiles", prob=254, param2=0},
		{name="vlf_deepslate:deepslate_tiles", prob=254, param2=0},
		{name="air", prob=254, param2=0},
		{name="air", prob=254, param2=0},
		{name="air", prob=254, param2=0},
		{name="air", prob=254, param2=0},
		{name="air", prob=254, param2=0},
		{name="air", prob=254, param2=0},
		{name="air", prob=254, param2=0},
		{name="air", prob=254, param2=0},
		{name="air", prob=254, param2=0},
		{name="air", prob=254, param2=0},
		{name="air", prob=254, param2=0},
		{name="air", prob=254, param2=0},
		{name="air", prob=254, param2=0},
		{name="vlf_deepslate:deepslate_tiles_cracked", prob=254, param2=0},
		{name="vlf_deepslate:deepslate_tiles", prob=254, param2=0},
		{name="vlf_deepslate:deepslate_tiles", prob=254, param2=0},
		{name="air", prob=254, param2=0},
		{name="air", prob=254, param2=0},
		{name="air", prob=254, param2=0},
		{name="air", prob=254, param2=0},
		{name="air", prob=254, param2=0},
		{name="air", prob=254, param2=0},
		{name="air", prob=254, param2=0},
		{name="air", prob=254, param2=0},
		{name="air", prob=254, param2=0},
		{name="air", prob=254, param2=0},
		{name="air", prob=254, param2=0},
		{name="air", prob=254, param2=0},
		{name="air", prob=254, param2=0},
		{name="vlf_deepslate:deepslate_tiles", prob=254, param2=0},
		{name="vlf_deepslate:deepslate_tiles", prob=254, param2=0},
		{name="vlf_deepslate:deepslate_tiles", prob=254, param2=0},
		{name="air", prob=254, param2=0},
		{name="air", prob=254, param2=0},
		{name="air", prob=254, param2=0},
		{name="air", prob=254, param2=0},
		{name="air", prob=254, param2=0},
		{name="air", prob=254, param2=0},
		{name="air", prob=254, param2=0},
		{name="air", prob=254, param2=0},
		{name="air", prob=254, param2=0},
		{name="air", prob=254, param2=0},
		{name="air", prob=254, param2=0},
		{name="air", prob=254, param2=0},
		{name="air", prob=254, param2=0},
		{name="vlf_deepslate:deepslate_tiles_cracked", prob=254, param2=0},
		{name="air", prob=254, param2=0},
		{name="vlf_deepslate:deepslate_tiles", prob=254, param2=0},
		{name="air", prob=254, param2=0},
		{name="air", prob=254, param2=0},
		{name="air", prob=254, param2=0},
		{name="air", prob=254, param2=0},
		{name="air", prob=254, param2=0},
		{name="air", prob=254, param2=0},
		{name="air", prob=254, param2=0},
		{name="air", prob=254, param2=0},
		{name="air", prob=254, param2=0},
		{name="air", prob=254, param2=0},
		{name="air", prob=254, param2=0},
		{name="air", prob=254, param2=0},
		{name="air", prob=254, param2=0},
		{name="vlf_deepslate:deepslate_tiles_cracked", prob=254, param2=0},
		{name="air", prob=254, param2=0},
		{name="vlf_deepslate:deepslate_tiles", prob=254, param2=0},
		{name="air", prob=254, param2=0},
		{name="air", prob=254, param2=0},
		{name="air", prob=254, param2=0},
		{name="air", prob=254, param2=0},
		{name="air", prob=254, param2=0},
		{name="air", prob=254, param2=0},
		{name="air", prob=254, param2=0},
		{name="air", prob=254, param2=0},
		{name="air", prob=254, param2=0},
		{name="air", prob=254, param2=0},
		{name="air", prob=254, param2=0},
		{name="air", prob=254, param2=0},
		{name="air", prob=254, param2=0},
		{name="vlf_deepslate:deepslate_tiles_cracked", prob=254, param2=0},
		{name="air", prob=254, param2=0},
		{name="vlf_deepslate:deepslate_tiles", prob=254, param2=0},
		{name="air", prob=254, param2=0},
		{name="air", prob=254, param2=0},
		{name="air", prob=254, param2=0},
		{name="air", prob=254, param2=0},
		{name="air", prob=254, param2=0},
		{name="air", prob=254, param2=0},
		{name="air", prob=254, param2=0},
		{name="air", prob=254, param2=0},
		{name="air", prob=254, param2=0},
		{name="air", prob=254, param2=0},
		{name="air", prob=254, param2=0},
		{name="air", prob=254, param2=0},
		{name="air", prob=254, param2=0},
		{name="vlf_deepslate:deepslate_tiles_cracked", prob=254, param2=0},
		{name="air", prob=254, param2=0},
		{name="air", prob=254, param2=0},
		{name="vlf_deepslate:deepslate_cobbled", prob=254, param2=0},
		{name="air", prob=254, param2=0},
		{name="air", prob=254, param2=0},
		{name="air", prob=254, param2=0},
		{name="air", prob=254, param2=0},
		{name="air", prob=254, param2=0},
		{name="air", prob=254, param2=0},
		{name="air", prob=254, param2=0},
		{name="air", prob=254, param2=0},
		{name="air", prob=254, param2=0},
		{name="air", prob=254, param2=0},
		{name="air", prob=254, param2=0},
		{name="vlf_deepslate:deepslate_cobbled", prob=254, param2=0},
		{name="air", prob=254, param2=0},
		{name="air", prob=254, param2=0},
		{name="air", prob=254, param2=0},
		{name="air", prob=254, param2=0},
		{name="vlf_deepslate:deepslate_cobbled", prob=254, param2=0},
		{name="air", prob=254, param2=0},
		{name="air", prob=254, param2=0},
		{name="air", prob=254, param2=0},
		{name="air", prob=254, param2=0},
		{name="air", prob=254, param2=0},
		{name="air", prob=254, param2=0},
		{name="air", prob=254, param2=0},
		{name="air", prob=254, param2=0},
		{name="air", prob=254, param2=0},
		{name="vlf_deepslate:deepslate_cobbled", prob=254, param2=0},
		{name="air", prob=254, param2=0},
		{name="air", prob=254, param2=0},
		{name="air", prob=254, param2=0},
		{name="air", prob=254, param2=0},
		{name="air", prob=254, param2=0},
		{name="air", prob=254, param2=0},
		{name="vlf_deepslate:deepslate_cobbled", prob=254, param2=0},
		{name="air", prob=254, param2=0},
		{name="air", prob=254, param2=0},
		{name="air", prob=254, param2=0},
		{name="air", prob=254, param2=0},
		{name="air", prob=254, param2=0},
		{name="air", prob=254, param2=0},
		{name="air", prob=254, param2=0},
		{name="vlf_deepslate:deepslate_cobbled", prob=254, param2=0},
		{name="air", prob=254, param2=0},
		{name="air", prob=254, param2=0},
		{name="air", prob=254, param2=0},
		{name="air", prob=254, param2=0},
		{name="air", prob=254, param2=0},
		{name="air", prob=254, param2=0},
		{name="air", prob=254, param2=0},
		{name="air", prob=254, param2=0},
		{name="vlf_deepslate:deepslate_cobbled", prob=254, param2=0},
		{name="air", prob=254, param2=0},
		{name="air", prob=254, param2=0},
		{name="air", prob=254, param2=0},
		{name="air", prob=254, param2=0},
		{name="air", prob=254, param2=0},
		{name="vlf_deepslate:deepslate_cobbled", prob=254, param2=0},
		{name="air", prob=254, param2=0},
		{name="air", prob=254, param2=0},
		{name="air", prob=254, param2=0},
		{name="air", prob=254, param2=0},
		{name="air", prob=254, param2=0},
		{name="air", prob=254, param2=0},
		{name="air", prob=254, param2=0},
		{name="air", prob=254, param2=0},
		{name="air", prob=254, param2=0},
		{name="air", prob=254, param2=0},
		{name="vlf_deepslate:deepslate_cobbled", prob=254, param2=0},
		{name="air", prob=254, param2=0},
		{name="air", prob=254, param2=0},
		{name="air", prob=254, param2=0},
		{name="vlf_deepslate:deepslate_cobbled", prob=254, param2=0},
		{name="air", prob=254, param2=0},
		{name="air", prob=254, param2=0},
		{name="air", prob=254, param2=0},
		{name="air", prob=254, param2=0},
		{name="air", prob=254, param2=0},
		{name="air", prob=254, param2=0},
		{name="air", prob=254, param2=0},
		{name="air", prob=254, param2=0},
		{name="air", prob=254, param2=0},
		{name="air", prob=254, param2=0},
		{name="air", prob=254, param2=0},
		{name="air", prob=254, param2=0},
		{name="vlf_deepslate:deepslate_cobbled", prob=254, param2=0},
		{name="air", prob=254, param2=0},
		{name="vlf_deepslate:deepslate_cobbled", prob=254, param2=0},
		{name="air", prob=254, param2=0},
		{name="air", prob=254, param2=0},
		{name="air", prob=254, param2=0},
		{name="air", prob=254, param2=0},
		{name="air", prob=254, param2=0},
		{name="air", prob=254, param2=0},
		{name="air", prob=254, param2=0},
		{name="air", prob=254, param2=0},
		{name="air", prob=254, param2=0},
		{name="air", prob=254, param2=0},
		{name="air", prob=254, param2=0},
		{name="air", prob=254, param2=0},
		{name="air", prob=254, param2=0},
		{name="air", prob=254, param2=0},
		{name="vlf_deepslate:deepslate_tiles_cracked", prob=254, param2=0},
		{name="air", prob=254, param2=0},
		{name="air", prob=254, param2=0},
		{name="air", prob=254, param2=0},
		{name="air", prob=254, param2=0},
		{name="air", prob=254, param2=0},
		{name="air", prob=254, param2=0},
		{name="air", prob=254, param2=0},
		{name="vlf_deepslate:deepslate", prob=254, param2=0},
		{name="air", prob=254, param2=0},
		{name="air", prob=254, param2=0},
		{name="air", prob=254, param2=0},
		{name="air", prob=254, param2=0},
		{name="air", prob=254, param2=0},
		{name="air", prob=254, param2=0},
		{name="air", prob=254, param2=0},
		{name="air", prob=254, param2=0},
		{name="air", prob=254, param2=0},
		{name="air", prob=254, param2=0},
		{name="air", prob=254, param2=0},
		{name="air", prob=254, param2=0},
		{name="air", prob=254, param2=0},
		{name="air", prob=254, param2=0},
		{name="air", prob=254, param2=0},
		{name="vlf_deepslate:deepslate_tiles", prob=254, param2=0},
		{name="vlf_deepslate:deepslate_tiles", prob=254, param2=0},
