schematic = {
	size = {x=5, y=7, z=5},
	yslice_prob = {
		{ypos=0, prob=254},
		{ypos=1, prob=254},
		{ypos=2, prob=254},
		{ypos=3, prob=254},
		{ypos=4, prob=254},
		{ypos=5, prob=254},
		{ypos=6, prob=254},
	},
	data = {
		{name="vlf_core:sandstone", prob=254, param2=0},
		{name="vlf_core:sandstone", prob=254, param2=0},
		{name="vlf_core:sandstone", prob=254, param2=0},
		{name="vlf_core:sandstone", prob=254, param2=0},
		{name="vlf_core:sandstone", prob=254, param2=0},
		{name="vlf_core:sandstone", prob=254, param2=0},
		{name="vlf_core:sandstone", prob=254, param2=0},
		{name="vlf_core:sandstone", prob=254, param2=0},
		{name="vlf_core:sandstone", prob=254, param2=0},
		{name="vlf_core:sandstone", prob=254, param2=0},
		{name="vlf_core:sandstone", prob=254, param2=0},
		{name="vlf_core:sandstone", prob=254, param2=0},
		{name="vlf_stairs:slab_sandstone", prob=254, param2=0},
		{name="vlf_core:sandstone", prob=254, param2=0},
		{name="vlf_core:sandstone", prob=254, param2=0},
		{name="air", prob=254, param2=0},
		{name="air", prob=254, param2=0},
		{name="air", prob=254, param2=0},
		{name="air", prob=254, param2=0},
		{name="air", prob=254, param2=0},
		{name="air", prob=254, param2=0},
		{name="air", prob=254, param2=0},
		{name="air", prob=254, param2=0},
		{name="air", prob=254, param2=0},
		{name="air", prob=254, param2=0},
		{name="air", prob=254, param2=0},
		{name="air", prob=254, param2=0},
		{name="air", prob=254, param2=0},
		{name="air", prob=254, param2=0},
		{name="air", prob=254, param2=0},
		{name="air", prob=254, param2=0},
		{name="air", prob=254, param2=0},
		{name="air", prob=254, param2=0},
		{name="air", prob=254, param2=0},
		{name="air", prob=254, param2=0},
		{name="vlf_core:sandstone", prob=254, param2=0},
		{name="vlf_core:sandstone", prob=254, param2=0},
		{name="vlf_core:sandstone", prob=254, param2=0},
		{name="vlf_core:sandstone", prob=254, param2=0},
		{name="vlf_core:sandstone", prob=254, param2=0},
		{name="vlf_core:sandstone", prob=254, param2=0},
		{name="vlf_core:sandstone", prob=254, param2=0},
		{name="vlf_core:sandstone", prob=254, param2=0},
		{name="vlf_core:sandstone", prob=254, param2=0},
		{name="vlf_core:sandstone", prob=254, param2=0},
		{name="vlf_core:sandstone", prob=254, param2=0},
		{name="vlf_core:sandstone", prob=254, param2=0},
		{name="vlf_core:sandstone", prob=254, param2=0},
		{name="vlf_core:sandstone", prob=254, param2=0},
		{name="vlf_core:sandstone", prob=254, param2=0},
		{name="air", prob=254, param2=0},
		{name="vlf_core:sandstone", prob=254, param2=0},
		{name="air", prob=254, param2=0},
		{name="vlf_core:sandstone", prob=254, param2=0},
		{name="air", prob=254, param2=0},
		{name="air", prob=254, param2=0},
		{name="vlf_core:sandstone", prob=254, param2=0},
		{name="air", prob=254, param2=0},
		{name="vlf_core:sandstone", prob=254, param2=0},
		{name="air", prob=254, param2=0},
		{name="air", prob=254, param2=0},
		{name="vlf_stairs:slab_sandstone", prob=254, param2=0},
		{name="vlf_stairs:slab_sandstone", prob=254, param2=0},
		{name="vlf_stairs:slab_sandstone", prob=254, param2=0},
		{name="air", prob=254, param2=0},
		{name="air", prob=254, param2=0},
		{name="air", prob=254, param2=0},
		{name="air", prob=254, param2=0},
		{name="air", prob=254, param2=0},
		{name="air", prob=254, param2=0},
		{name="vlf_core:sandstone", prob=254, param2=0},
		{name="vlf_core:sandstone", prob=254, param2=0},
		{name="vlf_core:water_flowing", prob=254, param2=15},
		{name="vlf_core:sandstone", prob=254, param2=0},
		{name="vlf_core:sandstone", prob=254, param2=0},
		{name="vlf_core:sandstone", prob=254, param2=0},
		{name="vlf_core:sandstone", prob=254, param2=0},
		{name="vlf_core:water_source", prob=254, param2=8},
		{name="vlf_core:sandstone", prob=254, param2=0},
		{name="vlf_core:sandstone", prob=254, param2=0},
		{name="vlf_stairs:slab_sandstone", prob=254, param2=0},
		{name="vlf_core:sandstone", prob=254, param2=0},
		{name="air", prob=254, param2=0},
		{name="vlf_core:sandstone", prob=254, param2=0},
		{name="vlf_stairs:slab_sandstone", prob=254, param2=0},
		{name="air", prob=254, param2=0},
		{name="air", prob=254, param2=0},
		{name="air", prob=254, param2=0},
		{name="air", prob=254, param2=0},
		{name="air", prob=254, param2=0},
		{name="air", prob=254, param2=0},
		{name="air", prob=254, param2=0},
		{name="air", prob=254, param2=0},
		{name="air", prob=254, param2=0},
		{name="air", prob=254, param2=0},
		{name="air", prob=254, param2=0},
		{name="vlf_stairs:slab_sandstone", prob=254, param2=0},
		{name="vlf_core:sandstone", prob=254, param2=0},
		{name="vlf_stairs:slab_sandstone", prob=254, param2=0},
		{name="air", prob=254, param2=0},
		{name="air", prob=254, param2=0},
		{name="air", prob=254, param2=0},
		{name="air", prob=254, param2=0},
		{name="air", prob=254, param2=0},
		{name="air", prob=254, param2=0},
		{name="vlf_core:sandstone", prob=254, param2=0},
		{name="vlf_core:sandstone", prob=254, param2=0},
		{name="vlf_core:sandstone", prob=254, param2=0},
		{name="vlf_core:sandstone", prob=254, param2=0},
		{name="vlf_core:sandstone", prob=254, param2=0},
		{name="vlf_core:sandstone", prob=254, param2=0},
		{name="vlf_core:sandstone", prob=254, param2=0},
		{name="vlf_core:sandstone", prob=254, param2=0},
		{name="vlf_core:sandstone", prob=254, param2=0},
		{name="vlf_core:sandstone", prob=254, param2=0},
		{name="vlf_core:sandstone", prob=254, param2=0},
		{name="vlf_core:sandstone", prob=254, param2=0},
		{name="vlf_core:sandstone", prob=254, param2=0},
		{name="vlf_core:sandstone", prob=254, param2=0},
		{name="vlf_core:sandstone", prob=254, param2=0},
		{name="air", prob=254, param2=0},
		{name="vlf_core:sandstone", prob=254, param2=0},
		{name="air", prob=254, param2=0},
		{name="vlf_core:sandstone", prob=254, param2=0},
		{name="air", prob=254, param2=0},
		{name="air", prob=254, param2=0},
		{name="vlf_core:sandstone", prob=254, param2=0},
		{name="air", prob=254, param2=0},
		{name="vlf_core:sandstone", prob=254, param2=0},
		{name="air", prob=254, param2=0},
		{name="air", prob=254, param2=0},
		{name="vlf_stairs:slab_sandstone", prob=254, param2=0},
		{name="vlf_stairs:slab_sandstone", prob=254, param2=0},
		{name="vlf_stairs:slab_sandstone", prob=254, param2=0},
		{name="air", prob=254, param2=0},
		{name="air", prob=254, param2=0},
		{name="air", prob=254, param2=0},
		{name="air", prob=254, param2=0},
		{name="air", prob=254, param2=0},
		{name="air", prob=254, param2=0},
		{name="vlf_core:sandstone", prob=254, param2=0},
		{name="vlf_core:sandstone", prob=254, param2=0},
		{name="vlf_core:sandstone", prob=254, param2=0},
		{name="vlf_core:sandstone", prob=254, param2=0},
		{name="vlf_core:sandstone", prob=254, param2=0},
		{name="vlf_core:sandstone", prob=254, param2=0},
		{name="vlf_core:sandstone", prob=254, param2=0},
		{name="vlf_core:sandstone", prob=254, param2=0},
		{name="vlf_core:sandstone", prob=254, param2=0},
		{name="vlf_core:sandstone", prob=254, param2=0},
		{name="vlf_core:sandstone", prob=254, param2=0},
		{name="vlf_core:sandstone", prob=254, param2=0},
		{name="vlf_stairs:slab_sandstone", prob=254, param2=0},
		{name="vlf_core:sandstone", prob=254, param2=0},
		{name="vlf_core:sandstone", prob=254, param2=0},
		{name="air", prob=254, param2=0},
		{name="air", prob=254, param2=0},
		{name="air", prob=254, param2=0},
		{name="air", prob=254, param2=0},
		{name="air", prob=254, param2=0},
		{name="air", prob=254, param2=0},
		{name="air", prob=254, param2=0},
		{name="air", prob=254, param2=0},
		{name="air", prob=254, param2=0},
		{name="air", prob=254, param2=0},
		{name="air", prob=254, param2=0},
		{name="air", prob=254, param2=0},
		{name="air", prob=254, param2=0},
		{name="air", prob=254, param2=0},
		{name="air", prob=254, param2=0},
		{name="air", prob=254, param2=0},
		{name="air", prob=254, param2=0},
		{name="air", prob=254, param2=0},
		{name="air", prob=254, param2=0},
		{name="air", prob=254, param2=0},
	},
}
