schematic = {
	size = {x=3, y=4, z=3},
	yslice_prob = {
		{ypos=0, prob=254},
		{ypos=1, prob=254},
		{ypos=2, prob=254},
		{ypos=3, prob=254},
	},
	data = {
		{name="air", prob=0, param2=0},
		{name="vlf_ocean:fire_coral_block", prob=254, param2=0},
		{name="air", prob=0, param2=0},
		{name="vlf_ocean:fire_coral_fan", prob=254, param2=4},
		{name="vlf_ocean:fire_coral_block", prob=254, param2=0},
		{name="vlf_ocean:fire_coral_fan", prob=254, param2=12},
		{name="air", prob=0, param2=0},
		{name="vlf_ocean:fire_coral", prob=254, param2=9},
		{name="air", prob=0, param2=0},
		{name="air", prob=0, param2=0},
		{name="air", prob=0, param2=0},
		{name="air", prob=0, param2=0},
		{name="air", prob=0, param2=0},
		{name="air", prob=0, param2=0},
		{name="air", prob=0, param2=0},
		{name="air", prob=0, param2=0},
		{name="air", prob=0, param2=0},
		{name="air", prob=0, param2=0},
		{name="air", prob=0, param2=0},
		{name="vlf_ocean:fire_coral_fan", prob=254, param2=12},
		{name="air", prob=0, param2=0},
		{name="air", prob=0, param2=0},
		{name="air", prob=0, param2=0},
		{name="air", prob=0, param2=0},
		{name="air", prob=0, param2=0},
		{name="air", prob=0, param2=0},
		{name="air", prob=0, param2=0},
		{name="air", prob=0, param2=0},
		{name="air", prob=0, param2=0},
		{name="air", prob=0, param2=0},
		{name="air", prob=0, param2=0},
		{name="vlf_ocean:fire_coral_block", prob=254, param2=0},
		{name="vlf_ocean:fire_coral_fan", prob=254, param2=4},
		{name="air", prob=0, param2=0},
		{name="vlf_ocean:fire_coral", prob=254, param2=1},
		{name="air", prob=0, param2=0},
	},
}
