schematic = {
	size = {x=5, y=8, z=5},
	yslice_prob = {
		{ypos=0, prob=254},
		{ypos=1, prob=254},
		{ypos=2, prob=254},
		{ypos=3, prob=254},
		{ypos=4, prob=254},
		{ypos=5, prob=254},
		{ypos=6, prob=254},
		{ypos=7, prob=254},
	},
	data = {
		{name="air", prob=0, param2=0},
		{name="air", prob=0, param2=0},
		{name="air", prob=0, param2=0},
		{name="air", prob=0, param2=0},
		{name="air", prob=0, param2=0},
		{name="air", prob=0, param2=0},
		{name="air", prob=0, param2=0},
		{name="air", prob=0, param2=0},
		{name="air", prob=0, param2=0},
		{name="air", prob=0, param2=0},
		{name="air", prob=0, param2=0},
		{name="air", prob=0, param2=0},
		{name="air", prob=0, param2=0},
		{name="air", prob=0, param2=0},
		{name="air", prob=0, param2=0},
		{name="air", prob=0, param2=0},
		{name="air", prob=0, param2=0},
		{name="air", prob=0, param2=0},
		{name="air", prob=0, param2=0},
		{name="air", prob=0, param2=0},
		{name="air", prob=0, param2=0},
		{name="vlf_trees:leaves_birch", prob=254, param2=128},
		{name="vlf_trees:leaves_birch", prob=254, param2=96},
		{name="vlf_trees:leaves_birch", prob=254, param2=128},
		{name="air", prob=0, param2=0},
		{name="air", prob=0, param2=0},
		{name="vlf_trees:leaves_birch", prob=254, param2=128},
		{name="vlf_trees:leaves_birch", prob=254, param2=96},
		{name="vlf_trees:leaves_birch", prob=254, param2=128},
		{name="air", prob=0, param2=0},
		{name="air", prob=0, param2=0},
		{name="air", prob=0, param2=0},
		{name="air", prob=0, param2=0},
		{name="air", prob=0, param2=0},
		{name="air", prob=0, param2=0},
		{name="air", prob=0, param2=0},
		{name="air", prob=0, param2=0},
		{name="air", prob=0, param2=0},
		{name="air", prob=0, param2=0},
		{name="air", prob=0, param2=0},
		{name="air", prob=0, param2=0},
		{name="air", prob=0, param2=0},
		{name="air", prob=0, param2=0},
		{name="air", prob=0, param2=0},
		{name="air", prob=0, param2=0},
		{name="air", prob=0, param2=0},
		{name="air", prob=0, param2=0},
		{name="air", prob=0, param2=0},
		{name="air", prob=0, param2=0},
		{name="air", prob=0, param2=0},
		{name="air", prob=0, param2=0},
		{name="air", prob=0, param2=0},
		{name="air", prob=0, param2=0},
		{name="air", prob=0, param2=0},
		{name="air", prob=0, param2=0},
		{name="air", prob=0, param2=0},
		{name="air", prob=0, param2=0},
		{name="vlf_beehives:bee_nest_5", prob=254, param2=0},
		{name="air", prob=0, param2=0},
		{name="air", prob=0, param2=0},
		{name="vlf_trees:leaves_birch", prob=254, param2=128},
		{name="vlf_trees:leaves_birch", prob=254, param2=96},
		{name="vlf_trees:leaves_birch", prob=254, param2=64},
		{name="vlf_trees:leaves_birch", prob=254, param2=96},
		{name="vlf_trees:leaves_birch", prob=254, param2=128},
		{name="vlf_trees:leaves_birch", prob=254, param2=128},
		{name="vlf_trees:leaves_birch", prob=254, param2=96},
		{name="vlf_trees:leaves_birch", prob=254, param2=64},
		{name="vlf_trees:leaves_birch", prob=254, param2=96},
		{name="vlf_trees:leaves_birch", prob=254, param2=128},
		{name="air", prob=0, param2=0},
		{name="vlf_trees:leaves_birch", prob=254, param2=128},
		{name="vlf_trees:leaves_birch", prob=254, param2=96},
		{name="air", prob=0, param2=0},
		{name="air", prob=0, param2=0},
		{name="air", prob=0, param2=0},
		{name="air", prob=0, param2=0},
		{name="vlf_trees:leaves_birch", prob=254, param2=128},
		{name="air", prob=0, param2=0},
		{name="air", prob=0, param2=0},
		{name="air", prob=0, param2=0},
		{name="air", prob=0, param2=0},
		{name="vlf_trees:tree_birch", prob=254, param2=0},
		{name="air", prob=0, param2=0},
		{name="air", prob=0, param2=0},
		{name="air", prob=0, param2=0},
		{name="air", prob=0, param2=0},
		{name="vlf_trees:tree_birch", prob=254, param2=0},
		{name="air", prob=0, param2=0},
		{name="air", prob=0, param2=0},
		{name="air", prob=0, param2=0},
		{name="air", prob=0, param2=0},
		{name="vlf_trees:tree_birch", prob=254, param2=0},
		{name="air", prob=0, param2=0},
		{name="air", prob=0, param2=0},
		{name="air", prob=0, param2=0},
		{name="air", prob=0, param2=0},
		{name="vlf_trees:tree_birch", prob=254, param2=0},
		{name="air", prob=0, param2=0},
		{name="air", prob=0, param2=0},
		{name="vlf_trees:leaves_birch", prob=254, param2=96},
		{name="vlf_trees:leaves_birch", prob=254, param2=64},
		{name="vlf_trees:tree_birch", prob=254, param2=0},
		{name="vlf_trees:leaves_birch", prob=254, param2=64},
		{name="vlf_trees:leaves_birch", prob=254, param2=96},
		{name="vlf_trees:leaves_birch", prob=254, param2=96},
		{name="vlf_trees:leaves_birch", prob=254, param2=64},
		{name="vlf_trees:tree_birch", prob=254, param2=0},
		{name="vlf_trees:leaves_birch", prob=254, param2=64},
		{name="vlf_trees:leaves_birch", prob=254, param2=96},
		{name="air", prob=0, param2=0},
		{name="vlf_trees:leaves_birch", prob=254, param2=96},
		{name="vlf_trees:leaves_birch", prob=254, param2=64},
		{name="vlf_trees:leaves_birch", prob=254, param2=96},
		{name="air", prob=0, param2=0},
		{name="air", prob=0, param2=0},
		{name="vlf_trees:leaves_birch", prob=254, param2=128},
		{name="vlf_trees:leaves_birch", prob=254, param2=96},
		{name="vlf_trees:leaves_birch", prob=254, param2=128},
		{name="air", prob=0, param2=0},
		{name="air", prob=0, param2=0},
		{name="air", prob=0, param2=0},
		{name="air", prob=0, param2=0},
		{name="air", prob=0, param2=0},
		{name="air", prob=0, param2=0},
		{name="air", prob=0, param2=0},
		{name="air", prob=0, param2=0},
		{name="air", prob=0, param2=0},
		{name="air", prob=0, param2=0},
		{name="air", prob=0, param2=0},
		{name="air", prob=0, param2=0},
		{name="air", prob=0, param2=0},
		{name="air", prob=0, param2=0},
		{name="air", prob=0, param2=0},
		{name="air", prob=0, param2=0},
		{name="air", prob=0, param2=0},
		{name="air", prob=0, param2=0},
		{name="air", prob=0, param2=0},
		{name="air", prob=0, param2=0},
		{name="air", prob=0, param2=0},
		{name="vlf_trees:leaves_birch", prob=254, param2=128},
		{name="vlf_trees:leaves_birch", prob=254, param2=96},
		{name="vlf_trees:leaves_birch", prob=254, param2=64},
		{name="vlf_trees:leaves_birch", prob=254, param2=96},
		{name="vlf_trees:leaves_birch", prob=254, param2=128},
		{name="vlf_trees:leaves_birch", prob=254, param2=128},
		{name="vlf_trees:leaves_birch", prob=254, param2=96},
		{name="vlf_trees:leaves_birch", prob=254, param2=64},
		{name="vlf_trees:leaves_birch", prob=254, param2=96},
		{name="vlf_trees:leaves_birch", prob=254, param2=128},
		{name="air", prob=0, param2=0},
		{name="vlf_trees:leaves_birch", prob=254, param2=128},
		{name="vlf_trees:leaves_birch", prob=254, param2=96},
		{name="vlf_trees:leaves_birch", prob=254, param2=128},
		{name="air", prob=0, param2=0},
		{name="air", prob=0, param2=0},
		{name="air", prob=0, param2=0},
		{name="vlf_trees:leaves_birch", prob=254, param2=128},
		{name="air", prob=0, param2=0},
		{name="air", prob=0, param2=0},
		{name="air", prob=0, param2=0},
		{name="air", prob=0, param2=0},
		{name="air", prob=0, param2=0},
		{name="air", prob=0, param2=0},
		{name="air", prob=0, param2=0},
		{name="air", prob=0, param2=0},
		{name="air", prob=0, param2=0},
		{name="air", prob=0, param2=0},
		{name="air", prob=0, param2=0},
		{name="air", prob=0, param2=0},
		{name="air", prob=0, param2=0},
		{name="air", prob=0, param2=0},
		{name="air", prob=0, param2=0},
		{name="air", prob=0, param2=0},
		{name="air", prob=0, param2=0},
		{name="air", prob=0, param2=0},
		{name="air", prob=0, param2=0},
		{name="air", prob=0, param2=0},
		{name="air", prob=0, param2=0},
		{name="air", prob=0, param2=0},
		{name="air", prob=0, param2=0},
		{name="vlf_trees:leaves_birch", prob=254, param2=128},
		{name="vlf_trees:leaves_birch", prob=254, param2=96},
		{name="vlf_trees:leaves_birch", prob=254, param2=128},
		{name="air", prob=0, param2=0},
		{name="air", prob=0, param2=0},
		{name="vlf_trees:leaves_birch", prob=254, param2=128},
		{name="vlf_trees:leaves_birch", prob=254, param2=96},
		{name="vlf_trees:leaves_birch", prob=254, param2=128},
		{name="air", prob=0, param2=0},
		{name="air", prob=0, param2=0},
		{name="air", prob=0, param2=0},
		{name="air", prob=0, param2=0},
		{name="air", prob=0, param2=0},
		{name="air", prob=0, param2=0},
		{name="air", prob=0, param2=0},
		{name="air", prob=0, param2=0},
		{name="air", prob=0, param2=0},
		{name="air", prob=0, param2=0},
		{name="air", prob=0, param2=0},
	},
}
