schematic = {
	size = {x=9, y=6, z=7},
	yslice_prob = {
		{ypos=0, prob=254},
		{ypos=1, prob=254},
		{ypos=2, prob=254},
		{ypos=3, prob=254},
		{ypos=4, prob=254},
		{ypos=5, prob=254},
	},
	data = {
		{name="air", prob=0, param2=0},
		{name="air", prob=0, param2=0},
		{name="air", prob=0, param2=0},
		{name="air", prob=0, param2=0},
		{name="air", prob=0, param2=0},
		{name="air", prob=0, param2=0},
		{name="air", prob=0, param2=0},
		{name="air", prob=0, param2=0},
		{name="air", prob=0, param2=0},
		{name="air", prob=0, param2=0},
		{name="air", prob=0, param2=0},
		{name="air", prob=0, param2=0},
		{name="air", prob=0, param2=0},
		{name="air", prob=0, param2=0},
		{name="air", prob=0, param2=0},
		{name="air", prob=0, param2=0},
		{name="air", prob=0, param2=0},
		{name="air", prob=0, param2=0},
		{name="air", prob=0, param2=0},
		{name="air", prob=0, param2=0},
		{name="air", prob=0, param2=0},
		{name="air", prob=0, param2=0},
		{name="air", prob=0, param2=0},
		{name="air", prob=0, param2=0},
		{name="air", prob=0, param2=0},
		{name="air", prob=0, param2=0},
		{name="air", prob=0, param2=0},
		{name="air", prob=254, param2=0},
		{name="air", prob=254, param2=0},
		{name="air", prob=254, param2=0},
		{name="air", prob=254, param2=0},
		{name="air", prob=254, param2=0},
		{name="air", prob=254, param2=0},
		{name="air", prob=254, param2=0},
		{name="air", prob=254, param2=0},
		{name="air", prob=254, param2=0},
		{name="air", prob=254, param2=0},
		{name="air", prob=254, param2=0},
		{name="air", prob=254, param2=0},
		{name="air", prob=254, param2=0},
		{name="air", prob=254, param2=0},
		{name="air", prob=254, param2=0},
		{name="air", prob=254, param2=0},
		{name="air", prob=254, param2=0},
		{name="air", prob=254, param2=0},
		{name="vlf_stairs:stair_sprucewood_outer", prob=254, param2=1},
		{name="vlf_stairs:stair_sprucewood", prob=254, param2=0},
		{name="vlf_stairs:stair_sprucewood", prob=254, param2=0},
		{name="vlf_stairs:stair_sprucewood", prob=254, param2=0},
		{name="vlf_stairs:stair_sprucewood", prob=254, param2=0},
		{name="vlf_stairs:stair_sprucewood", prob=254, param2=0},
		{name="vlf_stairs:stair_sprucewood", prob=254, param2=0},
		{name="vlf_stairs:stair_sprucewood_outer", prob=254, param2=0},
		{name="air", prob=254, param2=0},
		{name="air", prob=0, param2=0},
		{name="vlf_core:tree", prob=254, param2=3},
		{name="air", prob=0, param2=0},
		{name="air", prob=0, param2=0},
		{name="air", prob=0, param2=0},
		{name="air", prob=0, param2=0},
		{name="vlf_core:tree", prob=254, param2=3},
		{name="air", prob=0, param2=0},
		{name="air", prob=0, param2=0},
		{name="air", prob=0, param2=0},
		{name="vlf_core:tree", prob=254, param2=3},
		{name="air", prob=0, param2=0},
		{name="air", prob=0, param2=0},
		{name="air", prob=0, param2=0},
		{name="air", prob=0, param2=0},
		{name="vlf_core:tree", prob=254, param2=3},
		{name="air", prob=0, param2=0},
		{name="air", prob=0, param2=0},
		{name="air", prob=0, param2=0},
		{name="vlf_core:tree", prob=254, param2=3},
		{name="vlf_core:sprucewood", prob=254, param2=0},
		{name="vlf_core:sprucewood", prob=254, param2=0},
		{name="vlf_core:sprucewood", prob=254, param2=0},
		{name="vlf_core:sprucewood", prob=254, param2=0},
		{name="vlf_core:tree", prob=254, param2=3},
		{name="vlf_core:sprucewood", prob=254, param2=0},
		{name="air", prob=0, param2=0},
		{name="air", prob=254, param2=0},
		{name="vlf_core:tree", prob=254, param2=3},
		{name="vlf_core:sprucewood", prob=254, param2=0},
		{name="vlf_core:sprucewood", prob=254, param2=0},
		{name="vlf_core:sprucewood", prob=254, param2=0},
		{name="vlf_core:sprucewood", prob=254, param2=0},
		{name="vlf_core:tree", prob=254, param2=3},
		{name="vlf_fences:fence", prob=254, param2=0},
		{name="air", prob=254, param2=0},
		{name="air", prob=254, param2=0},
		{name="vlf_core:tree", prob=254, param2=3},
		{name="air", prob=254, param2=0},
		{name="air", prob=254, param2=0},
		{name="air", prob=254, param2=0},
		{name="air", prob=254, param2=0},
		{name="vlf_core:tree", prob=254, param2=3},
		{name="air", prob=254, param2=0},
		{name="air", prob=254, param2=0},
		{name="vlf_stairs:stair_sprucewood", prob=254, param2=1},
		{name="vlf_core:sprucewood", prob=254, param2=0},
		{name="vlf_core:sprucewood", prob=254, param2=0},
		{name="vlf_core:sprucewood", prob=254, param2=0},
		{name="vlf_core:sprucewood", prob=254, param2=0},
		{name="vlf_core:sprucewood", prob=254, param2=0},
		{name="vlf_core:sprucewood", prob=254, param2=0},
		{name="vlf_stairs:stair_sprucewood", prob=254, param2=3},
		{name="air", prob=254, param2=0},
		{name="air", prob=0, param2=0},
		{name="air", prob=0, param2=0},
		{name="air", prob=0, param2=0},
		{name="air", prob=0, param2=0},
		{name="air", prob=0, param2=0},
		{name="air", prob=0, param2=0},
		{name="air", prob=0, param2=0},
		{name="air", prob=0, param2=0},
		{name="air", prob=0, param2=0},
		{name="air", prob=0, param2=0},
		{name="air", prob=0, param2=0},
		{name="air", prob=0, param2=0},
		{name="air", prob=0, param2=0},
		{name="air", prob=0, param2=0},
		{name="air", prob=0, param2=0},
		{name="air", prob=0, param2=0},
		{name="air", prob=0, param2=0},
		{name="air", prob=0, param2=0},
		{name="air", prob=0, param2=0},
		{name="vlf_core:sprucewood", prob=254, param2=0},
		{name="vlf_core:sprucewood", prob=254, param2=0},
		{name="vlf_core:sprucewood", prob=254, param2=0},
		{name="vlf_core:sprucewood", prob=254, param2=0},
		{name="vlf_core:sprucewood", prob=254, param2=0},
		{name="vlf_core:sprucewood", prob=254, param2=0},
		{name="vlf_core:sprucewood", prob=254, param2=0},
		{name="vlf_core:sprucewood", prob=254, param2=0},
		{name="air", prob=254, param2=0},
		{name="vlf_core:sprucewood", prob=254, param2=0},
		{name="vlf_crafting_table:crafting_table", prob=254, param2=3},
		{name="air", prob=254, param2=0},
		{name="air", prob=254, param2=0},
		{name="air", prob=254, param2=0},
		{name="air", prob=254, param2=0},
		{name="air", prob=254, param2=0},
		{name="air", prob=254, param2=0},
		{name="air", prob=254, param2=0},
		{name="air", prob=254, param2=0},
		{name="air", prob=254, param2=0},
		{name="air", prob=254, param2=0},
		{name="air", prob=254, param2=0},
		{name="air", prob=254, param2=0},
		{name="air", prob=254, param2=0},
		{name="air", prob=254, param2=0},
		{name="air", prob=254, param2=0},
		{name="vlf_stairs:stair_sprucewood", prob=254, param2=1},
		{name="vlf_core:sprucewood", prob=254, param2=0},
		{name="vlf_core:sprucewood", prob=254, param2=0},
		{name="vlf_core:sprucewood", prob=254, param2=0},
		{name="vlf_core:sprucewood", prob=254, param2=0},
		{name="vlf_core:sprucewood", prob=254, param2=0},
		{name="vlf_core:sprucewood", prob=254, param2=0},
		{name="vlf_stairs:stair_sprucewood", prob=254, param2=3},
		{name="air", prob=254, param2=0},
		{name="air", prob=0, param2=0},
		{name="air", prob=0, param2=0},
		{name="air", prob=0, param2=0},
		{name="air", prob=0, param2=0},
		{name="air", prob=0, param2=0},
		{name="air", prob=0, param2=0},
		{name="air", prob=0, param2=0},
		{name="air", prob=0, param2=0},
		{name="air", prob=0, param2=0},
		{name="air", prob=0, param2=0},
		{name="air", prob=0, param2=0},
		{name="air", prob=0, param2=0},
		{name="air", prob=0, param2=0},
		{name="air", prob=0, param2=0},
		{name="air", prob=0, param2=0},
		{name="air", prob=0, param2=0},
		{name="air", prob=0, param2=0},
		{name="air", prob=0, param2=0},
		{name="air", prob=0, param2=0},
		{name="vlf_core:sprucewood", prob=254, param2=0},
		{name="vlf_core:sprucewood", prob=254, param2=0},
		{name="vlf_core:sprucewood", prob=254, param2=0},
		{name="vlf_core:sprucewood", prob=254, param2=0},
		{name="vlf_core:sprucewood", prob=254, param2=0},
		{name="vlf_core:sprucewood", prob=254, param2=0},
		{name="vlf_core:sprucewood", prob=254, param2=0},
		{name="vlf_core:sprucewood", prob=254, param2=0},
		{name="air", prob=254, param2=0},
		{name="vlf_core:sprucewood", prob=254, param2=0},
		{name="vlf_cauldrons:cauldron", prob=254, param2=0},
		{name="air", prob=254, param2=0},
		{name="air", prob=254, param2=0},
		{name="air", prob=254, param2=0},
		{name="vlf_core:sprucewood", prob=254, param2=0},
		{name="air", prob=254, param2=0},
		{name="air", prob=254, param2=0},
		{name="air", prob=254, param2=0},
		{name="air", prob=254, param2=0},
		{name="air", prob=254, param2=0},
		{name="air", prob=254, param2=0},
		{name="air", prob=254, param2=0},
		{name="air", prob=254, param2=0},
		{name="vlf_core:sprucewood", prob=254, param2=0},
		{name="air", prob=254, param2=0},
		{name="air", prob=254, param2=0},
		{name="vlf_stairs:stair_sprucewood", prob=254, param2=1},
		{name="vlf_core:sprucewood", prob=254, param2=0},
		{name="vlf_core:sprucewood", prob=254, param2=0},
		{name="vlf_core:sprucewood", prob=254, param2=0},
		{name="vlf_core:sprucewood", prob=254, param2=0},
		{name="vlf_core:sprucewood", prob=254, param2=0},
		{name="vlf_core:sprucewood", prob=254, param2=0},
		{name="vlf_stairs:stair_sprucewood", prob=254, param2=3},
		{name="air", prob=254, param2=0},
		{name="air", prob=0, param2=0},
		{name="air", prob=0, param2=0},
		{name="air", prob=0, param2=0},
		{name="air", prob=0, param2=0},
		{name="air", prob=0, param2=0},
		{name="air", prob=0, param2=0},
		{name="air", prob=0, param2=0},
		{name="air", prob=0, param2=0},
		{name="air", prob=0, param2=0},
		{name="air", prob=0, param2=0},
		{name="air", prob=0, param2=0},
		{name="air", prob=0, param2=0},
		{name="air", prob=0, param2=0},
		{name="air", prob=0, param2=0},
		{name="air", prob=0, param2=0},
		{name="air", prob=0, param2=0},
		{name="air", prob=0, param2=0},
		{name="air", prob=0, param2=0},
		{name="air", prob=0, param2=0},
		{name="vlf_core:sprucewood", prob=254, param2=0},
		{name="vlf_core:sprucewood", prob=254, param2=0},
		{name="vlf_core:sprucewood", prob=254, param2=0},
		{name="vlf_core:sprucewood", prob=254, param2=0},
		{name="vlf_core:sprucewood", prob=254, param2=0},
		{name="vlf_core:sprucewood", prob=254, param2=0},
		{name="vlf_core:sprucewood", prob=254, param2=0},
		{name="vlf_core:sprucewood", prob=254, param2=0},
		{name="air", prob=254, param2=0},
		{name="vlf_core:sprucewood", prob=254, param2=0},
		{name="air", prob=254, param2=0},
		{name="air", prob=254, param2=0},
		{name="air", prob=254, param2=0},
		{name="air", prob=254, param2=0},
		{name="vlf_core:sprucewood", prob=254, param2=0},
		{name="air", prob=254, param2=0},
		{name="air", prob=254, param2=0},
		{name="air", prob=254, param2=0},
		{name="air", prob=254, param2=0},
		{name="air", prob=254, param2=0},
		{name="air", prob=254, param2=0},
		{name="air", prob=254, param2=0},
		{name="air", prob=254, param2=0},
		{name="air", prob=254, param2=0},
		{name="air", prob=254, param2=0},
		{name="air", prob=254, param2=0},
		{name="vlf_stairs:stair_sprucewood", prob=254, param2=1},
		{name="vlf_core:sprucewood", prob=254, param2=0},
		{name="vlf_core:sprucewood", prob=254, param2=0},
		{name="vlf_core:sprucewood", prob=254, param2=0},
		{name="vlf_core:sprucewood", prob=254, param2=0},
		{name="vlf_core:sprucewood", prob=254, param2=0},
		{name="vlf_core:sprucewood", prob=254, param2=0},
		{name="vlf_stairs:stair_sprucewood", prob=254, param2=3},
		{name="air", prob=254, param2=0},
		{name="air", prob=0, param2=0},
		{name="vlf_core:tree", prob=254, param2=3},
		{name="air", prob=0, param2=0},
		{name="air", prob=0, param2=0},
		{name="air", prob=0, param2=0},
		{name="air", prob=0, param2=0},
		{name="vlf_core:tree", prob=254, param2=3},
		{name="air", prob=0, param2=0},
		{name="air", prob=0, param2=0},
		{name="air", prob=0, param2=0},
		{name="vlf_core:tree", prob=254, param2=3},
		{name="air", prob=0, param2=0},
		{name="air", prob=0, param2=0},
		{name="air", prob=0, param2=0},
		{name="air", prob=0, param2=0},
		{name="vlf_core:tree", prob=254, param2=3},
		{name="air", prob=0, param2=0},
		{name="air", prob=0, param2=0},
		{name="air", prob=0, param2=0},
		{name="vlf_core:tree", prob=254, param2=3},
		{name="vlf_core:sprucewood", prob=254, param2=0},
		{name="vlf_core:sprucewood", prob=254, param2=0},
		{name="vlf_core:sprucewood", prob=254, param2=0},
		{name="vlf_core:sprucewood", prob=254, param2=0},
		{name="vlf_core:tree", prob=254, param2=3},
		{name="vlf_core:sprucewood", prob=254, param2=0},
		{name="air", prob=0, param2=0},
		{name="air", prob=254, param2=0},
		{name="vlf_core:tree", prob=254, param2=3},
		{name="vlf_core:sprucewood", prob=254, param2=0},
		{name="vlf_core:sprucewood", prob=254, param2=0},
		{name="vlf_core:sprucewood", prob=254, param2=0},
		{name="vlf_core:sprucewood", prob=254, param2=0},
		{name="vlf_core:tree", prob=254, param2=3},
		{name="vlf_fences:fence", prob=254, param2=0},
		{name="air", prob=254, param2=0},
		{name="air", prob=254, param2=0},
		{name="vlf_core:tree", prob=254, param2=3},
		{name="vlf_flowerpots:flower_pot", prob=254, param2=0},
		{name="air", prob=254, param2=0},
		{name="air", prob=254, param2=0},
		{name="air", prob=254, param2=0},
		{name="vlf_core:tree", prob=254, param2=3},
		{name="air", prob=254, param2=0},
		{name="air", prob=254, param2=0},
		{name="vlf_stairs:stair_sprucewood", prob=254, param2=1},
		{name="vlf_core:sprucewood", prob=254, param2=0},
		{name="vlf_core:sprucewood", prob=254, param2=0},
		{name="vlf_core:sprucewood", prob=254, param2=0},
		{name="vlf_core:sprucewood", prob=254, param2=0},
		{name="vlf_core:sprucewood", prob=254, param2=0},
		{name="vlf_core:sprucewood", prob=254, param2=0},
		{name="vlf_stairs:stair_sprucewood", prob=254, param2=3},
		{name="air", prob=254, param2=0},
		{name="air", prob=0, param2=0},
		{name="air", prob=0, param2=0},
		{name="air", prob=0, param2=0},
		{name="air", prob=0, param2=0},
		{name="air", prob=0, param2=0},
		{name="air", prob=0, param2=0},
		{name="air", prob=0, param2=0},
		{name="air", prob=0, param2=0},
		{name="air", prob=0, param2=0},
		{name="air", prob=0, param2=0},
		{name="air", prob=0, param2=0},
		{name="air", prob=0, param2=0},
		{name="air", prob=0, param2=0},
		{name="air", prob=0, param2=0},
		{name="air", prob=0, param2=0},
		{name="air", prob=0, param2=0},
		{name="air", prob=0, param2=0},
		{name="air", prob=0, param2=0},
		{name="air", prob=0, param2=0},
		{name="air", prob=0, param2=0},
		{name="air", prob=0, param2=0},
		{name="air", prob=0, param2=0},
		{name="air", prob=0, param2=0},
		{name="air", prob=0, param2=0},
		{name="air", prob=0, param2=0},
		{name="air", prob=0, param2=0},
		{name="air", prob=0, param2=0},
		{name="air", prob=254, param2=0},
		{name="air", prob=254, param2=0},
		{name="air", prob=254, param2=0},
		{name="air", prob=254, param2=0},
		{name="air", prob=254, param2=0},
		{name="air", prob=254, param2=0},
		{name="air", prob=254, param2=0},
		{name="air", prob=254, param2=0},
		{name="air", prob=254, param2=0},
		{name="air", prob=254, param2=0},
		{name="air", prob=254, param2=0},
		{name="air", prob=254, param2=0},
		{name="air", prob=254, param2=0},
		{name="air", prob=254, param2=0},
		{name="air", prob=254, param2=0},
		{name="air", prob=254, param2=0},
		{name="air", prob=254, param2=0},
		{name="air", prob=254, param2=0},
		{name="vlf_stairs:stair_sprucewood_outer", prob=254, param2=2},
		{name="vlf_stairs:stair_sprucewood", prob=254, param2=2},
		{name="vlf_stairs:stair_sprucewood", prob=254, param2=2},
		{name="vlf_stairs:stair_sprucewood", prob=254, param2=2},
		{name="vlf_stairs:stair_sprucewood", prob=254, param2=2},
		{name="vlf_stairs:stair_sprucewood", prob=254, param2=2},
		{name="vlf_stairs:stair_sprucewood", prob=254, param2=2},
		{name="vlf_stairs:stair_sprucewood_outer", prob=254, param2=3},
		{name="air", prob=254, param2=0},
	},
}
