schematic = {
	size = {x=2, y=3, z=2},
	yslice_prob = {
		{ypos=0, prob=254},
		{ypos=1, prob=202},
		{ypos=2, prob=254},
	},
	data = {
		{name="vlf_core:mossycobble", prob=254, param2=0},
		{name="vlf_core:mossycobble", prob=254, param2=0},
		{name="vlf_core:mossycobble", prob=254, param2=0},
		{name="vlf_core:mossycobble", prob=254, param2=0},
		{name="vlf_core:mossycobble", prob=170, param2=0},
		{name="vlf_core:mossycobble", prob=170, param2=0},
		{name="vlf_core:mossycobble", prob=254, param2=0},
		{name="vlf_core:mossycobble", prob=254, param2=0},
		{name="vlf_core:mossycobble", prob=254, param2=0},
		{name="vlf_core:mossycobble", prob=254, param2=0},
		{name="vlf_core:mossycobble", prob=170, param2=0},
		{name="vlf_core:mossycobble", prob=170, param2=0},
	},
}
