schematic = {
	size = {x=22, y=24, z=22},
	yslice_prob = {
		{ypos=0, prob=254},
		{ypos=1, prob=254},
		{ypos=2, prob=254},
		{ypos=3, prob=254},
		{ypos=4, prob=254},
		{ypos=5, prob=254},
		{ypos=6, prob=254},
		{ypos=7, prob=254},
		{ypos=8, prob=254},
		{ypos=9, prob=254},
		{ypos=10, prob=254},
		{ypos=11, prob=254},
		{ypos=12, prob=254},
		{ypos=13, prob=254},
		{ypos=14, prob=254},
		{ypos=15, prob=254},
		{ypos=16, prob=254},
		{ypos=17, prob=254},
		{ypos=18, prob=254},
		{ypos=19, prob=254},
		{ypos=20, prob=254},
		{ypos=21, prob=254},
		{ypos=22, prob=254},
		{ypos=23, prob=254},
	},
	data = {
		{name="vlf_core:sandstone", prob=254, param2=0},
		{name="vlf_core:sandstone", prob=254, param2=0},
		{name="vlf_core:sandstone", prob=254, param2=0},
		{name="vlf_core:sandstone", prob=254, param2=0},
		{name="vlf_core:sandstone", prob=254, param2=0},
		{name="vlf_core:sandstone", prob=254, param2=0},
		{name="vlf_core:sandstone", prob=254, param2=0},
		{name="vlf_core:sandstone", prob=254, param2=0},
		{name="vlf_core:sandstone", prob=254, param2=0},
		{name="vlf_core:sandstone", prob=254, param2=0},
		{name="vlf_core:sandstone", prob=254, param2=0},
		{name="vlf_core:sandstone", prob=254, param2=0},
		{name="vlf_core:sandstone", prob=254, param2=0},
		{name="vlf_core:sandstone", prob=254, param2=0},
		{name="vlf_core:sandstone", prob=254, param2=0},
		{name="vlf_core:sandstone", prob=254, param2=0},
		{name="vlf_core:sandstone", prob=254, param2=0},
		{name="vlf_core:sandstone", prob=254, param2=0},
		{name="vlf_core:sandstone", prob=254, param2=0},
		{name="vlf_core:sandstone", prob=254, param2=0},
		{name="vlf_core:sandstone", prob=254, param2=0},
		{name="vlf_core:sandstone", prob=254, param2=0},
		{name="vlf_core:sandstone", prob=254, param2=0},
		{name="vlf_core:sandstone", prob=254, param2=0},
		{name="vlf_core:sandstone", prob=254, param2=0},
		{name="vlf_core:sandstone", prob=254, param2=0},
		{name="vlf_core:sandstone", prob=254, param2=0},
		{name="vlf_core:sandstone", prob=254, param2=0},
		{name="vlf_core:sandstone", prob=254, param2=0},
		{name="vlf_core:sandstone", prob=254, param2=0},
		{name="vlf_core:sandstone", prob=254, param2=0},
		{name="vlf_core:sandstone", prob=254, param2=0},
		{name="vlf_core:sandstone", prob=254, param2=0},
		{name="vlf_core:sandstone", prob=254, param2=0},
		{name="vlf_core:sandstone", prob=254, param2=0},
		{name="vlf_core:sandstone", prob=254, param2=0},
		{name="vlf_core:sandstone", prob=254, param2=0},
		{name="vlf_core:sandstone", prob=254, param2=0},
		{name="vlf_core:sandstone", prob=254, param2=0},
		{name="vlf_core:sandstone", prob=254, param2=0},
		{name="vlf_core:sandstone", prob=254, param2=0},
		{name="vlf_core:sandstone", prob=254, param2=0},
		{name="vlf_core:sandstone", prob=254, param2=0},
		{name="vlf_core:sandstone", prob=254, param2=0},
		{name="vlf_core:sandstone", prob=254, param2=0},
		{name="vlf_core:sandstone", prob=254, param2=0},
		{name="vlf_core:sandstone", prob=254, param2=0},
		{name="vlf_core:sandstone", prob=254, param2=0},
		{name="vlf_core:sandstone", prob=254, param2=0},
		{name="vlf_core:sandstone", prob=254, param2=0},
		{name="vlf_core:sandstone", prob=254, param2=0},
		{name="vlf_core:sandstone", prob=254, param2=0},
		{name="vlf_core:sandstone", prob=254, param2=0},
		{name="vlf_core:sandstone", prob=254, param2=0},
		{name="vlf_core:sandstone", prob=254, param2=0},
		{name="vlf_core:sandstone", prob=254, param2=0},
		{name="vlf_core:sandstone", prob=254, param2=0},
		{name="vlf_core:sandstone", prob=254, param2=0},
		{name="vlf_core:sandstone", prob=254, param2=0},
		{name="vlf_core:sandstone", prob=254, param2=0},
		{name="vlf_core:sandstone", prob=254, param2=0},
		{name="vlf_core:sandstone", prob=254, param2=0},
		{name="vlf_core:sandstone", prob=254, param2=0},
		{name="vlf_core:sandstone", prob=254, param2=0},
		{name="vlf_core:sandstone", prob=254, param2=0},
		{name="vlf_core:sandstone", prob=254, param2=0},
		{name="vlf_core:sandstone", prob=254, param2=0},
		{name="vlf_core:sandstone", prob=254, param2=0},
		{name="vlf_core:sandstone", prob=254, param2=0},
		{name="vlf_core:sandstone", prob=254, param2=0},
		{name="vlf_core:sandstone", prob=254, param2=0},
		{name="vlf_core:sandstone", prob=254, param2=0},
		{name="vlf_core:sandstone", prob=254, param2=0},
		{name="vlf_core:sandstone", prob=254, param2=0},
		{name="vlf_core:sandstone", prob=254, param2=0},
		{name="vlf_core:sandstone", prob=254, param2=0},
		{name="vlf_core:sandstone", prob=254, param2=0},
		{name="vlf_core:sandstone", prob=254, param2=0},
		{name="vlf_core:sandstone", prob=254, param2=0},
		{name="vlf_core:sandstone", prob=254, param2=0},
		{name="vlf_core:sandstone", prob=254, param2=0},
		{name="vlf_core:sandstone", prob=254, param2=0},
		{name="vlf_core:sandstone", prob=254, param2=0},
		{name="vlf_core:sandstone", prob=254, param2=0},
		{name="vlf_core:sandstone", prob=254, param2=0},
		{name="vlf_core:sandstone", prob=254, param2=0},
		{name="vlf_core:sandstone", prob=254, param2=0},
		{name="vlf_core:sandstone", prob=254, param2=0},
		{name="vlf_core:sandstone", prob=254, param2=0},
		{name="vlf_core:sandstone", prob=254, param2=0},
		{name="vlf_core:sandstone", prob=254, param2=0},
		{name="vlf_core:sandstone", prob=254, param2=0},
		{name="vlf_core:sandstone", prob=254, param2=0},
		{name="vlf_core:sandstone", prob=254, param2=0},
		{name="vlf_core:sandstone", prob=254, param2=0},
		{name="vlf_core:sandstone", prob=254, param2=0},
		{name="vlf_core:sandstone", prob=254, param2=0},
		{name="vlf_core:sandstone", prob=254, param2=0},
		{name="vlf_core:sandstone", prob=254, param2=0},
		{name="vlf_core:sandstone", prob=254, param2=0},
		{name="vlf_core:sandstone", prob=254, param2=0},
		{name="vlf_core:sandstone", prob=254, param2=0},
		{name="vlf_core:sandstone", prob=254, param2=0},
		{name="vlf_core:sandstone", prob=254, param2=0},
		{name="vlf_core:sandstone", prob=254, param2=0},
		{name="vlf_core:sandstone", prob=254, param2=0},
		{name="vlf_core:sandstone", prob=254, param2=0},
		{name="vlf_core:sandstone", prob=254, param2=0},
		{name="vlf_core:sandstone", prob=254, param2=0},
		{name="vlf_core:sandstone", prob=254, param2=0},
		{name="vlf_core:sandstone", prob=254, param2=0},
		{name="vlf_core:sandstone", prob=254, param2=0},
		{name="vlf_core:sandstone", prob=254, param2=0},
		{name="vlf_core:sandstone", prob=254, param2=0},
		{name="vlf_core:sandstone", prob=254, param2=0},
		{name="vlf_core:sandstone", prob=254, param2=0},
		{name="vlf_core:sandstone", prob=254, param2=0},
		{name="vlf_core:sandstone", prob=254, param2=0},
		{name="vlf_core:sandstone", prob=254, param2=0},
		{name="vlf_core:sandstone", prob=254, param2=0},
		{name="vlf_core:sandstone", prob=254, param2=0},
		{name="vlf_core:sandstone", prob=254, param2=0},
		{name="vlf_core:sandstone", prob=254, param2=0},
		{name="vlf_core:sandstone", prob=254, param2=0},
		{name="vlf_core:sandstone", prob=254, param2=0},
		{name="vlf_core:sandstone", prob=254, param2=0},
		{name="vlf_core:sandstone", prob=254, param2=0},
		{name="vlf_core:sandstone", prob=254, param2=0},
		{name="vlf_core:sandstone", prob=254, param2=0},
		{name="vlf_core:sandstone", prob=254, param2=0},
		{name="vlf_core:sandstone", prob=254, param2=0},
		{name="vlf_core:sandstone", prob=254, param2=0},
		{name="vlf_core:sandstone", prob=254, param2=0},
		{name="vlf_core:sandstone", prob=254, param2=0},
		{name="vlf_core:sandstone", prob=254, param2=0},
		{name="vlf_core:sandstone", prob=254, param2=0},
		{name="vlf_core:sandstone", prob=254, param2=0},
		{name="vlf_core:sandstone", prob=254, param2=0},
		{name="vlf_core:sandstone", prob=254, param2=0},
		{name="vlf_core:sandstone", prob=254, param2=0},
		{name="vlf_core:sandstone", prob=254, param2=0},
		{name="vlf_core:sandstone", prob=254, param2=0},
		{name="vlf_core:sandstone", prob=254, param2=0},
		{name="vlf_core:sandstone", prob=254, param2=0},
		{name="vlf_core:sandstone", prob=254, param2=0},
		{name="vlf_core:sandstone", prob=254, param2=0},
		{name="vlf_core:sandstone", prob=254, param2=0},
		{name="vlf_core:sandstone", prob=254, param2=0},
		{name="vlf_core:sandstone", prob=254, param2=0},
		{name="vlf_core:sandstone", prob=254, param2=0},
		{name="vlf_core:sandstone", prob=254, param2=0},
		{name="vlf_core:sandstone", prob=254, param2=0},
		{name="vlf_core:sandstone", prob=254, param2=0},
		{name="vlf_core:sandstone", prob=254, param2=0},
		{name="vlf_core:sandstone", prob=254, param2=0},
		{name="vlf_core:sandstone", prob=254, param2=0},
		{name="vlf_core:sandstone", prob=254, param2=0},
		{name="vlf_core:sandstone", prob=254, param2=0},
		{name="vlf_core:sandstone", prob=254, param2=0},
		{name="vlf_core:sandstone", prob=254, param2=0},
		{name="vlf_core:sandstone", prob=254, param2=0},
		{name="vlf_core:sandstone", prob=254, param2=0},
		{name="vlf_core:sandstone", prob=254, param2=0},
		{name="vlf_core:sandstone", prob=254, param2=0},
		{name="vlf_core:sandstone", prob=254, param2=0},
		{name="vlf_core:sandstone", prob=254, param2=0},
		{name="vlf_core:sandstone", prob=254, param2=0},
		{name="vlf_core:sandstone", prob=254, param2=0},
		{name="vlf_core:sandstone", prob=254, param2=0},
		{name="vlf_core:sandstone", prob=254, param2=0},
		{name="vlf_core:sandstone", prob=254, param2=0},
		{name="vlf_core:sandstone", prob=254, param2=0},
		{name="vlf_core:sandstone", prob=254, param2=0},
		{name="vlf_core:sandstone", prob=254, param2=0},
		{name="vlf_core:sandstone", prob=254, param2=0},
		{name="vlf_core:sandstone", prob=254, param2=0},
		{name="vlf_core:sandstone", prob=254, param2=0},
		{name="vlf_core:sandstone", prob=254, param2=0},
		{name="vlf_core:sandstone", prob=254, param2=0},
		{name="vlf_core:sandstone", prob=254, param2=0},
		{name="vlf_core:sandstone", prob=254, param2=0},
		{name="vlf_core:sandstone", prob=254, param2=0},
		{name="vlf_core:sandstone", prob=254, param2=0},
		{name="vlf_core:sandstone", prob=254, param2=0},
		{name="vlf_core:sandstone", prob=254, param2=0},
		{name="vlf_core:sandstone", prob=254, param2=0},
		{name="vlf_core:sandstone", prob=254, param2=0},
		{name="vlf_core:sandstone", prob=254, param2=0},
		{name="vlf_core:sandstone", prob=254, param2=0},
		{name="vlf_core:sandstone", prob=254, param2=0},
		{name="vlf_core:sandstone", prob=254, param2=0},
		{name="vlf_core:sandstone", prob=254, param2=0},
		{name="vlf_core:sandstone", prob=254, param2=0},
		{name="vlf_core:sandstone", prob=254, param2=0},
		{name="vlf_core:sandstone", prob=254, param2=0},
		{name="vlf_core:sandstone", prob=254, param2=0},
		{name="vlf_core:sandstone", prob=254, param2=0},
		{name="vlf_core:sandstone", prob=254, param2=0},
		{name="vlf_core:sandstone", prob=254, param2=0},
		{name="vlf_core:sandstone", prob=254, param2=0},
		{name="vlf_core:sandstone", prob=254, param2=0},
		{name="vlf_core:sandstone", prob=254, param2=0},
		{name="vlf_core:sandstone", prob=254, param2=0},
		{name="vlf_core:sandstone", prob=254, param2=0},
		{name="vlf_core:sandstone", prob=254, param2=0},
		{name="vlf_core:sandstone", prob=254, param2=0},
		{name="vlf_core:sandstone", prob=254, param2=0},
		{name="vlf_core:sandstone", prob=254, param2=0},
		{name="vlf_core:sandstone", prob=254, param2=0},
		{name="vlf_core:sandstone", prob=254, param2=0},
		{name="vlf_core:sandstone", prob=254, param2=0},
		{name="vlf_core:sandstone", prob=254, param2=0},
		{name="vlf_core:sandstone", prob=254, param2=0},
		{name="vlf_core:sandstone", prob=254, param2=0},
		{name="vlf_core:sandstone", prob=254, param2=0},
		{name="vlf_core:sandstone", prob=254, param2=0},
		{name="vlf_core:sandstone", prob=254, param2=0},
		{name="vlf_core:sandstone", prob=254, param2=0},
		{name="vlf_core:sandstone", prob=254, param2=0},
		{name="vlf_core:sandstone", prob=254, param2=0},
		{name="vlf_core:sand", prob=254, param2=0},
		{name="vlf_core:sand", prob=254, param2=0},
		{name="vlf_core:sand", prob=254, param2=0},
		{name="vlf_core:sand", prob=254, param2=0},
		{name="vlf_core:sand", prob=254, param2=0},
		{name="vlf_core:sand", prob=254, param2=0},
		{name="vlf_core:sand", prob=254, param2=0},
		{name="vlf_core:sand", prob=254, param2=0},
		{name="vlf_core:sand", prob=254, param2=0},
		{name="vlf_core:sand", prob=254, param2=0},
		{name="vlf_core:sand", prob=254, param2=0},
		{name="vlf_core:sand", prob=254, param2=0},
		{name="vlf_core:sand", prob=254, param2=0},
		{name="vlf_core:sand", prob=254, param2=0},
		{name="vlf_core:sand", prob=254, param2=0},
		{name="vlf_core:sand", prob=254, param2=0},
		{name="vlf_core:sand", prob=254, param2=0},
		{name="vlf_core:sand", prob=254, param2=0},
		{name="vlf_core:sand", prob=254, param2=0},
		{name="vlf_core:sand", prob=254, param2=0},
		{name="vlf_core:sand", prob=254, param2=0},
		{name="vlf_core:sand", prob=254, param2=0},
		{name="vlf_core:sand", prob=254, param2=0},
		{name="vlf_core:sand", prob=254, param2=0},
		{name="vlf_core:sand", prob=254, param2=0},
		{name="vlf_core:sand", prob=254, param2=0},
		{name="vlf_core:sand", prob=254, param2=0},
		{name="vlf_core:sand", prob=254, param2=0},
		{name="vlf_core:sand", prob=254, param2=0},
		{name="vlf_core:sand", prob=254, param2=0},
		{name="vlf_core:sand", prob=254, param2=0},
		{name="vlf_core:sand", prob=254, param2=0},
		{name="vlf_core:sand", prob=254, param2=0},
		{name="vlf_core:sand", prob=254, param2=0},
		{name="vlf_core:sand", prob=254, param2=0},
		{name="vlf_core:sand", prob=254, param2=0},
		{name="vlf_core:sand", prob=254, param2=0},
		{name="vlf_core:sand", prob=254, param2=0},
		{name="vlf_core:sand", prob=254, param2=0},
		{name="vlf_core:sand", prob=254, param2=0},
		{name="vlf_core:sand", prob=254, param2=0},
		{name="vlf_core:sand", prob=254, param2=0},
		{name="vlf_core:sand", prob=254, param2=0},
		{name="vlf_core:sand", prob=254, param2=0},
		{name="air", prob=0, param2=0},
		{name="air", prob=0, param2=0},
		{name="air", prob=0, param2=0},
		{name="air", prob=0, param2=0},
		{name="air", prob=0, param2=0},
		{name="air", prob=0, param2=0},
		{name="air", prob=0, param2=0},
		{name="air", prob=0, param2=0},
		{name="air", prob=0, param2=0},
		{name="air", prob=0, param2=0},
		{name="air", prob=0, param2=0},
		{name="air", prob=0, param2=0},
		{name="air", prob=0, param2=0},
		{name="air", prob=0, param2=0},
		{name="air", prob=0, param2=0},
		{name="air", prob=0, param2=0},
		{name="air", prob=0, param2=0},
		{name="air", prob=0, param2=0},
		{name="air", prob=0, param2=0},
		{name="air", prob=0, param2=0},
		{name="air", prob=0, param2=0},
		{name="air", prob=0, param2=0},
		{name="air", prob=0, param2=0},
		{name="air", prob=0, param2=0},
		{name="air", prob=0, param2=0},
		{name="air", prob=0, param2=0},
		{name="air", prob=0, param2=0},
		{name="air", prob=0, param2=0},
		{name="air", prob=0, param2=0},
		{name="air", prob=0, param2=0},
		{name="air", prob=0, param2=0},
		{name="air", prob=0, param2=0},
		{name="air", prob=0, param2=0},
		{name="air", prob=0, param2=0},
		{name="air", prob=0, param2=0},
		{name="air", prob=0, param2=0},
		{name="air", prob=0, param2=0},
		{name="air", prob=0, param2=0},
		{name="air", prob=0, param2=0},
		{name="air", prob=0, param2=0},
		{name="air", prob=0, param2=0},
		{name="air", prob=0, param2=0},
		{name="air", prob=0, param2=0},
		{name="air", prob=0, param2=0},
		{name="air", prob=0, param2=0},
		{name="air", prob=0, param2=0},
		{name="air", prob=0, param2=0},
		{name="air", prob=0, param2=0},
		{name="air", prob=0, param2=0},
		{name="air", prob=0, param2=0},
		{name="air", prob=0, param2=0},
		{name="air", prob=0, param2=0},
		{name="air", prob=0, param2=0},
		{name="air", prob=0, param2=0},
		{name="air", prob=0, param2=0},
		{name="air", prob=0, param2=0},
		{name="air", prob=0, param2=0},
		{name="air", prob=0, param2=0},
		{name="air", prob=0, param2=0},
		{name="air", prob=0, param2=0},
		{name="air", prob=0, param2=0},
		{name="air", prob=0, param2=0},
		{name="air", prob=0, param2=0},
		{name="air", prob=0, param2=0},
		{name="air", prob=0, param2=0},
		{name="air", prob=0, param2=0},
		{name="air", prob=0, param2=0},
		{name="air", prob=0, param2=0},
		{name="air", prob=0, param2=0},
		{name="air", prob=0, param2=0},
		{name="air", prob=0, param2=0},
		{name="air", prob=0, param2=0},
		{name="air", prob=0, param2=0},
		{name="air", prob=0, param2=0},
		{name="air", prob=0, param2=0},
		{name="air", prob=0, param2=0},
		{name="air", prob=0, param2=0},
		{name="air", prob=0, param2=0},
		{name="air", prob=0, param2=0},
		{name="air", prob=0, param2=0},
		{name="air", prob=0, param2=0},
		{name="air", prob=0, param2=0},
		{name="air", prob=0, param2=0},
		{name="air", prob=0, param2=0},
		{name="air", prob=0, param2=0},
		{name="air", prob=0, param2=0},
		{name="air", prob=0, param2=0},
		{name="air", prob=0, param2=0},
		{name="air", prob=0, param2=0},
		{name="air", prob=0, param2=0},
		{name="air", prob=0, param2=0},
		{name="air", prob=0, param2=0},
		{name="air", prob=0, param2=0},
		{name="air", prob=0, param2=0},
		{name="air", prob=0, param2=0},
		{name="air", prob=0, param2=0},
		{name="air", prob=0, param2=0},
		{name="air", prob=0, param2=0},
		{name="air", prob=0, param2=0},
		{name="air", prob=0, param2=0},
		{name="air", prob=0, param2=0},
		{name="air", prob=0, param2=0},
		{name="air", prob=0, param2=0},
		{name="air", prob=0, param2=0},
		{name="air", prob=0, param2=0},
		{name="air", prob=0, param2=0},
		{name="air", prob=0, param2=0},
		{name="air", prob=0, param2=0},
		{name="air", prob=0, param2=0},
		{name="air", prob=0, param2=0},
		{name="air", prob=0, param2=0},
		{name="air", prob=0, param2=0},
		{name="air", prob=0, param2=0},
		{name="air", prob=0, param2=0},
		{name="air", prob=0, param2=0},
		{name="air", prob=0, param2=0},
		{name="air", prob=0, param2=0},
		{name="air", prob=0, param2=0},
		{name="air", prob=0, param2=0},
		{name="air", prob=0, param2=0},
		{name="air", prob=0, param2=0},
		{name="air", prob=0, param2=0},
		{name="air", prob=0, param2=0},
		{name="air", prob=0, param2=0},
		{name="air", prob=0, param2=0},
		{name="air", prob=0, param2=0},
		{name="air", prob=0, param2=0},
		{name="air", prob=0, param2=0},
		{name="air", prob=0, param2=0},
		{name="air", prob=0, param2=0},
		{name="air", prob=0, param2=0},
		{name="air", prob=0, param2=0},
		{name="air", prob=0, param2=0},
		{name="air", prob=0, param2=0},
		{name="air", prob=0, param2=0},
		{name="air", prob=0, param2=0},
		{name="air", prob=0, param2=0},
		{name="air", prob=0, param2=0},
		{name="air", prob=0, param2=0},
		{name="air", prob=0, param2=0},
		{name="air", prob=0, param2=0},
		{name="air", prob=0, param2=0},
		{name="air", prob=0, param2=0},
		{name="air", prob=0, param2=0},
		{name="air", prob=0, param2=0},
		{name="air", prob=0, param2=0},
		{name="air", prob=0, param2=0},
		{name="air", prob=0, param2=0},
		{name="air", prob=0, param2=0},
		{name="air", prob=0, param2=0},
		{name="air", prob=0, param2=0},
		{name="air", prob=0, param2=0},
		{name="air", prob=0, param2=0},
		{name="air", prob=0, param2=0},
		{name="air", prob=0, param2=0},
		{name="air", prob=0, param2=0},
		{name="air", prob=0, param2=0},
		{name="air", prob=0, param2=0},
		{name="air", prob=0, param2=0},
		{name="air", prob=0, param2=0},
		{name="air", prob=0, param2=0},
		{name="air", prob=0, param2=0},
		{name="air", prob=0, param2=0},
		{name="air", prob=0, param2=0},
		{name="air", prob=0, param2=0},
		{name="air", prob=0, param2=0},
		{name="air", prob=0, param2=0},
		{name="air", prob=0, param2=0},
		{name="air", prob=0, param2=0},
		{name="air", prob=0, param2=0},
		{name="air", prob=0, param2=0},
		{name="air", prob=0, param2=0},
		{name="air", prob=0, param2=0},
		{name="air", prob=0, param2=0},
		{name="air", prob=0, param2=0},
		{name="air", prob=0, param2=0},
		{name="air", prob=0, param2=0},
		{name="air", prob=0, param2=0},
		{name="air", prob=0, param2=0},
		{name="air", prob=0, param2=0},
		{name="air", prob=0, param2=0},
		{name="air", prob=0, param2=0},
		{name="air", prob=0, param2=0},
		{name="air", prob=0, param2=0},
		{name="air", prob=0, param2=0},
		{name="air", prob=0, param2=0},
		{name="air", prob=0, param2=0},
		{name="air", prob=0, param2=0},
		{name="air", prob=0, param2=0},
		{name="air", prob=0, param2=0},
		{name="air", prob=0, param2=0},
		{name="air", prob=0, param2=0},
		{name="air", prob=0, param2=0},
		{name="air", prob=0, param2=0},
		{name="air", prob=0, param2=0},
		{name="air", prob=0, param2=0},
		{name="air", prob=0, param2=0},
		{name="air", prob=0, param2=0},
		{name="air", prob=0, param2=0},
		{name="air", prob=0, param2=0},
		{name="air", prob=0, param2=0},
		{name="air", prob=0, param2=0},
		{name="air", prob=0, param2=0},
		{name="air", prob=0, param2=0},
		{name="air", prob=0, param2=0},
		{name="air", prob=0, param2=0},
		{name="air", prob=0, param2=0},
		{name="air", prob=0, param2=0},
		{name="air", prob=0, param2=0},
		{name="air", prob=0, param2=0},
		{name="air", prob=0, param2=0},
		{name="air", prob=0, param2=0},
		{name="air", prob=0, param2=0},
		{name="air", prob=0, param2=0},
		{name="air", prob=0, param2=0},
		{name="air", prob=0, param2=0},
		{name="air", prob=0, param2=0},
		{name="air", prob=0, param2=0},
		{name="air", prob=0, param2=0},
		{name="air", prob=0, param2=0},
		{name="air", prob=0, param2=0},
		{name="air", prob=0, param2=0},
		{name="air", prob=0, param2=0},
		{name="air", prob=0, param2=0},
		{name="air", prob=0, param2=0},
		{name="air", prob=0, param2=0},
		{name="air", prob=0, param2=0},
		{name="air", prob=0, param2=0},
		{name="air", prob=0, param2=0},
		{name="air", prob=0, param2=0},
		{name="air", prob=0, param2=0},
		{name="air", prob=0, param2=0},
		{name="air", prob=0, param2=0},
		{name="air", prob=0, param2=0},
		{name="air", prob=0, param2=0},
		{name="air", prob=0, param2=0},
		{name="air", prob=0, param2=0},
		{name="air", prob=0, param2=0},
		{name="air", prob=0, param2=0},
		{name="air", prob=0, param2=0},
		{name="air", prob=0, param2=0},
		{name="air", prob=0, param2=0},
		{name="air", prob=0, param2=0},
		{name="air", prob=0, param2=0},
		{name="air", prob=0, param2=0},
		{name="air", prob=0, param2=0},
		{name="air", prob=0, param2=0},
		{name="air", prob=0, param2=0},
		{name="air", prob=0, param2=0},
		{name="air", prob=0, param2=0},
		{name="air", prob=0, param2=0},
		{name="air", prob=0, param2=0},
		{name="air", prob=0, param2=0},
		{name="air", prob=0, param2=0},
		{name="air", prob=0, param2=0},
		{name="air", prob=0, param2=0},
		{name="air", prob=0, param2=0},
		{name="air", prob=0, param2=0},
		{name="air", prob=0, param2=0},
		{name="air", prob=0, param2=0},
		{name="air", prob=0, param2=0},
		{name="air", prob=0, param2=0},
		{name="air", prob=0, param2=0},
		{name="air", prob=0, param2=0},
		{name="vlf_core:sandstone", prob=254, param2=0},
		{name="vlf_core:sandstone", prob=254, param2=0},
		{name="vlf_core:sandstone", prob=254, param2=0},
		{name="vlf_core:sandstone", prob=254, param2=0},
		{name="vlf_core:sandstone", prob=254, param2=0},
		{name="vlf_core:sandstone", prob=254, param2=0},
		{name="vlf_core:sandstone", prob=254, param2=0},
		{name="vlf_core:sandstone", prob=254, param2=0},
		{name="vlf_core:sandstone", prob=254, param2=0},
		{name="vlf_core:sandstone", prob=254, param2=0},
		{name="vlf_core:sandstone", prob=254, param2=0},
		{name="vlf_core:sandstone", prob=254, param2=0},
		{name="vlf_core:sandstone", prob=254, param2=0},
		{name="vlf_core:sandstone", prob=254, param2=0},
		{name="vlf_core:sandstone", prob=254, param2=0},
		{name="vlf_core:sandstone", prob=254, param2=0},
		{name="vlf_core:sandstone", prob=254, param2=0},
		{name="vlf_core:sandstone", prob=254, param2=0},
		{name="vlf_core:sandstone", prob=254, param2=0},
		{name="vlf_core:sandstone", prob=254, param2=0},
		{name="vlf_core:sandstone", prob=254, param2=0},
		{name="vlf_core:sandstone", prob=254, param2=0},
		{name="vlf_core:sandstone", prob=254, param2=0},
		{name="vlf_core:sandstone", prob=254, param2=0},
		{name="vlf_core:sandstone", prob=254, param2=0},
		{name="vlf_core:sandstone", prob=254, param2=0},
		{name="vlf_core:sandstone", prob=254, param2=0},
		{name="vlf_core:sandstone", prob=254, param2=0},
		{name="vlf_core:sandstone", prob=254, param2=0},
		{name="vlf_core:sandstone", prob=254, param2=0},
		{name="vlf_core:sandstone", prob=254, param2=0},
		{name="vlf_core:sandstone", prob=254, param2=0},
		{name="vlf_core:sandstone", prob=254, param2=0},
		{name="vlf_core:sandstone", prob=254, param2=0},
		{name="vlf_core:sandstone", prob=254, param2=0},
		{name="vlf_core:sandstone", prob=254, param2=0},
		{name="vlf_core:sandstone", prob=254, param2=0},
		{name="vlf_core:sandstone", prob=254, param2=0},
		{name="vlf_core:sandstone", prob=254, param2=0},
		{name="vlf_core:sandstone", prob=254, param2=0},
		{name="vlf_core:sandstone", prob=254, param2=0},
		{name="vlf_core:sandstone", prob=254, param2=0},
		{name="vlf_core:sandstone", prob=254, param2=0},
		{name="vlf_core:sandstone", prob=254, param2=0},
		{name="vlf_core:sandstone", prob=254, param2=0},
		{name="vlf_core:sandstone", prob=254, param2=0},
		{name="vlf_core:sandstone", prob=254, param2=0},
		{name="vlf_core:sandstone", prob=254, param2=0},
		{name="vlf_core:sandstone", prob=254, param2=0},
		{name="vlf_core:sandstone", prob=254, param2=0},
		{name="vlf_core:sandstone", prob=254, param2=0},
		{name="vlf_core:sandstone", prob=254, param2=0},
		{name="vlf_core:sandstone", prob=254, param2=0},
		{name="vlf_core:sandstone", prob=254, param2=0},
		{name="vlf_core:sandstone", prob=254, param2=0},
		{name="vlf_core:sandstone", prob=254, param2=0},
		{name="vlf_core:sandstone", prob=254, param2=0},
		{name="vlf_core:sandstone", prob=254, param2=0},
		{name="vlf_core:sandstone", prob=254, param2=0},
		{name="vlf_core:sandstone", prob=254, param2=0},
		{name="vlf_core:sandstone", prob=254, param2=0},
		{name="vlf_core:sandstone", prob=254, param2=0},
		{name="vlf_core:sandstone", prob=254, param2=0},
		{name="vlf_core:sandstone", prob=254, param2=0},
		{name="vlf_core:sandstone", prob=254, param2=0},
		{name="vlf_core:sandstone", prob=254, param2=0},
		{name="vlf_core:sandstone", prob=254, param2=0},
		{name="vlf_core:sandstone", prob=254, param2=0},
		{name="vlf_core:sandstone", prob=254, param2=0},
		{name="vlf_core:sandstone", prob=254, param2=0},
		{name="vlf_core:sandstone", prob=254, param2=0},
		{name="vlf_core:sandstone", prob=254, param2=0},
		{name="vlf_core:sandstone", prob=254, param2=0},
		{name="vlf_core:sandstone", prob=254, param2=0},
		{name="vlf_core:sandstone", prob=254, param2=0},
		{name="vlf_core:sandstone", prob=254, param2=0},
		{name="vlf_core:sandstone", prob=254, param2=0},
		{name="vlf_core:sandstone", prob=254, param2=0},
		{name="vlf_core:sandstone", prob=254, param2=0},
		{name="vlf_core:sandstone", prob=254, param2=0},
		{name="vlf_core:sandstone", prob=254, param2=0},
		{name="vlf_core:sandstone", prob=254, param2=0},
		{name="vlf_core:sandstone", prob=254, param2=0},
		{name="vlf_core:sandstone", prob=254, param2=0},
		{name="vlf_core:sandstone", prob=254, param2=0},
		{name="vlf_core:sandstone", prob=254, param2=0},
		{name="vlf_core:sandstone", prob=254, param2=0},
		{name="vlf_core:sandstone", prob=254, param2=0},
		{name="vlf_core:sandstone", prob=254, param2=0},
		{name="vlf_core:sandstone", prob=254, param2=0},
		{name="vlf_core:sandstone", prob=254, param2=0},
		{name="vlf_core:sandstone", prob=254, param2=0},
		{name="vlf_core:sandstone", prob=254, param2=0},
		{name="vlf_core:sandstone", prob=254, param2=0},
		{name="vlf_core:sandstone", prob=254, param2=0},
		{name="vlf_core:sandstone", prob=254, param2=0},
		{name="vlf_core:sandstone", prob=254, param2=0},
		{name="vlf_core:sandstone", prob=254, param2=0},
		{name="vlf_core:sandstone", prob=254, param2=0},
		{name="vlf_core:sandstone", prob=254, param2=0},
		{name="vlf_core:sandstone", prob=254, param2=0},
		{name="vlf_core:sandstone", prob=254, param2=0},
		{name="vlf_core:sandstone", prob=254, param2=0},
		{name="vlf_core:sandstone", prob=254, param2=0},
		{name="vlf_core:sandstone", prob=254, param2=0},
		{name="vlf_core:sandstone", prob=254, param2=0},
		{name="vlf_core:sandstone", prob=254, param2=0},
		{name="vlf_core:sandstone", prob=254, param2=0},
		{name="vlf_core:sandstone", prob=254, param2=0},
		{name="vlf_core:sandstone", prob=254, param2=0},
		{name="vlf_core:sandstone", prob=254, param2=0},
		{name="vlf_core:sandstone", prob=254, param2=0},
		{name="vlf_core:sandstone", prob=254, param2=0},
		{name="vlf_core:sandstone", prob=254, param2=0},
		{name="vlf_core:sandstone", prob=254, param2=0},
		{name="vlf_core:sandstone", prob=254, param2=0},
		{name="vlf_core:sandstone", prob=254, param2=0},
		{name="vlf_core:sandstone", prob=254, param2=0},
		{name="vlf_core:sandstone", prob=254, param2=0},
		{name="vlf_core:sandstone", prob=254, param2=0},
		{name="vlf_core:sandstone", prob=254, param2=0},
		{name="vlf_core:sandstone", prob=254, param2=0},
		{name="vlf_core:sandstone", prob=254, param2=0},
		{name="vlf_core:sandstone", prob=254, param2=0},
		{name="vlf_core:sandstone", prob=254, param2=0},
		{name="vlf_core:sandstone", prob=254, param2=0},
		{name="vlf_core:sandstone", prob=254, param2=0},
		{name="vlf_core:sandstone", prob=254, param2=0},
		{name="vlf_core:sandstone", prob=254, param2=0},
		{name="vlf_core:sandstone", prob=254, param2=0},
		{name="vlf_core:sandstone", prob=254, param2=0},
		{name="vlf_core:sandstone", prob=254, param2=0},
		{name="vlf_core:sandstone", prob=254, param2=0},
		{name="vlf_core:sandstone", prob=254, param2=0},
		{name="vlf_core:sandstone", prob=254, param2=0},
		{name="vlf_core:sandstone", prob=254, param2=0},
		{name="vlf_core:sandstone", prob=254, param2=0},
		{name="vlf_core:sandstone", prob=254, param2=0},
		{name="vlf_core:sandstone", prob=254, param2=0},
		{name="vlf_core:sandstone", prob=254, param2=0},
		{name="vlf_core:sandstone", prob=254, param2=0},
		{name="vlf_core:sandstone", prob=254, param2=0},
		{name="vlf_core:sandstone", prob=254, param2=0},
		{name="vlf_core:sandstone", prob=254, param2=0},
		{name="vlf_core:sandstone", prob=254, param2=0},
		{name="vlf_core:sandstone", prob=254, param2=0},
		{name="vlf_core:sandstone", prob=254, param2=0},
		{name="vlf_core:sandstone", prob=254, param2=0},
		{name="vlf_core:sandstone", prob=254, param2=0},
		{name="vlf_core:sandstone", prob=254, param2=0},
		{name="vlf_core:sandstone", prob=254, param2=0},
		{name="vlf_core:sandstone", prob=254, param2=0},
		{name="vlf_core:sandstone", prob=254, param2=0},
		{name="vlf_core:sandstone", prob=254, param2=0},
		{name="vlf_core:sandstone", prob=254, param2=0},
		{name="vlf_core:sandstone", prob=254, param2=0},
		{name="vlf_core:sandstone", prob=254, param2=0},
		{name="vlf_core:sandstone", prob=254, param2=0},
		{name="vlf_core:sandstone", prob=254, param2=0},
		{name="vlf_core:sandstone", prob=254, param2=0},
		{name="vlf_core:sandstone", prob=254, param2=0},
		{name="vlf_core:sandstone", prob=254, param2=0},
		{name="vlf_core:sandstone", prob=254, param2=0},
		{name="vlf_core:sandstone", prob=254, param2=0},
		{name="vlf_core:sandstone", prob=254, param2=0},
		{name="vlf_core:sandstone", prob=254, param2=0},
		{name="vlf_core:sandstone", prob=254, param2=0},
		{name="vlf_core:sandstone", prob=254, param2=0},
		{name="vlf_core:sandstone", prob=254, param2=0},
		{name="vlf_core:sandstone", prob=254, param2=0},
		{name="vlf_core:sandstone", prob=254, param2=0},
		{name="vlf_core:sandstone", prob=254, param2=0},
		{name="vlf_core:sandstone", prob=254, param2=0},
		{name="vlf_core:sandstone", prob=254, param2=0},
		{name="vlf_core:sandstone", prob=254, param2=0},
		{name="vlf_core:sandstone", prob=254, param2=0},
		{name="vlf_core:sandstone", prob=254, param2=0},
		{name="vlf_core:sandstone", prob=254, param2=0},
		{name="vlf_core:sandstone", prob=254, param2=0},
		{name="vlf_core:sandstone", prob=254, param2=0},
		{name="vlf_core:sandstone", prob=254, param2=0},
		{name="vlf_core:sandstone", prob=254, param2=0},
		{name="vlf_core:sandstone", prob=254, param2=0},
		{name="vlf_core:sandstone", prob=254, param2=0},
		{name="vlf_core:sandstone", prob=254, param2=0},
		{name="vlf_core:sandstone", prob=254, param2=0},
		{name="vlf_core:sandstone", prob=254, param2=0},
		{name="vlf_core:sandstone", prob=254, param2=0},
		{name="vlf_core:sandstone", prob=254, param2=0},
		{name="vlf_core:sandstone", prob=254, param2=0},
		{name="vlf_core:sandstone", prob=254, param2=0},
		{name="vlf_core:sandstone", prob=254, param2=0},
		{name="vlf_core:sandstone", prob=254, param2=0},
		{name="vlf_core:sandstone", prob=254, param2=0},
		{name="vlf_core:sandstone", prob=254, param2=0},
		{name="vlf_core:sandstone", prob=254, param2=0},
		{name="vlf_core:sandstone", prob=254, param2=0},
		{name="vlf_core:sandstone", prob=254, param2=0},
		{name="vlf_core:sandstone", prob=254, param2=0},
		{name="vlf_core:sandstone", prob=254, param2=0},
		{name="vlf_core:sandstone", prob=254, param2=0},
		{name="vlf_core:sandstone", prob=254, param2=0},
		{name="vlf_core:sandstone", prob=254, param2=0},
		{name="vlf_core:sandstone", prob=254, param2=0},
		{name="vlf_core:sandstone", prob=254, param2=0},
		{name="vlf_core:sandstone", prob=254, param2=0},
		{name="vlf_core:sandstone", prob=254, param2=0},
		{name="vlf_core:sandstone", prob=254, param2=0},
		{name="vlf_core:sandstone", prob=254, param2=0},
		{name="vlf_core:sandstone", prob=254, param2=0},
		{name="vlf_core:sandstone", prob=254, param2=0},
		{name="vlf_core:sandstone", prob=254, param2=0},
		{name="vlf_core:sandstone", prob=254, param2=0},
		{name="vlf_core:sandstone", prob=254, param2=0},
		{name="vlf_core:sandstone", prob=254, param2=0},
		{name="vlf_core:sandstone", prob=254, param2=0},
		{name="vlf_core:sandstone", prob=254, param2=0},
		{name="vlf_core:sandstone", prob=254, param2=0},
		{name="vlf_core:sandstone", prob=254, param2=0},
		{name="vlf_core:sandstone", prob=254, param2=0},
		{name="vlf_core:sand", prob=254, param2=0},
		{name="vlf_core:sand", prob=254, param2=0},
		{name="vlf_core:sand", prob=254, param2=0},
		{name="vlf_core:sand", prob=254, param2=0},
		{name="vlf_core:sand", prob=254, param2=0},
		{name="vlf_core:sand", prob=254, param2=0},
		{name="vlf_core:sand", prob=254, param2=0},
		{name="vlf_core:sand", prob=254, param2=0},
		{name="vlf_core:sandstone", prob=254, param2=0},
		{name="vlf_core:sandstone", prob=254, param2=0},
		{name="vlf_core:sandstone", prob=254, param2=0},
		{name="vlf_core:sandstone", prob=254, param2=0},
		{name="vlf_core:sandstone", prob=254, param2=0},
		{name="vlf_core:sand", prob=254, param2=0},
		{name="vlf_core:sand", prob=254, param2=0},
		{name="vlf_core:sand", prob=254, param2=0},
		{name="vlf_core:sand", prob=254, param2=0},
		{name="vlf_core:sand", prob=254, param2=0},
		{name="vlf_core:sand", prob=254, param2=0},
		{name="vlf_core:sand", prob=254, param2=0},
		{name="vlf_core:sand", prob=254, param2=0},
		{name="vlf_core:sand", prob=254, param2=0},
		{name="vlf_core:sand", prob=254, param2=0},
		{name="vlf_core:sand", prob=254, param2=0},
		{name="vlf_core:sand", prob=254, param2=0},
		{name="vlf_core:sand", prob=254, param2=0},
		{name="vlf_core:sand", prob=254, param2=0},
		{name="vlf_core:sand", prob=254, param2=0},
		{name="vlf_core:sand", prob=254, param2=0},
		{name="vlf_core:sand", prob=254, param2=0},
		{name="vlf_core:sandstone", prob=254, param2=0},
		{name="vlf_core:sandstone", prob=254, param2=0},
		{name="vlf_core:sandstone", prob=254, param2=0},
		{name="vlf_core:sandstone", prob=254, param2=0},
		{name="vlf_core:sandstone", prob=254, param2=0},
		{name="vlf_core:sand", prob=254, param2=0},
		{name="vlf_core:sand", prob=254, param2=0},
		{name="vlf_core:sand", prob=254, param2=0},
		{name="vlf_core:sand", prob=254, param2=0},
		{name="vlf_core:sand", prob=254, param2=0},
		{name="vlf_core:sand", prob=254, param2=0},
		{name="vlf_core:sand", prob=254, param2=0},
		{name="vlf_core:sand", prob=254, param2=0},
		{name="vlf_core:sand", prob=254, param2=0},
		{name="air", prob=0, param2=0},
		{name="air", prob=0, param2=0},
		{name="air", prob=0, param2=0},
		{name="air", prob=0, param2=0},
		{name="air", prob=0, param2=0},
		{name="air", prob=0, param2=0},
		{name="air", prob=0, param2=0},
		{name="air", prob=0, param2=0},
		{name="vlf_core:sandstone", prob=254, param2=0},
		{name="vlf_core:sandstone", prob=254, param2=0},
		{name="vlf_core:sandstone", prob=254, param2=0},
		{name="vlf_core:sandstone", prob=254, param2=0},
		{name="vlf_core:sandstone", prob=254, param2=0},
		{name="air", prob=0, param2=0},
		{name="air", prob=0, param2=0},
		{name="air", prob=0, param2=0},
		{name="air", prob=0, param2=0},
		{name="air", prob=0, param2=0},
		{name="air", prob=0, param2=0},
		{name="air", prob=0, param2=0},
		{name="air", prob=0, param2=0},
		{name="air", prob=0, param2=0},
		{name="air", prob=0, param2=0},
		{name="air", prob=0, param2=0},
		{name="air", prob=0, param2=0},
		{name="air", prob=0, param2=0},
		{name="air", prob=0, param2=0},
		{name="air", prob=0, param2=0},
		{name="air", prob=0, param2=0},
		{name="air", prob=0, param2=0},
		{name="vlf_core:sandstone", prob=254, param2=0},
		{name="vlf_core:sandstonesmooth", prob=254, param2=0},
		{name="vlf_core:sandstonesmooth", prob=254, param2=0},
		{name="vlf_core:sandstonesmooth", prob=254, param2=0},
		{name="vlf_core:sandstone", prob=254, param2=0},
		{name="air", prob=0, param2=0},
		{name="air", prob=0, param2=0},
		{name="air", prob=0, param2=0},
		{name="air", prob=0, param2=0},
		{name="air", prob=0, param2=0},
		{name="air", prob=0, param2=0},
		{name="air", prob=0, param2=0},
		{name="air", prob=0, param2=0},
		{name="air", prob=0, param2=0},
		{name="air", prob=0, param2=0},
		{name="air", prob=0, param2=0},
		{name="air", prob=0, param2=0},
		{name="air", prob=0, param2=0},
		{name="air", prob=0, param2=0},
		{name="air", prob=0, param2=0},
		{name="air", prob=0, param2=0},
		{name="air", prob=0, param2=0},
		{name="vlf_core:sandstone", prob=254, param2=0},
		{name="vlf_core:sandstonesmooth", prob=254, param2=0},
		{name="vlf_colorblocks:hardened_clay_red", prob=254, param2=0},
		{name="vlf_core:sandstonesmooth", prob=254, param2=0},
		{name="vlf_core:sandstone", prob=254, param2=0},
		{name="air", prob=0, param2=0},
		{name="air", prob=0, param2=0},
		{name="air", prob=0, param2=0},
		{name="air", prob=0, param2=0},
		{name="air", prob=0, param2=0},
		{name="air", prob=0, param2=0},
		{name="air", prob=0, param2=0},
		{name="air", prob=0, param2=0},
		{name="air", prob=0, param2=0},
		{name="air", prob=0, param2=0},
		{name="air", prob=0, param2=0},
		{name="air", prob=0, param2=0},
		{name="air", prob=0, param2=0},
		{name="air", prob=0, param2=0},
		{name="air", prob=0, param2=0},
		{name="air", prob=0, param2=0},
		{name="air", prob=0, param2=0},
		{name="vlf_core:sandstone", prob=254, param2=0},
		{name="vlf_core:sandstonesmooth", prob=254, param2=0},
		{name="vlf_colorblocks:hardened_clay_red", prob=254, param2=0},
		{name="vlf_core:sandstonesmooth", prob=254, param2=0},
		{name="vlf_core:sandstone", prob=254, param2=0},
		{name="air", prob=0, param2=0},
		{name="air", prob=0, param2=0},
		{name="air", prob=0, param2=0},
		{name="air", prob=0, param2=0},
		{name="air", prob=0, param2=0},
		{name="air", prob=0, param2=0},
		{name="air", prob=0, param2=0},
		{name="air", prob=0, param2=0},
		{name="air", prob=0, param2=0},
		{name="air", prob=0, param2=0},
		{name="air", prob=0, param2=0},
		{name="air", prob=0, param2=0},
		{name="air", prob=0, param2=0},
		{name="air", prob=0, param2=0},
		{name="air", prob=0, param2=0},
		{name="air", prob=0, param2=0},
		{name="air", prob=0, param2=0},
		{name="vlf_core:sandstone", prob=254, param2=0},
		{name="vlf_colorblocks:hardened_clay_red", prob=254, param2=0},
		{name="vlf_core:sandstonecarved", prob=254, param2=0},
		{name="vlf_colorblocks:hardened_clay_red", prob=254, param2=0},
		{name="vlf_core:sandstone", prob=254, param2=0},
		{name="air", prob=0, param2=0},
		{name="air", prob=0, param2=0},
		{name="air", prob=0, param2=0},
		{name="air", prob=0, param2=0},
		{name="air", prob=0, param2=0},
		{name="air", prob=0, param2=0},
		{name="air", prob=0, param2=0},
		{name="air", prob=0, param2=0},
		{name="air", prob=0, param2=0},
		{name="air", prob=0, param2=0},
		{name="air", prob=0, param2=0},
		{name="air", prob=0, param2=0},
		{name="air", prob=0, param2=0},
		{name="air", prob=0, param2=0},
		{name="air", prob=0, param2=0},
		{name="air", prob=0, param2=0},
		{name="air", prob=0, param2=0},
		{name="vlf_core:sandstone", prob=254, param2=0},
		{name="vlf_core:sandstonesmooth", prob=254, param2=0},
		{name="vlf_colorblocks:hardened_clay_red", prob=254, param2=0},
		{name="vlf_core:sandstonesmooth", prob=254, param2=0},
		{name="vlf_core:sandstone", prob=254, param2=0},
		{name="air", prob=0, param2=0},
		{name="air", prob=0, param2=0},
		{name="air", prob=0, param2=0},
		{name="air", prob=0, param2=0},
		{name="air", prob=0, param2=0},
		{name="air", prob=0, param2=0},
		{name="air", prob=0, param2=0},
		{name="air", prob=0, param2=0},
		{name="air", prob=0, param2=0},
		{name="air", prob=0, param2=0},
		{name="air", prob=0, param2=0},
		{name="air", prob=0, param2=0},
		{name="air", prob=0, param2=0},
		{name="air", prob=0, param2=0},
		{name="air", prob=0, param2=0},
		{name="air", prob=0, param2=0},
		{name="air", prob=0, param2=0},
		{name="vlf_core:sandstone", prob=254, param2=0},
		{name="vlf_core:sandstonesmooth", prob=254, param2=0},
		{name="vlf_colorblocks:hardened_clay_red", prob=254, param2=0},
		{name="vlf_core:sandstonesmooth", prob=254, param2=0},
		{name="vlf_core:sandstone", prob=254, param2=0},
		{name="air", prob=0, param2=0},
		{name="air", prob=0, param2=0},
		{name="air", prob=0, param2=0},
		{name="air", prob=0, param2=0},
		{name="air", prob=0, param2=0},
		{name="air", prob=0, param2=0},
		{name="air", prob=0, param2=0},
		{name="air", prob=0, param2=0},
		{name="air", prob=0, param2=0},
		{name="air", prob=0, param2=0},
		{name="air", prob=0, param2=0},
		{name="air", prob=0, param2=0},
		{name="air", prob=0, param2=0},
		{name="air", prob=0, param2=0},
		{name="air", prob=0, param2=0},
		{name="air", prob=0, param2=0},
		{name="air", prob=0, param2=0},
		{name="vlf_core:sandstone", prob=254, param2=0},
		{name="vlf_core:sandstonesmooth", prob=254, param2=0},
		{name="vlf_core:sandstonesmooth", prob=254, param2=0},
		{name="vlf_core:sandstonesmooth", prob=254, param2=0},
		{name="vlf_core:sandstone", prob=254, param2=0},
		{name="air", prob=0, param2=0},
		{name="air", prob=0, param2=0},
		{name="air", prob=0, param2=0},
		{name="air", prob=0, param2=0},
		{name="air", prob=0, param2=0},
		{name="air", prob=0, param2=0},
		{name="air", prob=0, param2=0},
		{name="air", prob=0, param2=0},
		{name="air", prob=0, param2=0},
		{name="air", prob=0, param2=0},
		{name="air", prob=0, param2=0},
		{name="air", prob=0, param2=0},
		{name="air", prob=0, param2=0},
		{name="air", prob=0, param2=0},
		{name="air", prob=0, param2=0},
		{name="air", prob=0, param2=0},
		{name="air", prob=0, param2=0},
		{name="vlf_core:sandstone", prob=254, param2=0},
		{name="vlf_core:sandstone", prob=254, param2=0},
		{name="vlf_core:sandstone", prob=254, param2=0},
		{name="vlf_core:sandstone", prob=254, param2=0},
		{name="vlf_core:sandstone", prob=254, param2=0},
		{name="air", prob=0, param2=0},
		{name="air", prob=0, param2=0},
		{name="air", prob=0, param2=0},
		{name="air", prob=0, param2=0},
		{name="air", prob=0, param2=0},
		{name="air", prob=0, param2=0},
		{name="air", prob=0, param2=0},
		{name="air", prob=0, param2=0},
		{name="air", prob=0, param2=0},
		{name="air", prob=0, param2=0},
		{name="air", prob=0, param2=0},
		{name="air", prob=0, param2=0},
		{name="air", prob=0, param2=0},
		{name="air", prob=0, param2=0},
		{name="air", prob=0, param2=0},
		{name="air", prob=0, param2=0},
		{name="air", prob=0, param2=0},
		{name="vlf_stairs:stair_sandstone_outer", prob=254, param2=1},
		{name="vlf_stairs:stair_sandstone", prob=254, param2=0},
		{name="vlf_stairs:stair_sandstone", prob=254, param2=0},
		{name="vlf_stairs:stair_sandstone", prob=254, param2=0},
		{name="vlf_stairs:stair_sandstone_outer", prob=254, param2=0},
		{name="air", prob=0, param2=0},
		{name="air", prob=0, param2=0},
		{name="air", prob=0, param2=0},
		{name="air", prob=0, param2=0},
		{name="air", prob=0, param2=0},
		{name="air", prob=0, param2=0},
		{name="air", prob=0, param2=0},
		{name="air", prob=0, param2=0},
		{name="air", prob=0, param2=0},
		{name="air", prob=0, param2=0},
		{name="air", prob=0, param2=0},
		{name="air", prob=0, param2=0},
		{name="air", prob=0, param2=0},
		{name="air", prob=0, param2=0},
		{name="air", prob=0, param2=0},
		{name="air", prob=0, param2=0},
		{name="air", prob=0, param2=0},
		{name="air", prob=0, param2=0},
		{name="air", prob=0, param2=0},
		{name="air", prob=0, param2=0},
		{name="air", prob=0, param2=0},
		{name="air", prob=0, param2=0},
		{name="air", prob=0, param2=0},
		{name="air", prob=0, param2=0},
		{name="air", prob=0, param2=0},
		{name="air", prob=0, param2=0},
		{name="air", prob=0, param2=0},
		{name="air", prob=0, param2=0},
		{name="air", prob=0, param2=0},
		{name="air", prob=0, param2=0},
		{name="air", prob=0, param2=0},
		{name="air", prob=0, param2=0},
		{name="air", prob=0, param2=0},
		{name="air", prob=0, param2=0},
		{name="air", prob=0, param2=0},
		{name="air", prob=0, param2=0},
		{name="air", prob=0, param2=0},
		{name="air", prob=0, param2=0},
		{name="air", prob=0, param2=0},
		{name="air", prob=0, param2=0},
		{name="air", prob=0, param2=0},
		{name="air", prob=0, param2=0},
		{name="air", prob=0, param2=0},
		{name="air", prob=0, param2=0},
		{name="air", prob=0, param2=0},
		{name="air", prob=0, param2=0},
		{name="air", prob=0, param2=0},
		{name="air", prob=0, param2=0},
		{name="air", prob=0, param2=0},
		{name="air", prob=0, param2=0},
		{name="air", prob=0, param2=0},
		{name="air", prob=0, param2=0},
		{name="air", prob=0, param2=0},
		{name="vlf_core:sandstone", prob=254, param2=0},
		{name="vlf_core:sandstone", prob=254, param2=0},
		{name="vlf_core:sandstone", prob=254, param2=0},
		{name="vlf_core:sandstone", prob=254, param2=0},
		{name="vlf_core:sandstone", prob=254, param2=0},
		{name="vlf_core:sandstone", prob=254, param2=0},
		{name="vlf_core:sandstone", prob=254, param2=0},
		{name="vlf_core:sandstone", prob=254, param2=0},
		{name="vlf_core:sandstone", prob=254, param2=0},
		{name="vlf_core:sandstone", prob=254, param2=0},
		{name="vlf_core:sandstone", prob=254, param2=0},
		{name="vlf_core:sandstone", prob=254, param2=0},
		{name="vlf_core:sandstone", prob=254, param2=0},
		{name="vlf_core:sandstone", prob=254, param2=0},
		{name="vlf_core:sandstone", prob=254, param2=0},
		{name="vlf_core:sandstone", prob=254, param2=0},
		{name="vlf_core:sandstone", prob=254, param2=0},
		{name="vlf_core:sandstone", prob=254, param2=0},
		{name="vlf_core:sandstone", prob=254, param2=0},
		{name="vlf_core:sandstone", prob=254, param2=0},
		{name="vlf_core:sandstone", prob=254, param2=0},
		{name="vlf_core:sandstone", prob=254, param2=0},
		{name="vlf_core:sandstone", prob=254, param2=0},
		{name="vlf_core:sandstone", prob=254, param2=0},
		{name="vlf_core:sandstone", prob=254, param2=0},
		{name="vlf_core:sandstone", prob=254, param2=0},
		{name="vlf_core:sandstone", prob=254, param2=0},
		{name="vlf_core:sandstone", prob=254, param2=0},
		{name="vlf_core:sandstone", prob=254, param2=0},
		{name="vlf_core:sandstone", prob=254, param2=0},
		{name="vlf_core:sandstone", prob=254, param2=0},
		{name="vlf_core:sandstone", prob=254, param2=0},
		{name="vlf_core:sandstone", prob=254, param2=0},
		{name="vlf_core:sandstone", prob=254, param2=0},
		{name="vlf_core:sandstone", prob=254, param2=0},
		{name="vlf_core:sandstone", prob=254, param2=0},
		{name="vlf_core:sandstone", prob=254, param2=0},
		{name="vlf_core:sandstone", prob=254, param2=0},
		{name="vlf_core:sandstone", prob=254, param2=0},
		{name="vlf_core:sandstone", prob=254, param2=0},
		{name="vlf_core:sandstone", prob=254, param2=0},
		{name="vlf_core:sandstone", prob=254, param2=0},
		{name="vlf_core:sandstone", prob=254, param2=0},
		{name="vlf_core:sandstone", prob=254, param2=0},
		{name="vlf_core:sandstone", prob=254, param2=0},
		{name="vlf_core:sandstone", prob=254, param2=0},
		{name="vlf_core:sandstone", prob=254, param2=0},
		{name="vlf_core:sandstone", prob=254, param2=0},
		{name="vlf_core:sandstone", prob=254, param2=0},
		{name="vlf_core:sandstone", prob=254, param2=0},
		{name="vlf_core:sandstone", prob=254, param2=0},
		{name="vlf_core:sandstone", prob=254, param2=0},
		{name="vlf_core:sandstone", prob=254, param2=0},
		{name="vlf_core:sandstone", prob=254, param2=0},
		{name="vlf_core:sandstone", prob=254, param2=0},
		{name="vlf_core:sandstone", prob=254, param2=0},
		{name="vlf_core:sandstone", prob=254, param2=0},
		{name="vlf_core:sandstone", prob=254, param2=0},
		{name="vlf_core:sandstone", prob=254, param2=0},
		{name="vlf_core:sandstone", prob=254, param2=0},
		{name="vlf_core:sandstone", prob=254, param2=0},
		{name="vlf_core:sandstone", prob=254, param2=0},
		{name="vlf_core:sandstone", prob=254, param2=0},
		{name="vlf_core:sandstone", prob=254, param2=0},
		{name="vlf_core:sandstone", prob=254, param2=0},
		{name="vlf_core:sandstone", prob=254, param2=0},
		{name="vlf_core:sandstone", prob=254, param2=0},
		{name="vlf_core:sandstone", prob=254, param2=0},
		{name="vlf_core:sandstone", prob=254, param2=0},
		{name="vlf_core:sandstone", prob=254, param2=0},
		{name="vlf_core:sandstone", prob=254, param2=0},
		{name="vlf_core:sandstone", prob=254, param2=0},
		{name="vlf_core:sandstone", prob=254, param2=0},
		{name="vlf_core:sandstone", prob=254, param2=0},
		{name="vlf_core:sandstone", prob=254, param2=0},
		{name="vlf_core:sandstone", prob=254, param2=0},
		{name="vlf_core:sandstone", prob=254, param2=0},
		{name="vlf_core:sandstone", prob=254, param2=0},
		{name="vlf_core:sandstone", prob=254, param2=0},
		{name="vlf_core:sandstone", prob=254, param2=0},
		{name="vlf_core:sandstone", prob=254, param2=0},
		{name="vlf_core:sandstone", prob=254, param2=0},
		{name="vlf_core:sandstone", prob=254, param2=0},
		{name="vlf_core:sandstone", prob=254, param2=0},
		{name="vlf_core:sandstone", prob=254, param2=0},
		{name="vlf_core:sandstone", prob=254, param2=0},
		{name="vlf_core:sandstone", prob=254, param2=0},
		{name="vlf_core:sandstone", prob=254, param2=0},
		{name="vlf_core:sandstone", prob=254, param2=0},
		{name="vlf_core:sandstone", prob=254, param2=0},
		{name="vlf_core:sandstone", prob=254, param2=0},
		{name="vlf_core:sandstone", prob=254, param2=0},
		{name="vlf_core:sandstone", prob=254, param2=0},
		{name="vlf_core:sandstone", prob=254, param2=0},
		{name="vlf_core:sandstone", prob=254, param2=0},
		{name="vlf_core:sandstone", prob=254, param2=0},
		{name="vlf_core:sandstone", prob=254, param2=0},
		{name="vlf_core:sandstone", prob=254, param2=0},
		{name="vlf_core:sandstone", prob=254, param2=0},
		{name="vlf_core:sandstone", prob=254, param2=0},
		{name="vlf_core:sandstone", prob=254, param2=0},
		{name="vlf_core:sandstone", prob=254, param2=0},
		{name="vlf_core:sandstone", prob=254, param2=0},
		{name="vlf_core:sandstone", prob=254, param2=0},
		{name="vlf_core:sandstone", prob=254, param2=0},
		{name="vlf_core:sandstone", prob=254, param2=0},
		{name="vlf_core:sandstone", prob=254, param2=0},
		{name="vlf_core:sandstone", prob=254, param2=0},
		{name="vlf_core:sandstone", prob=254, param2=0},
		{name="vlf_core:sandstone", prob=254, param2=0},
		{name="vlf_core:sandstone", prob=254, param2=0},
		{name="vlf_core:sandstone", prob=254, param2=0},
		{name="vlf_core:sandstone", prob=254, param2=0},
		{name="vlf_core:sandstone", prob=254, param2=0},
		{name="vlf_core:sandstone", prob=254, param2=0},
		{name="vlf_core:sandstone", prob=254, param2=0},
		{name="vlf_core:sandstone", prob=254, param2=0},
		{name="vlf_core:sandstone", prob=254, param2=0},
		{name="vlf_core:sandstone", prob=254, param2=0},
		{name="vlf_core:sandstone", prob=254, param2=0},
		{name="vlf_core:sandstone", prob=254, param2=0},
		{name="vlf_core:sandstone", prob=254, param2=0},
		{name="vlf_core:sandstone", prob=254, param2=0},
		{name="vlf_core:sandstone", prob=254, param2=0},
		{name="vlf_core:sandstone", prob=254, param2=0},
		{name="vlf_core:sandstone", prob=254, param2=0},
		{name="vlf_core:sandstone", prob=254, param2=0},
		{name="vlf_core:sandstone", prob=254, param2=0},
		{name="vlf_core:sandstone", prob=254, param2=0},
		{name="vlf_core:sandstone", prob=254, param2=0},
		{name="vlf_core:sandstone", prob=254, param2=0},
		{name="vlf_core:sandstone", prob=254, param2=0},
		{name="vlf_core:sandstone", prob=254, param2=0},
		{name="vlf_core:sandstone", prob=254, param2=0},
		{name="vlf_core:sandstone", prob=254, param2=0},
		{name="vlf_core:sandstone", prob=254, param2=0},
		{name="vlf_core:sandstone", prob=254, param2=0},
		{name="vlf_core:sandstone", prob=254, param2=0},
		{name="vlf_core:sandstone", prob=254, param2=0},
		{name="vlf_core:sandstone", prob=254, param2=0},
		{name="vlf_core:sandstone", prob=254, param2=0},
		{name="vlf_core:sandstone", prob=254, param2=0},
		{name="vlf_core:sandstone", prob=254, param2=0},
		{name="vlf_core:sandstone", prob=254, param2=0},
		{name="vlf_core:sandstone", prob=254, param2=0},
		{name="vlf_core:sandstone", prob=254, param2=0},
		{name="vlf_core:sandstone", prob=254, param2=0},
		{name="vlf_core:sandstone", prob=254, param2=0},
		{name="vlf_core:sandstone", prob=254, param2=0},
		{name="vlf_core:sandstone", prob=254, param2=0},
		{name="vlf_core:sandstone", prob=254, param2=0},
		{name="vlf_core:sandstone", prob=254, param2=0},
		{name="vlf_core:sandstone", prob=254, param2=0},
		{name="vlf_core:sandstone", prob=254, param2=0},
		{name="vlf_core:sandstone", prob=254, param2=0},
		{name="vlf_core:sandstone", prob=254, param2=0},
		{name="vlf_core:sandstone", prob=254, param2=0},
		{name="vlf_core:sandstone", prob=254, param2=0},
		{name="vlf_core:sandstone", prob=254, param2=0},
		{name="vlf_core:sandstone", prob=254, param2=0},
		{name="vlf_core:sandstone", prob=254, param2=0},
		{name="vlf_core:sandstone", prob=254, param2=0},
		{name="vlf_core:sandstone", prob=254, param2=0},
		{name="vlf_core:sandstone", prob=254, param2=0},
		{name="vlf_core:sandstone", prob=254, param2=0},
		{name="vlf_core:sandstone", prob=254, param2=0},
		{name="vlf_core:sandstone", prob=254, param2=0},
		{name="vlf_core:sandstone", prob=254, param2=0},
		{name="vlf_core:sandstone", prob=254, param2=0},
		{name="vlf_core:sandstone", prob=254, param2=0},
		{name="vlf_core:sandstone", prob=254, param2=0},
		{name="vlf_core:sandstone", prob=254, param2=0},
		{name="vlf_core:sandstone", prob=254, param2=0},
		{name="vlf_core:sandstone", prob=254, param2=0},
		{name="vlf_core:sandstone", prob=254, param2=0},
		{name="vlf_core:sandstone", prob=254, param2=0},
		{name="vlf_core:sandstone", prob=254, param2=0},
		{name="vlf_core:sandstone", prob=254, param2=0},
		{name="vlf_core:sandstone", prob=254, param2=0},
		{name="vlf_core:sandstone", prob=254, param2=0},
		{name="vlf_core:sandstone", prob=254, param2=0},
		{name="vlf_core:sandstone", prob=254, param2=0},
		{name="vlf_core:sandstone", prob=254, param2=0},
		{name="vlf_core:sandstone", prob=254, param2=0},
		{name="vlf_core:sandstone", prob=254, param2=0},
		{name="vlf_core:sandstone", prob=254, param2=0},
		{name="vlf_core:sandstone", prob=254, param2=0},
		{name="vlf_core:sandstone", prob=254, param2=0},
		{name="vlf_core:sandstone", prob=254, param2=0},
		{name="vlf_core:sandstone", prob=254, param2=0},
		{name="vlf_core:sandstone", prob=254, param2=0},
		{name="vlf_core:sandstone", prob=254, param2=0},
		{name="vlf_core:sandstone", prob=254, param2=0},
		{name="vlf_core:sandstone", prob=254, param2=0},
		{name="vlf_core:sandstone", prob=254, param2=0},
		{name="vlf_core:sandstone", prob=254, param2=0},
		{name="vlf_core:sandstone", prob=254, param2=0},
		{name="vlf_core:sandstone", prob=254, param2=0},
		{name="vlf_core:sandstone", prob=254, param2=0},
		{name="vlf_core:sandstone", prob=254, param2=0},
		{name="vlf_core:sandstone", prob=254, param2=0},
		{name="vlf_core:sandstone", prob=254, param2=0},
		{name="vlf_core:sandstone", prob=254, param2=0},
		{name="vlf_core:sandstone", prob=254, param2=0},
		{name="vlf_core:sandstone", prob=254, param2=0},
		{name="vlf_core:sandstone", prob=254, param2=0},
		{name="vlf_core:sandstone", prob=254, param2=0},
		{name="vlf_core:sandstone", prob=254, param2=0},
		{name="vlf_core:sandstone", prob=254, param2=0},
		{name="vlf_core:sandstone", prob=254, param2=0},
		{name="vlf_core:sandstone", prob=254, param2=0},
		{name="vlf_core:sandstone", prob=254, param2=0},
		{name="vlf_core:sandstone", prob=254, param2=0},
		{name="vlf_core:sandstone", prob=254, param2=0},
		{name="vlf_core:sandstone", prob=254, param2=0},
		{name="vlf_core:sandstone", prob=254, param2=0},
		{name="vlf_core:sandstone", prob=254, param2=0},
		{name="vlf_core:sandstone", prob=254, param2=0},
		{name="vlf_core:sandstone", prob=254, param2=0},
		{name="vlf_core:sandstone", prob=254, param2=0},
		{name="vlf_core:sand", prob=254, param2=0},
		{name="vlf_core:sandstone", prob=254, param2=0},
		{name="vlf_core:sandstone", prob=254, param2=0},
		{name="vlf_core:sandstone", prob=254, param2=0},
		{name="vlf_core:sandstone", prob=254, param2=0},
		{name="vlf_core:sandstone", prob=254, param2=0},
		{name="vlf_core:sandstone", prob=254, param2=0},
		{name="vlf_core:sandstone", prob=254, param2=0},
		{name="vlf_core:sandstone", prob=254, param2=0},
		{name="vlf_core:sandstone", prob=254, param2=0},
		{name="vlf_core:sandstone", prob=254, param2=0},
		{name="vlf_core:sandstone", prob=254, param2=0},
		{name="vlf_core:sandstone", prob=254, param2=0},
		{name="vlf_core:sandstone", prob=254, param2=0},
		{name="vlf_core:sandstone", prob=254, param2=0},
		{name="vlf_core:sandstone", prob=254, param2=0},
		{name="vlf_core:sandstone", prob=254, param2=0},
		{name="vlf_core:sandstone", prob=254, param2=0},
		{name="vlf_core:sandstone", prob=254, param2=0},
		{name="vlf_core:sandstone", prob=254, param2=0},
		{name="vlf_core:sand", prob=254, param2=0},
		{name="vlf_core:sand", prob=254, param2=0},
		{name="vlf_core:sand", prob=254, param2=0},
		{name="vlf_core:sandstone", prob=254, param2=0},
		{name="vlf_core:sandstone", prob=254, param2=0},
		{name="vlf_core:sandstone", prob=254, param2=0},
		{name="vlf_core:sandstone", prob=254, param2=0},
		{name="vlf_core:sandstone", prob=254, param2=0},
		{name="vlf_core:sandstone", prob=254, param2=0},
		{name="vlf_core:sandstone", prob=254, param2=0},
		{name="vlf_core:sandstone", prob=254, param2=0},
		{name="vlf_core:sandstone", prob=254, param2=0},
		{name="vlf_core:sandstone", prob=254, param2=0},
		{name="vlf_core:sandstone", prob=254, param2=0},
		{name="vlf_core:sandstone", prob=254, param2=0},
		{name="vlf_core:sandstone", prob=254, param2=0},
		{name="vlf_core:sandstone", prob=254, param2=0},
		{name="vlf_core:sandstone", prob=254, param2=0},
		{name="vlf_core:sandstone", prob=254, param2=0},
		{name="vlf_core:sandstone", prob=254, param2=0},
		{name="vlf_core:sandstone", prob=254, param2=0},
		{name="vlf_core:sandstone", prob=254, param2=0},
		{name="vlf_core:sand", prob=254, param2=0},
		{name="vlf_core:sand", prob=254, param2=0},
		{name="air", prob=0, param2=0},
		{name="vlf_core:sandstone", prob=254, param2=0},
		{name="vlf_core:sandstone", prob=254, param2=0},
		{name="vlf_core:sandstone", prob=254, param2=0},
		{name="vlf_core:sandstone", prob=254, param2=0},
		{name="vlf_core:sandstone", prob=254, param2=0},
		{name="vlf_core:sandstone", prob=254, param2=0},
		{name="vlf_core:sandstone", prob=254, param2=0},
		{name="vlf_core:sandstone", prob=254, param2=0},
		{name="vlf_core:sandstone", prob=254, param2=0},
		{name="vlf_core:sandstone", prob=254, param2=0},
		{name="vlf_core:sandstone", prob=254, param2=0},
		{name="vlf_core:sandstone", prob=254, param2=0},
		{name="vlf_core:sandstone", prob=254, param2=0},
		{name="vlf_core:sandstone", prob=254, param2=0},
		{name="vlf_core:sandstone", prob=254, param2=0},
		{name="vlf_core:sandstone", prob=254, param2=0},
		{name="vlf_core:sandstone", prob=254, param2=0},
		{name="vlf_core:sandstone", prob=254, param2=0},
		{name="vlf_core:sandstone", prob=254, param2=0},
		{name="air", prob=0, param2=0},
		{name="air", prob=0, param2=0},
		{name="air", prob=0, param2=0},
		{name="air", prob=0, param2=0},
		{name="air", prob=0, param2=0},
		{name="air", prob=0, param2=0},
		{name="air", prob=0, param2=0},
		{name="air", prob=0, param2=0},
		{name="air", prob=0, param2=0},
		{name="air", prob=0, param2=0},
		{name="vlf_core:sandstone", prob=254, param2=0},
		{name="air", prob=254, param2=0},
		{name="vlf_stairs:stair_sandstone", prob=254, param2=1},
		{name="vlf_core:sandstone", prob=254, param2=0},
		{name="vlf_core:sandstone", prob=254, param2=0},
		{name="air", prob=0, param2=0},
		{name="air", prob=0, param2=0},
		{name="air", prob=0, param2=0},
		{name="air", prob=0, param2=0},
		{name="air", prob=0, param2=0},
		{name="air", prob=0, param2=0},
		{name="air", prob=0, param2=0},
		{name="air", prob=0, param2=0},
		{name="air", prob=0, param2=0},
		{name="air", prob=0, param2=0},
		{name="air", prob=0, param2=0},
		{name="air", prob=0, param2=0},
		{name="air", prob=0, param2=0},
		{name="air", prob=0, param2=0},
		{name="air", prob=0, param2=0},
		{name="air", prob=0, param2=0},
		{name="air", prob=0, param2=0},
		{name="vlf_core:sandstone", prob=254, param2=0},
		{name="air", prob=254, param2=0},
		{name="air", prob=254, param2=0},
		{name="air", prob=254, param2=0},
		{name="vlf_core:sandstone", prob=254, param2=0},
		{name="air", prob=0, param2=0},
		{name="air", prob=0, param2=0},
		{name="air", prob=0, param2=0},
		{name="air", prob=0, param2=0},
		{name="air", prob=0, param2=0},
		{name="air", prob=0, param2=0},
		{name="air", prob=0, param2=0},
		{name="air", prob=0, param2=0},
		{name="air", prob=0, param2=0},
		{name="air", prob=0, param2=0},
		{name="air", prob=0, param2=0},
		{name="air", prob=0, param2=0},
		{name="air", prob=0, param2=0},
		{name="air", prob=0, param2=0},
		{name="air", prob=0, param2=0},
		{name="air", prob=0, param2=0},
		{name="air", prob=0, param2=0},
		{name="vlf_core:sandstone", prob=254, param2=0},
		{name="air", prob=254, param2=0},
		{name="air", prob=254, param2=0},
		{name="air", prob=254, param2=0},
		{name="vlf_core:sandstone", prob=254, param2=0},
		{name="air", prob=0, param2=0},
		{name="air", prob=0, param2=0},
		{name="air", prob=0, param2=0},
		{name="air", prob=0, param2=0},
		{name="air", prob=0, param2=0},
		{name="air", prob=0, param2=0},
		{name="air", prob=0, param2=0},
		{name="air", prob=0, param2=0},
		{name="air", prob=0, param2=0},
		{name="air", prob=0, param2=0},
		{name="air", prob=0, param2=0},
		{name="air", prob=0, param2=0},
		{name="air", prob=0, param2=0},
		{name="air", prob=0, param2=0},
		{name="air", prob=0, param2=0},
		{name="air", prob=0, param2=0},
		{name="air", prob=0, param2=0},
		{name="vlf_core:sandstone", prob=254, param2=0},
		{name="air", prob=254, param2=0},
		{name="air", prob=254, param2=0},
		{name="air", prob=254, param2=0},
		{name="vlf_core:sandstone", prob=254, param2=0},
		{name="air", prob=0, param2=0},
		{name="air", prob=0, param2=0},
		{name="air", prob=0, param2=0},
		{name="air", prob=0, param2=0},
		{name="air", prob=0, param2=0},
		{name="air", prob=0, param2=0},
		{name="air", prob=0, param2=0},
		{name="air", prob=0, param2=0},
		{name="air", prob=0, param2=0},
		{name="air", prob=0, param2=0},
		{name="air", prob=0, param2=0},
		{name="air", prob=0, param2=0},
		{name="air", prob=0, param2=0},
		{name="air", prob=0, param2=0},
		{name="air", prob=0, param2=0},
		{name="air", prob=0, param2=0},
		{name="air", prob=0, param2=0},
		{name="vlf_core:sandstonesmooth", prob=254, param2=0},
		{name="air", prob=254, param2=0},
		{name="air", prob=254, param2=0},
		{name="air", prob=254, param2=0},
		{name="vlf_core:sandstonesmooth", prob=254, param2=0},
		{name="air", prob=0, param2=0},
		{name="air", prob=0, param2=0},
		{name="air", prob=0, param2=0},
		{name="air", prob=0, param2=0},
		{name="air", prob=0, param2=0},
		{name="air", prob=0, param2=0},
		{name="air", prob=0, param2=0},
		{name="air", prob=0, param2=0},
		{name="air", prob=0, param2=0},
		{name="air", prob=0, param2=0},
		{name="air", prob=0, param2=0},
		{name="air", prob=0, param2=0},
		{name="air", prob=0, param2=0},
		{name="air", prob=0, param2=0},
		{name="air", prob=0, param2=0},
		{name="air", prob=0, param2=0},
		{name="air", prob=0, param2=0},
		{name="vlf_colorblocks:hardened_clay_orange", prob=254, param2=0},
		{name="air", prob=254, param2=0},
		{name="air", prob=254, param2=0},
		{name="air", prob=254, param2=0},
		{name="vlf_colorblocks:hardened_clay_orange", prob=254, param2=0},
		{name="air", prob=0, param2=0},
		{name="air", prob=0, param2=0},
		{name="air", prob=0, param2=0},
		{name="air", prob=0, param2=0},
		{name="air", prob=0, param2=0},
		{name="air", prob=0, param2=0},
		{name="air", prob=0, param2=0},
		{name="air", prob=0, param2=0},
		{name="air", prob=0, param2=0},
		{name="air", prob=0, param2=0},
		{name="air", prob=0, param2=0},
		{name="air", prob=0, param2=0},
		{name="air", prob=0, param2=0},
		{name="air", prob=0, param2=0},
		{name="air", prob=0, param2=0},
		{name="air", prob=0, param2=0},
		{name="air", prob=0, param2=0},
		{name="vlf_core:sandstonesmooth", prob=254, param2=0},
		{name="air", prob=254, param2=0},
		{name="air", prob=254, param2=0},
		{name="air", prob=254, param2=0},
		{name="vlf_core:sandstonesmooth", prob=254, param2=0},
		{name="air", prob=0, param2=0},
		{name="air", prob=0, param2=0},
		{name="air", prob=0, param2=0},
		{name="air", prob=0, param2=0},
		{name="air", prob=0, param2=0},
		{name="air", prob=0, param2=0},
		{name="air", prob=0, param2=0},
		{name="air", prob=0, param2=0},
		{name="air", prob=0, param2=0},
		{name="air", prob=0, param2=0},
		{name="air", prob=0, param2=0},
		{name="air", prob=0, param2=0},
		{name="air", prob=0, param2=0},
		{name="air", prob=0, param2=0},
		{name="air", prob=0, param2=0},
		{name="air", prob=0, param2=0},
		{name="air", prob=0, param2=0},
		{name="vlf_core:sandstone", prob=254, param2=0},
		{name="vlf_core:sandstone", prob=254, param2=0},
		{name="vlf_core:sandstone", prob=254, param2=0},
		{name="vlf_core:sandstone", prob=254, param2=0},
		{name="vlf_core:sandstone", prob=254, param2=0},
		{name="air", prob=0, param2=0},
		{name="air", prob=0, param2=0},
		{name="air", prob=0, param2=0},
		{name="air", prob=0, param2=0},
		{name="air", prob=0, param2=0},
		{name="air", prob=0, param2=0},
		{name="air", prob=0, param2=0},
		{name="air", prob=0, param2=0},
		{name="air", prob=0, param2=0},
		{name="air", prob=0, param2=0},
		{name="air", prob=0, param2=0},
		{name="air", prob=0, param2=0},
		{name="air", prob=0, param2=0},
		{name="air", prob=0, param2=0},
		{name="air", prob=0, param2=0},
		{name="air", prob=0, param2=0},
		{name="air", prob=0, param2=0},
		{name="vlf_stairs:stair_sandstone", prob=254, param2=1},
		{name="vlf_core:sandstone", prob=254, param2=0},
		{name="vlf_core:sandstone", prob=254, param2=0},
		{name="vlf_core:sandstone", prob=254, param2=0},
		{name="vlf_stairs:stair_sandstone", prob=254, param2=3},
		{name="air", prob=0, param2=0},
		{name="air", prob=0, param2=0},
		{name="air", prob=0, param2=0},
		{name="air", prob=0, param2=0},
		{name="air", prob=0, param2=0},
		{name="air", prob=0, param2=0},
		{name="air", prob=0, param2=0},
		{name="air", prob=0, param2=0},
		{name="air", prob=0, param2=0},
		{name="air", prob=0, param2=0},
		{name="air", prob=0, param2=0},
		{name="air", prob=0, param2=0},
		{name="air", prob=0, param2=0},
		{name="air", prob=0, param2=0},
		{name="air", prob=0, param2=0},
		{name="air", prob=0, param2=0},
		{name="air", prob=0, param2=0},
		{name="air", prob=0, param2=0},
		{name="vlf_stairs:stair_sandstone_outer", prob=254, param2=1},
		{name="vlf_stairs:stair_sandstone", prob=254, param2=0},
		{name="vlf_stairs:stair_sandstone_outer", prob=254, param2=0},
		{name="air", prob=0, param2=0},
		{name="air", prob=0, param2=0},
		{name="air", prob=0, param2=0},
		{name="air", prob=0, param2=0},
		{name="air", prob=0, param2=0},
		{name="air", prob=0, param2=0},
		{name="air", prob=0, param2=0},
		{name="air", prob=0, param2=0},
		{name="air", prob=0, param2=0},
		{name="air", prob=0, param2=0},
		{name="air", prob=0, param2=0},
		{name="air", prob=0, param2=0},
		{name="air", prob=0, param2=0},
		{name="air", prob=0, param2=0},
		{name="air", prob=0, param2=0},
		{name="air", prob=0, param2=0},
		{name="air", prob=0, param2=0},
		{name="air", prob=0, param2=0},
		{name="air", prob=0, param2=0},
		{name="air", prob=0, param2=0},
		{name="air", prob=0, param2=0},
		{name="air", prob=0, param2=0},
		{name="air", prob=0, param2=0},
		{name="air", prob=0, param2=0},
		{name="air", prob=0, param2=0},
		{name="air", prob=0, param2=0},
		{name="air", prob=0, param2=0},
		{name="air", prob=0, param2=0},
		{name="air", prob=0, param2=0},
		{name="air", prob=0, param2=0},
		{name="air", prob=0, param2=0},
		{name="air", prob=0, param2=0},
		{name="vlf_core:sandstone", prob=254, param2=0},
		{name="vlf_core:sandstone", prob=254, param2=0},
		{name="vlf_core:sandstone", prob=254, param2=0},
		{name="vlf_core:sandstone", prob=254, param2=0},
		{name="vlf_core:sandstone", prob=254, param2=0},
		{name="vlf_core:sandstone", prob=254, param2=0},
		{name="vlf_core:sandstone", prob=254, param2=0},
		{name="vlf_core:sandstone", prob=254, param2=0},
		{name="vlf_core:sandstone", prob=254, param2=0},
		{name="vlf_core:sandstone", prob=254, param2=0},
		{name="vlf_core:sandstone", prob=254, param2=0},
		{name="vlf_core:sandstone", prob=254, param2=0},
		{name="vlf_core:sandstone", prob=254, param2=0},
		{name="vlf_core:sandstone", prob=254, param2=0},
		{name="vlf_core:sandstone", prob=254, param2=0},
		{name="vlf_core:sandstone", prob=254, param2=0},
		{name="vlf_core:sandstone", prob=254, param2=0},
		{name="vlf_core:sandstone", prob=254, param2=0},
		{name="vlf_core:sandstone", prob=254, param2=0},
		{name="vlf_core:sandstone", prob=254, param2=0},
		{name="vlf_core:sandstone", prob=254, param2=0},
		{name="vlf_core:sandstone", prob=254, param2=0},
		{name="vlf_core:sandstone", prob=254, param2=0},
		{name="vlf_core:sandstone", prob=254, param2=0},
		{name="vlf_core:sandstone", prob=254, param2=0},
		{name="vlf_core:sandstone", prob=254, param2=0},
		{name="vlf_core:sandstone", prob=254, param2=0},
		{name="vlf_core:sandstone", prob=254, param2=0},
		{name="vlf_core:sandstone", prob=254, param2=0},
		{name="vlf_core:sandstone", prob=254, param2=0},
		{name="vlf_core:sandstone", prob=254, param2=0},
		{name="vlf_core:sandstone", prob=254, param2=0},
		{name="vlf_core:sandstone", prob=254, param2=0},
		{name="vlf_core:sandstone", prob=254, param2=0},
		{name="vlf_core:sandstone", prob=254, param2=0},
		{name="vlf_core:sandstone", prob=254, param2=0},
		{name="vlf_core:sandstone", prob=254, param2=0},
		{name="vlf_core:sandstone", prob=254, param2=0},
		{name="vlf_core:sandstone", prob=254, param2=0},
		{name="vlf_core:sandstone", prob=254, param2=0},
		{name="vlf_core:sandstone", prob=254, param2=0},
		{name="vlf_core:sandstone", prob=254, param2=0},
		{name="vlf_core:sandstone", prob=254, param2=0},
		{name="vlf_core:sandstone", prob=254, param2=0},
		{name="vlf_core:sandstone", prob=254, param2=0},
		{name="vlf_core:sandstone", prob=254, param2=0},
		{name="vlf_core:sandstone", prob=254, param2=0},
		{name="vlf_core:sandstone", prob=254, param2=0},
		{name="vlf_core:sandstone", prob=254, param2=0},
		{name="vlf_core:sandstone", prob=254, param2=0},
		{name="vlf_core:sandstone", prob=254, param2=0},
		{name="vlf_core:sandstone", prob=254, param2=0},
		{name="vlf_core:sandstone", prob=254, param2=0},
		{name="vlf_core:sandstone", prob=254, param2=0},
		{name="vlf_core:sandstone", prob=254, param2=0},
		{name="vlf_core:sandstone", prob=254, param2=0},
		{name="vlf_core:sandstone", prob=254, param2=0},
		{name="vlf_core:sandstone", prob=254, param2=0},
		{name="vlf_core:sandstone", prob=254, param2=0},
		{name="vlf_core:sandstone", prob=254, param2=0},
		{name="vlf_core:sandstone", prob=254, param2=0},
		{name="vlf_core:sandstone", prob=254, param2=0},
		{name="vlf_core:sandstone", prob=254, param2=0},
		{name="vlf_core:sandstone", prob=254, param2=0},
		{name="vlf_core:sandstone", prob=254, param2=0},
		{name="vlf_core:sandstone", prob=254, param2=0},
		{name="vlf_core:sandstone", prob=254, param2=0},
		{name="vlf_core:sandstone", prob=254, param2=0},
		{name="vlf_core:sandstone", prob=254, param2=0},
		{name="vlf_core:sandstone", prob=254, param2=0},
		{name="vlf_core:sandstone", prob=254, param2=0},
		{name="vlf_core:sandstone", prob=254, param2=0},
		{name="vlf_core:sandstone", prob=254, param2=0},
		{name="vlf_core:sandstone", prob=254, param2=0},
		{name="vlf_core:sandstone", prob=254, param2=0},
		{name="vlf_core:sandstone", prob=254, param2=0},
		{name="vlf_core:sandstone", prob=254, param2=0},
		{name="vlf_core:sandstone", prob=254, param2=0},
		{name="vlf_core:sandstone", prob=254, param2=0},
		{name="vlf_core:sandstone", prob=254, param2=0},
		{name="vlf_core:sandstone", prob=254, param2=0},
		{name="vlf_core:sandstone", prob=254, param2=0},
		{name="vlf_core:sandstone", prob=254, param2=0},
		{name="vlf_core:sandstone", prob=254, param2=0},
		{name="vlf_core:sandstone", prob=254, param2=0},
		{name="vlf_core:sandstone", prob=254, param2=0},
		{name="vlf_core:sandstone", prob=254, param2=0},
		{name="vlf_core:sandstone", prob=254, param2=0},
		{name="vlf_core:sandstone", prob=254, param2=0},
		{name="vlf_core:sandstone", prob=254, param2=0},
		{name="vlf_core:sandstone", prob=254, param2=0},
		{name="vlf_core:sandstone", prob=254, param2=0},
		{name="vlf_core:sandstone", prob=254, param2=0},
		{name="vlf_core:sandstone", prob=254, param2=0},
		{name="vlf_core:sandstone", prob=254, param2=0},
		{name="vlf_core:sandstone", prob=254, param2=0},
		{name="vlf_core:sandstone", prob=254, param2=0},
		{name="vlf_core:sandstone", prob=254, param2=0},
		{name="vlf_core:sandstone", prob=254, param2=0},
		{name="vlf_core:sandstone", prob=254, param2=0},
		{name="vlf_core:sandstone", prob=254, param2=0},
		{name="vlf_core:sandstone", prob=254, param2=0},
		{name="vlf_core:sandstone", prob=254, param2=0},
		{name="vlf_core:sandstone", prob=254, param2=0},
		{name="vlf_core:sandstone", prob=254, param2=0},
		{name="vlf_core:sandstone", prob=254, param2=0},
		{name="vlf_core:sandstone", prob=254, param2=0},
		{name="vlf_core:sandstone", prob=254, param2=0},
		{name="vlf_core:sandstone", prob=254, param2=0},
		{name="vlf_core:sandstone", prob=254, param2=0},
		{name="vlf_core:sandstone", prob=254, param2=0},
		{name="vlf_core:sandstone", prob=254, param2=0},
		{name="vlf_core:sandstone", prob=254, param2=0},
		{name="vlf_core:sandstone", prob=254, param2=0},
		{name="vlf_core:sandstone", prob=254, param2=0},
		{name="vlf_core:sandstone", prob=254, param2=0},
		{name="vlf_core:sandstone", prob=254, param2=0},
		{name="vlf_core:sandstone", prob=254, param2=0},
		{name="vlf_core:sandstone", prob=254, param2=0},
		{name="vlf_core:sandstone", prob=254, param2=0},
		{name="vlf_core:sandstone", prob=254, param2=0},
		{name="vlf_core:sandstone", prob=254, param2=0},
		{name="vlf_core:sandstone", prob=254, param2=0},
		{name="vlf_core:sandstone", prob=254, param2=0},
		{name="vlf_core:sandstone", prob=254, param2=0},
		{name="vlf_core:sandstone", prob=254, param2=0},
		{name="vlf_core:sandstone", prob=254, param2=0},
		{name="vlf_core:sandstone", prob=254, param2=0},
		{name="vlf_core:sandstone", prob=254, param2=0},
		{name="vlf_core:sandstone", prob=254, param2=0},
		{name="vlf_core:sandstone", prob=254, param2=0},
		{name="vlf_core:sandstone", prob=254, param2=0},
		{name="vlf_core:sandstone", prob=254, param2=0},
		{name="vlf_core:sandstone", prob=254, param2=0},
		{name="vlf_core:sandstone", prob=254, param2=0},
		{name="vlf_core:sandstone", prob=254, param2=0},
		{name="vlf_core:sandstone", prob=254, param2=0},
		{name="vlf_core:sandstone", prob=254, param2=0},
		{name="vlf_core:sandstone", prob=254, param2=0},
		{name="vlf_core:sandstone", prob=254, param2=0},
		{name="vlf_core:sandstone", prob=254, param2=0},
		{name="vlf_core:sandstone", prob=254, param2=0},
		{name="vlf_core:sandstone", prob=254, param2=0},
		{name="vlf_core:sandstone", prob=254, param2=0},
		{name="vlf_core:sandstone", prob=254, param2=0},
		{name="vlf_core:sandstone", prob=254, param2=0},
		{name="vlf_core:sandstone", prob=254, param2=0},
		{name="vlf_core:sandstone", prob=254, param2=0},
		{name="vlf_core:sandstone", prob=254, param2=0},
		{name="vlf_core:sandstone", prob=254, param2=0},
		{name="vlf_core:sandstone", prob=254, param2=0},
		{name="vlf_core:sandstone", prob=254, param2=0},
		{name="vlf_core:sandstone", prob=254, param2=0},
		{name="vlf_core:sandstone", prob=254, param2=0},
		{name="vlf_core:sandstone", prob=254, param2=0},
		{name="vlf_core:sandstone", prob=254, param2=0},
		{name="vlf_core:sandstone", prob=254, param2=0},
		{name="vlf_core:sandstone", prob=254, param2=0},
		{name="vlf_core:sandstone", prob=254, param2=0},
		{name="vlf_core:sandstone", prob=254, param2=0},
		{name="vlf_core:sandstone", prob=254, param2=0},
		{name="vlf_core:sandstone", prob=254, param2=0},
		{name="vlf_core:sandstone", prob=254, param2=0},
		{name="vlf_core:sandstone", prob=254, param2=0},
		{name="vlf_core:sandstone", prob=254, param2=0},
		{name="vlf_core:sandstone", prob=254, param2=0},
		{name="vlf_core:sandstone", prob=254, param2=0},
		{name="vlf_core:sandstone", prob=254, param2=0},
		{name="vlf_core:sandstone", prob=254, param2=0},
		{name="vlf_core:sandstone", prob=254, param2=0},
		{name="vlf_core:sandstone", prob=254, param2=0},
		{name="vlf_core:sandstone", prob=254, param2=0},
		{name="vlf_core:sandstone", prob=254, param2=0},
		{name="vlf_core:sandstone", prob=254, param2=0},
		{name="vlf_core:sandstone", prob=254, param2=0},
		{name="vlf_core:sandstone", prob=254, param2=0},
		{name="vlf_core:sandstone", prob=254, param2=0},
		{name="vlf_core:sandstone", prob=254, param2=0},
		{name="vlf_core:sandstone", prob=254, param2=0},
		{name="vlf_core:sandstone", prob=254, param2=0},
		{name="vlf_core:sandstone", prob=254, param2=0},
		{name="vlf_core:sandstone", prob=254, param2=0},
		{name="vlf_core:sandstone", prob=254, param2=0},
		{name="vlf_core:sandstone", prob=254, param2=0},
		{name="vlf_core:sandstone", prob=254, param2=0},
		{name="vlf_core:sandstone", prob=254, param2=0},
		{name="vlf_core:sandstone", prob=254, param2=0},
		{name="vlf_core:sandstone", prob=254, param2=0},
		{name="vlf_core:sandstone", prob=254, param2=0},
		{name="vlf_core:sandstone", prob=254, param2=0},
		{name="vlf_core:sandstone", prob=254, param2=0},
		{name="vlf_core:sandstone", prob=254, param2=0},
		{name="vlf_core:sandstone", prob=254, param2=0},
		{name="vlf_core:sandstone", prob=254, param2=0},
		{name="vlf_core:sandstone", prob=254, param2=0},
		{name="vlf_core:sandstone", prob=254, param2=0},
		{name="vlf_core:sandstone", prob=254, param2=0},
		{name="vlf_core:sandstone", prob=254, param2=0},
		{name="vlf_core:sandstone", prob=254, param2=0},
		{name="vlf_core:sandstone", prob=254, param2=0},
		{name="vlf_core:sandstone", prob=254, param2=0},
		{name="vlf_core:sandstone", prob=254, param2=0},
		{name="vlf_core:sandstone", prob=254, param2=0},
		{name="vlf_core:sandstone", prob=254, param2=0},
		{name="vlf_core:sandstone", prob=254, param2=0},
		{name="vlf_core:sandstone", prob=254, param2=0},
		{name="vlf_core:sandstone", prob=254, param2=0},
		{name="vlf_core:sandstone", prob=254, param2=0},
		{name="vlf_core:sandstone", prob=254, param2=0},
		{name="vlf_core:sandstone", prob=254, param2=0},
		{name="vlf_core:sandstone", prob=254, param2=0},
		{name="vlf_core:sandstone", prob=254, param2=0},
		{name="vlf_core:sandstone", prob=254, param2=0},
		{name="vlf_core:sandstone", prob=254, param2=0},
		{name="vlf_core:sandstone", prob=254, param2=0},
		{name="vlf_core:sandstone", prob=254, param2=0},
		{name="vlf_core:sandstone", prob=254, param2=0},
		{name="vlf_core:sandstone", prob=254, param2=0},
		{name="vlf_core:sandstone", prob=254, param2=0},
		{name="vlf_core:sandstone", prob=254, param2=0},
		{name="vlf_core:sand", prob=254, param2=0},
		{name="vlf_core:sandstone", prob=254, param2=0},
		{name="vlf_core:sandstone", prob=254, param2=0},
		{name="vlf_core:sandstone", prob=254, param2=0},
		{name="vlf_core:sandstone", prob=254, param2=0},
		{name="vlf_core:sandstone", prob=254, param2=0},
		{name="vlf_core:sandstone", prob=254, param2=0},
		{name="vlf_core:sandstone", prob=254, param2=0},
		{name="vlf_core:sandstone", prob=254, param2=0},
		{name="vlf_core:sandstone", prob=254, param2=0},
		{name="vlf_core:sandstone", prob=254, param2=0},
		{name="vlf_core:sandstone", prob=254, param2=0},
		{name="vlf_core:sandstone", prob=254, param2=0},
		{name="vlf_core:sandstone", prob=254, param2=0},
		{name="vlf_core:sandstone", prob=254, param2=0},
		{name="vlf_core:sandstone", prob=254, param2=0},
		{name="vlf_core:sandstone", prob=254, param2=0},
		{name="vlf_core:sandstone", prob=254, param2=0},
		{name="vlf_core:sandstone", prob=254, param2=0},
		{name="vlf_core:sandstone", prob=254, param2=0},
		{name="vlf_core:sand", prob=254, param2=0},
		{name="vlf_core:sand", prob=254, param2=0},
		{name="vlf_core:sand", prob=254, param2=0},
		{name="vlf_core:sandstone", prob=254, param2=0},
		{name="vlf_core:sandstone", prob=254, param2=0},
		{name="vlf_core:sandstone", prob=254, param2=0},
		{name="vlf_core:sandstone", prob=254, param2=0},
		{name="vlf_core:sandstone", prob=254, param2=0},
		{name="vlf_core:sandstone", prob=254, param2=0},
		{name="vlf_core:sandstone", prob=254, param2=0},
		{name="vlf_core:sandstone", prob=254, param2=0},
		{name="vlf_core:sandstone", prob=254, param2=0},
		{name="vlf_core:sandstone", prob=254, param2=0},
		{name="vlf_core:sandstone", prob=254, param2=0},
		{name="vlf_core:sandstone", prob=254, param2=0},
		{name="vlf_core:sandstone", prob=254, param2=0},
		{name="vlf_core:sandstone", prob=254, param2=0},
		{name="vlf_core:sandstone", prob=254, param2=0},
		{name="vlf_core:sandstone", prob=254, param2=0},
		{name="vlf_core:sandstone", prob=254, param2=0},
		{name="vlf_core:sandstone", prob=254, param2=0},
		{name="vlf_core:sandstone", prob=254, param2=0},
		{name="vlf_core:sand", prob=254, param2=0},
		{name="vlf_core:sand", prob=254, param2=0},
		{name="air", prob=0, param2=0},
		{name="vlf_core:sandstone", prob=254, param2=0},
		{name="vlf_core:sandstone", prob=254, param2=0},
		{name="vlf_core:sandstone", prob=254, param2=0},
		{name="vlf_core:sandstone", prob=254, param2=0},
		{name="vlf_core:sandstone", prob=254, param2=0},
		{name="vlf_core:sandstone", prob=254, param2=0},
		{name="vlf_core:sandstone", prob=254, param2=0},
		{name="vlf_core:sandstone", prob=254, param2=0},
		{name="vlf_stairs:stair_sandstone", prob=254, param2=2},
		{name="vlf_core:sandstone", prob=254, param2=0},
		{name="vlf_core:sandstone", prob=254, param2=0},
		{name="vlf_core:sandstone", prob=254, param2=0},
		{name="vlf_core:sandstone", prob=254, param2=0},
		{name="vlf_core:sandstone", prob=254, param2=0},
		{name="vlf_core:sandstone", prob=254, param2=0},
		{name="vlf_core:sandstone", prob=254, param2=0},
		{name="vlf_core:sandstone", prob=254, param2=0},
		{name="vlf_core:sandstone", prob=254, param2=0},
		{name="vlf_core:sandstone", prob=254, param2=0},
		{name="air", prob=0, param2=0},
		{name="air", prob=0, param2=0},
		{name="air", prob=0, param2=0},
		{name="air", prob=0, param2=0},
		{name="vlf_core:sandstone", prob=254, param2=0},
		{name="vlf_core:sandstone", prob=254, param2=0},
		{name="vlf_core:sandstone", prob=254, param2=0},
		{name="vlf_core:sandstone", prob=254, param2=0},
		{name="vlf_core:sandstone", prob=254, param2=0},
		{name="vlf_core:sandstone", prob=254, param2=0},
		{name="vlf_core:sandstone", prob=254, param2=0},
		{name="air", prob=254, param2=0},
		{name="vlf_core:sandstone", prob=254, param2=0},
		{name="vlf_core:sandstone", prob=254, param2=0},
		{name="vlf_core:sandstone", prob=254, param2=0},
		{name="vlf_core:sandstone", prob=254, param2=0},
		{name="vlf_core:sandstone", prob=254, param2=0},
		{name="vlf_core:sandstone", prob=254, param2=0},
		{name="vlf_core:sandstone", prob=254, param2=0},
		{name="vlf_core:sandstone", prob=254, param2=0},
		{name="vlf_core:sandstone", prob=254, param2=0},
		{name="air", prob=0, param2=0},
		{name="air", prob=0, param2=0},
		{name="air", prob=0, param2=0},
		{name="air", prob=0, param2=0},
		{name="air", prob=0, param2=0},
		{name="air", prob=0, param2=0},
		{name="air", prob=0, param2=0},
		{name="air", prob=0, param2=0},
		{name="air", prob=0, param2=0},
		{name="air", prob=0, param2=0},
		{name="air", prob=0, param2=0},
		{name="vlf_core:sandstone", prob=254, param2=0},
		{name="air", prob=254, param2=0},
		{name="vlf_stairs:slab_sandstone", prob=254, param2=0},
		{name="vlf_stairs:stair_sandstone", prob=254, param2=0},
		{name="vlf_core:sandstone", prob=254, param2=0},
		{name="air", prob=0, param2=0},
		{name="air", prob=0, param2=0},
		{name="air", prob=0, param2=0},
		{name="air", prob=0, param2=0},
		{name="air", prob=0, param2=0},
		{name="air", prob=0, param2=0},
		{name="air", prob=0, param2=0},
		{name="air", prob=0, param2=0},
		{name="air", prob=0, param2=0},
		{name="air", prob=0, param2=0},
		{name="air", prob=0, param2=0},
		{name="air", prob=0, param2=0},
		{name="air", prob=0, param2=0},
		{name="air", prob=0, param2=0},
		{name="air", prob=0, param2=0},
		{name="air", prob=0, param2=0},
		{name="air", prob=0, param2=0},
		{name="vlf_core:sandstone", prob=254, param2=0},
		{name="air", prob=254, param2=0},
		{name="air", prob=254, param2=0},
		{name="air", prob=254, param2=0},
		{name="vlf_core:sandstone", prob=254, param2=0},
		{name="air", prob=0, param2=0},
		{name="air", prob=0, param2=0},
		{name="air", prob=0, param2=0},
		{name="air", prob=0, param2=0},
		{name="air", prob=0, param2=0},
		{name="air", prob=0, param2=0},
		{name="air", prob=0, param2=0},
		{name="air", prob=0, param2=0},
		{name="air", prob=0, param2=0},
		{name="air", prob=0, param2=0},
		{name="air", prob=0, param2=0},
		{name="air", prob=0, param2=0},
		{name="air", prob=0, param2=0},
		{name="air", prob=0, param2=0},
		{name="air", prob=0, param2=0},
		{name="air", prob=0, param2=0},
		{name="air", prob=0, param2=0},
		{name="vlf_core:sandstone", prob=254, param2=0},
		{name="air", prob=254, param2=0},
		{name="air", prob=254, param2=0},
		{name="air", prob=254, param2=0},
		{name="vlf_core:sandstone", prob=254, param2=0},
		{name="air", prob=0, param2=0},
		{name="air", prob=0, param2=0},
		{name="air", prob=0, param2=0},
		{name="air", prob=0, param2=0},
		{name="air", prob=0, param2=0},
		{name="air", prob=0, param2=0},
		{name="air", prob=0, param2=0},
		{name="air", prob=0, param2=0},
		{name="air", prob=0, param2=0},
		{name="air", prob=0, param2=0},
		{name="air", prob=0, param2=0},
		{name="air", prob=0, param2=0},
		{name="air", prob=0, param2=0},
		{name="air", prob=0, param2=0},
		{name="air", prob=0, param2=0},
		{name="air", prob=0, param2=0},
		{name="air", prob=0, param2=0},
		{name="vlf_colorblocks:hardened_clay_orange", prob=254, param2=0},
		{name="air", prob=254, param2=0},
		{name="air", prob=254, param2=0},
		{name="air", prob=254, param2=0},
		{name="vlf_colorblocks:hardened_clay_orange", prob=254, param2=0},
		{name="air", prob=0, param2=0},
		{name="air", prob=0, param2=0},
		{name="air", prob=0, param2=0},
		{name="air", prob=0, param2=0},
		{name="air", prob=0, param2=0},
		{name="air", prob=0, param2=0},
		{name="air", prob=0, param2=0},
		{name="air", prob=0, param2=0},
		{name="air", prob=0, param2=0},
		{name="air", prob=0, param2=0},
		{name="air", prob=0, param2=0},
		{name="air", prob=0, param2=0},
		{name="air", prob=0, param2=0},
		{name="air", prob=0, param2=0},
		{name="air", prob=0, param2=0},
		{name="air", prob=0, param2=0},
		{name="air", prob=0, param2=0},
		{name="vlf_core:sandstonecarved", prob=254, param2=0},
		{name="air", prob=254, param2=0},
		{name="air", prob=254, param2=0},
		{name="air", prob=254, param2=0},
		{name="vlf_core:sandstonecarved", prob=254, param2=0},
		{name="air", prob=0, param2=0},
		{name="air", prob=0, param2=0},
		{name="air", prob=0, param2=0},
		{name="air", prob=0, param2=0},
		{name="air", prob=0, param2=0},
		{name="air", prob=0, param2=0},
		{name="air", prob=0, param2=0},
		{name="air", prob=0, param2=0},
		{name="air", prob=0, param2=0},
		{name="air", prob=0, param2=0},
		{name="air", prob=0, param2=0},
		{name="air", prob=0, param2=0},
		{name="air", prob=0, param2=0},
		{name="air", prob=0, param2=0},
		{name="air", prob=0, param2=0},
		{name="air", prob=0, param2=0},
		{name="air", prob=0, param2=0},
		{name="vlf_colorblocks:hardened_clay_orange", prob=254, param2=0},
		{name="air", prob=254, param2=0},
		{name="air", prob=254, param2=0},
		{name="air", prob=254, param2=0},
		{name="vlf_colorblocks:hardened_clay_orange", prob=254, param2=0},
		{name="air", prob=0, param2=0},
		{name="air", prob=0, param2=0},
		{name="air", prob=0, param2=0},
		{name="air", prob=0, param2=0},
		{name="air", prob=0, param2=0},
		{name="air", prob=0, param2=0},
		{name="air", prob=0, param2=0},
		{name="air", prob=0, param2=0},
		{name="air", prob=0, param2=0},
		{name="air", prob=0, param2=0},
		{name="air", prob=0, param2=0},
		{name="air", prob=0, param2=0},
		{name="air", prob=0, param2=0},
		{name="air", prob=0, param2=0},
		{name="air", prob=0, param2=0},
		{name="air", prob=0, param2=0},
		{name="air", prob=0, param2=0},
		{name="vlf_core:sandstone", prob=254, param2=0},
		{name="vlf_core:sandstone", prob=254, param2=0},
		{name="vlf_core:sandstone", prob=254, param2=0},
		{name="vlf_core:sandstone", prob=254, param2=0},
		{name="vlf_core:sandstone", prob=254, param2=0},
		{name="air", prob=0, param2=0},
		{name="air", prob=0, param2=0},
		{name="air", prob=0, param2=0},
		{name="air", prob=0, param2=0},
		{name="air", prob=0, param2=0},
		{name="air", prob=0, param2=0},
		{name="air", prob=0, param2=0},
		{name="air", prob=0, param2=0},
		{name="air", prob=0, param2=0},
		{name="air", prob=0, param2=0},
		{name="air", prob=0, param2=0},
		{name="air", prob=0, param2=0},
		{name="air", prob=0, param2=0},
		{name="air", prob=0, param2=0},
		{name="air", prob=0, param2=0},
		{name="air", prob=0, param2=0},
		{name="air", prob=0, param2=0},
		{name="vlf_stairs:stair_sandstone", prob=254, param2=1},
		{name="vlf_core:sandstone", prob=254, param2=0},
		{name="vlf_core:sandstone", prob=254, param2=0},
		{name="vlf_core:sandstone", prob=254, param2=0},
		{name="vlf_stairs:stair_sandstone", prob=254, param2=3},
		{name="air", prob=0, param2=0},
		{name="air", prob=0, param2=0},
		{name="air", prob=0, param2=0},
		{name="air", prob=0, param2=0},
		{name="air", prob=0, param2=0},
		{name="air", prob=0, param2=0},
		{name="air", prob=0, param2=0},
		{name="air", prob=0, param2=0},
		{name="air", prob=0, param2=0},
		{name="air", prob=0, param2=0},
		{name="air", prob=0, param2=0},
		{name="air", prob=0, param2=0},
		{name="air", prob=0, param2=0},
		{name="air", prob=0, param2=0},
		{name="air", prob=0, param2=0},
		{name="air", prob=0, param2=0},
		{name="air", prob=0, param2=0},
		{name="air", prob=0, param2=0},
		{name="vlf_stairs:stair_sandstone", prob=254, param2=1},
		{name="vlf_core:sandstone", prob=254, param2=0},
		{name="vlf_stairs:stair_sandstone", prob=254, param2=3},
		{name="air", prob=0, param2=0},
		{name="air", prob=0, param2=0},
		{name="air", prob=0, param2=0},
		{name="air", prob=0, param2=0},
		{name="air", prob=0, param2=0},
		{name="air", prob=0, param2=0},
		{name="air", prob=0, param2=0},
		{name="air", prob=0, param2=0},
		{name="air", prob=0, param2=0},
		{name="air", prob=0, param2=0},
		{name="air", prob=0, param2=0},
		{name="air", prob=0, param2=0},
		{name="air", prob=0, param2=0},
		{name="air", prob=0, param2=0},
		{name="air", prob=0, param2=0},
		{name="air", prob=0, param2=0},
		{name="air", prob=0, param2=0},
		{name="air", prob=0, param2=0},
		{name="air", prob=0, param2=0},
		{name="air", prob=0, param2=0},
		{name="vlf_stairs:slab_sandstone", prob=254, param2=0},
		{name="air", prob=0, param2=0},
		{name="air", prob=0, param2=0},
		{name="air", prob=0, param2=0},
		{name="air", prob=0, param2=0},
		{name="air", prob=0, param2=0},
		{name="air", prob=0, param2=0},
		{name="air", prob=0, param2=0},
		{name="air", prob=0, param2=0},
		{name="air", prob=0, param2=0},
		{name="air", prob=0, param2=0},
		{name="air", prob=0, param2=0},
		{name="vlf_core:sandstone", prob=254, param2=0},
		{name="vlf_core:sandstone", prob=254, param2=0},
		{name="vlf_core:sandstone", prob=254, param2=0},
		{name="vlf_core:sandstone", prob=254, param2=0},
		{name="vlf_core:sandstone", prob=254, param2=0},
		{name="vlf_core:sandstone", prob=254, param2=0},
		{name="vlf_core:sandstone", prob=254, param2=0},
		{name="vlf_core:sandstone", prob=254, param2=0},
		{name="vlf_core:sandstone", prob=254, param2=0},
		{name="vlf_core:sandstone", prob=254, param2=0},
		{name="vlf_core:sandstone", prob=254, param2=0},
		{name="vlf_core:sandstone", prob=254, param2=0},
		{name="vlf_core:sandstone", prob=254, param2=0},
		{name="vlf_core:sandstone", prob=254, param2=0},
		{name="vlf_core:sandstone", prob=254, param2=0},
		{name="vlf_core:sandstone", prob=254, param2=0},
		{name="vlf_core:sandstone", prob=254, param2=0},
		{name="vlf_core:sandstone", prob=254, param2=0},
		{name="vlf_core:sandstone", prob=254, param2=0},
		{name="vlf_core:sandstone", prob=254, param2=0},
		{name="vlf_core:sandstone", prob=254, param2=0},
		{name="vlf_core:sandstone", prob=254, param2=0},
		{name="vlf_core:sandstone", prob=254, param2=0},
		{name="vlf_core:sandstone", prob=254, param2=0},
		{name="vlf_core:sandstone", prob=254, param2=0},
		{name="vlf_core:sandstone", prob=254, param2=0},
		{name="vlf_core:sandstone", prob=254, param2=0},
		{name="vlf_core:sandstone", prob=254, param2=0},
		{name="vlf_core:sandstone", prob=254, param2=0},
		{name="vlf_core:sandstone", prob=254, param2=0},
		{name="vlf_core:sandstone", prob=254, param2=0},
		{name="vlf_core:sandstone", prob=254, param2=0},
		{name="vlf_core:sandstone", prob=254, param2=0},
		{name="vlf_core:sandstone", prob=254, param2=0},
		{name="vlf_core:sandstone", prob=254, param2=0},
		{name="vlf_core:sandstone", prob=254, param2=0},
		{name="vlf_core:sandstone", prob=254, param2=0},
		{name="vlf_core:sandstone", prob=254, param2=0},
		{name="vlf_core:sandstone", prob=254, param2=0},
		{name="vlf_core:sandstone", prob=254, param2=0},
		{name="vlf_core:sandstone", prob=254, param2=0},
		{name="vlf_core:sandstone", prob=254, param2=0},
		{name="vlf_core:sandstone", prob=254, param2=0},
		{name="vlf_core:sandstone", prob=254, param2=0},
		{name="vlf_core:sandstone", prob=254, param2=0},
		{name="vlf_core:sandstone", prob=254, param2=0},
		{name="vlf_core:sandstone", prob=254, param2=0},
		{name="vlf_core:sandstone", prob=254, param2=0},
		{name="vlf_core:sandstone", prob=254, param2=0},
		{name="vlf_core:sandstone", prob=254, param2=0},
		{name="vlf_core:sandstone", prob=254, param2=0},
		{name="vlf_core:sandstone", prob=254, param2=0},
		{name="vlf_core:sandstone", prob=254, param2=0},
		{name="vlf_core:sandstone", prob=254, param2=0},
		{name="vlf_core:sandstone", prob=254, param2=0},
		{name="vlf_core:sandstone", prob=254, param2=0},
		{name="vlf_core:sandstone", prob=254, param2=0},
		{name="vlf_core:sandstone", prob=254, param2=0},
		{name="vlf_core:sandstone", prob=254, param2=0},
		{name="vlf_core:sandstone", prob=254, param2=0},
		{name="vlf_core:sandstone", prob=254, param2=0},
		{name="vlf_core:sandstone", prob=254, param2=0},
		{name="vlf_core:sandstone", prob=254, param2=0},
		{name="vlf_core:sandstone", prob=254, param2=0},
		{name="vlf_core:sandstone", prob=254, param2=0},
		{name="vlf_core:sandstone", prob=254, param2=0},
		{name="vlf_core:sandstone", prob=254, param2=0},
		{name="vlf_core:sandstone", prob=254, param2=0},
		{name="vlf_core:sandstone", prob=254, param2=0},
		{name="vlf_core:sandstone", prob=254, param2=0},
		{name="vlf_core:sandstone", prob=254, param2=0},
		{name="vlf_core:sandstone", prob=254, param2=0},
		{name="vlf_core:sandstone", prob=254, param2=0},
		{name="vlf_core:sandstone", prob=254, param2=0},
		{name="vlf_core:sandstone", prob=254, param2=0},
		{name="vlf_core:sandstone", prob=254, param2=0},
		{name="vlf_core:sandstone", prob=254, param2=0},
		{name="vlf_core:sandstone", prob=254, param2=0},
		{name="vlf_core:sandstone", prob=254, param2=0},
		{name="vlf_core:sandstone", prob=254, param2=0},
		{name="vlf_core:sandstone", prob=254, param2=0},
		{name="vlf_core:sandstone", prob=254, param2=0},
		{name="vlf_core:sandstone", prob=254, param2=0},
		{name="vlf_core:sandstone", prob=254, param2=0},
		{name="vlf_core:sandstone", prob=254, param2=0},
		{name="vlf_core:sandstone", prob=254, param2=0},
		{name="vlf_core:sandstone", prob=254, param2=0},
		{name="vlf_core:sandstone", prob=254, param2=0},
		{name="vlf_core:sandstone", prob=254, param2=0},
		{name="vlf_core:sandstone", prob=254, param2=0},
		{name="vlf_core:sandstone", prob=254, param2=0},
		{name="vlf_core:sandstone", prob=254, param2=0},
		{name="vlf_core:sandstone", prob=254, param2=0},
		{name="vlf_core:sandstone", prob=254, param2=0},
		{name="vlf_core:sandstone", prob=254, param2=0},
		{name="vlf_core:sandstone", prob=254, param2=0},
		{name="vlf_core:sandstone", prob=254, param2=0},
		{name="vlf_core:sandstone", prob=254, param2=0},
		{name="vlf_core:sandstone", prob=254, param2=0},
		{name="vlf_core:sandstone", prob=254, param2=0},
		{name="vlf_core:sandstone", prob=254, param2=0},
		{name="vlf_core:sandstone", prob=254, param2=0},
		{name="vlf_core:sandstone", prob=254, param2=0},
		{name="vlf_core:sandstone", prob=254, param2=0},
		{name="vlf_core:sandstone", prob=254, param2=0},
		{name="vlf_core:sandstone", prob=254, param2=0},
		{name="vlf_core:sandstone", prob=254, param2=0},
		{name="vlf_core:sandstone", prob=254, param2=0},
		{name="vlf_core:sandstone", prob=254, param2=0},
		{name="vlf_core:sandstone", prob=254, param2=0},
		{name="vlf_core:sandstone", prob=254, param2=0},
		{name="vlf_core:sandstone", prob=254, param2=0},
		{name="vlf_core:sandstone", prob=254, param2=0},
		{name="vlf_core:sandstone", prob=254, param2=0},
		{name="vlf_core:sandstone", prob=254, param2=0},
		{name="vlf_core:sandstone", prob=254, param2=0},
		{name="vlf_core:sandstone", prob=254, param2=0},
		{name="vlf_core:sandstone", prob=254, param2=0},
		{name="vlf_core:sandstone", prob=254, param2=0},
		{name="vlf_core:sandstone", prob=254, param2=0},
		{name="vlf_core:sandstone", prob=254, param2=0},
		{name="vlf_core:sandstone", prob=254, param2=0},
		{name="vlf_core:sandstone", prob=254, param2=0},
		{name="vlf_core:sandstone", prob=254, param2=0},
		{name="vlf_core:sandstone", prob=254, param2=0},
		{name="vlf_core:sandstone", prob=254, param2=0},
		{name="vlf_core:sandstone", prob=254, param2=0},
		{name="vlf_core:sandstone", prob=254, param2=0},
		{name="vlf_core:sandstone", prob=254, param2=0},
		{name="vlf_core:sandstone", prob=254, param2=0},
		{name="vlf_core:sandstone", prob=254, param2=0},
		{name="vlf_core:sandstone", prob=254, param2=0},
