schematic = {
	size = {x=20, y=10, z=20},
	yslice_prob = {
		{ypos=0, prob=254},
		{ypos=1, prob=254},
		{ypos=2, prob=254},
		{ypos=3, prob=254},
		{ypos=4, prob=254},
		{ypos=5, prob=254},
		{ypos=6, prob=254},
		{ypos=7, prob=254},
		{ypos=8, prob=254},
		{ypos=9, prob=254},
	},
	data = {
		{name="vlf_deepslate:deepslate", prob=254, param2=0},
		{name="vlf_deepslate:deepslate", prob=254, param2=0},
		{name="vlf_deepslate:deepslate", prob=254, param2=0},
		{name="vlf_deepslate:deepslate", prob=254, param2=0},
		{name="vlf_deepslate:deepslate", prob=254, param2=0},
		{name="vlf_deepslate:deepslate", prob=254, param2=0},
		{name="vlf_deepslate:deepslate", prob=254, param2=0},
		{name="vlf_sculk:sculk", prob=254, param2=0},
		{name="air", prob=254, param2=0},
		{name="air", prob=254, param2=0},
		{name="air", prob=254, param2=0},
		{name="air", prob=254, param2=0},
		{name="air", prob=254, param2=0},
		{name="vlf_deepslate:deepslate", prob=254, param2=0},
		{name="vlf_deepslate:deepslate", prob=254, param2=0},
		{name="vlf_deepslate:deepslate", prob=254, param2=0},
		{name="vlf_deepslate:deepslate", prob=254, param2=0},
		{name="vlf_deepslate:deepslate", prob=254, param2=0},
		{name="vlf_deepslate:deepslate", prob=254, param2=0},
		{name="vlf_deepslate:deepslate", prob=254, param2=0},
		{name="vlf_deepslate:deepslate", prob=254, param2=0},
		{name="vlf_deepslate:deepslate", prob=254, param2=0},
		{name="vlf_deepslate:deepslate", prob=254, param2=0},
		{name="vlf_deepslate:deepslate", prob=254, param2=0},
		{name="vlf_deepslate:deepslate", prob=254, param2=0},
		{name="vlf_deepslate:deepslate", prob=254, param2=0},
		{name="vlf_deepslate:deepslate", prob=254, param2=0},
		{name="air", prob=254, param2=0},
		{name="air", prob=254, param2=0},
		{name="air", prob=254, param2=0},
		{name="air", prob=254, param2=0},
		{name="air", prob=254, param2=0},
		{name="air", prob=254, param2=0},
		{name="vlf_deepslate:deepslate", prob=254, param2=0},
		{name="vlf_deepslate:deepslate", prob=254, param2=0},
		{name="vlf_deepslate:deepslate", prob=254, param2=0},
		{name="vlf_deepslate:deepslate", prob=254, param2=0},
		{name="vlf_deepslate:deepslate", prob=254, param2=0},
		{name="vlf_deepslate:deepslate", prob=254, param2=0},
		{name="vlf_deepslate:deepslate", prob=254, param2=0},
		{name="vlf_deepslate:deepslate", prob=254, param2=0},
		{name="vlf_deepslate:deepslate", prob=254, param2=0},
		{name="vlf_deepslate:deepslate", prob=254, param2=0},
		{name="vlf_deepslate:deepslate", prob=254, param2=0},
		{name="vlf_deepslate:deepslate", prob=254, param2=0},
		{name="vlf_deepslate:deepslate", prob=254, param2=0},
		{name="air", prob=254, param2=0},
		{name="air", prob=254, param2=0},
		{name="air", prob=254, param2=0},
		{name="air", prob=254, param2=0},
		{name="air", prob=254, param2=0},
		{name="air", prob=254, param2=0},
		{name="air", prob=254, param2=0},
		{name="vlf_deepslate:deepslate", prob=254, param2=0},
		{name="vlf_deepslate:deepslate", prob=254, param2=0},
		{name="vlf_deepslate:deepslate", prob=254, param2=0},
		{name="vlf_deepslate:deepslate", prob=254, param2=0},
		{name="vlf_deepslate:deepslate", prob=254, param2=0},
		{name="vlf_deepslate:deepslate", prob=254, param2=0},
		{name="vlf_deepslate:deepslate", prob=254, param2=0},
		{name="vlf_deepslate:deepslate", prob=254, param2=0},
		{name="vlf_deepslate:deepslate", prob=254, param2=0},
		{name="vlf_deepslate:deepslate", prob=254, param2=0},
		{name="vlf_deepslate:deepslate", prob=254, param2=0},
		{name="vlf_deepslate:deepslate", prob=254, param2=0},
		{name="vlf_deepslate:deepslate", prob=254, param2=0},
		{name="air", prob=254, param2=0},
		{name="air", prob=254, param2=0},
		{name="air", prob=254, param2=0},
		{name="air", prob=254, param2=0},
		{name="air", prob=254, param2=0},
		{name="air", prob=254, param2=0},
		{name="vlf_deepslate:deepslate", prob=254, param2=0},
		{name="vlf_deepslate:deepslate", prob=254, param2=0},
		{name="vlf_deepslate:deepslate", prob=254, param2=0},
		{name="vlf_deepslate:deepslate", prob=254, param2=0},
		{name="vlf_deepslate:deepslate", prob=254, param2=0},
		{name="air", prob=254, param2=0},
		{name="air", prob=254, param2=0},
		{name="air", prob=254, param2=0},
		{name="vlf_deepslate:deepslate", prob=254, param2=0},
		{name="vlf_deepslate:deepslate", prob=254, param2=0},
		{name="vlf_deepslate:deepslate", prob=254, param2=0},
		{name="vlf_deepslate:deepslate", prob=254, param2=0},
		{name="vlf_deepslate:deepslate", prob=254, param2=0},
		{name="vlf_deepslate:deepslate", prob=254, param2=0},
		{name="air", prob=254, param2=0},
		{name="air", prob=254, param2=0},
		{name="air", prob=254, param2=0},
		{name="air", prob=254, param2=0},
		{name="air", prob=254, param2=0},
		{name="vlf_deepslate:deepslate", prob=254, param2=0},
		{name="vlf_deepslate:deepslate", prob=254, param2=0},
		{name="vlf_deepslate:deepslate", prob=254, param2=0},
		{name="vlf_deepslate:deepslate", prob=254, param2=0},
		{name="vlf_deepslate:deepslate", prob=254, param2=0},
		{name="vlf_deepslate:deepslate", prob=254, param2=0},
		{name="air", prob=254, param2=0},
		{name="air", prob=254, param2=0},
		{name="air", prob=254, param2=0},
		{name="vlf_deepslate:deepslate", prob=254, param2=0},
		{name="vlf_deepslate:deepslate", prob=254, param2=0},
		{name="vlf_deepslate:deepslate", prob=254, param2=0},
		{name="vlf_deepslate:deepslate", prob=254, param2=0},
		{name="vlf_deepslate:deepslate", prob=254, param2=0},
		{name="vlf_deepslate:deepslate", prob=254, param2=0},
		{name="air", prob=254, param2=0},
		{name="air", prob=254, param2=0},
		{name="air", prob=254, param2=0},
		{name="air", prob=254, param2=0},
		{name="air", prob=254, param2=0},
		{name="vlf_deepslate:deepslate", prob=254, param2=0},
		{name="vlf_deepslate:deepslate", prob=254, param2=0},
		{name="vlf_deepslate:deepslate", prob=254, param2=0},
		{name="vlf_deepslate:deepslate", prob=254, param2=0},
		{name="vlf_deepslate:deepslate", prob=254, param2=0},
		{name="vlf_deepslate:deepslate", prob=254, param2=0},
		{name="air", prob=254, param2=0},
		{name="air", prob=254, param2=0},
		{name="air", prob=254, param2=0},
		{name="vlf_deepslate:deepslate", prob=254, param2=0},
		{name="vlf_deepslate:deepslate", prob=254, param2=0},
		{name="vlf_deepslate:deepslate", prob=254, param2=0},
		{name="vlf_deepslate:deepslate", prob=254, param2=0},
		{name="vlf_deepslate:deepslate", prob=254, param2=0},
		{name="vlf_deepslate:deepslate", prob=254, param2=0},
		{name="vlf_deepslate:deepslate", prob=254, param2=0},
		{name="air", prob=254, param2=0},
		{name="air", prob=254, param2=0},
		{name="air", prob=254, param2=0},
		{name="air", prob=254, param2=0},
		{name="vlf_deepslate:deepslate", prob=254, param2=0},
		{name="vlf_deepslate:deepslate", prob=254, param2=0},
		{name="vlf_deepslate:deepslate", prob=254, param2=0},
		{name="vlf_deepslate:deepslate", prob=254, param2=0},
		{name="vlf_deepslate:deepslate", prob=254, param2=0},
		{name="vlf_deepslate:deepslate", prob=254, param2=0},
		{name="air", prob=254, param2=0},
		{name="air", prob=254, param2=0},
		{name="air", prob=254, param2=0},
		{name="vlf_deepslate:deepslate", prob=254, param2=0},
		{name="vlf_deepslate:deepslate", prob=254, param2=0},
		{name="vlf_deepslate:deepslate", prob=254, param2=0},
		{name="vlf_deepslate:deepslate", prob=254, param2=0},
		{name="vlf_deepslate:deepslate", prob=254, param2=0},
		{name="vlf_deepslate:deepslate", prob=254, param2=0},
		{name="vlf_deepslate:deepslate", prob=254, param2=0},
		{name="air", prob=254, param2=0},
		{name="air", prob=254, param2=0},
		{name="air", prob=254, param2=0},
		{name="air", prob=254, param2=0},
		{name="vlf_deepslate:deepslate", prob=254, param2=0},
		{name="vlf_deepslate:deepslate", prob=254, param2=0},
		{name="vlf_deepslate:deepslate", prob=254, param2=0},
		{name="vlf_deepslate:deepslate", prob=254, param2=0},
		{name="vlf_deepslate:deepslate", prob=254, param2=0},
		{name="vlf_deepslate:deepslate", prob=254, param2=0},
		{name="air", prob=254, param2=0},
		{name="air", prob=254, param2=0},
		{name="air", prob=254, param2=0},
		{name="vlf_deepslate:deepslate", prob=254, param2=0},
		{name="vlf_deepslate:deepslate", prob=254, param2=0},
		{name="vlf_deepslate:deepslate", prob=254, param2=0},
		{name="vlf_deepslate:deepslate", prob=254, param2=0},
		{name="vlf_deepslate:deepslate", prob=254, param2=0},
		{name="vlf_deepslate:deepslate", prob=254, param2=0},
		{name="vlf_deepslate:deepslate", prob=254, param2=0},
		{name="vlf_deepslate:deepslate", prob=254, param2=0},
		{name="vlf_deepslate:deepslate", prob=254, param2=0},
		{name="vlf_deepslate:deepslate", prob=254, param2=0},
		{name="vlf_deepslate:deepslate", prob=254, param2=0},
		{name="vlf_deepslate:deepslate", prob=254, param2=0},
		{name="vlf_deepslate:deepslate", prob=254, param2=0},
		{name="vlf_deepslate:deepslate", prob=254, param2=0},
		{name="vlf_deepslate:deepslate", prob=254, param2=0},
		{name="vlf_deepslate:deepslate", prob=254, param2=0},
		{name="vlf_deepslate:deepslate", prob=254, param2=0},
		{name="air", prob=254, param2=0},
		{name="air", prob=254, param2=0},
		{name="air", prob=254, param2=0},
		{name="vlf_deepslate:deepslate", prob=254, param2=0},
		{name="vlf_deepslate:deepslate", prob=254, param2=0},
		{name="vlf_deepslate:deepslate", prob=254, param2=0},
		{name="vlf_deepslate:deepslate", prob=254, param2=0},
		{name="vlf_deepslate:deepslate", prob=254, param2=0},
		{name="vlf_deepslate:deepslate", prob=254, param2=0},
		{name="vlf_deepslate:deepslate", prob=254, param2=0},
		{name="vlf_deepslate:deepslate", prob=254, param2=0},
		{name="vlf_deepslate:deepslate", prob=254, param2=0},
		{name="vlf_deepslate:deepslate", prob=254, param2=0},
		{name="vlf_deepslate:deepslate", prob=254, param2=0},
		{name="vlf_deepslate:deepslate", prob=254, param2=0},
		{name="vlf_deepslate:deepslate", prob=254, param2=0},
		{name="vlf_deepslate:deepslate", prob=254, param2=0},
		{name="vlf_deepslate:deepslate", prob=254, param2=0},
		{name="vlf_deepslate:deepslate", prob=254, param2=0},
		{name="vlf_deepslate:deepslate", prob=254, param2=0},
		{name="air", prob=254, param2=0},
		{name="air", prob=254, param2=0},
		{name="air", prob=254, param2=0},
		{name="vlf_deepslate:deepslate", prob=254, param2=0},
		{name="vlf_deepslate:deepslate", prob=254, param2=0},
		{name="vlf_deepslate:deepslate", prob=254, param2=0},
		{name="vlf_deepslate:deepslate", prob=254, param2=0},
		{name="vlf_deepslate:deepslate", prob=254, param2=0},
		{name="vlf_deepslate:deepslate", prob=254, param2=0},
		{name="vlf_deepslate:deepslate", prob=254, param2=0},
		{name="vlf_sculk:sculk", prob=254, param2=0},
		{name="vlf_sculk:catalyst", prob=254, param2=0},
		{name="air", prob=254, param2=0},
		{name="air", prob=254, param2=0},
		{name="air", prob=254, param2=0},
		{name="air", prob=254, param2=0},
		{name="air", prob=254, param2=0},
		{name="air", prob=254, param2=0},
		{name="vlf_deepslate:deepslate", prob=254, param2=0},
		{name="vlf_deepslate:deepslate", prob=254, param2=0},
		{name="vlf_deepslate:deepslate", prob=254, param2=0},
		{name="vlf_deepslate:deepslate", prob=254, param2=0},
		{name="vlf_deepslate:deepslate", prob=254, param2=0},
		{name="vlf_deepslate:deepslate", prob=254, param2=0},
		{name="vlf_deepslate:deepslate", prob=254, param2=0},
		{name="vlf_deepslate:deepslate", prob=254, param2=0},
		{name="vlf_deepslate:deepslate", prob=254, param2=0},
		{name="vlf_deepslate:deepslate", prob=254, param2=0},
		{name="vlf_deepslate:deepslate", prob=254, param2=0},
		{name="vlf_deepslate:deepslate", prob=254, param2=0},
		{name="air", prob=254, param2=0},
		{name="air", prob=254, param2=0},
		{name="air", prob=254, param2=0},
		{name="air", prob=254, param2=0},
		{name="air", prob=254, param2=0},
		{name="air", prob=254, param2=0},
		{name="air", prob=254, param2=0},
		{name="air", prob=254, param2=0},
		{name="vlf_deepslate:deepslate", prob=254, param2=0},
		{name="vlf_deepslate:deepslate", prob=254, param2=0},
		{name="vlf_deepslate:deepslate", prob=254, param2=0},
		{name="vlf_deepslate:deepslate", prob=254, param2=0},
		{name="vlf_deepslate:deepslate", prob=254, param2=0},
		{name="vlf_deepslate:deepslate", prob=254, param2=0},
		{name="vlf_deepslate:deepslate", prob=254, param2=0},
		{name="vlf_deepslate:deepslate", prob=254, param2=0},
		{name="vlf_deepslate:deepslate", prob=254, param2=0},
		{name="vlf_deepslate:deepslate", prob=254, param2=0},
		{name="vlf_deepslate:deepslate", prob=254, param2=0},
		{name="vlf_deepslate:deepslate", prob=254, param2=0},
		{name="air", prob=254, param2=0},
		{name="air", prob=254, param2=0},
		{name="air", prob=254, param2=0},
		{name="air", prob=254, param2=0},
		{name="air", prob=254, param2=0},
		{name="air", prob=254, param2=0},
		{name="air", prob=254, param2=0},
		{name="air", prob=254, param2=0},
		{name="vlf_deepslate:deepslate", prob=254, param2=0},
		{name="vlf_deepslate:deepslate", prob=254, param2=0},
		{name="vlf_deepslate:deepslate", prob=254, param2=0},
		{name="vlf_deepslate:deepslate", prob=254, param2=0},
		{name="vlf_deepslate:deepslate", prob=254, param2=0},
		{name="vlf_deepslate:deepslate", prob=254, param2=0},
		{name="vlf_deepslate:deepslate", prob=254, param2=0},
		{name="vlf_deepslate:deepslate", prob=254, param2=0},
		{name="vlf_deepslate:deepslate", prob=254, param2=0},
		{name="vlf_deepslate:deepslate", prob=254, param2=0},
		{name="vlf_deepslate:deepslate", prob=254, param2=0},
		{name="air", prob=254, param2=0},
		{name="air", prob=254, param2=0},
		{name="air", prob=254, param2=0},
		{name="air", prob=254, param2=0},
		{name="air", prob=254, param2=0},
		{name="air", prob=254, param2=0},
		{name="air", prob=254, param2=0},
		{name="air", prob=254, param2=0},
		{name="vlf_deepslate:deepslate", prob=254, param2=0},
		{name="vlf_deepslate:deepslate_with_coal", prob=254, param2=0},
		{name="vlf_deepslate:deepslate", prob=254, param2=0},
		{name="vlf_deepslate:deepslate", prob=254, param2=0},
		{name="air", prob=254, param2=0},
		{name="air", prob=254, param2=0},
		{name="vlf_deepslate:deepslate", prob=254, param2=0},
		{name="vlf_deepslate:deepslate", prob=254, param2=0},
		{name="vlf_deepslate:deepslate", prob=254, param2=0},
		{name="vlf_deepslate:deepslate", prob=254, param2=0},
		{name="vlf_deepslate:deepslate", prob=254, param2=0},
		{name="vlf_deepslate:deepslate", prob=254, param2=0},
		{name="air", prob=254, param2=0},
		{name="air", prob=254, param2=0},
		{name="air", prob=254, param2=0},
		{name="air", prob=254, param2=0},
		{name="air", prob=254, param2=0},
		{name="vlf_deepslate:deepslate", prob=254, param2=0},
		{name="air", prob=254, param2=0},
		{name="vlf_deepslate:deepslate", prob=254, param2=0},
		{name="vlf_deepslate:deepslate", prob=254, param2=0},
		{name="vlf_deepslate:deepslate_with_coal", prob=254, param2=0},
		{name="vlf_deepslate:deepslate", prob=254, param2=0},
		{name="vlf_deepslate:deepslate", prob=254, param2=0},
		{name="air", prob=254, param2=0},
		{name="air", prob=254, param2=0},
		{name="vlf_deepslate:deepslate", prob=254, param2=0},
		{name="vlf_deepslate:deepslate", prob=254, param2=0},
		{name="vlf_deepslate:deepslate", prob=254, param2=0},
		{name="vlf_deepslate:deepslate", prob=254, param2=0},
		{name="vlf_deepslate:deepslate", prob=254, param2=0},
		{name="vlf_deepslate:deepslate", prob=254, param2=0},
		{name="air", prob=254, param2=0},
		{name="air", prob=254, param2=0},
		{name="air", prob=254, param2=0},
		{name="air", prob=254, param2=0},
		{name="air", prob=254, param2=0},
		{name="vlf_deepslate:deepslate", prob=254, param2=0},
		{name="vlf_deepslate:deepslate", prob=254, param2=0},
		{name="vlf_deepslate:deepslate", prob=254, param2=0},
		{name="vlf_deepslate:deepslate", prob=254, param2=0},
		{name="vlf_deepslate:deepslate", prob=254, param2=0},
		{name="vlf_deepslate:deepslate", prob=254, param2=0},
		{name="air", prob=254, param2=0},
		{name="air", prob=254, param2=0},
		{name="air", prob=254, param2=0},
		{name="vlf_deepslate:deepslate", prob=254, param2=0},
		{name="vlf_deepslate:deepslate", prob=254, param2=0},
		{name="vlf_deepslate:deepslate", prob=254, param2=0},
		{name="vlf_deepslate:deepslate", prob=254, param2=0},
		{name="vlf_deepslate:deepslate", prob=254, param2=0},
		{name="vlf_deepslate:deepslate", prob=254, param2=0},
		{name="vlf_deepslate:deepslate", prob=254, param2=0},
		{name="vlf_deepslate:deepslate", prob=254, param2=0},
		{name="air", prob=254, param2=0},
		{name="air", prob=254, param2=0},
		{name="vlf_deepslate:deepslate", prob=254, param2=0},
		{name="vlf_deepslate:deepslate", prob=254, param2=0},
		{name="vlf_deepslate:deepslate", prob=254, param2=0},
		{name="vlf_deepslate:deepslate", prob=254, param2=0},
		{name="vlf_deepslate:deepslate", prob=254, param2=0},
		{name="vlf_deepslate:deepslate", prob=254, param2=0},
		{name="air", prob=254, param2=0},
		{name="air", prob=254, param2=0},
		{name="air", prob=254, param2=0},
		{name="air", prob=254, param2=0},
		{name="vlf_deepslate:deepslate", prob=254, param2=0},
		{name="vlf_deepslate:deepslate", prob=254, param2=0},
		{name="vlf_deepslate:deepslate", prob=254, param2=0},
		{name="vlf_deepslate:deepslate_with_redstone", prob=254, param2=0},
		{name="vlf_deepslate:deepslate", prob=254, param2=0},
		{name="vlf_deepslate:deepslate", prob=254, param2=0},
		{name="vlf_deepslate:deepslate", prob=254, param2=0},
		{name="vlf_deepslate:deepslate", prob=254, param2=0},
		{name="vlf_deepslate:deepslate", prob=254, param2=0},
		{name="vlf_deepslate:deepslate", prob=254, param2=0},
		{name="vlf_deepslate:deepslate", prob=254, param2=0},
		{name="vlf_deepslate:deepslate", prob=254, param2=0},
		{name="vlf_deepslate:deepslate", prob=254, param2=0},
		{name="vlf_deepslate:deepslate", prob=254, param2=0},
		{name="vlf_deepslate:deepslate", prob=254, param2=0},
		{name="vlf_deepslate:deepslate", prob=254, param2=0},
		{name="air", prob=254, param2=0},
		{name="air", prob=254, param2=0},
		{name="air", prob=254, param2=0},
		{name="air", prob=254, param2=0},
		{name="vlf_deepslate:deepslate", prob=254, param2=0},
		{name="vlf_deepslate:deepslate", prob=254, param2=0},
		{name="vlf_deepslate:deepslate", prob=254, param2=0},
		{name="vlf_deepslate:deepslate_with_redstone", prob=254, param2=0},
		{name="vlf_deepslate:deepslate", prob=254, param2=0},
		{name="vlf_deepslate:deepslate", prob=254, param2=0},
		{name="vlf_deepslate:deepslate", prob=254, param2=0},
		{name="vlf_deepslate:deepslate", prob=254, param2=0},
		{name="vlf_deepslate:deepslate", prob=254, param2=0},
		{name="vlf_deepslate:deepslate", prob=254, param2=0},
		{name="vlf_deepslate:deepslate", prob=254, param2=0},
		{name="vlf_deepslate:deepslate", prob=254, param2=0},
		{name="vlf_deepslate:deepslate", prob=254, param2=0},
		{name="vlf_deepslate:deepslate", prob=254, param2=0},
		{name="vlf_deepslate:deepslate", prob=254, param2=0},
		{name="vlf_deepslate:deepslate", prob=254, param2=0},
		{name="air", prob=254, param2=0},
		{name="air", prob=254, param2=0},
		{name="air", prob=254, param2=0},
		{name="air", prob=254, param2=0},
		{name="vlf_deepslate:deepslate", prob=254, param2=0},
		{name="vlf_deepslate:deepslate", prob=254, param2=0},
		{name="vlf_deepslate:deepslate", prob=254, param2=0},
		{name="vlf_deepslate:deepslate", prob=254, param2=0},
		{name="vlf_deepslate:deepslate", prob=254, param2=0},
		{name="vlf_deepslate:deepslate", prob=254, param2=0},
		{name="vlf_deepslate:deepslate", prob=254, param2=0},
		{name="vlf_deepslate:deepslate", prob=254, param2=0},
		{name="vlf_deepslate:deepslate", prob=254, param2=0},
		{name="vlf_deepslate:deepslate", prob=254, param2=0},
		{name="vlf_deepslate:deepslate", prob=254, param2=0},
		{name="vlf_deepslate:deepslate", prob=254, param2=0},
		{name="vlf_deepslate:deepslate", prob=254, param2=0},
		{name="vlf_deepslate:deepslate", prob=254, param2=0},
		{name="vlf_deepslate:deepslate", prob=254, param2=0},
		{name="vlf_deepslate:deepslate_with_iron", prob=254, param2=0},
		{name="air", prob=254, param2=0},
		{name="air", prob=254, param2=0},
		{name="air", prob=254, param2=0},
		{name="air", prob=254, param2=0},
		{name="air", prob=254, param2=0},
		{name="air", prob=254, param2=0},
		{name="air", prob=254, param2=0},
		{name="vlf_deepslate:deepslate", prob=254, param2=0},
		{name="vlf_deepslate:deepslate_with_redstone", prob=254, param2=0},
		{name="vlf_deepslate:deepslate", prob=254, param2=0},
		{name="vlf_deepslate:deepslate", prob=254, param2=0},
		{name="vlf_sculk:sculk", prob=254, param2=0},
		{name="air", prob=254, param2=0},
		{name="air", prob=254, param2=0},
		{name="air", prob=254, param2=0},
		{name="air", prob=254, param2=0},
		{name="air", prob=254, param2=0},
		{name="air", prob=254, param2=0},
		{name="air", prob=254, param2=0},
		{name="vlf_deepslate:deepslate", prob=254, param2=0},
		{name="vlf_deepslate:deepslate", prob=254, param2=0},
		{name="vlf_deepslate:deepslate", prob=254, param2=0},
		{name="vlf_deepslate:deepslate", prob=254, param2=0},
		{name="vlf_deepslate:deepslate", prob=254, param2=0},
		{name="air", prob=254, param2=0},
		{name="air", prob=254, param2=0},
		{name="air", prob=254, param2=0},
		{name="vlf_deepslate:deepslate", prob=254, param2=0},
		{name="vlf_deepslate:deepslate", prob=254, param2=0},
		{name="vlf_deepslate:deepslate", prob=254, param2=0},
		{name="vlf_deepslate:deepslate", prob=254, param2=0},
		{name="air", prob=254, param2=0},
		{name="air", prob=254, param2=0},
		{name="air", prob=254, param2=0},
		{name="air", prob=254, param2=0},
		{name="air", prob=254, param2=0},
		{name="air", prob=254, param2=0},
		{name="air", prob=254, param2=0},
		{name="air", prob=254, param2=0},
		{name="vlf_deepslate:deepslate", prob=254, param2=0},
		{name="vlf_deepslate:deepslate", prob=254, param2=0},
		{name="vlf_deepslate:deepslate", prob=254, param2=0},
		{name="vlf_deepslate:deepslate", prob=254, param2=0},
		{name="vlf_deepslate:deepslate", prob=254, param2=0},
		{name="air", prob=254, param2=0},
		{name="air", prob=254, param2=0},
		{name="air", prob=254, param2=0},
		{name="vlf_deepslate:deepslate", prob=254, param2=0},
		{name="vlf_deepslate:deepslate", prob=254, param2=0},
		{name="vlf_deepslate:deepslate", prob=254, param2=0},
		{name="vlf_deepslate:deepslate", prob=254, param2=0},
		{name="air", prob=254, param2=0},
		{name="air", prob=254, param2=0},
		{name="air", prob=254, param2=0},
		{name="air", prob=254, param2=0},
		{name="air", prob=254, param2=0},
		{name="air", prob=254, param2=0},
		{name="air", prob=254, param2=0},
		{name="air", prob=254, param2=0},
		{name="vlf_deepslate:deepslate_with_coal", prob=254, param2=0},
		{name="vlf_deepslate:deepslate_with_coal", prob=254, param2=0},
		{name="vlf_deepslate:deepslate", prob=254, param2=0},
		{name="vlf_deepslate:deepslate", prob=254, param2=0},
		{name="vlf_deepslate:deepslate", prob=254, param2=0},
		{name="vlf_deepslate:deepslate", prob=254, param2=0},
		{name="vlf_deepslate:deepslate", prob=254, param2=0},
		{name="vlf_deepslate:deepslate", prob=254, param2=0},
		{name="vlf_deepslate:deepslate", prob=254, param2=0},
		{name="vlf_deepslate:deepslate", prob=254, param2=0},
		{name="vlf_deepslate:deepslate", prob=254, param2=0},
		{name="air", prob=254, param2=0},
		{name="air", prob=254, param2=0},
		{name="air", prob=254, param2=0},
		{name="air", prob=254, param2=0},
		{name="air", prob=254, param2=0},
		{name="air", prob=254, param2=0},
		{name="air", prob=254, param2=0},
		{name="air", prob=254, param2=0},
		{name="vlf_deepslate:deepslate", prob=254, param2=0},
		{name="vlf_deepslate:deepslate_with_coal", prob=254, param2=0},
		{name="vlf_deepslate:deepslate_with_coal", prob=254, param2=0},
		{name="vlf_deepslate:deepslate_with_coal", prob=254, param2=0},
		{name="air", prob=254, param2=0},
		{name="air", prob=254, param2=0},
		{name="vlf_deepslate:deepslate", prob=254, param2=0},
		{name="vlf_deepslate:deepslate", prob=254, param2=0},
		{name="vlf_deepslate:deepslate", prob=254, param2=0},
		{name="vlf_deepslate:deepslate", prob=254, param2=0},
		{name="vlf_deepslate:deepslate", prob=254, param2=0},
		{name="air", prob=254, param2=0},
		{name="air", prob=254, param2=0},
		{name="air", prob=254, param2=0},
		{name="air", prob=254, param2=0},
		{name="air", prob=254, param2=0},
		{name="air", prob=254, param2=0},
		{name="vlf_deepslate:deepslate", prob=254, param2=0},
		{name="vlf_deepslate:deepslate", prob=254, param2=0},
		{name="air", prob=254, param2=0},
		{name="vlf_deepslate:deepslate", prob=254, param2=0},
		{name="vlf_deepslate:deepslate", prob=254, param2=0},
		{name="vlf_deepslate:deepslate", prob=254, param2=0},
		{name="vlf_deepslate:deepslate_with_coal", prob=254, param2=0},
		{name="air", prob=254, param2=0},
		{name="air", prob=254, param2=0},
		{name="vlf_deepslate:deepslate", prob=254, param2=0},
		{name="vlf_deepslate:deepslate", prob=254, param2=0},
		{name="vlf_deepslate:deepslate", prob=254, param2=0},
		{name="vlf_deepslate:deepslate", prob=254, param2=0},
		{name="vlf_deepslate:deepslate", prob=254, param2=0},
		{name="vlf_deepslate:deepslate", prob=254, param2=0},
		{name="air", prob=254, param2=0},
		{name="air", prob=254, param2=0},
		{name="air", prob=254, param2=0},
		{name="air", prob=254, param2=0},
		{name="vlf_deepslate:deepslate", prob=254, param2=0},
		{name="vlf_deepslate:deepslate", prob=254, param2=0},
		{name="vlf_deepslate:deepslate", prob=254, param2=0},
		{name="vlf_deepslate:deepslate", prob=254, param2=0},
		{name="vlf_deepslate:deepslate", prob=254, param2=0},
		{name="vlf_deepslate:deepslate", prob=254, param2=0},
		{name="vlf_deepslate:deepslate", prob=254, param2=0},
		{name="air", prob=254, param2=0},
		{name="air", prob=254, param2=0},
		{name="air", prob=254, param2=0},
		{name="vlf_deepslate:deepslate", prob=254, param2=0},
		{name="vlf_deepslate:deepslate", prob=254, param2=0},
		{name="vlf_deepslate:deepslate", prob=254, param2=0},
		{name="vlf_deepslate:deepslate", prob=254, param2=0},
		{name="vlf_deepslate:deepslate", prob=254, param2=0},
		{name="vlf_deepslate:deepslate", prob=254, param2=0},
		{name="vlf_deepslate:deepslate", prob=254, param2=0},
		{name="vlf_deepslate:deepslate", prob=254, param2=0},
		{name="vlf_deepslate:deepslate", prob=254, param2=0},
		{name="vlf_deepslate:deepslate", prob=254, param2=0},
		{name="vlf_deepslate:deepslate", prob=254, param2=0},
		{name="vlf_deepslate:deepslate", prob=254, param2=0},
		{name="vlf_deepslate:deepslate", prob=254, param2=0},
		{name="vlf_deepslate:deepslate", prob=254, param2=0},
		{name="vlf_deepslate:deepslate", prob=254, param2=0},
		{name="vlf_deepslate:deepslate", prob=254, param2=0},
		{name="air", prob=254, param2=0},
		{name="air", prob=254, param2=0},
		{name="air", prob=254, param2=0},
		{name="air", prob=254, param2=0},
		{name="vlf_deepslate:deepslate", prob=254, param2=0},
		{name="vlf_deepslate:deepslate", prob=254, param2=0},
		{name="vlf_deepslate:deepslate_with_redstone", prob=254, param2=0},
		{name="vlf_deepslate:deepslate", prob=254, param2=0},
		{name="vlf_deepslate:deepslate", prob=254, param2=0},
		{name="vlf_deepslate:deepslate", prob=254, param2=0},
		{name="vlf_deepslate:deepslate", prob=254, param2=0},
		{name="vlf_deepslate:deepslate", prob=254, param2=0},
		{name="vlf_deepslate:deepslate", prob=254, param2=0},
		{name="vlf_deepslate:deepslate", prob=254, param2=0},
		{name="vlf_deepslate:deepslate", prob=254, param2=0},
		{name="vlf_deepslate:deepslate", prob=254, param2=0},
		{name="vlf_deepslate:deepslate", prob=254, param2=0},
		{name="vlf_deepslate:deepslate", prob=254, param2=0},
		{name="vlf_deepslate:deepslate", prob=254, param2=0},
		{name="vlf_deepslate:deepslate", prob=254, param2=0},
		{name="air", prob=254, param2=0},
		{name="air", prob=254, param2=0},
		{name="air", prob=254, param2=0},
		{name="air", prob=254, param2=0},
		{name="vlf_deepslate:deepslate", prob=254, param2=0},
		{name="vlf_deepslate:deepslate", prob=254, param2=0},
		{name="vlf_deepslate:deepslate", prob=254, param2=0},
		{name="vlf_deepslate:deepslate_with_redstone", prob=254, param2=0},
		{name="vlf_deepslate:deepslate", prob=254, param2=0},
		{name="vlf_deepslate:deepslate", prob=254, param2=0},
		{name="vlf_deepslate:deepslate", prob=254, param2=0},
		{name="vlf_deepslate:deepslate", prob=254, param2=0},
		{name="vlf_deepslate:deepslate", prob=254, param2=0},
		{name="vlf_deepslate:deepslate", prob=254, param2=0},
		{name="vlf_deepslate:deepslate", prob=254, param2=0},
		{name="vlf_deepslate:deepslate", prob=254, param2=0},
		{name="vlf_deepslate:deepslate", prob=254, param2=0},
		{name="vlf_deepslate:deepslate", prob=254, param2=0},
		{name="vlf_deepslate:deepslate", prob=254, param2=0},
		{name="vlf_deepslate:deepslate", prob=254, param2=0},
		{name="air", prob=254, param2=0},
		{name="air", prob=254, param2=0},
		{name="air", prob=254, param2=0},
		{name="air", prob=254, param2=0},
		{name="vlf_deepslate:deepslate", prob=254, param2=0},
		{name="vlf_deepslate:deepslate_with_redstone", prob=254, param2=0},
		{name="vlf_deepslate:deepslate", prob=254, param2=0},
		{name="vlf_deepslate:deepslate", prob=254, param2=0},
		{name="vlf_deepslate:deepslate", prob=254, param2=0},
		{name="vlf_deepslate:deepslate", prob=254, param2=0},
		{name="vlf_deepslate:deepslate", prob=254, param2=0},
		{name="vlf_deepslate:deepslate", prob=254, param2=0},
		{name="vlf_deepslate:deepslate", prob=254, param2=0},
		{name="vlf_deepslate:deepslate", prob=254, param2=0},
		{name="vlf_deepslate:deepslate", prob=254, param2=0},
		{name="vlf_deepslate:deepslate", prob=254, param2=0},
		{name="vlf_deepslate:deepslate", prob=254, param2=0},
		{name="vlf_deepslate:deepslate", prob=254, param2=0},
		{name="vlf_deepslate:deepslate", prob=254, param2=0},
		{name="vlf_deepslate:deepslate", prob=254, param2=0},
		{name="vlf_deepslate:deepslate_with_iron", prob=254, param2=0},
		{name="air", prob=254, param2=0},
		{name="air", prob=254, param2=0},
		{name="air", prob=254, param2=0},
		{name="air", prob=254, param2=0},
		{name="air", prob=254, param2=0},
		{name="air", prob=254, param2=0},
		{name="air", prob=254, param2=0},
		{name="air", prob=254, param2=0},
		{name="air", prob=254, param2=0},
		{name="vlf_sculk:sculk", prob=254, param2=0},
		{name="vlf_sculk:sculk", prob=254, param2=0},
		{name="air", prob=254, param2=0},
		{name="air", prob=254, param2=0},
		{name="air", prob=254, param2=0},
		{name="air", prob=254, param2=0},
		{name="air", prob=254, param2=0},
		{name="air", prob=254, param2=0},
		{name="vlf_deepslate:deepslate", prob=254, param2=0},
		{name="vlf_deepslate:deepslate", prob=254, param2=0},
		{name="vlf_deepslate:deepslate", prob=254, param2=0},
		{name="vlf_deepslate:deepslate", prob=254, param2=0},
		{name="vlf_deepslate:deepslate", prob=254, param2=0},
		{name="vlf_deepslate:deepslate", prob=254, param2=0},
		{name="air", prob=254, param2=0},
		{name="air", prob=254, param2=0},
		{name="air", prob=254, param2=0},
		{name="air", prob=254, param2=0},
		{name="air", prob=254, param2=0},
		{name="air", prob=254, param2=0},
		{name="air", prob=254, param2=0},
		{name="air", prob=254, param2=0},
		{name="air", prob=254, param2=0},
		{name="air", prob=254, param2=0},
		{name="air", prob=254, param2=0},
		{name="air", prob=254, param2=0},
		{name="air", prob=254, param2=0},
		{name="air", prob=254, param2=0},
		{name="vlf_deepslate:deepslate", prob=254, param2=0},
		{name="vlf_deepslate:deepslate", prob=254, param2=0},
		{name="vlf_deepslate:deepslate", prob=254, param2=0},
		{name="vlf_deepslate:deepslate", prob=254, param2=0},
		{name="vlf_deepslate:deepslate", prob=254, param2=0},
		{name="vlf_deepslate:deepslate", prob=254, param2=0},
		{name="air", prob=254, param2=0},
		{name="air", prob=254, param2=0},
		{name="air", prob=254, param2=0},
		{name="air", prob=254, param2=0},
		{name="air", prob=254, param2=0},
		{name="air", prob=254, param2=0},
		{name="air", prob=254, param2=0},
		{name="air", prob=254, param2=0},
		{name="air", prob=254, param2=0},
		{name="air", prob=254, param2=0},
		{name="air", prob=254, param2=0},
		{name="air", prob=254, param2=0},
		{name="air", prob=254, param2=0},
		{name="air", prob=254, param2=0},
		{name="vlf_deepslate:deepslate", prob=254, param2=0},
		{name="vlf_deepslate:deepslate_with_coal", prob=254, param2=0},
		{name="vlf_deepslate:deepslate_with_coal", prob=254, param2=0},
		{name="vlf_deepslate:deepslate", prob=254, param2=0},
		{name="vlf_deepslate:deepslate", prob=254, param2=0},
		{name="vlf_deepslate:deepslate", prob=254, param2=0},
		{name="air", prob=254, param2=0},
		{name="air", prob=254, param2=0},
		{name="air", prob=254, param2=0},
		{name="air", prob=254, param2=0},
		{name="air", prob=254, param2=0},
		{name="air", prob=254, param2=0},
		{name="air", prob=254, param2=0},
		{name="air", prob=254, param2=0},
		{name="air", prob=254, param2=0},
		{name="air", prob=254, param2=0},
		{name="air", prob=254, param2=0},
		{name="air", prob=254, param2=0},
		{name="air", prob=254, param2=0},
		{name="air", prob=254, param2=0},
		{name="vlf_deepslate:deepslate", prob=254, param2=0},
		{name="vlf_deepslate:deepslate_with_coal", prob=254, param2=0},
		{name="vlf_deepslate:deepslate_with_coal", prob=254, param2=0},
		{name="vlf_deepslate:deepslate_with_coal", prob=254, param2=0},
		{name="vlf_deepslate:deepslate", prob=254, param2=0},
		{name="vlf_deepslate:deepslate", prob=254, param2=0},
		{name="vlf_deepslate:deepslate", prob=254, param2=0},
		{name="vlf_deepslate:deepslate", prob=254, param2=0},
		{name="air", prob=254, param2=0},
		{name="air", prob=254, param2=0},
		{name="air", prob=254, param2=0},
		{name="air", prob=254, param2=0},
		{name="air", prob=254, param2=0},
		{name="air", prob=254, param2=0},
		{name="air", prob=254, param2=0},
		{name="air", prob=254, param2=0},
		{name="air", prob=254, param2=0},
		{name="vlf_deepslate:deepslate", prob=254, param2=0},
		{name="vlf_deepslate:deepslate", prob=254, param2=0},
		{name="vlf_deepslate:deepslate", prob=254, param2=0},
		{name="vlf_deepslate:deepslate", prob=254, param2=0},
		{name="vlf_deepslate:deepslate", prob=254, param2=0},
		{name="vlf_deepslate:deepslate_with_coal", prob=254, param2=0},
		{name="vlf_deepslate:deepslate", prob=254, param2=0},
		{name="air", prob=254, param2=0},
		{name="air", prob=254, param2=0},
		{name="vlf_deepslate:deepslate", prob=254, param2=0},
		{name="vlf_deepslate:deepslate", prob=254, param2=0},
		{name="vlf_deepslate:deepslate", prob=254, param2=0},
		{name="air", prob=254, param2=0},
		{name="air", prob=254, param2=0},
		{name="air", prob=254, param2=0},
		{name="air", prob=254, param2=0},
		{name="air", prob=254, param2=0},
		{name="vlf_deepslate:deepslate", prob=254, param2=0},
		{name="vlf_deepslate:deepslate", prob=254, param2=0},
		{name="vlf_deepslate:deepslate", prob=254, param2=0},
		{name="vlf_deepslate:deepslate", prob=254, param2=0},
		{name="vlf_deepslate:deepslate", prob=254, param2=0},
		{name="vlf_deepslate:deepslate", prob=254, param2=0},
		{name="vlf_deepslate:deepslate", prob=254, param2=0},
		{name="vlf_deepslate:deepslate", prob=254, param2=0},
		{name="vlf_deepslate:deepslate", prob=254, param2=0},
		{name="vlf_deepslate:deepslate", prob=254, param2=0},
		{name="air", prob=254, param2=0},
		{name="air", prob=254, param2=0},
		{name="vlf_deepslate:deepslate", prob=254, param2=0},
		{name="vlf_deepslate:deepslate", prob=254, param2=0},
		{name="vlf_deepslate:deepslate", prob=254, param2=0},
		{name="vlf_deepslate:deepslate", prob=254, param2=0},
		{name="vlf_deepslate:deepslate", prob=254, param2=0},
		{name="vlf_deepslate:deepslate", prob=254, param2=0},
		{name="vlf_deepslate:deepslate", prob=254, param2=0},
		{name="vlf_deepslate:deepslate", prob=254, param2=0},
		{name="vlf_deepslate:deepslate", prob=254, param2=0},
		{name="vlf_deepslate:deepslate", prob=254, param2=0},
		{name="vlf_deepslate:deepslate", prob=254, param2=0},
		{name="vlf_deepslate:deepslate", prob=254, param2=0},
		{name="vlf_deepslate:deepslate", prob=254, param2=0},
		{name="vlf_deepslate:deepslate", prob=254, param2=0},
		{name="vlf_deepslate:deepslate", prob=254, param2=0},
		{name="vlf_deepslate:deepslate", prob=254, param2=0},
		{name="vlf_deepslate:deepslate", prob=254, param2=0},
		{name="vlf_deepslate:deepslate", prob=254, param2=0},
		{name="air", prob=254, param2=0},
		{name="air", prob=254, param2=0},
		{name="vlf_deepslate:deepslate", prob=254, param2=0},
		{name="vlf_deepslate:deepslate", prob=254, param2=0},
		{name="vlf_deepslate:deepslate", prob=254, param2=0},
		{name="vlf_deepslate:deepslate", prob=254, param2=0},
		{name="vlf_deepslate:deepslate", prob=254, param2=0},
		{name="vlf_deepslate:deepslate", prob=254, param2=0},
		{name="vlf_deepslate:deepslate", prob=254, param2=0},
		{name="vlf_deepslate:deepslate", prob=254, param2=0},
		{name="vlf_deepslate:deepslate", prob=254, param2=0},
		{name="vlf_deepslate:deepslate", prob=254, param2=0},
		{name="vlf_deepslate:deepslate", prob=254, param2=0},
		{name="vlf_deepslate:deepslate", prob=254, param2=0},
		{name="vlf_deepslate:deepslate", prob=254, param2=0},
		{name="vlf_deepslate:deepslate", prob=254, param2=0},
		{name="vlf_deepslate:deepslate", prob=254, param2=0},
		{name="vlf_deepslate:deepslate", prob=254, param2=0},
		{name="vlf_deepslate:deepslate", prob=254, param2=0},
		{name="vlf_deepslate:deepslate", prob=254, param2=0},
		{name="air", prob=254, param2=0},
		{name="air", prob=254, param2=0},
		{name="vlf_deepslate:deepslate", prob=254, param2=0},
		{name="vlf_deepslate:deepslate", prob=254, param2=0},
		{name="vlf_deepslate:deepslate", prob=254, param2=0},
		{name="vlf_deepslate:deepslate", prob=254, param2=0},
		{name="vlf_deepslate:deepslate", prob=254, param2=0},
		{name="vlf_deepslate:deepslate", prob=254, param2=0},
		{name="vlf_deepslate:deepslate", prob=254, param2=0},
		{name="vlf_deepslate:deepslate", prob=254, param2=0},
		{name="vlf_deepslate:deepslate", prob=254, param2=0},
		{name="vlf_deepslate:deepslate", prob=254, param2=0},
		{name="vlf_deepslate:deepslate", prob=254, param2=0},
		{name="vlf_deepslate:deepslate", prob=254, param2=0},
		{name="vlf_deepslate:deepslate", prob=254, param2=0},
		{name="vlf_deepslate:deepslate", prob=254, param2=0},
		{name="vlf_deepslate:deepslate", prob=254, param2=0},
		{name="vlf_deepslate:deepslate", prob=254, param2=0},
		{name="vlf_deepslate:deepslate", prob=254, param2=0},
		{name="vlf_deepslate:deepslate_with_coal", prob=254, param2=0},
		{name="air", prob=254, param2=0},
		{name="air", prob=254, param2=0},
		{name="vlf_deepslate:deepslate", prob=254, param2=0},
		{name="vlf_deepslate:deepslate", prob=254, param2=0},
		{name="vlf_deepslate:deepslate", prob=254, param2=0},
		{name="vlf_deepslate:deepslate", prob=254, param2=0},
		{name="vlf_deepslate:deepslate", prob=254, param2=0},
		{name="vlf_deepslate:deepslate", prob=254, param2=0},
		{name="vlf_deepslate:deepslate", prob=254, param2=0},
		{name="vlf_deepslate:deepslate", prob=254, param2=0},
		{name="vlf_deepslate:deepslate", prob=254, param2=0},
		{name="vlf_deepslate:deepslate", prob=254, param2=0},
		{name="vlf_deepslate:deepslate", prob=254, param2=0},
		{name="vlf_deepslate:deepslate", prob=254, param2=0},
		{name="vlf_deepslate:deepslate", prob=254, param2=0},
		{name="vlf_deepslate:deepslate", prob=254, param2=0},
		{name="vlf_deepslate:deepslate", prob=254, param2=0},
		{name="vlf_deepslate:deepslate", prob=254, param2=0},
		{name="vlf_deepslate:deepslate", prob=254, param2=0},
		{name="vlf_deepslate:deepslate_with_coal", prob=254, param2=0},
		{name="air", prob=254, param2=0},
		{name="air", prob=254, param2=0},
		{name="vlf_sculk:catalyst", prob=254, param2=0},
		{name="air", prob=254, param2=0},
		{name="air", prob=254, param2=0},
		{name="air", prob=254, param2=0},
		{name="air", prob=254, param2=0},
		{name="air", prob=254, param2=0},
		{name="air", prob=254, param2=0},
		{name="air", prob=254, param2=0},
		{name="vlf_sculk:catalyst", prob=254, param2=0},
		{name="air", prob=254, param2=0},
		{name="air", prob=254, param2=0},
		{name="air", prob=254, param2=0},
		{name="air", prob=254, param2=0},
		{name="air", prob=254, param2=0},
		{name="air", prob=254, param2=0},
		{name="vlf_deepslate:deepslate", prob=254, param2=0},
		{name="vlf_deepslate:deepslate", prob=254, param2=0},
		{name="vlf_deepslate:deepslate", prob=254, param2=0},
		{name="vlf_deepslate:deepslate", prob=254, param2=0},
		{name="vlf_deepslate:deepslate", prob=254, param2=0},
		{name="air", prob=254, param2=0},
		{name="air", prob=254, param2=0},
		{name="air", prob=254, param2=0},
		{name="air", prob=254, param2=0},
		{name="air", prob=254, param2=0},
		{name="air", prob=254, param2=0},
		{name="air", prob=254, param2=0},
		{name="air", prob=254, param2=0},
		{name="air", prob=254, param2=0},
		{name="air", prob=254, param2=0},
		{name="air", prob=254, param2=0},
		{name="air", prob=254, param2=0},
		{name="air", prob=254, param2=0},
		{name="air", prob=254, param2=0},
		{name="air", prob=254, param2=0},
		{name="vlf_deepslate:deepslate_with_copper", prob=254, param2=0},
		{name="vlf_deepslate:deepslate_with_copper", prob=254, param2=0},
		{name="vlf_deepslate:deepslate", prob=254, param2=0},
		{name="vlf_deepslate:deepslate", prob=254, param2=0},
		{name="vlf_deepslate:deepslate", prob=254, param2=0},
		{name="air", prob=254, param2=0},
		{name="air", prob=254, param2=0},
		{name="air", prob=254, param2=0},
		{name="air", prob=254, param2=0},
		{name="air", prob=254, param2=0},
		{name="air", prob=254, param2=0},
		{name="air", prob=254, param2=0},
		{name="air", prob=254, param2=0},
		{name="air", prob=254, param2=0},
		{name="air", prob=254, param2=0},
		{name="air", prob=254, param2=0},
		{name="air", prob=254, param2=0},
		{name="air", prob=254, param2=0},
		{name="air", prob=254, param2=0},
		{name="air", prob=254, param2=0},
		{name="air", prob=254, param2=0},
		{name="vlf_deepslate:deepslate", prob=254, param2=0},
		{name="vlf_deepslate:deepslate", prob=254, param2=0},
		{name="vlf_deepslate:deepslate_with_redstone", prob=254, param2=0},
		{name="vlf_deepslate:deepslate", prob=254, param2=0},
		{name="air", prob=254, param2=0},
		{name="air", prob=254, param2=0},
		{name="air", prob=254, param2=0},
		{name="air", prob=254, param2=0},
		{name="air", prob=254, param2=0},
		{name="air", prob=254, param2=0},
		{name="air", prob=254, param2=0},
		{name="air", prob=254, param2=0},
		{name="air", prob=254, param2=0},
		{name="air", prob=254, param2=0},
		{name="air", prob=254, param2=0},
		{name="air", prob=254, param2=0},
		{name="air", prob=254, param2=0},
		{name="air", prob=254, param2=0},
		{name="vlf_deepslate:deepslate", prob=254, param2=0},
		{name="vlf_deepslate:deepslate_with_copper", prob=254, param2=0},
		{name="vlf_deepslate:deepslate", prob=254, param2=0},
		{name="vlf_deepslate:deepslate", prob=254, param2=0},
		{name="vlf_deepslate:deepslate", prob=254, param2=0},
		{name="vlf_deepslate:deepslate", prob=254, param2=0},
		{name="vlf_deepslate:deepslate", prob=254, param2=0},
		{name="vlf_deepslate:deepslate", prob=254, param2=0},
		{name="air", prob=254, param2=0},
		{name="air", prob=254, param2=0},
		{name="air", prob=254, param2=0},
		{name="air", prob=254, param2=0},
		{name="air", prob=254, param2=0},
		{name="air", prob=254, param2=0},
		{name="air", prob=254, param2=0},
		{name="vlf_deepslate:deepslate", prob=254, param2=0},
		{name="vlf_deepslate:deepslate", prob=254, param2=0},
		{name="vlf_deepslate:deepslate", prob=254, param2=0},
		{name="air", prob=254, param2=0},
		{name="vlf_deepslate:deepslate", prob=254, param2=0},
		{name="vlf_deepslate:deepslate", prob=254, param2=0},
		{name="vlf_deepslate:deepslate", prob=254, param2=0},
		{name="vlf_deepslate:deepslate", prob=254, param2=0},
		{name="vlf_deepslate:deepslate", prob=254, param2=0},
		{name="air", prob=254, param2=0},
		{name="air", prob=254, param2=0},
		{name="vlf_deepslate:deepslate", prob=254, param2=0},
		{name="vlf_deepslate:deepslate", prob=254, param2=0},
		{name="vlf_deepslate:deepslate", prob=254, param2=0},
		{name="air", prob=254, param2=0},
		{name="air", prob=254, param2=0},
		{name="air", prob=254, param2=0},
		{name="air", prob=254, param2=0},
		{name="air", prob=254, param2=0},
		{name="vlf_deepslate:deepslate", prob=254, param2=0},
		{name="vlf_deepslate:deepslate", prob=254, param2=0},
		{name="vlf_deepslate:deepslate", prob=254, param2=0},
		{name="vlf_deepslate:deepslate", prob=254, param2=0},
		{name="vlf_deepslate:deepslate", prob=254, param2=0},
		{name="vlf_deepslate:deepslate", prob=254, param2=0},
		{name="vlf_deepslate:deepslate", prob=254, param2=0},
		{name="vlf_deepslate:deepslate", prob=254, param2=0},
		{name="vlf_deepslate:deepslate", prob=254, param2=0},
		{name="vlf_deepslate:deepslate", prob=254, param2=0},
		{name="air", prob=254, param2=0},
		{name="air", prob=254, param2=0},
		{name="vlf_deepslate:deepslate", prob=254, param2=0},
		{name="vlf_deepslate:deepslate", prob=254, param2=0},
		{name="vlf_deepslate:deepslate", prob=254, param2=0},
		{name="vlf_deepslate:deepslate", prob=254, param2=0},
		{name="vlf_deepslate:deepslate", prob=254, param2=0},
		{name="vlf_deepslate:deepslate", prob=254, param2=0},
		{name="vlf_deepslate:deepslate_with_redstone", prob=254, param2=0},
		{name="vlf_deepslate:deepslate", prob=254, param2=0},
		{name="vlf_deepslate:deepslate", prob=254, param2=0},
		{name="vlf_deepslate:deepslate", prob=254, param2=0},
		{name="vlf_deepslate:deepslate", prob=254, param2=0},
		{name="vlf_deepslate:deepslate", prob=254, param2=0},
		{name="vlf_deepslate:deepslate", prob=254, param2=0},
		{name="vlf_deepslate:deepslate", prob=254, param2=0},
		{name="vlf_deepslate:deepslate", prob=254, param2=0},
		{name="vlf_deepslate:deepslate", prob=254, param2=0},
		{name="vlf_deepslate:deepslate", prob=254, param2=0},
		{name="vlf_deepslate:deepslate", prob=254, param2=0},
		{name="air", prob=254, param2=0},
		{name="air", prob=254, param2=0},
		{name="vlf_deepslate:deepslate", prob=254, param2=0},
		{name="vlf_deepslate:deepslate", prob=254, param2=0},
		{name="vlf_deepslate:deepslate", prob=254, param2=0},
		{name="vlf_deepslate:deepslate", prob=254, param2=0},
		{name="vlf_deepslate:deepslate", prob=254, param2=0},
		{name="vlf_deepslate:deepslate", prob=254, param2=0},
		{name="vlf_deepslate:deepslate", prob=254, param2=0},
		{name="vlf_deepslate:deepslate", prob=254, param2=0},
		{name="vlf_deepslate:deepslate", prob=254, param2=0},
		{name="vlf_deepslate:deepslate", prob=254, param2=0},
		{name="vlf_deepslate:deepslate", prob=254, param2=0},
		{name="vlf_deepslate:deepslate", prob=254, param2=0},
		{name="vlf_deepslate:deepslate", prob=254, param2=0},
		{name="vlf_deepslate:deepslate", prob=254, param2=0},
		{name="vlf_deepslate:deepslate", prob=254, param2=0},
		{name="vlf_deepslate:deepslate", prob=254, param2=0},
		{name="vlf_deepslate:deepslate", prob=254, param2=0},
		{name="vlf_deepslate:deepslate", prob=254, param2=0},
		{name="air", prob=254, param2=0},
		{name="air", prob=254, param2=0},
		{name="vlf_deepslate:deepslate", prob=254, param2=0},
		{name="vlf_deepslate:deepslate", prob=254, param2=0},
		{name="vlf_deepslate:deepslate", prob=254, param2=0},
		{name="vlf_deepslate:deepslate", prob=254, param2=0},
		{name="vlf_deepslate:deepslate", prob=254, param2=0},
		{name="vlf_deepslate:deepslate", prob=254, param2=0},
		{name="vlf_deepslate:deepslate_with_redstone", prob=254, param2=0},
		{name="vlf_deepslate:deepslate", prob=254, param2=0},
		{name="vlf_deepslate:deepslate", prob=254, param2=0},
		{name="vlf_deepslate:deepslate", prob=254, param2=0},
		{name="vlf_deepslate:deepslate", prob=254, param2=0},
		{name="vlf_deepslate:deepslate", prob=254, param2=0},
		{name="vlf_deepslate:deepslate", prob=254, param2=0},
		{name="vlf_deepslate:deepslate", prob=254, param2=0},
		{name="vlf_deepslate:deepslate", prob=254, param2=0},
		{name="vlf_deepslate:deepslate", prob=254, param2=0},
		{name="vlf_deepslate:deepslate", prob=254, param2=0},
		{name="vlf_deepslate:deepslate", prob=254, param2=0},
		{name="air", prob=254, param2=0},
		{name="air", prob=254, param2=0},
		{name="vlf_deepslate:deepslate", prob=254, param2=0},
		{name="vlf_deepslate:deepslate", prob=254, param2=0},
		{name="vlf_deepslate:deepslate", prob=254, param2=0},
		{name="vlf_deepslate:deepslate", prob=254, param2=0},
		{name="vlf_deepslate:deepslate", prob=254, param2=0},
		{name="vlf_deepslate:deepslate", prob=254, param2=0},
		{name="vlf_deepslate:deepslate", prob=254, param2=0},
		{name="vlf_deepslate:deepslate", prob=254, param2=0},
		{name="vlf_deepslate:deepslate", prob=254, param2=0},
		{name="vlf_deepslate:deepslate", prob=254, param2=0},
		{name="vlf_deepslate:deepslate_with_coal", prob=254, param2=0},
		{name="vlf_deepslate:deepslate_with_coal", prob=254, param2=0},
		{name="vlf_deepslate:deepslate_with_coal", prob=254, param2=0},
		{name="vlf_deepslate:deepslate", prob=254, param2=0},
		{name="vlf_deepslate:deepslate", prob=254, param2=0},
		{name="vlf_deepslate:deepslate", prob=254, param2=0},
		{name="vlf_deepslate:deepslate", prob=254, param2=0},
		{name="vlf_deepslate:deepslate", prob=254, param2=0},
		{name="air", prob=254, param2=0},
		{name="air", prob=254, param2=0},
		{name="air", prob=254, param2=0},
		{name="air", prob=254, param2=0},
		{name="air", prob=254, param2=0},
		{name="air", prob=254, param2=0},
		{name="air", prob=254, param2=0},
		{name="air", prob=254, param2=0},
		{name="air", prob=254, param2=0},
		{name="air", prob=254, param2=0},
		{name="air", prob=254, param2=0},
		{name="air", prob=254, param2=0},
		{name="air", prob=254, param2=0},
		{name="air", prob=254, param2=0},
		{name="air", prob=254, param2=0},
		{name="air", prob=254, param2=0},
		{name="air", prob=254, param2=0},
		{name="air", prob=254, param2=0},
		{name="vlf_deepslate:deepslate", prob=254, param2=0},
		{name="vlf_deepslate:deepslate", prob=254, param2=0},
		{name="vlf_deepslate:deepslate", prob=254, param2=0},
		{name="vlf_deepslate:deepslate", prob=254, param2=0},
		{name="air", prob=254, param2=0},
		{name="air", prob=254, param2=0},
		{name="air", prob=254, param2=0},
		{name="air", prob=254, param2=0},
		{name="air", prob=254, param2=0},
		{name="air", prob=254, param2=0},
		{name="air", prob=254, param2=0},
		{name="air", prob=254, param2=0},
		{name="air", prob=254, param2=0},
		{name="air", prob=254, param2=0},
		{name="air", prob=254, param2=0},
		{name="air", prob=254, param2=0},
		{name="air", prob=254, param2=0},
		{name="air", prob=254, param2=0},
		{name="air", prob=254, param2=0},
		{name="air", prob=254, param2=0},
		{name="vlf_deepslate:deepslate_with_copper", prob=254, param2=0},
		{name="vlf_deepslate:deepslate", prob=254, param2=0},
		{name="vlf_deepslate:deepslate", prob=254, param2=0},
		{name="vlf_deepslate:deepslate", prob=254, param2=0},
		{name="air", prob=254, param2=0},
		{name="air", prob=254, param2=0},
		{name="air", prob=254, param2=0},
		{name="air", prob=254, param2=0},
		{name="air", prob=254, param2=0},
		{name="air", prob=254, param2=0},
		{name="air", prob=254, param2=0},
		{name="air", prob=254, param2=0},
		{name="air", prob=254, param2=0},
		{name="air", prob=254, param2=0},
		{name="air", prob=254, param2=0},
		{name="air", prob=254, param2=0},
		{name="air", prob=254, param2=0},
		{name="air", prob=254, param2=0},
		{name="air", prob=254, param2=0},
		{name="air", prob=254, param2=0},
		{name="vlf_deepslate:deepslate_with_copper", prob=254, param2=0},
		{name="vlf_deepslate:deepslate", prob=254, param2=0},
		{name="vlf_deepslate:deepslate", prob=254, param2=0},
		{name="vlf_deepslate:deepslate", prob=254, param2=0},
		{name="air", prob=254, param2=0},
		{name="air", prob=254, param2=0},
		{name="air", prob=254, param2=0},
		{name="air", prob=254, param2=0},
		{name="air", prob=254, param2=0},
		{name="air", prob=254, param2=0},
		{name="air", prob=254, param2=0},
		{name="air", prob=254, param2=0},
		{name="air", prob=254, param2=0},
		{name="air", prob=254, param2=0},
		{name="air", prob=254, param2=0},
		{name="air", prob=254, param2=0},
		{name="air", prob=254, param2=0},
		{name="air", prob=254, param2=0},
		{name="air", prob=254, param2=0},
		{name="vlf_deepslate:deepslate_with_copper", prob=254, param2=0},
		{name="vlf_deepslate:deepslate", prob=254, param2=0},
		{name="vlf_deepslate:deepslate", prob=254, param2=0},
		{name="air", prob=254, param2=0},
		{name="air", prob=254, param2=0},
		{name="air", prob=254, param2=0},
		{name="air", prob=254, param2=0},
		{name="air", prob=254, param2=0},
		{name="air", prob=254, param2=0},
		{name="air", prob=254, param2=0},
		{name="air", prob=254, param2=0},
		{name="air", prob=254, param2=0},
		{name="air", prob=254, param2=0},
		{name="air", prob=254, param2=0},
		{name="vlf_deepslate:deepslate", prob=254, param2=0},
		{name="vlf_deepslate:deepslate", prob=254, param2=0},
		{name="vlf_deepslate:deepslate", prob=254, param2=0},
		{name="air", prob=254, param2=0},
		{name="vlf_deepslate:deepslate", prob=254, param2=0},
		{name="vlf_deepslate:deepslate", prob=254, param2=0},
		{name="vlf_deepslate:deepslate", prob=254, param2=0},
		{name="vlf_deepslate:deepslate", prob=254, param2=0},
		{name="vlf_deepslate:deepslate", prob=254, param2=0},
		{name="air", prob=254, param2=0},
		{name="air", prob=254, param2=0},
		{name="vlf_deepslate:deepslate", prob=254, param2=0},
		{name="vlf_deepslate:deepslate", prob=254, param2=0},
		{name="vlf_deepslate:deepslate", prob=254, param2=0},
		{name="air", prob=254, param2=0},
		{name="air", prob=254, param2=0},
		{name="air", prob=254, param2=0},
		{name="air", prob=254, param2=0},
		{name="vlf_deepslate:deepslate", prob=254, param2=0},
		{name="vlf_deepslate:deepslate", prob=254, param2=0},
		{name="vlf_deepslate:deepslate", prob=254, param2=0},
		{name="vlf_deepslate:deepslate", prob=254, param2=0},
		{name="vlf_deepslate:deepslate", prob=254, param2=0},
		{name="vlf_deepslate:deepslate", prob=254, param2=0},
		{name="vlf_deepslate:deepslate", prob=254, param2=0},
		{name="vlf_deepslate:deepslate", prob=254, param2=0},
		{name="vlf_deepslate:deepslate", prob=254, param2=0},
		{name="vlf_deepslate:deepslate", prob=254, param2=0},
		{name="vlf_deepslate:deepslate", prob=254, param2=0},
		{name="air", prob=254, param2=0},
		{name="air", prob=254, param2=0},
		{name="vlf_deepslate:deepslate", prob=254, param2=0},
		{name="vlf_deepslate:deepslate", prob=254, param2=0},
		{name="vlf_deepslate:deepslate", prob=254, param2=0},
		{name="vlf_deepslate:deepslate", prob=254, param2=0},
		{name="vlf_deepslate:deepslate", prob=254, param2=0},
		{name="vlf_deepslate:deepslate", prob=254, param2=0},
		{name="vlf_deepslate:deepslate", prob=254, param2=0},
		{name="vlf_deepslate:deepslate_with_redstone", prob=254, param2=0},
		{name="vlf_deepslate:deepslate", prob=254, param2=0},
		{name="vlf_deepslate:deepslate", prob=254, param2=0},
		{name="vlf_deepslate:deepslate", prob=254, param2=0},
		{name="vlf_deepslate:deepslate", prob=254, param2=0},
		{name="vlf_deepslate:deepslate", prob=254, param2=0},
		{name="vlf_deepslate:deepslate", prob=254, param2=0},
		{name="vlf_deepslate:deepslate", prob=254, param2=0},
		{name="vlf_deepslate:deepslate", prob=254, param2=0},
		{name="vlf_deepslate:deepslate", prob=254, param2=0},
		{name="vlf_deepslate:deepslate", prob=254, param2=0},
		{name="vlf_deepslate:deepslate", prob=254, param2=0},
		{name="air", prob=254, param2=0},
		{name="vlf_deepslate:deepslate", prob=254, param2=0},
		{name="vlf_deepslate:deepslate", prob=254, param2=0},
		{name="vlf_deepslate:deepslate", prob=254, param2=0},
		{name="vlf_deepslate:deepslate", prob=254, param2=0},
		{name="vlf_deepslate:deepslate", prob=254, param2=0},
		{name="vlf_deepslate:deepslate", prob=254, param2=0},
		{name="vlf_deepslate:deepslate", prob=254, param2=0},
		{name="vlf_deepslate:deepslate_with_redstone", prob=254, param2=0},
		{name="vlf_deepslate:deepslate", prob=254, param2=0},
		{name="vlf_deepslate:deepslate", prob=254, param2=0},
		{name="vlf_deepslate:deepslate", prob=254, param2=0},
		{name="vlf_deepslate:deepslate", prob=254, param2=0},
		{name="vlf_deepslate:deepslate", prob=254, param2=0},
		{name="vlf_deepslate:deepslate", prob=254, param2=0},
		{name="vlf_deepslate:deepslate", prob=254, param2=0},
		{name="vlf_deepslate:deepslate", prob=254, param2=0},
		{name="vlf_deepslate:deepslate", prob=254, param2=0},
		{name="vlf_deepslate:deepslate", prob=254, param2=0},
		{name="vlf_deepslate:deepslate", prob=254, param2=0},
		{name="air", prob=254, param2=0},
		{name="vlf_deepslate:deepslate", prob=254, param2=0},
		{name="vlf_deepslate:deepslate", prob=254, param2=0},
		{name="vlf_deepslate:deepslate", prob=254, param2=0},
		{name="vlf_deepslate:deepslate", prob=254, param2=0},
		{name="vlf_deepslate:deepslate", prob=254, param2=0},
		{name="vlf_deepslate:deepslate", prob=254, param2=0},
		{name="vlf_deepslate:deepslate", prob=254, param2=0},
		{name="vlf_deepslate:deepslate_with_redstone", prob=254, param2=0},
		{name="vlf_deepslate:deepslate", prob=254, param2=0},
		{name="vlf_deepslate:deepslate", prob=254, param2=0},
		{name="vlf_deepslate:deepslate", prob=254, param2=0},
		{name="vlf_deepslate:deepslate", prob=254, param2=0},
		{name="vlf_deepslate:deepslate", prob=254, param2=0},
		{name="vlf_deepslate:deepslate", prob=254, param2=0},
		{name="vlf_deepslate:deepslate", prob=254, param2=0},
		{name="vlf_deepslate:deepslate", prob=254, param2=0},
		{name="vlf_deepslate:deepslate", prob=254, param2=0},
		{name="vlf_deepslate:deepslate", prob=254, param2=0},
		{name="vlf_deepslate:deepslate", prob=254, param2=0},
		{name="air", prob=254, param2=0},
		{name="vlf_deepslate:deepslate", prob=254, param2=0},
		{name="vlf_deepslate:deepslate", prob=254, param2=0},
		{name="vlf_deepslate:deepslate", prob=254, param2=0},
		{name="vlf_deepslate:deepslate", prob=254, param2=0},
		{name="vlf_deepslate:deepslate_with_redstone", prob=254, param2=0},
		{name="vlf_deepslate:deepslate", prob=254, param2=0},
		{name="vlf_deepslate:deepslate", prob=254, param2=0},
		{name="vlf_deepslate:deepslate", prob=254, param2=0},
		{name="vlf_deepslate:deepslate", prob=254, param2=0},
		{name="vlf_deepslate:deepslate", prob=254, param2=0},
		{name="vlf_deepslate:deepslate", prob=254, param2=0},
		{name="vlf_deepslate:deepslate_with_coal", prob=254, param2=0},
		{name="vlf_deepslate:deepslate_with_coal", prob=254, param2=0},
		{name="vlf_deepslate:deepslate", prob=254, param2=0},
		{name="vlf_deepslate:deepslate", prob=254, param2=0},
		{name="vlf_deepslate:deepslate", prob=254, param2=0},
		{name="vlf_deepslate:deepslate", prob=254, param2=0},
		{name="vlf_deepslate:deepslate", prob=254, param2=0},
		{name="vlf_deepslate:deepslate_with_coal", prob=254, param2=0},
		{name="air", prob=254, param2=0},
		{name="air", prob=254, param2=0},
		{name="air", prob=254, param2=0},
		{name="vlf_deepslate:deepslate_bricks", prob=254, param2=0},
		{name="air", prob=254, param2=0},
		{name="air", prob=254, param2=0},
		{name="air", prob=254, param2=0},
		{name="vlf_wool:grey_carpet", prob=254, param2=0},
		{name="air", prob=254, param2=0},
		{name="air", prob=254, param2=0},
		{name="air", prob=254, param2=0},
		{name="air", prob=254, param2=0},
		{name="air", prob=254, param2=0},
		{name="air", prob=254, param2=0},
		{name="air", prob=254, param2=0},
		{name="air", prob=254, param2=0},
		{name="air", prob=254, param2=0},
		{name="vlf_deepslate:deepslate", prob=254, param2=0},
		{name="vlf_deepslate:deepslate", prob=254, param2=0},
		{name="vlf_deepslate:deepslate", prob=254, param2=0},
		{name="vlf_deepslate:deepslate", prob=254, param2=0},
		{name="air", prob=254, param2=0},
		{name="air", prob=254, param2=0},
		{name="vlf_deepslate:deepslate_bricks", prob=254, param2=0},
		{name="air", prob=254, param2=0},
		{name="air", prob=254, param2=0},
		{name="air", prob=254, param2=0},
		{name="air", prob=254, param2=0},
		{name="air", prob=254, param2=0},
		{name="air", prob=254, param2=0},
		{name="air", prob=254, param2=0},
		{name="air", prob=254, param2=0},
		{name="air", prob=254, param2=0},
		{name="air", prob=254, param2=0},
		{name="air", prob=254, param2=0},
		{name="air", prob=254, param2=0},
		{name="air", prob=254, param2=0},
		{name="vlf_deepslate:deepslate", prob=254, param2=0},
		{name="vlf_deepslate:deepslate", prob=254, param2=0},
		{name="vlf_deepslate:deepslate", prob=254, param2=0},
		{name="vlf_deepslate:deepslate", prob=254, param2=0},
		{name="air", prob=254, param2=0},
		{name="air", prob=254, param2=0},
		{name="vlf_deepslate:deepslate_bricks", prob=254, param2=0},
		{name="air", prob=254, param2=0},
		{name="air", prob=254, param2=0},
		{name="air", prob=254, param2=0},
		{name="air", prob=254, param2=0},
		{name="air", prob=254, param2=0},
		{name="air", prob=254, param2=0},
		{name="air", prob=254, param2=0},
		{name="air", prob=254, param2=0},
		{name="air", prob=254, param2=0},
		{name="air", prob=254, param2=0},
		{name="air", prob=254, param2=0},
		{name="air", prob=254, param2=0},
		{name="air", prob=254, param2=0},
		{name="vlf_deepslate:deepslate", prob=254, param2=0},
		{name="vlf_deepslate:deepslate", prob=254, param2=0},
		{name="vlf_deepslate:deepslate", prob=254, param2=0},
		{name="vlf_deepslate:deepslate", prob=254, param2=0},
		{name="air", prob=254, param2=0},
		{name="air", prob=254, param2=0},
		{name="vlf_deepslate:deepslate_bricks", prob=254, param2=0},
		{name="air", prob=254, param2=0},
		{name="air", prob=254, param2=0},
		{name="air", prob=254, param2=0},
		{name="air", prob=254, param2=0},
		{name="air", prob=254, param2=0},
		{name="air", prob=254, param2=0},
		{name="air", prob=254, param2=0},
		{name="air", prob=254, param2=0},
		{name="air", prob=254, param2=0},
		{name="air", prob=254, param2=0},
		{name="air", prob=254, param2=0},
		{name="air", prob=254, param2=0},
		{name="vlf_deepslate:deepslate", prob=254, param2=0},
		{name="vlf_deepslate:deepslate", prob=254, param2=0},
		{name="vlf_deepslate:deepslate", prob=254, param2=0},
		{name="air", prob=254, param2=0},
		{name="air", prob=254, param2=0},
		{name="air", prob=254, param2=0},
		{name="air", prob=254, param2=0},
		{name="vlf_deepslate:deepslate_bricks", prob=254, param2=0},
		{name="air", prob=254, param2=0},
		{name="air", prob=254, param2=0},
		{name="air", prob=254, param2=0},
		{name="air", prob=254, param2=0},
		{name="air", prob=254, param2=0},
		{name="air", prob=254, param2=0},
		{name="air", prob=254, param2=0},
		{name="air", prob=254, param2=0},
		{name="vlf_deepslate:deepslate", prob=254, param2=0},
		{name="vlf_deepslate:deepslate", prob=254, param2=0},
		{name="vlf_deepslate:deepslate", prob=254, param2=0},
		{name="vlf_deepslate:deepslate", prob=254, param2=0},
		{name="vlf_deepslate:deepslate", prob=254, param2=0},
		{name="vlf_deepslate:deepslate", prob=254, param2=0},
		{name="air", prob=254, param2=0},
		{name="air", prob=254, param2=0},
		{name="air", prob=254, param2=0},
		{name="vlf_deepslate:deepslate", prob=254, param2=0},
		{name="air", prob=254, param2=0},
		{name="vlf_deepslate:deepslate_bricks", prob=254, param2=0},
		{name="air", prob=254, param2=0},
		{name="air", prob=254, param2=0},
		{name="air", prob=254, param2=0},
		{name="air", prob=254, param2=0},
		{name="vlf_deepslate:deepslate", prob=254, param2=0},
		{name="vlf_deepslate:deepslate", prob=254, param2=0},
		{name="vlf_deepslate:deepslate", prob=254, param2=0},
		{name="vlf_deepslate:deepslate", prob=254, param2=0},
		{name="vlf_deepslate:deepslate", prob=254, param2=0},
		{name="vlf_deepslate:deepslate", prob=254, param2=0},
		{name="vlf_deepslate:deepslate", prob=254, param2=0},
		{name="vlf_deepslate:deepslate", prob=254, param2=0},
		{name="vlf_deepslate:deepslate", prob=254, param2=0},
		{name="vlf_deepslate:deepslate", prob=254, param2=0},
		{name="air", prob=254, param2=0},
		{name="air", prob=254, param2=0},
		{name="air", prob=254, param2=0},
		{name="vlf_deepslate:deepslate", prob=254, param2=0},
		{name="vlf_deepslate:deepslate", prob=254, param2=0},
		{name="vlf_deepslate:deepslate_bricks", prob=254, param2=0},
		{name="air", prob=254, param2=0},
		{name="air", prob=254, param2=0},
		{name="vlf_deepslate:deepslate_with_redstone", prob=254, param2=0},
		{name="vlf_deepslate:deepslate", prob=254, param2=0},
		{name="vlf_deepslate:deepslate", prob=254, param2=0},
		{name="vlf_deepslate:deepslate", prob=254, param2=0},
		{name="vlf_deepslate:deepslate", prob=254, param2=0},
		{name="vlf_deepslate:deepslate", prob=254, param2=0},
		{name="vlf_deepslate:deepslate", prob=254, param2=0},
		{name="vlf_deepslate:deepslate", prob=254, param2=0},
		{name="vlf_deepslate:deepslate", prob=254, param2=0},
		{name="vlf_deepslate:deepslate", prob=254, param2=0},
		{name="vlf_deepslate:deepslate", prob=254, param2=0},
		{name="vlf_deepslate:deepslate", prob=254, param2=0},
		{name="vlf_deepslate:deepslate", prob=254, param2=0},
		{name="air", prob=254, param2=0},
		{name="air", prob=254, param2=0},
		{name="vlf_deepslate:tuff", prob=254, param2=0},
		{name="vlf_deepslate:deepslate_with_redstone", prob=254, param2=0},
		{name="vlf_deepslate:deepslate", prob=254, param2=0},
		{name="vlf_deepslate:deepslate_with_redstone", prob=254, param2=0},
		{name="vlf_deepslate:deepslate", prob=254, param2=0},
		{name="vlf_deepslate:deepslate", prob=254, param2=0},
		{name="vlf_deepslate:deepslate", prob=254, param2=0},
		{name="vlf_deepslate:deepslate", prob=254, param2=0},
		{name="vlf_deepslate:deepslate", prob=254, param2=0},
		{name="vlf_deepslate:deepslate", prob=254, param2=0},
		{name="vlf_deepslate:deepslate", prob=254, param2=0},
		{name="vlf_deepslate:deepslate", prob=254, param2=0},
		{name="vlf_deepslate:deepslate", prob=254, param2=0},
		{name="vlf_deepslate:deepslate", prob=254, param2=0},
		{name="vlf_deepslate:deepslate", prob=254, param2=0},
		{name="vlf_deepslate:deepslate", prob=254, param2=0},
		{name="vlf_deepslate:deepslate", prob=254, param2=0},
		{name="vlf_deepslate:deepslate", prob=254, param2=0},
		{name="vlf_deepslate:deepslate", prob=254, param2=0},
		{name="vlf_deepslate:deepslate", prob=254, param2=0},
		{name="vlf_deepslate:deepslate", prob=254, param2=0},
		{name="vlf_deepslate:deepslate", prob=254, param2=0},
		{name="vlf_deepslate:deepslate", prob=254, param2=0},
		{name="vlf_deepslate:deepslate", prob=254, param2=0},
		{name="vlf_deepslate:deepslate", prob=254, param2=0},
		{name="vlf_deepslate:deepslate", prob=254, param2=0},
		{name="vlf_deepslate:deepslate", prob=254, param2=0},
		{name="vlf_deepslate:deepslate", prob=254, param2=0},
		{name="vlf_deepslate:deepslate", prob=254, param2=0},
		{name="vlf_deepslate:deepslate", prob=254, param2=0},
		{name="vlf_deepslate:deepslate", prob=254, param2=0},
		{name="vlf_deepslate:deepslate", prob=254, param2=0},
		{name="vlf_deepslate:deepslate", prob=254, param2=0},
		{name="vlf_deepslate:deepslate", prob=254, param2=0},
		{name="vlf_deepslate:deepslate", prob=254, param2=0},
		{name="vlf_deepslate:deepslate", prob=254, param2=0},
		{name="vlf_deepslate:deepslate", prob=254, param2=0},
		{name="vlf_deepslate:deepslate", prob=254, param2=0},
		{name="vlf_deepslate:deepslate", prob=254, param2=0},
		{name="vlf_deepslate:deepslate", prob=254, param2=0},
		{name="vlf_deepslate:deepslate", prob=254, param2=0},
		{name="vlf_deepslate:deepslate", prob=254, param2=0},
		{name="vlf_deepslate:deepslate", prob=254, param2=0},
		{name="vlf_deepslate:deepslate", prob=254, param2=0},
		{name="vlf_deepslate:deepslate", prob=254, param2=0},
		{name="vlf_deepslate:deepslate", prob=254, param2=0},
		{name="vlf_deepslate:deepslate", prob=254, param2=0},
		{name="vlf_deepslate:deepslate", prob=254, param2=0},
		{name="vlf_deepslate:deepslate", prob=254, param2=0},
		{name="vlf_deepslate:deepslate", prob=254, param2=0},
		{name="vlf_deepslate:deepslate_with_coal", prob=254, param2=0},
		{name="vlf_deepslate:deepslate", prob=254, param2=0},
		{name="vlf_deepslate:deepslate", prob=254, param2=0},
		{name="vlf_deepslate:deepslate", prob=254, param2=0},
		{name="vlf_deepslate:deepslate", prob=254, param2=0},
		{name="vlf_deepslate:deepslate", prob=254, param2=0},
		{name="vlf_deepslate:deepslate", prob=254, param2=0},
		{name="vlf_deepslate:deepslate", prob=254, param2=0},
		{name="vlf_deepslate:deepslate", prob=254, param2=0},
		{name="vlf_deepslate:deepslate", prob=254, param2=0},
		{name="air", prob=254, param2=0},
		{name="air", prob=254, param2=0},
		{name="vlf_deepslate:deepslate_tiles", prob=254, param2=0},
		{name="air", prob=254, param2=0},
		{name="air", prob=254, param2=0},
		{name="air", prob=254, param2=0},
		{name="vlf_wool:grey_carpet", prob=254, param2=0},
		{name="vlf_wool:grey_carpet", prob=254, param2=0},
		{name="air", prob=254, param2=0},
		{name="air", prob=254, param2=0},
		{name="vlf_wool:grey_carpet", prob=254, param2=0},
		{name="air", prob=254, param2=0},
		{name="air", prob=254, param2=0},
		{name="air", prob=254, param2=0},
		{name="air", prob=254, param2=0},
		{name="air", prob=254, param2=0},
		{name="vlf_deepslate:deepslate", prob=254, param2=0},
		{name="vlf_deepslate:deepslate", prob=254, param2=0},
		{name="vlf_deepslate:deepslate", prob=254, param2=0},
		{name="vlf_deepslate:deepslate", prob=254, param2=0},
		{name="air", prob=254, param2=0},
		{name="air", prob=254, param2=0},
		{name="vlf_deepslate:deepslate_tiles", prob=254, param2=0},
		{name="air", prob=254, param2=0},
		{name="air", prob=254, param2=0},
		{name="air", prob=254, param2=0},
		{name="air", prob=254, param2=0},
		{name="air", prob=254, param2=0},
		{name="air", prob=254, param2=0},
		{name="air", prob=254, param2=0},
		{name="air", prob=254, param2=0},
		{name="air", prob=254, param2=0},
		{name="air", prob=254, param2=0},
		{name="air", prob=254, param2=0},
		{name="air", prob=254, param2=0},
		{name="air", prob=254, param2=0},
		{name="air", prob=254, param2=0},
		{name="air", prob=254, param2=0},
		{name="air", prob=254, param2=0},
		{name="vlf_deepslate:deepslate", prob=254, param2=0},
		{name="air", prob=254, param2=0},
		{name="air", prob=254, param2=0},
		{name="vlf_deepslate:deepslate_chiseled", prob=254, param2=0},
		{name="air", prob=254, param2=0},
		{name="air", prob=254, param2=0},
		{name="air", prob=254, param2=0},
		{name="air", prob=254, param2=0},
		{name="air", prob=254, param2=0},
		{name="air", prob=254, param2=0},
		{name="air", prob=254, param2=0},
		{name="air", prob=254, param2=0},
		{name="air", prob=254, param2=0},
		{name="air", prob=254, param2=0},
		{name="air", prob=254, param2=0},
		{name="air", prob=254, param2=0},
		{name="air", prob=254, param2=0},
		{name="vlf_deepslate:deepslate", prob=254, param2=0},
		{name="vlf_deepslate:deepslate", prob=254, param2=0},
		{name="vlf_deepslate:deepslate_with_redstone", prob=254, param2=0},
		{name="vlf_deepslate:deepslate", prob=254, param2=0},
		{name="air", prob=254, param2=0},
		{name="air", prob=254, param2=0},
		{name="vlf_deepslate:deepslate_reinforced", prob=254, param2=0},
		{name="air", prob=254, param2=0},
		{name="air", prob=254, param2=0},
		{name="air", prob=254, param2=0},
		{name="air", prob=254, param2=0},
		{name="air", prob=254, param2=0},
		{name="air", prob=254, param2=0},
		{name="air", prob=254, param2=0},
		{name="air", prob=254, param2=0},
		{name="air", prob=254, param2=0},
		{name="air", prob=254, param2=0},
		{name="air", prob=254, param2=0},
		{name="air", prob=254, param2=0},
		{name="vlf_deepslate:deepslate", prob=254, param2=0},
		{name="vlf_deepslate:deepslate", prob=254, param2=0},
		{name="vlf_deepslate:deepslate", prob=254, param2=0},
		{name="air", prob=254, param2=0},
		{name="air", prob=254, param2=0},
		{name="air", prob=254, param2=0},
		{name="air", prob=254, param2=0},
		{name="vlf_deepslate:deepslate_reinforced", prob=254, param2=0},
		{name="air", prob=254, param2=0},
		{name="air", prob=254, param2=0},
		{name="air", prob=254, param2=0},
		{name="air", prob=254, param2=0},
		{name="air", prob=254, param2=0},
		{name="air", prob=254, param2=0},
		{name="air", prob=254, param2=0},
		{name="vlf_deepslate:deepslate", prob=254, param2=0},
		{name="vlf_deepslate:deepslate", prob=254, param2=0},
		{name="air", prob=254, param2=0},
		{name="air", prob=254, param2=0},
		{name="air", prob=254, param2=0},
		{name="vlf_deepslate:deepslate_with_coal", prob=254, param2=0},
		{name="vlf_deepslate:deepslate", prob=254, param2=0},
		{name="air", prob=254, param2=0},
		{name="air", prob=254, param2=0},
		{name="air", prob=254, param2=0},
		{name="vlf_deepslate:deepslate", prob=254, param2=0},
		{name="air", prob=254, param2=0},
		{name="vlf_deepslate:deepslate_reinforced", prob=254, param2=0},
		{name="air", prob=254, param2=0},
		{name="air", prob=254, param2=0},
		{name="air", prob=254, param2=0},
		{name="air", prob=254, param2=0},
		{name="vlf_deepslate:deepslate", prob=254, param2=0},
		{name="vlf_deepslate:deepslate", prob=254, param2=0},
		{name="vlf_deepslate:deepslate", prob=254, param2=0},
		{name="vlf_deepslate:deepslate", prob=254, param2=0},
		{name="vlf_deepslate:deepslate", prob=254, param2=0},
		{name="vlf_deepslate:deepslate", prob=254, param2=0},
		{name="vlf_deepslate:deepslate", prob=254, param2=0},
		{name="vlf_deepslate:deepslate", prob=254, param2=0},
		{name="vlf_deepslate:deepslate_with_coal", prob=254, param2=0},
		{name="vlf_deepslate:deepslate", prob=254, param2=0},
		{name="air", prob=254, param2=0},
		{name="air", prob=254, param2=0},
		{name="air", prob=254, param2=0},
		{name="vlf_deepslate:deepslate", prob=254, param2=0},
		{name="vlf_deepslate:deepslate", prob=254, param2=0},
		{name="vlf_deepslate:deepslate_chiseled", prob=254, param2=0},
		{name="air", prob=254, param2=0},
		{name="air", prob=254, param2=0},
		{name="vlf_deepslate:deepslate", prob=254, param2=0},
		{name="vlf_deepslate:deepslate", prob=254, param2=0},
		{name="vlf_deepslate:deepslate", prob=254, param2=0},
		{name="vlf_deepslate:deepslate", prob=254, param2=0},
		{name="vlf_deepslate:deepslate", prob=254, param2=0},
		{name="vlf_deepslate:deepslate", prob=254, param2=0},
		{name="vlf_deepslate:deepslate", prob=254, param2=0},
		{name="vlf_deepslate:deepslate", prob=254, param2=0},
		{name="vlf_deepslate:deepslate_with_coal", prob=254, param2=0},
		{name="air", prob=254, param2=0},
		{name="vlf_deepslate:deepslate_with_coal", prob=254, param2=0},
		{name="vlf_deepslate:deepslate", prob=254, param2=0},
		{name="air", prob=254, param2=0},
		{name="air", prob=254, param2=0},
		{name="air", prob=254, param2=0},
		{name="vlf_deepslate:deepslate", prob=254, param2=0},
		{name="vlf_deepslate:deepslate", prob=254, param2=0},
		{name="vlf_deepslate:deepslate_bricks", prob=254, param2=0},
		{name="air", prob=254, param2=0},
		{name="vlf_deepslate:deepslate", prob=254, param2=0},
		{name="vlf_deepslate:deepslate", prob=254, param2=0},
		{name="vlf_deepslate:deepslate", prob=254, param2=0},
		{name="vlf_deepslate:deepslate", prob=254, param2=0},
		{name="vlf_deepslate:deepslate", prob=254, param2=0},
		{name="vlf_deepslate:deepslate", prob=254, param2=0},
		{name="vlf_deepslate:deepslate", prob=254, param2=0},
		{name="vlf_deepslate:deepslate", prob=254, param2=0},
		{name="vlf_deepslate:deepslate", prob=254, param2=0},
		{name="vlf_deepslate:deepslate", prob=254, param2=0},
		{name="vlf_deepslate:deepslate", prob=254, param2=0},
		{name="vlf_deepslate:deepslate", prob=254, param2=0},
		{name="vlf_deepslate:deepslate", prob=254, param2=0},
		{name="vlf_deepslate:deepslate", prob=254, param2=0},
		{name="vlf_deepslate:deepslate", prob=254, param2=0},
		{name="vlf_deepslate:deepslate", prob=254, param2=0},
		{name="vlf_deepslate:deepslate", prob=254, param2=0},
		{name="vlf_deepslate:deepslate", prob=254, param2=0},
		{name="vlf_deepslate:deepslate", prob=254, param2=0},
		{name="vlf_deepslate:deepslate", prob=254, param2=0},
		{name="vlf_deepslate:deepslate", prob=254, param2=0},
		{name="vlf_deepslate:deepslate", prob=254, param2=0},
		{name="vlf_deepslate:deepslate", prob=254, param2=0},
		{name="vlf_deepslate:deepslate", prob=254, param2=0},
		{name="vlf_deepslate:deepslate", prob=254, param2=0},
		{name="vlf_deepslate:deepslate", prob=254, param2=0},
		{name="vlf_deepslate:deepslate", prob=254, param2=0},
		{name="vlf_deepslate:deepslate", prob=254, param2=0},
		{name="vlf_deepslate:deepslate", prob=254, param2=0},
		{name="vlf_deepslate:deepslate", prob=254, param2=0},
		{name="vlf_deepslate:deepslate", prob=254, param2=0},
		{name="vlf_deepslate:deepslate", prob=254, param2=0},
		{name="vlf_deepslate:deepslate", prob=254, param2=0},
		{name="vlf_deepslate:deepslate", prob=254, param2=0},
		{name="vlf_deepslate:deepslate", prob=254, param2=0},
		{name="vlf_deepslate:deepslate", prob=254, param2=0},
		{name="vlf_deepslate:deepslate", prob=254, param2=0},
		{name="vlf_deepslate:deepslate", prob=254, param2=0},
		{name="vlf_deepslate:deepslate", prob=254, param2=0},
		{name="vlf_deepslate:deepslate", prob=254, param2=0},
		{name="vlf_deepslate:deepslate", prob=254, param2=0},
		{name="vlf_deepslate:deepslate", prob=254, param2=0},
		{name="vlf_deepslate:deepslate", prob=254, param2=0},
		{name="vlf_deepslate:deepslate", prob=254, param2=0},
		{name="vlf_deepslate:deepslate", prob=254, param2=0},
		{name="vlf_deepslate:deepslate", prob=254, param2=0},
		{name="vlf_deepslate:deepslate", prob=254, param2=0},
		{name="vlf_deepslate:deepslate", prob=254, param2=0},
		{name="vlf_deepslate:deepslate", prob=254, param2=0},
		{name="vlf_deepslate:deepslate", prob=254, param2=0},
		{name="vlf_deepslate:deepslate", prob=254, param2=0},
		{name="vlf_deepslate:deepslate", prob=254, param2=0},
		{name="vlf_deepslate:deepslate", prob=254, param2=0},
		{name="vlf_deepslate:deepslate", prob=254, param2=0},
		{name="vlf_deepslate:deepslate", prob=254, param2=0},
		{name="vlf_deepslate:deepslate", prob=254, param2=0},
		{name="vlf_deepslate:deepslate_bricks", prob=254, param2=0},
		{name="vlf_deepslate:deepslate_tiles", prob=254, param2=0},
		{name="vlf_deepslate:deepslate_tiles", prob=254, param2=0},
		{name="vlf_deepslate:deepslate_tiles", prob=254, param2=0},
		{name="vlf_deepslate:deepslate_chiseled", prob=254, param2=0},
		{name="vlf_sculk:sculk", prob=254, param2=0},
		{name="vlf_sculk:sculk", prob=254, param2=0},
		{name="air", prob=254, param2=0},
		{name="air", prob=254, param2=0},
		{name="air", prob=254, param2=0},
		{name="vlf_wool:grey_carpet", prob=254, param2=0},
		{name="vlf_wool:grey_carpet", prob=254, param2=0},
		{name="air", prob=254, param2=0},
		{name="air", prob=254, param2=0},
		{name="air", prob=254, param2=0},
		{name="air", prob=254, param2=0},
		{name="air", prob=254, param2=0},
		{name="air", prob=254, param2=0},
		{name="vlf_deepslate:deepslate", prob=254, param2=0},
		{name="vlf_deepslate:deepslate", prob=254, param2=0},
		{name="air", prob=254, param2=0},
		{name="vlf_deepslate:deepslate_tiles", prob=254, param2=0},
		{name="vlf_deepslate:deepslate_tiles", prob=254, param2=0},
		{name="vlf_deepslate:deepslate_tiles", prob=254, param2=0},
		{name="air", prob=254, param2=0},
		{name="air", prob=254, param2=0},
		{name="air", prob=254, param2=0},
		{name="air", prob=254, param2=0},
		{name="air", prob=254, param2=0},
		{name="air", prob=254, param2=0},
		{name="air", prob=254, param2=0},
		{name="air", prob=254, param2=0},
		{name="air", prob=254, param2=0},
		{name="air", prob=254, param2=0},
		{name="air", prob=254, param2=0},
		{name="air", prob=254, param2=0},
		{name="air", prob=254, param2=0},
		{name="air", prob=254, param2=0},
		{name="vlf_deepslate:deepslate", prob=254, param2=0},
		{name="vlf_deepslate:deepslate", prob=254, param2=0},
		{name="air", prob=254, param2=0},
		{name="air", prob=254, param2=0},
		{name="vlf_deepslate:deepslate_reinforced", prob=254, param2=6},
		{name="air", prob=254, param2=0},
		{name="air", prob=254, param2=0},
		{name="air", prob=254, param2=0},
		{name="air", prob=254, param2=0},
		{name="air", prob=254, param2=0},
		{name="air", prob=254, param2=0},
		{name="air", prob=254, param2=0},
		{name="air", prob=254, param2=0},
		{name="air", prob=254, param2=0},
		{name="air", prob=254, param2=0},
		{name="air", prob=254, param2=0},
		{name="air", prob=254, param2=0},
		{name="air", prob=254, param2=0},
		{name="air", prob=254, param2=0},
		{name="air", prob=254, param2=0},
		{name="vlf_deepslate:deepslate", prob=254, param2=0},
		{name="vlf_deepslate:deepslate", prob=254, param2=0},
		{name="air", prob=254, param2=0},
		{name="air", prob=254, param2=0},
		{name="air", prob=254, param2=0},
		{name="air", prob=254, param2=0},
		{name="air", prob=254, param2=0},
		{name="air", prob=254, param2=0},
		{name="air", prob=254, param2=0},
		{name="air", prob=254, param2=0},
		{name="air", prob=254, param2=0},
		{name="air", prob=254, param2=0},
		{name="air", prob=254, param2=0},
		{name="air", prob=254, param2=0},
		{name="air", prob=254, param2=0},
		{name="air", prob=254, param2=0},
		{name="air", prob=254, param2=0},
		{name="air", prob=254, param2=0},
		{name="air", prob=254, param2=0},
		{name="air", prob=254, param2=0},
		{name="air", prob=254, param2=0},
		{name="air", prob=254, param2=0},
		{name="air", prob=254, param2=0},
		{name="air", prob=254, param2=0},
		{name="air", prob=254, param2=0},
		{name="air", prob=254, param2=0},
		{name="air", prob=254, param2=0},
		{name="air", prob=254, param2=0},
		{name="air", prob=254, param2=0},
		{name="air", prob=254, param2=0},
		{name="air", prob=254, param2=0},
		{name="air", prob=254, param2=0},
		{name="air", prob=254, param2=0},
		{name="air", prob=254, param2=0},
		{name="air", prob=254, param2=0},
		{name="air", prob=254, param2=0},
		{name="air", prob=254, param2=0},
		{name="vlf_deepslate:deepslate", prob=254, param2=0},
		{name="vlf_deepslate:deepslate", prob=254, param2=0},
		{name="air", prob=254, param2=0},
		{name="air", prob=254, param2=0},
		{name="air", prob=254, param2=0},
		{name="vlf_deepslate:deepslate", prob=254, param2=0},
		{name="air", prob=254, param2=0},
		{name="air", prob=254, param2=0},
		{name="air", prob=254, param2=0},
		{name="air", prob=254, param2=0},
		{name="air", prob=254, param2=0},
		{name="air", prob=254, param2=0},
		{name="vlf_deepslate:deepslate", prob=254, param2=0},
		{name="vlf_deepslate:deepslate", prob=254, param2=0},
		{name="vlf_deepslate:deepslate", prob=254, param2=0},
		{name="vlf_deepslate:deepslate", prob=254, param2=0},
		{name="vlf_deepslate:deepslate", prob=254, param2=0},
		{name="vlf_deepslate:deepslate", prob=254, param2=0},
		{name="air", prob=254, param2=0},
		{name="air", prob=254, param2=0},
		{name="air", prob=254, param2=0},
		{name="air", prob=254, param2=0},
		{name="air", prob=254, param2=0},
		{name="air", prob=254, param2=0},
		{name="air", prob=254, param2=0},
		{name="vlf_deepslate:deepslate", prob=254, param2=0},
		{name="vlf_deepslate:deepslate", prob=254, param2=0},
		{name="vlf_deepslate:deepslate_reinforced", prob=254, param2=6},
		{name="air", prob=254, param2=0},
		{name="air", prob=254, param2=0},
		{name="air", prob=254, param2=0},
		{name="vlf_deepslate:deepslate", prob=254, param2=0},
		{name="vlf_deepslate:deepslate", prob=254, param2=0},
		{name="vlf_deepslate:deepslate", prob=254, param2=0},
		{name="vlf_deepslate:deepslate", prob=254, param2=0},
		{name="vlf_deepslate:deepslate", prob=254, param2=0},
		{name="vlf_deepslate:deepslate", prob=254, param2=0},
		{name="air", prob=254, param2=0},
		{name="air", prob=254, param2=0},
		{name="air", prob=254, param2=0},
		{name="air", prob=254, param2=0},
		{name="air", prob=254, param2=0},
		{name="air", prob=254, param2=0},
		{name="air", prob=254, param2=0},
		{name="air", prob=254, param2=0},
		{name="vlf_deepslate:deepslate", prob=254, param2=0},
		{name="vlf_deepslate:deepslate_with_redstone", prob=254, param2=0},
		{name="vlf_deepslate:deepslate", prob=254, param2=0},
		{name="air", prob=254, param2=0},
		{name="vlf_deepslate:deepslate", prob=254, param2=0},
		{name="vlf_deepslate:deepslate", prob=254, param2=0},
		{name="vlf_deepslate:deepslate", prob=254, param2=0},
		{name="vlf_deepslate:deepslate", prob=254, param2=0},
		{name="vlf_deepslate:deepslate", prob=254, param2=0},
		{name="vlf_deepslate:deepslate", prob=254, param2=0},
		{name="vlf_deepslate:deepslate", prob=254, param2=0},
		{name="air", prob=254, param2=0},
		{name="air", prob=254, param2=0},
		{name="air", prob=254, param2=0},
		{name="air", prob=254, param2=0},
		{name="air", prob=254, param2=0},
		{name="air", prob=254, param2=0},
		{name="air", prob=254, param2=0},
		{name="vlf_deepslate:deepslate", prob=254, param2=0},
		{name="vlf_deepslate:deepslate", prob=254, param2=0},
		{name="vlf_deepslate:deepslate", prob=254, param2=0},
		{name="vlf_deepslate:deepslate", prob=254, param2=0},
		{name="vlf_deepslate:deepslate", prob=254, param2=0},
		{name="vlf_deepslate:deepslate", prob=254, param2=0},
		{name="vlf_deepslate:deepslate", prob=254, param2=0},
		{name="vlf_deepslate:deepslate", prob=254, param2=0},
		{name="vlf_deepslate:deepslate", prob=254, param2=0},
		{name="vlf_deepslate:deepslate", prob=254, param2=0},
		{name="vlf_deepslate:deepslate", prob=254, param2=0},
		{name="vlf_deepslate:deepslate", prob=254, param2=0},
		{name="vlf_deepslate:deepslate", prob=254, param2=0},
		{name="vlf_deepslate:deepslate", prob=254, param2=0},
		{name="air", prob=254, param2=0},
		{name="air", prob=254, param2=0},
		{name="vlf_deepslate:deepslate", prob=254, param2=0},
		{name="vlf_deepslate:deepslate", prob=254, param2=0},
		{name="vlf_deepslate:deepslate", prob=254, param2=0},
		{name="vlf_deepslate:deepslate", prob=254, param2=0},
		{name="vlf_deepslate:deepslate", prob=254, param2=0},
		{name="vlf_deepslate:deepslate", prob=254, param2=0},
		{name="vlf_deepslate:deepslate", prob=254, param2=0},
		{name="vlf_deepslate:deepslate", prob=254, param2=0},
		{name="vlf_deepslate:deepslate", prob=254, param2=0},
		{name="vlf_deepslate:deepslate", prob=254, param2=0},
		{name="vlf_deepslate:deepslate", prob=254, param2=0},
		{name="vlf_deepslate:deepslate", prob=254, param2=0},
		{name="vlf_deepslate:deepslate", prob=254, param2=0},
		{name="vlf_deepslate:deepslate", prob=254, param2=0},
		{name="vlf_deepslate:deepslate", prob=254, param2=0},
		{name="vlf_deepslate:deepslate", prob=254, param2=0},
		{name="vlf_deepslate:deepslate", prob=254, param2=0},
		{name="vlf_deepslate:deepslate", prob=254, param2=0},
		{name="vlf_deepslate:deepslate", prob=254, param2=0},
		{name="vlf_deepslate:deepslate", prob=254, param2=0},
		{name="vlf_deepslate:deepslate", prob=254, param2=0},
		{name="vlf_deepslate:deepslate", prob=254, param2=0},
		{name="vlf_deepslate:deepslate", prob=254, param2=0},
		{name="vlf_deepslate:deepslate", prob=254, param2=0},
		{name="vlf_deepslate:deepslate", prob=254, param2=0},
		{name="vlf_deepslate:deepslate", prob=254, param2=0},
		{name="vlf_deepslate:deepslate_bricks", prob=254, param2=0},
		{name="vlf_deepslate:deepslate_bricks", prob=254, param2=0},
		{name="vlf_chests:chest_small", prob=254, param2=3},
		{name="vlf_deepslate:deepslate_bricks", prob=254, param2=0},
		{name="vlf_deepslate:deepslate_bricks", prob=254, param2=0},
		{name="air", prob=254, param2=0},
		{name="air", prob=254, param2=0},
		{name="air", prob=254, param2=0},
		{name="air", prob=254, param2=0},
		{name="air", prob=254, param2=0},
		{name="air", prob=254, param2=0},
		{name="air", prob=254, param2=0},
		{name="air", prob=254, param2=0},
		{name="air", prob=254, param2=0},
		{name="air", prob=254, param2=0},
		{name="air", prob=254, param2=0},
		{name="air", prob=254, param2=0},
		{name="air", prob=254, param2=0},
		{name="vlf_deepslate:deepslate_bricks_cracked", prob=254, param2=0},
		{name="vlf_deepslate:deepslate", prob=254, param2=0},
		{name="air", prob=254, param2=0},
		{name="vlf_deepslate:deepslate_bricks", prob=254, param2=0},
		{name="air", prob=254, param2=0},
		{name="vlf_deepslate:deepslate_bricks", prob=254, param2=0},
		{name="air", prob=254, param2=0},
		{name="air", prob=254, param2=0},
		{name="air", prob=254, param2=0},
		{name="air", prob=254, param2=0},
		{name="air", prob=254, param2=0},
		{name="air", prob=254, param2=0},
		{name="air", prob=254, param2=0},
		{name="air", prob=254, param2=0},
		{name="air", prob=254, param2=0},
		{name="air", prob=254, param2=0},
		{name="air", prob=254, param2=0},
		{name="air", prob=254, param2=0},
		{name="air", prob=254, param2=0},
		{name="air", prob=254, param2=0},
		{name="vlf_deepslate:deepslate_bricks", prob=254, param2=0},
		{name="vlf_deepslate:deepslate", prob=254, param2=0},
		{name="air", prob=254, param2=0},
		{name="air", prob=254, param2=0},
		{name="vlf_deepslate:deepslate_reinforced", prob=254, param2=6},
		{name="air", prob=254, param2=0},
		{name="air", prob=254, param2=0},
		{name="air", prob=254, param2=0},
		{name="air", prob=254, param2=0},
		{name="air", prob=254, param2=0},
		{name="air", prob=254, param2=0},
		{name="air", prob=254, param2=0},
		{name="air", prob=254, param2=0},
		{name="air", prob=254, param2=0},
		{name="air", prob=254, param2=0},
		{name="air", prob=254, param2=0},
		{name="air", prob=254, param2=0},
		{name="air", prob=254, param2=0},
		{name="air", prob=254, param2=0},
		{name="air", prob=254, param2=0},
		{name="vlf_deepslate:deepslate_bricks", prob=254, param2=0},
		{name="vlf_deepslate:deepslate", prob=254, param2=0},
		{name="air", prob=254, param2=0},
		{name="air", prob=254, param2=0},
		{name="air", prob=254, param2=0},
		{name="air", prob=254, param2=0},
		{name="air", prob=254, param2=0},
		{name="air", prob=254, param2=0},
		{name="air", prob=254, param2=0},
		{name="air", prob=254, param2=0},
		{name="air", prob=254, param2=0},
		{name="air", prob=254, param2=0},
		{name="air", prob=254, param2=0},
		{name="air", prob=254, param2=0},
		{name="air", prob=254, param2=0},
		{name="air", prob=254, param2=0},
		{name="air", prob=254, param2=0},
		{name="air", prob=254, param2=0},
		{name="air", prob=254, param2=0},
		{name="air", prob=254, param2=0},
		{name="vlf_deepslate:deepslate_bricks", prob=254, param2=0},
		{name="vlf_deepslate:deepslate", prob=254, param2=0},
		{name="air", prob=254, param2=0},
		{name="air", prob=254, param2=0},
		{name="air", prob=254, param2=0},
		{name="air", prob=254, param2=0},
		{name="air", prob=254, param2=0},
		{name="air", prob=254, param2=0},
		{name="air", prob=254, param2=0},
		{name="air", prob=254, param2=0},
		{name="air", prob=254, param2=0},
		{name="air", prob=254, param2=0},
		{name="air", prob=254, param2=0},
		{name="air", prob=254, param2=0},
		{name="air", prob=254, param2=0},
		{name="air", prob=254, param2=0},
		{name="air", prob=254, param2=0},
		{name="air", prob=254, param2=0},
		{name="vlf_deepslate:deepslate", prob=254, param2=0},
		{name="vlf_deepslate:deepslate", prob=254, param2=0},
		{name="vlf_deepslate:deepslate", prob=254, param2=0},
		{name="vlf_deepslate:deepslate", prob=254, param2=0},
		{name="air", prob=254, param2=0},
		{name="air", prob=254, param2=0},
		{name="air", prob=254, param2=0},
		{name="air", prob=254, param2=0},
		{name="air", prob=254, param2=0},
		{name="air", prob=254, param2=0},
		{name="air", prob=254, param2=0},
		{name="air", prob=254, param2=0},
		{name="vlf_deepslate:deepslate", prob=254, param2=0},
		{name="vlf_deepslate:deepslate", prob=254, param2=0},
		{name="vlf_deepslate:deepslate", prob=254, param2=0},
		{name="vlf_deepslate:deepslate", prob=254, param2=0},
		{name="vlf_deepslate:deepslate", prob=254, param2=0},
		{name="air", prob=254, param2=0},
		{name="air", prob=254, param2=0},
		{name="air", prob=254, param2=0},
		{name="air", prob=254, param2=0},
		{name="vlf_deepslate:deepslate", prob=254, param2=0},
		{name="air", prob=254, param2=0},
		{name="air", prob=254, param2=0},
		{name="vlf_deepslate:deepslate", prob=254, param2=0},
		{name="vlf_deepslate:deepslate", prob=254, param2=0},
		{name="vlf_deepslate:deepslate_reinforced", prob=254, param2=6},
		{name="air", prob=254, param2=0},
		{name="air", prob=254, param2=0},
		{name="air", prob=254, param2=0},
		{name="air", prob=254, param2=0},
		{name="air", prob=254, param2=0},
		{name="vlf_deepslate:deepslate", prob=254, param2=0},
		{name="vlf_deepslate:deepslate", prob=254, param2=0},
		{name="vlf_deepslate:deepslate", prob=254, param2=0},
		{name="vlf_deepslate:deepslate", prob=254, param2=0},
		{name="air", prob=254, param2=0},
		{name="air", prob=254, param2=0},
		{name="air", prob=254, param2=0},
		{name="air", prob=254, param2=0},
		{name="air", prob=254, param2=0},
		{name="vlf_deepslate:deepslate", prob=254, param2=0},
		{name="vlf_deepslate:deepslate", prob=254, param2=0},
		{name="vlf_deepslate:deepslate", prob=254, param2=0},
		{name="vlf_deepslate:deepslate", prob=254, param2=0},
		{name="vlf_deepslate:deepslate", prob=254, param2=0},
		{name="vlf_deepslate:deepslate_bricks", prob=254, param2=0},
		{name="air", prob=254, param2=0},
		{name="air", prob=254, param2=0},
		{name="vlf_deepslate:deepslate", prob=254, param2=0},
		{name="vlf_deepslate:deepslate", prob=254, param2=0},
		{name="vlf_deepslate:deepslate", prob=254, param2=0},
		{name="vlf_deepslate:deepslate", prob=254, param2=0},
		{name="vlf_deepslate:deepslate", prob=254, param2=0},
		{name="vlf_deepslate:deepslate", prob=254, param2=0},
		{name="air", prob=254, param2=0},
		{name="air", prob=254, param2=0},
		{name="air", prob=254, param2=0},
		{name="air", prob=254, param2=0},
		{name="air", prob=254, param2=0},
		{name="air", prob=254, param2=0},
		{name="vlf_deepslate:deepslate", prob=254, param2=0},
		{name="vlf_deepslate:deepslate", prob=254, param2=0},
		{name="vlf_deepslate:deepslate", prob=254, param2=0},
		{name="vlf_deepslate:deepslate", prob=254, param2=0},
		{name="vlf_deepslate:deepslate", prob=254, param2=0},
		{name="vlf_deepslate:deepslate", prob=254, param2=0},
		{name="vlf_deepslate:deepslate", prob=254, param2=0},
		{name="vlf_deepslate:deepslate", prob=254, param2=0},
		{name="vlf_deepslate:deepslate", prob=254, param2=0},
		{name="vlf_deepslate:deepslate", prob=254, param2=0},
		{name="vlf_deepslate:deepslate", prob=254, param2=0},
		{name="vlf_deepslate:deepslate", prob=254, param2=0},
		{name="vlf_deepslate:deepslate", prob=254, param2=0},
		{name="vlf_deepslate:deepslate", prob=254, param2=0},
		{name="air", prob=254, param2=0},
		{name="air", prob=254, param2=0},
		{name="air", prob=254, param2=0},
		{name="air", prob=254, param2=0},
		{name="vlf_deepslate:deepslate", prob=254, param2=0},
		{name="vlf_deepslate:deepslate", prob=254, param2=0},
		{name="vlf_deepslate:deepslate", prob=254, param2=0},
		{name="vlf_deepslate:deepslate", prob=254, param2=0},
		{name="vlf_deepslate:deepslate", prob=254, param2=0},
		{name="vlf_deepslate:deepslate", prob=254, param2=0},
		{name="vlf_deepslate:deepslate", prob=254, param2=0},
		{name="vlf_deepslate:deepslate", prob=254, param2=0},
		{name="vlf_deepslate:deepslate", prob=254, param2=0},
		{name="vlf_deepslate:deepslate", prob=254, param2=0},
		{name="vlf_deepslate:deepslate", prob=254, param2=0},
		{name="vlf_deepslate:deepslate", prob=254, param2=0},
		{name="vlf_deepslate:deepslate", prob=254, param2=0},
		{name="vlf_deepslate:deepslate", prob=254, param2=0},
		{name="vlf_deepslate:deepslate", prob=254, param2=0},
		{name="vlf_deepslate:deepslate", prob=254, param2=0},
		{name="vlf_deepslate:deepslate", prob=254, param2=0},
		{name="vlf_deepslate:deepslate", prob=254, param2=0},
		{name="vlf_deepslate:deepslate", prob=254, param2=0},
		{name="vlf_deepslate:deepslate", prob=254, param2=0},
		{name="vlf_deepslate:deepslate", prob=254, param2=0},
		{name="vlf_deepslate:deepslate", prob=254, param2=0},
		{name="vlf_deepslate:deepslate", prob=254, param2=0},
		{name="vlf_deepslate:deepslate", prob=254, param2=0},
		{name="vlf_deepslate:deepslate", prob=254, param2=0},
		{name="vlf_deepslate:deepslate_bricks", prob=254, param2=0},
		{name="vlf_deepslate:deepslate_tiles", prob=254, param2=0},
		{name="vlf_deepslate:deepslate_tiles", prob=254, param2=0},
		{name="vlf_deepslate:deepslate_tiles", prob=254, param2=0},
		{name="vlf_deepslate:deepslate_chiseled", prob=254, param2=0},
		{name="air", prob=254, param2=0},
		{name="air", prob=254, param2=0},
		{name="vlf_wool:grey_carpet", prob=254, param2=0},
		{name="air", prob=254, param2=0},
		{name="air", prob=254, param2=0},
		{name="air", prob=254, param2=0},
		{name="air", prob=254, param2=0},
		{name="air", prob=254, param2=0},
		{name="air", prob=254, param2=0},
		{name="air", prob=254, param2=0},
		{name="air", prob=254, param2=0},
		{name="air", prob=254, param2=0},
		{name="air", prob=254, param2=0},
		{name="air", prob=254, param2=0},
		{name="vlf_deepslate:deepslate_tiles", prob=254, param2=0},
		{name="air", prob=254, param2=0},
		{name="vlf_deepslate:deepslate_tiles", prob=254, param2=0},
		{name="vlf_deepslate:deepslate_tiles", prob=254, param2=0},
		{name="vlf_deepslate:deepslate_tiles", prob=254, param2=0},
		{name="air", prob=254, param2=0},
		{name="air", prob=254, param2=0},
		{name="air", prob=254, param2=0},
		{name="air", prob=254, param2=0},
		{name="air", prob=254, param2=0},
		{name="air", prob=254, param2=0},
		{name="air", prob=254, param2=0},
		{name="air", prob=254, param2=0},
		{name="air", prob=254, param2=0},
		{name="air", prob=254, param2=0},
		{name="air", prob=254, param2=0},
		{name="air", prob=254, param2=0},
		{name="air", prob=254, param2=0},
		{name="air", prob=254, param2=0},
		{name="air", prob=254, param2=0},
		{name="vlf_deepslate:deepslate_tiles", prob=254, param2=0},
		{name="air", prob=254, param2=0},
		{name="air", prob=254, param2=0},
		{name="vlf_deepslate:deepslate_reinforced", prob=254, param2=6},
		{name="air", prob=254, param2=0},
		{name="air", prob=254, param2=0},
		{name="air", prob=254, param2=0},
		{name="air", prob=254, param2=0},
		{name="air", prob=254, param2=0},
		{name="air", prob=254, param2=0},
		{name="air", prob=254, param2=0},
		{name="air", prob=254, param2=0},
		{name="air", prob=254, param2=0},
		{name="air", prob=254, param2=0},
		{name="air", prob=254, param2=0},
		{name="air", prob=254, param2=0},
		{name="air", prob=254, param2=0},
		{name="air", prob=254, param2=0},
		{name="air", prob=254, param2=0},
		{name="air", prob=254, param2=0},
		{name="vlf_deepslate:deepslate_tiles_cracked", prob=254, param2=0},
		{name="air", prob=254, param2=0},
		{name="air", prob=254, param2=0},
		{name="air", prob=254, param2=0},
		{name="air", prob=254, param2=0},
		{name="air", prob=254, param2=0},
		{name="air", prob=254, param2=0},
		{name="air", prob=254, param2=0},
		{name="air", prob=254, param2=0},
		{name="air", prob=254, param2=0},
		{name="air", prob=254, param2=0},
		{name="air", prob=254, param2=0},
		{name="air", prob=254, param2=0},
		{name="air", prob=254, param2=0},
		{name="air", prob=254, param2=0},
		{name="air", prob=254, param2=0},
		{name="air", prob=254, param2=0},
		{name="air", prob=254, param2=0},
		{name="air", prob=254, param2=0},
		{name="air", prob=254, param2=0},
		{name="vlf_deepslate:deepslate_tiles", prob=254, param2=0},
		{name="air", prob=254, param2=0},
		{name="air", prob=254, param2=0},
		{name="air", prob=254, param2=0},
		{name="air", prob=254, param2=0},
		{name="air", prob=254, param2=0},
		{name="air", prob=254, param2=0},
		{name="air", prob=254, param2=0},
		{name="air", prob=254, param2=0},
		{name="air", prob=254, param2=0},
		{name="air", prob=254, param2=0},
		{name="air", prob=254, param2=0},
		{name="air", prob=254, param2=0},
		{name="air", prob=254, param2=0},
		{name="air", prob=254, param2=0},
		{name="air", prob=254, param2=0},
		{name="vlf_deepslate:deepslate", prob=254, param2=0},
		{name="vlf_deepslate:deepslate", prob=254, param2=0},
		{name="vlf_deepslate:deepslate_with_redstone", prob=254, param2=0},
