schematic = {
	size = {x=5, y=4, z=13},
	yslice_prob = {
		{ypos=0, prob=254},
		{ypos=1, prob=254},
		{ypos=2, prob=254},
		{ypos=3, prob=254},
	},
	data = {
		{name="air", prob=0, param2=0},
		{name="air", prob=0, param2=0},
		{name="air", prob=0, param2=0},
		{name="air", prob=0, param2=0},
		{name="air", prob=0, param2=0},
		{name="air", prob=0, param2=0},
		{name="air", prob=0, param2=0},
		{name="air", prob=0, param2=0},
		{name="air", prob=0, param2=0},
		{name="air", prob=0, param2=0},
		{name="air", prob=0, param2=0},
		{name="air", prob=0, param2=0},
		{name="air", prob=0, param2=0},
		{name="air", prob=0, param2=0},
		{name="air", prob=0, param2=0},
		{name="air", prob=0, param2=0},
		{name="air", prob=0, param2=0},
		{name="vlf_core:bone_block", prob=238, param2=6},
		{name="air", prob=0, param2=0},
		{name="air", prob=0, param2=0},
		{name="vlf_core:bone_block", prob=238, param2=12},
		{name="vlf_core:bone_block", prob=238, param2=12},
		{name="air", prob=0, param2=0},
		{name="vlf_core:bone_block", prob=238, param2=12},
		{name="vlf_core:bone_block", prob=238, param2=12},
		{name="vlf_core:bone_block", prob=238, param2=0},
		{name="air", prob=0, param2=0},
		{name="air", prob=0, param2=0},
		{name="air", prob=0, param2=0},
		{name="vlf_core:bone_block", prob=238, param2=0},
		{name="vlf_core:bone_block", prob=238, param2=0},
		{name="air", prob=0, param2=0},
		{name="air", prob=0, param2=0},
		{name="air", prob=0, param2=0},
		{name="vlf_core:bone_block", prob=238, param2=0},
		{name="vlf_core:bone_block", prob=238, param2=12},
		{name="vlf_core:bone_block", prob=238, param2=12},
		{name="vlf_core:bone_block", prob=238, param2=6},
		{name="vlf_core:bone_block", prob=238, param2=12},
		{name="vlf_core:bone_block", prob=238, param2=12},
		{name="air", prob=0, param2=0},
		{name="air", prob=0, param2=0},
		{name="air", prob=0, param2=0},
		{name="air", prob=0, param2=0},
		{name="air", prob=0, param2=0},
		{name="air", prob=0, param2=0},
		{name="air", prob=0, param2=0},
		{name="air", prob=0, param2=0},
		{name="air", prob=0, param2=0},
		{name="air", prob=0, param2=0},
		{name="air", prob=0, param2=0},
		{name="air", prob=0, param2=0},
		{name="air", prob=0, param2=0},
		{name="air", prob=0, param2=0},
		{name="air", prob=0, param2=0},
		{name="air", prob=0, param2=0},
		{name="air", prob=0, param2=0},
		{name="vlf_core:bone_block", prob=238, param2=6},
		{name="air", prob=0, param2=0},
		{name="air", prob=0, param2=0},
		{name="vlf_core:bone_block", prob=238, param2=12},
		{name="vlf_core:bone_block", prob=238, param2=12},
		{name="air", prob=0, param2=0},
		{name="vlf_core:bone_block", prob=238, param2=12},
		{name="vlf_core:bone_block", prob=238, param2=12},
		{name="vlf_core:bone_block", prob=238, param2=0},
		{name="air", prob=0, param2=0},
		{name="air", prob=0, param2=0},
		{name="air", prob=0, param2=0},
		{name="vlf_core:bone_block", prob=238, param2=0},
		{name="vlf_core:bone_block", prob=238, param2=0},
		{name="air", prob=0, param2=0},
		{name="air", prob=0, param2=0},
		{name="air", prob=0, param2=0},
		{name="vlf_core:bone_block", prob=238, param2=0},
		{name="vlf_core:bone_block", prob=238, param2=12},
		{name="vlf_core:bone_block", prob=238, param2=12},
		{name="vlf_core:bone_block", prob=238, param2=6},
		{name="vlf_core:bone_block", prob=238, param2=12},
		{name="vlf_core:bone_block", prob=238, param2=12},
		{name="air", prob=0, param2=0},
		{name="air", prob=0, param2=0},
		{name="air", prob=0, param2=0},
		{name="air", prob=0, param2=0},
		{name="air", prob=0, param2=0},
		{name="air", prob=0, param2=0},
		{name="air", prob=0, param2=0},
		{name="air", prob=0, param2=0},
		{name="air", prob=0, param2=0},
		{name="air", prob=0, param2=0},
		{name="air", prob=0, param2=0},
		{name="air", prob=0, param2=0},
		{name="air", prob=0, param2=0},
		{name="air", prob=0, param2=0},
		{name="air", prob=0, param2=0},
		{name="air", prob=0, param2=0},
		{name="air", prob=0, param2=0},
		{name="vlf_core:bone_block", prob=238, param2=6},
		{name="air", prob=0, param2=0},
		{name="air", prob=0, param2=0},
		{name="vlf_core:bone_block", prob=238, param2=12},
		{name="vlf_core:bone_block", prob=238, param2=12},
		{name="air", prob=0, param2=0},
		{name="vlf_core:bone_block", prob=238, param2=12},
		{name="vlf_core:bone_block", prob=238, param2=12},
		{name="vlf_core:bone_block", prob=238, param2=0},
		{name="air", prob=0, param2=0},
		{name="air", prob=0, param2=0},
		{name="air", prob=0, param2=0},
		{name="vlf_core:bone_block", prob=238, param2=0},
		{name="vlf_core:bone_block", prob=238, param2=0},
		{name="air", prob=0, param2=0},
		{name="air", prob=0, param2=0},
		{name="air", prob=0, param2=0},
		{name="vlf_core:bone_block", prob=238, param2=0},
		{name="vlf_core:bone_block", prob=238, param2=12},
		{name="vlf_core:bone_block", prob=238, param2=12},
		{name="vlf_core:bone_block", prob=238, param2=6},
		{name="vlf_core:bone_block", prob=238, param2=12},
		{name="vlf_core:bone_block", prob=238, param2=12},
		{name="air", prob=0, param2=0},
		{name="air", prob=0, param2=0},
		{name="air", prob=0, param2=0},
		{name="air", prob=0, param2=0},
		{name="air", prob=0, param2=0},
		{name="air", prob=0, param2=0},
		{name="air", prob=0, param2=0},
		{name="air", prob=0, param2=0},
		{name="air", prob=0, param2=0},
		{name="air", prob=0, param2=0},
		{name="air", prob=0, param2=0},
		{name="air", prob=0, param2=0},
		{name="air", prob=0, param2=0},
		{name="air", prob=0, param2=0},
		{name="air", prob=0, param2=0},
		{name="air", prob=0, param2=0},
		{name="air", prob=0, param2=0},
		{name="vlf_core:bone_block", prob=238, param2=6},
		{name="air", prob=0, param2=0},
		{name="air", prob=0, param2=0},
		{name="vlf_core:bone_block", prob=238, param2=12},
		{name="vlf_core:bone_block", prob=238, param2=12},
		{name="air", prob=0, param2=0},
		{name="vlf_core:bone_block", prob=238, param2=12},
		{name="vlf_core:bone_block", prob=238, param2=12},
		{name="vlf_core:bone_block", prob=238, param2=0},
		{name="air", prob=0, param2=0},
		{name="air", prob=0, param2=0},
		{name="air", prob=0, param2=0},
		{name="vlf_core:bone_block", prob=238, param2=0},
		{name="vlf_core:bone_block", prob=238, param2=0},
		{name="air", prob=0, param2=0},
		{name="air", prob=0, param2=0},
		{name="air", prob=0, param2=0},
		{name="vlf_core:bone_block", prob=238, param2=0},
		{name="vlf_core:bone_block", prob=238, param2=12},
		{name="vlf_core:bone_block", prob=238, param2=12},
		{name="vlf_core:bone_block", prob=238, param2=6},
		{name="vlf_core:bone_block", prob=238, param2=12},
		{name="vlf_core:bone_block", prob=238, param2=12},
		{name="air", prob=0, param2=0},
		{name="air", prob=0, param2=0},
		{name="air", prob=0, param2=0},
		{name="air", prob=0, param2=0},
		{name="air", prob=0, param2=0},
		{name="air", prob=0, param2=0},
		{name="air", prob=0, param2=0},
		{name="air", prob=0, param2=0},
		{name="air", prob=0, param2=0},
		{name="air", prob=0, param2=0},
		{name="air", prob=0, param2=0},
		{name="air", prob=0, param2=0},
		{name="air", prob=0, param2=0},
		{name="air", prob=0, param2=0},
		{name="air", prob=0, param2=0},
		{name="air", prob=0, param2=0},
		{name="air", prob=0, param2=0},
		{name="vlf_core:bone_block", prob=238, param2=6},
		{name="air", prob=0, param2=0},
		{name="air", prob=0, param2=0},
		{name="vlf_core:bone_block", prob=238, param2=12},
		{name="vlf_core:bone_block", prob=238, param2=12},
		{name="air", prob=0, param2=0},
		{name="vlf_core:bone_block", prob=238, param2=12},
		{name="vlf_core:bone_block", prob=238, param2=12},
		{name="vlf_core:bone_block", prob=238, param2=0},
		{name="air", prob=0, param2=0},
		{name="air", prob=0, param2=0},
		{name="air", prob=0, param2=0},
		{name="vlf_core:bone_block", prob=238, param2=0},
		{name="vlf_core:bone_block", prob=238, param2=0},
		{name="air", prob=0, param2=0},
		{name="air", prob=0, param2=0},
		{name="air", prob=0, param2=0},
		{name="vlf_core:bone_block", prob=238, param2=0},
		{name="vlf_core:bone_block", prob=238, param2=12},
		{name="vlf_core:bone_block", prob=238, param2=12},
		{name="vlf_core:bone_block", prob=238, param2=6},
		{name="vlf_core:bone_block", prob=238, param2=12},
		{name="vlf_core:bone_block", prob=238, param2=12},
		{name="air", prob=0, param2=0},
		{name="air", prob=0, param2=0},
		{name="air", prob=0, param2=0},
		{name="air", prob=0, param2=0},
		{name="air", prob=0, param2=0},
		{name="air", prob=0, param2=0},
		{name="air", prob=0, param2=0},
		{name="air", prob=0, param2=0},
		{name="air", prob=0, param2=0},
		{name="air", prob=0, param2=0},
		{name="air", prob=0, param2=0},
		{name="air", prob=0, param2=0},
		{name="air", prob=0, param2=0},
		{name="air", prob=0, param2=0},
		{name="air", prob=0, param2=0},
		{name="air", prob=0, param2=0},
		{name="air", prob=0, param2=0},
		{name="vlf_core:bone_block", prob=238, param2=6},
		{name="air", prob=0, param2=0},
		{name="air", prob=0, param2=0},
		{name="vlf_core:bone_block", prob=238, param2=12},
		{name="vlf_core:bone_block", prob=238, param2=12},
		{name="air", prob=0, param2=0},
		{name="vlf_core:bone_block", prob=238, param2=12},
		{name="vlf_core:bone_block", prob=238, param2=0},
		{name="vlf_core:bone_block", prob=238, param2=0},
		{name="air", prob=0, param2=0},
		{name="air", prob=0, param2=0},
		{name="air", prob=0, param2=0},
		{name="vlf_core:bone_block", prob=238, param2=0},
		{name="vlf_core:bone_block", prob=238, param2=0},
		{name="air", prob=0, param2=0},
		{name="air", prob=0, param2=0},
		{name="air", prob=0, param2=0},
		{name="vlf_core:bone_block", prob=238, param2=0},
		{name="vlf_core:bone_block", prob=238, param2=12},
		{name="vlf_core:bone_block", prob=238, param2=12},
		{name="vlf_core:bone_block", prob=238, param2=6},
		{name="vlf_core:bone_block", prob=238, param2=12},
		{name="vlf_core:bone_block", prob=238, param2=12},
		{name="air", prob=0, param2=0},
		{name="air", prob=0, param2=0},
		{name="air", prob=0, param2=0},
		{name="air", prob=0, param2=0},
		{name="air", prob=0, param2=0},
		{name="air", prob=0, param2=0},
		{name="air", prob=0, param2=0},
		{name="air", prob=0, param2=0},
		{name="air", prob=0, param2=0},
		{name="air", prob=0, param2=0},
		{name="air", prob=0, param2=0},
		{name="air", prob=0, param2=0},
		{name="air", prob=0, param2=0},
		{name="air", prob=0, param2=0},
		{name="air", prob=0, param2=0},
		{name="air", prob=0, param2=0},
		{name="air", prob=0, param2=0},
		{name="vlf_core:bone_block", prob=238, param2=6},
		{name="air", prob=0, param2=0},
		{name="air", prob=0, param2=0},
	},
}
