schematic = {
	size = {x=9, y=2, z=19},
	yslice_prob = {
		{ypos=0, prob=254},
		{ypos=1, prob=254},
	},
	data = {
		{name="air", prob=254, param2=0},
		{name="air", prob=254, param2=0},
		{name="air", prob=254, param2=0},
		{name="vlf_core:junglesapling", prob=254, param2=0},
		{name="vlf_core:acaciasapling", prob=254, param2=0},
		{name="vlf_core:darksapling", prob=254, param2=0},
		{name="vlf_core:sprucesapling", prob=254, param2=0},
		{name="vlf_core:birchsapling", prob=254, param2=0},
		{name="vlf_core:sapling", prob=254, param2=0},
		{name="air", prob=254, param2=0},
		{name="air", prob=254, param2=0},
		{name="air", prob=254, param2=0},
		{name="vlf_core:acaciawood", prob=254, param2=0},
		{name="vlf_core:acaciawood", prob=254, param2=0},
		{name="vlf_core:acaciawood", prob=254, param2=0},
		{name="vlf_core:acaciawood", prob=254, param2=0},
		{name="vlf_core:acaciawood", prob=254, param2=0},
		{name="vlf_core:acaciawood", prob=254, param2=0},
		{name="vlf_crimson:warped_trapdoor", prob=254, param2=0},
		{name="vlf_crimson:crimson_trapdoor", prob=254, param2=0},
		{name="vlf_mangrove:mangrove_trapdoor", prob=254, param2=0},
		{name="vlf_doors:jungle_trapdoor", prob=254, param2=0},
		{name="vlf_doors:acacia_trapdoor", prob=254, param2=0},
		{name="vlf_doors:dark_oak_trapdoor", prob=254, param2=0},
		{name="vlf_doors:spruce_trapdoor", prob=254, param2=0},
		{name="vlf_doors:birch_trapdoor", prob=254, param2=0},
		{name="vlf_doors:trapdoor", prob=254, param2=0},
		{name="air", prob=254, param2=0},
		{name="air", prob=254, param2=0},
		{name="air", prob=254, param2=0},
		{name="air", prob=254, param2=0},
		{name="air", prob=254, param2=0},
		{name="air", prob=254, param2=0},
		{name="air", prob=254, param2=0},
		{name="air", prob=254, param2=0},
		{name="air", prob=254, param2=0},
		{name="vlf_crimson:warped_door_b_1", prob=254, param2=0},
		{name="vlf_crimson:crimson_door_b_1", prob=254, param2=0},
		{name="vlf_mangrove:mangrove_door_b_1", prob=254, param2=0},
		{name="vlf_doors:jungle_door_b_1", prob=254, param2=0},
		{name="vlf_doors:acacia_door_b_1", prob=254, param2=0},
		{name="vlf_doors:dark_oak_door_b_1", prob=254, param2=0},
		{name="vlf_doors:spruce_door_b_1", prob=254, param2=0},
		{name="vlf_doors:birch_door_b_1", prob=254, param2=0},
		{name="vlf_doors:wooden_door_b_1", prob=254, param2=0},
		{name="vlf_crimson:warped_door_t_1", prob=254, param2=0},
		{name="vlf_crimson:crimson_door_t_1", prob=254, param2=0},
		{name="vlf_mangrove:mangrove_door_t_1", prob=254, param2=0},
		{name="vlf_doors:jungle_door_t_1", prob=254, param2=0},
		{name="vlf_doors:acacia_door_t_1", prob=254, param2=0},
		{name="vlf_doors:dark_oak_door_t_1", prob=254, param2=0},
		{name="vlf_doors:spruce_door_t_1", prob=254, param2=0},
		{name="vlf_doors:birch_door_t_1", prob=254, param2=0},
		{name="vlf_doors:wooden_door_t_1", prob=254, param2=0},
		{name="vlf_crimson:warped_fence_gate", prob=254, param2=3},
		{name="vlf_crimson:crimson_fence_gate", prob=254, param2=3},
		{name="vlf_fences:mangrove_fence_gate", prob=254, param2=3},
		{name="vlf_fences:jungle_fence_gate", prob=254, param2=3},
		{name="vlf_fences:acacia_fence_gate", prob=254, param2=3},
		{name="vlf_fences:dark_oak_fence_gate", prob=254, param2=3},
		{name="vlf_fences:spruce_fence_gate", prob=254, param2=3},
		{name="vlf_fences:birch_fence_gate", prob=254, param2=3},
		{name="vlf_fences:fence_gate", prob=254, param2=1},
		{name="air", prob=254, param2=0},
		{name="air", prob=254, param2=0},
		{name="air", prob=254, param2=0},
		{name="air", prob=254, param2=0},
		{name="air", prob=254, param2=0},
		{name="air", prob=254, param2=0},
		{name="air", prob=254, param2=0},
		{name="air", prob=254, param2=0},
		{name="air", prob=254, param2=0},
		{name="vlf_crimson:warped_fence", prob=254, param2=0},
		{name="vlf_crimson:crimson_fence", prob=254, param2=0},
		{name="vlf_fences:mangrove_fence", prob=254, param2=0},
		{name="vlf_fences:jungle_fence", prob=254, param2=0},
		{name="vlf_fences:acacia_fence", prob=254, param2=0},
		{name="vlf_fences:dark_oak_fence", prob=254, param2=0},
		{name="vlf_fences:spruce_fence", prob=254, param2=0},
		{name="vlf_fences:birch_fence", prob=254, param2=0},
		{name="vlf_fences:fence", prob=254, param2=0},
		{name="air", prob=254, param2=0},
		{name="air", prob=254, param2=0},
		{name="air", prob=254, param2=0},
		{name="air", prob=254, param2=0},
		{name="air", prob=254, param2=0},
		{name="air", prob=254, param2=0},
		{name="air", prob=254, param2=0},
		{name="air", prob=254, param2=0},
		{name="air", prob=254, param2=0},
		{name="air", prob=254, param2=0},
		{name="air", prob=254, param2=0},
		{name="air", prob=254, param2=0},
		{name="vlf_stairs:slab_jungletree_bark_double", prob=254, param2=0},
		{name="vlf_stairs:slab_acaciatree_bark_double", prob=254, param2=0},
		{name="vlf_stairs:slab_darktree_bark_double", prob=254, param2=0},
		{name="vlf_stairs:slab_sprucetree_bark_double", prob=254, param2=0},
		{name="vlf_stairs:slab_birchtree_bark_double", prob=254, param2=0},
		{name="vlf_stairs:slab_tree_bark_double", prob=254, param2=0},
		{name="air", prob=254, param2=0},
		{name="air", prob=254, param2=0},
		{name="air", prob=254, param2=0},
		{name="air", prob=254, param2=0},
		{name="air", prob=254, param2=0},
		{name="air", prob=254, param2=0},
		{name="air", prob=254, param2=0},
		{name="air", prob=254, param2=0},
		{name="air", prob=254, param2=0},
		{name="air", prob=254, param2=0},
		{name="air", prob=254, param2=0},
		{name="air", prob=254, param2=0},
		{name="vlf_stairs:slab_jungletree_bark_top", prob=254, param2=0},
		{name="vlf_stairs:slab_acaciatree_bark_top", prob=254, param2=0},
		{name="vlf_stairs:slab_darktree_bark_top", prob=254, param2=0},
		{name="vlf_stairs:slab_sprucetree_bark_top", prob=254, param2=0},
		{name="vlf_stairs:slab_birchtree_bark_top", prob=254, param2=0},
		{name="vlf_stairs:slab_tree_bark_top", prob=254, param2=0},
		{name="air", prob=254, param2=0},
		{name="air", prob=254, param2=0},
		{name="air", prob=254, param2=0},
		{name="vlf_stairs:slab_jungletree_bark", prob=254, param2=0},
		{name="vlf_stairs:slab_acaciatree_bark", prob=254, param2=0},
		{name="vlf_stairs:slab_darktree_bark", prob=254, param2=0},
		{name="vlf_stairs:slab_sprucetree_bark", prob=254, param2=0},
		{name="vlf_stairs:slab_birchtree_bark", prob=254, param2=0},
		{name="vlf_stairs:slab_tree_bark", prob=254, param2=0},
		{name="vlf_crimson:warped_hyphae_bark", prob=254, param2=0},
		{name="vlf_crimson:crimson_hyphae_bark", prob=254, param2=0},
		{name="vlf_mangrove:mangrove_tree_bark", prob=254, param2=0},
		{name="vlf_core:jungletree_bark", prob=254, param2=0},
		{name="vlf_core:acaciatree_bark", prob=254, param2=0},
		{name="vlf_core:darktree_bark", prob=254, param2=0},
		{name="vlf_core:sprucetree_bark", prob=254, param2=0},
		{name="vlf_core:birchtree_bark", prob=254, param2=0},
		{name="vlf_core:tree_bark", prob=254, param2=0},
		{name="air", prob=254, param2=0},
		{name="air", prob=254, param2=0},
		{name="air", prob=254, param2=0},
		{name="air", prob=254, param2=0},
		{name="air", prob=254, param2=0},
		{name="air", prob=254, param2=0},
		{name="air", prob=254, param2=0},
		{name="air", prob=254, param2=0},
		{name="air", prob=254, param2=0},
		{name="vlf_stairs:slab_warped_hyphae_wood_double", prob=254, param2=0},
		{name="vlf_stairs:slab_crimson_hyphae_wood_double", prob=254, param2=0},
		{name="vlf_stairs:slab_mangrove_wood_double", prob=254, param2=0},
		{name="vlf_stairs:slab_junglewood_double", prob=254, param2=0},
		{name="vlf_stairs:slab_acaciawood_double", prob=254, param2=0},
		{name="vlf_stairs:slab_darkwood_double", prob=254, param2=0},
		{name="vlf_stairs:slab_sprucewood_double", prob=254, param2=0},
		{name="vlf_stairs:slab_birchwood_double", prob=254, param2=0},
		{name="vlf_stairs:slab_wood_double", prob=254, param2=0},
		{name="air", prob=254, param2=0},
		{name="air", prob=254, param2=0},
		{name="air", prob=254, param2=0},
		{name="air", prob=254, param2=0},
		{name="air", prob=254, param2=0},
		{name="air", prob=254, param2=0},
		{name="air", prob=254, param2=0},
		{name="air", prob=254, param2=0},
		{name="air", prob=254, param2=0},
		{name="vlf_stairs:slab_warped_hyphae_wood_top", prob=254, param2=0},
		{name="vlf_stairs:slab_crimson_hyphae_wood_top", prob=254, param2=0},
		{name="vlf_stairs:slab_mangrove_wood_top", prob=254, param2=0},
		{name="vlf_stairs:slab_junglewood_top", prob=254, param2=0},
		{name="vlf_stairs:slab_acaciawood_top", prob=254, param2=0},
		{name="vlf_stairs:slab_darkwood_top", prob=254, param2=0},
		{name="vlf_stairs:slab_sprucewood_top", prob=254, param2=0},
		{name="vlf_stairs:slab_birchwood_top", prob=254, param2=0},
		{name="vlf_stairs:slab_wood_top", prob=254, param2=0},
		{name="air", prob=254, param2=0},
		{name="air", prob=254, param2=0},
		{name="air", prob=254, param2=0},
		{name="air", prob=254, param2=0},
		{name="air", prob=254, param2=0},
		{name="air", prob=254, param2=0},
		{name="air", prob=254, param2=0},
		{name="air", prob=254, param2=0},
		{name="air", prob=254, param2=0},
		{name="vlf_crimson:stripped_warped_hyphae_bark", prob=254, param2=0},
		{name="vlf_crimson:stripped_crimson_hyphae_bark", prob=254, param2=6},
		{name="vlf_mangrove:mangrove_stripped_bark", prob=254, param2=6},
		{name="vlf_core:stripped_jungle_bark", prob=254, param2=0},
		{name="vlf_core:stripped_acacia_bark", prob=254, param2=6},
		{name="vlf_core:stripped_dark_oak_bark", prob=254, param2=0},
		{name="vlf_core:stripped_spruce_bark", prob=254, param2=0},
		{name="vlf_core:stripped_birch_bark", prob=254, param2=0},
		{name="vlf_core:stripped_oak_bark", prob=254, param2=0},
		{name="air", prob=254, param2=0},
		{name="air", prob=254, param2=0},
		{name="vlf_mangrove:mangroveleaves", prob=254, param2=1},
		{name="vlf_core:jungleleaves", prob=254, param2=1},
		{name="vlf_core:acacialeaves", prob=254, param2=1},
		{name="vlf_core:darkleaves", prob=254, param2=1},
		{name="vlf_core:spruceleaves", prob=254, param2=1},
		{name="vlf_core:birchleaves", prob=254, param2=1},
		{name="vlf_core:leaves", prob=254, param2=1},
		{name="vlf_crimson:stripped_warped_hyphae", prob=254, param2=0},
		{name="vlf_crimson:stripped_crimson_hyphae", prob=254, param2=0},
		{name="vlf_mangrove:mangrove_stripped_trunk", prob=254, param2=0},
		{name="vlf_core:stripped_jungle", prob=254, param2=0},
		{name="vlf_core:stripped_acacia", prob=254, param2=0},
		{name="vlf_core:stripped_dark_oak", prob=254, param2=0},
		{name="vlf_core:stripped_spruce", prob=254, param2=0},
		{name="vlf_core:stripped_birch", prob=254, param2=0},
		{name="vlf_core:stripped_oak", prob=254, param2=0},
		{name="air", prob=254, param2=0},
		{name="air", prob=254, param2=0},
		{name="air", prob=254, param2=0},
		{name="air", prob=254, param2=0},
		{name="air", prob=254, param2=0},
		{name="air", prob=254, param2=0},
		{name="air", prob=254, param2=0},
		{name="air", prob=254, param2=0},
		{name="air", prob=254, param2=0},
		{name="vlf_crimson:warped_hyphae_wood", prob=254, param2=0},
		{name="vlf_crimson:crimson_hyphae_wood", prob=254, param2=0},
		{name="vlf_trees:wood_mangrove", prob=254, param2=0},
		{name="vlf_core:junglewood", prob=254, param2=0},
		{name="vlf_core:acaciawood", prob=254, param2=0},
		{name="vlf_core:darkwood", prob=254, param2=0},
		{name="vlf_core:sprucewood", prob=254, param2=0},
		{name="vlf_core:birchwood", prob=254, param2=0},
		{name="vlf_core:wood", prob=254, param2=0},
		{name="air", prob=254, param2=0},
		{name="air", prob=254, param2=0},
		{name="air", prob=254, param2=0},
		{name="air", prob=254, param2=0},
		{name="air", prob=254, param2=0},
		{name="air", prob=254, param2=0},
		{name="air", prob=254, param2=0},
		{name="air", prob=254, param2=0},
		{name="air", prob=254, param2=0},
		{name="vlf_crimson:warped_hyphae", prob=254, param2=0},
		{name="vlf_crimson:crimson_hyphae", prob=254, param2=0},
		{name="vlf_mangrove:mangrove_tree", prob=254, param2=0},
		{name="vlf_core:jungletree", prob=254, param2=0},
		{name="vlf_core:acaciatree", prob=254, param2=0},
		{name="vlf_core:darktree", prob=254, param2=0},
		{name="vlf_core:sprucetree", prob=254, param2=0},
		{name="vlf_core:birchtree", prob=254, param2=0},
		{name="vlf_core:tree", prob=254, param2=0},
		{name="air", prob=254, param2=0},
		{name="air", prob=254, param2=0},
		{name="air", prob=254, param2=0},
		{name="air", prob=254, param2=0},
		{name="air", prob=254, param2=0},
		{name="air", prob=254, param2=0},
		{name="air", prob=254, param2=0},
		{name="air", prob=254, param2=0},
		{name="air", prob=254, param2=0},
		{name="vlf_stairs:stair_warped_hyphae_wood", prob=254, param2=2},
		{name="vlf_stairs:stair_crimson_hyphae_wood", prob=254, param2=2},
		{name="vlf_stairs:stair_mangrove_wood", prob=254, param2=2},
		{name="vlf_stairs:stair_junglewood", prob=254, param2=2},
		{name="vlf_stairs:stair_acaciawood", prob=254, param2=2},
		{name="vlf_stairs:stair_darkwood", prob=254, param2=2},
		{name="vlf_stairs:stair_sprucewood", prob=254, param2=2},
		{name="vlf_stairs:stair_birchwood", prob=254, param2=2},
		{name="vlf_stairs:stair_wood", prob=254, param2=2},
		{name="air", prob=254, param2=0},
		{name="air", prob=254, param2=0},
		{name="air", prob=254, param2=0},
		{name="air", prob=254, param2=0},
		{name="air", prob=254, param2=0},
		{name="air", prob=254, param2=0},
		{name="air", prob=254, param2=0},
		{name="air", prob=254, param2=0},
		{name="air", prob=254, param2=0},
		{name="vlf_stairs:slab_warped_hyphae_wood", prob=254, param2=0},
		{name="vlf_stairs:slab_crimson_hyphae_wood", prob=254, param2=0},
		{name="vlf_stairs:slab_mangrove_wood", prob=254, param2=0},
		{name="vlf_stairs:slab_junglewood", prob=254, param2=0},
		{name="vlf_stairs:slab_acaciawood", prob=254, param2=0},
		{name="vlf_stairs:slab_darkwood", prob=254, param2=0},
		{name="vlf_stairs:slab_sprucewood", prob=254, param2=0},
		{name="vlf_stairs:slab_birchwood", prob=254, param2=0},
		{name="vlf_stairs:slab_wood", prob=254, param2=0},
		{name="air", prob=254, param2=0},
		{name="air", prob=254, param2=0},
		{name="air", prob=254, param2=0},
		{name="air", prob=254, param2=0},
		{name="air", prob=254, param2=0},
		{name="air", prob=254, param2=0},
		{name="air", prob=254, param2=0},
		{name="air", prob=254, param2=0},
		{name="air", prob=254, param2=0},
		{name="mesecons_pressureplates:pressure_plate_warped_off", prob=254, param2=0},
		{name="mesecons_pressureplates:pressure_plate_crimson_off", prob=254, param2=0},
		{name="mesecons_pressureplates:pressure_plate_mangrove_wood_off", prob=254, param2=0},
		{name="mesecons_pressureplates:pressure_plate_junglewood_off", prob=254, param2=0},
		{name="mesecons_pressureplates:pressure_plate_acaciawood_off", prob=254, param2=0},
		{name="mesecons_pressureplates:pressure_plate_darkwood_off", prob=254, param2=0},
		{name="mesecons_pressureplates:pressure_plate_sprucewood_off", prob=254, param2=0},
		{name="mesecons_pressureplates:pressure_plate_birchwood_off", prob=254, param2=0},
		{name="mesecons_pressureplates:pressure_plate_wood_off", prob=254, param2=0},
		{name="air", prob=254, param2=0},
		{name="air", prob=254, param2=0},
		{name="air", prob=254, param2=0},
		{name="air", prob=254, param2=0},
		{name="air", prob=254, param2=0},
		{name="air", prob=254, param2=0},
		{name="air", prob=254, param2=0},
		{name="air", prob=254, param2=0},
		{name="air", prob=254, param2=0},
		{name="mesecons_button:button_warped_off", prob=254, param2=1},
		{name="mesecons_button:button_crimson_off", prob=254, param2=1},
		{name="mesecons_button:button_mangrove_wood_off", prob=254, param2=1},
		{name="mesecons_button:button_junglewood_off", prob=254, param2=1},
		{name="mesecons_button:button_acaciawood_off", prob=254, param2=1},
		{name="mesecons_button:button_darkwood_off", prob=254, param2=1},
		{name="mesecons_button:button_sprucewood_off", prob=254, param2=1},
		{name="mesecons_button:button_birchwood_off", prob=254, param2=1},
		{name="mesecons_button:button_wood_off", prob=254, param2=1},
		{name="air", prob=254, param2=0},
		{name="air", prob=254, param2=0},
		{name="air", prob=254, param2=0},
		{name="air", prob=254, param2=0},
		{name="air", prob=254, param2=0},
		{name="air", prob=254, param2=0},
		{name="air", prob=254, param2=0},
		{name="air", prob=254, param2=0},
		{name="air", prob=254, param2=0},
		{name="vlf_signs:standing_sign_warped", prob=254, param2=2},
		{name="vlf_signs:standing_sign_crimson", prob=254, param2=2},
		{name="vlf_signs:standing_sign_mangrove", prob=254, param2=2},
		{name="vlf_signs:standing_sign_jungle", prob=254, param2=2},
		{name="vlf_signs:standing_sign_acacia", prob=254, param2=2},
		{name="vlf_signs:standing_sign_dark_oak", prob=254, param2=2},
		{name="vlf_signs:standing_sign_spruce", prob=254, param2=2},
		{name="vlf_signs:standing_sign_birch", prob=254, param2=2},
		{name="vlf_signs:standing_sign_oak", prob=254, param2=2},
		{name="air", prob=254, param2=0},
		{name="air", prob=254, param2=0},
		{name="air", prob=254, param2=0},
		{name="air", prob=254, param2=0},
		{name="air", prob=254, param2=0},
		{name="air", prob=254, param2=0},
		{name="air", prob=254, param2=0},
		{name="air", prob=254, param2=0},
		{name="air", prob=254, param2=0},
	},
}
